weight=25
embed_into_distance=1
max_leveling=4
max_cut_in=2
leveling_buffer=1
dimensions=22,18,18

rule1=0,100,3134-10
rule2=2,100,2843-4
rule3=0,100,2843-14,2843-14,2843-14,2843-14,2843
rule4=0,95,2835-2,2835-2,2835-2,2835-2,2835-2,2835-2,2835-2,2835-1,2835-1,2835-0
rule5=2,66,3225-3
rule6=0,100,622
rule7=1,20,308
rule8=0,66,623
rule9=1,15,311
rule10=0,100,2781-4,2781-4,2781-4,2781-4,2781-4,2781-4,2781-4,2781-4,2781-4,2781-8
rule1=0,100,3134-10
rule12=0,100,300


layer
11,11,11,11,11,11,11,11,11,11,11,11,11,11,11,11,11,11
11,11,11,11,11,11,11,11,11,11,11,11,11,11,11,11,11,11
11,11,1,1,1,1,1,1,1,1,1,1,1,1,1,1,11,11
11,11,1,2,2,2,2,2,2,2,2,2,2,2,2,1,11,11
11,11,1,2,2,2,2,2,2,2,2,2,2,2,2,1,11,11
11,11,1,2,2,2,2,2,2,2,2,2,2,2,2,1,11,11
11,11,1,2,2,2,2,6,2,2,2,2,2,2,2,1,11,11
11,11,1,2,2,2,3,2,2,3,2,2,2,2,2,1,11,11
11,11,1,1,1,1,1,1,1,1,1,1,1,1,1,1,11,11
11,11,1,1,1,1,1,1,1,1,1,1,1,1,1,1,11,11
11,11,1,1,1,1,1,1,1,1,1,1,1,1,1,1,11,11
11,11,1,2,2,2,2,2,2,2,2,2,2,2,2,1,11,11
11,11,1,2,2,2,2,2,2,2,2,2,2,2,2,1,11,11
11,11,1,2,2,2,2,2,2,2,2,2,2,2,2,1,11,11
11,11,1,2,2,2,2,2,2,2,2,2,2,2,2,1,11,11
11,11,1,1,1,1,1,1,1,1,1,1,1,1,1,1,11,11
11,11,11,11,11,11,11,11,11,11,11,11,11,11,11,11,11,11
11,11,11,11,11,11,11,11,11,11,11,11,11,11,11,11,11,11
endlayer

layer
0,0,0,0,0,0,0,0,0,0,0,0,0,0,0,0,0,0
0,0,0,0,0,0,0,0,0,0,0,0,0,0,0,0,0,0
0,0,3,3,3,3,3,3,3,3,3,3,3,3,3,3,0,0
0,0,3,7,0,0,0,0,0,0,0,0,0,0,7,3,0,0
0,0,3,0,0,0,4,0,0,4,0,0,0,0,0,3,0,0
0,0,3,0,0,0,5,0,0,5,0,0,0,0,0,3,0,0
0,0,3,7,0,0,4,8,0,4,0,0,0,0,7,3,0,0
0,0,3,4,5,4,3,0,5,3,4,4,4,5,4,3,0,0
0,0,0,0,0,0,0,0,0,0,0,0,0,0,0,0,0,0
0,0,0,0,0,0,0,0,0,0,0,0,0,0,0,0,0,0
0,0,0,0,0,0,0,0,0,0,0,0,0,0,0,0,0,0
0,0,3,4,0,4,5,4,3,3,4,5,4,0,4,3,0,0
0,0,3,7,0,0,0,0,4,4,0,0,0,0,7,3,0,0
0,0,3,0,0,0,0,0,4,4,0,0,0,0,0,3,0,0
0,0,3,7,0,0,0,0,4,4,0,0,0,0,7,3,0,0
0,0,3,3,3,3,3,3,3,3,3,3,3,3,3,3,0,0
0,0,0,0,0,0,0,0,0,0,0,0,0,0,0,0,0,0
0,0,0,0,0,0,0,0,0,0,0,0,0,0,0,0,0,0
endlayer

layer
0,0,0,0,0,0,0,0,0,0,0,0,0,0,0,0,0,0
0,0,0,0,0,0,0,0,0,0,0,0,0,0,0,0,0,0
0,0,3,4,5,4,3,5,5,3,4,5,4,5,4,3,0,0
0,0,4,9,0,0,0,0,0,0,0,0,0,0,9,4,0,0
0,0,5,0,0,0,4,0,0,4,0,0,0,0,0,5,0,0
0,0,5,0,0,0,5,0,0,5,0,0,0,0,0,5,0,0
0,0,4,9,0,0,4,8,0,4,0,0,0,0,9,4,0,0
0,0,3,4,5,4,3,0,5,3,4,0,4,5,4,3,0,0
0,0,0,0,0,0,0,0,0,0,0,0,0,0,0,0,0,0
0,0,0,0,0,0,0,0,0,0,0,0,0,0,0,0,0,0
0,0,0,0,0,0,0,0,0,0,0,0,0,0,0,0,0,0
0,0,3,4,0,4,5,4,3,3,4,5,4,0,4,3,0,0
0,0,4,9,0,0,0,0,4,4,0,0,0,0,9,4,0,0
0,0,5,0,0,0,0,0,4,4,0,0,0,0,0,5,0,0
0,0,4,9,0,0,0,0,4,4,0,0,0,0,9,4,0,0
0,0,3,4,5,4,5,4,3,3,4,5,4,5,4,3,0,0
0,0,0,0,0,0,0,0,0,0,0,0,0,0,0,0,0,0
0,0,0,0,0,0,0,0,0,0,0,0,0,0,0,0,0,0
endlayer

layer
0,0,0,0,0,0,0,0,0,0,0,0,0,0,0,0,0,0
0,0,0,0,0,0,0,0,0,0,0,0,0,0,0,0,0,0
0,0,3,4,5,4,3,5,5,3,4,5,4,5,4,3,0,0
0,0,4,0,0,0,4,0,0,4,0,0,0,0,0,4,0,0
0,0,5,0,0,0,4,0,0,4,0,0,0,0,0,5,0,0
0,0,5,0,0,0,5,0,0,5,0,0,0,0,0,5,0,0
0,0,4,0,0,0,4,8,0,4,0,0,0,0,0,4,0,0
0,0,3,4,5,4,3,5,5,3,4,4,4,5,4,3,0,0
0,0,0,0,0,0,0,0,0,0,0,0,0,0,0,0,0,0
0,0,0,0,0,0,0,0,0,0,0,0,0,0,0,0,0,0
0,0,0,0,0,0,0,0,0,0,0,0,0,0,0,0,0,0
0,0,3,4,4,4,5,4,3,3,4,5,4,4,4,3,0,0
0,0,4,0,0,0,0,0,4,4,0,0,0,0,0,4,0,0
0,0,5,0,0,0,0,0,4,4,0,0,0,0,0,5,0,0
0,0,4,0,0,0,0,0,4,4,0,0,0,0,0,4,0,0
0,0,3,4,5,4,5,4,3,3,4,5,4,5,4,3,0,0
0,0,0,0,0,0,0,0,0,0,0,0,0,0,0,0,0,0
0,0,0,0,0,0,0,0,0,0,0,0,0,0,0,0,0,0
endlayer

layer
0,0,0,0,0,0,0,0,0,0,0,0,0,0,0,0,0,0
0,0,0,0,0,0,0,0,0,0,0,0,0,0,0,0,0,0
0,0,3,4,5,4,3,5,5,3,4,5,4,5,4,3,0,0
0,0,4,0,0,0,4,0,0,4,0,0,0,0,0,4,0,0
0,0,5,0,0,0,4,0,0,4,0,0,0,0,0,5,0,0
0,0,5,0,0,0,5,0,0,5,0,0,0,0,0,5,0,0
0,0,4,0,0,0,4,8,0,4,0,0,0,0,0,4,0,0
0,0,3,4,5,4,3,5,5,3,4,4,4,5,4,3,0,0
0,0,0,0,0,0,0,0,0,0,0,0,0,0,0,0,0,0
0,0,0,0,0,0,0,0,0,0,0,0,0,0,0,0,0,0
0,0,0,0,0,0,0,0,0,0,0,0,0,0,0,0,0,0
0,0,3,4,4,4,5,4,3,3,4,5,4,4,4,3,0,0
0,0,4,0,0,0,0,0,4,4,0,0,0,0,0,4,0,0
0,0,5,0,0,0,0,0,4,4,0,0,0,0,0,5,0,0
0,0,4,0,0,0,0,0,4,4,0,0,0,0,0,4,0,0
0,0,3,4,5,4,5,4,3,3,4,5,4,5,4,3,0,0
0,0,0,0,0,0,0,0,0,0,0,0,0,0,0,0,0,0
0,0,0,0,0,0,0,0,0,0,0,0,0,0,0,0,0,0
endlayer

layer
0,0,0,0,0,0,0,0,0,0,0,0,0,0,0,0,0,0
0,0,0,0,0,0,0,0,0,0,0,0,0,0,0,0,0,0
0,0,3,4,5,4,3,5,5,3,4,5,4,5,4,3,0,0
0,0,4,0,0,0,4,0,0,4,0,0,0,0,0,4,0,0
0,0,5,0,0,0,4,0,0,4,0,0,0,0,0,5,0,0
0,0,5,0,0,0,5,0,0,5,0,0,0,0,0,5,0,0
0,0,4,0,0,0,4,8,0,4,0,0,0,0,0,4,0,0
0,0,3,4,5,4,3,5,5,3,4,4,4,5,4,3,0,0
0,0,0,0,0,0,0,0,0,0,0,0,0,0,0,0,0,0
0,0,0,0,0,0,0,0,0,0,0,0,0,0,0,0,0,0
0,0,0,0,0,0,0,0,0,0,0,0,0,0,0,0,0,0
0,0,3,4,4,4,5,4,3,3,4,5,4,4,4,3,0,0
0,0,4,0,0,0,0,0,4,4,0,0,0,0,0,4,0,0
0,0,5,0,0,0,0,0,4,4,0,0,0,0,0,5,0,0
0,0,4,0,0,0,0,0,4,4,0,0,0,0,0,4,0,0
0,0,3,4,5,4,5,4,3,3,4,5,4,5,4,3,0,0
0,0,0,0,0,0,0,0,0,0,0,0,0,0,0,0,0,0
0,0,0,0,0,0,0,0,0,0,0,0,0,0,0,0,0,0
endlayer

layer
0,0,0,0,0,0,0,0,0,0,0,0,0,0,0,0,0,0
0,0,0,0,0,0,0,0,0,0,0,0,0,0,0,0,0,0
0,0,3,3,3,3,3,3,3,3,3,3,3,3,3,3,0,0
0,0,3,2,2,2,2,2,2,2,2,2,2,2,2,3,0,0
0,0,3,2,2,2,3,2,2,3,2,2,2,2,2,3,0,0
0,0,3,2,2,2,3,2,2,3,2,2,2,2,2,3,0,0
0,0,3,2,2,2,3,8,2,3,2,2,2,2,2,3,0,0
0,0,3,3,3,3,3,2,2,3,3,3,3,3,3,3,0,0
0,0,0,2,2,2,2,2,2,2,2,2,2,2,2,0,0,0
0,0,0,2,2,2,2,2,2,2,2,2,2,2,2,0,0,0
0,0,0,2,2,2,2,2,2,2,2,2,2,2,2,0,0,0
0,0,3,3,2,3,3,3,3,3,3,3,3,2,3,3,0,0
0,0,3,2,2,2,2,2,2,2,2,2,2,2,2,3,0,0
0,0,3,2,2,2,2,2,2,2,2,2,2,2,2,3,0,0
0,0,3,2,2,2,2,2,2,2,2,2,2,2,2,3,0,0
0,0,3,3,3,3,3,3,3,3,3,3,3,3,3,3,0,0
0,0,0,0,0,0,0,0,0,0,0,0,0,0,0,0,0,0
0,0,0,0,0,0,0,0,0,0,0,0,0,0,0,0,0,0
endlayer

layer
0,0,0,0,0,0,0,0,0,0,0,0,0,0,0,0,0,0
0,0,0,0,0,0,0,0,0,0,0,0,0,0,0,0,0,0
0,0,3,4,5,4,3,5,5,3,4,5,4,5,4,3,0,0
0,0,4,7,0,0,0,0,0,0,0,0,0,0,7,4,0,0
0,0,5,0,0,0,4,0,0,4,0,0,0,0,0,5,0,0
0,0,5,0,0,0,5,0,0,5,0,0,0,0,0,5,0,0
0,0,4,7,0,0,4,8,0,4,0,0,0,0,7,4,0,0
0,0,3,4,5,4,3,0,5,3,4,5,4,5,4,3,0,0
0,0,0,0,0,0,0,0,0,0,0,0,0,0,0,0,0,0
0,0,0,0,0,0,0,0,0,0,0,0,0,0,0,0,0,0
0,0,0,0,0,0,0,0,0,0,0,0,0,0,0,0,0,0
0,0,3,4,0,4,5,4,3,3,4,5,4,0,4,3,0,0
0,0,4,7,0,0,0,0,4,4,0,0,0,0,7,4,0,0
0,0,5,0,0,0,0,0,4,4,0,0,0,0,0,5,0,0
0,0,4,7,0,0,0,0,4,4,0,0,0,0,7,4,0,0
0,0,3,4,5,4,5,4,3,3,4,5,4,5,4,3,0,0
0,0,0,0,0,0,0,0,0,0,0,0,0,0,0,0,0,0
0,0,0,0,0,0,0,0,0,0,0,0,0,0,0,0,0,0
endlayer

layer
0,0,0,0,0,0,0,0,0,0,0,0,0,0,0,0,0,0
0,0,0,0,0,0,0,0,0,0,0,0,0,0,0,0,0,0
0,0,3,4,5,4,3,5,5,3,4,5,4,5,4,3,0,0
0,0,4,9,0,0,0,0,0,0,0,0,0,0,9,4,0,0
0,0,5,0,0,0,4,0,0,4,0,0,0,0,0,5,0,0
0,0,5,0,0,0,5,0,0,5,0,0,0,0,0,5,0,0
0,0,4,9,0,0,4,8,0,4,0,0,0,0,9,4,0,0
0,0,3,4,5,4,3,0,5,3,4,5,4,5,4,3,0,0
0,0,0,0,0,0,0,0,0,0,0,0,0,0,0,0,0,0
0,0,0,0,0,0,0,0,0,0,0,0,0,0,0,0,0,0
0,0,0,0,0,0,0,0,0,0,0,0,0,0,0,0,0,0
0,0,3,4,0,4,5,4,3,3,4,5,4,0,4,3,0,0
0,0,4,9,0,0,0,0,4,4,0,0,0,0,9,4,0,0
0,0,5,0,0,0,0,0,4,4,0,0,0,0,0,5,0,0
0,0,4,9,0,0,0,0,4,4,0,0,0,0,9,4,0,0
0,0,3,4,5,4,5,4,3,3,4,5,4,5,4,3,0,0
0,0,0,0,0,0,0,0,0,0,0,0,0,0,0,0,0,0
0,0,0,0,0,0,0,0,0,0,0,0,0,0,0,0,0,0
endlayer

layer
0,0,0,0,0,0,0,0,0,0,0,0,0,0,0,0,0,0
0,0,0,0,0,0,0,0,0,0,0,0,0,0,0,0,0,0
0,0,3,4,5,4,3,5,5,3,4,5,4,5,4,3,0,0
0,0,4,0,0,0,4,0,0,4,0,0,0,0,0,4,0,0
0,0,5,0,0,0,4,0,0,4,0,0,0,0,0,5,0,0
0,0,5,0,0,0,5,0,0,5,0,0,0,0,0,5,0,0
0,0,4,0,0,0,4,8,0,4,0,0,0,0,0,4,0,0
0,0,3,4,5,4,3,5,5,3,4,5,4,5,4,3,0,0
0,0,0,0,0,0,0,0,0,0,0,0,0,0,0,0,0,0
0,0,0,0,0,0,0,0,0,0,0,0,0,0,0,0,0,0
0,0,0,0,0,0,0,0,0,0,0,0,0,0,0,0,0,0
0,0,3,4,4,4,5,4,3,3,4,5,4,4,4,3,0,0
0,0,4,0,0,0,0,0,4,4,0,0,0,0,0,4,0,0
0,0,5,0,0,0,0,0,4,4,0,0,0,0,0,5,0,0
0,0,4,0,0,0,0,0,4,4,0,0,0,0,0,4,0,0
0,0,3,4,5,4,5,4,3,3,4,5,4,5,4,3,0,0
0,0,0,0,0,0,0,0,0,0,0,0,0,0,0,0,0,0
0,0,0,0,0,0,0,0,0,0,0,0,0,0,0,0,0,0
endlayer

layer
0,0,0,0,0,0,0,0,0,0,0,0,0,0,0,0,0,0
0,0,0,0,0,0,0,0,0,0,0,0,0,0,0,0,0,0
0,0,3,4,5,4,3,5,5,3,4,5,4,5,4,3,0,0
0,0,4,0,0,0,4,0,0,4,0,0,0,0,0,4,0,0
0,0,5,0,0,0,4,0,0,4,0,0,0,0,0,5,0,0
0,0,5,0,0,0,5,0,0,5,0,0,0,0,0,5,0,0
0,0,4,0,0,0,4,8,0,4,0,0,0,0,0,4,0,0
0,0,3,4,5,4,3,5,5,3,4,5,4,5,4,3,0,0
0,0,0,0,0,0,0,0,0,0,0,0,0,0,0,0,0,0
0,0,0,0,0,0,0,0,0,0,0,0,0,0,0,0,0,0
0,0,0,0,0,0,0,0,0,0,0,0,0,0,0,0,0,0
0,0,3,4,4,4,5,4,3,3,4,5,4,4,4,3,0,0
0,0,4,0,0,0,0,0,4,4,0,0,0,0,0,4,0,0
0,0,5,0,0,0,0,0,4,4,0,0,0,0,0,5,0,0
0,0,4,0,0,0,0,0,4,4,0,0,0,0,0,4,0,0
0,0,3,4,5,4,5,4,3,3,4,5,4,5,4,3,0,0
0,0,0,0,0,0,0,0,0,0,0,0,0,0,0,0,0,0
0,0,0,0,0,0,0,0,0,0,0,0,0,0,0,0,0,0
endlayer

layer
0,0,0,0,0,0,0,0,0,0,0,0,0,0,0,0,0,0
0,0,0,0,0,0,0,0,0,0,0,0,0,0,0,0,0,0
0,0,3,3,3,3,3,3,3,3,3,3,3,3,3,3,0,0
0,0,3,2,2,2,2,2,2,2,2,2,2,2,2,3,0,0
0,0,3,2,2,2,3,2,2,3,2,2,2,2,2,3,0,0
0,0,3,2,2,2,3,2,2,3,2,2,2,2,2,3,0,0
0,0,3,2,2,2,3,8,2,3,2,2,2,2,2,3,0,0
0,0,3,3,3,3,3,3,3,3,3,3,3,3,3,3,0,0
0,0,0,0,0,0,0,0,0,0,0,0,0,0,0,0,0,0
0,0,0,0,0,0,0,0,0,0,0,0,0,0,0,0,0,0
0,0,0,0,0,0,0,0,0,0,0,0,0,0,0,0,0,0
0,0,3,3,3,3,3,3,3,3,3,3,3,3,3,3,0,0
0,0,3,10,10,10,10,10,10,10,10,10,10,10,10,3,0,0
0,0,3,10,10,10,10,10,10,10,10,10,10,10,10,3,0,0
0,0,3,10,10,10,10,10,10,10,10,10,10,10,10,3,0,0
0,0,3,3,3,3,3,3,3,3,3,3,3,3,3,3,0,0
0,0,0,0,0,0,0,0,0,0,0,0,0,0,0,0,0,0
0,0,0,0,0,0,0,0,0,0,0,0,0,0,0,0,0,0
endlayer

layer
0,0,0,0,0,0,0,0,0,0,0,0,0,0,0,0,0,0
0,0,0,0,0,0,0,0,0,0,0,0,0,0,0,0,0,0
0,0,3,4,5,4,3,5,5,3,4,5,4,5,4,3,0,0
0,0,4,7,0,0,0,0,0,0,0,0,0,0,7,4,0,0
0,0,5,0,0,0,4,0,0,4,0,0,0,0,0,5,0,0
0,0,5,0,0,0,5,0,0,5,0,0,0,0,0,5,0,0
0,0,4,7,0,0,4,8,0,4,0,0,0,0,7,4,0,0
0,0,3,4,5,4,3,5,5,3,4,5,4,5,4,3,0,0
0,0,0,0,0,0,0,0,0,0,0,0,0,0,0,0,0,0
0,0,0,0,0,0,0,0,0,0,0,0,0,0,0,0,0,0
0,0,0,0,0,0,0,0,0,0,0,0,0,0,0,0,0,0
0,0,0,0,0,0,0,0,0,0,0,0,0,0,0,0,0,0
0,0,0,0,0,0,0,0,0,0,0,0,0,0,0,0,0,0
0,0,0,0,0,0,0,0,0,0,0,0,0,0,0,0,0,0
0,0,0,0,0,0,0,0,0,0,0,0,0,0,0,0,0,0
0,0,0,0,0,0,0,0,0,0,0,0,0,0,0,0,0,0
0,0,0,0,0,0,0,0,0,0,0,0,0,0,0,0,0,0
0,0,0,0,0,0,0,0,0,0,0,0,0,0,0,0,0,0
endlayer

layer
0,0,0,0,0,0,0,0,0,0,0,0,0,0,0,0,0,0
0,0,0,0,0,0,0,0,0,0,0,0,0,0,0,0,0,0
0,0,3,4,5,4,3,5,5,3,4,5,4,5,4,3,0,0
0,0,4,9,0,0,0,0,0,0,0,0,0,0,9,4,0,0
0,0,5,0,0,0,4,0,0,4,0,0,0,0,0,5,0,0
0,0,5,0,0,0,5,0,0,5,0,0,0,0,0,5,0,0
0,0,4,9,0,0,4,8,0,4,0,0,0,0,9,4,0,0
0,0,3,4,5,4,3,5,5,3,4,5,4,5,4,3,0,0
0,0,0,0,0,0,0,0,0,0,0,0,0,0,0,0,0,0
0,0,0,0,0,0,0,0,0,0,0,0,0,0,0,0,0,0
0,0,0,0,0,0,0,0,0,0,0,0,0,0,0,0,0,0
0,0,0,0,0,0,0,0,0,0,0,0,0,0,0,0,0,0
0,0,0,0,0,0,0,0,0,0,0,0,0,0,0,0,0,0
0,0,0,0,0,0,0,0,0,0,0,0,0,0,0,0,0,0
0,0,0,0,0,0,0,0,0,0,0,0,0,0,0,0,0,0
0,0,0,0,0,0,0,0,0,0,0,0,0,0,0,0,0,0
0,0,0,0,0,0,0,0,0,0,0,0,0,0,0,0,0,0
0,0,0,0,0,0,0,0,0,0,0,0,0,0,0,0,0,0
endlayer

layer
0,0,0,0,0,0,0,0,0,0,0,0,0,0,0,0,0,0
0,0,0,0,0,0,0,0,0,0,0,0,0,0,0,0,0,0
0,0,3,4,5,4,3,5,5,3,4,5,4,5,4,3,0,0
0,0,4,0,0,0,4,0,0,0,0,0,0,0,0,4,0,0
0,0,5,0,0,0,4,0,0,4,0,0,0,0,0,5,0,0
0,0,5,0,0,0,5,0,0,5,0,0,0,0,0,5,0,0
0,0,4,0,0,0,4,8,0,4,0,0,0,0,0,4,0,0
0,0,3,4,5,4,3,5,5,3,4,5,4,5,4,3,0,0
0,0,0,0,0,0,0,0,0,0,0,0,0,0,0,0,0,0
0,0,0,0,0,0,0,0,0,0,0,0,0,0,0,0,0,0
0,0,0,0,0,0,0,0,0,0,0,0,0,0,0,0,0,0
0,0,0,0,0,0,0,0,0,0,0,0,0,0,0,0,0,0
0,0,0,0,0,0,0,0,0,0,0,0,0,0,0,0,0,0
0,0,0,0,0,0,0,0,0,0,0,0,0,0,0,0,0,0
0,0,0,0,0,0,0,0,0,0,0,0,0,0,0,0,0,0
0,0,0,0,0,0,0,0,0,0,0,0,0,0,0,0,0,0
0,0,0,0,0,0,0,0,0,0,0,0,0,0,0,0,0,0
0,0,0,0,0,0,0,0,0,0,0,0,0,0,0,0,0,0
endlayer

layer
0,0,0,0,0,0,0,0,0,0,0,0,0,0,0,0,0,0
0,0,0,0,0,0,0,0,0,0,0,0,0,0,0,0,0,0
0,0,3,4,5,4,3,5,5,3,4,5,4,5,4,3,0,0
0,0,4,0,0,0,4,0,0,0,0,0,0,0,0,4,0,0
0,0,5,0,0,0,4,0,0,4,0,0,0,0,0,5,0,0
0,0,5,0,0,0,5,0,0,5,0,0,0,0,0,5,0,0
0,0,4,0,0,0,4,8,0,4,0,0,0,0,0,4,0,0
0,0,3,4,5,4,3,5,5,3,4,5,4,5,4,3,0,0
0,0,0,0,0,0,0,0,0,0,0,0,0,0,0,0,0,0
0,0,0,0,0,0,0,0,0,0,0,0,0,0,0,0,0,0
0,0,0,0,0,0,0,0,0,0,0,0,0,0,0,0,0,0
0,0,0,0,0,0,0,0,0,0,0,0,0,0,0,0,0,0
0,0,0,0,0,0,0,0,0,0,0,0,0,0,0,0,0,0
0,0,0,0,0,0,0,0,0,0,0,0,0,0,0,0,0,0
0,0,0,0,0,0,0,0,0,0,0,0,0,0,0,0,0,0
0,0,0,0,0,0,0,0,0,0,0,0,0,0,0,0,0,0
0,0,0,0,0,0,0,0,0,0,0,0,0,0,0,0,0,0
0,0,0,0,0,0,0,0,0,0,0,0,0,0,0,0,0,0
endlayer

layer
0,0,0,0,0,0,0,0,0,0,0,0,0,0,0,0,0,0
0,0,0,0,0,0,0,0,0,0,0,0,0,0,0,0,0,0
0,0,3,3,3,3,3,3,3,3,3,3,3,3,3,3,0,0
0,0,3,2,2,2,2,2,2,2,2,2,2,2,2,3,0,0
0,0,3,2,2,2,3,2,2,3,2,2,2,2,2,3,0,0
0,0,3,2,2,2,3,2,2,3,2,2,2,2,2,3,0,0
0,0,3,2,2,2,3,8,2,3,2,2,2,2,2,3,0,0
0,0,3,3,3,3,3,3,3,3,3,3,3,3,3,3,0,0
0,0,0,0,0,0,0,0,0,0,0,0,0,0,0,0,0,0
0,0,0,0,0,0,0,0,0,0,0,0,0,0,0,0,0,0
0,0,0,0,0,0,0,0,0,0,0,0,0,0,0,0,0,0
0,0,0,0,0,0,0,0,0,0,0,0,0,0,0,0,0,0
0,0,0,0,0,0,0,0,0,0,0,0,0,0,0,0,0,0
0,0,0,0,0,0,0,0,0,0,0,0,0,0,0,0,0,0
0,0,0,0,0,0,0,0,0,0,0,0,0,0,0,0,0,0
0,0,0,0,0,0,0,0,0,0,0,0,0,0,0,0,0,0
0,0,0,0,0,0,0,0,0,0,0,0,0,0,0,0,0,0
0,0,0,0,0,0,0,0,0,0,0,0,0,0,0,0,0,0
endlayer

layer
0,0,0,0,0,0,0,0,0,0,0,0,0,0,0,0,0,0
0,0,0,0,0,0,0,0,0,0,0,0,0,0,0,0,0,0
0,0,3,4,5,4,3,5,5,3,4,5,4,5,4,3,0,0
0,0,4,7,0,0,0,0,0,0,0,0,0,0,7,4,0,0
0,0,5,0,0,0,4,0,0,4,0,0,0,0,0,5,0,0
0,0,5,0,0,0,5,0,0,5,0,0,0,0,0,5,0,0
0,0,4,7,0,0,4,8,0,4,0,0,0,0,7,4,0,0
0,0,3,4,5,4,3,5,5,3,4,5,4,5,4,3,0,0
0,0,0,0,0,0,0,0,0,0,0,0,0,0,0,0,0,0
0,0,0,0,0,0,0,0,0,0,0,0,0,0,0,0,0,0
0,0,0,0,0,0,0,0,0,0,0,0,0,0,0,0,0,0
0,0,0,0,0,0,0,0,0,0,0,0,0,0,0,0,0,0
0,0,0,0,0,0,0,0,0,0,0,0,0,0,0,0,0,0
0,0,0,0,0,0,0,0,0,0,0,0,0,0,0,0,0,0
0,0,0,0,0,0,0,0,0,0,0,0,0,0,0,0,0,0
0,0,0,0,0,0,0,0,0,0,0,0,0,0,0,0,0,0
0,0,0,0,0,0,0,0,0,0,0,0,0,0,0,0,0,0
0,0,0,0,0,0,0,0,0,0,0,0,0,0,0,0,0,0
endlayer

layer
0,0,0,0,0,0,0,0,0,0,0,0,0,0,0,0,0,0
0,0,0,0,0,0,0,0,0,0,0,0,0,0,0,0,0,0
0,0,3,4,5,4,3,5,5,3,4,5,4,5,4,3,0,0
0,0,4,9,0,0,0,0,0,0,0,0,0,0,9,4,0,0
0,0,5,0,0,0,4,0,0,4,0,0,0,0,0,5,0,0
0,0,5,0,0,0,5,0,0,5,0,0,0,0,0,5,0,0
0,0,4,9,0,0,4,8,0,4,0,0,0,0,9,4,0,0
0,0,3,4,5,4,3,5,5,3,4,5,4,5,4,3,0,0
0,0,0,0,0,0,0,0,0,0,0,0,0,0,0,0,0,0
0,0,0,0,0,0,0,0,0,0,0,0,0,0,0,0,0,0
0,0,0,0,0,0,0,0,0,0,0,0,0,0,0,0,0,0
0,0,0,0,0,0,0,0,0,0,0,0,0,0,0,0,0,0
0,0,0,0,0,0,0,0,0,0,0,0,0,0,0,0,0,0
0,0,0,0,0,0,0,0,0,0,0,0,0,0,0,0,0,0
0,0,0,0,0,0,0,0,0,0,0,0,0,0,0,0,0,0
0,0,0,0,0,0,0,0,0,0,0,0,0,0,0,0,0,0
0,0,0,0,0,0,0,0,0,0,0,0,0,0,0,0,0,0
0,0,0,0,0,0,0,0,0,0,0,0,0,0,0,0,0,0
endlayer

layer
0,0,0,0,0,0,0,0,0,0,0,0,0,0,0,0,0,0
0,0,0,0,0,0,0,0,0,0,0,0,0,0,0,0,0,0
0,0,3,4,5,4,3,5,5,3,4,5,4,5,4,3,0,0
0,0,4,0,0,0,4,0,0,0,0,0,0,0,0,4,0,0
0,0,5,0,0,0,4,0,0,4,0,0,0,0,0,5,0,0
0,0,5,0,0,0,5,0,0,5,0,0,0,0,0,5,0,0
0,0,4,0,0,0,4,0,0,4,0,0,0,0,0,4,0,0
0,0,3,4,5,4,3,5,5,3,4,5,4,5,4,3,0,0
0,0,0,0,0,0,0,0,0,0,0,0,0,0,0,0,0,0
0,0,0,0,0,0,0,0,0,0,0,0,0,0,0,0,0,0
0,0,0,0,0,0,0,0,0,0,0,0,0,0,0,0,0,0
0,0,0,0,0,0,0,0,0,0,0,0,0,0,0,0,0,0
0,0,0,0,0,0,0,0,0,0,0,0,0,0,0,0,0,0
0,0,0,0,0,0,0,0,0,0,0,0,0,0,0,0,0,0
0,0,0,0,0,0,0,0,0,0,0,0,0,0,0,0,0,0
0,0,0,0,0,0,0,0,0,0,0,0,0,0,0,0,0,0
0,0,0,0,0,0,0,0,0,0,0,0,0,0,0,0,0,0
0,0,0,0,0,0,0,0,0,0,0,0,0,0,0,0,0,0
endlayer

layer
0,0,0,0,0,0,0,0,0,0,0,0,0,0,0,0,0,0
0,0,0,0,0,0,0,0,0,0,0,0,0,0,0,0,0,0
0,0,3,4,5,4,3,5,5,3,4,5,4,5,4,3,0,0
0,0,4,0,0,0,4,0,0,0,0,0,0,0,0,4,0,0
0,0,5,0,0,0,4,0,0,4,0,0,0,0,0,5,0,0
0,0,5,0,0,0,5,0,0,5,0,0,0,0,0,5,0,0
0,0,4,0,0,0,4,0,0,4,0,0,0,0,0,4,0,0
0,0,3,4,5,4,3,5,5,3,4,5,4,5,4,3,0,0
0,0,0,0,0,0,0,0,0,0,0,0,0,0,0,0,0,0
0,0,0,0,0,0,0,0,0,0,0,0,0,0,0,0,0,0
0,0,0,0,0,0,0,0,0,0,0,0,0,0,0,0,0,0
0,0,0,0,0,0,0,0,0,0,0,0,0,0,0,0,0,0
0,0,0,0,0,0,0,0,0,0,0,0,0,0,0,0,0,0
0,0,0,0,0,0,0,0,0,0,0,0,0,0,0,0,0,0
0,0,0,0,0,0,0,0,0,0,0,0,0,0,0,0,0,0
0,0,0,0,0,0,0,0,0,0,0,0,0,0,0,0,0,0
0,0,0,0,0,0,0,0,0,0,0,0,0,0,0,0,0,0
0,0,0,0,0,0,0,0,0,0,0,0,0,0,0,0,0,0
endlayer

layer
0,0,0,0,0,0,0,0,0,0,0,0,0,0,0,0,0,0
0,0,0,0,0,0,0,0,0,0,0,0,0,0,0,0,0,0
0,0,3,3,3,3,3,3,3,3,3,3,3,3,3,3,0,0
0,0,3,10,10,10,3,10,10,3,10,10,10,10,10,3,0,0
0,0,3,10,10,10,3,10,10,3,10,10,10,10,10,3,0,0
0,0,3,10,10,10,3,10,10,3,10,10,10,10,10,3,0,0
0,0,3,10,10,10,3,10,10,3,10,10,10,10,10,3,0,0
0,0,3,3,3,3,3,3,3,3,3,3,3,3,3,3,0,0
0,0,0,0,0,0,0,0,0,0,0,0,0,0,0,0,0,0
0,0,0,0,0,0,0,0,0,0,0,0,0,0,0,0,0,0
0,0,0,0,0,0,0,0,0,0,0,0,0,0,0,0,0,0
0,0,0,0,0,0,0,0,0,0,0,0,0,0,0,0,0,0
0,0,0,0,0,0,0,0,0,0,0,0,0,0,0,0,0,0
0,0,0,0,0,0,0,0,0,0,0,0,0,0,0,0,0,0
0,0,0,0,0,0,0,0,0,0,0,0,0,0,0,0,0,0
0,0,0,0,0,0,0,0,0,0,0,0,0,0,0,0,0,0
0,0,0,0,0,0,0,0,0,0,0,0,0,0,0,0,0,0
0,0,0,0,0,0,0,0,0,0,0,0,0,0,0,0,0,0
endlayer

