weight=20
embed_into_distance=1
dimensions=22,18,18
max_cut_in=0



rule1=0,100,3134-10
rule2=0,100,2843-4
rule3=0,100,2843-14,2843-14,2843-14,2843-14,2843
rule4=0,100,622,2838-4,2838-4,2838-4,2838-4,2838-4,2838-4,2838-4,2838-4,2838-4
rule5=0,100,2245-0,2245-1,2245-2,2245-3,
rule6=0,100,35
rule7=0,50,308,308,308,308,308,308,313,313,314,327
rule8=0,95,2835-2,2835-2,2835-2,2835-2,2835-2,2835-2,2835-2,2835-1,2835-1,2835-0
rule9=0,100,35-1,35-2,35-3,35-4,35-5,35-6,35-7,35-8,35-9,35-10,35-11,35-12,35-13,35-14,35-15
rule10=0,25,3225-3
rule11=0,100,5
rule12=0,100,126-8
rule13=0,66,623
rule14=1,10,2244-0,2244-1,2244-2,2244-3,2244-4,2244-5,2244-6,2244-7,2244-8,2244-9,2244-10,2244-11,2244-12,2244-13,2244-14,2244-15
rule15=1,25,140-10
rule16=0,100,2781-4,2781-4,2781-4,2781-4,2781-4,2781-4,2781-4,2781-4,2781-4,2781-8
rule17=0,50,311



layer
1,1,1,1,1,1,1,1,1,1,1,1,1,1,1,1,1,1
1,1,1,1,1,1,1,1,1,1,1,1,1,1,1,1,1,1
1,1,1,1,1,1,1,1,1,1,1,1,1,1,1,1,1,1
1,1,1,2,2,2,2,2,2,2,2,2,2,2,2,1,1,1
1,1,1,2,2,2,2,2,2,2,2,2,2,2,2,1,1,1
1,1,1,2,2,2,2,2,2,2,2,2,2,2,2,1,1,1
1,1,1,2,2,2,2,4,2,2,2,2,2,2,2,1,1,1
1,1,1,2,2,2,3,2,2,3,2,2,2,2,2,1,1,1
1,1,1,1,1,1,1,1,1,1,1,1,1,1,1,1,1,1
1,1,1,1,1,1,1,1,1,1,1,1,1,1,1,1,1,1
1,1,1,1,1,1,1,1,1,1,1,1,1,1,1,1,1,1
1,1,1,2,2,2,2,2,2,2,2,2,2,2,2,1,1,1
1,1,1,2,2,2,2,2,2,2,2,2,2,2,2,1,1,1
1,1,1,2,2,2,2,2,2,2,2,2,2,2,2,1,1,1
1,1,1,2,2,2,2,2,2,2,2,2,2,2,2,1,1,1
1,1,1,1,1,1,1,1,1,1,1,1,1,1,1,1,1,1
1,1,1,1,1,1,1,1,1,1,1,1,1,1,1,1,1,1
1,1,1,1,1,1,1,1,1,1,1,1,1,1,1,1,1,1
endlayer

layer
0,0,0,0,0,0,0,0,0,0,0,0,0,0,0,0,0,0
0,0,0,0,0,0,0,0,0,0,0,0,0,0,0,0,0,0
0,0,3,3,3,3,3,3,3,3,3,3,3,3,3,3,0,0
0,0,3,12,0,0,0,0,0,0,0,0,0,0,5,3,0,0
0,0,3,0,0,0,8,0,0,8,11,0,0,9,6,3,0,0
0,0,3,0,9,0,10,0,0,10,12,0,0,0,5,3,0,0
0,0,3,7,6,5,8,13,0,8,11,0,0,0,7,3,0,0
0,0,3,8,10,8,3,0,10,3,8,8,8,10,8,3,0,0
0,0,0,0,0,0,0,0,0,0,0,0,0,0,0,0,0,0
0,0,0,0,0,0,0,0,0,0,0,0,0,0,0,0,0,0
0,0,0,0,0,0,0,0,0,0,0,0,0,0,0,0,0,0
0,0,3,8,0,8,10,8,3,3,8,10,8,0,8,3,0,0
0,0,3,5,0,0,0,11,8,8,11,0,0,0,5,3,0,0
0,0,3,6,9,0,0,12,8,8,12,0,0,9,6,3,0,0
0,0,3,7,0,0,0,11,8,8,11,0,0,0,7,3,0,0
0,0,3,3,3,3,3,3,3,3,3,3,3,3,3,3,0,0
0,0,0,0,0,0,0,0,0,0,0,0,0,0,0,0,0,0
0,0,0,0,0,0,0,0,0,0,0,0,0,0,0,0,0,0
endlayer

layer
0,0,0,0,0,0,0,0,0,0,0,0,0,0,0,0,0,0
0,0,0,0,0,0,0,0,0,0,0,0,0,0,0,0,0,0
0,0,3,8,10,8,3,10,10,3,8,10,8,10,8,3,0,0
0,0,8,15,0,0,0,0,0,0,0,0,0,0,14,8,0,0
0,0,10,0,0,0,8,0,0,8,0,0,0,0,0,10,0,0
0,0,10,0,0,0,10,0,0,10,0,0,0,0,0,10,0,0
0,0,8,0,0,14,8,13,0,8,15,0,0,0,0,8,0,0
0,0,3,8,10,8,3,0,10,3,8,8,8,10,8,3,0,0
0,0,0,0,0,0,0,0,0,0,0,0,0,0,0,0,0,0
0,0,0,0,0,0,0,0,0,0,0,0,0,0,0,0,0,0
0,0,0,0,0,0,0,0,0,0,0,0,0,0,0,0,0,0
0,0,3,8,0,8,10,8,3,3,8,10,8,0,8,3,0,0
0,0,8,14,0,0,0,0,8,8,0,0,0,0,14,8,0,0
0,0,10,0,0,0,0,0,8,8,15,0,0,0,0,10,0,0
0,0,8,0,0,0,0,15,8,8,0,0,0,0,0,8,0,0
0,0,3,8,10,8,10,8,3,3,8,10,8,10,8,3,0,0
0,0,0,0,0,0,0,0,0,0,0,0,0,0,0,0,0,0
0,0,0,0,0,0,0,0,0,0,0,0,0,0,0,0,0,0
endlayer

layer
0,0,0,0,0,0,0,0,0,0,0,0,0,0,0,0,0,0
0,0,0,0,0,0,0,0,0,0,0,0,0,0,0,0,0,0
0,0,3,8,10,8,3,10,10,3,8,10,8,10,8,3,0,0
0,0,8,0,0,0,8,0,0,8,0,0,0,0,0,8,0,0
0,0,10,0,0,0,8,0,0,8,0,0,0,0,0,10,0,0
0,0,10,0,0,0,10,0,0,10,0,0,0,0,0,10,0,0
0,0,8,0,0,0,8,13,0,8,0,0,0,0,0,8,0,0
0,0,3,8,10,8,3,10,10,3,8,8,8,10,8,3,0,0
0,0,0,0,0,0,0,0,0,0,0,0,0,0,0,0,0,0
0,0,0,0,0,0,0,0,0,0,0,0,0,0,0,0,0,0
0,0,0,0,0,0,0,0,0,0,0,0,0,0,0,0,0,0
0,0,3,8,8,8,10,8,3,3,8,10,8,8,8,3,0,0
0,0,8,0,0,0,0,0,8,8,0,0,0,0,0,8,0,0
0,0,10,0,0,0,0,0,8,8,0,0,0,0,0,10,0,0
0,0,8,0,0,0,0,0,8,8,0,0,0,0,0,8,0,0
0,0,3,8,10,8,10,8,3,3,8,10,8,10,8,3,0,0
0,0,0,0,0,0,0,0,0,0,0,0,0,0,0,0,0,0
0,0,0,0,0,0,0,0,0,0,0,0,0,0,0,0,0,0
endlayer

layer
0,0,0,0,0,0,0,0,0,0,0,0,0,0,0,0,0,0
0,0,0,0,0,0,0,0,0,0,0,0,0,0,0,0,0,0
0,0,3,8,10,8,3,10,10,3,8,10,8,10,8,3,0,0
0,0,8,0,0,0,8,0,0,8,0,0,0,0,0,8,0,0
0,0,10,0,0,0,8,0,0,8,0,0,0,0,0,10,0,0
0,0,10,0,0,0,10,0,0,10,0,0,0,0,0,10,0,0
0,0,8,0,0,0,8,13,0,8,0,0,0,0,0,8,0,0
0,0,3,8,10,8,3,10,10,3,8,8,8,10,8,3,0,0
0,0,0,0,0,0,0,0,0,0,0,0,0,0,0,0,0,0
0,0,0,0,0,0,0,0,0,0,0,0,0,0,0,0,0,0
0,0,0,0,0,0,0,0,0,0,0,0,0,0,0,0,0,0
0,0,3,8,8,8,10,8,3,3,8,10,8,8,8,3,0,0
0,0,8,0,0,0,0,0,8,8,0,0,0,0,0,8,0,0
0,0,10,0,0,0,0,0,8,8,0,0,0,0,0,10,0,0
0,0,8,0,0,0,0,0,8,8,0,0,0,0,0,8,0,0
0,0,3,8,10,8,10,8,3,3,8,10,8,10,8,3,0,0
0,0,0,0,0,0,0,0,0,0,0,0,0,0,0,0,0,0
0,0,0,0,0,0,0,0,0,0,0,0,0,0,0,0,0,0
endlayer

layer
0,0,0,0,0,0,0,0,0,0,0,0,0,0,0,0,0,0
0,0,0,0,0,0,0,0,0,0,0,0,0,0,0,0,0,0
0,0,3,8,10,8,3,10,10,3,8,10,8,10,8,3,0,0
0,0,8,0,0,0,8,0,0,8,0,0,0,0,0,8,0,0
0,0,10,0,0,0,8,0,0,8,0,0,0,0,0,10,0,0
0,0,10,0,0,0,10,0,0,10,0,0,0,0,0,10,0,0
0,0,8,0,0,0,8,13,0,8,0,0,0,0,0,8,0,0
0,0,3,8,10,8,3,10,10,3,8,8,8,10,8,3,0,0
0,0,0,0,0,0,0,0,0,0,0,0,0,0,0,0,0,0
0,0,0,0,0,0,0,0,0,0,0,0,0,0,0,0,0,0
0,0,0,0,0,0,0,0,0,0,0,0,0,0,0,0,0,0
0,0,3,8,8,8,10,8,3,3,8,10,8,8,8,3,0,0
0,0,8,0,0,0,0,0,8,8,0,0,0,0,0,8,0,0
0,0,10,0,0,0,0,0,8,8,0,0,0,0,0,10,0,0
0,0,8,0,0,0,0,0,8,8,0,0,0,0,0,8,0,0
0,0,3,8,10,8,10,8,3,3,8,10,8,10,8,3,0,0
0,0,0,0,0,0,0,0,0,0,0,0,0,0,0,0,0,0
0,0,0,0,0,0,0,0,0,0,0,0,0,0,0,0,0,0
endlayer

layer
0,0,0,0,0,0,0,0,0,0,0,0,0,0,0,0,0,0
0,0,0,0,0,0,0,0,0,0,0,0,0,0,0,0,0,0
0,0,3,3,3,3,3,3,3,3,3,3,3,3,3,3,0,0
0,0,3,2,2,2,2,2,2,2,2,2,2,2,2,3,0,0
0,0,3,2,2,2,3,2,2,3,2,2,2,2,2,3,0,0
0,0,3,2,2,2,3,2,2,3,2,2,2,2,2,3,0,0
0,0,3,2,2,2,3,13,2,3,2,2,2,2,2,3,0,0
0,0,3,3,3,3,3,2,2,3,3,3,3,3,3,3,0,0
0,0,0,2,2,2,2,2,2,2,2,2,2,2,2,0,0,0
0,0,0,2,2,2,2,2,2,2,2,2,2,2,2,0,0,0
0,0,0,2,2,2,2,2,2,2,2,2,2,2,2,0,0,0
0,0,3,3,2,3,3,3,3,3,3,3,3,2,3,3,0,0
0,0,3,2,2,2,2,2,2,2,2,2,2,2,2,3,0,0
0,0,3,2,2,2,2,2,2,2,2,2,2,2,2,3,0,0
0,0,3,2,2,2,2,2,2,2,2,2,2,2,2,3,0,0
0,0,3,3,3,3,3,3,3,3,3,3,3,3,3,3,0,0
0,0,0,0,0,0,0,0,0,0,0,0,0,0,0,0,0,0
0,0,0,0,0,0,0,0,0,0,0,0,0,0,0,0,0,0
endlayer

layer
0,0,0,0,0,0,0,0,0,0,0,0,0,0,0,0,0,0
0,0,0,0,0,0,0,0,0,0,0,0,0,0,0,0,0,0
0,0,3,8,10,8,3,10,10,3,8,10,8,10,8,3,0,0
0,0,8,7,0,0,0,0,0,0,0,0,0,0,7,8,0,0
0,0,10,0,0,0,8,0,0,8,11,0,0,9,6,10,0,0
0,0,10,0,9,0,10,0,0,10,12,0,0,0,5,10,0,0
0,0,8,5,6,5,8,13,0,8,11,0,0,0,0,8,0,0
0,0,3,8,10,8,3,0,10,3,8,10,8,10,8,3,0,0
0,0,0,0,0,0,0,0,0,0,0,0,0,0,0,0,0,0
0,0,0,0,0,0,0,0,0,0,0,0,0,0,0,0,0,0
0,0,0,0,0,0,0,0,0,0,0,0,0,0,0,0,0,0
0,0,3,8,0,8,10,8,3,3,8,10,8,0,8,3,0,0
0,0,8,5,0,0,0,11,8,8,11,0,0,0,5,8,0,0
0,0,10,6,9,0,0,12,8,8,12,0,0,9,6,10,0,0
0,0,8,7,0,0,0,11,8,8,11,0,0,0,7,8,0,0
0,0,3,8,10,8,10,8,3,3,8,10,8,10,8,3,0,0
0,0,0,0,0,0,0,0,0,0,0,0,0,0,0,0,0,0
0,0,0,0,0,0,0,0,0,0,0,0,0,0,0,0,0,0
endlayer

layer
0,0,0,0,0,0,0,0,0,0,0,0,0,0,0,0,0,0
0,0,0,0,0,0,0,0,0,0,0,0,0,0,0,0,0,0
0,0,3,8,10,8,3,10,10,3,8,10,8,10,8,3,0,0
0,0,8,15,0,0,0,0,0,0,0,0,0,0,0,8,0,0
0,0,10,0,0,0,8,0,0,8,0,0,0,0,0,10,0,0
0,0,10,0,0,0,10,0,0,10,0,0,0,0,14,10,0,0
0,0,8,14,0,0,8,13,0,8,15,0,0,0,0,8,0,0
0,0,3,8,10,8,3,0,10,3,8,10,8,10,8,3,0,0
0,0,0,0,0,0,0,0,0,0,0,0,0,0,0,0,0,0
0,0,0,0,0,0,0,0,0,0,0,0,0,0,0,0,0,0
0,0,0,0,0,0,0,0,0,0,0,0,0,0,0,0,0,0
0,0,3,8,0,8,10,8,3,3,8,10,8,0,8,3,0,0
0,0,8,0,0,0,0,0,8,8,0,0,0,0,0,8,0,0
0,0,10,0,0,0,0,0,8,8,0,0,0,0,0,10,0,0
0,0,8,17,0,0,0,0,8,8,0,0,0,0,17,8,0,0
0,0,3,8,10,8,10,8,3,3,8,10,8,10,8,3,0,0
0,0,0,0,0,0,0,0,0,0,0,0,0,0,0,0,0,0
0,0,0,0,0,0,0,0,0,0,0,0,0,0,0,0,0,0
endlayer

layer
0,0,0,0,0,0,0,0,0,0,0,0,0,0,0,0,0,0
0,0,0,0,0,0,0,0,0,0,0,0,0,0,0,0,0,0
0,0,3,8,10,8,3,10,10,3,8,10,8,10,8,3,0,0
0,0,8,0,0,0,8,0,0,8,0,0,0,0,0,8,0,0
0,0,10,0,0,0,8,0,0,8,0,0,0,0,0,10,0,0
0,0,10,0,0,0,10,0,0,10,0,0,0,0,0,10,0,0
0,0,8,0,0,0,8,13,0,8,0,0,0,0,0,8,0,0
0,0,3,8,10,8,3,10,10,3,8,10,8,10,8,3,0,0
0,0,0,0,0,0,0,0,0,0,0,0,0,0,0,0,0,0
0,0,0,0,0,0,0,0,0,0,0,0,0,0,0,0,0,0
0,0,0,0,0,0,0,0,0,0,0,0,0,0,0,0,0,0
0,0,3,8,8,8,10,8,3,3,8,10,8,8,8,3,0,0
0,0,8,0,0,0,0,0,8,8,0,0,0,0,0,8,0,0
0,0,10,0,0,0,0,0,8,8,0,0,0,0,0,10,0,0
0,0,8,0,0,0,0,0,8,8,0,0,0,0,0,8,0,0
0,0,3,8,10,8,10,8,3,3,8,10,8,10,8,3,0,0
0,0,0,0,0,0,0,0,0,0,0,0,0,0,0,0,0,0
0,0,0,0,0,0,0,0,0,0,0,0,0,0,0,0,0,0
endlayer

layer
0,0,0,0,0,0,0,0,0,0,0,0,0,0,0,0,0,0
0,0,0,0,0,0,0,0,0,0,0,0,0,0,0,0,0,0
0,0,3,8,10,8,3,10,10,3,8,10,8,10,8,3,0,0
0,0,8,0,0,0,8,0,0,8,0,0,0,0,0,8,0,0
0,0,10,0,0,0,8,0,0,8,0,0,0,0,0,10,0,0
0,0,10,0,0,0,10,0,0,10,0,0,0,0,0,10,0,0
0,0,8,0,0,0,8,13,0,8,0,0,0,0,0,8,0,0
0,0,3,8,10,8,3,10,10,3,8,10,8,10,8,3,0,0
0,0,0,0,0,0,0,0,0,0,0,0,0,0,0,0,0,0
0,0,0,0,0,0,0,0,0,0,0,0,0,0,0,0,0,0
0,0,0,0,0,0,0,0,0,0,0,0,0,0,0,0,0,0
0,0,3,8,8,8,10,8,3,3,8,10,8,8,8,3,0,0
0,0,8,0,0,0,0,0,8,8,0,0,0,0,0,8,0,0
0,0,10,0,0,0,0,0,8,8,0,0,0,0,0,10,0,0
0,0,8,0,0,0,0,0,8,8,0,0,0,0,0,8,0,0
0,0,3,8,10,8,10,8,3,3,8,10,8,10,8,3,0,0
0,0,0,0,0,0,0,0,0,0,0,0,0,0,0,0,0,0
0,0,0,0,0,0,0,0,0,0,0,0,0,0,0,0,0,0
endlayer

layer
0,0,0,0,0,0,0,0,0,0,0,0,0,0,0,0,0,0
0,0,0,0,0,0,0,0,0,0,0,0,0,0,0,0,0,0
0,0,3,3,3,3,3,3,3,3,3,3,3,3,3,3,0,0
0,0,3,2,2,2,2,2,2,2,2,2,2,2,2,3,0,0
0,0,3,2,2,2,3,2,2,3,2,2,2,2,2,3,0,0
0,0,3,2,2,2,3,2,2,3,2,2,2,2,2,3,0,0
0,0,3,2,2,2,3,13,2,3,2,2,2,2,2,3,0,0
0,0,3,3,3,3,3,3,3,3,3,3,3,3,3,3,0,0
0,0,0,0,0,0,0,0,0,0,0,0,0,0,0,0,0,0
0,0,0,0,0,0,0,0,0,0,0,0,0,0,0,0,0,0
0,0,0,0,0,0,0,0,0,0,0,0,0,0,0,0,0,0
0,0,3,3,3,3,3,3,3,3,3,3,3,3,3,3,0,0
0,0,3,16,16,16,16,16,16,16,16,16,16,16,16,3,0,0
0,0,3,16,16,16,16,16,16,16,16,16,16,16,16,3,0,0
0,0,3,16,16,16,16,16,16,16,16,16,16,16,16,3,0,0
0,0,3,3,3,3,3,3,3,3,3,3,3,3,3,3,0,0
0,0,0,0,0,0,0,0,0,0,0,0,0,0,0,0,0,0
0,0,0,0,0,0,0,0,0,0,0,0,0,0,0,0,0,0
endlayer

layer
0,0,0,0,0,0,0,0,0,0,0,0,0,0,0,0,0,0
0,0,0,0,0,0,0,0,0,0,0,0,0,0,0,0,0,0
0,0,3,8,10,8,3,10,10,3,8,10,8,10,8,3,0,0
0,0,8,7,0,0,0,0,0,0,0,0,0,0,7,8,0,0
0,0,10,0,0,0,8,0,0,8,11,0,0,9,6,10,0,0
0,0,10,0,9,0,10,0,0,10,12,0,0,0,5,10,0,0
0,0,8,7,6,5,8,13,0,8,11,0,0,0,6,8,0,0
0,0,3,8,10,8,3,10,10,3,8,10,8,10,8,3,0,0
0,0,0,0,0,0,0,0,0,0,0,0,0,0,0,0,0,0
0,0,0,0,0,0,0,0,0,0,0,0,0,0,0,0,0,0
0,0,0,0,0,0,0,0,0,0,0,0,0,0,0,0,0,0
0,0,0,0,0,0,0,0,0,0,0,0,0,0,0,0,0,0
0,0,0,0,0,0,0,0,0,0,0,0,0,0,0,0,0,0
0,0,0,0,0,0,0,0,0,0,0,0,0,0,0,0,0,0
0,0,0,0,0,0,0,0,0,0,0,0,0,0,0,0,0,0
0,0,0,0,0,0,0,0,0,0,0,0,0,0,0,0,0,0
0,0,0,0,0,0,0,0,0,0,0,0,0,0,0,0,0,0
0,0,0,0,0,0,0,0,0,0,0,0,0,0,0,0,0,0
endlayer

layer
0,0,0,0,0,0,0,0,0,0,0,0,0,0,0,0,0,0
0,0,0,0,0,0,0,0,0,0,0,0,0,0,0,0,0,0
0,0,3,8,10,8,3,10,10,3,8,10,8,10,8,3,0,0
0,0,8,15,0,0,0,0,0,0,0,0,0,0,0,8,0,0
0,0,10,0,0,0,8,0,0,8,0,0,0,0,0,10,0,0
0,0,10,0,0,0,10,0,0,10,15,0,0,0,14,10,0,0
0,0,8,0,0,14,8,13,0,8,0,0,0,0,0,8,0,0
0,0,3,8,10,8,3,10,10,3,8,10,8,10,8,3,0,0
0,0,0,0,0,0,0,0,0,0,0,0,0,0,0,0,0,0
0,0,0,0,0,0,0,0,0,0,0,0,0,0,0,0,0,0
0,0,0,0,0,0,0,0,0,0,0,0,0,0,0,0,0,0
0,0,0,0,0,0,0,0,0,0,0,0,0,0,0,0,0,0
0,0,0,0,0,0,0,0,0,0,0,0,0,0,0,0,0,0
0,0,0,0,0,0,0,0,0,0,0,0,0,0,0,0,0,0
0,0,0,0,0,0,0,0,0,0,0,0,0,0,0,0,0,0
0,0,0,0,0,0,0,0,0,0,0,0,0,0,0,0,0,0
0,0,0,0,0,0,0,0,0,0,0,0,0,0,0,0,0,0
0,0,0,0,0,0,0,0,0,0,0,0,0,0,0,0,0,0
endlayer

layer
0,0,0,0,0,0,0,0,0,0,0,0,0,0,0,0,0,0
0,0,0,0,0,0,0,0,0,0,0,0,0,0,0,0,0,0
0,0,3,8,10,8,3,10,10,3,8,10,8,10,8,3,0,0
0,0,8,0,0,0,8,0,0,0,0,0,0,0,0,8,0,0
0,0,10,0,0,0,8,0,0,8,0,0,0,0,0,10,0,0
0,0,10,0,0,0,10,0,0,10,0,0,0,0,0,10,0,0
0,0,8,0,0,0,8,13,0,8,0,0,0,0,0,8,0,0
0,0,3,8,10,8,3,10,10,3,8,10,8,10,8,3,0,0
0,0,0,0,0,0,0,0,0,0,0,0,0,0,0,0,0,0
0,0,0,0,0,0,0,0,0,0,0,0,0,0,0,0,0,0
0,0,0,0,0,0,0,0,0,0,0,0,0,0,0,0,0,0
0,0,0,0,0,0,0,0,0,0,0,0,0,0,0,0,0,0
0,0,0,0,0,0,0,0,0,0,0,0,0,0,0,0,0,0
0,0,0,0,0,0,0,0,0,0,0,0,0,0,0,0,0,0
0,0,0,0,0,0,0,0,0,0,0,0,0,0,0,0,0,0
0,0,0,0,0,0,0,0,0,0,0,0,0,0,0,0,0,0
0,0,0,0,0,0,0,0,0,0,0,0,0,0,0,0,0,0
0,0,0,0,0,0,0,0,0,0,0,0,0,0,0,0,0,0
endlayer

layer
0,0,0,0,0,0,0,0,0,0,0,0,0,0,0,0,0,0
0,0,0,0,0,0,0,0,0,0,0,0,0,0,0,0,0,0
0,0,3,8,10,8,3,10,10,3,8,10,8,10,8,3,0,0
0,0,8,0,0,0,8,0,0,0,0,0,0,0,0,8,0,0
0,0,10,0,0,0,8,0,0,8,0,0,0,0,0,10,0,0
0,0,10,0,0,0,10,0,0,10,0,0,0,0,0,10,0,0
0,0,8,0,0,0,8,13,0,8,0,0,0,0,0,8,0,0
0,0,3,8,10,8,3,10,10,3,8,10,8,10,8,3,0,0
0,0,0,0,0,0,0,0,0,0,0,0,0,0,0,0,0,0
0,0,0,0,0,0,0,0,0,0,0,0,0,0,0,0,0,0
0,0,0,0,0,0,0,0,0,0,0,0,0,0,0,0,0,0
0,0,0,0,0,0,0,0,0,0,0,0,0,0,0,0,0,0
0,0,0,0,0,0,0,0,0,0,0,0,0,0,0,0,0,0
0,0,0,0,0,0,0,0,0,0,0,0,0,0,0,0,0,0
0,0,0,0,0,0,0,0,0,0,0,0,0,0,0,0,0,0
0,0,0,0,0,0,0,0,0,0,0,0,0,0,0,0,0,0
0,0,0,0,0,0,0,0,0,0,0,0,0,0,0,0,0,0
0,0,0,0,0,0,0,0,0,0,0,0,0,0,0,0,0,0
endlayer

layer
0,0,0,0,0,0,0,0,0,0,0,0,0,0,0,0,0,0
0,0,0,0,0,0,0,0,0,0,0,0,0,0,0,0,0,0
0,0,3,3,3,3,3,3,3,3,3,3,3,3,3,3,0,0
0,0,3,2,2,2,2,2,2,2,2,2,2,2,2,3,0,0
0,0,3,2,2,2,3,2,2,3,2,2,2,2,2,3,0,0
0,0,3,2,2,2,3,2,2,3,2,2,2,2,2,3,0,0
0,0,3,2,2,2,3,13,2,3,2,2,2,2,2,3,0,0
0,0,3,3,3,3,3,3,3,3,3,3,3,3,3,3,0,0
0,0,0,0,0,0,0,0,0,0,0,0,0,0,0,0,0,0
0,0,0,0,0,0,0,0,0,0,0,0,0,0,0,0,0,0
0,0,0,0,0,0,0,0,0,0,0,0,0,0,0,0,0,0
0,0,0,0,0,0,0,0,0,0,0,0,0,0,0,0,0,0
0,0,0,0,0,0,0,0,0,0,0,0,0,0,0,0,0,0
0,0,0,0,0,0,0,0,0,0,0,0,0,0,0,0,0,0
0,0,0,0,0,0,0,0,0,0,0,0,0,0,0,0,0,0
0,0,0,0,0,0,0,0,0,0,0,0,0,0,0,0,0,0
0,0,0,0,0,0,0,0,0,0,0,0,0,0,0,0,0,0
0,0,0,0,0,0,0,0,0,0,0,0,0,0,0,0,0,0
endlayer

layer
0,0,0,0,0,0,0,0,0,0,0,0,0,0,0,0,0,0
0,0,0,0,0,0,0,0,0,0,0,0,0,0,0,0,0,0
0,0,3,8,10,8,3,10,10,3,8,10,8,10,8,3,0,0
0,0,8,12,0,0,0,0,0,0,0,0,0,0,5,8,0,0
0,0,10,0,0,0,8,0,0,8,11,0,0,9,6,10,0,0
0,0,10,0,9,0,10,0,0,10,12,0,0,0,5,10,0,0
0,0,8,17,6,5,8,13,0,8,11,0,0,0,17,8,0,0
0,0,3,8,10,8,3,10,10,3,8,10,8,10,8,3,0,0
0,0,0,0,0,0,0,0,0,0,0,0,0,0,0,0,0,0
0,0,0,0,0,0,0,0,0,0,0,0,0,0,0,0,0,0
0,0,0,0,0,0,0,0,0,0,0,0,0,0,0,0,0,0
0,0,0,0,0,0,0,0,0,0,0,0,0,0,0,0,0,0
0,0,0,0,0,0,0,0,0,0,0,0,0,0,0,0,0,0
0,0,0,0,0,0,0,0,0,0,0,0,0,0,0,0,0,0
0,0,0,0,0,0,0,0,0,0,0,0,0,0,0,0,0,0
0,0,0,0,0,0,0,0,0,0,0,0,0,0,0,0,0,0
0,0,0,0,0,0,0,0,0,0,0,0,0,0,0,0,0,0
0,0,0,0,0,0,0,0,0,0,0,0,0,0,0,0,0,0
endlayer

layer
0,0,0,0,0,0,0,0,0,0,0,0,0,0,0,0,0,0
0,0,0,0,0,0,0,0,0,0,0,0,0,0,0,0,0,0
0,0,3,8,10,8,3,10,10,3,8,10,8,10,8,3,0,0
0,0,8,15,0,0,0,0,0,0,0,0,0,0,14,8,0,0
0,0,10,0,0,0,8,0,0,8,15,0,0,0,0,10,0,0
0,0,10,0,0,0,10,0,0,10,0,0,0,0,0,10,0,0
0,0,8,0,0,14,8,13,0,8,0,0,0,0,0,8,0,0
0,0,3,8,10,8,3,10,10,3,8,10,8,10,8,3,0,0
0,0,0,0,0,0,0,0,0,0,0,0,0,0,0,0,0,0
0,0,0,0,0,0,0,0,0,0,0,0,0,0,0,0,0,0
0,0,0,0,0,0,0,0,0,0,0,0,0,0,0,0,0,0
0,0,0,0,0,0,0,0,0,0,0,0,0,0,0,0,0,0
0,0,0,0,0,0,0,0,0,0,0,0,0,0,0,0,0,0
0,0,0,0,0,0,0,0,0,0,0,0,0,0,0,0,0,0
0,0,0,0,0,0,0,0,0,0,0,0,0,0,0,0,0,0
0,0,0,0,0,0,0,0,0,0,0,0,0,0,0,0,0,0
0,0,0,0,0,0,0,0,0,0,0,0,0,0,0,0,0,0
0,0,0,0,0,0,0,0,0,0,0,0,0,0,0,0,0,0
endlayer

layer
0,0,0,0,0,0,0,0,0,0,0,0,0,0,0,0,0,0
0,0,0,0,0,0,0,0,0,0,0,0,0,0,0,0,0,0
0,0,3,8,10,8,3,10,10,3,8,10,8,10,8,3,0,0
0,0,8,0,0,0,8,0,0,0,0,0,0,0,0,8,0,0
0,0,10,0,0,0,8,0,0,8,0,0,0,0,0,10,0,0
0,0,10,0,0,0,10,0,0,10,0,0,0,0,0,10,0,0
0,0,8,0,0,0,8,0,0,8,0,0,0,0,0,8,0,0
0,0,3,8,10,8,3,10,10,3,8,10,8,10,8,3,0,0
0,0,0,0,0,0,0,0,0,0,0,0,0,0,0,0,0,0
0,0,0,0,0,0,0,0,0,0,0,0,0,0,0,0,0,0
0,0,0,0,0,0,0,0,0,0,0,0,0,0,0,0,0,0
0,0,0,0,0,0,0,0,0,0,0,0,0,0,0,0,0,0
0,0,0,0,0,0,0,0,0,0,0,0,0,0,0,0,0,0
0,0,0,0,0,0,0,0,0,0,0,0,0,0,0,0,0,0
0,0,0,0,0,0,0,0,0,0,0,0,0,0,0,0,0,0
0,0,0,0,0,0,0,0,0,0,0,0,0,0,0,0,0,0
0,0,0,0,0,0,0,0,0,0,0,0,0,0,0,0,0,0
0,0,0,0,0,0,0,0,0,0,0,0,0,0,0,0,0,0
endlayer

layer
0,0,0,0,0,0,0,0,0,0,0,0,0,0,0,0,0,0
0,0,0,0,0,0,0,0,0,0,0,0,0,0,0,0,0,0
0,0,3,8,10,8,3,10,10,3,8,10,8,10,8,3,0,0
0,0,8,0,0,0,8,0,0,0,0,0,0,0,0,8,0,0
0,0,10,0,0,0,8,0,0,8,0,0,0,0,0,10,0,0
0,0,10,0,0,0,10,0,0,10,0,0,0,0,0,10,0,0
0,0,8,0,0,0,8,0,0,8,0,0,0,0,0,8,0,0
0,0,3,8,10,8,3,10,10,3,8,10,8,10,8,3,0,0
0,0,0,0,0,0,0,0,0,0,0,0,0,0,0,0,0,0
0,0,0,0,0,0,0,0,0,0,0,0,0,0,0,0,0,0
0,0,0,0,0,0,0,0,0,0,0,0,0,0,0,0,0,0
0,0,0,0,0,0,0,0,0,0,0,0,0,0,0,0,0,0
0,0,0,0,0,0,0,0,0,0,0,0,0,0,0,0,0,0
0,0,0,0,0,0,0,0,0,0,0,0,0,0,0,0,0,0
0,0,0,0,0,0,0,0,0,0,0,0,0,0,0,0,0,0
0,0,0,0,0,0,0,0,0,0,0,0,0,0,0,0,0,0
0,0,0,0,0,0,0,0,0,0,0,0,0,0,0,0,0,0
0,0,0,0,0,0,0,0,0,0,0,0,0,0,0,0,0,0
endlayer

layer
0,0,0,0,0,0,0,0,0,0,0,0,0,0,0,0,0,0
0,0,0,0,0,0,0,0,0,0,0,0,0,0,0,0,0,0
0,0,3,3,3,3,3,3,3,3,3,3,3,3,3,3,0,0
0,0,3,16,16,16,3,16,16,3,16,16,16,16,16,3,0,0
0,0,3,16,16,16,3,16,16,3,16,16,16,16,16,3,0,0
0,0,3,16,16,16,3,16,16,3,16,16,16,16,16,3,0,0
0,0,3,16,16,16,3,16,16,3,16,16,16,16,16,3,0,0
0,0,3,3,3,3,3,3,3,3,3,3,3,3,3,3,0,0
0,0,0,0,0,0,0,0,0,0,0,0,0,0,0,0,0,0
0,0,0,0,0,0,0,0,0,0,0,0,0,0,0,0,0,0
0,0,0,0,0,0,0,0,0,0,0,0,0,0,0,0,0,0
0,0,0,0,0,0,0,0,0,0,0,0,0,0,0,0,0,0
0,0,0,0,0,0,0,0,0,0,0,0,0,0,0,0,0,0
0,0,0,0,0,0,0,0,0,0,0,0,0,0,0,0,0,0
0,0,0,0,0,0,0,0,0,0,0,0,0,0,0,0,0,0
0,0,0,0,0,0,0,0,0,0,0,0,0,0,0,0,0,0
0,0,0,0,0,0,0,0,0,0,0,0,0,0,0,0,0,0
0,0,0,0,0,0,0,0,0,0,0,0,0,0,0,0,0,0
endlayer

