# Converted from schematic
# THIS TEMPLATE USES DEFAULTS!  Please edit for corrections.
# If you need help, consult template_rules.txt

weight=5
embed_into_distance=5
acceptable_target_blocks=1,2,3,12,13,250
dimensions=22,18,18
allowable_overhang=0
max_cut_in=2
cut_in_buffer=1
max_leveling=2
leveling_buffer=1
preserve_water=0
preserve_lava=0
preserve_plants=0


rule1=0,100,3134-10
rule2=0,100,2843-4
rule3=0,100,2843-14,2843-14,2843-14,2843-14,2843
rule4=0,100,622,2838-4,2838-4,2838-4,2838-4,2838-4,2838-4,2838-4,2838-4,2838-4
rule5=0,100,300
rule6=0,100,2245-0,2245-1,2245-2,2245-3,
rule7=0,100,2013
rule8=0,50,308,308,308,308,308,308,313,313,314,327
rule9=0,95,2835-2,2835-2,2835-2,2835-2,2835-2,2835-2,2835-2,2835-1,2835-1,2835-0
rule10=0,100,2013-1,2013-2,2013-3,2013-4,2013-5,2013-6,2013-7,2013-8,2013-9,2013-10,2013-11,2013-12,2013-13,2013-14,2013-15
rule11=0,25,3225-3
rule12=0,100,5
rule13=0,100,126-8
rule14=0,66,623
rule15=1,10,2244-0,2244-1,2244-2,2244-3,2244-4,2244-5,2244-6,2244-7,2244-8,2244-9,2244-10,2244-11,2244-12,2244-13,2244-14,2244-15
rule16=0,25,311
rule17=0,95,300
rule18=0,100,54
rule19=0,100,3134,3134,3134,3134-8,3134-2


layer
1,1,1,1,1,1,1,1,1,1,1,1,1,1,1,1,1,1
1,1,1,1,1,1,1,1,1,1,1,1,1,1,1,1,1,1
1,1,1,1,1,1,1,1,1,1,1,1,1,1,1,1,1,1
1,1,1,2,2,2,2,2,2,2,2,2,2,2,2,1,1,1
1,1,1,2,2,2,2,2,2,2,2,2,2,2,2,1,1,1
1,1,1,2,2,2,2,2,2,2,2,2,2,2,2,1,1,1
1,1,1,2,2,2,2,4,2,2,2,2,2,2,2,1,1,1
1,1,1,2,2,2,3,2,2,3,2,2,2,2,2,1,1,1
1,1,1,1,1,1,1,1,1,1,1,1,1,1,1,1,1,1
1,1,1,1,1,1,1,1,1,1,1,1,1,1,1,1,1,1
1,1,1,1,1,1,1,1,1,1,1,1,1,1,1,1,1,1
1,1,1,2,2,2,2,2,2,2,2,2,2,2,2,1,1,1
1,1,1,2,2,2,2,2,2,2,2,2,2,2,2,1,1,1
1,1,1,2,2,2,2,2,2,2,2,2,2,2,2,1,1,1
1,1,1,2,2,2,2,2,2,2,2,2,2,2,2,1,1,1
1,1,1,1,1,1,1,1,1,1,1,1,1,1,1,1,1,1
1,1,1,1,1,1,1,1,1,1,1,1,1,1,1,1,1,1
1,1,1,1,1,1,1,1,1,1,1,1,1,1,1,1,1,1
endlayer

layer
5,5,5,5,5,5,5,5,5,5,5,5,5,5,5,5,5,5
5,5,5,5,5,5,5,5,5,5,5,5,5,5,5,5,5,5
5,5,3,3,3,3,3,3,3,3,3,3,3,3,3,3,5,5
5,5,3,13,0,0,0,0,0,0,0,0,0,0,6,3,5,5
5,5,3,0,0,0,9,0,0,9,12,0,0,10,7,3,5,5
5,5,3,0,10,0,11,0,0,11,13,0,0,0,6,3,5,5
5,5,3,8,7,6,9,14,0,9,12,0,0,0,8,3,5,5
5,5,3,9,11,9,3,0,11,3,9,9,9,11,9,3,5,5
5,5,5,5,5,5,0,0,0,0,0,5,5,5,5,5,5,5
5,5,5,5,5,5,5,0,0,0,0,0,5,5,5,5,5,5
5,5,5,5,5,5,0,0,0,0,0,0,0,5,5,5,5,5
5,5,3,9,5,9,11,9,3,3,9,11,9,5,9,3,5,5
5,5,3,6,5,0,0,12,9,9,12,0,5,5,6,3,5,5
5,5,3,7,10,0,0,13,9,9,13,5,0,10,7,3,5,5
5,5,3,8,0,0,0,12,9,9,12,5,0,0,8,3,5,5
5,5,3,3,3,3,3,3,3,3,3,3,3,3,3,3,5,5
5,5,5,5,5,5,5,5,5,5,5,5,5,5,5,5,5,5
5,5,5,5,5,5,5,5,5,5,5,5,5,5,5,5,5,5
endlayer

layer
5,5,5,5,5,5,5,5,5,5,5,5,5,5,5,5,5,5
5,5,5,5,5,5,5,5,5,5,5,5,5,5,5,5,5,5
5,5,3,9,11,9,3,11,11,3,9,11,9,11,9,3,5,5
5,5,9,16,0,0,0,0,0,0,0,0,0,0,15,9,5,5
5,5,11,0,0,0,9,0,0,9,0,0,0,0,0,11,5,5
5,5,11,0,0,0,11,0,0,11,0,0,0,0,0,11,5,5
5,5,9,0,0,15,9,14,0,9,16,0,0,0,0,9,5,5
5,5,3,9,11,9,3,0,11,3,9,9,9,11,9,3,5,5
5,5,5,0,0,0,0,0,0,0,0,0,0,5,5,5,5,5
5,5,5,5,5,0,0,0,0,0,0,0,0,5,5,5,5,5
5,5,5,5,0,0,0,0,0,0,0,0,0,0,5,5,5,5
5,5,3,9,5,9,11,9,3,3,9,11,9,0,9,3,5,5
5,5,9,15,0,0,0,0,9,9,0,0,0,0,15,9,5,5
5,5,11,0,0,0,0,0,9,9,16,0,0,0,0,11,5,5
5,5,9,0,0,0,0,16,9,9,0,0,0,0,0,9,5,5
5,5,3,9,11,9,11,9,3,3,9,11,9,11,9,3,5,5
5,5,5,5,5,5,5,5,5,5,5,5,5,5,5,5,5,5
5,5,5,5,5,5,5,5,5,5,5,5,5,5,5,5,5,5
endlayer

layer
5,5,5,5,5,5,5,5,5,5,5,5,5,5,5,5,5,5
5,5,5,5,5,5,5,5,5,5,5,5,5,5,5,5,5,5
5,5,3,9,11,9,3,11,11,3,9,11,9,11,9,3,5,5
5,5,9,0,0,0,9,0,0,9,0,0,0,0,0,9,5,5
5,5,11,0,0,0,9,0,0,9,0,0,0,0,0,11,5,5
5,5,11,0,0,0,11,0,0,11,0,0,0,0,0,11,5,5
5,5,9,0,0,0,9,14,0,9,0,0,0,0,0,9,5,5
5,5,3,9,11,9,3,11,11,3,9,9,9,11,9,3,5,5
5,5,0,0,0,0,0,0,0,0,0,0,0,0,5,5,5,5
5,5,0,0,0,0,0,0,0,0,0,0,0,0,0,5,5,5
5,5,5,0,0,0,0,0,0,0,0,0,0,0,0,0,5,5
5,5,3,9,9,9,11,9,3,3,9,11,9,9,9,3,5,5
5,5,9,0,0,0,0,0,9,9,0,0,0,0,0,9,5,5
5,5,11,0,0,0,0,0,9,9,0,0,0,0,0,11,5,5
5,5,9,0,0,0,0,0,9,9,0,0,0,0,0,9,5,5
5,5,3,9,11,9,11,9,3,3,9,11,9,11,9,3,5,5
5,5,5,5,5,5,5,5,5,5,5,5,5,5,5,5,5,5
5,5,5,5,5,5,5,5,5,5,5,5,5,5,5,5,5,5
endlayer

layer
17,17,17,17,17,17,17,17,17,17,17,17,17,17,17,17,17,17
17,17,17,17,17,17,17,17,17,17,17,17,17,17,17,17,17,17
17,17,3,9,11,9,3,11,11,3,9,11,9,11,9,3,17,17
17,17,9,0,0,0,9,0,0,9,0,0,0,0,0,9,17,17
17,17,11,0,0,0,9,0,0,9,0,0,0,0,0,11,17,17
17,17,11,0,0,0,11,0,0,11,0,0,0,0,0,11,17,17
17,17,9,0,0,0,9,14,0,9,0,0,0,0,0,9,17,17
17,17,3,9,11,9,3,11,11,3,9,9,9,11,9,3,17,17
17,17,0,0,0,0,0,0,0,0,0,0,0,0,0,17,17,17
17,0,0,0,0,0,0,0,0,0,0,0,0,0,0,0,17,17
17,17,0,0,0,0,0,0,0,0,0,0,0,0,0,0,0,17
17,17,3,9,9,9,11,9,3,3,9,11,9,9,9,3,17,17
17,17,9,0,0,0,0,0,9,9,0,0,0,0,0,9,17,17
17,17,11,0,0,0,0,0,9,9,0,0,0,0,0,11,17,17
17,17,9,0,0,0,0,0,9,9,0,0,0,0,0,9,17,17
17,17,3,9,11,9,11,9,3,3,9,11,9,11,9,3,17,17
17,17,17,17,17,17,17,17,17,17,17,17,17,17,17,17,17,17
17,17,17,17,17,17,17,17,17,17,17,17,17,17,17,17,17,17
endlayer

layer
0,0,0,0,0,0,0,0,0,0,0,0,0,0,0,0,0,0
0,0,0,0,0,0,0,0,0,0,0,0,0,0,0,0,0,0
0,0,3,9,11,9,3,11,11,3,9,11,9,11,9,3,0,0
0,0,9,0,0,0,9,0,0,9,0,0,0,0,0,9,0,0
0,0,11,0,0,0,9,0,0,9,0,0,0,0,0,11,0,0
0,0,11,0,0,0,11,0,0,11,0,0,0,0,0,11,0,0
0,0,9,0,0,0,9,14,0,9,0,0,0,0,0,9,0,0
0,0,3,9,11,9,3,11,11,3,9,9,9,11,9,3,0,0
0,0,0,0,0,0,0,0,0,0,0,0,0,0,0,0,0,0
0,0,0,0,0,0,0,0,0,0,0,0,0,0,0,0,0,0
0,0,0,0,0,0,0,0,0,0,0,0,0,0,0,0,0,0
0,0,3,9,9,9,11,9,3,3,9,11,9,9,9,3,0,0
0,0,9,0,0,0,0,0,9,9,0,0,0,0,0,9,0,0
0,0,11,0,0,0,0,0,9,9,0,0,0,0,0,11,0,0
0,0,9,0,0,0,0,0,9,9,0,0,0,0,0,9,0,0
0,0,3,9,11,9,11,9,3,3,9,11,9,11,9,3,0,0
0,0,0,0,0,0,0,0,0,0,0,0,0,0,0,0,0,0
0,0,0,0,0,0,0,0,0,0,0,0,0,0,0,0,0,0
endlayer

layer
0,0,0,0,0,0,0,0,0,0,0,0,0,0,0,0,0,0
0,0,0,0,0,0,0,0,0,0,0,0,0,0,0,0,0,0
0,0,3,3,3,3,3,3,3,3,3,3,3,3,3,3,0,0
0,0,3,2,2,2,2,2,2,2,2,2,2,2,2,3,0,0
0,0,3,2,2,2,3,2,2,3,2,2,2,2,2,3,0,0
0,0,3,2,2,2,3,2,2,3,2,2,2,2,2,3,0,0
0,0,3,2,2,2,3,14,2,3,2,2,2,2,2,3,0,0
0,0,3,3,3,3,3,2,2,3,3,3,3,3,3,3,0,0
0,0,0,2,2,2,2,2,2,2,2,2,2,2,2,0,0,0
0,0,0,2,2,2,2,2,2,2,2,2,2,2,2,0,0,0
0,0,0,2,2,2,2,2,2,2,2,2,2,2,2,0,0,0
0,0,3,3,2,3,3,3,3,3,3,3,3,2,3,3,0,0
0,0,3,2,2,2,2,2,2,2,2,2,2,2,2,3,0,0
0,0,3,2,2,2,2,2,2,2,2,2,2,2,2,3,0,0
0,0,3,2,2,2,2,2,2,2,2,2,2,2,2,3,0,0
0,0,3,3,3,3,3,3,3,3,3,3,3,3,3,3,0,0
0,0,0,0,0,0,0,0,0,0,0,0,0,0,0,0,0,0
0,0,0,0,0,0,0,0,0,0,0,0,0,0,0,0,0,0
endlayer

layer
0,0,0,0,0,0,0,0,0,0,0,0,0,0,0,0,0,0
0,0,0,0,0,0,0,0,0,0,0,0,0,0,0,0,0,0
0,0,3,9,11,9,3,11,11,3,9,11,9,11,9,3,0,0
0,0,9,8,0,0,0,0,0,0,0,0,0,0,8,9,0,0
0,0,11,0,0,0,9,0,0,9,12,0,0,10,7,11,0,0
0,0,11,0,10,0,11,0,0,11,13,0,0,0,6,11,0,0
0,0,9,6,7,6,9,14,0,9,12,0,0,0,0,9,0,0
0,0,3,9,11,9,3,0,11,3,9,11,9,11,9,3,0,0
0,0,0,0,0,0,0,0,0,0,0,0,0,0,0,0,0,0
0,0,0,0,0,0,0,0,0,0,0,0,0,0,0,0,0,0
0,0,0,0,0,0,0,0,0,0,0,0,0,0,0,0,0,0
0,0,3,9,0,9,11,9,3,3,9,11,9,0,9,3,0,0
0,0,9,6,0,0,0,12,9,9,12,0,0,0,6,9,0,0
0,0,11,7,10,0,0,13,9,9,13,0,0,10,7,11,0,0
0,0,9,8,0,0,0,12,9,9,12,0,0,0,8,9,0,0
0,0,3,9,11,9,11,9,3,3,9,11,9,11,9,3,0,0
0,0,0,0,0,0,0,0,0,0,0,0,0,0,0,0,0,0
0,0,0,0,0,0,0,0,0,0,0,0,0,0,0,0,0,0
endlayer

layer
0,0,0,0,0,0,0,0,0,0,0,0,0,0,0,0,0,0
0,0,0,0,0,0,0,0,0,0,0,0,0,0,0,0,0,0
0,0,3,9,11,9,3,11,11,3,9,11,9,11,9,3,0,0
0,0,9,16,0,0,0,0,0,0,0,0,0,0,0,9,0,0
0,0,11,0,0,0,9,0,0,9,0,0,0,0,0,11,0,0
0,0,11,0,0,0,11,0,0,11,0,0,0,0,15,11,0,0
0,0,9,15,0,0,9,14,0,9,16,0,0,0,0,9,0,0
0,0,3,9,11,9,3,0,11,3,9,11,9,11,9,3,0,0
0,0,0,0,0,0,0,0,0,0,0,0,0,0,0,0,0,0
0,0,0,0,0,0,0,0,0,0,0,0,0,0,0,0,0,0
0,0,0,0,0,0,0,0,0,0,0,0,0,0,0,0,0,0
0,0,3,9,0,9,11,9,3,3,9,11,9,0,9,3,0,0
0,0,9,0,0,0,0,0,9,9,0,0,0,0,0,9,0,0
0,0,11,0,0,0,0,0,9,9,0,0,0,0,0,11,0,0
0,0,9,18,0,0,0,0,9,9,0,0,0,0,18,9,0,0
0,0,3,9,11,9,11,9,3,3,9,11,9,11,9,3,0,0
0,0,0,0,0,0,0,0,0,0,0,0,0,0,0,0,0,0
0,0,0,0,0,0,0,0,0,0,0,0,0,0,0,0,0,0
endlayer

layer
0,0,0,0,0,0,0,0,0,0,0,0,0,0,0,0,0,0
0,0,0,0,0,0,0,0,0,0,0,0,0,0,0,0,0,0
0,0,3,9,11,9,3,11,11,3,9,11,9,11,9,3,0,0
0,0,9,0,0,0,9,0,0,9,0,0,0,0,0,9,0,0
0,0,11,0,0,0,9,0,0,9,0,0,0,0,0,11,0,0
0,0,11,0,0,0,11,0,0,11,0,0,0,0,0,11,0,0
0,0,9,0,0,0,9,14,0,9,0,0,0,0,0,9,0,0
0,0,3,9,11,9,3,11,11,3,9,11,9,11,9,3,0,0
0,0,0,0,0,0,0,0,0,0,0,0,0,0,0,0,0,0
0,0,0,0,0,0,0,0,0,0,0,0,0,0,0,0,0,0
0,0,0,0,0,0,0,0,0,0,0,0,0,0,0,0,0,0
0,0,3,9,9,9,11,9,3,3,9,11,9,9,9,3,0,0
0,0,9,0,0,0,0,0,9,9,0,0,0,0,0,9,0,0
0,0,11,0,0,0,0,0,9,9,0,0,0,0,0,11,0,0
0,0,9,0,0,0,0,0,9,9,0,0,0,0,0,9,0,0
0,0,3,9,11,9,11,9,3,3,9,11,9,11,9,3,0,0
0,0,0,0,0,0,0,0,0,0,0,0,0,0,0,0,0,0
0,0,0,0,0,0,0,0,0,0,0,0,0,0,0,0,0,0
endlayer

layer
0,0,0,0,0,0,0,0,0,0,0,0,0,0,0,0,0,0
0,0,0,0,0,0,0,0,0,0,0,0,0,0,0,0,0,0
0,0,3,9,11,9,3,11,11,3,9,11,9,11,9,3,0,0
0,0,9,0,0,0,9,0,0,9,0,0,0,0,0,9,0,0
0,0,11,0,0,0,9,0,0,9,0,0,0,0,0,11,0,0
0,0,11,0,0,0,11,0,0,11,0,0,0,0,0,11,0,0
0,0,9,0,0,0,9,14,0,9,0,0,0,0,0,9,0,0
0,0,3,9,11,9,3,11,11,3,9,11,9,11,9,3,0,0
0,0,0,0,0,0,0,0,0,0,0,0,0,0,0,0,0,0
0,0,0,0,0,0,0,0,0,0,0,0,0,0,0,0,0,0
0,0,0,0,0,0,0,0,0,0,0,0,0,0,0,0,0,0
0,0,3,9,9,9,11,9,3,3,9,11,9,9,9,3,0,0
0,0,9,0,0,0,0,0,9,9,0,0,0,0,0,9,0,0
0,0,11,0,0,0,0,0,9,9,0,0,0,0,0,11,0,0
0,0,9,0,0,0,0,0,9,9,0,0,0,0,0,9,0,0
0,0,3,9,11,9,11,9,3,3,9,11,9,11,9,3,0,0
0,0,0,0,0,0,0,0,0,0,0,0,0,0,0,0,0,0
0,0,0,0,0,0,0,0,0,0,0,0,0,0,0,0,0,0
endlayer

layer
0,0,0,0,0,0,0,0,0,0,0,0,0,0,0,0,0,0
0,0,0,0,0,0,0,0,0,0,0,0,0,0,0,0,0,0
0,0,3,3,3,3,3,3,3,3,3,3,3,3,3,3,0,0
0,0,3,2,2,2,2,2,2,2,2,2,2,2,2,3,0,0
0,0,3,2,2,2,3,2,2,3,2,2,2,2,2,3,0,0
0,0,3,2,2,2,3,2,2,3,2,2,2,2,2,3,0,0
0,0,3,2,2,2,3,14,2,3,2,2,2,2,2,3,0,0
0,0,3,3,3,3,3,3,3,3,3,3,3,3,3,3,0,0
0,0,0,0,0,0,0,0,0,0,0,0,0,0,0,0,0,0
0,0,0,0,0,0,0,0,0,0,0,0,0,0,0,0,0,0
0,0,0,0,0,0,0,0,0,0,0,0,0,0,0,0,0,0
0,0,3,3,3,3,3,3,3,3,3,3,3,3,3,3,0,0
0,0,3,19,19,19,19,19,19,19,19,19,19,19,19,3,0,0
0,0,3,19,19,19,19,19,19,19,19,19,19,19,19,3,0,0
0,0,3,19,19,19,19,19,19,19,19,19,19,19,19,3,0,0
0,0,3,3,3,3,3,3,3,3,3,3,3,3,3,3,0,0
0,0,0,0,0,0,0,0,0,0,0,0,0,0,0,0,0,0
0,0,0,0,0,0,0,0,0,0,0,0,0,0,0,0,0,0
endlayer

layer
0,0,0,0,0,0,0,0,0,0,0,0,0,0,0,0,0,0
0,0,0,0,0,0,0,0,0,0,0,0,0,0,0,0,0,0
0,0,3,9,11,9,3,11,11,3,9,11,9,11,9,3,0,0
0,0,9,8,0,0,0,0,0,0,0,0,0,0,8,9,0,0
0,0,11,0,0,0,9,0,0,9,12,0,0,10,7,11,0,0
0,0,11,0,10,0,11,0,0,11,13,0,0,0,6,11,0,0
0,0,9,8,7,6,9,14,0,9,12,0,0,0,7,9,0,0
0,0,3,9,11,9,3,11,11,3,9,11,9,11,9,3,0,0
0,0,0,0,0,0,0,0,0,0,0,0,0,0,0,0,0,0
0,0,0,0,0,0,0,0,0,0,0,0,0,0,0,0,0,0
0,0,0,0,0,0,0,0,0,0,0,0,0,0,0,0,0,0
0,0,0,0,0,0,0,0,0,0,0,0,0,0,0,0,0,0
0,0,0,0,0,0,0,0,0,0,0,0,0,0,0,0,0,0
0,0,0,0,0,0,0,0,0,0,0,0,0,0,0,0,0,0
0,0,0,0,0,0,0,0,0,0,0,0,0,0,0,0,0,0
0,0,0,0,0,0,0,0,0,0,0,0,0,0,0,0,0,0
0,0,0,0,0,0,0,0,0,0,0,0,0,0,0,0,0,0
0,0,0,0,0,0,0,0,0,0,0,0,0,0,0,0,0,0
endlayer

layer
0,0,0,0,0,0,0,0,0,0,0,0,0,0,0,0,0,0
0,0,0,0,0,0,0,0,0,0,0,0,0,0,0,0,0,0
0,0,3,9,11,9,3,11,11,3,9,11,9,11,9,3,0,0
0,0,9,16,0,0,0,0,0,0,0,0,0,0,0,9,0,0
0,0,11,0,0,0,9,0,0,9,0,0,0,0,0,11,0,0
0,0,11,0,0,0,11,0,0,11,16,0,0,0,15,11,0,0
0,0,9,0,0,15,9,14,0,9,0,0,0,0,0,9,0,0
0,0,3,9,11,9,3,11,11,3,9,11,9,11,9,3,0,0
0,0,0,0,0,0,0,0,0,0,0,0,0,0,0,0,0,0
0,0,0,0,0,0,0,0,0,0,0,0,0,0,0,0,0,0
0,0,0,0,0,0,0,0,0,0,0,0,0,0,0,0,0,0
0,0,0,0,0,0,0,0,0,0,0,0,0,0,0,0,0,0
0,0,0,0,0,0,0,0,0,0,0,0,0,0,0,0,0,0
0,0,0,0,0,0,0,0,0,0,0,0,0,0,0,0,0,0
0,0,0,0,0,0,0,0,0,0,0,0,0,0,0,0,0,0
0,0,0,0,0,0,0,0,0,0,0,0,0,0,0,0,0,0
0,0,0,0,0,0,0,0,0,0,0,0,0,0,0,0,0,0
0,0,0,0,0,0,0,0,0,0,0,0,0,0,0,0,0,0
endlayer

layer
0,0,0,0,0,0,0,0,0,0,0,0,0,0,0,0,0,0
0,0,0,0,0,0,0,0,0,0,0,0,0,0,0,0,0,0
0,0,3,9,11,9,3,11,11,3,9,11,9,11,9,3,0,0
0,0,9,0,0,0,9,0,0,0,0,0,0,0,0,9,0,0
0,0,11,0,0,0,9,0,0,9,0,0,0,0,0,11,0,0
0,0,11,0,0,0,11,0,0,11,0,0,0,0,0,11,0,0
0,0,9,0,0,0,9,14,0,9,0,0,0,0,0,9,0,0
0,0,3,9,11,9,3,11,11,3,9,11,9,11,9,3,0,0
0,0,0,0,0,0,0,0,0,0,0,0,0,0,0,0,0,0
0,0,0,0,0,0,0,0,0,0,0,0,0,0,0,0,0,0
0,0,0,0,0,0,0,0,0,0,0,0,0,0,0,0,0,0
0,0,0,0,0,0,0,0,0,0,0,0,0,0,0,0,0,0
0,0,0,0,0,0,0,0,0,0,0,0,0,0,0,0,0,0
0,0,0,0,0,0,0,0,0,0,0,0,0,0,0,0,0,0
0,0,0,0,0,0,0,0,0,0,0,0,0,0,0,0,0,0
0,0,0,0,0,0,0,0,0,0,0,0,0,0,0,0,0,0
0,0,0,0,0,0,0,0,0,0,0,0,0,0,0,0,0,0
0,0,0,0,0,0,0,0,0,0,0,0,0,0,0,0,0,0
endlayer

layer
0,0,0,0,0,0,0,0,0,0,0,0,0,0,0,0,0,0
0,0,0,0,0,0,0,0,0,0,0,0,0,0,0,0,0,0
0,0,3,9,11,9,3,11,11,3,9,11,9,11,9,3,0,0
0,0,9,0,0,0,9,0,0,0,0,0,0,0,0,9,0,0
0,0,11,0,0,0,9,0,0,9,0,0,0,0,0,11,0,0
0,0,11,0,0,0,11,0,0,11,0,0,0,0,0,11,0,0
0,0,9,0,0,0,9,14,0,9,0,0,0,0,0,9,0,0
0,0,3,9,11,9,3,11,11,3,9,11,9,11,9,3,0,0
0,0,0,0,0,0,0,0,0,0,0,0,0,0,0,0,0,0
0,0,0,0,0,0,0,0,0,0,0,0,0,0,0,0,0,0
0,0,0,0,0,0,0,0,0,0,0,0,0,0,0,0,0,0
0,0,0,0,0,0,0,0,0,0,0,0,0,0,0,0,0,0
0,0,0,0,0,0,0,0,0,0,0,0,0,0,0,0,0,0
0,0,0,0,0,0,0,0,0,0,0,0,0,0,0,0,0,0
0,0,0,0,0,0,0,0,0,0,0,0,0,0,0,0,0,0
0,0,0,0,0,0,0,0,0,0,0,0,0,0,0,0,0,0
0,0,0,0,0,0,0,0,0,0,0,0,0,0,0,0,0,0
0,0,0,0,0,0,0,0,0,0,0,0,0,0,0,0,0,0
endlayer

layer
0,0,0,0,0,0,0,0,0,0,0,0,0,0,0,0,0,0
0,0,0,0,0,0,0,0,0,0,0,0,0,0,0,0,0,0
0,0,3,3,3,3,3,3,3,3,3,3,3,3,3,3,0,0
0,0,3,2,2,2,2,2,2,2,2,2,2,2,2,3,0,0
0,0,3,2,2,2,3,2,2,3,2,2,2,2,2,3,0,0
0,0,3,2,2,2,3,2,2,3,2,2,2,2,2,3,0,0
0,0,3,2,2,2,3,14,2,3,2,2,2,2,2,3,0,0
0,0,3,3,3,3,3,3,3,3,3,3,3,3,3,3,0,0
0,0,0,0,0,0,0,0,0,0,0,0,0,0,0,0,0,0
0,0,0,0,0,0,0,0,0,0,0,0,0,0,0,0,0,0
0,0,0,0,0,0,0,0,0,0,0,0,0,0,0,0,0,0
0,0,0,0,0,0,0,0,0,0,0,0,0,0,0,0,0,0
0,0,0,0,0,0,0,0,0,0,0,0,0,0,0,0,0,0
0,0,0,0,0,0,0,0,0,0,0,0,0,0,0,0,0,0
0,0,0,0,0,0,0,0,0,0,0,0,0,0,0,0,0,0
0,0,0,0,0,0,0,0,0,0,0,0,0,0,0,0,0,0
0,0,0,0,0,0,0,0,0,0,0,0,0,0,0,0,0,0
0,0,0,0,0,0,0,0,0,0,0,0,0,0,0,0,0,0
endlayer

layer
0,0,0,0,0,0,0,0,0,0,0,0,0,0,0,0,0,0
0,0,0,0,0,0,0,0,0,0,0,0,0,0,0,0,0,0
0,0,3,9,11,9,3,11,11,3,9,11,9,11,9,3,0,0
0,0,9,13,0,0,0,0,0,0,0,0,0,0,6,9,0,0
0,0,11,0,0,0,9,0,0,9,12,0,0,10,7,11,0,0
0,0,11,0,10,0,11,0,0,11,13,0,0,0,6,11,0,0
0,0,9,18,7,6,9,14,0,9,12,0,0,0,18,9,0,0
0,0,3,9,11,9,3,11,11,3,9,11,9,11,9,3,0,0
0,0,0,0,0,0,0,0,0,0,0,0,0,0,0,0,0,0
0,0,0,0,0,0,0,0,0,0,0,0,0,0,0,0,0,0
0,0,0,0,0,0,0,0,0,0,0,0,0,0,0,0,0,0
0,0,0,0,0,0,0,0,0,0,0,0,0,0,0,0,0,0
0,0,0,0,0,0,0,0,0,0,0,0,0,0,0,0,0,0
0,0,0,0,0,0,0,0,0,0,0,0,0,0,0,0,0,0
0,0,0,0,0,0,0,0,0,0,0,0,0,0,0,0,0,0
0,0,0,0,0,0,0,0,0,0,0,0,0,0,0,0,0,0
0,0,0,0,0,0,0,0,0,0,0,0,0,0,0,0,0,0
0,0,0,0,0,0,0,0,0,0,0,0,0,0,0,0,0,0
endlayer

layer
0,0,0,0,0,0,0,0,0,0,0,0,0,0,0,0,0,0
0,0,0,0,0,0,0,0,0,0,0,0,0,0,0,0,0,0
0,0,3,9,11,9,3,11,11,3,9,11,9,11,9,3,0,0
0,0,9,16,0,0,0,0,0,0,0,0,0,0,15,9,0,0
0,0,11,0,0,0,9,0,0,9,16,0,0,0,0,11,0,0
0,0,11,0,0,0,11,0,0,11,0,0,0,0,0,11,0,0
0,0,9,0,0,15,9,14,0,9,0,0,0,0,0,9,0,0
0,0,3,9,11,9,3,11,11,3,9,11,9,11,9,3,0,0
0,0,0,0,0,0,0,0,0,0,0,0,0,0,0,0,0,0
0,0,0,0,0,0,0,0,0,0,0,0,0,0,0,0,0,0
0,0,0,0,0,0,0,0,0,0,0,0,0,0,0,0,0,0
0,0,0,0,0,0,0,0,0,0,0,0,0,0,0,0,0,0
0,0,0,0,0,0,0,0,0,0,0,0,0,0,0,0,0,0
0,0,0,0,0,0,0,0,0,0,0,0,0,0,0,0,0,0
0,0,0,0,0,0,0,0,0,0,0,0,0,0,0,0,0,0
0,0,0,0,0,0,0,0,0,0,0,0,0,0,0,0,0,0
0,0,0,0,0,0,0,0,0,0,0,0,0,0,0,0,0,0
0,0,0,0,0,0,0,0,0,0,0,0,0,0,0,0,0,0
endlayer

layer
0,0,0,0,0,0,0,0,0,0,0,0,0,0,0,0,0,0
0,0,0,0,0,0,0,0,0,0,0,0,0,0,0,0,0,0
0,0,3,9,11,9,3,11,11,3,9,11,9,11,9,3,0,0
0,0,9,0,0,0,9,0,0,0,0,0,0,0,0,9,0,0
0,0,11,0,0,0,9,0,0,9,0,0,0,0,0,11,0,0
0,0,11,0,0,0,11,0,0,11,0,0,0,0,0,11,0,0
0,0,9,0,0,0,9,0,0,9,0,0,0,0,0,9,0,0
0,0,3,9,11,9,3,11,11,3,9,11,9,11,9,3,0,0
0,0,0,0,0,0,0,0,0,0,0,0,0,0,0,0,0,0
0,0,0,0,0,0,0,0,0,0,0,0,0,0,0,0,0,0
0,0,0,0,0,0,0,0,0,0,0,0,0,0,0,0,0,0
0,0,0,0,0,0,0,0,0,0,0,0,0,0,0,0,0,0
0,0,0,0,0,0,0,0,0,0,0,0,0,0,0,0,0,0
0,0,0,0,0,0,0,0,0,0,0,0,0,0,0,0,0,0
0,0,0,0,0,0,0,0,0,0,0,0,0,0,0,0,0,0
0,0,0,0,0,0,0,0,0,0,0,0,0,0,0,0,0,0
0,0,0,0,0,0,0,0,0,0,0,0,0,0,0,0,0,0
0,0,0,0,0,0,0,0,0,0,0,0,0,0,0,0,0,0
endlayer

layer
0,0,0,0,0,0,0,0,0,0,0,0,0,0,0,0,0,0
0,0,0,0,0,0,0,0,0,0,0,0,0,0,0,0,0,0
0,0,3,9,11,9,3,11,11,3,9,11,9,11,9,3,0,0
0,0,9,0,0,0,9,0,0,0,0,0,0,0,0,9,0,0
0,0,11,0,0,0,9,0,0,9,0,0,0,0,0,11,0,0
0,0,11,0,0,0,11,0,0,11,0,0,0,0,0,11,0,0
0,0,9,0,0,0,9,0,0,9,0,0,0,0,0,9,0,0
0,0,3,9,11,9,3,11,11,3,9,11,9,11,9,3,0,0
0,0,0,0,0,0,0,0,0,0,0,0,0,0,0,0,0,0
0,0,0,0,0,0,0,0,0,0,0,0,0,0,0,0,0,0
0,0,0,0,0,0,0,0,0,0,0,0,0,0,0,0,0,0
0,0,0,0,0,0,0,0,0,0,0,0,0,0,0,0,0,0
0,0,0,0,0,0,0,0,0,0,0,0,0,0,0,0,0,0
0,0,0,0,0,0,0,0,0,0,0,0,0,0,0,0,0,0
0,0,0,0,0,0,0,0,0,0,0,0,0,0,0,0,0,0
0,0,0,0,0,0,0,0,0,0,0,0,0,0,0,0,0,0
0,0,0,0,0,0,0,0,0,0,0,0,0,0,0,0,0,0
0,0,0,0,0,0,0,0,0,0,0,0,0,0,0,0,0,0
endlayer

layer
0,0,0,0,0,0,0,0,0,0,0,0,0,0,0,0,0,0
0,0,0,0,0,0,0,0,0,0,0,0,0,0,0,0,0,0
0,0,3,3,3,3,3,3,3,3,3,3,3,3,3,3,0,0
0,0,3,19,19,19,3,19,19,3,19,19,19,19,19,3,0,0
0,0,3,19,19,19,3,19,19,3,19,19,19,19,19,3,0,0
0,0,3,19,19,19,3,19,19,3,19,19,19,19,19,3,0,0
0,0,3,19,19,19,3,19,19,3,19,19,19,19,19,3,0,0
0,0,3,3,3,3,3,3,3,3,3,3,3,3,3,3,0,0
0,0,0,0,0,0,0,0,0,0,0,0,0,0,0,0,0,0
0,0,0,0,0,0,0,0,0,0,0,0,0,0,0,0,0,0
0,0,0,0,0,0,0,0,0,0,0,0,0,0,0,0,0,0
0,0,0,0,0,0,0,0,0,0,0,0,0,0,0,0,0,0
0,0,0,0,0,0,0,0,0,0,0,0,0,0,0,0,0,0
0,0,0,0,0,0,0,0,0,0,0,0,0,0,0,0,0,0
0,0,0,0,0,0,0,0,0,0,0,0,0,0,0,0,0,0
0,0,0,0,0,0,0,0,0,0,0,0,0,0,0,0,0,0
0,0,0,0,0,0,0,0,0,0,0,0,0,0,0,0,0,0
0,0,0,0,0,0,0,0,0,0,0,0,0,0,0,0,0,0
endlayer

