# Converted from schematic
# THIS TEMPLATE USES DEFAULTS!  Please edit for corrections.
# If you need help, consult template_rules.txt

weight=3
embed_into_distance=11
acceptable_target_blocks=1,2,3,12,13,250
dimensions=22,18,18
allowable_overhang=0
max_cut_in=2
cut_in_buffer=1
max_leveling=2
leveling_buffer=1
preserve_water=0
preserve_lava=0
preserve_plants=0


rule1=0,100,3134-10
rule2=0,100,2843-4
rule3=0,100,300
rule4=0,100,2843-14,2843-14,2843-14,2843-14,2843
rule5=0,100,622,2838-4,2838-4,2838-4,2838-4,2838-4,2838-4,2838-4,2838-4,2838-4
rule6=0,75,308,308,308,308,308,308,313,313,314,327
rule7=0,95,2835-2,2835-2,2835-2,2835-2,2835-2,2835-2,2835-2,2835-1,2835-1,2835-0
rule8=0,25,311
rule9=0,25,3225-3
rule10=0,100,623
rule11=0,95,300
rule12=0,100,3134,3134,3134,3134,3134,3134,3134,3134,3134,3134-8,3134-2


layer
1,1,1,1,1,1,1,1,1,1,1,1,1,1,1,1,1,1
1,1,1,1,1,1,1,1,1,1,1,1,1,1,1,1,1,1
1,1,1,1,1,1,1,1,1,1,1,1,1,1,1,1,1,1
1,1,1,2,2,2,2,2,1,1,1,2,2,2,2,1,1,1
1,1,1,2,2,2,2,2,1,1,1,2,2,2,2,1,1,1
1,1,1,2,2,2,2,2,1,1,1,2,2,2,2,1,1,1
1,1,1,2,2,2,2,2,3,1,1,2,2,2,2,1,1,1
1,1,1,2,2,2,2,3,3,3,1,2,2,2,2,1,1,1
1,1,1,2,2,2,2,3,3,3,1,2,2,2,2,1,1,1
1,1,1,2,2,2,2,2,3,1,1,2,2,2,2,1,1,1
1,1,1,2,2,2,5,2,1,1,1,2,2,2,2,1,1,1
1,1,1,2,2,2,2,4,1,1,1,2,2,2,2,1,1,1
1,1,1,2,2,2,2,2,1,1,1,2,2,2,2,1,1,1
1,1,1,2,3,3,2,2,1,1,1,2,2,2,2,1,1,1
1,1,1,3,3,3,6,2,1,1,1,2,3,3,2,1,1,1
1,1,1,3,3,1,1,1,1,1,1,3,3,3,1,1,1,1
1,1,1,1,1,1,1,1,1,1,1,3,3,3,1,1,1,1
1,1,1,1,1,1,1,1,1,1,1,1,1,1,1,1,1,1
endlayer

layer
3,3,3,3,3,3,3,3,3,3,3,3,3,3,3,3,3,3
3,3,3,3,3,3,3,3,3,3,3,3,3,3,3,3,3,3
3,3,4,4,4,4,4,4,3,3,3,4,4,4,4,4,3,3
3,3,4,0,0,0,6,7,3,3,3,7,8,0,6,4,3,3
3,3,4,0,0,0,0,9,3,3,3,3,3,0,0,4,3,3
3,3,4,0,0,0,0,7,3,3,3,7,3,0,0,4,3,3
3,3,4,0,0,0,0,7,3,3,3,3,3,3,3,4,3,3
3,3,4,0,0,0,0,3,3,3,3,7,0,0,0,4,3,3
3,3,4,0,7,9,7,3,3,3,3,4,7,7,7,4,3,3
3,3,4,0,0,0,3,3,3,3,3,4,7,7,7,4,3,3
3,3,4,0,0,3,10,3,3,3,3,7,0,0,0,4,3,3
3,3,4,0,7,3,7,4,3,3,3,3,3,0,3,4,3,3
3,3,4,3,3,3,3,7,3,3,3,7,3,3,3,4,3,3
3,3,4,3,3,3,3,3,3,3,3,3,3,3,3,4,3,3
3,3,4,3,3,3,3,7,3,3,3,3,3,3,3,4,3,3
3,3,4,3,3,3,4,4,3,3,3,3,3,3,4,4,3,3
3,3,3,3,3,3,3,3,3,3,3,3,3,3,3,3,3,3
3,3,3,3,3,3,3,3,3,3,3,3,3,3,3,3,3,3
endlayer

layer
3,3,3,3,3,3,3,3,3,3,3,3,3,3,3,3,3,3
3,3,3,3,3,3,3,3,3,3,3,3,3,3,3,3,3,3
3,3,4,7,9,9,7,4,3,3,3,4,7,9,7,4,3,3
3,3,7,0,0,0,0,7,3,3,3,7,0,0,0,7,3,3
3,3,9,0,0,0,0,9,3,3,3,0,0,0,0,9,3,3
3,3,7,0,0,0,0,7,3,3,3,7,0,0,0,7,3,3
3,3,9,0,0,0,0,7,3,3,3,3,0,0,0,9,3,3
3,3,7,0,0,0,0,3,3,3,3,7,0,0,0,7,3,3
3,3,4,0,7,9,7,3,3,3,3,4,7,7,7,4,3,3
3,3,9,0,0,0,3,3,3,3,3,4,7,7,7,4,3,3
3,3,9,0,0,0,0,0,0,3,3,7,0,0,0,7,3,3
3,3,4,0,7,0,7,4,3,3,3,3,3,0,0,3,3,3
3,3,7,3,0,3,3,3,3,3,3,3,3,3,3,7,3,3
3,3,3,3,3,3,3,3,3,3,3,3,3,3,3,3,3,3
3,3,7,3,3,3,3,3,3,3,3,3,3,3,3,7,3,3
3,3,4,3,3,3,7,4,3,3,3,3,3,3,3,4,3,3
3,3,3,3,3,3,3,3,3,3,3,3,3,3,3,3,3,3
3,3,3,3,3,3,3,3,3,3,3,3,3,3,3,3,3,3
endlayer

layer
3,3,3,3,3,3,3,3,3,3,3,3,3,3,3,3,3,3
3,3,3,3,3,3,3,3,3,3,3,3,3,3,3,3,3,3
3,3,4,7,9,9,7,4,3,3,3,4,7,9,7,4,3,3
3,3,7,0,0,0,0,7,3,3,3,7,0,0,0,7,3,3
3,3,9,0,0,0,0,9,3,3,3,7,0,0,0,9,3,3
3,3,7,0,0,0,0,7,3,3,3,7,0,0,0,7,3,3
3,3,9,0,0,0,0,7,3,3,3,9,0,0,0,9,3,3
3,3,7,0,0,0,0,7,0,3,3,7,0,0,0,7,3,3
3,3,4,7,7,9,7,4,0,0,3,4,7,7,7,4,3,3
3,3,9,0,0,0,0,0,0,0,0,4,7,7,7,4,3,3
3,3,9,0,0,0,10,0,0,0,0,7,0,0,0,7,3,3
3,3,4,7,7,0,7,4,0,3,3,3,3,0,0,3,3,3
3,3,7,0,0,3,3,3,3,3,3,3,3,3,0,7,3,3
3,3,3,3,3,3,3,3,3,3,3,3,3,3,3,3,3,3
3,3,7,3,3,3,3,3,3,3,3,3,3,3,3,7,3,3
3,3,4,7,3,3,7,4,3,3,3,3,3,3,7,4,3,3
3,3,3,3,3,3,3,3,3,3,3,3,3,3,3,3,3,3
3,3,3,3,3,3,3,3,3,3,3,3,3,3,3,3,3,3
endlayer

layer
3,3,3,3,3,3,3,3,3,3,3,3,3,3,3,3,3,3
3,3,3,3,3,3,3,3,3,3,3,3,3,3,3,3,3,3
3,3,4,7,9,9,7,4,3,3,3,4,7,9,7,4,3,3
3,3,7,0,0,0,0,7,3,3,3,7,0,0,0,7,3,3
3,3,9,0,0,0,0,9,3,3,3,7,0,0,0,9,3,3
3,3,7,0,0,0,0,7,3,3,3,7,0,0,0,7,3,3
3,3,9,0,0,0,0,7,0,3,3,9,0,0,0,9,3,3
3,3,7,0,0,0,0,7,0,0,0,7,0,0,0,7,3,3
3,3,4,7,7,9,7,4,0,0,0,4,7,7,7,4,3,3
3,3,9,0,0,0,0,9,0,0,0,4,7,7,7,4,3,3
3,3,9,0,0,0,0,0,0,0,0,7,0,0,0,7,3,3
3,3,4,7,7,0,7,4,0,0,3,3,3,0,0,3,3,3
3,3,7,0,0,3,3,3,3,3,3,3,0,0,0,7,3,3
3,3,3,3,3,3,3,3,3,3,3,3,3,3,0,0,3,3
3,3,7,3,3,3,3,3,3,3,3,3,3,3,0,7,3,3
3,3,4,7,3,3,7,4,3,3,3,3,7,3,7,4,3,3
3,3,3,3,3,3,3,3,3,3,3,3,3,3,3,3,3,3
3,3,3,3,3,3,3,3,3,3,3,3,3,3,3,3,3,3
endlayer

layer
3,3,3,3,3,3,3,3,3,3,3,3,3,3,3,3,3,3
3,3,3,3,3,3,3,3,3,3,3,3,3,3,3,3,3,3
3,3,4,7,9,9,7,4,3,3,3,4,7,9,7,4,3,3
3,3,7,0,0,0,0,7,3,3,3,7,0,0,0,7,3,3
3,3,9,0,0,0,0,9,3,3,3,7,0,0,0,9,3,3
3,3,7,0,0,0,0,7,3,3,3,7,0,0,0,7,3,3
3,3,9,0,0,0,0,7,0,3,0,9,0,0,0,9,3,3
3,3,7,0,0,0,0,7,0,0,0,7,0,0,0,7,3,3
3,3,4,7,7,9,7,4,0,0,0,4,7,7,7,4,3,3
3,3,9,0,0,0,0,0,0,0,0,4,7,7,7,4,3,3
3,3,9,0,0,0,10,0,0,0,0,7,0,0,0,7,3,3
3,3,4,7,7,0,0,0,0,0,0,3,0,0,0,9,3,3
3,3,7,0,0,3,3,0,3,3,3,3,0,0,0,7,3,3
3,3,3,3,3,3,3,3,3,3,3,3,0,3,0,9,3,3
3,3,0,3,3,3,3,3,3,3,3,3,3,3,0,7,3,3
3,3,4,7,3,3,3,4,3,3,3,3,7,3,7,4,3,3
3,3,3,3,3,3,3,3,3,3,3,3,3,3,3,3,3,3
3,3,3,3,3,3,3,3,3,3,3,3,3,3,3,3,3,3
endlayer

layer
3,3,3,3,3,3,3,3,3,3,3,3,3,3,3,3,3,3
3,3,3,3,3,3,3,3,3,3,3,3,3,3,3,3,3,3
3,3,4,4,4,4,4,4,3,3,3,4,4,4,4,4,3,3
3,3,4,2,2,2,2,4,3,3,3,4,2,2,2,4,3,3
3,3,4,2,2,2,2,4,3,3,3,2,2,2,2,4,3,3
3,3,4,2,2,2,2,4,0,3,0,4,2,2,2,4,3,3
3,3,4,2,2,2,2,4,0,0,2,4,2,2,2,4,3,3
3,3,4,2,2,2,2,4,0,0,0,0,2,2,2,4,3,3
3,3,4,2,4,4,4,4,0,0,0,0,2,2,2,4,3,3
3,3,4,2,2,2,2,2,2,0,0,4,2,2,2,4,3,3
3,3,4,2,2,2,10,0,0,0,2,4,2,2,2,4,3,3
3,3,4,2,4,4,0,0,0,0,0,0,2,2,2,4,3,3
3,3,4,2,2,2,0,0,0,3,0,0,0,2,2,4,3,3
3,3,4,2,3,3,3,3,3,3,3,3,0,3,2,4,3,3
3,3,4,2,3,3,3,3,3,3,3,3,3,3,2,4,3,3
3,3,4,4,3,3,3,3,3,3,3,4,4,4,4,4,3,3
3,3,3,3,3,3,3,3,3,3,3,3,3,3,3,3,3,3
3,3,3,3,3,3,3,3,3,3,3,3,3,3,3,3,3,3
endlayer

layer
3,3,3,3,3,3,3,3,3,3,3,3,3,3,3,3,3,3
3,3,3,3,3,3,3,3,3,3,3,3,3,3,3,3,3,3
3,3,4,7,9,9,7,4,3,3,3,4,7,9,7,4,3,3
3,3,7,6,0,0,3,7,3,3,3,7,8,3,6,7,3,3
3,3,9,0,3,0,3,3,3,3,3,3,3,0,0,9,3,3
3,3,7,0,0,0,3,7,0,0,0,0,0,0,0,7,3,3
3,3,9,0,0,0,3,0,0,0,0,0,0,0,0,9,3,3
3,3,7,0,0,0,0,7,0,0,0,0,0,0,0,7,3,3
3,3,4,0,7,9,7,4,0,0,0,0,7,7,7,4,3,3
3,3,9,0,0,0,0,0,0,0,0,4,7,7,7,4,3,3
3,3,9,0,0,0,10,0,0,0,0,7,0,0,0,7,3,3
3,3,4,0,7,0,0,0,0,0,0,0,0,0,0,9,3,3
3,3,7,0,0,0,0,0,0,0,0,0,0,0,0,7,3,3
3,3,0,0,0,0,0,0,3,3,3,0,0,0,3,0,3,3
3,3,7,0,0,3,3,3,3,3,3,3,0,3,6,7,3,3
3,3,4,7,0,3,3,3,3,3,3,3,3,3,7,4,3,3
3,3,3,3,3,3,3,3,3,3,3,3,3,3,3,3,3,3
3,3,3,3,3,3,3,3,3,3,3,3,3,3,3,3,3,3
endlayer

layer
3,3,3,3,3,3,3,3,3,3,3,3,3,3,3,3,3,3
3,3,3,3,3,3,3,3,3,3,3,3,3,3,3,3,3,3
3,3,4,7,9,9,7,4,3,3,3,4,7,9,7,4,3,3
3,3,7,0,0,0,0,7,3,3,3,7,3,0,0,7,3,3
3,3,9,0,0,0,0,0,0,3,0,0,0,0,0,9,3,3
3,3,7,0,0,0,0,7,0,0,0,7,0,0,0,7,3,3
3,3,9,0,0,0,0,0,0,0,0,0,0,0,0,9,3,3
3,3,7,0,0,0,0,7,0,0,0,0,0,0,0,7,3,3
3,3,4,0,7,9,7,4,0,0,0,0,7,7,7,4,3,3
3,3,9,0,0,0,0,0,0,0,0,4,7,7,7,4,3,3
3,3,9,0,0,0,0,0,0,0,0,7,0,0,0,7,3,3
3,3,4,0,7,0,7,0,0,0,0,0,0,0,0,9,3,3
3,3,7,0,0,0,0,0,0,0,0,0,0,0,0,7,3,3
3,3,0,0,0,0,0,0,0,3,0,0,0,0,0,9,3,3
3,3,7,0,0,3,0,0,3,3,3,3,0,0,3,7,3,3
3,3,4,7,0,3,3,3,3,3,3,4,7,3,7,4,3,3
3,3,3,3,3,3,3,3,3,3,3,3,3,3,3,3,3,3
3,3,3,3,3,3,3,3,3,3,3,3,3,3,3,3,3,3
endlayer

layer
3,3,3,3,3,3,3,3,3,3,3,3,3,3,3,3,3,3
3,3,3,3,3,3,3,3,3,3,3,3,3,3,3,3,3,3
3,3,4,7,9,9,7,4,3,3,3,4,7,9,7,4,3,3
3,3,7,0,0,0,0,7,3,3,3,7,0,0,0,7,3,3
3,3,9,0,0,0,0,0,0,0,0,7,0,0,0,9,3,3
3,3,7,0,0,0,0,7,0,0,0,7,0,0,0,7,3,3
3,3,9,0,0,0,0,0,0,0,0,0,0,0,0,9,3,3
3,3,7,0,0,0,0,7,0,0,0,7,0,0,0,7,3,3
3,3,4,7,7,9,7,4,0,0,0,4,7,7,7,4,3,3
3,3,9,0,0,0,0,0,0,0,0,4,7,7,7,4,3,3
3,3,9,0,0,0,10,0,0,0,0,7,0,0,0,7,3,3
3,3,4,7,7,9,7,4,0,0,0,0,0,0,0,9,3,3
3,3,7,0,0,0,0,7,0,0,0,0,0,0,0,7,3,3
3,3,0,0,0,0,0,0,0,0,0,0,0,0,0,9,3,3
3,3,7,0,0,0,0,7,0,3,3,7,0,0,0,7,3,3
3,3,4,7,0,3,7,4,3,3,3,4,7,3,7,4,3,3
3,3,3,3,3,3,3,3,3,3,3,3,3,3,3,3,3,3
3,3,3,3,3,3,3,3,3,3,3,3,3,3,3,3,3,3
endlayer

layer
11,11,11,11,11,11,11,11,11,11,11,11,11,11,11,11,11,11
11,11,11,11,11,11,11,11,11,11,11,11,11,11,11,11,11,11
11,11,4,7,9,9,7,4,11,11,11,4,7,9,7,4,11,11
11,11,7,0,0,0,0,7,0,0,0,7,0,0,0,7,11,11
11,11,9,0,0,0,0,0,0,0,0,7,0,0,0,9,11,11
11,11,7,0,0,0,0,7,0,0,0,7,0,0,0,7,11,11
11,11,9,0,0,0,0,0,0,0,0,9,0,0,0,9,11,11
11,11,7,0,0,0,0,7,0,0,0,7,0,0,0,7,11,11
11,11,4,7,7,9,7,4,0,0,0,4,7,7,7,4,11,11
11,11,9,0,0,0,0,0,0,0,0,4,7,7,7,4,11,11
11,11,9,0,0,0,10,9,0,0,0,7,0,0,0,7,11,11
11,11,4,7,7,9,7,4,0,0,0,0,0,0,0,0,11,11
11,11,7,0,0,0,0,7,0,0,0,0,0,0,0,7,11,11
11,11,0,0,0,0,0,0,0,0,0,0,0,0,0,0,11,11
11,11,7,0,0,0,0,7,0,0,0,7,0,0,0,7,11,11
11,11,4,7,0,11,7,4,11,11,11,4,7,0,7,4,11,11
11,11,11,11,11,11,11,11,11,11,11,11,11,11,11,11,11,11
11,11,11,11,11,11,11,11,11,11,11,11,11,11,11,11,11,11
endlayer

layer
0,0,0,0,0,0,0,0,0,0,0,0,0,0,0,0,0,0
0,0,0,0,0,0,0,0,0,0,0,0,0,0,0,0,0,0
0,0,4,4,4,4,4,4,0,0,0,4,4,4,4,4,0,0
0,0,4,2,2,2,2,4,0,0,0,4,12,12,12,4,0,0
0,0,4,2,2,2,2,4,0,0,0,4,12,12,12,4,0,0
0,0,4,2,2,2,2,4,0,0,0,4,12,12,12,4,0,0
0,0,4,2,2,2,2,4,0,0,0,4,12,12,12,4,0,0
0,0,4,2,2,2,2,4,0,0,0,4,12,12,12,4,0,0
0,0,4,2,4,4,4,4,0,0,0,4,12,12,12,4,0,0
0,0,4,2,2,2,2,4,0,0,0,4,0,0,0,4,0,0
0,0,4,2,2,2,10,4,0,0,0,4,12,0,0,4,0,0
0,0,4,2,4,4,4,4,0,0,0,4,0,0,0,4,0,0
0,0,4,0,0,0,2,4,0,0,0,4,0,0,0,4,0,0
0,0,4,0,0,0,2,4,0,0,0,0,0,0,0,4,0,0
0,0,4,0,0,0,2,4,0,0,0,4,0,0,0,4,0,0
0,0,4,4,4,4,4,4,0,0,0,4,4,4,4,4,0,0
0,0,0,0,0,0,0,0,0,0,0,0,0,0,0,0,0,0
0,0,0,0,0,0,0,0,0,0,0,0,0,0,0,0,0,0
endlayer

layer
0,0,0,0,0,0,0,0,0,0,0,0,0,0,0,0,0,0
0,0,0,0,0,0,0,0,0,0,0,0,0,0,0,0,0,0
0,0,4,7,0,9,7,4,0,0,0,0,0,0,0,0,0,0
0,0,7,6,0,0,8,7,0,0,0,0,0,0,0,0,0,0
0,0,9,0,0,0,0,9,0,0,0,0,0,0,0,0,0,0
0,0,7,0,0,0,0,7,0,0,0,0,0,0,0,0,0,0
0,0,9,0,0,0,0,9,0,0,0,0,0,0,0,0,0,0
0,0,7,0,0,0,0,7,0,0,0,0,0,0,0,0,0,0
0,0,4,0,7,0,7,4,0,0,0,0,0,0,0,0,0,0
0,0,9,0,0,0,0,9,0,0,0,0,0,0,0,0,0,0
0,0,0,0,0,0,0,0,0,0,0,0,0,0,0,0,0,0
0,0,4,0,7,0,7,4,0,0,0,0,0,0,0,0,0,0
0,0,7,0,0,0,0,7,0,0,0,0,0,0,0,0,0,0
0,0,0,0,0,0,0,0,0,0,0,0,0,0,0,0,0,0
0,0,7,0,0,0,0,0,0,0,0,0,0,0,0,0,0,0
0,0,4,7,0,0,0,4,0,0,0,0,0,0,0,0,0,0
0,0,0,0,0,0,0,0,0,0,0,0,0,0,0,0,0,0
0,0,0,0,0,0,0,0,0,0,0,0,0,0,0,0,0,0
endlayer

layer
0,0,0,0,0,0,0,0,0,0,0,0,0,0,0,0,0,0
0,0,0,0,0,0,0,0,0,0,0,0,0,0,0,0,0,0
0,0,4,7,0,9,7,4,0,0,0,0,0,0,0,0,0,0
0,0,7,0,0,0,0,7,0,0,0,0,0,0,0,0,0,0
0,0,9,0,0,0,0,9,0,0,0,0,0,0,0,0,0,0
0,0,7,0,0,0,0,7,0,0,0,0,0,0,0,0,0,0
0,0,9,0,0,0,0,9,0,0,0,0,0,0,0,0,0,0
0,0,7,0,0,0,0,7,0,0,0,0,0,0,0,0,0,0
0,0,4,0,7,9,7,4,0,0,0,0,0,0,0,0,0,0
0,0,9,0,0,0,0,0,0,0,0,0,0,0,0,0,0,0
0,0,9,0,0,0,0,0,0,0,0,0,0,0,0,0,0,0
0,0,4,0,7,0,7,4,0,0,0,0,0,0,0,0,0,0
0,0,7,0,0,0,0,0,0,0,0,0,0,0,0,0,0,0
0,0,0,0,0,0,0,0,0,0,0,0,0,0,0,0,0,0
0,0,7,0,0,0,0,0,0,0,0,0,0,0,0,0,0,0
0,0,4,7,0,0,0,0,0,0,0,0,0,0,0,0,0,0
0,0,0,0,0,0,0,0,0,0,0,0,0,0,0,0,0,0
0,0,0,0,0,0,0,0,0,0,0,0,0,0,0,0,0,0
endlayer

layer
0,0,0,0,0,0,0,0,0,0,0,0,0,0,0,0,0,0
0,0,0,0,0,0,0,0,0,0,0,0,0,0,0,0,0,0
0,0,4,7,9,9,7,4,0,0,0,0,0,0,0,0,0,0
0,0,7,0,0,0,0,7,0,0,0,0,0,0,0,0,0,0
0,0,9,0,0,0,0,9,0,0,0,0,0,0,0,0,0,0
0,0,7,0,0,0,0,7,0,0,0,0,0,0,0,0,0,0
0,0,9,0,0,0,0,9,0,0,0,0,0,0,0,0,0,0
0,0,7,0,0,0,0,7,0,0,0,0,0,0,0,0,0,0
0,0,4,0,7,9,7,4,0,0,0,0,0,0,0,0,0,0
0,0,9,0,0,0,0,9,0,0,0,0,0,0,0,0,0,0
0,0,9,0,0,0,0,0,0,0,0,0,0,0,0,0,0,0
0,0,4,7,7,0,7,4,0,0,0,0,0,0,0,0,0,0
0,0,7,0,0,0,0,0,0,0,0,0,0,0,0,0,0,0
0,0,0,0,0,0,0,0,0,0,0,0,0,0,0,0,0,0
0,0,7,0,0,0,0,0,0,0,0,0,0,0,0,0,0,0
0,0,4,7,0,0,0,4,0,0,0,0,0,0,0,0,0,0
0,0,0,0,0,0,0,0,0,0,0,0,0,0,0,0,0,0
0,0,0,0,0,0,0,0,0,0,0,0,0,0,0,0,0,0
endlayer

layer
0,0,0,0,0,0,0,0,0,0,0,0,0,0,0,0,0,0
0,0,0,0,0,0,0,0,0,0,0,0,0,0,0,0,0,0
0,0,4,7,9,9,7,4,0,0,0,0,0,0,0,0,0,0
0,0,7,0,0,0,0,7,0,0,0,0,0,0,0,0,0,0
0,0,9,0,0,0,0,9,0,0,0,0,0,0,0,0,0,0
0,0,7,0,0,0,0,7,0,0,0,0,0,0,0,0,0,0
0,0,9,0,0,0,0,9,0,0,0,0,0,0,0,0,0,0
0,0,7,0,0,0,0,7,0,0,0,0,0,0,0,0,0,0
0,0,4,0,7,9,7,4,0,0,0,0,0,0,0,0,0,0
0,0,9,0,0,0,0,0,0,0,0,0,0,0,0,0,0,0
0,0,9,0,0,0,10,0,0,0,0,0,0,0,0,0,0,0
0,0,4,7,7,0,7,4,0,0,0,0,0,0,0,0,0,0
0,0,7,0,0,0,0,7,0,0,0,0,0,0,0,0,0,0
0,0,0,0,0,0,0,0,0,0,0,0,0,0,0,0,0,0
0,0,7,0,0,0,0,7,0,0,0,0,0,0,0,0,0,0
0,0,4,7,0,0,7,4,0,0,0,0,0,0,0,0,0,0
0,0,0,0,0,0,0,0,0,0,0,0,0,0,0,0,0,0
0,0,0,0,0,0,0,0,0,0,0,0,0,0,0,0,0,0
endlayer

layer
0,0,0,0,0,0,0,0,0,0,0,0,0,0,0,0,0,0
0,0,0,0,0,0,0,0,0,0,0,0,0,0,0,0,0,0
0,0,4,4,4,4,4,4,0,0,0,0,0,0,0,0,0,0
0,0,4,2,2,2,2,4,0,0,0,0,0,0,0,0,0,0
0,0,4,2,2,2,2,4,0,0,0,0,0,0,0,0,0,0
0,0,4,2,2,2,2,4,0,0,0,0,0,0,0,0,0,0
0,0,4,2,2,2,2,4,0,0,0,0,0,0,0,0,0,0
0,0,4,2,2,2,2,4,0,0,0,0,0,0,0,0,0,0
0,0,4,2,4,4,4,4,0,0,0,0,0,0,0,0,0,0
0,0,4,2,2,2,2,4,0,0,0,0,0,0,0,0,0,0
0,0,4,2,2,2,10,4,0,0,0,0,0,0,0,0,0,0
0,0,4,2,4,4,4,4,0,0,0,0,0,0,0,0,0,0
0,0,4,2,2,0,0,4,0,0,0,0,0,0,0,0,0,0
0,0,4,2,0,0,0,4,0,0,0,0,0,0,0,0,0,0
0,0,4,2,2,0,0,4,0,0,0,0,0,0,0,0,0,0
0,0,4,4,4,4,4,4,0,0,0,0,0,0,0,0,0,0
0,0,0,0,0,0,0,0,0,0,0,0,0,0,0,0,0,0
0,0,0,0,0,0,0,0,0,0,0,0,0,0,0,0,0,0
endlayer

layer
0,0,0,0,0,0,0,0,0,0,0,0,0,0,0,0,0,0
0,0,0,0,0,0,0,0,0,0,0,0,0,0,0,0,0,0
0,0,4,7,9,9,7,4,0,0,0,0,0,0,0,0,0,0
0,0,7,0,0,0,0,7,0,0,0,0,0,0,0,0,0,0
0,0,9,0,0,0,0,9,0,0,0,0,0,0,0,0,0,0
0,0,7,0,0,0,0,7,0,0,0,0,0,0,0,0,0,0
0,0,9,0,0,0,0,9,0,0,0,0,0,0,0,0,0,0
0,0,7,0,0,0,0,7,0,0,0,0,0,0,0,0,0,0
0,0,4,0,7,9,7,4,0,0,0,0,0,0,0,0,0,0
0,0,9,0,0,0,0,9,0,0,0,0,0,0,0,0,0,0
0,0,9,0,0,0,10,9,0,0,0,0,0,0,0,0,0,0
0,0,4,0,7,0,7,4,0,0,0,0,0,0,0,0,0,0
0,0,7,0,0,0,0,0,0,0,0,0,0,0,0,0,0,0
0,0,0,0,0,0,0,0,0,0,0,0,0,0,0,0,0,0
0,0,7,0,0,0,0,0,0,0,0,0,0,0,0,0,0,0
0,0,4,7,0,0,0,4,0,0,0,0,0,0,0,0,0,0
0,0,0,0,0,0,0,0,0,0,0,0,0,0,0,0,0,0
0,0,0,0,0,0,0,0,0,0,0,0,0,0,0,0,0,0
endlayer

layer
0,0,0,0,0,0,0,0,0,0,0,0,0,0,0,0,0,0
0,0,0,0,0,0,0,0,0,0,0,0,0,0,0,0,0,0
0,0,4,7,9,9,7,4,0,0,0,0,0,0,0,0,0,0
0,0,7,0,0,0,0,7,0,0,0,0,0,0,0,0,0,0
0,0,9,0,0,0,0,9,0,0,0,0,0,0,0,0,0,0
0,0,7,0,0,0,0,7,0,0,0,0,0,0,0,0,0,0
0,0,9,0,0,0,0,9,0,0,0,0,0,0,0,0,0,0
0,0,7,0,0,0,0,7,0,0,0,0,0,0,0,0,0,0
0,0,4,0,7,9,7,4,0,0,0,0,0,0,0,0,0,0
0,0,9,0,0,0,0,9,0,0,0,0,0,0,0,0,0,0
0,0,9,0,0,0,10,9,0,0,0,0,0,0,0,0,0,0
0,0,4,0,7,0,7,4,0,0,0,0,0,0,0,0,0,0
0,0,7,0,0,0,0,0,0,0,0,0,0,0,0,0,0,0
0,0,0,0,0,0,0,0,0,0,0,0,0,0,0,0,0,0
0,0,7,0,0,0,0,0,0,0,0,0,0,0,0,0,0,0
0,0,4,7,0,0,0,4,0,0,0,0,0,0,0,0,0,0
0,0,0,0,0,0,0,0,0,0,0,0,0,0,0,0,0,0
0,0,0,0,0,0,0,0,0,0,0,0,0,0,0,0,0,0
endlayer

layer
0,0,0,0,0,0,0,0,0,0,0,0,0,0,0,0,0,0
0,0,0,0,0,0,0,0,0,0,0,0,0,0,0,0,0,0
0,0,4,7,9,9,7,4,0,0,0,0,0,0,0,0,0,0
0,0,7,0,0,0,0,7,0,0,0,0,0,0,0,0,0,0
0,0,9,0,0,0,0,9,0,0,0,0,0,0,0,0,0,0
0,0,7,0,0,0,0,7,0,0,0,0,0,0,0,0,0,0
0,0,9,0,0,0,0,9,0,0,0,0,0,0,0,0,0,0
0,0,7,0,0,0,0,7,0,0,0,0,0,0,0,0,0,0
0,0,4,0,7,9,7,4,0,0,0,0,0,0,0,0,0,0
0,0,9,0,0,0,0,9,0,0,0,0,0,0,0,0,0,0
0,0,9,0,0,0,0,9,0,0,0,0,0,0,0,0,0,0
0,0,4,7,7,0,7,4,0,0,0,0,0,0,0,0,0,0
0,0,7,0,0,0,0,7,0,0,0,0,0,0,0,0,0,0
0,0,0,0,0,0,0,0,0,0,0,0,0,0,0,0,0,0
0,0,7,0,0,0,0,0,0,0,0,0,0,0,0,0,0,0
0,0,4,7,0,0,0,4,0,0,0,0,0,0,0,0,0,0
0,0,0,0,0,0,0,0,0,0,0,0,0,0,0,0,0,0
0,0,0,0,0,0,0,0,0,0,0,0,0,0,0,0,0,0
endlayer

layer
0,0,0,0,0,0,0,0,0,0,0,0,0,0,0,0,0,0
0,0,0,0,0,0,0,0,0,0,0,0,0,0,0,0,0,0
0,0,4,7,9,9,7,4,0,0,0,0,0,0,0,0,0,0
0,0,7,0,0,0,0,7,0,0,0,0,0,0,0,0,0,0
0,0,9,0,0,0,0,9,0,0,0,0,0,0,0,0,0,0
0,0,7,0,0,0,0,7,0,0,0,0,0,0,0,0,0,0
0,0,9,0,0,0,0,9,0,0,0,0,0,0,0,0,0,0
0,0,7,0,0,0,0,7,0,0,0,0,0,0,0,0,0,0
0,0,4,0,7,9,7,4,0,0,0,0,0,0,0,0,0,0
0,0,9,0,0,0,0,9,0,0,0,0,0,0,0,0,0,0
0,0,9,0,0,0,0,9,0,0,0,0,0,0,0,0,0,0
0,0,4,7,7,0,7,4,0,0,0,0,0,0,0,0,0,0
0,0,7,0,0,0,0,7,0,0,0,0,0,0,0,0,0,0
0,0,9,0,0,0,0,0,0,0,0,0,0,0,0,0,0,0
0,0,7,0,0,0,0,7,0,0,0,0,0,0,0,0,0,0
0,0,4,7,0,0,7,4,0,0,0,0,0,0,0,0,0,0
0,0,0,0,0,0,0,0,0,0,0,0,0,0,0,0,0,0
0,0,0,0,0,0,0,0,0,0,0,0,0,0,0,0,0,0
endlayer

layer
0,0,0,0,0,0,0,0,0,0,0,0,0,0,0,0,0,0
0,0,0,0,0,0,0,0,0,0,0,0,0,0,0,0,0,0
0,0,4,4,4,4,4,4,0,0,0,0,0,0,0,0,0,0
0,0,4,12,12,12,12,4,0,0,0,0,0,0,0,0,0,0
0,0,4,12,12,12,12,4,0,0,0,0,0,0,0,0,0,0
0,0,4,12,12,12,12,4,0,0,0,0,0,0,0,0,0,0
0,0,4,12,12,12,12,4,0,0,0,0,0,0,0,0,0,0
0,0,4,12,12,12,12,4,0,0,0,0,0,0,0,0,0,0
0,0,4,4,4,4,4,4,0,0,0,0,0,0,0,0,0,0
0,0,4,12,12,12,12,4,0,0,0,0,0,0,0,0,0,0
0,0,4,12,12,12,12,4,0,0,0,0,0,0,0,0,0,0
0,0,4,4,4,4,4,4,0,0,0,0,0,0,0,0,0,0
0,0,4,12,12,12,0,4,0,0,0,0,0,0,0,0,0,0
0,0,4,12,0,0,0,4,0,0,0,0,0,0,0,0,0,0
0,0,4,12,0,0,0,4,0,0,0,0,0,0,0,0,0,0
0,0,4,4,4,4,4,4,0,0,0,0,0,0,0,0,0,0
0,0,0,0,0,0,0,0,0,0,0,0,0,0,0,0,0,0
0,0,0,0,0,0,0,0,0,0,0,0,0,0,0,0,0,0
endlayer

