# Converted from schematic
# THIS TEMPLATE USES DEFAULTS!  Please edit for corrections.
# If you need help, consult template_rules.txt

weight=2
embed_into_distance=11
acceptable_target_blocks=1,2,3,12,13,250
dimensions=13,17,17
allowable_overhang=0
max_cut_in=2
cut_in_buffer=1
max_leveling=2
leveling_buffer=1
preserve_water=0
preserve_lava=0
preserve_plants=0


rule1=0,100,3134-10
rule2=0,100,2843-4
rule3=0,100,300
rule4=0,100,311
rule5=0,100,308,308,308,308,308,308,313,313,314,327
rule6=0,100,2542
rule7=0,100,2843-14,2843-14,2843-14,2843-14,2843
rule8=0,100,2761-5
rule9=0,100,2761-4
rule10=0,100,2761-10
rule11=0,100,2838-15
rule12=0,95,2835-2,2835-2,2835-2,2835-2,2835-2,2835-2,2835-2,2835-1,2835-1,2835-0
rule13=0,25,3225-3
rule14=0,100,2843-12
rule15=0,100,113
rule16=0,100,3134,3134,3134,3134-8,3134-2
rule17=0,95,300


layer
1,1,1,1,1,1,1,1,1,1,1,1,1,1,1,1,1
1,1,1,1,1,1,1,1,1,1,1,1,1,1,1,1,1
1,1,2,2,2,2,2,2,2,2,2,2,2,2,2,1,1
1,1,2,2,2,2,4,2,2,2,2,2,2,2,2,1,1
1,1,2,2,2,2,3,2,2,2,2,2,2,2,2,1,1
1,1,2,2,2,2,3,2,2,2,2,2,2,2,2,1,1
1,1,2,2,2,2,3,2,2,2,2,2,2,2,2,1,1
1,1,2,2,2,2,5,2,2,2,2,3,3,2,2,1,1
1,1,2,2,2,2,3,2,2,2,2,3,3,2,2,1,1
1,1,2,2,2,2,3,2,2,2,2,2,2,2,2,1,1
1,1,2,2,2,2,3,2,2,2,2,2,2,2,2,1,1
1,1,2,2,2,2,3,2,2,2,2,2,2,2,2,1,1
1,1,2,2,2,2,2,2,2,2,2,2,2,2,2,1,1
1,1,2,6,2,2,2,2,2,2,2,2,2,2,2,1,1
1,1,2,2,2,2,2,2,2,2,2,2,2,2,2,1,1
1,1,1,1,1,1,1,1,1,1,1,1,1,1,1,1,1
1,1,1,1,1,1,1,1,1,1,1,1,1,1,1,1,1
endlayer

layer
3,3,3,3,3,3,3,3,3,3,3,3,3,3,3,3,3
3,3,3,3,3,3,3,3,3,3,3,3,3,3,3,3,3
3,3,7,7,7,7,7,7,7,7,7,7,7,7,7,3,3
3,3,7,9,0,0,8,0,0,3,0,0,0,0,7,3,3
3,3,7,10,0,0,8,0,0,3,3,0,3,3,7,3,3
3,3,7,9,0,0,8,0,0,3,3,3,3,3,3,3,3
3,3,7,0,0,0,8,0,0,3,3,3,3,3,3,3,3
3,3,7,0,0,0,8,0,0,3,3,3,3,3,3,3,3
3,3,7,0,0,0,0,0,0,0,3,3,3,3,3,3,3
3,3,7,11,0,0,0,0,0,3,3,3,3,3,3,3,3
3,3,7,0,0,0,8,0,0,0,3,3,3,3,3,3,3
3,3,7,11,0,0,8,0,0,3,3,0,0,3,7,3,3
3,3,7,0,3,0,0,0,0,0,0,0,3,3,3,3,3
3,3,7,3,0,0,0,0,0,0,0,0,3,3,7,3,3
3,3,7,7,7,7,7,7,7,7,7,7,7,7,7,3,3
3,3,3,3,3,3,3,3,3,3,3,3,3,3,3,3,3
3,3,3,3,3,3,3,3,3,3,3,3,3,3,3,3,3
endlayer

layer
3,3,3,3,3,3,3,3,3,3,3,3,3,3,3,3,3
3,3,3,3,3,3,3,3,3,3,3,3,3,3,3,3,3
3,3,7,12,13,13,12,13,13,13,12,13,13,12,7,3,3
3,3,12,9,0,0,0,0,0,0,0,0,0,0,12,3,3
3,3,12,10,0,0,0,0,0,0,0,0,0,3,3,3,3
3,3,12,9,0,0,0,0,0,0,0,0,0,3,3,3,3
3,3,12,0,0,0,0,0,0,0,0,3,3,3,3,3,3
3,3,12,0,0,0,0,0,0,0,0,3,3,3,3,3,3
3,3,12,0,0,0,0,0,0,0,0,0,3,3,3,3,3
3,3,12,0,0,0,0,0,0,0,0,3,3,3,3,3,3
3,3,12,0,0,0,0,0,0,0,0,0,3,3,3,3,3
3,3,12,0,0,0,0,0,0,0,0,0,0,0,12,3,3
3,3,12,0,3,0,0,0,0,0,0,0,0,3,3,3,3
3,3,12,3,0,0,0,0,0,0,0,0,0,0,12,3,3
3,3,7,12,13,13,12,13,13,13,12,13,13,12,7,3,3
3,3,3,3,3,3,3,3,3,3,3,3,3,3,3,3,3
3,3,3,3,3,3,3,3,3,3,3,3,3,3,3,3,3
endlayer

layer
3,3,3,3,3,3,3,3,3,3,3,3,3,3,3,3,3
3,3,3,3,3,3,3,3,3,3,3,3,3,3,3,3,3
3,3,7,12,13,13,12,13,13,13,12,13,13,12,7,3,3
3,3,12,0,0,0,0,0,0,0,0,0,0,0,12,3,3
3,3,12,0,0,0,0,0,0,0,0,0,0,3,3,3,3
3,3,12,0,0,0,0,0,0,0,0,0,0,3,3,3,3
3,3,12,0,0,0,0,0,0,0,0,0,0,3,3,3,3
3,3,12,0,0,0,0,0,0,0,0,0,3,3,3,3,3
3,3,12,0,0,0,0,0,0,0,0,0,0,3,3,3,3
3,3,12,0,0,0,0,0,0,0,0,0,3,3,3,3,3
3,3,12,0,0,0,0,0,0,0,0,0,0,3,3,3,3
3,3,12,0,0,0,0,0,0,0,0,0,0,0,12,3,3
3,3,12,0,0,0,0,0,0,0,0,0,0,0,12,3,3
3,3,12,3,0,0,0,0,0,0,0,0,0,0,12,3,3
3,3,7,12,13,13,12,13,13,13,12,13,13,12,7,3,3
3,3,3,3,3,3,3,3,3,3,3,3,3,3,3,3,3
3,3,3,3,3,3,3,3,3,3,3,3,3,3,3,3,3
endlayer

layer
3,3,3,3,3,3,3,3,3,3,3,3,3,3,3,3,3
3,3,3,3,3,3,3,3,3,3,3,3,3,3,3,3,3
3,3,7,12,13,13,12,13,13,13,12,13,13,12,7,3,3
3,3,12,0,0,0,0,0,0,0,0,0,0,0,12,3,3
3,3,12,0,0,0,0,0,0,0,0,0,0,0,3,3,3
3,3,12,0,0,0,0,0,0,0,0,0,0,3,3,3,3
3,3,12,0,0,0,0,0,0,0,0,0,0,3,3,3,3
3,3,12,0,0,0,0,0,0,0,0,0,0,0,12,3,3
3,3,12,0,0,0,0,0,0,0,0,0,0,3,3,3,3
3,3,12,0,0,0,0,0,0,0,0,0,0,3,3,3,3
3,3,12,0,0,0,0,0,0,0,0,0,0,3,3,3,3
3,3,12,0,0,0,0,0,0,0,0,0,0,0,12,3,3
3,3,12,0,0,0,0,0,0,0,0,0,0,0,12,15,14
3,3,12,3,0,0,0,0,0,0,0,0,0,0,12,3,3
3,3,7,12,0,0,12,0,13,13,12,13,13,12,7,3,3
3,3,3,3,3,3,3,3,3,3,3,3,3,3,3,3,3
3,3,3,3,3,3,3,3,3,3,3,3,3,3,3,3,3
endlayer

layer
3,3,3,3,3,3,3,3,3,3,3,3,3,3,3,3,3
3,3,3,3,3,3,3,3,3,3,3,3,3,3,3,3,3
3,3,7,12,13,13,12,13,13,13,12,13,13,12,7,3,3
3,3,12,0,0,0,0,0,0,0,0,0,0,0,12,3,3
3,3,12,0,0,0,0,0,0,0,0,0,0,0,13,3,3
3,3,12,0,0,0,0,0,0,0,0,0,0,3,3,3,3
3,3,12,0,0,0,0,0,0,0,0,0,0,0,13,3,3
3,3,12,0,0,0,0,0,0,0,0,0,0,0,12,3,3
3,3,12,0,0,0,0,0,0,0,0,0,0,0,13,3,3
3,3,12,0,0,0,0,0,0,0,0,0,0,0,13,3,3
3,3,12,0,0,0,0,0,0,0,0,0,0,0,3,3,3
3,3,12,0,0,0,0,0,0,0,0,0,0,0,12,3,3
3,3,12,0,0,0,0,0,0,0,0,0,0,0,12,3,14
3,3,12,0,0,0,0,0,0,0,0,0,0,0,12,3,3
3,3,7,12,0,0,12,13,0,0,12,13,13,12,7,3,3
3,3,3,3,3,3,3,3,3,3,3,3,3,3,3,3,3
3,3,3,3,3,3,3,3,3,3,3,3,3,3,3,3,3
endlayer

layer
3,3,3,3,3,3,3,3,3,3,3,3,3,3,3,3,3
3,3,3,3,3,3,3,3,3,3,3,3,3,3,3,3,3
3,3,7,7,7,7,7,7,7,7,7,7,7,7,7,3,3
3,3,7,16,16,16,16,16,16,16,16,16,16,16,7,3,3
3,3,7,16,16,16,16,16,16,16,16,16,16,16,7,3,3
3,3,7,16,16,16,16,16,16,16,16,16,16,16,7,3,3
3,3,7,16,16,16,16,16,16,16,16,16,16,16,7,3,3
3,3,7,16,16,16,16,16,16,16,16,16,16,16,7,3,3
3,3,7,2,2,2,2,2,2,16,16,16,16,16,7,3,3
3,3,7,2,2,0,0,2,2,16,16,16,16,16,7,3,3
3,3,7,2,0,0,0,0,2,16,16,16,16,16,7,3,3
3,3,7,2,0,0,0,0,2,16,16,16,16,16,7,3,3
3,3,7,2,0,2,2,2,2,16,16,16,16,16,7,3,14
3,3,7,0,2,2,2,2,2,16,16,16,16,16,7,3,3
3,3,7,7,7,7,7,7,7,7,7,7,7,7,7,3,3
3,3,3,3,3,3,3,3,3,3,3,3,3,3,3,3,3
3,3,3,3,3,3,3,3,3,3,3,3,3,3,3,3,3
endlayer

layer
3,3,3,3,3,3,3,3,3,3,3,3,3,3,3,3,3
3,3,3,3,3,3,3,3,3,3,3,3,3,3,3,3,3
3,3,3,3,3,3,3,3,3,3,3,3,3,3,3,3,3
3,3,3,3,3,3,3,3,3,3,3,3,3,3,3,3,3
3,3,3,3,3,3,3,3,3,3,3,3,3,3,3,3,3
3,3,3,3,3,3,3,3,3,3,3,3,3,3,3,3,3
3,3,3,3,3,3,3,3,3,3,3,3,3,3,3,3,3
3,3,3,3,3,3,3,3,3,3,3,3,3,3,3,3,3
3,3,7,7,7,7,7,7,7,3,3,3,3,3,3,3,3
3,3,7,0,0,0,0,0,7,3,3,3,3,3,3,3,3
3,3,7,0,0,0,0,0,7,3,3,3,3,3,3,3,3
3,3,7,3,0,0,0,0,7,3,3,3,3,3,3,3,3
3,3,7,3,0,0,0,0,7,3,3,3,3,3,3,3,3
3,3,7,0,3,3,0,0,7,3,3,3,3,3,3,3,3
3,3,7,7,7,7,7,7,7,3,3,3,3,3,3,3,3
3,3,3,3,3,3,3,3,3,3,3,3,3,3,3,3,3
3,3,3,3,3,3,3,3,3,3,3,3,3,3,3,3,3
endlayer

layer
3,3,3,3,3,3,3,3,3,3,3,3,3,3,3,3,3
3,3,3,3,3,3,3,3,3,3,3,3,3,3,3,3,3
3,3,3,3,3,3,3,3,3,3,3,3,3,3,3,3,3
3,3,3,3,3,3,3,3,3,3,3,3,3,3,3,3,3
3,3,3,3,3,3,3,3,3,3,3,3,3,3,3,3,3
3,3,3,3,3,3,3,3,3,3,3,3,3,3,3,3,3
3,3,3,3,3,3,3,3,3,3,3,3,3,3,3,3,3
3,3,3,3,3,3,3,3,3,3,3,3,3,3,3,3,3
3,3,7,12,13,12,13,12,7,3,3,3,3,3,3,3,3
3,3,12,0,0,0,0,0,12,3,3,3,3,3,3,3,3
3,3,13,0,0,0,0,0,0,3,3,3,3,3,3,3,3
3,3,12,0,0,0,0,0,12,3,3,3,3,3,3,3,3
3,3,13,3,0,0,0,0,13,3,3,3,3,3,3,3,3
3,3,12,0,3,0,0,0,12,3,3,3,3,3,3,3,3
3,3,7,12,13,12,13,12,7,3,3,3,3,3,3,3,3
3,3,3,3,3,3,3,3,3,3,3,3,3,3,3,3,3
3,3,3,3,3,3,3,3,3,3,3,3,3,3,3,3,3
endlayer

layer
3,3,3,3,3,3,3,3,3,3,3,3,3,3,3,3,3
3,3,3,3,3,3,3,3,3,3,3,3,3,3,3,3,3
3,3,3,3,3,3,3,3,3,3,3,3,3,3,3,3,3
3,3,3,3,3,3,3,3,3,3,3,3,3,3,3,3,3
3,3,3,3,3,3,3,3,3,3,3,3,3,3,3,3,3
3,3,3,3,3,3,3,3,3,3,3,3,3,3,3,3,3
3,3,3,3,3,3,3,3,3,3,3,3,3,3,3,3,3
3,3,3,3,3,3,3,3,3,3,3,3,3,3,3,3,3
3,3,7,12,13,12,13,12,7,3,3,3,3,3,3,3,3
3,3,12,0,0,0,0,0,12,3,3,3,3,3,3,3,3
3,3,13,0,0,0,0,0,13,3,3,3,3,3,3,3,3
3,3,12,0,0,0,0,0,12,3,3,3,3,3,3,3,3
3,3,3,0,0,0,0,0,13,3,3,3,3,3,3,3,3
3,3,3,0,0,0,0,0,12,3,3,3,3,3,3,3,3
3,3,3,3,3,12,13,12,7,3,3,3,3,3,3,3,3
3,3,3,3,3,3,3,3,3,3,3,3,3,3,3,3,3
3,3,3,3,3,3,3,3,3,3,3,3,3,3,3,3,3
endlayer

layer
17,17,17,17,17,17,17,17,17,17,17,17,17,17,17,17,17
17,17,17,17,17,17,17,17,17,17,17,17,17,17,17,17,17
17,17,17,17,17,17,17,17,17,17,17,17,17,17,17,17,17
17,17,17,17,17,17,17,17,17,17,17,17,17,17,17,17,17
17,17,17,17,17,17,17,17,17,17,17,17,17,17,17,17,17
17,17,17,17,17,17,17,17,17,17,17,17,17,17,17,17,17
17,17,17,17,17,17,17,17,17,17,17,17,17,17,17,17,17
17,17,17,17,17,17,17,17,17,17,17,17,17,17,17,17,17
17,17,7,12,0,12,13,12,7,17,17,17,17,17,17,17,17
17,17,12,0,0,0,0,0,12,17,17,17,17,17,17,17,17
17,17,13,0,0,0,0,0,13,17,17,17,17,17,17,17,17
17,17,12,0,0,0,0,0,12,17,17,17,17,17,17,17,17
17,17,17,0,0,0,0,0,13,17,17,17,17,17,17,17,17
17,17,17,0,0,0,0,0,12,17,17,17,17,17,17,17,17
17,17,17,17,17,12,13,12,7,17,17,17,17,17,17,17,17
17,17,17,17,17,17,17,17,17,17,17,17,17,17,17,17,17
17,17,17,17,17,17,17,17,17,17,17,17,17,17,17,17,17
endlayer

layer
0,0,0,0,0,0,0,0,0,0,0,0,0,0,0,0,0
0,0,0,0,0,0,0,0,0,0,0,0,0,0,0,0,0
0,0,0,0,0,0,0,0,0,0,0,0,0,0,0,0,0
0,0,0,0,0,0,0,0,0,0,0,0,0,0,0,0,0
0,0,0,0,0,0,0,0,0,0,0,0,0,0,0,0,0
0,0,0,0,0,0,0,0,0,0,0,0,0,0,0,0,0
0,0,0,0,0,0,0,0,0,0,0,0,0,0,0,0,0
0,0,0,0,0,0,0,0,0,0,0,0,0,0,0,0,0
0,0,7,12,13,12,13,12,7,0,0,0,0,0,0,0,0
0,0,12,0,0,0,0,0,12,0,0,0,0,0,0,0,0
0,0,13,0,0,0,0,0,13,0,0,0,0,0,0,0,0
0,0,0,0,0,0,0,0,12,0,0,0,0,0,0,0,0
0,0,0,0,0,0,0,0,13,0,0,0,0,0,0,0,0
0,0,0,0,0,0,0,0,12,0,0,0,0,0,0,0,0
0,0,0,0,0,12,13,12,7,0,0,0,0,0,0,0,0
0,0,0,0,0,0,0,0,0,0,0,0,0,0,0,0,0
0,0,0,0,0,0,0,0,0,0,0,0,0,0,0,0,0
endlayer

layer
0,0,0,0,0,0,0,0,0,0,0,0,0,0,0,0,0
0,0,0,0,0,0,0,0,0,0,0,0,0,0,0,0,0
0,0,0,0,0,0,0,0,0,0,0,0,0,0,0,0,0
0,0,0,0,0,0,0,0,0,0,0,0,0,0,0,0,0
0,0,0,0,0,0,0,0,0,0,0,0,0,0,0,0,0
0,0,0,0,0,0,0,0,0,0,0,0,0,0,0,0,0
0,0,0,0,0,0,0,0,0,0,0,0,0,0,0,0,0
0,0,0,0,0,0,0,0,0,0,0,0,0,0,0,0,0
0,0,7,7,7,7,7,7,7,0,0,0,0,0,0,0,0
0,0,7,0,0,16,16,16,7,0,0,0,0,0,0,0,0
0,0,7,0,0,0,16,16,7,0,0,0,0,0,0,0,0
0,0,0,0,0,0,0,16,7,0,0,0,0,0,0,0,0
0,0,0,0,0,0,0,16,7,0,0,0,0,0,0,0,0
0,0,0,0,0,0,0,16,7,0,0,0,0,0,0,0,0
0,0,0,0,7,7,7,7,7,0,0,0,0,0,0,0,0
0,0,0,0,0,0,0,0,0,0,0,0,0,0,0,0,0
0,0,0,0,0,0,0,0,0,0,0,0,0,0,0,0,0
endlayer

