# Converted from schematic
# THIS TEMPLATE USES DEFAULTS!  Please edit for corrections.
# If you need help, consult template_rules.txt

weight=1
embed_into_distance=11
acceptable_target_blocks=1,2,3,12,13,250
dimensions=13,17,17
allowable_overhang=0
max_cut_in=2
cut_in_buffer=1
max_leveling=2
leveling_buffer=1
preserve_water=0
preserve_lava=0
preserve_plants=0


rule1=0,100,3134-10
rule2=0,100,2843-4
rule3=0,100,311
rule4=0,100,300
rule5=0,100,308,308,308,308,308,308,313,313,314,327
rule6=0,100,2542
rule7=0,100,2843-14,2843-14,2843-14,2843-14,2843
rule8=0,65,2291
rule9=0,65,2245
rule10=0,100,2761-5
rule11=0,100,2761-4
rule12=0,100,2761-10
rule13=0,50,3192
rule14=0,100,25
rule15=0,100,2838-15
rule16=0,95,2835-2,2835-2,2835-2,2835-2,2835-2,2835-2,2835-2,2835-1,2835-1,2835-0
rule17=0,25,3225-3
rule18=0,100,2838-14
rule19=0,100,2843-12
rule20=0,100,113
rule21=0,100,3134,3134,3134,3134-8,3134-2
rule22=0,100,2013
rule23=0,100,2013-1,2013-2,2013-3,2013-4,2013-5,2013-6,2013-7,2013-8,2013-9,2013-10,2013-11,2013-12,2013-13,2013-14,2013-15
rule24=0,100,5
rule25=0,100,126-8
rule26=0,100,140-10
rule27=0,95,300


layer
1,1,1,1,1,1,1,1,1,1,1,1,1,1,1,1,1
1,1,1,1,1,1,1,1,1,1,1,1,1,1,1,1,1
1,1,2,2,2,2,2,2,2,2,2,2,2,2,2,1,1
1,1,2,2,2,2,3,2,2,2,2,2,2,2,2,1,1
1,1,2,2,2,2,4,2,2,2,2,2,2,2,2,1,1
1,1,2,2,2,2,4,2,2,2,2,2,2,2,2,1,1
1,1,2,2,2,2,4,2,2,2,2,2,2,2,2,1,1
1,1,2,2,2,2,5,2,2,2,2,2,2,2,2,1,1
1,1,2,2,2,2,4,2,2,2,2,2,2,2,2,1,1
1,1,2,2,2,2,4,2,2,2,2,2,2,2,2,1,1
1,1,2,2,2,2,4,2,2,2,2,2,2,2,2,1,1
1,1,2,2,2,2,4,2,2,2,2,2,2,2,2,1,1
1,1,2,2,2,2,2,2,2,2,2,2,2,2,2,1,1
1,1,2,6,2,2,2,2,2,2,2,2,2,2,2,1,1
1,1,2,2,2,2,2,2,2,2,2,2,2,2,2,1,1
1,1,1,1,1,1,1,1,1,1,1,1,1,1,1,1,1
1,1,1,1,1,1,1,1,1,1,1,1,1,1,1,1,1
endlayer

layer
4,4,4,4,4,4,4,4,4,4,4,4,4,4,4,4,4
4,4,4,4,4,4,4,4,4,4,4,4,4,4,4,4,4
4,4,7,7,7,7,7,7,7,7,7,7,7,7,7,4,4
4,4,7,11,0,0,10,0,0,8,0,8,8,0,7,4,4
4,4,7,12,0,0,10,8,0,9,0,9,9,0,7,4,4
4,4,7,11,0,0,10,8,0,8,0,8,8,0,7,4,4
4,4,7,13,0,0,10,8,0,0,0,0,0,0,7,4,4
4,4,7,13,0,0,10,8,0,8,0,8,8,0,7,4,4
4,4,7,14,0,0,10,8,0,9,0,9,9,0,7,4,4
4,4,7,15,0,0,10,8,0,8,0,8,8,0,7,4,4
4,4,7,15,0,0,10,8,0,0,0,0,0,0,7,4,4
4,4,7,15,0,0,10,0,0,0,0,0,4,4,7,4,4
4,4,7,0,0,0,0,0,0,0,0,4,4,4,4,4,4
4,4,7,0,0,0,0,0,0,0,0,0,4,4,7,4,4
4,4,7,7,7,7,7,7,7,7,7,7,7,7,7,4,4
4,4,4,4,4,4,4,4,4,4,4,4,4,4,4,4,4
4,4,4,4,4,4,4,4,4,4,4,4,4,4,4,4,4
endlayer

layer
4,4,4,4,4,4,4,4,4,4,4,4,4,4,4,4,4
4,4,4,4,4,4,4,4,4,4,4,4,4,4,4,4,4
4,4,7,16,17,17,16,17,17,17,16,17,17,16,7,4,4
4,4,16,11,0,0,0,0,0,0,0,0,0,0,16,4,4
4,4,16,12,0,0,0,0,0,0,0,0,0,0,17,4,4
4,4,16,11,0,0,0,0,0,0,0,0,0,0,17,4,4
4,4,16,0,0,0,0,0,0,0,0,0,0,0,17,4,4
4,4,16,0,0,0,0,0,0,0,0,0,0,0,16,4,4
4,4,16,0,0,0,0,0,0,0,0,0,0,0,17,4,4
4,4,16,0,0,0,0,0,0,0,0,0,0,0,17,4,4
4,4,16,0,0,0,0,0,0,0,0,0,0,0,17,4,4
4,4,16,18,0,0,0,0,0,0,0,0,0,0,16,4,4
4,4,16,0,0,0,0,0,0,0,0,0,0,4,4,4,4
4,4,16,0,0,0,0,0,0,0,0,0,0,0,16,4,4
4,4,7,16,17,17,16,17,17,17,16,17,17,16,7,4,4
4,4,4,4,4,4,4,4,4,4,4,4,4,4,4,4,4
4,4,4,4,4,4,4,4,4,4,4,4,4,4,4,4,4
endlayer

layer
4,4,4,4,4,4,4,4,4,4,4,4,4,4,4,4,4
4,4,4,4,4,4,4,4,4,4,4,4,4,4,4,4,4
4,4,7,16,17,17,16,17,17,17,16,17,17,16,7,4,4
4,4,16,0,0,0,0,0,0,0,0,0,0,0,16,4,4
4,4,16,0,0,0,0,0,0,0,0,0,0,0,17,4,4
4,4,16,0,0,0,0,0,0,0,0,0,0,0,17,4,4
4,4,16,0,0,0,0,0,0,0,0,0,0,0,17,4,4
4,4,16,0,0,0,0,0,0,0,0,0,0,0,16,4,4
4,4,16,0,0,0,0,0,0,0,0,0,0,0,17,4,4
4,4,16,0,0,0,0,0,0,0,0,0,0,0,17,4,4
4,4,16,0,0,0,0,0,0,0,0,0,0,0,17,4,4
4,4,16,0,0,0,0,0,0,0,0,0,0,0,16,4,4
4,4,16,0,0,0,0,0,0,0,0,0,0,0,16,4,4
4,4,16,0,0,0,0,0,0,0,0,0,0,0,16,4,4
4,4,7,16,17,17,16,17,17,17,16,17,17,16,7,4,4
4,4,4,4,4,4,4,4,4,4,4,4,4,4,4,4,4
4,4,4,4,4,4,4,4,4,4,4,4,4,4,4,4,4
endlayer

layer
4,4,4,4,4,4,4,4,4,4,4,4,4,4,4,4,4
4,4,4,4,4,4,4,4,4,4,4,4,4,4,4,4,4
4,4,7,16,17,17,16,17,17,17,16,17,17,16,7,4,4
4,4,16,0,0,0,0,0,0,0,0,0,0,0,16,4,4
4,4,16,0,0,0,0,0,0,0,0,0,0,0,17,4,4
4,4,16,0,0,0,0,0,0,0,0,0,0,0,17,4,4
4,4,16,0,0,0,0,0,0,0,0,0,0,0,17,4,4
4,4,16,0,0,0,0,0,0,0,0,0,0,0,16,4,4
4,4,16,0,0,0,0,0,0,0,0,0,0,0,17,4,4
4,4,16,0,0,0,0,0,0,0,0,0,0,0,17,4,4
4,4,16,0,0,0,0,0,0,0,0,0,0,0,17,4,4
4,4,16,0,0,0,0,0,0,0,0,0,0,0,16,4,4
4,4,16,0,0,0,0,0,0,0,0,0,0,0,16,20,19
4,4,16,0,0,0,0,0,0,0,0,0,0,0,16,4,4
4,4,7,16,17,17,16,17,17,17,16,17,17,16,7,4,4
4,4,4,4,4,4,4,4,4,4,4,4,4,4,4,4,4
4,4,4,4,4,4,4,4,4,4,4,4,4,4,4,4,4
endlayer

layer
4,4,4,4,4,4,4,4,4,4,4,4,4,4,4,4,4
4,4,4,4,4,4,4,4,4,4,4,4,4,4,4,4,4
4,4,7,16,17,17,16,17,17,17,16,17,17,16,7,4,4
4,4,16,0,0,0,0,0,0,0,0,0,0,0,16,4,4
4,4,16,0,0,0,0,0,0,0,0,0,0,0,17,4,4
4,4,16,0,0,0,0,0,0,0,0,0,0,0,17,4,4
4,4,16,0,0,0,0,0,0,0,0,0,0,0,17,4,4
4,4,16,0,0,0,0,0,0,0,0,0,0,0,16,4,4
4,4,16,0,0,0,0,0,0,0,0,0,0,0,17,4,4
4,4,16,0,0,0,0,0,0,0,0,0,0,0,17,4,4
4,4,16,0,0,0,0,0,0,0,0,0,0,0,17,4,4
4,4,16,0,0,0,0,0,0,0,0,0,0,0,16,4,4
4,4,16,0,0,0,0,0,0,0,0,0,0,0,16,4,19
4,4,16,0,0,0,0,0,0,0,0,0,0,0,16,4,4
4,4,7,16,17,17,16,17,17,17,16,17,17,16,7,4,4
4,4,4,4,4,4,4,4,4,4,4,4,4,4,4,4,4
4,4,4,4,4,4,4,4,4,4,4,4,4,4,4,4,4
endlayer

layer
4,4,4,4,4,4,4,4,4,4,4,4,4,4,4,4,4
4,4,4,4,4,4,4,4,4,4,4,4,4,4,4,4,4
4,4,7,7,7,7,7,7,7,7,7,7,7,7,7,4,4
4,4,7,21,21,21,21,21,21,21,21,21,21,21,7,4,4
4,4,7,21,21,21,21,21,21,21,21,21,21,21,7,4,4
4,4,7,21,21,21,21,21,21,21,21,21,21,21,7,4,4
4,4,7,21,21,21,21,21,21,21,21,21,21,21,7,4,4
4,4,7,21,21,21,21,21,21,21,21,21,21,21,7,4,4
4,4,7,2,2,2,2,2,2,21,21,21,21,21,7,4,4
4,4,7,2,2,2,2,2,2,21,21,21,21,21,7,4,4
4,4,7,2,2,2,2,2,2,21,21,21,21,21,7,4,4
4,4,7,2,2,2,2,2,2,21,21,21,21,21,7,4,4
4,4,7,2,2,2,2,2,2,21,21,21,21,21,7,4,19
4,4,7,6,2,2,2,2,2,21,21,21,21,21,7,4,4
4,4,7,7,7,7,7,7,7,7,7,7,7,7,7,4,4
4,4,4,4,4,4,4,4,4,4,4,4,4,4,4,4,4
4,4,4,4,4,4,4,4,4,4,4,4,4,4,4,4,4
endlayer

layer
4,4,4,4,4,4,4,4,4,4,4,4,4,4,4,4,4
4,4,4,4,4,4,4,4,4,4,4,4,4,4,4,4,4
4,4,4,4,4,4,4,4,4,4,4,4,4,4,4,4,4
4,4,4,4,4,4,4,4,4,4,4,4,4,4,4,4,4
4,4,4,4,4,4,4,4,4,4,4,4,4,4,4,4,4
4,4,4,4,4,4,4,4,4,4,4,4,4,4,4,4,4
4,4,4,4,4,4,4,4,4,4,4,4,4,4,4,4,4
4,4,4,4,4,4,4,4,4,4,4,4,4,4,4,4,4
4,4,7,7,7,7,7,7,7,4,4,4,4,4,4,4,4
4,4,7,24,0,9,22,9,7,4,4,4,4,4,4,4,4
4,4,7,25,0,0,23,0,7,4,4,4,4,4,4,4,4
4,4,7,24,0,0,0,0,7,4,4,4,4,4,4,4,4
4,4,7,0,0,0,0,0,7,4,4,4,4,4,4,4,4
4,4,7,0,0,0,0,0,7,4,4,4,4,4,4,4,4
4,4,7,7,7,7,7,7,7,4,4,4,4,4,4,4,4
4,4,4,4,4,4,4,4,4,4,4,4,4,4,4,4,4
4,4,4,4,4,4,4,4,4,4,4,4,4,4,4,4,4
endlayer

layer
4,4,4,4,4,4,4,4,4,4,4,4,4,4,4,4,4
4,4,4,4,4,4,4,4,4,4,4,4,4,4,4,4,4
4,4,4,4,4,4,4,4,4,4,4,4,4,4,4,4,4
4,4,4,4,4,4,4,4,4,4,4,4,4,4,4,4,4
4,4,4,4,4,4,4,4,4,4,4,4,4,4,4,4,4
4,4,4,4,4,4,4,4,4,4,4,4,4,4,4,4,4
4,4,4,4,4,4,4,4,4,4,4,4,4,4,4,4,4
4,4,4,4,4,4,4,4,4,4,4,4,4,4,4,4,4
4,4,7,16,17,16,17,16,7,4,4,4,4,4,4,4,4
4,4,16,26,0,0,0,0,16,4,4,4,4,4,4,4,4
4,4,17,0,0,0,0,0,17,4,4,4,4,4,4,4,4
4,4,16,0,0,0,0,0,16,4,4,4,4,4,4,4,4
4,4,17,0,0,0,0,0,17,4,4,4,4,4,4,4,4
4,4,16,0,0,0,0,0,16,4,4,4,4,4,4,4,4
4,4,7,16,17,16,17,16,7,4,4,4,4,4,4,4,4
4,4,4,4,4,4,4,4,4,4,4,4,4,4,4,4,4
4,4,4,4,4,4,4,4,4,4,4,4,4,4,4,4,4
endlayer

layer
4,4,4,4,4,4,4,4,4,4,4,4,4,4,4,4,4
4,4,4,4,4,4,4,4,4,4,4,4,4,4,4,4,4
4,4,4,4,4,4,4,4,4,4,4,4,4,4,4,4,4
4,4,4,4,4,4,4,4,4,4,4,4,4,4,4,4,4
4,4,4,4,4,4,4,4,4,4,4,4,4,4,4,4,4
4,4,4,4,4,4,4,4,4,4,4,4,4,4,4,4,4
4,4,4,4,4,4,4,4,4,4,4,4,4,4,4,4,4
4,4,4,4,4,4,4,4,4,4,4,4,4,4,4,4,4
4,4,7,16,17,16,17,16,7,4,4,4,4,4,4,4,4
4,4,16,0,0,0,0,0,16,4,4,4,4,4,4,4,4
4,4,17,0,0,0,0,0,17,4,4,4,4,4,4,4,4
4,4,16,0,0,0,0,0,16,4,4,4,4,4,4,4,4
4,4,17,0,0,0,0,0,17,4,4,4,4,4,4,4,4
4,4,16,0,0,0,0,0,16,4,4,4,4,4,4,4,4
4,4,7,16,17,16,17,16,7,4,4,4,4,4,4,4,4
4,4,4,4,4,4,4,4,4,4,4,4,4,4,4,4,4
4,4,4,4,4,4,4,4,4,4,4,4,4,4,4,4,4
endlayer

layer
27,27,27,27,27,27,27,27,27,27,27,27,27,27,27,27,27
27,27,27,27,27,27,27,27,27,27,27,27,27,27,27,27,27
27,27,27,27,27,27,27,27,27,27,27,27,27,27,27,27,27
27,27,27,27,27,27,27,27,27,27,27,27,27,27,27,27,27
27,27,27,27,27,27,27,27,27,27,27,27,27,27,27,27,27
27,27,27,27,27,27,27,27,27,27,27,27,27,27,27,27,27
27,27,27,27,27,27,27,27,27,27,27,27,27,27,27,27,27
27,27,27,27,27,27,27,27,27,27,27,27,27,27,27,27,27
27,27,7,16,17,16,17,16,7,27,27,27,27,27,27,27,27
27,27,16,0,0,0,0,0,16,27,27,27,27,27,27,27,27
27,27,17,0,0,0,0,0,17,27,27,27,27,27,27,27,27
27,27,16,0,0,0,0,0,16,27,27,27,27,27,27,27,27
27,27,17,0,0,0,0,0,17,27,27,27,27,27,27,27,27
27,27,16,0,0,0,0,0,16,27,27,27,27,27,27,27,27
27,27,7,16,17,16,17,16,7,27,27,27,27,27,27,27,27
27,27,27,27,27,27,27,27,27,27,27,27,27,27,27,27,27
27,27,27,27,27,27,27,27,27,27,27,27,27,27,27,27,27
endlayer

layer
0,0,0,0,0,0,0,0,0,0,0,0,0,0,0,0,0
0,0,0,0,0,0,0,0,0,0,0,0,0,0,0,0,0
0,0,0,0,0,0,0,0,0,0,0,0,0,0,0,0,0
0,0,0,0,0,0,0,0,0,0,0,0,0,0,0,0,0
0,0,0,0,0,0,0,0,0,0,0,0,0,0,0,0,0
0,0,0,0,0,0,0,0,0,0,0,0,0,0,0,0,0
0,0,0,0,0,0,0,0,0,0,0,0,0,0,0,0,0
0,0,0,0,0,0,0,0,0,0,0,0,0,0,0,0,0
0,0,7,16,17,16,17,16,7,0,0,0,0,0,0,0,0
0,0,16,0,0,0,0,0,16,0,0,0,0,0,0,0,0
0,0,17,0,0,0,0,0,17,0,0,0,0,0,0,0,0
0,0,16,0,0,0,0,0,16,0,0,0,0,0,0,0,0
0,0,17,0,0,0,0,0,17,0,0,0,0,0,0,0,0
0,0,16,0,0,0,0,0,16,0,0,0,0,0,0,0,0
0,0,7,16,17,16,17,16,7,0,0,0,0,0,0,0,0
0,0,0,0,0,0,0,0,0,0,0,0,0,0,0,0,0
0,0,0,0,0,0,0,0,0,0,0,0,0,0,0,0,0
endlayer

layer
0,0,0,0,0,0,0,0,0,0,0,0,0,0,0,0,0
0,0,0,0,0,0,0,0,0,0,0,0,0,0,0,0,0
0,0,0,0,0,0,0,0,0,0,0,0,0,0,0,0,0
0,0,0,0,0,0,0,0,0,0,0,0,0,0,0,0,0
0,0,0,0,0,0,0,0,0,0,0,0,0,0,0,0,0
0,0,0,0,0,0,0,0,0,0,0,0,0,0,0,0,0
0,0,0,0,0,0,0,0,0,0,0,0,0,0,0,0,0
0,0,0,0,0,0,0,0,0,0,0,0,0,0,0,0,0
0,0,7,7,7,7,7,7,7,0,0,0,0,0,0,0,0
0,0,7,21,21,21,21,21,7,0,0,0,0,0,0,0,0
0,0,7,21,21,21,21,21,7,0,0,0,0,0,0,0,0
0,0,7,21,21,21,21,21,7,0,0,0,0,0,0,0,0
0,0,7,21,21,21,21,21,7,0,0,0,0,0,0,0,0
0,0,7,21,21,21,21,21,7,0,0,0,0,0,0,0,0
0,0,7,7,7,7,7,7,7,0,0,0,0,0,0,0,0
0,0,0,0,0,0,0,0,0,0,0,0,0,0,0,0,0
0,0,0,0,0,0,0,0,0,0,0,0,0,0,0,0,0
endlayer

