
biomesToSpawnIn=kelp forest,ocean,ocean oil field,oceanic abyss,coral reef,frozenocean,desert,dust planet
weight=2
embed_into_distance=8
acceptable_target_blocks=1,2,3,12,13,250
dimensions=22,34,26
allowable_overhang=0
max_cut_in=2
cut_in_buffer=1
max_leveling=2
leveling_buffer=1
preserve_water=0
preserve_lava=0
preserve_plants=0


rule1=0,100,250
rule2=0,100,2761-15,2761-15,2761-15,2762-13,2762-13,2762-13,2762-13,2762-13,2762-13,2762-13
rule3=0,100,2835-6
rule4=0,100,2835-7
rule5=0,100,3134-10
rule6=0,100,3,250,250,250,250,250,250,250,250,250
rule7=0,100,2843-4
rule8=0,66,311
rule9=0,100,2542-0
rule10=0,100,2761-9
rule11=0,100,2843-14,2843-14,2843-14,2843-14,2843
rule12=0,100,2844-12
rule13=0,100,2291-0
rule14=0,100,2843-12
rule15=0,100,47,2837-5,2837-1,250
rule16=0,100,2248-0
rule17=0,75,308,308,308,308,308,308,313,313,314,327
rule18=0,100,5
rule19=0,100,3123-5
rule20=0,95,2835-2,2835-2,2835-2,2835-2,2835-2,2835-2,2835-2,2835-1,2835-1,2835-0
rule21=0,66,3225-3
rule22=0,100,2765-11
rule23=0,95,300
rule24=0,100,2761-5
rule25=0,100,2291-1
rule26=0,100,2245-1
rule27=0,100,2778-10
rule28=0,100,2844-4
rule29=0,100,2248-1
rule30=0,100,2844-9
rule31=0,100,2761-10
rule32=0,100,2765-6
rule33=0,100,2766-3
rule34=0,25,2244-5
rule35=0,66,140-10
rule36=0,100,2844-14
rule37=0,100,2765-15
rule38=0,100,2761-2
rule39=0,100,2763-4
rule40=0,100,2788-9


layer
1,1,1,1,1,1,1,1,1,1,1,1,1,1,1,1,1,1,1,1,1,1,1,1,1,1
1,1,1,1,1,1,1,1,1,1,1,1,1,1,1,1,1,1,1,1,1,1,1,1,1,1
1,1,1,1,1,1,1,1,1,1,1,1,1,1,1,1,1,1,1,1,1,1,1,1,1,1
1,1,1,1,1,1,1,1,1,1,1,1,1,1,1,1,1,1,1,1,1,1,1,1,1,1
1,1,1,1,1,1,2,2,2,2,2,2,2,1,1,1,1,1,1,1,1,1,1,1,1,1
1,1,1,1,1,1,2,2,2,2,2,2,2,1,1,1,1,1,1,1,1,1,1,1,1,1
1,1,1,1,1,1,2,2,2,2,2,2,2,1,1,1,1,1,1,1,1,1,1,1,1,1
1,1,1,1,1,1,2,2,2,2,2,2,2,1,1,1,1,1,1,1,1,1,1,1,1,1
1,1,1,1,1,1,2,2,2,2,2,2,2,1,1,1,1,1,1,1,1,1,1,1,1,1
1,1,1,1,1,1,2,2,2,2,2,2,2,1,1,1,1,1,1,1,1,1,1,1,1,1
1,1,1,1,1,1,2,2,2,2,2,2,2,1,1,1,1,1,1,1,1,1,1,1,1,1
1,1,1,1,1,1,1,1,1,1,1,1,1,1,1,1,1,1,1,1,1,1,1,1,1,1
1,1,1,1,1,1,1,1,1,1,1,1,1,1,1,1,1,1,1,1,1,1,1,1,1,1
1,1,1,1,1,1,1,1,1,1,1,1,1,1,1,1,1,1,1,1,1,1,1,1,1,1
1,1,1,1,1,1,1,1,1,1,1,1,1,1,1,1,1,1,1,1,1,1,1,1,1,1
1,1,1,1,1,1,1,1,1,1,1,1,1,1,1,1,1,1,1,1,1,1,1,1,1,1
1,1,1,1,1,1,1,1,1,1,1,1,1,1,1,1,1,1,1,1,1,1,1,1,1,1
1,1,1,1,1,1,1,1,1,1,1,1,1,1,1,1,1,1,1,1,1,1,1,1,1,1
1,1,1,1,1,1,1,1,1,1,1,1,1,1,1,1,1,1,1,1,1,1,1,1,1,1
1,1,1,1,1,1,1,1,1,1,1,1,1,1,1,1,1,1,1,1,1,1,1,1,1,1
1,1,1,1,1,1,1,1,1,1,1,1,1,1,1,1,1,1,1,1,1,1,1,1,1,1
1,1,1,1,1,1,1,1,1,1,1,1,1,1,1,1,1,1,1,1,1,1,1,1,1,1
1,1,1,1,1,1,1,1,1,1,1,1,1,1,1,1,1,1,1,1,1,1,1,1,1,1
1,1,1,1,1,1,2,2,2,2,2,2,2,1,1,1,1,1,1,1,1,1,1,1,1,1
1,1,1,1,1,1,2,2,2,2,2,2,2,1,1,1,1,1,1,1,1,1,1,1,1,1
1,1,1,1,1,1,2,2,2,2,2,2,2,1,1,1,1,1,1,1,1,1,1,1,1,1
1,1,1,1,1,1,2,2,2,2,2,2,2,1,1,1,1,1,1,1,1,1,1,1,1,1
1,1,1,1,1,1,2,2,2,2,2,2,2,1,1,1,1,1,1,1,1,1,1,1,1,1
1,1,1,1,1,1,2,2,2,2,2,2,2,1,1,1,1,1,1,1,1,1,1,1,1,1
1,1,1,1,1,1,2,2,2,2,2,2,2,1,1,1,1,1,1,1,1,1,1,1,1,1
1,1,1,1,1,1,1,1,1,1,1,1,1,1,1,1,1,1,1,1,1,1,1,1,1,1
1,1,1,1,1,1,1,1,1,1,1,1,1,1,1,1,1,1,1,1,1,1,1,1,1,1
1,1,1,1,1,1,1,1,1,1,1,1,1,1,1,1,1,1,1,1,1,1,1,1,1,1
1,1,1,1,1,1,1,1,1,1,1,1,1,1,1,1,1,1,1,1,1,1,1,1,1,1
endlayer

layer
1,1,1,1,1,1,1,1,1,1,1,1,1,1,1,1,1,1,1,1,1,1,1,1,1,1
1,1,1,1,1,1,1,1,1,1,1,1,1,1,1,1,1,1,1,1,1,1,1,1,1,1
1,1,1,1,1,1,1,1,1,1,1,1,1,1,1,1,1,1,1,1,1,1,1,1,1,1
1,1,1,1,1,1,1,1,1,1,1,1,1,1,1,1,1,1,1,1,1,1,1,1,1,1
1,1,1,1,1,1,2,2,2,2,2,2,2,1,1,1,1,1,1,1,1,1,1,1,1,1
1,1,1,1,1,1,2,1,1,1,1,1,2,1,1,1,1,1,1,1,1,1,1,1,1,1
1,1,1,1,1,1,2,1,1,1,1,1,2,1,1,1,1,1,1,1,1,1,1,1,1,1
1,1,1,1,1,1,2,1,1,3,1,1,2,1,1,1,1,1,1,1,1,1,1,1,1,1
1,1,1,1,1,1,2,1,1,1,1,1,2,1,1,1,1,1,1,1,1,1,1,1,1,1
1,1,1,1,1,1,2,1,1,1,1,1,2,1,1,1,1,1,1,1,1,1,1,1,1,1
1,1,1,1,1,1,2,2,2,2,2,2,2,1,1,1,1,1,1,1,1,1,1,1,1,1
1,1,1,1,1,1,1,1,1,1,1,1,1,1,1,1,1,1,1,1,1,1,1,1,1,1
1,1,1,1,1,1,1,1,1,1,1,1,1,1,1,1,1,1,1,1,1,1,1,1,1,1
1,1,1,1,1,1,1,1,1,1,1,1,1,1,1,1,1,1,1,1,1,1,1,1,1,1
1,1,1,1,1,1,1,1,1,1,1,1,1,1,1,1,1,1,1,1,1,1,1,1,1,1
1,1,1,1,1,1,1,1,1,1,1,1,1,1,1,1,1,1,1,1,1,1,1,1,1,1
1,1,1,1,1,1,1,1,1,1,1,1,1,1,1,1,1,1,1,1,1,1,1,1,1,1
1,1,1,1,1,1,1,1,1,1,1,1,1,1,1,1,1,1,1,1,1,1,1,1,1,1
1,1,1,1,1,1,1,1,1,1,1,1,1,1,1,1,1,1,1,1,1,1,1,1,1,1
1,1,1,1,1,1,1,1,1,1,1,1,1,1,1,1,1,1,1,1,1,1,1,1,1,1
1,1,1,1,1,1,1,1,1,1,1,1,1,1,1,1,1,1,1,1,1,1,1,1,1,1
1,1,1,1,1,1,1,1,1,1,1,1,1,1,1,1,1,1,1,1,1,1,1,1,1,1
1,1,1,1,1,1,1,1,1,1,1,1,1,1,1,1,1,1,1,1,1,1,1,1,1,1
1,1,1,1,1,1,2,2,2,2,2,2,2,1,1,1,1,1,1,1,1,1,1,1,1,1
1,1,1,1,1,1,2,1,1,1,1,1,2,1,1,1,1,1,1,1,1,1,1,1,1,1
1,1,1,1,1,1,2,1,1,1,1,1,2,1,1,1,1,1,1,1,1,1,1,1,1,1
1,1,1,1,1,1,2,1,1,3,1,1,2,1,1,1,1,1,1,1,1,1,1,1,1,1
1,1,1,1,1,1,2,1,1,1,1,1,2,1,1,1,1,1,1,1,1,1,1,1,1,1
1,1,1,1,1,1,2,1,1,1,1,1,2,1,1,1,1,1,1,1,1,1,1,1,1,1
1,1,1,1,1,1,2,2,2,2,2,2,2,1,1,1,1,1,1,1,1,1,1,1,1,1
1,1,1,1,1,1,1,1,1,1,1,1,1,1,1,1,1,1,1,1,1,1,1,1,1,1
1,1,1,1,1,1,1,1,1,1,1,1,1,1,1,1,1,1,1,1,1,1,1,1,1,1
1,1,1,1,1,1,1,1,1,1,1,1,1,1,1,1,1,1,1,1,1,1,1,1,1,1
1,1,1,1,1,1,1,1,1,1,1,1,1,1,1,1,1,1,1,1,1,1,1,1,1,1
endlayer

layer
1,1,1,1,1,1,1,1,1,1,1,1,1,1,1,1,1,1,1,1,1,1,1,1,1,1
1,1,1,1,1,1,1,1,1,1,1,1,1,1,1,1,1,1,1,1,1,1,1,1,1,1
1,1,1,1,1,1,1,1,1,1,1,1,1,1,1,1,1,1,1,1,1,1,1,1,1,1
1,1,1,1,1,1,1,1,1,1,1,1,1,1,1,1,1,1,1,1,1,1,1,1,1,1
1,1,1,1,1,1,2,2,2,2,2,2,2,1,1,1,1,1,1,1,1,1,1,1,1,1
1,1,1,1,1,1,2,1,1,1,1,1,2,1,1,1,1,1,1,1,1,1,1,1,1,1
1,1,1,1,1,1,2,1,1,1,1,1,2,1,1,1,1,1,1,1,1,1,1,1,1,1
1,1,1,1,1,1,2,1,1,4,1,1,2,1,1,1,1,1,1,1,1,1,1,1,1,1
1,1,1,1,1,1,2,1,1,1,1,1,2,1,1,1,1,1,1,1,1,1,1,1,1,1
1,1,1,1,1,1,2,1,1,1,1,1,2,1,1,1,1,1,1,1,1,1,1,1,1,1
1,1,1,1,1,1,2,2,2,2,2,2,2,1,1,1,1,1,1,1,1,1,1,1,1,1
1,1,1,1,1,1,1,1,1,1,1,1,1,1,1,1,1,1,1,1,1,1,1,1,1,1
1,1,1,1,1,1,1,1,1,1,1,1,1,1,1,1,1,1,1,1,1,1,1,1,1,1
1,1,1,1,1,1,1,1,1,1,1,1,1,1,1,1,1,1,1,1,1,1,1,1,1,1
1,1,1,1,1,1,1,1,1,1,1,1,1,1,1,1,1,1,1,1,1,1,1,1,1,1
1,1,1,1,1,1,1,1,1,1,1,1,1,1,1,1,1,1,1,1,1,1,1,1,1,1
1,1,1,1,1,1,1,1,1,1,1,1,1,1,1,1,1,1,1,1,1,1,1,1,1,1
1,1,1,1,1,1,1,1,1,1,1,1,1,1,1,1,1,1,1,1,1,1,1,1,1,1
1,1,1,1,1,1,1,1,1,1,1,1,1,1,1,1,1,1,1,1,1,1,1,1,1,1
1,1,1,1,1,1,1,1,1,1,1,1,1,1,1,1,1,1,1,1,1,1,1,1,1,1
1,1,1,1,1,1,1,1,1,1,1,1,1,1,1,1,1,1,1,1,1,1,1,1,1,1
1,1,1,1,1,1,1,1,1,1,1,1,1,1,1,1,1,1,1,1,1,1,1,1,1,1
1,1,1,1,1,1,1,1,1,1,1,1,1,1,1,1,1,1,1,1,1,1,1,1,1,1
1,1,1,1,1,1,2,2,2,2,2,2,2,1,1,1,1,1,1,1,1,1,1,1,1,1
1,1,1,1,1,1,2,1,1,1,1,1,2,1,1,1,1,1,1,1,1,1,1,1,1,1
1,1,1,1,1,1,2,1,1,1,1,1,2,1,1,1,1,1,1,1,1,1,1,1,1,1
1,1,1,1,1,1,2,1,1,4,1,1,2,1,1,1,1,1,1,1,1,1,1,1,1,1
1,1,1,1,1,1,2,1,1,1,1,1,2,1,1,1,1,1,1,1,1,1,1,1,1,1
1,1,1,1,1,1,2,1,1,1,1,1,2,1,1,1,1,1,1,1,1,1,1,1,1,1
1,1,1,1,1,1,2,2,2,2,2,2,2,1,1,1,1,1,1,1,1,1,1,1,1,1
1,1,1,1,1,1,1,1,1,1,1,1,1,1,1,1,1,1,1,1,1,1,1,1,1,1
1,1,1,1,1,1,1,1,1,1,1,1,1,1,1,1,1,1,1,1,1,1,1,1,1,1
1,1,1,1,1,1,1,1,1,1,1,1,1,1,1,1,1,1,1,1,1,1,1,1,1,1
1,1,1,1,1,1,1,1,1,1,1,1,1,1,1,1,1,1,1,1,1,1,1,1,1,1
endlayer

layer
5,5,5,5,5,5,5,5,5,5,5,5,5,5,5,5,5,5,5,5,5,5,5,5,5,5
5,5,5,5,5,5,5,5,5,5,5,5,5,5,5,5,5,5,5,5,5,5,5,5,5,5
5,5,5,5,6,6,6,6,6,6,6,6,6,6,6,6,6,6,6,6,6,6,6,6,5,5
5,5,5,5,6,6,6,6,6,6,6,6,6,6,6,6,7,7,7,7,7,7,7,6,5,5
5,5,5,5,6,6,2,2,2,2,2,2,2,6,6,6,7,7,7,7,7,7,7,6,5,5
5,5,5,5,6,6,2,1,1,1,1,1,2,6,6,6,7,7,7,7,7,7,7,6,5,5
5,5,5,5,6,6,2,1,1,1,1,1,2,6,6,6,7,7,7,7,7,7,7,6,5,5
5,5,5,5,6,6,2,1,1,3,1,1,2,2,2,2,7,7,7,7,7,7,7,6,5,5
5,5,5,5,6,6,2,1,1,1,1,1,2,6,6,6,7,7,7,7,7,7,7,6,5,5
5,5,5,5,6,6,2,1,1,1,1,1,2,6,6,6,7,7,7,7,7,7,7,6,5,5
5,5,5,5,6,6,2,2,2,2,2,2,2,6,6,6,7,7,7,7,7,7,7,6,5,5
5,5,5,5,6,6,6,6,6,6,6,6,6,6,6,6,7,7,7,8,7,7,7,6,5,5
5,5,5,5,6,6,6,6,6,6,6,6,6,6,6,6,7,7,7,7,7,7,7,6,5,5
5,5,5,5,6,6,6,6,6,6,6,6,6,0,7,7,7,7,7,7,7,7,7,6,5,5
5,5,5,5,6,6,6,6,6,6,6,6,6,7,7,7,7,7,7,7,7,7,7,6,5,5
5,5,5,5,6,6,6,6,6,6,6,6,7,7,7,7,7,7,7,7,7,7,7,6,5,5
5,5,5,5,10,10,10,10,10,10,10,10,7,7,7,7,7,7,7,7,7,7,7,6,5,5
5,5,5,5,10,10,10,10,10,10,10,10,7,7,7,7,7,7,7,7,7,7,7,6,5,5
5,5,5,5,6,6,6,6,6,6,6,6,7,7,7,7,7,7,7,7,7,7,7,6,5,5
5,5,5,5,6,6,6,6,6,6,6,6,6,7,7,7,7,7,7,7,7,7,7,6,5,5
5,5,5,5,6,6,6,6,6,6,6,6,6,7,7,9,7,7,7,7,7,7,7,6,5,5
5,5,5,5,6,6,6,6,6,6,6,6,6,6,6,6,7,7,7,7,7,7,7,6,5,5
5,5,5,5,6,6,6,6,6,6,6,6,6,6,6,6,7,7,7,8,7,7,7,6,5,5
5,5,5,5,6,6,2,2,2,2,2,2,2,6,6,6,7,7,7,7,7,7,7,6,5,5
5,5,5,5,6,6,2,1,1,1,1,1,2,6,6,6,7,7,7,7,7,7,7,6,5,5
5,5,5,5,6,6,2,1,1,1,1,1,2,6,6,6,7,7,7,7,7,7,7,6,5,5
5,5,5,5,6,6,2,1,1,3,1,1,2,2,2,2,7,7,7,7,7,7,7,6,5,5
5,5,5,5,6,6,2,1,1,1,1,1,2,6,6,6,7,7,7,7,7,7,7,6,5,5
5,5,5,5,6,6,2,1,1,1,1,1,2,6,6,6,7,7,7,7,7,7,7,6,5,5
5,5,5,5,6,6,2,2,2,2,2,2,2,6,6,6,7,7,7,7,7,7,7,6,5,5
5,5,5,5,6,6,6,6,6,6,6,6,6,6,6,6,7,7,7,7,7,7,7,6,5,5
5,5,5,5,6,6,6,6,6,6,6,6,6,6,6,6,6,6,6,6,6,6,6,6,5,5
5,5,5,5,5,5,5,5,5,5,5,5,5,5,5,5,5,5,5,5,5,5,5,5,5,5
5,5,5,5,5,5,5,5,5,5,5,5,5,5,5,5,5,5,5,5,5,5,5,5,5,5
endlayer

layer
1,1,1,1,1,1,1,1,1,1,1,1,1,1,1,1,1,1,1,1,1,1,1,1,1,1
1,1,1,1,1,1,1,1,1,1,1,1,1,1,1,1,1,1,1,1,1,1,1,1,1,1
1,1,1,1,19,19,19,19,19,19,19,19,19,19,19,11,11,11,11,11,11,11,11,11,1,1
1,1,1,1,19,1,1,1,1,1,1,1,1,1,1,11,0,0,0,0,0,0,0,11,1,1
1,1,1,1,19,1,1,1,1,1,1,1,1,1,1,11,0,0,15,14,15,0,0,11,1,1
1,1,1,1,19,1,1,1,1,1,1,1,1,1,1,11,0,13,16,14,16,13,0,11,1,1
1,1,1,1,19,1,1,1,1,1,1,1,1,1,1,11,0,14,14,14,14,14,0,11,1,1
1,1,1,1,19,1,1,1,1,3,1,1,1,1,1,0,0,0,15,14,15,0,0,11,1,1
1,1,1,1,19,1,1,1,1,1,1,1,1,1,1,11,0,13,16,14,16,13,0,11,1,1
1,1,1,1,19,1,1,1,1,1,1,1,1,1,1,11,0,14,14,17,14,14,0,11,1,1
1,1,1,1,19,1,1,1,1,1,1,1,1,1,1,11,0,13,16,14,16,13,0,11,1,1
1,1,1,1,19,1,1,1,1,1,1,1,1,1,1,11,0,0,15,14,15,0,0,11,1,1
1,1,1,1,19,1,1,1,1,1,1,1,1,1,1,11,12,12,12,12,12,12,12,11,1,1
1,1,1,1,19,1,1,1,1,1,1,1,1,11,11,12,12,12,12,12,12,12,12,11,1,1
1,1,1,1,19,1,1,1,1,1,1,1,11,12,12,12,12,12,12,12,12,12,12,11,1,1
1,1,1,1,19,19,19,19,19,19,19,11,1,1,0,18,18,12,12,12,12,12,12,11,1,1
1,1,1,1,1,1,1,1,1,1,1,1,1,1,1,16,12,12,12,12,12,12,12,11,1,1
1,1,1,1,1,1,1,1,1,1,1,1,1,1,0,16,12,12,12,12,12,12,12,11,1,1
1,1,1,1,19,19,19,19,19,19,19,11,1,0,1,18,18,12,12,12,12,12,12,11,1,1
1,1,1,1,19,1,1,1,1,1,1,1,11,12,12,12,12,12,12,12,12,12,12,11,1,1
1,1,1,1,19,1,1,1,1,1,1,1,1,11,11,12,12,12,12,12,12,12,12,11,1,1
1,1,1,1,19,1,1,1,1,1,1,1,1,1,1,11,12,12,12,12,12,12,12,11,1,1
1,1,1,1,19,1,1,1,1,1,1,1,1,1,1,11,0,0,15,14,15,0,0,11,1,1
1,1,1,1,19,1,1,1,1,1,1,1,1,1,1,11,0,13,16,14,16,13,0,11,1,1
1,1,1,1,19,1,1,1,1,1,1,1,1,1,1,11,0,14,14,17,14,14,0,11,1,1
1,1,1,1,19,1,1,1,1,1,1,1,1,1,1,11,0,13,16,14,16,13,0,11,1,1
1,1,1,1,19,1,1,1,1,3,1,1,1,1,1,0,0,0,15,14,15,0,0,11,1,1
1,1,1,1,19,1,1,1,1,1,1,1,1,1,1,11,0,14,14,14,14,14,0,11,1,1
1,1,1,1,19,1,1,1,1,1,1,1,1,1,1,11,0,13,16,14,16,13,0,11,1,1
1,1,1,1,19,1,1,1,1,1,1,1,1,1,1,11,0,0,15,14,15,0,0,11,1,1
1,1,1,1,19,1,1,1,1,1,1,1,1,1,1,11,0,0,0,0,0,0,0,11,1,1
1,1,1,1,19,19,19,19,19,19,19,19,19,19,19,11,11,11,11,11,11,11,11,11,1,1
1,1,1,1,1,1,1,1,1,1,1,1,1,1,1,1,1,1,1,1,1,1,1,1,1,1
1,1,1,1,1,1,1,1,1,1,1,1,1,1,1,1,1,1,1,1,1,1,1,1,1,1
endlayer

layer
1,1,1,1,1,1,1,1,1,1,1,1,1,1,1,1,1,1,1,1,1,1,1,1,1,1
1,1,1,1,1,1,1,1,1,1,1,1,1,1,1,1,1,1,1,1,1,1,1,1,1,1
1,1,1,1,1,1,1,1,1,1,1,1,1,1,1,11,20,21,20,21,20,21,20,11,1,1
1,1,1,1,1,1,1,1,1,1,1,1,1,1,1,20,0,0,0,0,0,0,0,20,1,1
1,1,1,1,1,1,1,1,1,1,1,1,1,1,1,21,0,0,15,14,15,0,0,21,1,1
1,1,1,1,1,1,1,1,1,1,1,1,1,1,1,20,0,0,0,14,0,0,0,20,1,1
1,1,1,1,1,1,1,1,1,1,1,1,1,1,1,21,0,14,14,14,14,14,0,21,1,1
1,1,1,1,1,1,1,1,1,4,1,1,1,1,1,0,0,0,15,14,15,0,0,20,1,1
1,1,1,1,1,1,1,1,1,1,1,1,1,1,1,21,0,0,0,14,0,0,0,21,1,1
1,1,1,1,1,1,1,1,1,1,1,1,1,1,1,20,0,14,14,14,14,14,0,20,1,1
1,1,1,1,1,1,1,1,1,1,1,1,1,1,1,21,0,0,0,14,0,0,0,21,1,1
1,1,1,1,1,1,1,1,1,1,1,1,1,1,1,20,0,0,15,14,15,0,0,20,1,1
1,1,1,1,1,1,1,1,1,1,1,1,1,1,1,11,0,0,0,0,0,0,0,11,1,1
1,1,1,1,1,1,1,1,1,1,1,1,1,22,21,0,0,0,0,0,0,0,0,20,1,1
1,1,1,1,1,1,1,1,1,1,1,1,21,0,0,0,0,0,0,0,0,0,0,21,1,1
1,1,1,1,1,1,1,1,1,1,1,22,0,0,0,0,0,0,0,0,0,0,0,20,1,1
1,1,1,1,1,1,1,1,1,1,1,1,1,0,0,0,0,0,0,0,0,0,0,21,1,1
1,1,1,1,1,1,1,1,1,1,1,1,0,0,0,0,0,0,0,0,0,0,0,21,1,1
1,1,1,1,1,1,1,1,1,1,1,22,0,0,0,0,0,0,0,0,0,0,0,20,1,1
1,1,1,1,1,1,1,1,1,1,1,1,21,0,0,0,0,0,0,0,0,0,0,21,1,1
1,1,1,1,1,1,1,1,1,1,1,1,1,22,21,0,0,0,0,0,0,0,0,20,1,1
1,1,1,1,1,1,1,1,1,1,1,1,1,1,1,11,0,0,0,0,0,0,0,11,1,1
1,1,1,1,1,1,1,1,1,1,1,1,1,1,1,20,0,0,15,14,15,0,0,20,1,1
1,1,1,1,1,1,1,1,1,1,1,1,1,1,1,21,0,0,0,14,0,0,0,21,1,1
1,1,1,1,1,1,1,1,1,1,1,1,1,1,1,20,0,14,14,14,14,14,0,20,1,1
1,1,1,1,1,1,1,1,1,1,1,1,1,1,1,21,0,0,0,14,0,0,0,21,1,1
1,1,1,1,1,1,1,1,1,4,1,1,1,1,1,0,0,0,15,14,15,0,0,20,1,1
1,1,1,1,1,1,1,1,1,1,1,1,1,1,1,21,0,14,14,14,14,14,0,21,1,1
1,1,1,1,1,1,1,1,1,1,1,1,1,1,1,20,0,0,0,14,0,0,0,20,1,1
1,1,1,1,1,1,1,1,1,1,1,1,1,1,1,21,0,0,15,14,15,0,0,21,1,1
1,1,1,1,1,1,1,1,1,1,1,1,1,1,1,20,0,0,0,0,0,0,0,20,1,1
1,1,1,1,1,1,1,1,1,1,1,1,1,1,1,11,20,21,20,21,20,21,20,11,1,1
1,1,1,1,1,1,1,1,1,1,1,1,1,1,1,1,1,1,1,1,1,1,1,1,1,1
1,1,1,1,1,1,1,1,1,1,1,1,1,1,1,1,1,1,1,1,1,1,1,1,1,1
endlayer

layer
1,1,1,1,1,1,1,1,1,1,1,1,1,1,1,1,1,1,1,1,1,1,1,1,1,1
1,1,1,1,1,1,1,1,1,1,1,1,1,1,1,1,1,1,1,1,1,1,1,1,1,1
1,1,1,1,1,1,1,1,1,1,1,1,1,1,1,11,20,21,20,21,20,21,20,11,1,1
1,1,1,1,1,1,1,1,1,1,1,1,1,1,1,20,0,0,0,0,0,0,0,20,1,1
1,1,1,1,1,1,1,1,1,1,1,1,1,1,1,21,0,0,0,0,0,0,0,21,1,1
1,1,1,1,1,1,1,1,1,1,1,1,1,1,1,20,0,0,0,0,0,0,0,20,1,1
1,1,1,1,1,1,1,1,1,1,1,1,1,1,1,21,0,0,0,0,0,0,0,21,1,1
1,1,1,1,1,1,1,1,1,3,1,1,1,1,1,20,0,0,0,0,0,0,0,20,1,1
1,1,1,1,1,1,1,1,1,1,1,1,1,1,1,21,0,0,0,0,0,0,0,21,1,1
1,1,1,1,1,1,1,1,1,1,1,1,1,1,1,20,0,0,0,0,0,0,0,20,1,1
1,1,1,1,1,1,1,1,1,1,1,1,1,1,1,21,0,0,0,0,0,0,0,21,1,1
1,1,1,1,1,1,1,1,1,1,1,1,1,1,1,20,0,0,0,0,0,0,0,20,1,1
1,1,1,1,1,1,1,1,1,1,1,1,1,1,1,11,0,0,0,0,0,0,0,11,1,1
1,1,1,1,1,1,1,1,1,1,1,1,1,22,21,0,0,0,0,0,0,0,0,20,1,1
1,1,1,1,1,1,1,1,1,1,1,1,21,0,0,0,0,0,0,0,0,0,0,21,1,1
1,1,1,1,1,1,1,1,1,1,1,22,0,0,0,0,0,0,0,0,0,0,0,20,1,1
1,1,1,1,1,1,1,1,1,1,1,1,0,0,0,0,0,0,0,0,0,0,0,21,1,1
1,1,1,1,1,1,1,1,1,1,1,1,0,0,0,0,0,0,0,0,0,0,0,21,1,1
1,1,1,1,1,1,1,1,1,1,1,22,0,0,0,0,0,0,0,0,0,0,0,20,1,1
1,1,1,1,1,1,1,1,1,1,1,1,21,0,0,0,0,0,0,0,0,0,0,21,1,1
1,1,1,1,1,1,1,1,1,1,1,1,1,22,21,0,0,0,0,0,0,0,0,20,1,1
1,1,1,1,1,1,1,1,1,1,1,1,1,1,1,11,0,0,0,0,0,0,0,11,1,1
1,1,1,1,1,1,1,1,1,1,1,1,1,1,1,20,0,0,0,0,0,0,0,20,1,1
1,1,1,1,1,1,1,1,1,1,1,1,1,1,1,21,0,0,0,0,0,0,0,21,1,1
1,1,1,1,1,1,1,1,1,1,1,1,1,1,1,20,0,0,0,0,0,0,0,20,1,1
1,1,1,1,1,1,1,1,1,1,1,1,1,1,1,21,0,0,0,0,0,0,0,21,1,1
1,1,1,1,1,1,1,1,1,3,1,1,1,1,1,20,0,0,0,0,0,0,0,20,1,1
1,1,1,1,1,1,1,1,1,1,1,1,1,1,1,21,0,0,0,0,0,0,0,21,1,1
1,1,1,1,1,1,1,1,1,1,1,1,1,1,1,20,0,0,0,0,0,0,0,20,1,1
1,1,1,1,1,1,1,1,1,1,1,1,1,1,1,21,0,0,0,0,0,0,0,21,1,1
1,1,1,1,1,1,1,1,1,1,1,1,1,1,1,20,0,0,0,0,0,0,0,20,1,1
1,1,1,1,1,1,1,1,1,1,1,1,1,1,1,11,20,21,20,21,20,21,20,11,1,1
1,1,1,1,1,1,1,1,1,1,1,1,1,1,1,1,1,1,1,1,1,1,1,1,1,1
1,1,1,1,1,1,1,1,1,1,1,1,1,1,1,1,1,1,1,1,1,1,1,1,1,1
endlayer

layer
23,23,23,23,23,23,23,23,23,23,23,23,23,23,23,23,23,23,23,23,23,23,23,23,23,23
23,23,23,23,23,23,23,23,23,23,23,23,23,23,23,23,23,23,23,23,23,23,23,23,23,23
23,23,23,23,23,23,23,23,23,23,23,23,23,23,23,11,20,21,20,21,20,21,20,11,23,23
23,23,23,23,23,23,23,23,23,23,23,23,23,23,23,20,0,0,0,0,0,0,0,20,23,23
23,23,23,23,23,23,23,23,23,23,23,23,23,23,23,21,0,0,0,0,0,0,0,21,23,23
23,23,23,23,23,23,23,23,23,23,23,23,23,23,23,20,0,0,0,0,0,0,0,20,23,23
23,23,23,23,23,23,23,23,23,23,23,23,23,23,23,21,0,0,0,0,0,0,0,21,23,23
23,23,23,23,23,23,23,23,23,23,23,23,23,23,23,20,0,0,0,0,0,0,0,20,23,23
23,23,23,23,23,23,23,23,23,23,23,23,23,23,23,21,0,0,0,0,0,0,0,21,23,23
23,23,23,23,23,23,23,23,23,23,23,23,23,23,23,20,0,0,0,0,0,0,0,20,23,23
23,23,23,23,23,23,23,23,23,23,23,23,23,23,23,21,0,0,0,0,0,0,0,21,23,23
23,23,23,23,23,23,23,23,23,23,23,23,23,23,23,20,0,0,0,0,0,0,0,20,23,23
23,23,23,23,23,23,23,23,23,23,23,23,23,23,23,11,0,0,0,0,0,0,0,11,23,23
23,23,23,23,23,23,23,23,23,23,23,23,23,22,21,0,0,0,0,0,0,0,0,20,23,23
23,23,23,23,23,23,23,23,23,23,23,23,21,0,0,0,0,0,0,0,0,0,0,21,23,23
23,23,23,23,23,23,23,23,23,23,23,22,0,0,0,0,0,0,0,0,0,0,0,20,23,23
23,23,23,23,23,23,23,23,23,23,23,23,0,0,0,0,0,0,0,0,0,0,0,21,23,23
23,23,23,23,23,23,23,23,23,23,23,23,0,0,0,0,0,0,0,0,0,0,0,21,23,23
23,23,23,23,23,23,23,23,23,23,23,22,0,0,0,0,0,0,0,0,0,0,0,20,23,23
23,23,23,23,23,23,23,23,23,23,23,23,21,0,0,0,0,0,0,0,0,0,0,21,23,23
23,23,23,23,23,23,23,23,23,23,23,23,23,22,21,0,0,0,0,0,0,0,0,20,23,23
23,23,23,23,23,23,23,23,23,23,23,23,23,23,23,11,0,0,0,0,0,0,0,11,23,23
23,23,23,23,23,23,23,23,23,23,23,23,23,23,23,20,0,0,0,0,0,0,0,20,23,23
23,23,23,23,23,23,23,23,23,23,23,23,23,23,23,21,0,0,0,0,0,0,0,21,23,23
23,23,23,23,23,23,23,23,23,23,23,23,23,23,23,20,0,0,0,0,0,0,0,20,23,23
23,23,23,23,23,23,23,23,23,23,23,23,23,23,23,21,0,0,0,0,0,0,0,21,23,23
23,23,23,23,23,23,23,23,23,23,23,23,23,23,23,20,0,0,0,0,0,0,0,20,23,23
23,23,23,23,23,23,23,23,23,23,23,23,23,23,23,21,0,0,0,0,0,0,0,21,23,23
23,23,23,23,23,23,23,23,23,23,23,23,23,23,23,20,0,0,0,0,0,0,0,20,23,23
23,23,23,23,23,23,23,23,23,23,23,23,23,23,23,21,0,0,0,0,0,0,0,21,23,23
23,23,23,23,23,23,23,23,23,23,23,23,23,23,23,20,0,0,0,0,0,0,0,20,23,23
23,23,23,23,23,23,23,23,23,23,23,23,23,23,23,11,20,21,20,21,20,21,20,11,23,23
23,23,23,23,23,23,23,23,23,23,23,23,23,23,23,23,23,23,23,23,23,23,23,23,23,23
23,23,23,23,23,23,23,23,23,23,23,23,23,23,23,23,23,23,23,23,23,23,23,23,23,23
endlayer

layer
0,0,0,0,0,0,0,0,0,0,0,0,0,0,0,0,0,0,0,0,0,0,0,0,0,0
0,0,0,0,0,0,0,0,0,0,0,0,0,0,0,0,0,0,0,0,0,0,0,0,0,0
0,0,0,0,0,0,0,0,0,0,0,0,0,0,0,11,20,21,20,21,20,21,20,11,0,0
0,0,0,0,0,0,0,0,0,0,0,0,0,0,0,20,0,0,0,0,0,0,0,20,0,0
0,0,0,0,0,0,0,0,0,0,0,0,0,0,0,21,0,0,0,0,0,0,0,21,0,0
0,0,0,0,0,0,0,0,0,0,0,0,0,0,0,20,0,0,0,0,0,0,0,20,0,0
0,0,0,0,0,0,0,0,0,0,0,0,0,0,0,21,0,0,0,0,0,0,0,21,0,0
0,0,0,0,0,0,0,0,0,0,0,0,0,0,0,20,0,0,0,0,0,0,0,20,0,0
0,0,0,0,0,0,0,0,0,0,0,0,0,0,0,21,0,0,0,0,0,0,0,21,0,0
0,0,0,0,0,0,0,0,0,0,0,0,0,0,0,20,0,0,0,0,0,0,0,20,0,0
0,0,0,0,0,0,0,0,0,0,0,0,0,0,0,21,0,0,0,0,0,0,0,21,0,0
0,0,0,0,0,0,0,0,0,0,0,0,0,0,0,20,0,0,0,0,0,0,0,20,0,0
0,0,0,0,0,0,0,0,0,0,0,0,0,0,0,11,0,0,0,0,0,0,0,11,0,0
0,0,0,0,0,0,0,0,0,0,0,0,0,22,21,0,0,0,0,0,0,0,0,20,0,0
0,0,0,0,0,0,0,0,0,0,0,0,21,0,0,0,0,0,0,0,0,0,0,21,0,0
0,0,0,0,0,0,0,0,0,0,0,22,0,0,0,0,0,0,0,0,0,0,0,20,0,0
0,0,0,0,0,0,0,0,0,0,0,0,0,0,0,0,0,0,0,0,0,0,0,21,0,0
0,0,0,0,0,0,0,0,0,0,0,0,0,0,0,0,0,0,0,0,0,0,0,21,0,0
0,0,0,0,0,0,0,0,0,0,0,22,0,0,0,0,0,0,0,0,0,0,0,20,0,0
0,0,0,0,0,0,0,0,0,0,0,0,21,0,0,0,0,0,0,0,0,0,0,21,0,0
0,0,0,0,0,0,0,0,0,0,0,0,0,22,21,0,0,0,0,0,0,0,0,20,0,0
0,0,0,0,0,0,0,0,0,0,0,0,0,0,0,11,0,0,0,0,0,0,0,11,0,0
0,0,0,0,0,0,0,0,0,0,0,0,0,0,0,20,0,0,0,0,0,0,0,20,0,0
0,0,0,0,0,0,0,0,0,0,0,0,0,0,0,21,0,0,0,0,0,0,0,21,0,0
0,0,0,0,0,0,0,0,0,0,0,0,0,0,0,20,0,0,0,0,0,0,0,20,0,0
0,0,0,0,0,0,0,0,0,0,0,0,0,0,0,21,0,0,0,0,0,0,0,21,0,0
0,0,0,0,0,0,0,0,0,0,0,0,0,0,0,20,0,0,0,0,0,0,0,20,0,0
0,0,0,0,0,0,0,0,0,0,0,0,0,0,0,21,0,0,0,0,0,0,0,21,0,0
0,0,0,0,0,0,0,0,0,0,0,0,0,0,0,20,0,0,0,0,0,0,0,20,0,0
0,0,0,0,0,0,0,0,0,0,0,0,0,0,0,21,0,0,0,0,0,0,0,21,0,0
0,0,0,0,0,0,0,0,0,0,0,0,0,0,0,20,0,0,0,0,0,0,0,20,0,0
0,0,0,0,0,0,0,0,0,0,0,0,0,0,0,11,20,21,20,21,20,21,20,11,0,0
0,0,0,0,0,0,0,0,0,0,0,0,0,0,0,0,0,0,0,0,0,0,0,0,0,0
0,0,0,0,0,0,0,0,0,0,0,0,0,0,0,0,0,0,0,0,0,0,0,0,0,0
endlayer

layer
0,0,0,0,0,0,0,0,0,0,0,0,0,0,0,0,0,0,0,0,0,0,0,0,0,0
0,0,0,0,0,0,0,0,0,0,0,0,0,0,0,0,0,0,0,0,0,0,0,0,0,0
0,0,0,0,0,0,0,0,0,0,0,0,0,0,0,11,11,11,11,11,11,11,11,11,0,0
0,0,0,0,0,0,0,0,0,0,0,0,0,0,0,11,24,24,24,24,24,24,24,11,0,0
0,0,0,0,0,0,0,0,0,0,0,0,0,0,0,11,24,24,24,24,24,24,24,11,0,0
0,0,0,0,0,0,0,0,0,0,0,0,0,0,0,11,24,24,24,24,24,24,24,11,0,0
0,0,0,0,0,0,0,0,0,0,0,0,0,0,0,11,24,24,24,24,24,24,24,11,0,0
0,0,0,0,0,0,0,0,0,0,0,0,0,0,0,11,7,7,7,7,7,7,7,11,0,0
0,0,0,0,0,0,0,0,0,0,0,0,0,0,0,11,7,7,7,7,7,7,7,11,0,0
0,0,0,0,0,0,0,0,0,0,0,0,0,0,0,11,7,7,7,7,7,7,7,11,0,0
0,0,0,0,0,0,0,0,0,0,0,0,0,0,0,11,7,7,7,7,7,7,7,11,0,0
0,0,0,0,0,0,0,0,0,0,0,0,0,0,0,11,7,7,7,7,7,7,7,11,0,0
0,0,0,0,0,0,0,0,0,0,0,0,0,0,0,11,7,7,7,7,7,7,7,11,0,0
0,0,0,0,0,0,0,0,0,0,0,0,0,11,11,7,7,7,7,7,7,7,7,11,0,0
0,0,0,0,0,0,0,0,0,0,0,0,11,7,7,7,7,7,7,7,7,7,7,11,0,0
0,0,0,0,0,0,0,0,0,0,0,11,7,7,7,7,7,7,7,7,7,7,7,11,0,0
0,0,0,0,0,0,0,0,0,0,0,11,7,7,7,7,7,7,7,7,7,7,7,11,0,0
0,0,0,0,0,0,0,0,0,0,0,11,7,7,7,7,7,7,7,7,7,7,7,11,0,0
0,0,0,0,0,0,0,0,0,0,0,11,7,7,7,7,7,7,7,7,7,7,7,11,0,0
0,0,0,0,0,0,0,0,0,0,0,0,11,7,7,7,7,7,7,7,7,7,7,11,0,0
0,0,0,0,0,0,0,0,0,0,0,0,0,11,11,9,7,7,7,7,7,7,7,11,0,0
0,0,0,0,0,0,0,0,0,0,0,0,0,0,0,11,7,7,7,7,7,7,7,11,0,0
0,0,0,0,0,0,0,0,0,0,0,0,0,0,0,11,7,7,7,7,7,7,7,11,0,0
0,0,0,0,0,0,0,0,0,0,0,0,0,0,0,11,7,7,7,7,7,7,7,11,0,0
0,0,0,0,0,0,0,0,0,0,0,0,0,0,0,11,7,7,7,7,7,7,7,11,0,0
0,0,0,0,0,0,0,0,0,0,0,0,0,0,0,11,7,7,7,7,7,7,7,11,0,0
0,0,0,0,0,0,0,0,0,0,0,0,0,0,0,11,7,7,7,7,7,7,7,11,0,0
0,0,0,0,0,0,0,0,0,0,0,0,0,0,0,11,24,24,24,24,24,24,24,11,0,0
0,0,0,0,0,0,0,0,0,0,0,0,0,0,0,11,24,24,24,24,24,24,24,11,0,0
0,0,0,0,0,0,0,0,0,0,0,0,0,0,0,11,24,24,24,24,24,24,24,11,0,0
0,0,0,0,0,0,0,0,0,0,0,0,0,0,0,11,24,24,24,24,24,24,24,11,0,0
0,0,0,0,0,0,0,0,0,0,0,0,0,0,0,11,11,11,11,11,11,11,11,11,0,0
0,0,0,0,0,0,0,0,0,0,0,0,0,0,0,0,0,0,0,0,0,0,0,0,0,0
0,0,0,0,0,0,0,0,0,0,0,0,0,0,0,0,0,0,0,0,0,0,0,0,0,0
endlayer

layer
0,0,0,0,0,0,0,0,0,0,0,0,0,0,0,0,0,0,0,0,0,0,0,0,0,0
0,0,0,0,0,0,0,0,0,0,0,0,0,0,0,0,0,0,0,0,0,0,0,0,0,0
0,0,0,0,0,0,0,0,0,0,0,0,0,0,0,0,0,0,0,0,0,0,0,0,0,0
0,0,0,0,0,0,0,0,0,0,0,0,0,0,0,0,0,0,0,0,0,0,0,0,0,0
0,0,0,0,0,0,0,0,0,0,0,0,0,0,0,0,0,0,0,0,0,0,0,0,0,0
0,0,0,0,0,0,0,0,0,0,0,0,0,0,0,0,0,0,0,0,0,0,0,0,0,0
0,0,0,0,0,0,0,0,0,0,0,0,0,0,0,11,20,21,20,21,20,21,20,11,0,0
0,0,0,0,0,0,0,0,0,0,0,0,0,0,0,20,0,0,0,0,0,15,17,20,0,0
0,0,0,0,0,0,0,0,0,0,0,0,0,0,0,21,0,28,28,28,26,25,15,21,0,0
0,0,0,0,0,0,0,0,0,0,0,0,0,0,0,21,0,28,28,28,26,0,0,21,0,0
0,0,0,0,0,0,0,0,0,0,0,0,0,0,0,21,0,28,28,28,0,0,0,21,0,0
0,0,0,0,0,0,0,0,0,0,0,0,0,0,0,20,0,0,0,0,0,0,8,20,0,0
0,0,0,0,0,0,0,0,0,0,0,0,0,0,0,11,20,0,20,20,20,20,20,11,0,0
0,0,0,0,0,0,0,0,0,0,0,0,0,22,21,30,30,30,30,0,0,0,15,20,0,0
0,0,0,0,0,0,0,0,0,0,0,0,21,0,0,30,30,30,30,27,27,0,0,21,0,0
0,0,0,0,0,0,0,0,0,0,0,22,32,0,0,30,30,30,30,27,0,0,0,20,0,0
0,0,0,0,0,0,0,0,0,0,0,21,33,0,31,30,30,30,30,29,0,0,0,21,0,0
0,0,0,0,0,0,0,0,0,0,0,21,33,0,31,30,30,30,30,29,0,0,0,21,0,0
0,0,0,0,0,0,0,0,0,0,0,22,32,0,0,30,30,30,30,27,0,0,0,20,0,0
0,0,0,0,0,0,0,0,0,0,0,0,21,0,0,30,30,30,30,27,27,0,0,21,0,0
0,0,0,0,0,0,0,0,0,0,0,0,0,22,21,30,30,30,30,0,0,0,15,20,0,0
0,0,0,0,0,0,0,0,0,0,0,0,0,0,0,11,20,0,20,20,20,20,20,11,0,0
0,0,0,0,0,0,0,0,0,0,0,0,0,0,0,20,0,0,0,0,0,0,8,20,0,0
0,0,0,0,0,0,0,0,0,0,0,0,0,0,0,21,0,28,28,28,0,0,0,21,0,0
0,0,0,0,0,0,0,0,0,0,0,0,0,0,0,21,0,28,28,28,26,25,0,21,0,0
0,0,0,0,0,0,0,0,0,0,0,0,0,0,0,21,0,28,28,28,26,0,15,21,0,0
0,0,0,0,0,0,0,0,0,0,0,0,0,0,0,20,0,0,0,0,0,15,17,20,0,0
0,0,0,0,0,0,0,0,0,0,0,0,0,0,0,11,20,21,20,21,20,21,20,11,0,0
0,0,0,0,0,0,0,0,0,0,0,0,0,0,0,0,0,0,0,0,0,0,0,0,0,0
0,0,0,0,0,0,0,0,0,0,0,0,0,0,0,0,0,0,0,0,0,0,0,0,0,0
0,0,0,0,0,0,0,0,0,0,0,0,0,0,0,0,0,0,0,0,0,0,0,0,0,0
0,0,0,0,0,0,0,0,0,0,0,0,0,0,0,0,0,0,0,0,0,0,0,0,0,0
0,0,0,0,0,0,0,0,0,0,0,0,0,0,0,0,0,0,0,0,0,0,0,0,0,0
0,0,0,0,0,0,0,0,0,0,0,0,0,0,0,0,0,0,0,0,0,0,0,0,0,0
endlayer

layer
0,0,0,0,0,0,0,0,0,0,0,0,0,0,0,0,0,0,0,0,0,0,0,0,0,0
0,0,0,0,0,0,0,0,0,0,0,0,0,0,0,0,0,0,0,0,0,0,0,0,0,0
0,0,0,0,0,0,0,0,0,0,0,0,0,0,0,0,0,0,0,0,0,0,0,0,0,0
0,0,0,0,0,0,0,0,0,0,0,0,0,0,0,0,0,0,0,0,0,0,0,0,0,0
0,0,0,0,0,0,0,0,0,0,0,0,0,0,0,0,0,0,0,0,0,0,0,0,0,0
0,0,0,0,0,0,0,0,0,0,0,0,0,0,0,0,0,0,0,0,0,0,0,0,0,0
0,0,0,0,0,0,0,0,0,0,0,0,0,0,0,11,20,21,20,21,20,21,20,11,0,0
0,0,0,0,0,0,0,0,0,0,0,0,0,0,0,20,0,0,0,0,0,0,15,20,0,0
0,0,0,0,0,0,0,0,0,0,0,0,0,0,0,21,0,0,0,0,0,0,0,21,0,0
0,0,0,0,0,0,0,0,0,0,0,0,0,0,0,21,0,0,0,0,34,0,0,21,0,0
0,0,0,0,0,0,0,0,0,0,0,0,0,0,0,21,0,0,0,0,0,0,0,21,0,0
0,0,0,0,0,0,0,0,0,0,0,0,0,0,0,20,0,0,0,0,0,0,0,20,0,0
0,0,0,0,0,0,0,0,0,0,0,0,0,0,0,11,20,0,20,20,20,20,20,11,0,0
0,0,0,0,0,0,0,0,0,0,0,0,0,22,21,0,0,0,0,0,0,0,15,20,0,0
0,0,0,0,0,0,0,0,0,0,0,0,21,0,0,0,0,0,0,0,0,0,0,21,0,0
0,0,0,0,0,0,0,0,0,0,0,22,0,0,0,0,0,0,0,0,0,0,0,20,0,0
0,0,0,0,0,0,0,0,0,0,0,21,0,0,0,0,0,0,0,0,0,0,0,21,0,0
0,0,0,0,0,0,0,0,0,0,0,21,0,0,35,0,0,0,0,0,0,0,0,21,0,0
0,0,0,0,0,0,0,0,0,0,0,22,0,0,0,0,0,0,0,0,0,0,0,20,0,0
0,0,0,0,0,0,0,0,0,0,0,0,21,0,0,0,0,0,0,35,0,0,0,21,0,0
0,0,0,0,0,0,0,0,0,0,0,0,0,22,21,0,0,0,0,0,0,0,15,20,0,0
0,0,0,0,0,0,0,0,0,0,0,0,0,0,0,11,20,0,20,20,20,20,20,11,0,0
0,0,0,0,0,0,0,0,0,0,0,0,0,0,0,20,0,0,0,0,0,0,0,20,0,0
0,0,0,0,0,0,0,0,0,0,0,0,0,0,0,21,0,0,0,0,0,0,0,21,0,0
0,0,0,0,0,0,0,0,0,0,0,0,0,0,0,21,0,0,0,0,0,0,0,21,0,0
0,0,0,0,0,0,0,0,0,0,0,0,0,0,0,21,0,0,0,0,34,0,0,21,0,0
0,0,0,0,0,0,0,0,0,0,0,0,0,0,0,20,0,0,0,0,0,0,15,20,0,0
0,0,0,0,0,0,0,0,0,0,0,0,0,0,0,11,20,21,20,21,20,21,20,11,0,0
0,0,0,0,0,0,0,0,0,0,0,0,0,0,0,0,0,0,0,0,0,0,0,0,0,0
0,0,0,0,0,0,0,0,0,0,0,0,0,0,0,0,0,0,0,0,0,0,0,0,0,0
0,0,0,0,0,0,0,0,0,0,0,0,0,0,0,0,0,0,0,0,0,0,0,0,0,0
0,0,0,0,0,0,0,0,0,0,0,0,0,0,0,0,0,0,0,0,0,0,0,0,0,0
0,0,0,0,0,0,0,0,0,0,0,0,0,0,0,0,0,0,0,0,0,0,0,0,0,0
0,0,0,0,0,0,0,0,0,0,0,0,0,0,0,0,0,0,0,0,0,0,0,0,0,0
endlayer

layer
0,0,0,0,0,0,0,0,0,0,0,0,0,0,0,0,0,0,0,0,0,0,0,0,0,0
0,0,0,0,0,0,0,0,0,0,0,0,0,0,0,0,0,0,0,0,0,0,0,0,0,0
0,0,0,0,0,0,0,0,0,0,0,0,0,0,0,0,0,0,0,0,0,0,0,0,0,0
0,0,0,0,0,0,0,0,0,0,0,0,0,0,0,0,0,0,0,0,0,0,0,0,0,0
0,0,0,0,0,0,0,0,0,0,0,0,0,0,0,0,0,0,0,0,0,0,0,0,0,0
0,0,0,0,0,0,0,0,0,0,0,0,0,0,0,0,0,0,0,0,0,0,0,0,0,0
0,0,0,0,0,0,0,0,0,0,0,0,0,0,0,11,20,21,20,21,20,21,20,11,0,0
0,0,0,0,0,0,0,0,0,0,0,0,0,0,0,20,0,0,0,0,0,0,0,20,0,0
0,0,0,0,0,0,0,0,0,0,0,0,0,0,0,21,0,0,0,0,0,0,0,21,0,0
0,0,0,0,0,0,0,0,0,0,0,0,0,0,0,21,0,0,0,0,0,0,0,21,0,0
0,0,0,0,0,0,0,0,0,0,0,0,0,0,0,21,0,0,0,0,0,0,0,21,0,0
0,0,0,0,0,0,0,0,0,0,0,0,0,0,0,20,0,0,0,0,0,0,0,20,0,0
0,0,0,0,0,0,0,0,0,0,0,0,0,0,0,11,20,20,20,20,20,20,20,11,0,0
0,0,0,0,0,0,0,0,0,0,0,0,0,22,21,0,0,0,0,0,0,0,0,20,0,0
0,0,0,0,0,0,0,0,0,0,0,0,21,0,0,0,0,0,0,0,0,0,0,21,0,0
0,0,0,0,0,0,0,0,0,0,0,22,0,0,0,0,0,0,0,0,0,0,0,20,0,0
0,0,0,0,0,0,0,0,0,0,0,21,0,0,0,0,0,0,0,0,0,0,0,21,0,0
0,0,0,0,0,0,0,0,0,0,0,21,0,0,0,0,0,0,0,0,0,0,0,21,0,0
0,0,0,0,0,0,0,0,0,0,0,22,0,0,0,0,0,0,0,0,0,0,0,20,0,0
0,0,0,0,0,0,0,0,0,0,0,0,21,0,0,0,0,0,0,0,0,0,0,21,0,0
0,0,0,0,0,0,0,0,0,0,0,0,0,22,21,0,0,0,0,0,0,0,0,20,0,0
0,0,0,0,0,0,0,0,0,0,0,0,0,0,0,11,20,20,20,20,20,20,20,11,0,0
0,0,0,0,0,0,0,0,0,0,0,0,0,0,0,20,0,0,0,0,0,0,0,20,0,0
0,0,0,0,0,0,0,0,0,0,0,0,0,0,0,21,0,0,0,0,0,0,0,21,0,0
0,0,0,0,0,0,0,0,0,0,0,0,0,0,0,21,0,0,0,0,0,0,0,21,0,0
0,0,0,0,0,0,0,0,0,0,0,0,0,0,0,21,0,0,0,0,0,0,0,21,0,0
0,0,0,0,0,0,0,0,0,0,0,0,0,0,0,20,0,0,0,0,0,0,0,20,0,0
0,0,0,0,0,0,0,0,0,0,0,0,0,0,0,11,20,21,20,21,20,21,20,11,0,0
0,0,0,0,0,0,0,0,0,0,0,0,0,0,0,0,0,0,0,0,0,0,0,0,0,0
0,0,0,0,0,0,0,0,0,0,0,0,0,0,0,0,0,0,0,0,0,0,0,0,0,0
0,0,0,0,0,0,0,0,0,0,0,0,0,0,0,0,0,0,0,0,0,0,0,0,0,0
0,0,0,0,0,0,0,0,0,0,0,0,0,0,0,0,0,0,0,0,0,0,0,0,0,0
0,0,0,0,0,0,0,0,0,0,0,0,0,0,0,0,0,0,0,0,0,0,0,0,0,0
0,0,0,0,0,0,0,0,0,0,0,0,0,0,0,0,0,0,0,0,0,0,0,0,0,0
endlayer

layer
0,0,0,0,0,0,0,0,0,0,0,0,0,0,0,0,0,0,0,0,0,0,0,0,0,0
0,0,0,0,0,0,0,0,0,0,0,0,0,0,0,0,0,0,0,0,0,0,0,0,0,0
0,0,0,0,0,0,0,0,0,0,0,0,0,0,0,0,0,0,0,0,0,0,0,0,0,0
0,0,0,0,0,0,0,0,0,0,0,0,0,0,0,0,0,0,0,0,0,0,0,0,0,0
0,0,0,0,0,0,0,0,0,0,0,0,0,0,0,0,0,0,0,0,0,0,0,0,0,0
0,0,0,0,0,0,0,0,0,0,0,0,0,0,0,0,0,0,0,0,0,0,0,0,0,0
0,0,0,0,0,0,0,0,0,0,0,0,0,0,0,11,20,21,20,21,20,21,20,11,0,0
0,0,0,0,0,0,0,0,0,0,0,0,0,0,0,20,0,0,0,0,0,0,0,20,0,0
0,0,0,0,0,0,0,0,0,0,0,0,0,0,0,21,0,0,0,0,0,0,0,21,0,0
0,0,0,0,0,0,0,0,0,0,0,0,0,0,0,21,0,0,0,0,0,0,0,21,0,0
0,0,0,0,0,0,0,0,0,0,0,0,0,0,0,21,0,0,0,0,0,0,0,21,0,0
0,0,0,0,0,0,0,0,0,0,0,0,0,0,0,20,0,0,0,0,0,0,0,20,0,0
0,0,0,0,0,0,0,0,0,0,0,0,0,0,0,11,20,20,20,20,20,20,20,11,0,0
0,0,0,0,0,0,0,0,0,0,0,0,0,22,21,0,0,0,0,0,0,0,0,20,0,0
0,0,0,0,0,0,0,0,0,0,0,0,21,0,0,0,0,0,0,0,0,0,0,21,0,0
0,0,0,0,0,0,0,0,0,0,0,22,0,0,0,0,0,0,0,0,0,0,0,20,0,0
0,0,0,0,0,0,0,0,0,0,0,21,0,0,0,0,0,0,0,0,0,0,0,21,0,0
0,0,0,0,0,0,0,0,0,0,0,21,0,0,0,0,0,0,0,0,0,0,0,21,0,0
0,0,0,0,0,0,0,0,0,0,0,22,0,0,0,0,0,0,0,0,0,0,0,20,0,0
0,0,0,0,0,0,0,0,0,0,0,0,21,0,0,0,0,0,0,0,0,0,0,21,0,0
0,0,0,0,0,0,0,0,0,0,0,0,0,22,21,0,0,0,0,0,0,0,0,20,0,0
0,0,0,0,0,0,0,0,0,0,0,0,0,0,0,11,20,20,20,20,20,20,20,11,0,0
0,0,0,0,0,0,0,0,0,0,0,0,0,0,0,20,0,0,0,0,0,0,0,20,0,0
0,0,0,0,0,0,0,0,0,0,0,0,0,0,0,21,0,0,0,0,0,0,0,21,0,0
0,0,0,0,0,0,0,0,0,0,0,0,0,0,0,21,0,0,0,0,0,0,0,21,0,0
0,0,0,0,0,0,0,0,0,0,0,0,0,0,0,21,0,0,0,0,0,0,0,21,0,0
0,0,0,0,0,0,0,0,0,0,0,0,0,0,0,20,0,0,0,0,0,0,0,20,0,0
0,0,0,0,0,0,0,0,0,0,0,0,0,0,0,11,20,21,20,21,20,21,20,11,0,0
0,0,0,0,0,0,0,0,0,0,0,0,0,0,0,0,0,0,0,0,0,0,0,0,0,0
0,0,0,0,0,0,0,0,0,0,0,0,0,0,0,0,0,0,0,0,0,0,0,0,0,0
0,0,0,0,0,0,0,0,0,0,0,0,0,0,0,0,0,0,0,0,0,0,0,0,0,0
0,0,0,0,0,0,0,0,0,0,0,0,0,0,0,0,0,0,0,0,0,0,0,0,0,0
0,0,0,0,0,0,0,0,0,0,0,0,0,0,0,0,0,0,0,0,0,0,0,0,0,0
0,0,0,0,0,0,0,0,0,0,0,0,0,0,0,0,0,0,0,0,0,0,0,0,0,0
endlayer

layer
0,0,0,0,0,0,0,0,0,0,0,0,0,0,0,0,0,0,0,0,0,0,0,0,0,0
0,0,0,0,0,0,0,0,0,0,0,0,0,0,0,0,0,0,0,0,0,0,0,0,0,0
0,0,0,0,0,0,0,0,0,0,0,0,0,0,0,0,0,0,0,0,0,0,0,0,0,0
0,0,0,0,0,0,0,0,0,0,0,0,0,0,0,0,0,0,0,0,0,0,0,0,0,0
0,0,0,0,0,0,0,0,0,0,0,0,0,0,0,0,0,0,0,0,0,0,0,0,0,0
0,0,0,0,0,0,0,0,0,0,0,0,0,0,0,0,0,0,0,0,0,0,0,0,0,0
0,0,0,0,0,0,0,0,0,0,0,0,0,0,0,11,20,21,20,21,20,21,20,11,0,0
0,0,0,0,0,0,0,0,0,0,0,0,0,0,0,20,0,0,0,0,0,0,0,20,0,0
0,0,0,0,0,0,0,0,0,0,0,0,0,0,0,21,0,0,0,0,0,0,0,21,0,0
0,0,0,0,0,0,0,0,0,0,0,0,0,0,0,21,0,0,0,0,0,0,0,21,0,0
0,0,0,0,0,0,0,0,0,0,0,0,0,0,0,21,0,0,0,0,0,0,0,21,0,0
0,0,0,0,0,0,0,0,0,0,0,0,0,0,0,20,0,0,0,0,0,0,0,20,0,0
0,0,0,0,0,0,0,0,0,0,0,0,0,0,0,11,20,20,20,20,20,20,20,11,0,0
0,0,0,0,0,0,0,0,0,0,0,0,0,22,21,0,0,0,0,0,0,0,0,20,0,0
0,0,0,0,0,0,0,0,0,0,0,0,21,0,0,0,0,0,0,0,0,0,0,21,0,0
0,0,0,0,0,0,0,0,0,0,0,22,0,0,0,0,0,0,0,0,0,0,0,20,0,0
0,0,0,0,0,0,0,0,0,0,0,21,0,0,0,0,0,0,0,0,0,0,0,21,0,0
0,0,0,0,0,0,0,0,0,0,0,21,0,0,0,0,0,0,0,0,0,0,0,21,0,0
0,0,0,0,0,0,0,0,0,0,0,22,0,0,0,0,0,0,0,0,0,0,0,20,0,0
0,0,0,0,0,0,0,0,0,0,0,0,21,0,0,0,0,0,0,0,0,0,0,21,0,0
0,0,0,0,0,0,0,0,0,0,0,0,0,22,21,0,0,0,0,0,0,0,0,20,0,0
0,0,0,0,0,0,0,0,0,0,0,0,0,0,0,11,20,20,20,20,20,20,20,11,0,0
0,0,0,0,0,0,0,0,0,0,0,0,0,0,0,20,0,0,0,0,0,0,0,20,0,0
0,0,0,0,0,0,0,0,0,0,0,0,0,0,0,21,0,0,0,0,0,0,0,21,0,0
0,0,0,0,0,0,0,0,0,0,0,0,0,0,0,21,0,0,0,0,0,0,0,21,0,0
0,0,0,0,0,0,0,0,0,0,0,0,0,0,0,21,0,0,0,0,0,0,0,21,0,0
0,0,0,0,0,0,0,0,0,0,0,0,0,0,0,20,0,0,0,0,0,0,0,20,0,0
0,0,0,0,0,0,0,0,0,0,0,0,0,0,0,11,20,21,20,21,20,21,20,11,0,0
0,0,0,0,0,0,0,0,0,0,0,0,0,0,0,0,0,0,0,0,0,0,0,0,0,0
0,0,0,0,0,0,0,0,0,0,0,0,0,0,0,0,0,0,0,0,0,0,0,0,0,0
0,0,0,0,0,0,0,0,0,0,0,0,0,0,0,0,0,0,0,0,0,0,0,0,0,0
0,0,0,0,0,0,0,0,0,0,0,0,0,0,0,0,0,0,0,0,0,0,0,0,0,0
0,0,0,0,0,0,0,0,0,0,0,0,0,0,0,0,0,0,0,0,0,0,0,0,0,0
0,0,0,0,0,0,0,0,0,0,0,0,0,0,0,0,0,0,0,0,0,0,0,0,0,0
endlayer

layer
0,0,0,0,0,0,0,0,0,0,0,0,0,0,0,0,0,0,0,0,0,0,0,0,0,0
0,0,0,0,0,0,0,0,0,0,0,0,0,0,0,0,0,0,0,0,0,0,0,0,0,0
0,0,0,0,0,0,0,0,0,0,0,0,0,0,0,0,0,0,0,0,0,0,0,0,0,0
0,0,0,0,0,0,0,0,0,0,0,0,0,0,0,0,0,0,0,0,0,0,0,0,0,0
0,0,0,0,0,0,0,0,0,0,0,0,0,0,0,0,0,0,0,0,0,0,0,0,0,0
0,0,0,0,0,0,0,0,0,0,0,0,0,0,0,0,0,0,0,0,0,0,0,0,0,0
0,0,0,0,0,0,0,0,0,0,0,0,0,0,0,11,11,11,11,11,11,11,11,11,0,0
0,0,0,0,0,0,0,0,0,0,0,0,0,0,0,11,24,24,24,24,24,24,24,11,0,0
0,0,0,0,0,0,0,0,0,0,0,0,0,0,0,11,24,24,24,24,24,24,24,11,0,0
0,0,0,0,0,0,0,0,0,0,0,0,0,0,0,11,24,24,24,24,24,24,24,11,0,0
0,0,0,0,0,0,0,0,0,0,0,0,0,0,0,11,24,24,24,24,24,24,24,11,0,0
0,0,0,0,0,0,0,0,0,0,0,0,0,0,0,11,24,24,24,24,24,24,24,11,0,0
0,0,0,0,0,0,0,0,0,0,0,0,0,0,0,11,11,11,11,11,11,11,11,11,0,0
0,0,0,0,0,0,0,0,0,0,0,0,0,11,11,7,7,7,7,7,7,7,7,11,0,0
0,0,0,0,0,0,0,0,0,0,0,0,11,7,7,7,7,7,7,7,7,7,7,11,0,0
0,0,0,0,0,0,0,0,0,0,0,11,7,7,7,7,7,7,7,7,7,7,7,11,0,0
0,0,0,0,0,0,0,0,0,0,0,11,7,7,7,7,7,7,7,7,7,7,7,11,0,0
0,0,0,0,0,0,0,0,0,0,0,11,7,7,7,7,7,7,7,7,7,7,7,11,0,0
0,0,0,0,0,0,0,0,0,0,0,11,7,7,7,7,7,7,7,7,7,7,7,11,0,0
0,0,0,0,0,0,0,0,0,0,0,0,11,7,7,7,7,7,7,7,7,7,7,11,0,0
0,0,0,0,0,0,0,0,0,0,0,0,0,11,11,9,7,7,7,7,7,7,7,11,0,0
0,0,0,0,0,0,0,0,0,0,0,0,0,0,0,11,11,11,11,11,11,11,11,11,0,0
0,0,0,0,0,0,0,0,0,0,0,0,0,0,0,11,24,24,24,24,24,24,24,11,0,0
0,0,0,0,0,0,0,0,0,0,0,0,0,0,0,11,24,24,24,24,24,24,24,11,0,0
0,0,0,0,0,0,0,0,0,0,0,0,0,0,0,11,24,24,24,24,24,24,24,11,0,0
0,0,0,0,0,0,0,0,0,0,0,0,0,0,0,11,24,24,24,24,24,24,24,11,0,0
0,0,0,0,0,0,0,0,0,0,0,0,0,0,0,11,24,24,24,24,24,24,24,11,0,0
0,0,0,0,0,0,0,0,0,0,0,0,0,0,0,11,11,11,11,11,11,11,11,11,0,0
0,0,0,0,0,0,0,0,0,0,0,0,0,0,0,0,0,0,0,0,0,0,0,0,0,0
0,0,0,0,0,0,0,0,0,0,0,0,0,0,0,0,0,0,0,0,0,0,0,0,0,0
0,0,0,0,0,0,0,0,0,0,0,0,0,0,0,0,0,0,0,0,0,0,0,0,0,0
0,0,0,0,0,0,0,0,0,0,0,0,0,0,0,0,0,0,0,0,0,0,0,0,0,0
0,0,0,0,0,0,0,0,0,0,0,0,0,0,0,0,0,0,0,0,0,0,0,0,0,0
0,0,0,0,0,0,0,0,0,0,0,0,0,0,0,0,0,0,0,0,0,0,0,0,0,0
endlayer

layer
0,0,0,0,0,0,0,0,0,0,0,0,0,0,0,0,0,0,0,0,0,0,0,0,0,0
0,0,0,0,0,0,0,0,0,0,0,0,0,0,0,0,0,0,0,0,0,0,0,0,0,0
0,0,0,0,0,0,0,0,0,0,0,0,0,0,0,0,0,0,0,0,0,0,0,0,0,0
0,0,0,0,0,0,0,0,0,0,0,0,0,0,0,0,0,0,0,0,0,0,0,0,0,0
0,0,0,0,0,0,0,0,0,0,0,0,0,0,0,0,0,0,0,0,0,0,0,0,0,0
0,0,0,0,0,0,0,0,0,0,0,0,0,0,0,0,0,0,0,0,0,0,0,0,0,0
0,0,0,0,0,0,0,0,0,0,0,0,0,0,0,0,0,0,0,0,0,0,0,0,0,0
0,0,0,0,0,0,0,0,0,0,0,0,0,0,0,0,0,0,0,0,0,0,0,0,0,0
0,0,0,0,0,0,0,0,0,0,0,0,0,0,0,0,0,0,0,0,0,0,0,0,0,0
0,0,0,0,0,0,0,0,0,0,0,0,0,0,0,0,0,0,0,0,0,0,0,0,0,0
0,0,0,0,0,0,0,0,0,0,0,0,0,0,0,0,0,0,0,0,0,0,0,0,0,0
0,0,0,0,0,0,0,0,0,0,0,0,0,0,0,0,0,0,0,0,0,0,0,0,0,0
0,0,0,0,0,0,0,0,0,0,0,0,0,0,0,11,20,21,20,21,20,21,20,11,0,0
0,0,0,0,0,0,0,0,0,0,0,0,0,22,21,36,36,36,36,0,0,15,17,20,0,0
0,0,0,0,0,0,0,0,0,0,0,0,21,0,0,36,36,36,36,0,0,0,15,21,0,0
0,0,0,0,0,0,0,0,0,0,0,22,38,0,0,36,36,36,36,26,26,0,0,20,0,0
0,0,0,0,0,0,0,0,0,0,0,21,39,0,37,36,36,36,36,26,25,0,8,21,0,0
0,0,0,0,0,0,0,0,0,0,0,21,39,0,37,36,36,36,36,26,0,0,8,21,0,0
0,0,0,0,0,0,0,0,0,0,0,22,38,0,0,36,36,36,36,26,26,0,0,20,0,0
0,0,0,0,0,0,0,0,0,0,0,0,21,0,0,36,36,36,36,0,0,0,15,21,0,0
0,0,0,0,0,0,0,0,0,0,0,0,0,22,21,36,36,36,36,0,0,15,17,20,0,0
0,0,0,0,0,0,0,0,0,0,0,0,0,0,0,11,20,21,20,21,20,21,20,11,0,0
0,0,0,0,0,0,0,0,0,0,0,0,0,0,0,0,0,0,0,0,0,0,0,0,0,0
0,0,0,0,0,0,0,0,0,0,0,0,0,0,0,0,0,0,0,0,0,0,0,0,0,0
0,0,0,0,0,0,0,0,0,0,0,0,0,0,0,0,0,0,0,0,0,0,0,0,0,0
0,0,0,0,0,0,0,0,0,0,0,0,0,0,0,0,0,0,0,0,0,0,0,0,0,0
0,0,0,0,0,0,0,0,0,0,0,0,0,0,0,0,0,0,0,0,0,0,0,0,0,0
0,0,0,0,0,0,0,0,0,0,0,0,0,0,0,0,0,0,0,0,0,0,0,0,0,0
0,0,0,0,0,0,0,0,0,0,0,0,0,0,0,0,0,0,0,0,0,0,0,0,0,0
0,0,0,0,0,0,0,0,0,0,0,0,0,0,0,0,0,0,0,0,0,0,0,0,0,0
0,0,0,0,0,0,0,0,0,0,0,0,0,0,0,0,0,0,0,0,0,0,0,0,0,0
0,0,0,0,0,0,0,0,0,0,0,0,0,0,0,0,0,0,0,0,0,0,0,0,0,0
0,0,0,0,0,0,0,0,0,0,0,0,0,0,0,0,0,0,0,0,0,0,0,0,0,0
0,0,0,0,0,0,0,0,0,0,0,0,0,0,0,0,0,0,0,0,0,0,0,0,0,0
endlayer

layer
0,0,0,0,0,0,0,0,0,0,0,0,0,0,0,0,0,0,0,0,0,0,0,0,0,0
0,0,0,0,0,0,0,0,0,0,0,0,0,0,0,0,0,0,0,0,0,0,0,0,0,0
0,0,0,0,0,0,0,0,0,0,0,0,0,0,0,0,0,0,0,0,0,0,0,0,0,0
0,0,0,0,0,0,0,0,0,0,0,0,0,0,0,0,0,0,0,0,0,0,0,0,0,0
0,0,0,0,0,0,0,0,0,0,0,0,0,0,0,0,0,0,0,0,0,0,0,0,0,0
0,0,0,0,0,0,0,0,0,0,0,0,0,0,0,0,0,0,0,0,0,0,0,0,0,0
0,0,0,0,0,0,0,0,0,0,0,0,0,0,0,0,0,0,0,0,0,0,0,0,0,0
0,0,0,0,0,0,0,0,0,0,0,0,0,0,0,0,0,0,0,0,0,0,0,0,0,0
0,0,0,0,0,0,0,0,0,0,0,0,0,0,0,0,0,0,0,0,0,0,0,0,0,0
0,0,0,0,0,0,0,0,0,0,0,0,0,0,0,0,0,0,0,0,0,0,0,0,0,0
0,0,0,0,0,0,0,0,0,0,0,0,0,0,0,0,0,0,0,0,0,0,0,0,0,0
0,0,0,0,0,0,0,0,0,0,0,0,0,0,0,0,0,0,0,0,0,0,0,0,0,0
0,0,0,0,0,0,0,0,0,0,0,0,0,0,0,11,20,21,20,21,20,21,20,11,0,0
0,0,0,0,0,0,0,0,0,0,0,0,0,22,21,0,0,0,0,0,0,0,15,20,0,0
0,0,0,0,0,0,0,0,0,0,0,0,21,0,0,0,0,0,0,0,0,0,0,21,0,0
0,0,0,0,0,0,0,0,0,0,0,22,0,0,0,0,0,0,0,34,0,0,0,20,0,0
0,0,0,0,0,0,0,0,0,0,0,21,0,0,0,0,0,0,0,0,0,0,0,21,0,0
0,0,0,0,0,0,0,0,0,0,0,21,0,0,0,0,0,0,0,0,0,0,0,21,0,0
0,0,0,0,0,0,0,0,0,0,0,22,0,0,0,0,0,0,0,35,0,0,0,20,0,0
0,0,0,0,0,0,0,0,0,0,0,0,21,0,0,0,0,0,0,0,0,0,0,21,0,0
0,0,0,0,0,0,0,0,0,0,0,0,0,22,21,0,0,0,0,0,0,0,15,20,0,0
0,0,0,0,0,0,0,0,0,0,0,0,0,0,0,11,20,21,20,21,20,21,20,11,0,0
0,0,0,0,0,0,0,0,0,0,0,0,0,0,0,0,0,0,0,0,0,0,0,0,0,0
0,0,0,0,0,0,0,0,0,0,0,0,0,0,0,0,0,0,0,0,0,0,0,0,0,0
0,0,0,0,0,0,0,0,0,0,0,0,0,0,0,0,0,0,0,0,0,0,0,0,0,0
0,0,0,0,0,0,0,0,0,0,0,0,0,0,0,0,0,0,0,0,0,0,0,0,0,0
0,0,0,0,0,0,0,0,0,0,0,0,0,0,0,0,0,0,0,0,0,0,0,0,0,0
0,0,0,0,0,0,0,0,0,0,0,0,0,0,0,0,0,0,0,0,0,0,0,0,0,0
0,0,0,0,0,0,0,0,0,0,0,0,0,0,0,0,0,0,0,0,0,0,0,0,0,0
0,0,0,0,0,0,0,0,0,0,0,0,0,0,0,0,0,0,0,0,0,0,0,0,0,0
0,0,0,0,0,0,0,0,0,0,0,0,0,0,0,0,0,0,0,0,0,0,0,0,0,0
0,0,0,0,0,0,0,0,0,0,0,0,0,0,0,0,0,0,0,0,0,0,0,0,0,0
0,0,0,0,0,0,0,0,0,0,0,0,0,0,0,0,0,0,0,0,0,0,0,0,0,0
0,0,0,0,0,0,0,0,0,0,0,0,0,0,0,0,0,0,0,0,0,0,0,0,0,0
endlayer

layer
0,0,0,0,0,0,0,0,0,0,0,0,0,0,0,0,0,0,0,0,0,0,0,0,0,0
0,0,0,0,0,0,0,0,0,0,0,0,0,0,0,0,0,0,0,0,0,0,0,0,0,0
0,0,0,0,0,0,0,0,0,0,0,0,0,0,0,0,0,0,0,0,0,0,0,0,0,0
0,0,0,0,0,0,0,0,0,0,0,0,0,0,0,0,0,0,0,0,0,0,0,0,0,0
0,0,0,0,0,0,0,0,0,0,0,0,0,0,0,0,0,0,0,0,0,0,0,0,0,0
0,0,0,0,0,0,0,0,0,0,0,0,0,0,0,0,0,0,0,0,0,0,0,0,0,0
0,0,0,0,0,0,0,0,0,0,0,0,0,0,0,0,0,0,0,0,0,0,0,0,0,0
0,0,0,0,0,0,0,0,0,0,0,0,0,0,0,0,0,0,0,0,0,0,0,0,0,0
0,0,0,0,0,0,0,0,0,0,0,0,0,0,0,0,0,0,0,0,0,0,0,0,0,0
0,0,0,0,0,0,0,0,0,0,0,0,0,0,0,0,0,0,0,0,0,0,0,0,0,0
0,0,0,0,0,0,0,0,0,0,0,0,0,0,0,0,0,0,0,0,0,0,0,0,0,0
0,0,0,0,0,0,0,0,0,0,0,0,0,0,0,0,0,0,0,0,0,0,0,0,0,0
0,0,0,0,0,0,0,0,0,0,0,0,0,0,0,11,20,21,20,21,20,21,20,11,0,0
0,0,0,0,0,0,0,0,0,0,0,0,0,22,21,0,0,0,0,0,0,0,0,20,0,0
0,0,0,0,0,0,0,0,0,0,0,0,21,0,0,0,0,0,0,0,0,0,0,21,0,0
0,0,0,0,0,0,0,0,0,0,0,22,0,0,0,0,0,0,0,0,0,0,0,20,0,0
0,0,0,0,0,0,0,0,0,0,0,21,0,0,0,0,0,0,0,0,0,0,0,21,0,0
0,0,0,0,0,0,0,0,0,0,0,21,0,0,0,0,0,0,0,0,0,0,0,21,0,0
0,0,0,0,0,0,0,0,0,0,0,22,0,0,0,0,0,0,0,0,0,0,0,20,0,0
0,0,0,0,0,0,0,0,0,0,0,0,21,0,0,0,0,0,0,0,0,0,0,21,0,0
0,0,0,0,0,0,0,0,0,0,0,0,0,22,21,0,0,0,0,0,0,0,0,20,0,0
0,0,0,0,0,0,0,0,0,0,0,0,0,0,0,11,20,21,20,21,20,21,20,11,0,0
0,0,0,0,0,0,0,0,0,0,0,0,0,0,0,0,0,0,0,0,0,0,0,0,0,0
0,0,0,0,0,0,0,0,0,0,0,0,0,0,0,0,0,0,0,0,0,0,0,0,0,0
0,0,0,0,0,0,0,0,0,0,0,0,0,0,0,0,0,0,0,0,0,0,0,0,0,0
0,0,0,0,0,0,0,0,0,0,0,0,0,0,0,0,0,0,0,0,0,0,0,0,0,0
0,0,0,0,0,0,0,0,0,0,0,0,0,0,0,0,0,0,0,0,0,0,0,0,0,0
0,0,0,0,0,0,0,0,0,0,0,0,0,0,0,0,0,0,0,0,0,0,0,0,0,0
0,0,0,0,0,0,0,0,0,0,0,0,0,0,0,0,0,0,0,0,0,0,0,0,0,0
0,0,0,0,0,0,0,0,0,0,0,0,0,0,0,0,0,0,0,0,0,0,0,0,0,0
0,0,0,0,0,0,0,0,0,0,0,0,0,0,0,0,0,0,0,0,0,0,0,0,0,0
0,0,0,0,0,0,0,0,0,0,0,0,0,0,0,0,0,0,0,0,0,0,0,0,0,0
0,0,0,0,0,0,0,0,0,0,0,0,0,0,0,0,0,0,0,0,0,0,0,0,0,0
0,0,0,0,0,0,0,0,0,0,0,0,0,0,0,0,0,0,0,0,0,0,0,0,0,0
endlayer

layer
0,0,0,0,0,0,0,0,0,0,0,0,0,0,0,0,0,0,0,0,0,0,0,0,0,0
0,0,0,0,0,0,0,0,0,0,0,0,0,0,0,0,0,0,0,0,0,0,0,0,0,0
0,0,0,0,0,0,0,0,0,0,0,0,0,0,0,0,0,0,0,0,0,0,0,0,0,0
0,0,0,0,0,0,0,0,0,0,0,0,0,0,0,0,0,0,0,0,0,0,0,0,0,0
0,0,0,0,0,0,0,0,0,0,0,0,0,0,0,0,0,0,0,0,0,0,0,0,0,0
0,0,0,0,0,0,0,0,0,0,0,0,0,0,0,0,0,0,0,0,0,0,0,0,0,0
0,0,0,0,0,0,0,0,0,0,0,0,0,0,0,0,0,0,0,0,0,0,0,0,0,0
0,0,0,0,0,0,0,0,0,0,0,0,0,0,0,0,0,0,0,0,0,0,0,0,0,0
0,0,0,0,0,0,0,0,0,0,0,0,0,0,0,0,0,0,0,0,0,0,0,0,0,0
0,0,0,0,0,0,0,0,0,0,0,0,0,0,0,0,0,0,0,0,0,0,0,0,0,0
0,0,0,0,0,0,0,0,0,0,0,0,0,0,0,0,0,0,0,0,0,0,0,0,0,0
0,0,0,0,0,0,0,0,0,0,0,0,0,0,0,0,0,0,0,0,0,0,0,0,0,0
0,0,0,0,0,0,0,0,0,0,0,0,0,0,0,11,20,21,20,21,20,21,20,11,0,0
0,0,0,0,0,0,0,0,0,0,0,0,0,22,21,0,0,0,0,0,0,0,0,20,0,0
0,0,0,0,0,0,0,0,0,0,0,0,21,0,0,0,0,0,0,0,0,0,0,21,0,0
0,0,0,0,0,0,0,0,0,0,0,22,0,0,0,0,0,0,0,0,0,0,0,20,0,0
0,0,0,0,0,0,0,0,0,0,0,21,0,0,0,0,0,0,0,0,0,0,0,21,0,0
0,0,0,0,0,0,0,0,0,0,0,21,0,0,0,0,0,0,0,0,0,0,0,21,0,0
0,0,0,0,0,0,0,0,0,0,0,22,0,0,0,0,0,0,0,0,0,0,0,20,0,0
0,0,0,0,0,0,0,0,0,0,0,0,21,0,0,0,0,0,0,0,0,0,0,21,0,0
0,0,0,0,0,0,0,0,0,0,0,0,0,22,21,0,0,0,0,0,0,0,0,20,0,0
0,0,0,0,0,0,0,0,0,0,0,0,0,0,0,11,20,21,20,21,20,21,20,11,0,0
0,0,0,0,0,0,0,0,0,0,0,0,0,0,0,0,0,0,0,0,0,0,0,0,0,0
0,0,0,0,0,0,0,0,0,0,0,0,0,0,0,0,0,0,0,0,0,0,0,0,0,0
0,0,0,0,0,0,0,0,0,0,0,0,0,0,0,0,0,0,0,0,0,0,0,0,0,0
0,0,0,0,0,0,0,0,0,0,0,0,0,0,0,0,0,0,0,0,0,0,0,0,0,0
0,0,0,0,0,0,0,0,0,0,0,0,0,0,0,0,0,0,0,0,0,0,0,0,0,0
0,0,0,0,0,0,0,0,0,0,0,0,0,0,0,0,0,0,0,0,0,0,0,0,0,0
0,0,0,0,0,0,0,0,0,0,0,0,0,0,0,0,0,0,0,0,0,0,0,0,0,0
0,0,0,0,0,0,0,0,0,0,0,0,0,0,0,0,0,0,0,0,0,0,0,0,0,0
0,0,0,0,0,0,0,0,0,0,0,0,0,0,0,0,0,0,0,0,0,0,0,0,0,0
0,0,0,0,0,0,0,0,0,0,0,0,0,0,0,0,0,0,0,0,0,0,0,0,0,0
0,0,0,0,0,0,0,0,0,0,0,0,0,0,0,0,0,0,0,0,0,0,0,0,0,0
0,0,0,0,0,0,0,0,0,0,0,0,0,0,0,0,0,0,0,0,0,0,0,0,0,0
endlayer

layer
0,0,0,0,0,0,0,0,0,0,0,0,0,0,0,0,0,0,0,0,0,0,0,0,0,0
0,0,0,0,0,0,0,0,0,0,0,0,0,0,0,0,0,0,0,0,0,0,0,0,0,0
0,0,0,0,0,0,0,0,0,0,0,0,0,0,0,0,0,0,0,0,0,0,0,0,0,0
0,0,0,0,0,0,0,0,0,0,0,0,0,0,0,0,0,0,0,0,0,0,0,0,0,0
0,0,0,0,0,0,0,0,0,0,0,0,0,0,0,0,0,0,0,0,0,0,0,0,0,0
0,0,0,0,0,0,0,0,0,0,0,0,0,0,0,0,0,0,0,0,0,0,0,0,0,0
0,0,0,0,0,0,0,0,0,0,0,0,0,0,0,0,0,0,0,0,0,0,0,0,0,0
0,0,0,0,0,0,0,0,0,0,0,0,0,0,0,0,0,0,0,0,0,0,0,0,0,0
0,0,0,0,0,0,0,0,0,0,0,0,0,0,0,0,0,0,0,0,0,0,0,0,0,0
0,0,0,0,0,0,0,0,0,0,0,0,0,0,0,0,0,0,0,0,0,0,0,0,0,0
0,0,0,0,0,0,0,0,0,0,0,0,0,0,0,0,0,0,0,0,0,0,0,0,0,0
0,0,0,0,0,0,0,0,0,0,0,0,0,0,0,0,0,0,0,0,0,0,0,0,0,0
0,0,0,0,0,0,0,0,0,0,0,0,0,0,0,11,20,21,20,21,20,21,20,11,0,0
0,0,0,0,0,0,0,0,0,0,0,0,0,22,21,0,0,0,0,0,0,0,0,20,0,0
0,0,0,0,0,0,0,0,0,0,0,0,21,0,0,0,0,0,0,0,0,0,0,21,0,0
0,0,0,0,0,0,0,0,0,0,0,22,0,0,0,0,0,0,0,0,0,0,0,20,0,0
0,0,0,0,0,0,0,0,0,0,0,21,0,0,0,0,0,0,0,0,0,0,0,21,0,0
0,0,0,0,0,0,0,0,0,0,0,21,0,0,0,0,0,0,0,0,0,0,0,21,0,0
0,0,0,0,0,0,0,0,0,0,0,22,0,0,0,0,0,0,0,0,0,0,0,20,0,0
0,0,0,0,0,0,0,0,0,0,0,0,21,0,0,0,0,0,0,0,0,0,0,21,0,0
0,0,0,0,0,0,0,0,0,0,0,0,0,22,21,0,0,0,0,0,0,0,0,20,0,0
0,0,0,0,0,0,0,0,0,0,0,0,0,0,0,11,20,21,20,21,20,21,20,11,0,0
0,0,0,0,0,0,0,0,0,0,0,0,0,0,0,0,0,0,0,0,0,0,0,0,0,0
0,0,0,0,0,0,0,0,0,0,0,0,0,0,0,0,0,0,0,0,0,0,0,0,0,0
0,0,0,0,0,0,0,0,0,0,0,0,0,0,0,0,0,0,0,0,0,0,0,0,0,0
0,0,0,0,0,0,0,0,0,0,0,0,0,0,0,0,0,0,0,0,0,0,0,0,0,0
0,0,0,0,0,0,0,0,0,0,0,0,0,0,0,0,0,0,0,0,0,0,0,0,0,0
0,0,0,0,0,0,0,0,0,0,0,0,0,0,0,0,0,0,0,0,0,0,0,0,0,0
0,0,0,0,0,0,0,0,0,0,0,0,0,0,0,0,0,0,0,0,0,0,0,0,0,0
0,0,0,0,0,0,0,0,0,0,0,0,0,0,0,0,0,0,0,0,0,0,0,0,0,0
0,0,0,0,0,0,0,0,0,0,0,0,0,0,0,0,0,0,0,0,0,0,0,0,0,0
0,0,0,0,0,0,0,0,0,0,0,0,0,0,0,0,0,0,0,0,0,0,0,0,0,0
0,0,0,0,0,0,0,0,0,0,0,0,0,0,0,0,0,0,0,0,0,0,0,0,0,0
0,0,0,0,0,0,0,0,0,0,0,0,0,0,0,0,0,0,0,0,0,0,0,0,0,0
endlayer

layer
0,0,0,0,0,0,0,0,0,0,0,0,0,0,0,0,0,0,0,0,0,0,0,0,0,0
0,0,0,0,0,0,0,0,0,0,0,0,0,0,0,0,0,0,0,0,0,0,0,0,0,0
0,0,0,0,0,0,0,0,0,0,0,0,0,0,0,0,0,0,0,0,0,0,0,0,0,0
0,0,0,0,0,0,0,0,0,0,0,0,0,0,0,0,0,0,0,0,0,0,0,0,0,0
0,0,0,0,0,0,0,0,0,0,0,0,0,0,0,0,0,0,0,0,0,0,0,0,0,0
0,0,0,0,0,0,0,0,0,0,0,0,0,0,0,0,0,0,0,0,0,0,0,0,0,0
0,0,0,0,0,0,0,0,0,0,0,0,0,0,0,0,0,0,0,0,0,0,0,0,0,0
0,0,0,0,0,0,0,0,0,0,0,0,0,0,0,0,0,0,0,0,0,0,0,0,0,0
0,0,0,0,0,0,0,0,0,0,0,0,0,0,0,0,0,0,0,0,0,0,0,0,0,0
0,0,0,0,0,0,0,0,0,0,0,0,0,0,0,0,0,0,0,0,0,0,0,0,0,0
0,0,0,0,0,0,0,0,0,0,0,0,0,0,0,0,0,0,0,0,0,0,0,0,0,0
0,0,0,0,0,0,0,0,0,0,0,0,0,0,0,0,0,0,0,0,0,0,0,0,0,0
0,0,0,0,0,0,0,0,0,0,0,0,0,0,0,11,11,11,11,11,11,11,11,11,0,0
0,0,0,0,0,0,0,0,0,0,0,0,0,11,11,24,24,24,24,24,24,24,24,11,0,0
0,0,0,0,0,0,0,0,0,0,0,0,11,24,24,24,24,24,24,24,24,24,24,11,0,0
0,0,0,0,0,0,0,0,0,0,0,11,24,24,24,24,40,40,40,40,40,24,24,11,0,0
0,0,0,0,0,0,0,0,0,0,0,11,24,24,40,40,40,40,40,40,40,24,24,11,0,0
0,0,0,0,0,0,0,0,0,0,0,11,24,24,40,40,40,40,40,40,40,24,24,11,0,0
0,0,0,0,0,0,0,0,0,0,0,11,24,24,24,24,40,40,40,40,40,24,24,11,0,0
0,0,0,0,0,0,0,0,0,0,0,0,11,24,24,24,24,24,24,24,24,24,24,11,0,0
0,0,0,0,0,0,0,0,0,0,0,0,0,11,11,24,24,24,24,24,24,24,24,11,0,0
0,0,0,0,0,0,0,0,0,0,0,0,0,0,0,11,11,11,11,11,11,11,11,11,0,0
0,0,0,0,0,0,0,0,0,0,0,0,0,0,0,0,0,0,0,0,0,0,0,0,0,0
0,0,0,0,0,0,0,0,0,0,0,0,0,0,0,0,0,0,0,0,0,0,0,0,0,0
0,0,0,0,0,0,0,0,0,0,0,0,0,0,0,0,0,0,0,0,0,0,0,0,0,0
0,0,0,0,0,0,0,0,0,0,0,0,0,0,0,0,0,0,0,0,0,0,0,0,0,0
0,0,0,0,0,0,0,0,0,0,0,0,0,0,0,0,0,0,0,0,0,0,0,0,0,0
0,0,0,0,0,0,0,0,0,0,0,0,0,0,0,0,0,0,0,0,0,0,0,0,0,0
0,0,0,0,0,0,0,0,0,0,0,0,0,0,0,0,0,0,0,0,0,0,0,0,0,0
0,0,0,0,0,0,0,0,0,0,0,0,0,0,0,0,0,0,0,0,0,0,0,0,0,0
0,0,0,0,0,0,0,0,0,0,0,0,0,0,0,0,0,0,0,0,0,0,0,0,0,0
0,0,0,0,0,0,0,0,0,0,0,0,0,0,0,0,0,0,0,0,0,0,0,0,0,0
0,0,0,0,0,0,0,0,0,0,0,0,0,0,0,0,0,0,0,0,0,0,0,0,0,0
0,0,0,0,0,0,0,0,0,0,0,0,0,0,0,0,0,0,0,0,0,0,0,0,0,0
endlayer

