weight=2
embed_into_distance=4
dimensions=22,34,24
max_cut_in=0


rule1=0,100,250
rule2=0,100,2761-15,2761-15,2761-15,2762-13,2762-13,2762-13,2762-13,2762-13,2762-13,2762-13
rule3=0,66,250
rule4=0,100,2835-6
rule5=0,100,2835-7
rule6=0,100,3134-10
rule7=0,100,3,250,250,250,250,250,250,250,250,250
rule8=0,100,2761-9
rule9=0,100,2843-4
rule10=0,100,2542-0
rule11=0,66,311
rule12=0,100,3123-5
rule13=0,100,2843-14,2843-14,2843-14,2843-14,2843
rule14=0,100,2844-12
rule15=0,100,5
rule16=0,100,2248-0
rule17=0,100,2291-0
rule18=0,100,2779-8
rule19=0,100,47,2837-5,2837-1
rule20=0,75,308,308,308,308,308,308,313,313,314,327
rule21=0,100,2765-11
rule22=0,66,3225-3
rule23=0,95,2835-2,2835-2,2835-2,2835-2,2835-2,2835-2,2835-2,2835-1,2835-1,2835-0
rule24=0,100,2761-5
rule25=0,100,2765-6
rule26=0,100,3245-0
rule27=0,100,2761-10
rule28=0,100,2844-9
rule29=0,100,2844-4
rule30=0,100,2778-10
rule31=0,100,2248-1
rule32=0,100,2245-1
rule33=0,100,2291-1
rule34=0,100,47,2837-7,2837-5,2837-8
rule35=0,66,140-10
rule36=0,100,0
rule37=0,100,0
rule38=0,100,2761-2
rule39=0,100,2763-4
rule40=0,100,2765-15
rule41=0,100,2844-14
rule42=0,100,2245-1
rule43=0,100,2291-1
rule44=0,100,2837-5,2837-4
rule45=0,25,2244-4
rule46=0,100,0
rule47=0,100,0
rule48=0,100,2788-9


layer
1,1,1,1,1,1,1,1,1,1,1,1,1,1,1,1,1,1,1,1,1,1,1,1
1,1,1,1,1,1,1,1,1,1,1,1,1,1,1,1,1,1,1,1,1,1,1,1
1,1,1,1,1,1,1,1,1,1,1,1,1,1,1,1,1,1,1,1,1,1,1,1
1,1,1,1,1,1,1,1,1,1,1,1,1,1,1,1,1,1,1,1,1,1,1,1
1,1,1,1,1,1,1,1,1,1,1,1,1,2,2,2,2,2,2,2,1,1,1,1
1,1,1,1,1,1,1,1,1,1,1,1,1,2,2,2,2,2,2,2,1,1,1,1
1,1,1,1,1,1,1,1,1,1,1,1,1,2,2,2,2,2,2,2,1,1,1,1
1,1,1,1,1,1,1,1,1,1,1,1,1,2,2,2,2,2,2,2,1,1,1,1
1,1,1,1,1,1,1,1,1,1,1,1,1,2,2,2,2,2,2,2,1,1,1,1
1,1,1,1,1,1,1,1,1,1,1,1,1,2,2,2,2,2,2,2,1,1,1,1
1,1,1,1,1,1,1,1,1,1,1,1,1,2,2,2,2,2,2,2,1,1,1,1
1,1,1,1,1,1,1,1,1,1,1,1,1,1,1,1,1,1,1,1,1,1,1,1
1,1,1,1,1,1,1,1,1,1,1,1,1,1,1,1,1,1,1,1,1,1,1,1
1,1,1,1,1,1,1,1,1,1,1,1,1,1,1,1,1,1,1,1,1,1,1,1
1,1,1,1,1,1,1,1,1,1,1,1,1,1,1,1,1,1,1,1,1,1,1,1
1,1,1,1,1,1,1,1,1,1,1,1,1,1,1,1,1,1,1,1,1,1,1,1
1,1,1,1,1,1,1,1,1,1,1,1,1,1,1,1,1,1,1,1,1,1,1,1
1,1,1,1,1,1,1,1,1,1,1,1,1,1,1,1,1,1,1,1,1,1,1,1
1,1,1,1,1,1,1,1,1,1,1,1,1,1,1,1,1,1,1,1,1,1,1,1
1,1,1,1,1,1,1,1,1,1,1,1,1,1,1,1,1,1,1,1,1,1,1,1
1,1,1,1,1,1,1,1,1,1,1,1,1,1,1,1,1,1,1,1,1,1,1,1
1,1,1,1,1,1,1,1,1,1,1,1,1,1,1,1,1,1,1,1,1,1,1,1
1,1,1,1,1,1,1,1,1,1,1,1,1,1,1,1,1,1,1,1,1,1,1,1
1,1,1,1,1,1,1,1,1,1,1,1,1,2,2,2,2,2,2,2,1,1,1,1
1,1,1,1,1,1,1,1,1,1,1,1,1,2,2,2,2,2,2,2,1,1,1,1
1,1,1,1,1,1,1,1,1,1,1,1,1,2,2,2,2,2,2,2,1,1,1,1
1,1,1,1,1,1,1,1,1,1,1,1,1,2,2,2,2,2,2,2,1,1,1,1
1,1,1,1,1,1,1,1,1,1,1,1,1,2,2,2,2,2,2,2,1,1,1,1
1,1,1,1,1,1,1,1,1,1,1,1,1,2,2,2,2,2,2,2,1,1,1,1
1,1,1,1,1,1,1,1,1,1,1,1,1,2,2,2,2,2,2,2,1,1,1,1
1,1,1,1,1,1,1,1,1,1,1,1,1,1,1,1,1,1,1,1,1,1,1,1
1,1,1,1,1,1,1,1,1,1,1,1,1,1,1,1,1,1,1,1,1,1,1,1
1,1,1,1,1,1,1,1,1,1,1,1,1,1,1,1,1,1,1,1,1,1,1,1
1,1,1,1,1,1,1,1,1,1,1,1,1,1,1,1,1,1,1,1,1,1,1,1
endlayer

layer
1,1,1,1,1,1,1,1,1,1,1,1,1,1,1,1,1,1,1,1,1,1,1,1
1,1,1,1,1,1,1,1,1,1,1,1,1,1,1,1,1,1,1,1,1,1,1,1
1,1,1,1,1,1,1,1,1,1,1,1,1,1,1,1,1,1,1,1,1,1,1,1
1,1,1,1,1,1,1,1,1,1,1,1,1,1,1,1,1,1,1,1,1,1,1,1
1,1,1,1,1,1,1,1,1,1,1,1,1,2,2,2,2,2,2,2,1,1,1,1
1,1,1,1,1,1,1,1,1,1,1,1,1,2,3,3,3,3,3,2,1,1,1,1
1,1,1,1,1,1,1,1,1,1,1,1,1,2,3,3,3,3,3,2,1,1,1,1
1,1,1,1,1,1,1,1,1,1,1,1,1,2,3,3,4,3,3,2,1,1,1,1
1,1,1,1,1,1,1,1,1,1,1,1,1,2,3,3,3,3,3,2,1,1,1,1
1,1,1,1,1,1,1,1,1,1,1,1,1,2,3,3,3,3,3,2,1,1,1,1
1,1,1,1,1,1,1,1,1,1,1,1,1,2,2,2,2,2,2,2,1,1,1,1
1,1,1,1,1,1,1,1,1,1,1,1,1,1,1,1,1,1,1,1,1,1,1,1
1,1,1,1,1,1,1,1,1,1,1,1,1,1,1,1,1,1,1,1,1,1,1,1
1,1,1,1,1,1,1,1,1,1,1,1,1,1,1,1,1,1,1,1,1,1,1,1
1,1,1,1,1,1,1,1,1,1,1,1,1,1,1,1,1,1,1,1,1,1,1,1
1,1,1,1,1,1,1,1,1,1,1,1,1,1,1,1,1,1,1,1,1,1,1,1
1,1,1,1,1,1,1,1,1,1,1,1,1,1,1,1,1,1,1,1,1,1,1,1
1,1,1,1,1,1,1,1,1,1,1,1,1,1,1,1,1,1,1,1,1,1,1,1
1,1,1,1,1,1,1,1,1,1,1,1,1,1,1,1,1,1,1,1,1,1,1,1
1,1,1,1,1,1,1,1,1,1,1,1,1,1,1,1,1,1,1,1,1,1,1,1
1,1,1,1,1,1,1,1,1,1,1,1,1,1,1,1,1,1,1,1,1,1,1,1
1,1,1,1,1,1,1,1,1,1,1,1,1,1,1,1,1,1,1,1,1,1,1,1
1,1,1,1,1,1,1,1,1,1,1,1,1,1,1,1,1,1,1,1,1,1,1,1
1,1,1,1,1,1,1,1,1,1,1,1,1,2,2,2,2,2,2,2,1,1,1,1
1,1,1,1,1,1,1,1,1,1,1,1,1,2,3,3,3,3,3,2,1,1,1,1
1,1,1,1,1,1,1,1,1,1,1,1,1,2,3,3,3,3,3,2,1,1,1,1
1,1,1,1,1,1,1,1,1,1,1,1,1,2,3,3,4,3,3,2,1,1,1,1
1,1,1,1,1,1,1,1,1,1,1,1,1,2,3,3,3,3,3,2,1,1,1,1
1,1,1,1,1,1,1,1,1,1,1,1,1,2,3,3,3,3,3,2,1,1,1,1
1,1,1,1,1,1,1,1,1,1,1,1,1,2,2,2,2,2,2,2,1,1,1,1
1,1,1,1,1,1,1,1,1,1,1,1,1,1,1,1,1,1,1,1,1,1,1,1
1,1,1,1,1,1,1,1,1,1,1,1,1,1,1,1,1,1,1,1,1,1,1,1
1,1,1,1,1,1,1,1,1,1,1,1,1,1,1,1,1,1,1,1,1,1,1,1
1,1,1,1,1,1,1,1,1,1,1,1,1,1,1,1,1,1,1,1,1,1,1,1
endlayer

layer
1,1,1,1,1,1,1,1,1,1,1,1,1,1,1,1,1,1,1,1,1,1,1,1
1,1,1,1,1,1,1,1,1,1,1,1,1,1,1,1,1,1,1,1,1,1,1,1
1,1,1,1,1,1,1,1,1,1,1,1,1,1,1,1,1,1,1,1,1,1,1,1
1,1,1,1,1,1,1,1,1,1,1,1,1,1,1,1,1,1,1,1,1,1,1,1
1,1,1,1,1,1,1,1,1,1,1,1,1,2,2,2,2,2,2,2,1,1,1,1
1,1,1,1,1,1,1,1,1,1,1,1,1,2,3,3,3,3,3,2,1,1,1,1
1,1,1,1,1,1,1,1,1,1,1,1,1,2,3,3,3,3,3,2,1,1,1,1
1,1,1,1,1,1,1,1,1,1,1,1,1,2,3,3,5,3,3,2,1,1,1,1
1,1,1,1,1,1,1,1,1,1,1,1,1,2,3,3,3,3,3,2,1,1,1,1
1,1,1,1,1,1,1,1,1,1,1,1,1,2,3,3,3,3,3,2,1,1,1,1
1,1,1,1,1,1,1,1,1,1,1,1,1,2,2,2,2,2,2,2,1,1,1,1
1,1,1,1,1,1,1,1,1,1,1,1,1,1,1,1,1,1,1,1,1,1,1,1
1,1,1,1,1,1,1,1,1,1,1,1,1,1,1,1,1,1,1,1,1,1,1,1
1,1,1,1,1,1,1,1,1,1,1,1,1,1,1,1,1,1,1,1,1,1,1,1
1,1,1,1,1,1,1,1,1,1,1,1,1,1,1,1,1,1,1,1,1,1,1,1
1,1,1,1,1,1,1,1,1,1,1,1,1,1,1,1,1,1,1,1,1,1,1,1
1,1,1,1,1,1,1,1,1,1,1,1,1,1,1,1,1,1,1,1,1,1,1,1
1,1,1,1,1,1,1,1,1,1,1,1,1,1,1,1,1,1,1,1,1,1,1,1
1,1,1,1,1,1,1,1,1,1,1,1,1,1,1,1,1,1,1,1,1,1,1,1
1,1,1,1,1,1,1,1,1,1,1,1,1,1,1,1,1,1,1,1,1,1,1,1
1,1,1,1,1,1,1,1,1,1,1,1,1,1,1,1,1,1,1,1,1,1,1,1
1,1,1,1,1,1,1,1,1,1,1,1,1,1,1,1,1,1,1,1,1,1,1,1
1,1,1,1,1,1,1,1,1,1,1,1,1,1,1,1,1,1,1,1,1,1,1,1
1,1,1,1,1,1,1,1,1,1,1,1,1,2,2,2,2,2,2,2,1,1,1,1
1,1,1,1,1,1,1,1,1,1,1,1,1,2,3,3,3,3,3,2,1,1,1,1
1,1,1,1,1,1,1,1,1,1,1,1,1,2,3,3,3,3,3,2,1,1,1,1
1,1,1,1,1,1,1,1,1,1,1,1,1,2,3,3,5,3,3,2,1,1,1,1
1,1,1,1,1,1,1,1,1,1,1,1,1,2,3,3,3,3,3,2,1,1,1,1
1,1,1,1,1,1,1,1,1,1,1,1,1,2,3,3,3,3,3,2,1,1,1,1
1,1,1,1,1,1,1,1,1,1,1,1,1,2,2,2,2,2,2,2,1,1,1,1
1,1,1,1,1,1,1,1,1,1,1,1,1,1,1,1,1,1,1,1,1,1,1,1
1,1,1,1,1,1,1,1,1,1,1,1,1,1,1,1,1,1,1,1,1,1,1,1
1,1,1,1,1,1,1,1,1,1,1,1,1,1,1,1,1,1,1,1,1,1,1,1
1,1,1,1,1,1,1,1,1,1,1,1,1,1,1,1,1,1,1,1,1,1,1,1
endlayer

layer
6,6,6,6,6,6,6,6,6,6,6,6,6,6,6,6,6,6,6,6,6,6,6,6
6,6,6,6,6,6,6,6,6,6,6,6,6,6,6,6,6,6,6,6,6,6,6,6
6,6,7,7,7,7,7,7,7,7,7,7,7,7,7,7,7,7,7,7,7,7,6,6
6,6,7,9,9,9,9,9,9,9,7,7,7,7,7,7,7,7,7,7,7,7,6,6
6,6,7,9,9,9,9,9,9,9,7,7,7,2,2,2,2,2,2,2,7,7,6,6
6,6,7,9,9,9,9,9,9,9,7,7,7,2,3,3,3,3,3,2,7,7,6,6
6,6,7,9,9,9,9,9,9,9,7,7,7,2,3,3,3,3,3,2,7,7,6,6
6,6,7,9,9,9,9,9,9,9,2,2,2,2,3,0,4,3,3,2,7,7,6,6
6,6,7,9,9,9,9,9,9,9,7,7,7,2,3,3,3,3,3,2,7,7,6,6
6,6,7,9,9,9,9,9,9,9,7,7,7,2,3,3,3,3,3,2,7,7,6,6
6,6,7,9,9,9,9,9,9,9,7,7,7,2,2,2,2,2,2,2,7,7,6,6
6,6,7,9,9,9,11,9,9,9,7,7,7,7,7,7,7,7,7,7,7,7,6,6
6,6,7,9,9,9,9,9,9,9,7,7,7,7,7,7,7,7,7,7,7,7,6,6
6,6,7,9,9,9,9,9,9,9,10,9,9,7,7,7,7,7,7,7,7,7,6,6
6,6,7,9,9,9,9,9,9,9,9,9,9,7,7,7,7,7,7,7,7,7,6,6
6,6,7,9,9,9,9,9,9,9,9,9,9,9,7,7,7,7,7,7,7,7,6,6
6,6,7,9,9,9,9,9,9,9,9,9,9,9,8,8,8,8,8,8,8,8,6,6
6,6,7,9,9,9,9,9,9,9,9,9,9,9,8,8,8,8,8,8,8,8,6,6
6,6,7,9,9,9,9,9,9,9,9,9,9,9,7,7,7,7,7,7,7,7,6,6
6,6,7,9,9,9,9,9,9,9,9,9,9,7,7,7,7,7,7,7,7,7,6,6
6,6,7,9,9,9,9,9,9,9,9,9,0,7,7,7,7,7,7,7,7,7,6,6
6,6,7,9,9,9,9,9,9,9,7,7,7,7,7,7,7,7,7,7,7,7,6,6
6,6,7,9,9,9,11,9,9,9,7,7,7,7,7,7,7,7,7,7,7,7,6,6
6,6,7,9,9,9,9,9,9,9,7,7,7,2,2,2,2,2,2,2,7,7,6,6
6,6,7,9,9,9,9,9,9,9,7,7,7,2,3,3,3,3,3,2,7,7,6,6
6,6,7,9,9,9,9,9,9,9,7,7,7,2,3,3,3,3,3,2,7,7,6,6
6,6,7,9,9,9,9,9,9,9,2,2,2,2,3,3,4,3,3,2,7,7,6,6
6,6,7,9,9,9,9,9,9,9,7,7,7,2,3,3,3,3,3,2,7,7,6,6
6,6,7,9,9,9,9,9,9,9,7,7,7,2,3,3,3,3,3,2,7,7,6,6
6,6,7,9,9,9,9,9,9,9,7,7,7,2,2,2,2,2,2,2,7,7,6,6
6,6,7,9,9,9,9,9,9,9,7,7,7,7,7,7,7,7,7,7,7,7,6,6
6,6,7,7,7,7,7,7,7,7,7,7,7,7,7,7,7,7,7,7,7,7,6,6
6,6,6,6,6,6,6,6,6,6,6,6,6,6,6,6,6,6,6,6,6,6,6,6
6,6,6,6,6,6,6,6,6,6,6,6,6,6,6,6,6,6,6,6,6,6,6,6
endlayer

layer
0,0,0,0,0,0,0,0,0,0,0,0,0,0,0,0,0,0,0,0,0,0,0,0
0,0,0,0,0,0,0,0,0,0,0,0,0,0,0,0,0,0,0,0,0,0,0,0
0,0,13,13,13,13,13,13,13,13,13,12,12,12,12,12,12,12,12,12,12,12,0,0
0,0,13,0,0,0,0,0,0,0,13,0,0,0,0,0,0,0,0,0,0,12,0,0
0,0,13,0,0,19,18,19,0,0,13,0,0,0,0,0,0,0,0,0,0,12,0,0
0,0,13,0,17,16,18,16,17,0,13,0,0,0,0,0,0,0,0,0,0,12,0,0
0,0,13,0,18,18,18,18,18,0,13,0,0,0,0,0,0,0,0,0,0,12,0,0
0,0,13,0,0,19,18,19,0,0,0,0,0,0,0,0,4,0,0,0,0,12,0,0
0,0,13,0,17,16,18,16,17,0,13,0,0,0,0,0,0,0,0,0,0,12,0,0
0,0,13,0,18,18,20,18,18,0,13,0,0,0,0,0,0,0,0,0,0,12,0,0
0,0,13,0,17,16,18,16,17,0,13,0,0,0,0,0,0,0,0,0,0,12,0,0
0,0,13,0,0,19,18,19,0,0,13,0,0,0,0,0,0,0,0,0,0,12,0,0
0,0,13,14,14,14,14,14,14,14,13,0,0,0,0,0,0,0,0,0,0,12,0,0
0,0,13,14,14,14,14,14,14,14,14,13,13,0,0,0,0,0,0,0,0,12,0,0
0,0,13,14,14,14,14,14,14,14,14,14,14,13,0,0,0,0,0,0,0,12,0,0
0,0,13,14,14,14,14,14,14,15,15,14,14,14,13,12,12,12,12,12,12,12,0,0
0,0,13,14,14,14,14,14,14,14,16,14,14,14,0,0,0,0,0,0,0,0,0,0
0,0,13,14,14,14,14,14,14,14,16,14,14,14,0,0,0,0,0,0,0,0,0,0
0,0,13,14,14,14,14,14,14,15,15,14,14,14,13,12,12,12,12,12,12,12,0,0
0,0,13,14,14,14,14,14,14,14,14,14,14,13,0,0,0,0,0,0,0,12,0,0
0,0,13,14,14,14,14,14,14,14,14,13,13,0,0,0,0,0,0,0,0,12,0,0
0,0,13,14,14,14,14,14,14,14,13,0,0,0,0,0,0,0,0,0,0,12,0,0
0,0,13,0,0,19,18,19,0,0,13,0,0,0,0,0,0,0,0,0,0,12,0,0
0,0,13,0,17,16,18,16,17,0,13,0,0,0,0,0,0,0,0,0,0,12,0,0
0,0,13,0,18,18,20,18,18,0,13,0,0,0,0,0,0,0,0,0,0,12,0,0
0,0,13,0,17,16,18,16,17,0,13,0,0,0,0,0,0,0,0,0,0,12,0,0
0,0,13,0,0,19,18,19,0,0,0,0,0,0,0,0,4,0,0,0,0,12,0,0
0,0,13,0,18,18,18,18,18,0,13,0,0,0,0,0,0,0,0,0,0,12,0,0
0,0,13,0,17,16,18,16,17,0,13,0,0,0,0,0,0,0,0,0,0,12,0,0
0,0,13,0,0,19,18,19,0,0,13,0,0,0,0,0,0,0,0,0,0,12,0,0
0,0,13,0,0,0,0,0,0,0,13,0,0,0,0,0,0,0,0,0,0,12,0,0
0,0,13,13,13,13,13,13,13,13,13,12,12,12,12,12,12,12,12,12,12,12,0,0
0,0,0,0,0,0,0,0,0,0,0,0,0,0,0,0,0,0,0,0,0,0,0,0
0,0,0,0,0,0,0,0,0,0,0,0,0,0,0,0,0,0,0,0,0,0,0,0
endlayer

layer
0,0,0,0,0,0,0,0,0,0,0,0,0,0,0,0,0,0,0,0,0,0,0,0
0,0,0,0,0,0,0,0,0,0,0,0,0,0,0,0,0,0,0,0,0,0,0,0
0,0,13,23,22,23,22,23,22,23,13,0,0,0,0,0,0,0,0,0,0,0,0,0
0,0,23,0,0,0,0,0,0,0,23,0,0,0,0,0,0,0,0,0,0,0,0,0
0,0,22,0,0,19,18,19,0,0,22,0,0,0,0,0,0,0,0,0,0,0,0,0
0,0,23,0,0,0,18,0,0,0,23,0,0,0,0,0,0,0,0,0,0,0,0,0
0,0,22,0,18,18,18,18,18,0,22,0,0,0,0,0,0,0,0,0,0,0,0,0
0,0,23,0,0,19,18,19,0,0,0,0,0,0,0,0,5,0,0,0,0,0,0,0
0,0,22,0,0,0,18,0,0,0,22,0,0,0,0,0,0,0,0,0,0,0,0,0
0,0,23,0,18,18,18,18,18,0,23,0,0,0,0,0,0,0,0,0,0,0,0,0
0,0,22,0,0,0,18,0,0,0,22,0,0,0,0,0,0,0,0,0,0,0,0,0
0,0,23,0,0,19,18,19,0,0,23,0,0,0,0,0,0,0,0,0,0,0,0,0
0,0,13,0,0,0,0,0,0,0,13,0,0,0,0,0,0,0,0,0,0,0,0,0
0,0,23,0,0,0,0,0,0,0,0,22,21,0,0,0,0,0,0,0,0,0,0,0
0,0,22,0,0,0,0,0,0,0,0,0,0,22,0,0,0,0,0,0,0,0,0,0
0,0,23,0,0,0,0,0,0,0,0,0,0,0,21,0,0,0,0,0,0,0,0,0
0,0,22,0,0,0,0,0,0,0,0,0,0,0,0,0,0,0,0,0,0,0,0,0
0,0,22,0,0,0,0,0,0,0,0,0,0,0,0,0,0,0,0,0,0,0,0,0
0,0,23,0,0,0,0,0,0,0,0,0,0,0,21,0,0,0,0,0,0,0,0,0
0,0,22,0,0,0,0,0,0,0,0,0,0,22,0,0,0,0,0,0,0,0,0,0
0,0,23,0,0,0,0,0,0,0,0,22,21,0,0,0,0,0,0,0,0,0,0,0
0,0,13,0,0,0,0,0,0,0,13,0,0,0,0,0,0,0,0,0,0,0,0,0
0,0,23,0,0,19,18,19,0,0,23,0,0,0,0,0,0,0,0,0,0,0,0,0
0,0,22,0,0,0,18,0,0,0,22,0,0,0,0,0,0,0,0,0,0,0,0,0
0,0,23,0,18,18,18,18,18,0,23,0,0,0,0,0,0,0,0,0,0,0,0,0
0,0,22,0,0,0,18,0,0,0,22,0,0,0,0,0,0,0,0,0,0,0,0,0
0,0,23,0,0,19,18,19,0,0,0,0,0,0,0,0,5,0,0,0,0,0,0,0
0,0,22,0,18,18,18,18,18,0,22,0,0,0,0,0,0,0,0,0,0,0,0,0
0,0,23,0,0,0,18,0,0,0,23,0,0,0,0,0,0,0,0,0,0,0,0,0
0,0,22,0,0,19,18,19,0,0,22,0,0,0,0,0,0,0,0,0,0,0,0,0
0,0,23,0,0,0,0,0,0,0,23,0,0,0,0,0,0,0,0,0,0,0,0,0
0,0,13,23,22,23,22,23,22,23,13,0,0,0,0,0,0,0,0,0,0,0,0,0
0,0,0,0,0,0,0,0,0,0,0,0,0,0,0,0,0,0,0,0,0,0,0,0
0,0,0,0,0,0,0,0,0,0,0,0,0,0,0,0,0,0,0,0,0,0,0,0
endlayer

layer
0,0,0,0,0,0,0,0,0,0,0,0,0,0,0,0,0,0,0,0,0,0,0,0
0,0,0,0,0,0,0,0,0,0,0,0,0,0,0,0,0,0,0,0,0,0,0,0
0,0,13,23,22,23,22,23,22,23,13,0,0,0,0,0,0,0,0,0,0,0,0,0
0,0,23,0,0,0,0,0,0,0,23,0,0,0,0,0,0,0,0,0,0,0,0,0
0,0,22,0,0,0,0,0,0,0,22,0,0,0,0,0,0,0,0,0,0,0,0,0
0,0,23,0,0,0,0,0,0,0,23,0,0,0,0,0,0,0,0,0,0,0,0,0
0,0,22,0,0,0,0,0,0,0,22,0,0,0,0,0,0,0,0,0,0,0,0,0
0,0,23,0,0,0,0,0,0,0,23,0,0,0,0,0,4,0,0,0,0,0,0,0
0,0,22,0,0,0,0,0,0,0,22,0,0,0,0,0,0,0,0,0,0,0,0,0
0,0,23,0,0,0,0,0,0,0,23,0,0,0,0,0,0,0,0,0,0,0,0,0
0,0,22,0,0,0,0,0,0,0,22,0,0,0,0,0,0,0,0,0,0,0,0,0
0,0,23,0,0,0,0,0,0,0,23,0,0,0,0,0,0,0,0,0,0,0,0,0
0,0,13,0,0,0,0,0,0,0,13,0,0,0,0,0,0,0,0,0,0,0,0,0
0,0,23,0,0,0,0,0,0,0,0,22,21,0,0,0,0,0,0,0,0,0,0,0
0,0,22,0,0,0,0,0,0,0,0,0,0,22,0,0,0,0,0,0,0,0,0,0
0,0,23,0,0,0,0,0,0,0,0,0,0,0,21,0,0,0,0,0,0,0,0,0
0,0,22,0,0,0,0,0,0,0,0,0,0,0,0,0,0,0,0,0,0,0,0,0
0,0,22,0,0,0,0,0,0,0,0,0,0,0,0,0,0,0,0,0,0,0,0,0
0,0,23,0,0,0,0,0,0,0,0,0,0,0,21,0,0,0,0,0,0,0,0,0
0,0,22,0,0,0,0,0,0,0,0,0,0,22,0,0,0,0,0,0,0,0,0,0
0,0,23,0,0,0,0,0,0,0,0,22,21,0,0,0,0,0,0,0,0,0,0,0
0,0,13,0,0,0,0,0,0,0,13,0,0,0,0,0,0,0,0,0,0,0,0,0
0,0,23,0,0,0,0,0,0,0,23,0,0,0,0,0,0,0,0,0,0,0,0,0
0,0,22,0,0,0,0,0,0,0,22,0,0,0,0,0,0,0,0,0,0,0,0,0
0,0,23,0,0,0,0,0,0,0,23,0,0,0,0,0,0,0,0,0,0,0,0,0
0,0,22,0,0,0,0,0,0,0,22,0,0,0,0,0,0,0,0,0,0,0,0,0
0,0,23,0,0,0,0,0,0,0,23,0,0,0,0,0,4,0,0,0,0,0,0,0
0,0,22,0,0,0,0,0,0,0,22,0,0,0,0,0,0,0,0,0,0,0,0,0
0,0,23,0,0,0,0,0,0,0,23,0,0,0,0,0,0,0,0,0,0,0,0,0
0,0,22,0,0,0,0,0,0,0,22,0,0,0,0,0,0,0,0,0,0,0,0,0
0,0,23,0,0,0,0,0,0,0,23,0,0,0,0,0,0,0,0,0,0,0,0,0
0,0,13,23,22,23,22,23,22,23,13,0,0,0,0,0,0,0,0,0,0,0,0,0
0,0,0,0,0,0,0,0,0,0,0,0,0,0,0,0,0,0,0,0,0,0,0,0
0,0,0,0,0,0,0,0,0,0,0,0,0,0,0,0,0,0,0,0,0,0,0,0
endlayer

layer
0,0,0,0,0,0,0,0,0,0,0,0,0,0,0,0,0,0,0,0,0,0,0,0
0,0,0,0,0,0,0,0,0,0,0,0,0,0,0,0,0,0,0,0,0,0,0,0
0,0,13,23,22,23,22,23,22,23,13,0,0,0,0,0,0,0,0,0,0,0,0,0
0,0,23,0,0,0,0,0,0,0,23,0,0,0,0,0,0,0,0,0,0,0,0,0
0,0,22,0,0,0,0,0,0,0,22,0,0,0,0,0,0,0,0,0,0,0,0,0
0,0,23,0,0,0,0,0,0,0,23,0,0,0,0,0,0,0,0,0,0,0,0,0
0,0,22,0,0,0,0,0,0,0,22,0,0,0,0,0,0,0,0,0,0,0,0,0
0,0,23,0,0,0,0,0,0,0,23,0,0,0,0,0,0,0,0,0,0,0,0,0
0,0,22,0,0,0,0,0,0,0,22,0,0,0,0,0,0,0,0,0,0,0,0,0
0,0,23,0,0,0,0,0,0,0,23,0,0,0,0,0,0,0,0,0,0,0,0,0
0,0,22,0,0,0,0,0,0,0,22,0,0,0,0,0,0,0,0,0,0,0,0,0
0,0,23,0,0,0,0,0,0,0,23,0,0,0,0,0,0,0,0,0,0,0,0,0
0,0,13,0,0,0,0,0,0,0,13,0,0,0,0,0,0,0,0,0,0,0,0,0
0,0,23,0,0,0,0,0,0,0,0,22,21,0,0,0,0,0,0,0,0,0,0,0
0,0,22,0,0,0,0,0,0,0,0,0,0,22,0,0,0,0,0,0,0,0,0,0
0,0,23,0,0,0,0,0,0,0,0,0,0,0,21,0,0,0,0,0,0,0,0,0
0,0,22,0,0,0,0,0,0,0,0,0,0,0,0,0,0,0,0,0,0,0,0,0
0,0,22,0,0,0,0,0,0,0,0,0,0,0,0,0,0,0,0,0,0,0,0,0
0,0,23,0,0,0,0,0,0,0,0,0,0,0,21,0,0,0,0,0,0,0,0,0
0,0,22,0,0,0,0,0,0,0,0,0,0,22,0,0,0,0,0,0,0,0,0,0
0,0,23,0,0,0,0,0,0,0,0,22,21,0,0,0,0,0,0,0,0,0,0,0
0,0,13,0,0,0,0,0,0,0,13,0,0,0,0,0,0,0,0,0,0,0,0,0
0,0,23,0,0,0,0,0,0,0,23,0,0,0,0,0,0,0,0,0,0,0,0,0
0,0,22,0,0,0,0,0,0,0,22,0,0,0,0,0,0,0,0,0,0,0,0,0
0,0,23,0,0,0,0,0,0,0,23,0,0,0,0,0,0,0,0,0,0,0,0,0
0,0,22,0,0,0,0,0,0,0,22,0,0,0,0,0,0,0,0,0,0,0,0,0
0,0,23,0,0,0,0,0,0,0,23,0,0,0,0,0,0,0,0,0,0,0,0,0
0,0,22,0,0,0,0,0,0,0,22,0,0,0,0,0,0,0,0,0,0,0,0,0
0,0,23,0,0,0,0,0,0,0,23,0,0,0,0,0,0,0,0,0,0,0,0,0
0,0,22,0,0,0,0,0,0,0,22,0,0,0,0,0,0,0,0,0,0,0,0,0
0,0,23,0,0,0,0,0,0,0,23,0,0,0,0,0,0,0,0,0,0,0,0,0
0,0,13,23,22,23,22,23,22,23,13,0,0,0,0,0,0,0,0,0,0,0,0,0
0,0,0,0,0,0,0,0,0,0,0,0,0,0,0,0,0,0,0,0,0,0,0,0
0,0,0,0,0,0,0,0,0,0,0,0,0,0,0,0,0,0,0,0,0,0,0,0
endlayer

layer
0,0,0,0,0,0,0,0,0,0,0,0,0,0,0,0,0,0,0,0,0,0,0,0
0,0,0,0,0,0,0,0,0,0,0,0,0,0,0,0,0,0,0,0,0,0,0,0
0,0,13,23,22,23,22,23,22,23,13,0,0,0,0,0,0,0,0,0,0,0,0,0
0,0,23,0,0,0,0,0,0,0,23,0,0,0,0,0,0,0,0,0,0,0,0,0
0,0,22,0,0,0,0,0,0,0,22,0,0,0,0,0,0,0,0,0,0,0,0,0
0,0,23,0,0,0,0,0,0,0,23,0,0,0,0,0,0,0,0,0,0,0,0,0
0,0,22,0,0,0,0,0,0,0,22,0,0,0,0,0,0,0,0,0,0,0,0,0
0,0,23,0,0,0,0,0,0,0,23,0,0,0,0,0,0,0,0,0,0,0,0,0
0,0,22,0,0,0,0,0,0,0,22,0,0,0,0,0,0,0,0,0,0,0,0,0
0,0,23,0,0,0,0,0,0,0,23,0,0,0,0,0,0,0,0,0,0,0,0,0
0,0,22,0,0,0,0,0,0,0,22,0,0,0,0,0,0,0,0,0,0,0,0,0
0,0,23,0,0,0,0,0,0,0,23,0,0,0,0,0,0,0,0,0,0,0,0,0
0,0,13,0,0,0,0,0,0,0,13,0,0,0,0,0,0,0,0,0,0,0,0,0
0,0,23,0,0,0,0,0,0,0,0,22,21,0,0,0,0,0,0,0,0,0,0,0
0,0,22,0,0,0,0,0,0,0,0,0,0,22,0,0,0,0,0,0,0,0,0,0
0,0,23,0,0,0,0,0,0,0,0,0,0,0,21,0,0,0,0,0,0,0,0,0
0,0,22,0,0,0,0,0,0,0,0,0,0,0,0,0,0,0,0,0,0,0,0,0
0,0,22,0,0,0,0,0,0,0,0,0,0,0,0,0,0,0,0,0,0,0,0,0
0,0,23,0,0,0,0,0,0,0,0,0,0,0,21,0,0,0,0,0,0,0,0,0
0,0,22,0,0,0,0,0,0,0,0,0,0,22,0,0,0,0,0,0,0,0,0,0
0,0,23,0,0,0,0,0,0,0,0,22,21,0,0,0,0,0,0,0,0,0,0,0
0,0,13,0,0,0,0,0,0,0,13,0,0,0,0,0,0,0,0,0,0,0,0,0
0,0,23,0,0,0,0,0,0,0,23,0,0,0,0,0,0,0,0,0,0,0,0,0
0,0,22,0,0,0,0,0,0,0,22,0,0,0,0,0,0,0,0,0,0,0,0,0
0,0,23,0,0,0,0,0,0,0,23,0,0,0,0,0,0,0,0,0,0,0,0,0
0,0,22,0,0,0,0,0,0,0,22,0,0,0,0,0,0,0,0,0,0,0,0,0
0,0,23,0,0,0,0,0,0,0,23,0,0,0,0,0,0,0,0,0,0,0,0,0
0,0,22,0,0,0,0,0,0,0,22,0,0,0,0,0,0,0,0,0,0,0,0,0
0,0,23,0,0,0,0,0,0,0,23,0,0,0,0,0,0,0,0,0,0,0,0,0
0,0,22,0,0,0,0,0,0,0,22,0,0,0,0,0,0,0,0,0,0,0,0,0
0,0,23,0,0,0,0,0,0,0,23,0,0,0,0,0,0,0,0,0,0,0,0,0
0,0,13,23,22,23,22,23,22,23,13,0,0,0,0,0,0,0,0,0,0,0,0,0
0,0,0,0,0,0,0,0,0,0,0,0,0,0,0,0,0,0,0,0,0,0,0,0
0,0,0,0,0,0,0,0,0,0,0,0,0,0,0,0,0,0,0,0,0,0,0,0
endlayer

layer
0,0,0,0,0,0,0,0,0,0,0,0,0,0,0,0,0,0,0,0,0,0,0,0
0,0,0,0,0,0,0,0,0,0,0,0,0,0,0,0,0,0,0,0,0,0,0,0
0,0,13,13,13,13,13,13,13,13,13,0,0,0,0,0,0,0,0,0,0,0,0,0
0,0,13,24,24,24,24,24,24,24,13,0,0,0,0,0,0,0,0,0,0,0,0,0
0,0,13,24,24,24,24,24,24,24,13,0,0,0,0,0,0,0,0,0,0,0,0,0
0,0,13,24,24,24,24,24,24,24,13,0,0,0,0,0,0,0,0,0,0,0,0,0
0,0,13,24,24,24,24,24,24,24,13,0,0,0,0,0,0,0,0,0,0,0,0,0
0,0,13,9,9,9,9,9,9,9,13,0,0,0,0,0,0,0,0,0,0,0,0,0
0,0,13,9,9,9,9,9,9,9,13,0,0,0,0,0,0,0,0,0,0,0,0,0
0,0,13,9,9,9,9,9,9,9,13,0,0,0,0,0,0,0,0,0,0,0,0,0
0,0,13,9,9,9,9,9,9,9,13,0,0,0,0,0,0,0,0,0,0,0,0,0
0,0,13,9,9,9,9,9,9,9,13,0,0,0,0,0,0,0,0,0,0,0,0,0
0,0,13,9,9,9,9,9,9,9,13,0,0,0,0,0,0,0,0,0,0,0,0,0
0,0,13,9,9,9,9,9,9,9,10,13,13,0,0,0,0,0,0,0,0,0,0,0
0,0,13,9,9,9,9,9,9,9,9,9,9,13,0,0,0,0,0,0,0,0,0,0
0,0,13,9,9,9,9,9,9,9,9,9,9,9,13,0,0,0,0,0,0,0,0,0
0,0,13,9,9,9,9,9,9,9,9,9,9,9,13,0,0,0,0,0,0,0,0,0
0,0,13,9,9,9,9,9,9,9,9,9,9,9,13,0,0,0,0,0,0,0,0,0
0,0,13,9,9,9,9,9,9,9,9,9,9,9,13,0,0,0,0,0,0,0,0,0
0,0,13,9,9,9,9,9,9,9,9,9,9,13,0,0,0,0,0,0,0,0,0,0
0,0,13,9,9,9,9,9,9,9,9,13,13,0,0,0,0,0,0,0,0,0,0,0
0,0,13,9,9,9,9,9,9,9,13,0,0,0,0,0,0,0,0,0,0,0,0,0
0,0,13,9,9,9,9,9,9,9,13,0,0,0,0,0,0,0,0,0,0,0,0,0
0,0,13,9,9,9,9,9,9,9,13,0,0,0,0,0,0,0,0,0,0,0,0,0
0,0,13,9,9,9,9,9,9,9,13,0,0,0,0,0,0,0,0,0,0,0,0,0
0,0,13,9,9,9,9,9,9,9,13,0,0,0,0,0,0,0,0,0,0,0,0,0
0,0,13,9,9,9,9,9,9,9,13,0,0,0,0,0,0,0,0,0,0,0,0,0
0,0,13,24,24,24,24,24,24,24,13,0,0,0,0,0,0,0,0,0,0,0,0,0
0,0,13,24,24,24,24,24,24,24,13,0,0,0,0,0,0,0,0,0,0,0,0,0
0,0,13,24,24,24,24,24,24,24,13,0,0,0,0,0,0,0,0,0,0,0,0,0
0,0,13,24,24,24,24,24,24,24,13,0,0,0,0,0,0,0,0,0,0,0,0,0
0,0,13,13,13,13,13,13,13,13,13,0,0,0,0,0,0,0,0,0,0,0,0,0
0,0,0,0,0,0,0,0,0,0,0,0,0,0,0,0,0,0,0,0,0,0,0,0
0,0,0,0,0,0,0,0,0,0,0,0,0,0,0,0,0,0,0,0,0,0,0,0
endlayer

layer
0,0,0,0,0,0,0,0,0,0,0,0,0,0,0,0,0,0,0,0,0,0,0,0
0,0,0,0,0,0,0,0,0,0,0,0,0,0,0,0,0,0,0,0,0,0,0,0
0,0,0,0,0,0,0,0,0,0,0,0,0,0,0,0,0,0,0,0,0,0,0,0
0,0,0,0,0,0,0,0,0,0,0,0,0,0,0,0,0,0,0,0,0,0,0,0
0,0,0,0,0,0,0,0,0,0,0,0,0,0,0,0,0,0,0,0,0,0,0,0
0,0,0,0,0,0,0,0,0,0,0,0,0,0,0,0,0,0,0,0,0,0,0,0
0,0,13,23,22,23,22,23,22,23,13,0,0,0,0,0,0,0,0,0,0,0,0,0
0,0,23,20,34,0,0,0,0,0,23,0,0,0,0,0,0,0,0,0,0,0,0,0
0,0,22,34,0,32,29,29,29,0,22,0,0,0,0,0,0,0,0,0,0,0,0,0
0,0,22,0,33,32,29,29,29,0,22,0,0,0,0,0,0,0,0,0,0,0,0,0
0,0,22,0,0,0,29,29,29,0,22,0,0,0,0,0,0,0,0,0,0,0,0,0
0,0,23,11,0,0,0,0,0,0,23,0,0,0,0,0,0,0,0,0,0,0,0,0
0,0,13,23,23,23,23,23,0,23,13,0,0,0,0,0,0,0,0,0,0,0,0,0
0,0,23,34,0,0,0,28,28,28,28,22,21,0,0,0,0,0,0,0,0,0,0,0
0,0,22,0,0,30,30,28,28,28,28,0,0,22,0,0,0,0,0,0,0,0,0,0
0,0,23,0,0,0,30,28,28,28,28,0,0,25,21,0,0,0,0,0,0,0,0,0
0,0,22,0,0,0,31,28,28,28,28,27,0,26,22,0,0,0,0,0,0,0,0,0
0,0,22,0,0,0,31,28,28,28,28,27,0,26,22,0,0,0,0,0,0,0,0,0
0,0,23,0,0,0,30,28,28,28,28,0,0,25,21,0,0,0,0,0,0,0,0,0
0,0,22,0,0,30,30,28,28,28,28,0,0,22,0,0,0,0,0,0,0,0,0,0
0,0,23,34,0,0,0,28,28,28,28,22,21,0,0,0,0,0,0,0,0,0,0,0
0,0,13,23,23,23,23,23,0,23,13,0,0,0,0,0,0,0,0,0,0,0,0,0
0,0,23,11,0,0,0,0,0,0,23,0,0,0,0,0,0,0,0,0,0,0,0,0
0,0,22,0,0,0,29,29,29,0,22,0,0,0,0,0,0,0,0,0,0,0,0,0
0,0,22,0,0,32,29,29,29,0,22,0,0,0,0,0,0,0,0,0,0,0,0,0
0,0,22,34,33,32,29,29,29,0,22,0,0,0,0,0,0,0,0,0,0,0,0,0
0,0,23,20,34,0,0,0,0,0,23,0,0,0,0,0,0,0,0,0,0,0,0,0
0,0,13,23,22,23,22,23,22,23,13,0,0,0,0,0,0,0,0,0,0,0,0,0
0,0,0,0,0,0,0,0,0,0,0,0,0,0,0,0,0,0,0,0,0,0,0,0
0,0,0,0,0,0,0,0,0,0,0,0,0,0,0,0,0,0,0,0,0,0,0,0
0,0,0,0,0,0,0,0,0,0,0,0,0,0,0,0,0,0,0,0,0,0,0,0
0,0,0,0,0,0,0,0,0,0,0,0,0,0,0,0,0,0,0,0,0,0,0,0
0,0,0,0,0,0,0,0,0,0,0,0,0,0,0,0,0,0,0,0,0,0,0,0
0,0,0,0,0,0,0,0,0,0,0,0,0,0,0,0,0,0,0,0,0,0,0,0
endlayer

layer
0,0,0,0,0,0,0,0,0,0,0,0,0,0,0,0,0,0,0,0,0,0,0,0
0,0,0,0,0,0,0,0,0,0,0,0,0,0,0,0,0,0,0,0,0,0,0,0
0,0,0,0,0,0,0,0,0,0,0,0,0,0,0,0,0,0,0,0,0,0,0,0
0,0,0,0,0,0,0,0,0,0,0,0,0,0,0,0,0,0,0,0,0,0,0,0
0,0,0,0,0,0,0,0,0,0,0,0,0,0,0,0,0,0,0,0,0,0,0,0
0,0,0,0,0,0,0,0,0,0,0,0,0,0,0,0,0,0,0,0,0,0,0,0
0,0,13,23,22,23,22,23,22,23,13,0,0,0,0,0,0,0,0,0,0,0,0,0
0,0,23,34,0,0,0,0,0,0,23,0,0,0,0,0,0,0,0,0,0,0,0,0
0,0,22,0,0,45,0,0,0,0,22,0,0,0,0,0,0,0,0,0,0,0,0,0
0,0,22,0,0,0,0,0,0,0,22,0,0,0,0,0,0,0,0,0,0,0,0,0
0,0,22,0,0,0,0,0,0,0,22,0,0,0,0,0,0,0,0,0,0,0,0,0
0,0,23,37,36,36,0,0,0,0,23,0,0,0,0,0,0,0,0,0,0,0,0,0
0,0,13,23,23,23,23,23,0,23,13,0,0,0,0,0,0,0,0,0,0,0,0,0
0,0,23,34,0,0,0,0,0,0,0,22,21,0,0,0,0,0,0,0,0,0,0,0
0,0,22,0,0,0,35,0,0,0,0,0,0,22,0,0,0,0,0,0,0,0,0,0
0,0,23,0,0,0,0,0,0,0,0,0,0,0,21,0,0,0,0,0,0,0,0,0
0,0,22,0,0,0,0,0,0,0,0,35,0,0,22,0,0,0,0,0,0,0,0,0
0,0,22,0,0,0,0,0,0,0,0,0,0,0,22,0,0,0,0,0,0,0,0,0
0,0,23,0,0,0,0,0,0,0,0,0,0,0,21,0,0,0,0,0,0,0,0,0
0,0,22,0,0,0,0,0,0,0,0,0,0,22,0,0,0,0,0,0,0,0,0,0
0,0,23,34,0,0,0,0,0,0,0,22,21,0,0,0,0,0,0,0,0,0,0,0
0,0,13,23,23,23,23,23,0,23,13,0,0,0,0,0,0,0,0,0,0,0,0,0
0,0,23,37,36,36,0,0,0,0,23,0,0,0,0,0,0,0,0,0,0,0,0,0
0,0,22,0,0,0,0,0,0,0,22,0,0,0,0,0,0,0,0,0,0,0,0,0
0,0,22,0,0,45,0,0,0,0,22,0,0,0,0,0,0,0,0,0,0,0,0,0
0,0,22,0,0,0,0,0,0,0,22,0,0,0,0,0,0,0,0,0,0,0,0,0
0,0,23,34,0,0,0,0,0,0,23,0,0,0,0,0,0,0,0,0,0,0,0,0
0,0,13,23,22,23,22,23,22,23,13,0,0,0,0,0,0,0,0,0,0,0,0,0
0,0,0,0,0,0,0,0,0,0,0,0,0,0,0,0,0,0,0,0,0,0,0,0
0,0,0,0,0,0,0,0,0,0,0,0,0,0,0,0,0,0,0,0,0,0,0,0
0,0,0,0,0,0,0,0,0,0,0,0,0,0,0,0,0,0,0,0,0,0,0,0
0,0,0,0,0,0,0,0,0,0,0,0,0,0,0,0,0,0,0,0,0,0,0,0
0,0,0,0,0,0,0,0,0,0,0,0,0,0,0,0,0,0,0,0,0,0,0,0
0,0,0,0,0,0,0,0,0,0,0,0,0,0,0,0,0,0,0,0,0,0,0,0
endlayer

layer
0,0,0,0,0,0,0,0,0,0,0,0,0,0,0,0,0,0,0,0,0,0,0,0
0,0,0,0,0,0,0,0,0,0,0,0,0,0,0,0,0,0,0,0,0,0,0,0
0,0,0,0,0,0,0,0,0,0,0,0,0,0,0,0,0,0,0,0,0,0,0,0
0,0,0,0,0,0,0,0,0,0,0,0,0,0,0,0,0,0,0,0,0,0,0,0
0,0,0,0,0,0,0,0,0,0,0,0,0,0,0,0,0,0,0,0,0,0,0,0
0,0,0,0,0,0,0,0,0,0,0,0,0,0,0,0,0,0,0,0,0,0,0,0
0,0,13,23,22,23,22,23,22,23,13,0,0,0,0,0,0,0,0,0,0,0,0,0
0,0,23,0,0,0,0,0,0,0,23,0,0,0,0,0,0,0,0,0,0,0,0,0
0,0,22,0,0,0,0,0,0,0,22,0,0,0,0,0,0,0,0,0,0,0,0,0
0,0,22,0,0,0,0,0,0,0,22,0,0,0,0,0,0,0,0,0,0,0,0,0
0,0,22,0,0,0,0,0,0,0,22,0,0,0,0,0,0,0,0,0,0,0,0,0
0,0,23,0,0,0,0,0,0,0,23,0,0,0,0,0,0,0,0,0,0,0,0,0
0,0,13,23,23,23,23,23,23,23,13,0,0,0,0,0,0,0,0,0,0,0,0,0
0,0,23,0,0,0,0,0,0,0,0,22,21,0,0,0,0,0,0,0,0,0,0,0
0,0,22,0,0,0,0,0,0,0,0,0,0,22,0,0,0,0,0,0,0,0,0,0
0,0,23,0,0,0,0,0,0,0,0,0,0,0,21,0,0,0,0,0,0,0,0,0
0,0,22,0,0,0,0,0,0,0,0,0,0,0,22,0,0,0,0,0,0,0,0,0
0,0,22,0,0,0,0,0,0,0,0,0,0,0,22,0,0,0,0,0,0,0,0,0
0,0,23,0,0,0,0,0,0,0,0,0,0,0,21,0,0,0,0,0,0,0,0,0
0,0,22,0,0,0,0,0,0,0,0,0,0,22,0,0,0,0,0,0,0,0,0,0
0,0,23,0,0,0,0,0,0,0,0,22,21,0,0,0,0,0,0,0,0,0,0,0
0,0,13,23,23,23,23,23,23,23,13,0,0,0,0,0,0,0,0,0,0,0,0,0
0,0,23,0,0,0,0,0,0,0,23,0,0,0,0,0,0,0,0,0,0,0,0,0
0,0,22,0,0,0,0,0,0,0,22,0,0,0,0,0,0,0,0,0,0,0,0,0
0,0,22,0,0,0,0,0,0,0,22,0,0,0,0,0,0,0,0,0,0,0,0,0
0,0,22,0,0,0,0,0,0,0,22,0,0,0,0,0,0,0,0,0,0,0,0,0
0,0,23,0,0,0,0,0,0,0,23,0,0,0,0,0,0,0,0,0,0,0,0,0
0,0,13,23,22,23,22,23,22,23,13,0,0,0,0,0,0,0,0,0,0,0,0,0
0,0,0,0,0,0,0,0,0,0,0,0,0,0,0,0,0,0,0,0,0,0,0,0
0,0,0,0,0,0,0,0,0,0,0,0,0,0,0,0,0,0,0,0,0,0,0,0
0,0,0,0,0,0,0,0,0,0,0,0,0,0,0,0,0,0,0,0,0,0,0,0
0,0,0,0,0,0,0,0,0,0,0,0,0,0,0,0,0,0,0,0,0,0,0,0
0,0,0,0,0,0,0,0,0,0,0,0,0,0,0,0,0,0,0,0,0,0,0,0
0,0,0,0,0,0,0,0,0,0,0,0,0,0,0,0,0,0,0,0,0,0,0,0
endlayer

layer
0,0,0,0,0,0,0,0,0,0,0,0,0,0,0,0,0,0,0,0,0,0,0,0
0,0,0,0,0,0,0,0,0,0,0,0,0,0,0,0,0,0,0,0,0,0,0,0
0,0,0,0,0,0,0,0,0,0,0,0,0,0,0,0,0,0,0,0,0,0,0,0
0,0,0,0,0,0,0,0,0,0,0,0,0,0,0,0,0,0,0,0,0,0,0,0
0,0,0,0,0,0,0,0,0,0,0,0,0,0,0,0,0,0,0,0,0,0,0,0
0,0,0,0,0,0,0,0,0,0,0,0,0,0,0,0,0,0,0,0,0,0,0,0
0,0,13,23,22,23,22,23,22,23,13,0,0,0,0,0,0,0,0,0,0,0,0,0
0,0,23,0,0,0,0,0,0,0,23,0,0,0,0,0,0,0,0,0,0,0,0,0
0,0,22,0,0,0,0,0,0,0,22,0,0,0,0,0,0,0,0,0,0,0,0,0
0,0,22,0,0,0,0,0,0,0,22,0,0,0,0,0,0,0,0,0,0,0,0,0
0,0,22,0,0,0,0,0,0,0,22,0,0,0,0,0,0,0,0,0,0,0,0,0
0,0,23,0,0,0,0,0,0,0,23,0,0,0,0,0,0,0,0,0,0,0,0,0
0,0,13,23,23,23,23,23,23,23,13,0,0,0,0,0,0,0,0,0,0,0,0,0
0,0,23,0,0,0,0,0,0,0,0,22,21,0,0,0,0,0,0,0,0,0,0,0
0,0,22,0,0,0,0,0,0,0,0,0,0,22,0,0,0,0,0,0,0,0,0,0
0,0,23,0,0,0,0,0,0,0,0,0,0,0,21,0,0,0,0,0,0,0,0,0
0,0,22,0,0,0,0,0,0,0,0,0,0,0,22,0,0,0,0,0,0,0,0,0
0,0,22,0,0,0,0,0,0,0,0,0,0,0,22,0,0,0,0,0,0,0,0,0
0,0,23,0,0,0,0,0,0,0,0,0,0,0,21,0,0,0,0,0,0,0,0,0
0,0,22,0,0,0,0,0,0,0,0,0,0,22,0,0,0,0,0,0,0,0,0,0
0,0,23,0,0,0,0,0,0,0,0,22,21,0,0,0,0,0,0,0,0,0,0,0
0,0,13,23,23,23,23,23,23,23,13,0,0,0,0,0,0,0,0,0,0,0,0,0
0,0,23,0,0,0,0,0,0,0,23,0,0,0,0,0,0,0,0,0,0,0,0,0
0,0,22,0,0,0,0,0,0,0,22,0,0,0,0,0,0,0,0,0,0,0,0,0
0,0,22,0,0,0,0,0,0,0,22,0,0,0,0,0,0,0,0,0,0,0,0,0
0,0,22,0,0,0,0,0,0,0,22,0,0,0,0,0,0,0,0,0,0,0,0,0
0,0,23,0,0,0,0,0,0,0,23,0,0,0,0,0,0,0,0,0,0,0,0,0
0,0,13,23,22,23,22,23,22,23,13,0,0,0,0,0,0,0,0,0,0,0,0,0
0,0,0,0,0,0,0,0,0,0,0,0,0,0,0,0,0,0,0,0,0,0,0,0
0,0,0,0,0,0,0,0,0,0,0,0,0,0,0,0,0,0,0,0,0,0,0,0
0,0,0,0,0,0,0,0,0,0,0,0,0,0,0,0,0,0,0,0,0,0,0,0
0,0,0,0,0,0,0,0,0,0,0,0,0,0,0,0,0,0,0,0,0,0,0,0
0,0,0,0,0,0,0,0,0,0,0,0,0,0,0,0,0,0,0,0,0,0,0,0
0,0,0,0,0,0,0,0,0,0,0,0,0,0,0,0,0,0,0,0,0,0,0,0
endlayer

layer
0,0,0,0,0,0,0,0,0,0,0,0,0,0,0,0,0,0,0,0,0,0,0,0
0,0,0,0,0,0,0,0,0,0,0,0,0,0,0,0,0,0,0,0,0,0,0,0
0,0,0,0,0,0,0,0,0,0,0,0,0,0,0,0,0,0,0,0,0,0,0,0
0,0,0,0,0,0,0,0,0,0,0,0,0,0,0,0,0,0,0,0,0,0,0,0
0,0,0,0,0,0,0,0,0,0,0,0,0,0,0,0,0,0,0,0,0,0,0,0
0,0,0,0,0,0,0,0,0,0,0,0,0,0,0,0,0,0,0,0,0,0,0,0
0,0,13,23,22,23,22,23,22,23,13,0,0,0,0,0,0,0,0,0,0,0,0,0
0,0,23,0,0,0,0,0,0,0,23,0,0,0,0,0,0,0,0,0,0,0,0,0
0,0,22,0,0,0,0,0,0,0,22,0,0,0,0,0,0,0,0,0,0,0,0,0
0,0,22,0,0,0,0,0,0,0,22,0,0,0,0,0,0,0,0,0,0,0,0,0
0,0,22,0,0,0,0,0,0,0,22,0,0,0,0,0,0,0,0,0,0,0,0,0
0,0,23,0,0,0,0,0,0,0,23,0,0,0,0,0,0,0,0,0,0,0,0,0
0,0,13,23,23,23,23,23,23,23,13,0,0,0,0,0,0,0,0,0,0,0,0,0
0,0,23,0,0,0,0,0,0,0,0,22,21,0,0,0,0,0,0,0,0,0,0,0
0,0,22,0,0,0,0,0,0,0,0,0,0,22,0,0,0,0,0,0,0,0,0,0
0,0,23,0,0,0,0,0,0,0,0,0,0,0,21,0,0,0,0,0,0,0,0,0
0,0,22,0,0,0,0,0,0,0,0,0,0,0,22,0,0,0,0,0,0,0,0,0
0,0,22,0,0,0,0,0,0,0,0,0,0,0,22,0,0,0,0,0,0,0,0,0
0,0,23,0,0,0,0,0,0,0,0,0,0,0,21,0,0,0,0,0,0,0,0,0
0,0,22,0,0,0,0,0,0,0,0,0,0,22,0,0,0,0,0,0,0,0,0,0
0,0,23,0,0,0,0,0,0,0,0,22,21,0,0,0,0,0,0,0,0,0,0,0
0,0,13,23,23,23,23,23,23,23,13,0,0,0,0,0,0,0,0,0,0,0,0,0
0,0,23,0,0,0,0,0,0,0,23,0,0,0,0,0,0,0,0,0,0,0,0,0
0,0,22,0,0,0,0,0,0,0,22,0,0,0,0,0,0,0,0,0,0,0,0,0
0,0,22,0,0,0,0,0,0,0,22,0,0,0,0,0,0,0,0,0,0,0,0,0
0,0,22,0,0,0,0,0,0,0,22,0,0,0,0,0,0,0,0,0,0,0,0,0
0,0,23,0,0,0,0,0,0,0,23,0,0,0,0,0,0,0,0,0,0,0,0,0
0,0,13,23,22,23,22,23,22,23,13,0,0,0,0,0,0,0,0,0,0,0,0,0
0,0,0,0,0,0,0,0,0,0,0,0,0,0,0,0,0,0,0,0,0,0,0,0
0,0,0,0,0,0,0,0,0,0,0,0,0,0,0,0,0,0,0,0,0,0,0,0
0,0,0,0,0,0,0,0,0,0,0,0,0,0,0,0,0,0,0,0,0,0,0,0
0,0,0,0,0,0,0,0,0,0,0,0,0,0,0,0,0,0,0,0,0,0,0,0
0,0,0,0,0,0,0,0,0,0,0,0,0,0,0,0,0,0,0,0,0,0,0,0
0,0,0,0,0,0,0,0,0,0,0,0,0,0,0,0,0,0,0,0,0,0,0,0
endlayer

layer
0,0,0,0,0,0,0,0,0,0,0,0,0,0,0,0,0,0,0,0,0,0,0,0
0,0,0,0,0,0,0,0,0,0,0,0,0,0,0,0,0,0,0,0,0,0,0,0
0,0,0,0,0,0,0,0,0,0,0,0,0,0,0,0,0,0,0,0,0,0,0,0
0,0,0,0,0,0,0,0,0,0,0,0,0,0,0,0,0,0,0,0,0,0,0,0
0,0,0,0,0,0,0,0,0,0,0,0,0,0,0,0,0,0,0,0,0,0,0,0
0,0,0,0,0,0,0,0,0,0,0,0,0,0,0,0,0,0,0,0,0,0,0,0
0,0,13,13,13,13,13,13,13,13,13,0,0,0,0,0,0,0,0,0,0,0,0,0
0,0,13,24,24,24,24,24,24,24,13,0,0,0,0,0,0,0,0,0,0,0,0,0
0,0,13,24,24,24,24,24,24,24,13,0,0,0,0,0,0,0,0,0,0,0,0,0
0,0,13,24,24,24,24,24,24,24,13,0,0,0,0,0,0,0,0,0,0,0,0,0
0,0,13,24,24,24,24,24,24,24,13,0,0,0,0,0,0,0,0,0,0,0,0,0
0,0,13,24,24,24,24,24,24,24,13,0,0,0,0,0,0,0,0,0,0,0,0,0
0,0,13,13,13,13,13,13,13,13,13,0,0,0,0,0,0,0,0,0,0,0,0,0
0,0,13,9,9,9,9,9,9,9,10,13,13,0,0,0,0,0,0,0,0,0,0,0
0,0,13,9,9,9,9,9,9,9,9,9,9,13,0,0,0,0,0,0,0,0,0,0
0,0,13,9,9,9,9,9,9,9,9,9,9,9,13,0,0,0,0,0,0,0,0,0
0,0,13,9,9,9,9,9,9,9,9,9,9,9,13,0,0,0,0,0,0,0,0,0
0,0,13,9,9,9,9,9,9,9,9,9,9,9,13,0,0,0,0,0,0,0,0,0
0,0,13,9,9,9,9,9,9,9,9,9,9,9,13,0,0,0,0,0,0,0,0,0
0,0,13,9,9,9,9,9,9,9,9,9,9,13,0,0,0,0,0,0,0,0,0,0
0,0,13,9,9,9,9,9,9,9,9,13,13,0,0,0,0,0,0,0,0,0,0,0
0,0,13,13,13,13,13,13,13,13,13,0,0,0,0,0,0,0,0,0,0,0,0,0
0,0,13,24,24,24,24,24,24,24,13,0,0,0,0,0,0,0,0,0,0,0,0,0
0,0,13,24,24,24,24,24,24,24,13,0,0,0,0,0,0,0,0,0,0,0,0,0
0,0,13,24,24,24,24,24,24,24,13,0,0,0,0,0,0,0,0,0,0,0,0,0
0,0,13,24,24,24,24,24,24,24,13,0,0,0,0,0,0,0,0,0,0,0,0,0
0,0,13,24,24,24,24,24,24,24,13,0,0,0,0,0,0,0,0,0,0,0,0,0
0,0,13,13,13,13,13,13,13,13,13,0,0,0,0,0,0,0,0,0,0,0,0,0
0,0,0,0,0,0,0,0,0,0,0,0,0,0,0,0,0,0,0,0,0,0,0,0
0,0,0,0,0,0,0,0,0,0,0,0,0,0,0,0,0,0,0,0,0,0,0,0
0,0,0,0,0,0,0,0,0,0,0,0,0,0,0,0,0,0,0,0,0,0,0,0
0,0,0,0,0,0,0,0,0,0,0,0,0,0,0,0,0,0,0,0,0,0,0,0
0,0,0,0,0,0,0,0,0,0,0,0,0,0,0,0,0,0,0,0,0,0,0,0
0,0,0,0,0,0,0,0,0,0,0,0,0,0,0,0,0,0,0,0,0,0,0,0
endlayer

layer
0,0,0,0,0,0,0,0,0,0,0,0,0,0,0,0,0,0,0,0,0,0,0,0
0,0,0,0,0,0,0,0,0,0,0,0,0,0,0,0,0,0,0,0,0,0,0,0
0,0,0,0,0,0,0,0,0,0,0,0,0,0,0,0,0,0,0,0,0,0,0,0
0,0,0,0,0,0,0,0,0,0,0,0,0,0,0,0,0,0,0,0,0,0,0,0
0,0,0,0,0,0,0,0,0,0,0,0,0,0,0,0,0,0,0,0,0,0,0,0
0,0,0,0,0,0,0,0,0,0,0,0,0,0,0,0,0,0,0,0,0,0,0,0
0,0,0,0,0,0,0,0,0,0,0,0,0,0,0,0,0,0,0,0,0,0,0,0
0,0,0,0,0,0,0,0,0,0,0,0,0,0,0,0,0,0,0,0,0,0,0,0
0,0,0,0,0,0,0,0,0,0,0,0,0,0,0,0,0,0,0,0,0,0,0,0
0,0,0,0,0,0,0,0,0,0,0,0,0,0,0,0,0,0,0,0,0,0,0,0
0,0,0,0,0,0,0,0,0,0,0,0,0,0,0,0,0,0,0,0,0,0,0,0
0,0,0,0,0,0,0,0,0,0,0,0,0,0,0,0,0,0,0,0,0,0,0,0
0,0,13,23,22,23,22,23,22,23,13,0,0,0,0,0,0,0,0,0,0,0,0,0
0,0,23,20,44,0,0,41,41,41,41,22,21,0,0,0,0,0,0,0,0,0,0,0
0,0,22,44,0,0,0,41,41,41,41,0,0,22,0,0,0,0,0,0,0,0,0,0
0,0,23,0,0,42,42,41,41,41,41,0,0,38,21,0,0,0,0,0,0,0,0,0
0,0,22,11,0,0,42,41,41,41,41,40,0,39,22,0,0,0,0,0,0,0,0,0
0,0,22,11,0,43,42,41,41,41,41,40,0,39,22,0,0,0,0,0,0,0,0,0
0,0,23,0,0,42,42,41,41,41,41,0,0,38,21,0,0,0,0,0,0,0,0,0
0,0,22,44,0,0,0,41,41,41,41,0,0,22,0,0,0,0,0,0,0,0,0,0
0,0,23,20,44,0,0,41,41,41,41,22,21,0,0,0,0,0,0,0,0,0,0,0
0,0,13,23,22,23,22,23,22,23,13,0,0,0,0,0,0,0,0,0,0,0,0,0
0,0,0,0,0,0,0,0,0,0,0,0,0,0,0,0,0,0,0,0,0,0,0,0
0,0,0,0,0,0,0,0,0,0,0,0,0,0,0,0,0,0,0,0,0,0,0,0
0,0,0,0,0,0,0,0,0,0,0,0,0,0,0,0,0,0,0,0,0,0,0,0
0,0,0,0,0,0,0,0,0,0,0,0,0,0,0,0,0,0,0,0,0,0,0,0
0,0,0,0,0,0,0,0,0,0,0,0,0,0,0,0,0,0,0,0,0,0,0,0
0,0,0,0,0,0,0,0,0,0,0,0,0,0,0,0,0,0,0,0,0,0,0,0
0,0,0,0,0,0,0,0,0,0,0,0,0,0,0,0,0,0,0,0,0,0,0,0
0,0,0,0,0,0,0,0,0,0,0,0,0,0,0,0,0,0,0,0,0,0,0,0
0,0,0,0,0,0,0,0,0,0,0,0,0,0,0,0,0,0,0,0,0,0,0,0
0,0,0,0,0,0,0,0,0,0,0,0,0,0,0,0,0,0,0,0,0,0,0,0
0,0,0,0,0,0,0,0,0,0,0,0,0,0,0,0,0,0,0,0,0,0,0,0
0,0,0,0,0,0,0,0,0,0,0,0,0,0,0,0,0,0,0,0,0,0,0,0
endlayer

layer
0,0,0,0,0,0,0,0,0,0,0,0,0,0,0,0,0,0,0,0,0,0,0,0
0,0,0,0,0,0,0,0,0,0,0,0,0,0,0,0,0,0,0,0,0,0,0,0
0,0,0,0,0,0,0,0,0,0,0,0,0,0,0,0,0,0,0,0,0,0,0,0
0,0,0,0,0,0,0,0,0,0,0,0,0,0,0,0,0,0,0,0,0,0,0,0
0,0,0,0,0,0,0,0,0,0,0,0,0,0,0,0,0,0,0,0,0,0,0,0
0,0,0,0,0,0,0,0,0,0,0,0,0,0,0,0,0,0,0,0,0,0,0,0
0,0,0,0,0,0,0,0,0,0,0,0,0,0,0,0,0,0,0,0,0,0,0,0
0,0,0,0,0,0,0,0,0,0,0,0,0,0,0,0,0,0,0,0,0,0,0,0
0,0,0,0,0,0,0,0,0,0,0,0,0,0,0,0,0,0,0,0,0,0,0,0
0,0,0,0,0,0,0,0,0,0,0,0,0,0,0,0,0,0,0,0,0,0,0,0
0,0,0,0,0,0,0,0,0,0,0,0,0,0,0,0,0,0,0,0,0,0,0,0
0,0,0,0,0,0,0,0,0,0,0,0,0,0,0,0,0,0,0,0,0,0,0,0
0,0,13,23,22,23,22,23,22,23,13,0,0,0,0,0,0,0,0,0,0,0,0,0
0,0,23,44,0,0,0,0,0,0,0,22,21,0,0,0,0,0,0,0,0,0,0,0
0,0,22,0,0,0,0,0,0,0,0,0,0,22,0,0,0,0,0,0,0,0,0,0
0,0,23,0,0,0,35,0,0,0,0,0,0,0,21,0,0,0,0,0,0,0,0,0
0,0,22,0,0,0,0,0,0,0,0,0,0,0,22,0,0,0,0,0,0,0,0,0
0,0,22,0,0,0,0,0,0,0,0,0,0,0,22,0,0,0,0,0,0,0,0,0
0,0,23,0,0,0,45,0,0,0,0,0,0,0,21,0,0,0,0,0,0,0,0,0
0,0,22,0,0,0,0,0,0,0,0,0,0,22,0,0,0,0,0,0,0,0,0,0
0,0,23,44,0,0,0,0,0,0,0,22,21,0,0,0,0,0,0,0,0,0,0,0
0,0,13,23,22,23,22,23,22,23,13,0,0,0,0,0,0,0,0,0,0,0,0,0
0,0,0,0,0,0,0,0,0,0,0,0,0,0,0,0,0,0,0,0,0,0,0,0
0,0,0,0,0,0,0,0,0,0,0,0,0,0,0,0,0,0,0,0,0,0,0,0
0,0,0,0,0,0,0,0,0,0,0,0,0,0,0,0,0,0,0,0,0,0,0,0
0,0,0,0,0,0,0,0,0,0,0,0,0,0,0,0,0,0,0,0,0,0,0,0
0,0,0,0,0,0,0,0,0,0,0,0,0,0,0,0,0,0,0,0,0,0,0,0
0,0,0,0,0,0,0,0,0,0,0,0,0,0,0,0,0,0,0,0,0,0,0,0
0,0,0,0,0,0,0,0,0,0,0,0,0,0,0,0,0,0,0,0,0,0,0,0
0,0,0,0,0,0,0,0,0,0,0,0,0,0,0,0,0,0,0,0,0,0,0,0
0,0,0,0,0,0,0,0,0,0,0,0,0,0,0,0,0,0,0,0,0,0,0,0
0,0,0,0,0,0,0,0,0,0,0,0,0,0,0,0,0,0,0,0,0,0,0,0
0,0,0,0,0,0,0,0,0,0,0,0,0,0,0,0,0,0,0,0,0,0,0,0
0,0,0,0,0,0,0,0,0,0,0,0,0,0,0,0,0,0,0,0,0,0,0,0
endlayer

layer
0,0,0,0,0,0,0,0,0,0,0,0,0,0,0,0,0,0,0,0,0,0,0,0
0,0,0,0,0,0,0,0,0,0,0,0,0,0,0,0,0,0,0,0,0,0,0,0
0,0,0,0,0,0,0,0,0,0,0,0,0,0,0,0,0,0,0,0,0,0,0,0
0,0,0,0,0,0,0,0,0,0,0,0,0,0,0,0,0,0,0,0,0,0,0,0
0,0,0,0,0,0,0,0,0,0,0,0,0,0,0,0,0,0,0,0,0,0,0,0
0,0,0,0,0,0,0,0,0,0,0,0,0,0,0,0,0,0,0,0,0,0,0,0
0,0,0,0,0,0,0,0,0,0,0,0,0,0,0,0,0,0,0,0,0,0,0,0
0,0,0,0,0,0,0,0,0,0,0,0,0,0,0,0,0,0,0,0,0,0,0,0
0,0,0,0,0,0,0,0,0,0,0,0,0,0,0,0,0,0,0,0,0,0,0,0
0,0,0,0,0,0,0,0,0,0,0,0,0,0,0,0,0,0,0,0,0,0,0,0
0,0,0,0,0,0,0,0,0,0,0,0,0,0,0,0,0,0,0,0,0,0,0,0
0,0,0,0,0,0,0,0,0,0,0,0,0,0,0,0,0,0,0,0,0,0,0,0
0,0,13,23,22,23,22,23,22,23,13,0,0,0,0,0,0,0,0,0,0,0,0,0
0,0,23,0,0,46,0,0,0,0,0,22,21,0,0,0,0,0,0,0,0,0,0,0
0,0,22,0,0,0,0,0,0,0,0,0,0,22,0,0,0,0,0,0,0,0,0,0
0,0,23,47,0,0,0,0,0,0,0,0,0,0,21,0,0,0,0,0,0,0,0,0
0,0,22,0,0,0,0,0,0,0,0,0,0,0,22,0,0,0,0,0,0,0,0,0
0,0,22,0,0,0,0,0,0,0,0,0,0,0,22,0,0,0,0,0,0,0,0,0
0,0,23,47,0,0,0,0,0,0,0,0,0,0,21,0,0,0,0,0,0,0,0,0
0,0,22,0,0,0,0,0,0,0,0,0,0,22,0,0,0,0,0,0,0,0,0,0
0,0,23,0,0,46,0,0,0,0,0,22,21,0,0,0,0,0,0,0,0,0,0,0
0,0,13,23,22,23,22,23,22,23,13,0,0,0,0,0,0,0,0,0,0,0,0,0
0,0,0,0,0,0,0,0,0,0,0,0,0,0,0,0,0,0,0,0,0,0,0,0
0,0,0,0,0,0,0,0,0,0,0,0,0,0,0,0,0,0,0,0,0,0,0,0
0,0,0,0,0,0,0,0,0,0,0,0,0,0,0,0,0,0,0,0,0,0,0,0
0,0,0,0,0,0,0,0,0,0,0,0,0,0,0,0,0,0,0,0,0,0,0,0
0,0,0,0,0,0,0,0,0,0,0,0,0,0,0,0,0,0,0,0,0,0,0,0
0,0,0,0,0,0,0,0,0,0,0,0,0,0,0,0,0,0,0,0,0,0,0,0
0,0,0,0,0,0,0,0,0,0,0,0,0,0,0,0,0,0,0,0,0,0,0,0
0,0,0,0,0,0,0,0,0,0,0,0,0,0,0,0,0,0,0,0,0,0,0,0
0,0,0,0,0,0,0,0,0,0,0,0,0,0,0,0,0,0,0,0,0,0,0,0
0,0,0,0,0,0,0,0,0,0,0,0,0,0,0,0,0,0,0,0,0,0,0,0
0,0,0,0,0,0,0,0,0,0,0,0,0,0,0,0,0,0,0,0,0,0,0,0
0,0,0,0,0,0,0,0,0,0,0,0,0,0,0,0,0,0,0,0,0,0,0,0
endlayer

layer
0,0,0,0,0,0,0,0,0,0,0,0,0,0,0,0,0,0,0,0,0,0,0,0
0,0,0,0,0,0,0,0,0,0,0,0,0,0,0,0,0,0,0,0,0,0,0,0
0,0,0,0,0,0,0,0,0,0,0,0,0,0,0,0,0,0,0,0,0,0,0,0
0,0,0,0,0,0,0,0,0,0,0,0,0,0,0,0,0,0,0,0,0,0,0,0
0,0,0,0,0,0,0,0,0,0,0,0,0,0,0,0,0,0,0,0,0,0,0,0
0,0,0,0,0,0,0,0,0,0,0,0,0,0,0,0,0,0,0,0,0,0,0,0
0,0,0,0,0,0,0,0,0,0,0,0,0,0,0,0,0,0,0,0,0,0,0,0
0,0,0,0,0,0,0,0,0,0,0,0,0,0,0,0,0,0,0,0,0,0,0,0
0,0,0,0,0,0,0,0,0,0,0,0,0,0,0,0,0,0,0,0,0,0,0,0
0,0,0,0,0,0,0,0,0,0,0,0,0,0,0,0,0,0,0,0,0,0,0,0
0,0,0,0,0,0,0,0,0,0,0,0,0,0,0,0,0,0,0,0,0,0,0,0
0,0,0,0,0,0,0,0,0,0,0,0,0,0,0,0,0,0,0,0,0,0,0,0
0,0,13,23,22,23,22,23,22,23,13,0,0,0,0,0,0,0,0,0,0,0,0,0
0,0,23,0,0,0,0,0,0,0,0,22,21,0,0,0,0,0,0,0,0,0,0,0
0,0,22,0,0,0,0,0,0,0,0,0,0,22,0,0,0,0,0,0,0,0,0,0
0,0,23,0,0,0,0,0,0,0,0,0,0,0,21,0,0,0,0,0,0,0,0,0
0,0,22,0,0,0,0,0,0,0,0,0,0,0,22,0,0,0,0,0,0,0,0,0
0,0,22,0,0,0,0,0,0,0,0,0,0,0,22,0,0,0,0,0,0,0,0,0
0,0,23,0,0,0,0,0,0,0,0,0,0,0,21,0,0,0,0,0,0,0,0,0
0,0,22,0,0,0,0,0,0,0,0,0,0,22,0,0,0,0,0,0,0,0,0,0
0,0,23,0,0,0,0,0,0,0,0,22,21,0,0,0,0,0,0,0,0,0,0,0
0,0,13,23,22,23,22,23,22,23,13,0,0,0,0,0,0,0,0,0,0,0,0,0
0,0,0,0,0,0,0,0,0,0,0,0,0,0,0,0,0,0,0,0,0,0,0,0
0,0,0,0,0,0,0,0,0,0,0,0,0,0,0,0,0,0,0,0,0,0,0,0
0,0,0,0,0,0,0,0,0,0,0,0,0,0,0,0,0,0,0,0,0,0,0,0
0,0,0,0,0,0,0,0,0,0,0,0,0,0,0,0,0,0,0,0,0,0,0,0
0,0,0,0,0,0,0,0,0,0,0,0,0,0,0,0,0,0,0,0,0,0,0,0
0,0,0,0,0,0,0,0,0,0,0,0,0,0,0,0,0,0,0,0,0,0,0,0
0,0,0,0,0,0,0,0,0,0,0,0,0,0,0,0,0,0,0,0,0,0,0,0
0,0,0,0,0,0,0,0,0,0,0,0,0,0,0,0,0,0,0,0,0,0,0,0
0,0,0,0,0,0,0,0,0,0,0,0,0,0,0,0,0,0,0,0,0,0,0,0
0,0,0,0,0,0,0,0,0,0,0,0,0,0,0,0,0,0,0,0,0,0,0,0
0,0,0,0,0,0,0,0,0,0,0,0,0,0,0,0,0,0,0,0,0,0,0,0
0,0,0,0,0,0,0,0,0,0,0,0,0,0,0,0,0,0,0,0,0,0,0,0
endlayer

layer
0,0,0,0,0,0,0,0,0,0,0,0,0,0,0,0,0,0,0,0,0,0,0,0
0,0,0,0,0,0,0,0,0,0,0,0,0,0,0,0,0,0,0,0,0,0,0,0
0,0,0,0,0,0,0,0,0,0,0,0,0,0,0,0,0,0,0,0,0,0,0,0
0,0,0,0,0,0,0,0,0,0,0,0,0,0,0,0,0,0,0,0,0,0,0,0
0,0,0,0,0,0,0,0,0,0,0,0,0,0,0,0,0,0,0,0,0,0,0,0
0,0,0,0,0,0,0,0,0,0,0,0,0,0,0,0,0,0,0,0,0,0,0,0
0,0,0,0,0,0,0,0,0,0,0,0,0,0,0,0,0,0,0,0,0,0,0,0
0,0,0,0,0,0,0,0,0,0,0,0,0,0,0,0,0,0,0,0,0,0,0,0
0,0,0,0,0,0,0,0,0,0,0,0,0,0,0,0,0,0,0,0,0,0,0,0
0,0,0,0,0,0,0,0,0,0,0,0,0,0,0,0,0,0,0,0,0,0,0,0
0,0,0,0,0,0,0,0,0,0,0,0,0,0,0,0,0,0,0,0,0,0,0,0
0,0,0,0,0,0,0,0,0,0,0,0,0,0,0,0,0,0,0,0,0,0,0,0
0,0,13,23,22,23,22,23,22,23,13,0,0,0,0,0,0,0,0,0,0,0,0,0
0,0,23,0,0,0,0,0,0,0,0,22,21,0,0,0,0,0,0,0,0,0,0,0
0,0,22,0,0,0,0,0,0,0,0,0,0,22,0,0,0,0,0,0,0,0,0,0
0,0,23,0,0,0,0,0,0,0,0,0,0,0,21,0,0,0,0,0,0,0,0,0
0,0,22,0,0,0,0,0,0,0,0,0,0,0,22,0,0,0,0,0,0,0,0,0
0,0,22,0,0,0,0,0,0,0,0,0,0,0,22,0,0,0,0,0,0,0,0,0
0,0,23,0,0,0,0,0,0,0,0,0,0,0,21,0,0,0,0,0,0,0,0,0
0,0,22,0,0,0,0,0,0,0,0,0,0,22,0,0,0,0,0,0,0,0,0,0
0,0,23,0,0,0,0,0,0,0,0,22,21,0,0,0,0,0,0,0,0,0,0,0
0,0,13,23,22,23,22,23,22,23,13,0,0,0,0,0,0,0,0,0,0,0,0,0
0,0,0,0,0,0,0,0,0,0,0,0,0,0,0,0,0,0,0,0,0,0,0,0
0,0,0,0,0,0,0,0,0,0,0,0,0,0,0,0,0,0,0,0,0,0,0,0
0,0,0,0,0,0,0,0,0,0,0,0,0,0,0,0,0,0,0,0,0,0,0,0
0,0,0,0,0,0,0,0,0,0,0,0,0,0,0,0,0,0,0,0,0,0,0,0
0,0,0,0,0,0,0,0,0,0,0,0,0,0,0,0,0,0,0,0,0,0,0,0
0,0,0,0,0,0,0,0,0,0,0,0,0,0,0,0,0,0,0,0,0,0,0,0
0,0,0,0,0,0,0,0,0,0,0,0,0,0,0,0,0,0,0,0,0,0,0,0
0,0,0,0,0,0,0,0,0,0,0,0,0,0,0,0,0,0,0,0,0,0,0,0
0,0,0,0,0,0,0,0,0,0,0,0,0,0,0,0,0,0,0,0,0,0,0,0
0,0,0,0,0,0,0,0,0,0,0,0,0,0,0,0,0,0,0,0,0,0,0,0
0,0,0,0,0,0,0,0,0,0,0,0,0,0,0,0,0,0,0,0,0,0,0,0
0,0,0,0,0,0,0,0,0,0,0,0,0,0,0,0,0,0,0,0,0,0,0,0
endlayer

layer
0,0,0,0,0,0,0,0,0,0,0,0,0,0,0,0,0,0,0,0,0,0,0,0
0,0,0,0,0,0,0,0,0,0,0,0,0,0,0,0,0,0,0,0,0,0,0,0
0,0,0,0,0,0,0,0,0,0,0,0,0,0,0,0,0,0,0,0,0,0,0,0
0,0,0,0,0,0,0,0,0,0,0,0,0,0,0,0,0,0,0,0,0,0,0,0
0,0,0,0,0,0,0,0,0,0,0,0,0,0,0,0,0,0,0,0,0,0,0,0
0,0,0,0,0,0,0,0,0,0,0,0,0,0,0,0,0,0,0,0,0,0,0,0
0,0,0,0,0,0,0,0,0,0,0,0,0,0,0,0,0,0,0,0,0,0,0,0
0,0,0,0,0,0,0,0,0,0,0,0,0,0,0,0,0,0,0,0,0,0,0,0
0,0,0,0,0,0,0,0,0,0,0,0,0,0,0,0,0,0,0,0,0,0,0,0
0,0,0,0,0,0,0,0,0,0,0,0,0,0,0,0,0,0,0,0,0,0,0,0
0,0,0,0,0,0,0,0,0,0,0,0,0,0,0,0,0,0,0,0,0,0,0,0
0,0,0,0,0,0,0,0,0,0,0,0,0,0,0,0,0,0,0,0,0,0,0,0
0,0,13,13,13,13,13,13,13,13,13,0,0,0,0,0,0,0,0,0,0,0,0,0
0,0,13,24,24,24,24,24,24,24,24,13,13,0,0,0,0,0,0,0,0,0,0,0
0,0,13,24,24,24,24,24,24,24,24,24,24,13,0,0,0,0,0,0,0,0,0,0
0,0,13,24,24,48,48,48,48,48,24,24,24,24,13,0,0,0,0,0,0,0,0,0
0,0,13,24,24,48,48,48,48,48,48,48,24,24,13,0,0,0,0,0,0,0,0,0
0,0,13,24,24,48,48,48,48,48,48,48,24,24,13,0,0,0,0,0,0,0,0,0
0,0,13,24,24,48,48,48,48,48,24,24,24,24,13,0,0,0,0,0,0,0,0,0
0,0,13,24,24,24,24,24,24,24,24,24,24,13,0,0,0,0,0,0,0,0,0,0
0,0,13,24,24,24,24,24,24,24,24,13,13,0,0,0,0,0,0,0,0,0,0,0
0,0,13,13,13,13,13,13,13,13,13,0,0,0,0,0,0,0,0,0,0,0,0,0
0,0,0,0,0,0,0,0,0,0,0,0,0,0,0,0,0,0,0,0,0,0,0,0
0,0,0,0,0,0,0,0,0,0,0,0,0,0,0,0,0,0,0,0,0,0,0,0
0,0,0,0,0,0,0,0,0,0,0,0,0,0,0,0,0,0,0,0,0,0,0,0
0,0,0,0,0,0,0,0,0,0,0,0,0,0,0,0,0,0,0,0,0,0,0,0
0,0,0,0,0,0,0,0,0,0,0,0,0,0,0,0,0,0,0,0,0,0,0,0
0,0,0,0,0,0,0,0,0,0,0,0,0,0,0,0,0,0,0,0,0,0,0,0
0,0,0,0,0,0,0,0,0,0,0,0,0,0,0,0,0,0,0,0,0,0,0,0
0,0,0,0,0,0,0,0,0,0,0,0,0,0,0,0,0,0,0,0,0,0,0,0
0,0,0,0,0,0,0,0,0,0,0,0,0,0,0,0,0,0,0,0,0,0,0,0
0,0,0,0,0,0,0,0,0,0,0,0,0,0,0,0,0,0,0,0,0,0,0,0
0,0,0,0,0,0,0,0,0,0,0,0,0,0,0,0,0,0,0,0,0,0,0,0
0,0,0,0,0,0,0,0,0,0,0,0,0,0,0,0,0,0,0,0,0,0,0,0
endlayer

