weight=7
embed_into_distance=5
acceptable_target_blocks=1,2,3,12,13,250
dimensions=49,15,29
allowable_overhang=0
max_cut_in=2
cut_in_buffer=1
max_leveling=2
leveling_buffer=1
preserve_water=0
preserve_lava=0
preserve_plants=0


rule1=0,100,3134-10
rule2=0,100,300
rule3=0,100,2843-14,2843-14,2843-14,2843-14,2843
rule4=0,100,622,2838-4,2838-4,2838-4,2838-4,2838-4,2838-4,2838-4,2838-4,2838-4
rule5=0,100,2843-4
rule6=0,75,2245-1,2245-1,2245-1,2245-1,2245-1,2245-1,2245-1,311
rule7=0,100,2013
rule8=0,65,308,308,308,308,308,308,313,313,314,327
rule9=0,100,2013-14
rule10=0,66,2291-1
rule11=0,25,3225-3
rule12=0,95,2835-2,2835-2,2835-2,2835-2,2835-2,2835-2,2835-2,2835-1,2835-1,2835-0
rule13=0,25,140-10
rule14=0,66,623
rule15=0,95,300
rule16=0,100,3134,3134,3134,3134-8,3134-2



layer
1,1,1,1,1,1,1,1,1,1,1,1,1,1,1,1,1,1,1,1,1,1,1,1,1,1,1,1,1
1,1,1,1,1,1,1,1,1,1,1,1,1,1,1,1,1,1,1,1,1,1,1,1,1,1,1,1,1
1,1,2,2,2,3,3,3,3,3,2,2,2,2,1,2,2,2,2,3,3,3,3,3,2,2,2,1,1
1,1,2,2,3,4,4,4,4,4,2,2,2,2,1,2,2,2,2,4,4,4,4,4,3,2,2,1,1
1,1,2,3,4,4,4,4,4,4,4,2,2,2,1,2,2,2,4,4,4,4,4,4,4,3,2,1,1
1,1,3,4,4,4,4,4,4,4,4,4,2,2,1,2,2,4,4,4,4,4,4,4,4,4,3,1,1
1,1,3,4,4,4,4,4,4,4,4,4,4,2,4,2,4,4,4,4,4,4,4,4,4,4,3,1,1
1,1,3,4,4,4,4,4,4,4,4,4,4,4,5,4,4,4,4,4,4,4,4,4,4,4,3,1,1
1,1,3,4,4,4,4,4,4,4,4,4,4,2,2,2,4,4,4,4,4,4,4,4,4,4,3,1,1
1,1,3,4,4,4,4,4,4,4,4,4,2,2,2,2,2,4,4,4,4,4,4,4,4,4,3,1,1
1,1,2,3,4,4,4,4,4,4,4,2,2,2,2,2,2,2,4,4,4,4,4,4,4,3,2,1,1
1,1,2,2,3,4,4,4,4,4,2,2,2,2,2,2,2,2,2,4,4,4,4,4,3,2,2,1,1
1,1,2,2,2,3,3,3,3,3,2,2,2,2,2,2,2,2,2,3,3,3,3,3,2,2,2,1,1
1,1,1,1,1,1,1,1,1,1,1,1,1,1,1,1,1,1,1,1,1,1,1,1,1,1,1,1,1
1,1,1,1,1,1,1,1,1,1,1,1,1,1,1,1,1,1,1,1,1,1,1,1,1,1,1,1,1
endlayer

layer
2,2,2,2,2,2,2,2,2,2,2,2,2,2,2,2,2,2,2,2,2,2,2,2,2,2,2,2,2
2,2,2,2,2,2,2,2,2,2,2,2,2,2,2,2,2,2,2,2,2,2,2,2,2,2,2,2,2
2,2,2,2,2,3,3,3,3,3,2,2,2,2,2,2,2,2,2,3,3,3,3,3,2,2,2,2,2
2,2,2,2,3,0,10,6,6,10,3,2,2,2,2,2,2,2,3,10,6,6,10,0,3,2,2,2,2
2,2,2,3,8,0,10,6,6,10,0,3,2,2,2,2,2,3,0,10,6,6,10,0,8,3,2,2,2
2,2,3,0,0,0,0,0,0,0,0,0,3,2,2,2,3,0,0,0,0,0,0,0,0,0,3,2,2
2,2,3,6,0,0,0,0,0,0,0,0,0,3,0,3,0,0,0,0,0,0,0,0,0,6,3,2,2
2,2,3,7,9,9,0,0,0,0,0,0,0,2,2,2,0,0,0,0,0,0,0,9,9,7,3,2,2
2,2,3,7,9,9,0,0,0,0,0,0,0,3,3,3,0,0,0,0,0,0,0,9,9,7,3,2,2
2,2,3,6,0,0,0,0,0,0,0,0,3,2,2,2,3,0,0,0,0,0,0,0,0,6,3,2,2
2,2,2,3,8,0,0,0,0,0,0,3,2,2,2,2,2,3,0,0,0,0,0,0,8,3,2,2,2
2,2,2,2,3,0,0,0,0,0,3,2,2,2,2,2,2,2,3,0,0,0,0,0,3,2,2,2,2
2,2,2,2,2,3,3,3,3,3,2,2,2,2,2,2,2,2,2,3,3,3,3,3,2,2,2,2,2
2,2,2,2,2,2,2,2,2,2,2,2,2,2,2,2,2,2,2,2,2,2,2,2,2,2,2,2,2
2,2,2,2,2,2,2,2,2,2,2,2,2,2,2,2,2,2,2,2,2,2,2,2,2,2,2,2,2
endlayer

layer
2,2,2,2,2,2,2,2,2,2,2,2,2,2,2,2,2,2,2,2,2,2,2,2,2,2,2,2,2
2,2,2,2,2,2,2,2,2,2,2,2,2,2,2,2,2,2,2,2,2,2,2,2,2,2,2,2,2
2,2,2,2,2,11,12,11,12,11,2,2,2,2,2,2,2,2,2,11,12,11,12,11,2,2,2,2,2
2,2,2,2,3,0,0,0,0,0,3,2,2,2,2,2,2,2,3,0,0,0,0,0,3,2,2,2,2
2,2,2,3,0,0,0,0,0,0,0,3,2,2,2,2,2,3,0,0,0,0,0,0,0,3,2,2,2
2,2,11,0,0,0,0,0,0,0,0,0,11,2,2,2,11,0,0,0,0,0,0,0,0,0,11,2,2
2,2,12,13,0,0,0,0,0,0,0,0,0,12,0,12,0,0,0,0,0,0,0,0,0,13,12,2,2
2,2,11,0,0,0,0,0,0,0,0,0,0,0,14,0,0,0,0,0,0,0,0,0,0,0,11,2,2
2,2,12,0,0,0,0,0,0,0,0,0,0,12,11,12,0,0,0,0,0,0,0,0,0,0,12,2,2
2,2,11,0,0,0,0,0,0,0,0,0,11,2,2,2,11,0,0,0,0,0,0,0,0,0,11,2,2
2,2,2,3,0,0,0,0,0,0,0,3,2,2,2,2,2,3,0,0,0,0,0,0,0,3,2,2,2
2,2,2,2,3,0,0,0,0,0,3,2,2,2,2,2,2,2,3,0,0,0,0,0,3,2,2,2,2
2,2,2,2,2,11,12,11,12,11,2,2,2,2,2,2,2,2,2,11,12,11,12,11,2,2,2,2,2
2,2,2,2,2,2,2,2,2,2,2,2,2,2,2,2,2,2,2,2,2,2,2,2,2,2,2,2,2
2,2,2,2,2,2,2,2,2,2,2,2,2,2,2,2,2,2,2,2,2,2,2,2,2,2,2,2,2
endlayer

layer
2,2,2,2,2,2,2,2,2,2,2,2,2,2,2,2,2,2,2,2,2,2,2,2,2,2,2,2,2
2,2,2,2,2,2,2,2,2,2,2,2,2,2,2,2,2,2,2,2,2,2,2,2,2,2,2,2,2
2,2,2,2,2,11,12,11,12,11,2,2,2,2,2,2,2,2,2,11,12,11,12,11,2,2,2,2,2
2,2,2,2,3,0,0,0,0,0,3,2,2,2,2,2,2,2,3,0,0,0,0,0,3,2,2,2,2
2,2,2,3,0,0,0,0,0,0,0,3,2,2,2,2,2,3,0,0,0,0,0,0,0,3,2,2,2
2,2,11,0,0,0,0,0,0,0,0,0,11,2,2,2,11,0,0,0,0,0,0,0,0,0,11,2,2
2,2,12,0,0,0,0,0,0,0,0,0,0,12,12,12,0,0,0,0,0,0,0,0,0,0,12,2,2
2,2,11,0,0,0,0,0,0,0,0,0,0,11,14,11,0,0,0,0,0,0,0,0,0,0,11,2,2
2,2,12,0,0,0,0,0,0,0,0,0,0,12,11,12,0,0,0,0,0,0,0,0,0,0,12,2,2
2,2,11,0,0,0,0,0,0,0,0,0,11,2,2,2,11,0,0,0,0,0,0,0,0,0,11,2,2
2,2,2,3,0,0,0,0,0,0,0,3,2,2,2,2,2,3,0,0,0,0,0,0,0,3,2,2,2
2,2,2,2,3,0,0,0,0,0,3,2,2,2,2,2,2,2,3,0,0,0,0,0,3,2,2,2,2
2,2,2,2,2,11,12,11,12,11,2,2,2,2,2,2,2,2,2,11,12,11,12,11,2,2,2,2,2
2,2,2,2,2,2,2,2,2,2,2,2,2,2,2,2,2,2,2,2,2,2,2,2,2,2,2,2,2
2,2,2,2,2,2,2,2,2,2,2,2,2,2,2,2,2,2,2,2,2,2,2,2,2,2,2,2,2
endlayer

layer
15,15,15,15,15,15,15,15,15,15,15,15,15,15,15,15,15,15,15,15,15,15,15,15,15,15,15,15,15
15,15,15,15,15,15,15,15,15,15,15,15,15,15,15,15,15,15,15,15,15,15,15,15,15,15,15,15,15
15,15,15,15,15,11,12,11,12,11,15,15,15,15,15,15,15,15,15,11,12,11,12,11,15,15,15,15,15
15,15,15,15,3,0,0,0,0,0,3,15,15,15,15,15,15,15,3,0,0,0,0,0,3,15,15,15,15
15,15,15,3,0,0,0,0,0,0,0,3,15,15,15,15,15,3,0,0,0,0,0,0,0,3,15,15,15
15,15,11,0,0,0,0,0,0,0,0,0,11,15,15,15,11,0,0,0,0,0,0,0,0,0,11,15,15
15,15,12,0,0,0,0,0,0,0,0,0,0,12,11,12,0,0,0,0,0,0,0,0,0,0,12,15,15
15,15,11,0,0,0,0,0,0,0,0,0,0,11,14,11,0,0,0,0,0,0,0,0,0,0,11,15,15
15,15,12,0,0,0,0,0,0,0,0,0,0,12,11,12,0,0,0,0,0,0,0,0,0,0,12,15,15
15,15,11,0,0,0,0,0,0,0,0,0,11,15,15,15,11,0,0,0,0,0,0,0,0,0,11,15,15
15,15,15,3,0,0,0,0,0,0,0,3,15,15,15,15,15,3,0,0,0,0,0,0,0,3,15,15,15
15,15,15,15,3,0,0,0,0,0,3,15,15,15,15,15,15,15,3,0,0,0,0,0,3,15,15,15,15
15,15,15,15,15,11,12,11,12,11,15,15,15,15,15,15,15,15,15,11,12,11,12,11,15,15,15,15,15
15,15,15,15,15,15,15,15,15,15,15,15,15,15,15,15,15,15,15,15,15,15,15,15,15,15,15,15,15
15,15,15,15,15,15,15,15,15,15,15,15,15,15,15,15,15,15,15,15,15,15,15,15,15,15,15,15,15
endlayer

layer
0,0,0,0,0,0,0,0,0,0,0,0,0,0,0,0,0,0,0,0,0,0,0,0,0,0,0,0,0
0,0,0,0,0,0,0,0,0,0,0,0,0,0,0,0,0,0,0,0,0,0,0,0,0,0,0,0,0
0,0,0,0,0,11,12,11,12,11,0,0,0,0,0,0,0,0,0,11,12,11,12,11,0,0,0,0,0
0,0,0,0,3,0,0,0,0,0,3,0,0,0,0,0,0,0,3,0,0,0,0,0,3,0,0,0,0
0,0,0,3,0,0,0,0,0,0,0,3,0,0,0,0,0,3,0,0,0,0,0,0,0,3,0,0,0
0,0,11,0,0,0,0,0,0,0,0,0,11,0,0,0,11,0,0,0,0,0,0,0,0,0,11,0,0
0,0,12,0,0,0,0,0,0,0,0,0,0,12,11,12,0,0,0,0,0,0,0,0,0,0,12,0,0
0,0,11,0,0,0,0,0,0,0,0,0,0,11,14,11,0,0,0,0,0,0,0,0,0,0,11,0,0
0,0,12,0,0,0,0,0,0,0,0,0,0,12,11,12,0,0,0,0,0,0,0,0,0,0,12,0,0
0,0,11,0,0,0,0,0,0,0,0,0,11,0,0,0,11,0,0,0,0,0,0,0,0,0,11,0,0
0,0,0,3,0,0,0,0,0,0,0,3,0,0,0,0,0,3,0,0,0,0,0,0,0,3,0,0,0
0,0,0,0,3,0,0,0,0,0,3,0,0,0,0,0,0,0,3,0,0,0,0,0,3,0,0,0,0
0,0,0,0,0,11,12,11,12,11,0,0,0,0,0,0,0,0,0,11,12,11,12,11,0,0,0,0,0
0,0,0,0,0,0,0,0,0,0,0,0,0,0,0,0,0,0,0,0,0,0,0,0,0,0,0,0,0
0,0,0,0,0,0,0,0,0,0,0,0,0,0,0,0,0,0,0,0,0,0,0,0,0,0,0,0,0
endlayer

layer
0,0,0,0,0,0,0,0,0,0,0,0,0,0,0,0,0,0,0,0,0,0,0,0,0,0,0,0,0
0,0,0,0,0,0,0,0,0,0,0,0,0,0,0,0,0,0,0,0,0,0,0,0,0,0,0,0,0
0,0,0,0,0,11,12,11,12,11,0,0,0,0,0,0,0,0,0,11,12,11,12,11,0,0,0,0,0
0,0,0,0,3,0,0,0,0,0,3,0,0,0,0,0,0,0,3,0,0,0,0,0,3,0,0,0,0
0,0,0,3,0,0,0,0,0,0,0,3,0,0,0,0,0,3,0,0,0,0,0,0,0,3,0,0,0
0,0,11,0,0,0,0,0,0,0,0,0,11,0,0,0,11,0,0,0,0,0,0,0,0,0,11,0,0
0,0,12,0,0,0,0,0,0,0,0,0,0,12,11,12,0,0,0,0,0,0,0,0,0,0,12,0,0
0,0,11,0,0,0,0,0,0,0,0,0,0,11,14,11,0,0,0,0,0,0,0,0,0,0,11,0,0
0,0,12,0,0,0,0,0,0,0,0,0,0,12,11,12,0,0,0,0,0,0,0,0,0,0,12,0,0
0,0,11,0,0,0,0,0,0,0,0,0,11,0,0,0,11,0,0,0,0,0,0,0,0,0,11,0,0
0,0,0,3,0,0,0,0,0,0,0,3,0,0,0,0,0,3,0,0,0,0,0,0,0,3,0,0,0
0,0,0,0,3,0,0,0,0,0,3,0,0,0,0,0,0,0,3,0,0,0,0,0,3,0,0,0,0
0,0,0,0,0,11,12,11,12,11,0,0,0,0,0,0,0,0,0,11,12,11,12,11,0,0,0,0,0
0,0,0,0,0,0,0,0,0,0,0,0,0,0,0,0,0,0,0,0,0,0,0,0,0,0,0,0,0
0,0,0,0,0,0,0,0,0,0,0,0,0,0,0,0,0,0,0,0,0,0,0,0,0,0,0,0,0
endlayer

layer
0,0,0,0,0,0,0,0,0,0,0,0,0,0,0,0,0,0,0,0,0,0,0,0,0,0,0,0,0
0,0,0,0,0,0,0,0,0,0,0,0,0,0,0,0,0,0,0,0,0,0,0,0,0,0,0,0,0
0,0,0,0,0,3,3,3,3,3,0,0,0,0,0,0,0,0,0,3,3,3,3,3,0,0,0,0,0
0,0,0,0,3,4,4,4,4,4,3,0,0,0,0,0,0,0,3,4,4,4,4,4,3,0,0,0,0
0,0,0,3,4,4,4,4,4,4,4,3,0,0,0,0,0,3,4,4,4,4,4,4,4,3,0,0,0
0,0,3,4,4,4,4,4,4,4,4,4,3,0,0,0,3,4,4,4,4,4,4,4,4,4,3,0,0
0,0,3,4,4,4,4,4,4,4,4,4,4,3,3,3,4,4,4,4,4,4,4,4,4,4,3,0,0
0,0,3,4,4,4,4,4,4,4,4,4,4,4,14,4,4,4,4,4,4,4,4,4,4,4,3,0,0
0,0,3,4,4,4,4,4,4,4,4,4,4,3,3,3,4,4,4,4,4,4,4,4,4,4,3,0,0
0,0,3,4,4,4,4,4,4,4,4,4,3,0,0,0,3,4,4,4,4,4,4,4,4,4,3,0,0
0,0,0,3,4,4,4,4,4,4,4,3,0,0,0,0,0,3,4,4,4,4,4,4,4,3,0,0,0
0,0,0,0,3,4,4,4,4,4,3,0,0,0,0,0,0,0,3,4,4,4,4,4,3,0,0,0,0
0,0,0,0,0,3,3,3,3,3,0,0,0,0,0,0,0,0,0,3,3,3,3,3,0,0,0,0,0
0,0,0,0,0,0,0,0,0,0,0,0,0,0,0,0,0,0,0,0,0,0,0,0,0,0,0,0,0
0,0,0,0,0,0,0,0,0,0,0,0,0,0,0,0,0,0,0,0,0,0,0,0,0,0,0,0,0
endlayer

layer
0,0,0,0,0,0,0,0,0,0,0,0,0,0,0,0,0,0,0,0,0,0,0,0,0,0,0,0,0
0,0,0,0,0,0,0,0,0,0,0,0,0,0,0,0,0,0,0,0,0,0,0,0,0,0,0,0,0
0,0,0,0,0,11,12,11,12,11,0,0,0,0,0,0,0,0,0,11,12,11,12,11,0,0,0,0,0
0,0,0,0,3,0,10,6,6,10,3,0,0,0,0,0,0,0,3,10,6,6,10,0,3,0,0,0,0
0,0,0,3,8,0,10,6,6,10,0,3,0,0,0,0,0,3,0,10,6,6,10,0,8,3,0,0,0
0,0,11,0,0,0,0,0,0,0,0,0,11,0,0,0,11,0,0,0,0,0,0,0,0,0,11,0,0
0,0,12,6,0,0,0,0,0,0,0,0,0,12,11,12,0,0,0,0,0,0,0,0,0,6,12,0,0
0,0,11,7,9,9,0,0,0,0,0,0,0,0,14,0,0,0,0,0,0,0,0,9,9,7,11,0,0
0,0,12,7,9,9,0,0,0,0,0,0,0,12,11,12,0,0,0,0,0,0,0,9,9,7,12,0,0
0,0,11,6,0,0,0,0,0,0,0,0,11,0,0,0,11,0,0,0,0,0,0,0,0,6,11,0,0
0,0,0,3,8,0,0,0,0,0,0,3,0,0,0,0,0,3,0,0,0,0,0,0,8,3,0,0,0
0,0,0,0,3,0,0,0,0,0,3,0,0,0,0,0,0,0,3,0,0,0,0,0,3,0,0,0,0
0,0,0,0,0,11,12,11,12,11,0,0,0,0,0,0,0,0,0,11,12,11,12,11,0,0,0,0,0
0,0,0,0,0,0,0,0,0,0,0,0,0,0,0,0,0,0,0,0,0,0,0,0,0,0,0,0,0
0,0,0,0,0,0,0,0,0,0,0,0,0,0,0,0,0,0,0,0,0,0,0,0,0,0,0,0,0
endlayer

layer
0,0,0,0,0,0,0,0,0,0,0,0,0,0,0,0,0,0,0,0,0,0,0,0,0,0,0,0,0
0,0,0,0,0,0,0,0,0,0,0,0,0,0,0,0,0,0,0,0,0,0,0,0,0,0,0,0,0
0,0,0,0,0,11,12,11,12,11,0,0,0,0,0,0,0,0,0,11,12,11,12,11,0,0,0,0,0
0,0,0,0,3,0,0,0,0,0,3,0,0,0,0,0,0,0,3,0,0,0,0,0,3,0,0,0,0
0,0,0,3,0,0,0,0,0,0,0,3,0,0,0,0,0,3,0,0,0,0,0,0,0,3,0,0,0
0,0,11,0,0,0,0,0,0,0,0,0,11,0,0,0,11,0,0,0,0,0,0,0,0,0,11,0,0
0,0,12,13,0,0,0,0,0,0,0,0,0,12,11,12,0,0,0,0,0,0,0,0,0,13,12,0,0
0,0,11,0,0,0,0,0,0,0,0,0,0,0,14,0,0,0,0,0,0,0,0,0,0,0,11,0,0
0,0,12,0,0,0,0,0,0,0,0,0,0,12,11,12,0,0,0,0,0,0,0,0,0,0,12,0,0
0,0,11,0,0,0,0,0,0,0,0,0,11,0,0,0,11,0,0,0,0,0,0,0,0,0,11,0,0
0,0,0,3,0,0,0,0,0,0,0,3,0,0,0,0,0,3,0,0,0,0,0,0,0,3,0,0,0
0,0,0,0,3,0,0,0,0,0,3,0,0,0,0,0,0,0,3,0,0,0,0,0,3,0,0,0,0
0,0,0,0,0,11,12,11,12,11,0,0,0,0,0,0,0,0,0,11,12,11,12,11,0,0,0,0,0
0,0,0,0,0,0,0,0,0,0,0,0,0,0,0,0,0,0,0,0,0,0,0,0,0,0,0,0,0
0,0,0,0,0,0,0,0,0,0,0,0,0,0,0,0,0,0,0,0,0,0,0,0,0,0,0,0,0
endlayer

layer
0,0,0,0,0,0,0,0,0,0,0,0,0,0,0,0,0,0,0,0,0,0,0,0,0,0,0,0,0
0,0,0,0,0,0,0,0,0,0,0,0,0,0,0,0,0,0,0,0,0,0,0,0,0,0,0,0,0
0,0,0,0,0,11,12,11,12,11,0,0,0,0,0,0,0,0,0,11,12,11,12,11,0,0,0,0,0
0,0,0,0,3,0,0,0,0,0,3,0,0,0,0,0,0,0,3,0,0,0,0,0,3,0,0,0,0
0,0,0,3,0,0,0,0,0,0,0,3,0,0,0,0,0,3,0,0,0,0,0,0,0,3,0,0,0
0,0,11,0,0,0,0,0,0,0,0,0,11,0,0,0,11,0,0,0,0,0,0,0,0,0,11,0,0
0,0,12,0,0,0,0,0,0,0,0,0,0,12,11,12,0,0,0,0,0,0,0,0,0,0,12,0,0
0,0,11,0,0,0,0,0,0,0,0,0,0,11,14,11,0,0,0,0,0,0,0,0,0,0,11,0,0
0,0,12,0,0,0,0,0,0,0,0,0,0,12,11,12,0,0,0,0,0,0,0,0,0,0,12,0,0
0,0,11,0,0,0,0,0,0,0,0,0,11,0,0,0,11,0,0,0,0,0,0,0,0,0,11,0,0
0,0,0,3,0,0,0,0,0,0,0,3,0,0,0,0,0,3,0,0,0,0,0,0,0,3,0,0,0
0,0,0,0,3,0,0,0,0,0,3,0,0,0,0,0,0,0,3,0,0,0,0,0,3,0,0,0,0
0,0,0,0,0,11,12,11,12,11,0,0,0,0,0,0,0,0,0,11,12,11,12,11,0,0,0,0,0
0,0,0,0,0,0,0,0,0,0,0,0,0,0,0,0,0,0,0,0,0,0,0,0,0,0,0,0,0
0,0,0,0,0,0,0,0,0,0,0,0,0,0,0,0,0,0,0,0,0,0,0,0,0,0,0,0,0
endlayer

layer
0,0,0,0,0,0,0,0,0,0,0,0,0,0,0,0,0,0,0,0,0,0,0,0,0,0,0,0,0
0,0,0,0,0,0,0,0,0,0,0,0,0,0,0,0,0,0,0,0,0,0,0,0,0,0,0,0,0
0,0,0,0,0,11,12,11,12,11,0,0,0,0,0,0,0,0,0,11,12,11,12,11,0,0,0,0,0
0,0,0,0,3,0,0,0,0,0,3,0,0,0,0,0,0,0,3,0,0,0,0,0,3,0,0,0,0
0,0,0,3,0,0,0,0,0,0,0,3,0,0,0,0,0,3,0,0,0,0,0,0,0,3,0,0,0
0,0,11,0,0,0,0,0,0,0,0,0,11,0,0,0,11,0,0,0,0,0,0,0,0,0,11,0,0
0,0,12,0,0,0,0,0,0,0,0,0,0,12,11,12,0,0,0,0,0,0,0,0,0,0,12,0,0
0,0,11,0,0,0,0,0,0,0,0,0,0,11,14,11,0,0,0,0,0,0,0,0,0,0,11,0,0
0,0,12,0,0,0,0,0,0,0,0,0,0,12,11,12,0,0,0,0,0,0,0,0,0,0,12,0,0
0,0,11,0,0,0,0,0,0,0,0,0,11,0,0,0,11,0,0,0,0,0,0,0,0,0,11,0,0
0,0,0,3,0,0,0,0,0,0,0,3,0,0,0,0,0,3,0,0,0,0,0,0,0,3,0,0,0
0,0,0,0,3,0,0,0,0,0,3,0,0,0,0,0,0,0,3,0,0,0,0,0,3,0,0,0,0
0,0,0,0,0,11,12,11,12,11,0,0,0,0,0,0,0,0,0,11,12,11,12,11,0,0,0,0,0
0,0,0,0,0,0,0,0,0,0,0,0,0,0,0,0,0,0,0,0,0,0,0,0,0,0,0,0,0
0,0,0,0,0,0,0,0,0,0,0,0,0,0,0,0,0,0,0,0,0,0,0,0,0,0,0,0,0
endlayer

layer
0,0,0,0,0,0,0,0,0,0,0,0,0,0,0,0,0,0,0,0,0,0,0,0,0,0,0,0,0
0,0,0,0,0,0,0,0,0,0,0,0,0,0,0,0,0,0,0,0,0,0,0,0,0,0,0,0,0
0,0,0,0,0,11,12,11,12,11,0,0,0,0,0,0,0,0,0,11,12,11,12,11,0,0,0,0,0
0,0,0,0,3,0,0,0,0,0,3,0,0,0,0,0,0,0,3,0,0,0,0,0,3,0,0,0,0
0,0,0,3,0,0,0,0,0,0,0,3,0,0,0,0,0,3,0,0,0,0,0,0,0,3,0,0,0
0,0,11,0,0,0,0,0,0,0,0,0,11,0,0,0,11,0,0,0,0,0,0,0,0,0,11,0,0
0,0,12,0,0,0,0,0,0,0,0,0,0,12,11,12,0,0,0,0,0,0,0,0,0,0,12,0,0
0,0,11,0,0,0,0,0,0,0,0,0,0,11,14,11,0,0,0,0,0,0,0,0,0,0,11,0,0
0,0,12,0,0,0,0,0,0,0,0,0,0,12,11,12,0,0,0,0,0,0,0,0,0,0,12,0,0
0,0,11,0,0,0,0,0,0,0,0,0,11,0,0,0,11,0,0,0,0,0,0,0,0,0,11,0,0
0,0,0,3,0,0,0,0,0,0,0,3,0,0,0,0,0,3,0,0,0,0,0,0,0,3,0,0,0
0,0,0,0,3,0,0,0,0,0,3,0,0,0,0,0,0,0,3,0,0,0,0,0,3,0,0,0,0
0,0,0,0,0,11,12,11,12,11,0,0,0,0,0,0,0,0,0,11,12,11,12,11,0,0,0,0,0
0,0,0,0,0,0,0,0,0,0,0,0,0,0,0,0,0,0,0,0,0,0,0,0,0,0,0,0,0
0,0,0,0,0,0,0,0,0,0,0,0,0,0,0,0,0,0,0,0,0,0,0,0,0,0,0,0,0
endlayer

layer
0,0,0,0,0,0,0,0,0,0,0,0,0,0,0,0,0,0,0,0,0,0,0,0,0,0,0,0,0
0,0,0,0,0,0,0,0,0,0,0,0,0,0,0,0,0,0,0,0,0,0,0,0,0,0,0,0,0
0,0,0,0,0,11,12,11,12,11,0,0,0,0,0,0,0,0,0,11,12,11,12,11,0,0,0,0,0
0,0,0,0,3,0,0,0,0,0,3,0,0,0,0,0,0,0,3,0,0,0,0,0,3,0,0,0,0
0,0,0,3,0,0,0,0,0,0,0,3,0,0,0,0,0,3,0,0,0,0,0,0,0,3,0,0,0
0,0,11,0,0,0,0,0,0,0,0,0,11,0,0,0,11,0,0,0,0,0,0,0,0,0,11,0,0
0,0,12,0,0,0,0,0,0,0,0,0,0,12,11,12,0,0,0,0,0,0,0,0,0,0,12,0,0
0,0,11,0,0,0,0,0,0,0,0,0,0,11,14,11,0,0,0,0,0,0,0,0,0,0,11,0,0
0,0,12,0,0,0,0,0,0,0,0,0,0,12,11,12,0,0,0,0,0,0,0,0,0,0,12,0,0
0,0,11,0,0,0,0,0,0,0,0,0,11,0,0,0,11,0,0,0,0,0,0,0,0,0,11,0,0
0,0,0,3,0,0,0,0,0,0,0,3,0,0,0,0,0,3,0,0,0,0,0,0,0,3,0,0,0
0,0,0,0,3,0,0,0,0,0,3,0,0,0,0,0,0,0,3,0,0,0,0,0,3,0,0,0,0
0,0,0,0,0,11,12,11,12,11,0,0,0,0,0,0,0,0,0,11,12,11,12,11,0,0,0,0,0
0,0,0,0,0,0,0,0,0,0,0,0,0,0,0,0,0,0,0,0,0,0,0,0,0,0,0,0,0
0,0,0,0,0,0,0,0,0,0,0,0,0,0,0,0,0,0,0,0,0,0,0,0,0,0,0,0,0
endlayer

layer
0,0,0,0,0,0,0,0,0,0,0,0,0,0,0,0,0,0,0,0,0,0,0,0,0,0,0,0,0
0,0,0,0,0,0,0,0,0,0,0,0,0,0,0,0,0,0,0,0,0,0,0,0,0,0,0,0,0
0,0,0,0,0,3,3,3,3,3,0,0,0,0,0,0,0,0,0,3,3,3,3,3,0,0,0,0,0
0,0,0,0,3,4,4,4,4,4,3,0,0,0,0,0,0,0,3,4,4,4,4,4,3,0,0,0,0
0,0,0,3,4,4,4,4,4,4,4,3,0,0,0,0,0,3,4,4,4,4,4,4,4,3,0,0,0
0,0,3,4,4,4,4,4,4,4,4,4,3,0,0,0,3,4,4,4,4,4,4,4,4,4,3,0,0
0,0,3,4,4,4,4,4,4,4,4,4,4,3,3,3,4,4,4,4,4,4,4,4,4,4,3,0,0
0,0,3,4,4,4,4,4,4,4,4,4,4,4,14,4,4,4,4,4,4,4,4,4,4,4,3,0,0
0,0,3,4,4,4,4,4,4,4,4,4,4,3,3,3,4,4,4,4,4,4,4,4,4,4,3,0,0
0,0,3,4,4,4,4,4,4,4,4,4,3,0,0,0,3,4,4,4,4,4,4,4,4,4,3,0,0
0,0,0,3,4,4,4,4,4,4,4,3,0,0,0,0,0,3,4,4,4,4,4,4,4,3,0,0,0
0,0,0,0,3,4,4,4,4,4,3,0,0,0,0,0,0,0,3,4,4,4,4,4,3,0,0,0,0
0,0,0,0,0,3,3,3,3,3,0,0,0,0,0,0,0,0,0,3,3,3,3,3,0,0,0,0,0
0,0,0,0,0,0,0,0,0,0,0,0,0,0,0,0,0,0,0,0,0,0,0,0,0,0,0,0,0
0,0,0,0,0,0,0,0,0,0,0,0,0,0,0,0,0,0,0,0,0,0,0,0,0,0,0,0,0
endlayer

layer
0,0,0,0,0,0,0,0,0,0,0,0,0,0,0,0,0,0,0,0,0,0,0,0,0,0,0,0,0
0,0,0,0,0,0,0,0,0,0,0,0,0,0,0,0,0,0,0,0,0,0,0,0,0,0,0,0,0
0,0,0,0,0,11,12,11,12,11,0,0,0,0,0,0,0,0,0,11,12,11,12,11,0,0,0,0,0
0,0,0,0,3,0,10,6,6,10,3,0,0,0,0,0,0,0,3,10,6,6,10,0,3,0,0,0,0
0,0,0,3,8,0,10,6,6,10,0,3,0,0,0,0,0,3,0,10,6,6,10,0,8,3,0,0,0
0,0,11,0,0,0,0,0,0,0,0,0,11,0,0,0,11,0,0,0,0,0,0,0,0,0,11,0,0
0,0,12,6,0,0,0,0,0,0,0,0,0,12,11,12,0,0,0,0,0,0,0,0,0,6,12,0,0
0,0,11,7,9,9,0,0,0,0,0,0,0,0,14,0,0,0,0,0,0,0,0,9,9,7,11,0,0
0,0,12,7,9,9,0,0,0,0,0,0,0,12,11,12,0,0,0,0,0,0,0,9,9,7,12,0,0
0,0,11,6,0,0,0,0,0,0,0,0,11,0,0,0,11,0,0,0,0,0,0,0,0,6,11,0,0
0,0,0,3,8,0,0,0,0,0,0,3,0,0,0,0,0,3,0,0,0,0,0,0,8,3,0,0,0
0,0,0,0,3,0,0,0,0,0,3,0,0,0,0,0,0,0,3,0,0,0,0,0,3,0,0,0,0
0,0,0,0,0,11,12,11,12,11,0,0,0,0,0,0,0,0,0,11,12,11,12,11,0,0,0,0,0
0,0,0,0,0,0,0,0,0,0,0,0,0,0,0,0,0,0,0,0,0,0,0,0,0,0,0,0,0
0,0,0,0,0,0,0,0,0,0,0,0,0,0,0,0,0,0,0,0,0,0,0,0,0,0,0,0,0
endlayer

layer
0,0,0,0,0,0,0,0,0,0,0,0,0,0,0,0,0,0,0,0,0,0,0,0,0,0,0,0,0
0,0,0,0,0,0,0,0,0,0,0,0,0,0,0,0,0,0,0,0,0,0,0,0,0,0,0,0,0
0,0,0,0,0,11,12,11,12,11,0,0,0,0,0,0,0,0,0,11,12,11,12,11,0,0,0,0,0
0,0,0,0,3,0,0,0,0,0,3,0,0,0,0,0,0,0,3,0,0,0,0,0,3,0,0,0,0
0,0,0,3,0,0,0,0,0,0,0,3,0,0,0,0,0,3,0,0,0,0,0,0,0,3,0,0,0
0,0,11,0,0,0,0,0,0,0,0,0,11,0,0,0,11,0,0,0,0,0,0,0,0,0,11,0,0
0,0,12,13,0,0,0,0,0,0,0,0,0,12,11,12,0,0,0,0,0,0,0,0,0,13,12,0,0
0,0,11,0,0,0,0,0,0,0,0,0,0,0,14,0,0,0,0,0,0,0,0,0,0,0,11,0,0
0,0,12,0,0,0,0,0,0,0,0,0,0,12,11,12,0,0,0,0,0,0,0,0,0,0,12,0,0
0,0,11,0,0,0,0,0,0,0,0,0,11,0,0,0,11,0,0,0,0,0,0,0,0,0,11,0,0
0,0,0,3,0,0,0,0,0,0,0,3,0,0,0,0,0,3,0,0,0,0,0,0,0,3,0,0,0
0,0,0,0,3,0,0,0,0,0,3,0,0,0,0,0,0,0,3,0,0,0,0,0,3,0,0,0,0
0,0,0,0,0,11,12,11,12,11,0,0,0,0,0,0,0,0,0,11,12,11,12,11,0,0,0,0,0
0,0,0,0,0,0,0,0,0,0,0,0,0,0,0,0,0,0,0,0,0,0,0,0,0,0,0,0,0
0,0,0,0,0,0,0,0,0,0,0,0,0,0,0,0,0,0,0,0,0,0,0,0,0,0,0,0,0
endlayer

layer
0,0,0,0,0,0,0,0,0,0,0,0,0,0,0,0,0,0,0,0,0,0,0,0,0,0,0,0,0
0,0,0,0,0,0,0,0,0,0,0,0,0,0,0,0,0,0,0,0,0,0,0,0,0,0,0,0,0
0,0,0,0,0,11,12,11,12,11,0,0,0,0,0,0,0,0,0,11,12,11,12,11,0,0,0,0,0
0,0,0,0,3,0,0,0,0,0,3,0,0,0,0,0,0,0,3,0,0,0,0,0,3,0,0,0,0
0,0,0,3,0,0,0,0,0,0,0,3,0,0,0,0,0,3,0,0,0,0,0,0,0,3,0,0,0
0,0,11,0,0,0,0,0,0,0,0,0,11,0,0,0,11,0,0,0,0,0,0,0,0,0,11,0,0
0,0,12,0,0,0,0,0,0,0,0,0,0,12,11,12,0,0,0,0,0,0,0,0,0,0,12,0,0
0,0,11,0,0,0,0,0,0,0,0,0,0,11,14,11,0,0,0,0,0,0,0,0,0,0,11,0,0
0,0,12,0,0,0,0,0,0,0,0,0,0,12,11,12,0,0,0,0,0,0,0,0,0,0,12,0,0
0,0,11,0,0,0,0,0,0,0,0,0,11,0,0,0,11,0,0,0,0,0,0,0,0,0,11,0,0
0,0,0,3,0,0,0,0,0,0,0,3,0,0,0,0,0,3,0,0,0,0,0,0,0,3,0,0,0
0,0,0,0,3,0,0,0,0,0,3,0,0,0,0,0,0,0,3,0,0,0,0,0,3,0,0,0,0
0,0,0,0,0,11,12,11,12,11,0,0,0,0,0,0,0,0,0,11,12,11,12,11,0,0,0,0,0
0,0,0,0,0,0,0,0,0,0,0,0,0,0,0,0,0,0,0,0,0,0,0,0,0,0,0,0,0
0,0,0,0,0,0,0,0,0,0,0,0,0,0,0,0,0,0,0,0,0,0,0,0,0,0,0,0,0
endlayer

layer
0,0,0,0,0,0,0,0,0,0,0,0,0,0,0,0,0,0,0,0,0,0,0,0,0,0,0,0,0
0,0,0,0,0,0,0,0,0,0,0,0,0,0,0,0,0,0,0,0,0,0,0,0,0,0,0,0,0
0,0,0,0,0,11,12,11,12,11,0,0,0,0,0,0,0,0,0,11,12,11,12,11,0,0,0,0,0
0,0,0,0,3,0,0,0,0,0,3,0,0,0,0,0,0,0,3,0,0,0,0,0,3,0,0,0,0
0,0,0,3,0,0,0,0,0,0,0,3,0,0,0,0,0,3,0,0,0,0,0,0,0,3,0,0,0
0,0,11,0,0,0,0,0,0,0,0,0,11,0,0,0,11,0,0,0,0,0,0,0,0,0,11,0,0
0,0,12,0,0,0,0,0,0,0,0,0,0,12,11,12,0,0,0,0,0,0,0,0,0,0,12,0,0
0,0,11,0,0,0,0,0,0,0,0,0,0,11,14,11,0,0,0,0,0,0,0,0,0,0,11,0,0
0,0,12,0,0,0,0,0,0,0,0,0,0,12,11,12,0,0,0,0,0,0,0,0,0,0,12,0,0
0,0,11,0,0,0,0,0,0,0,0,0,11,0,0,0,11,0,0,0,0,0,0,0,0,0,11,0,0
0,0,0,3,0,0,0,0,0,0,0,3,0,0,0,0,0,3,0,0,0,0,0,0,0,3,0,0,0
0,0,0,0,3,0,0,0,0,0,3,0,0,0,0,0,0,0,3,0,0,0,0,0,3,0,0,0,0
0,0,0,0,0,11,12,11,12,11,0,0,0,0,0,0,0,0,0,11,12,11,12,11,0,0,0,0,0
0,0,0,0,0,0,0,0,0,0,0,0,0,0,0,0,0,0,0,0,0,0,0,0,0,0,0,0,0
0,0,0,0,0,0,0,0,0,0,0,0,0,0,0,0,0,0,0,0,0,0,0,0,0,0,0,0,0
endlayer

layer
0,0,0,0,0,0,0,0,0,0,0,0,0,0,0,0,0,0,0,0,0,0,0,0,0,0,0,0,0
0,0,0,0,0,0,0,0,0,0,0,0,0,0,0,0,0,0,0,0,0,0,0,0,0,0,0,0,0
0,0,0,0,0,11,12,11,12,11,0,0,0,0,0,0,0,0,0,11,12,11,12,11,0,0,0,0,0
0,0,0,0,3,0,0,0,0,0,3,0,0,0,0,0,0,0,3,0,0,0,0,0,3,0,0,0,0
0,0,0,3,0,0,0,0,0,0,0,3,0,0,0,0,0,3,0,0,0,0,0,0,0,3,0,0,0
0,0,11,0,0,0,0,0,0,0,0,0,11,0,0,0,11,0,0,0,0,0,0,0,0,0,11,0,0
0,0,12,0,0,0,0,0,0,0,0,0,0,12,11,12,0,0,0,0,0,0,0,0,0,0,12,0,0
0,0,11,0,0,0,0,0,0,0,0,0,0,11,14,11,0,0,0,0,0,0,0,0,0,0,11,0,0
0,0,12,0,0,0,0,0,0,0,0,0,0,12,11,12,0,0,0,0,0,0,0,0,0,0,12,0,0
0,0,11,0,0,0,0,0,0,0,0,0,11,0,0,0,11,0,0,0,0,0,0,0,0,0,11,0,0
0,0,0,3,0,0,0,0,0,0,0,3,0,0,0,0,0,3,0,0,0,0,0,0,0,3,0,0,0
0,0,0,0,3,0,0,0,0,0,3,0,0,0,0,0,0,0,3,0,0,0,0,0,3,0,0,0,0
0,0,0,0,0,11,12,11,12,11,0,0,0,0,0,0,0,0,0,11,12,11,12,11,0,0,0,0,0
0,0,0,0,0,0,0,0,0,0,0,0,0,0,0,0,0,0,0,0,0,0,0,0,0,0,0,0,0
0,0,0,0,0,0,0,0,0,0,0,0,0,0,0,0,0,0,0,0,0,0,0,0,0,0,0,0,0
endlayer

layer
0,0,0,0,0,0,0,0,0,0,0,0,0,0,0,0,0,0,0,0,0,0,0,0,0,0,0,0,0
0,0,0,0,0,0,0,0,0,0,0,0,0,0,0,0,0,0,0,0,0,0,0,0,0,0,0,0,0
0,0,0,0,0,11,12,11,12,11,0,0,0,0,0,0,0,0,0,11,12,11,12,11,0,0,0,0,0
0,0,0,0,3,0,0,0,0,0,3,0,0,0,0,0,0,0,3,0,0,0,0,0,3,0,0,0,0
0,0,0,3,0,0,0,0,0,0,0,3,0,0,0,0,0,3,0,0,0,0,0,0,0,3,0,0,0
0,0,11,0,0,0,0,0,0,0,0,0,11,0,0,0,11,0,0,0,0,0,0,0,0,0,11,0,0
0,0,12,0,0,0,0,0,0,0,0,0,0,12,11,12,0,0,0,0,0,0,0,0,0,0,12,0,0
0,0,11,0,0,0,0,0,0,0,0,0,0,11,14,11,0,0,0,0,0,0,0,0,0,0,11,0,0
0,0,12,0,0,0,0,0,0,0,0,0,0,12,11,12,0,0,0,0,0,0,0,0,0,0,12,0,0
0,0,11,0,0,0,0,0,0,0,0,0,11,0,0,0,11,0,0,0,0,0,0,0,0,0,11,0,0
0,0,0,3,0,0,0,0,0,0,0,3,0,0,0,0,0,3,0,0,0,0,0,0,0,3,0,0,0
0,0,0,0,3,0,0,0,0,0,3,0,0,0,0,0,0,0,3,0,0,0,0,0,3,0,0,0,0
0,0,0,0,0,11,12,11,12,11,0,0,0,0,0,0,0,0,0,11,12,11,12,11,0,0,0,0,0
0,0,0,0,0,0,0,0,0,0,0,0,0,0,0,0,0,0,0,0,0,0,0,0,0,0,0,0,0
0,0,0,0,0,0,0,0,0,0,0,0,0,0,0,0,0,0,0,0,0,0,0,0,0,0,0,0,0
endlayer

layer
0,0,0,0,0,0,0,0,0,0,0,0,0,0,0,0,0,0,0,0,0,0,0,0,0,0,0,0,0
0,0,0,0,0,0,0,0,0,0,0,0,0,0,0,0,0,0,0,0,0,0,0,0,0,0,0,0,0
0,0,0,0,0,3,3,3,3,3,0,0,0,0,0,0,0,0,0,3,3,3,3,3,0,0,0,0,0
0,0,0,0,3,4,4,4,4,4,3,0,0,0,0,0,0,0,3,4,4,4,4,4,3,0,0,0,0
0,0,0,3,4,4,4,4,4,4,4,3,0,0,0,0,0,3,4,4,4,4,4,4,4,3,0,0,0
0,0,3,4,4,4,4,4,4,4,4,4,3,0,0,0,3,4,4,4,4,4,4,4,4,4,3,0,0
0,0,3,4,4,4,4,4,4,4,4,4,4,3,3,3,4,4,4,4,4,4,4,4,4,4,3,0,0
0,0,3,4,4,4,4,4,4,4,4,4,4,4,14,4,4,4,4,4,4,4,4,4,4,4,3,0,0
0,0,3,4,4,4,4,4,4,4,4,4,4,3,3,3,4,4,4,4,4,4,4,4,4,4,3,0,0
0,0,3,4,4,4,4,4,4,4,4,4,3,0,0,0,3,4,4,4,4,4,4,4,4,4,3,0,0
0,0,0,3,4,4,4,4,4,4,4,3,0,0,0,0,0,3,4,4,4,4,4,4,4,3,0,0,0
0,0,0,0,3,4,4,4,4,4,3,0,0,0,0,0,0,0,3,4,4,4,4,4,3,0,0,0,0
0,0,0,0,0,3,3,3,3,3,0,0,0,0,0,0,0,0,0,3,3,3,3,3,0,0,0,0,0
0,0,0,0,0,0,0,0,0,0,0,0,0,0,0,0,0,0,0,0,0,0,0,0,0,0,0,0,0
0,0,0,0,0,0,0,0,0,0,0,0,0,0,0,0,0,0,0,0,0,0,0,0,0,0,0,0,0
endlayer

layer
0,0,0,0,0,0,0,0,0,0,0,0,0,0,0,0,0,0,0,0,0,0,0,0,0,0,0,0,0
0,0,0,0,0,0,0,0,0,0,0,0,0,0,0,0,0,0,0,0,0,0,0,0,0,0,0,0,0
0,0,0,0,0,11,12,11,12,11,0,0,0,0,0,0,0,0,0,11,12,11,12,11,0,0,0,0,0
0,0,0,0,3,0,10,6,6,10,3,0,0,0,0,0,0,0,3,10,6,6,10,0,3,0,0,0,0
0,0,0,3,8,0,10,6,6,10,0,3,0,0,0,0,0,3,0,10,6,6,10,0,8,3,0,0,0
0,0,11,0,0,0,0,0,0,0,0,0,11,0,0,0,11,0,0,0,0,0,0,0,0,0,11,0,0
0,0,12,6,0,0,0,0,0,0,0,0,0,12,11,12,0,0,0,0,0,0,0,0,0,6,12,0,0
0,0,11,7,9,9,0,0,0,0,0,0,0,0,14,0,0,0,0,0,0,0,0,9,9,7,11,0,0
0,0,12,7,9,9,0,0,0,0,0,0,0,12,11,12,0,0,0,0,0,0,0,9,9,7,12,0,0
0,0,11,6,0,0,0,0,0,0,0,0,11,0,0,0,11,0,0,0,0,0,0,0,0,6,11,0,0
0,0,0,3,8,0,0,0,0,0,0,3,0,0,0,0,0,3,0,0,0,0,0,0,8,3,0,0,0
0,0,0,0,3,0,0,0,0,0,3,0,0,0,0,0,0,0,3,0,0,0,0,0,3,0,0,0,0
0,0,0,0,0,11,12,11,12,11,0,0,0,0,0,0,0,0,0,11,12,11,12,11,0,0,0,0,0
0,0,0,0,0,0,0,0,0,0,0,0,0,0,0,0,0,0,0,0,0,0,0,0,0,0,0,0,0
0,0,0,0,0,0,0,0,0,0,0,0,0,0,0,0,0,0,0,0,0,0,0,0,0,0,0,0,0
endlayer

layer
0,0,0,0,0,0,0,0,0,0,0,0,0,0,0,0,0,0,0,0,0,0,0,0,0,0,0,0,0
0,0,0,0,0,0,0,0,0,0,0,0,0,0,0,0,0,0,0,0,0,0,0,0,0,0,0,0,0
0,0,0,0,0,11,12,11,12,11,0,0,0,0,0,0,0,0,0,11,12,11,12,11,0,0,0,0,0
0,0,0,0,3,0,0,0,0,0,3,0,0,0,0,0,0,0,3,0,0,0,0,0,3,0,0,0,0
0,0,0,3,0,0,0,0,0,0,0,3,0,0,0,0,0,3,0,0,0,0,0,0,0,3,0,0,0
0,0,11,0,0,0,0,0,0,0,0,0,11,0,0,0,11,0,0,0,0,0,0,0,0,0,11,0,0
0,0,12,13,0,0,0,0,0,0,0,0,0,12,11,12,0,0,0,0,0,0,0,0,0,13,12,0,0
0,0,11,0,0,0,0,0,0,0,0,0,0,0,14,0,0,0,0,0,0,0,0,0,0,0,11,0,0
0,0,12,0,0,0,0,0,0,0,0,0,0,12,11,12,0,0,0,0,0,0,0,0,0,0,12,0,0
0,0,11,0,0,0,0,0,0,0,0,0,11,0,0,0,11,0,0,0,0,0,0,0,0,0,11,0,0
0,0,0,3,0,0,0,0,0,0,0,3,0,0,0,0,0,3,0,0,0,0,0,0,0,3,0,0,0
0,0,0,0,3,0,0,0,0,0,3,0,0,0,0,0,0,0,3,0,0,0,0,0,3,0,0,0,0
0,0,0,0,0,11,12,11,12,11,0,0,0,0,0,0,0,0,0,11,12,11,12,11,0,0,0,0,0
0,0,0,0,0,0,0,0,0,0,0,0,0,0,0,0,0,0,0,0,0,0,0,0,0,0,0,0,0
0,0,0,0,0,0,0,0,0,0,0,0,0,0,0,0,0,0,0,0,0,0,0,0,0,0,0,0,0
endlayer

layer
0,0,0,0,0,0,0,0,0,0,0,0,0,0,0,0,0,0,0,0,0,0,0,0,0,0,0,0,0
0,0,0,0,0,0,0,0,0,0,0,0,0,0,0,0,0,0,0,0,0,0,0,0,0,0,0,0,0
0,0,0,0,0,11,12,11,12,11,0,0,0,0,0,0,0,0,0,11,12,11,12,11,0,0,0,0,0
0,0,0,0,3,0,0,0,0,0,3,0,0,0,0,0,0,0,3,0,0,0,0,0,3,0,0,0,0
0,0,0,3,0,0,0,0,0,0,0,3,0,0,0,0,0,3,0,0,0,0,0,0,0,3,0,0,0
0,0,11,0,0,0,0,0,0,0,0,0,11,0,0,0,11,0,0,0,0,0,0,0,0,0,11,0,0
0,0,12,0,0,0,0,0,0,0,0,0,0,12,11,12,0,0,0,0,0,0,0,0,0,0,12,0,0
0,0,11,0,0,0,0,0,0,0,0,0,0,11,14,11,0,0,0,0,0,0,0,0,0,0,11,0,0
0,0,12,0,0,0,0,0,0,0,0,0,0,12,11,12,0,0,0,0,0,0,0,0,0,0,12,0,0
0,0,11,0,0,0,0,0,0,0,0,0,11,0,0,0,11,0,0,0,0,0,0,0,0,0,11,0,0
0,0,0,3,0,0,0,0,0,0,0,3,0,0,0,0,0,3,0,0,0,0,0,0,0,3,0,0,0
0,0,0,0,3,0,0,0,0,0,3,0,0,0,0,0,0,0,3,0,0,0,0,0,3,0,0,0,0
0,0,0,0,0,11,12,11,12,11,0,0,0,0,0,0,0,0,0,11,12,11,12,11,0,0,0,0,0
0,0,0,0,0,0,0,0,0,0,0,0,0,0,0,0,0,0,0,0,0,0,0,0,0,0,0,0,0
0,0,0,0,0,0,0,0,0,0,0,0,0,0,0,0,0,0,0,0,0,0,0,0,0,0,0,0,0
endlayer

layer
0,0,0,0,0,0,0,0,0,0,0,0,0,0,0,0,0,0,0,0,0,0,0,0,0,0,0,0,0
0,0,0,0,0,0,0,0,0,0,0,0,0,0,0,0,0,0,0,0,0,0,0,0,0,0,0,0,0
0,0,0,0,0,11,12,11,12,11,0,0,0,0,0,0,0,0,0,11,12,11,12,11,0,0,0,0,0
0,0,0,0,3,0,0,0,0,0,3,0,0,0,0,0,0,0,3,0,0,0,0,0,3,0,0,0,0
0,0,0,3,0,0,0,0,0,0,0,3,0,0,0,0,0,3,0,0,0,0,0,0,0,3,0,0,0
0,0,11,0,0,0,0,0,0,0,0,0,11,0,0,0,11,0,0,0,0,0,0,0,0,0,11,0,0
0,0,12,0,0,0,0,0,0,0,0,0,0,12,11,12,0,0,0,0,0,0,0,0,0,0,12,0,0
0,0,11,0,0,0,0,0,0,0,0,0,0,11,14,11,0,0,0,0,0,0,0,0,0,0,11,0,0
0,0,12,0,0,0,0,0,0,0,0,0,0,12,11,12,0,0,0,0,0,0,0,0,0,0,12,0,0
0,0,11,0,0,0,0,0,0,0,0,0,11,0,0,0,11,0,0,0,0,0,0,0,0,0,11,0,0
0,0,0,3,0,0,0,0,0,0,0,3,0,0,0,0,0,3,0,0,0,0,0,0,0,3,0,0,0
0,0,0,0,3,0,0,0,0,0,3,0,0,0,0,0,0,0,3,0,0,0,0,0,3,0,0,0,0
0,0,0,0,0,11,12,11,12,11,0,0,0,0,0,0,0,0,0,11,12,11,12,11,0,0,0,0,0
0,0,0,0,0,0,0,0,0,0,0,0,0,0,0,0,0,0,0,0,0,0,0,0,0,0,0,0,0
0,0,0,0,0,0,0,0,0,0,0,0,0,0,0,0,0,0,0,0,0,0,0,0,0,0,0,0,0
endlayer

layer
0,0,0,0,0,0,0,0,0,0,0,0,0,0,0,0,0,0,0,0,0,0,0,0,0,0,0,0,0
0,0,0,0,0,0,0,0,0,0,0,0,0,0,0,0,0,0,0,0,0,0,0,0,0,0,0,0,0
0,0,0,0,0,11,12,11,12,11,0,0,0,0,0,0,0,0,0,11,12,11,12,11,0,0,0,0,0
0,0,0,0,3,0,0,0,0,0,3,0,0,0,0,0,0,0,3,0,0,0,0,0,3,0,0,0,0
0,0,0,3,0,0,0,0,0,0,0,3,0,0,0,0,0,3,0,0,0,0,0,0,0,3,0,0,0
0,0,11,0,0,0,0,0,0,0,0,0,11,0,0,0,11,0,0,0,0,0,0,0,0,0,11,0,0
0,0,12,0,0,0,0,0,0,0,0,0,0,12,11,12,0,0,0,0,0,0,0,0,0,0,12,0,0
0,0,11,0,0,0,0,0,0,0,0,0,0,11,14,11,0,0,0,0,0,0,0,0,0,0,11,0,0
0,0,12,0,0,0,0,0,0,0,0,0,0,12,11,12,0,0,0,0,0,0,0,0,0,0,12,0,0
0,0,11,0,0,0,0,0,0,0,0,0,11,0,0,0,11,0,0,0,0,0,0,0,0,0,11,0,0
0,0,0,3,0,0,0,0,0,0,0,3,0,0,0,0,0,3,0,0,0,0,0,0,0,3,0,0,0
0,0,0,0,3,0,0,0,0,0,3,0,0,0,0,0,0,0,3,0,0,0,0,0,3,0,0,0,0
0,0,0,0,0,11,12,11,12,11,0,0,0,0,0,0,0,0,0,11,12,11,12,11,0,0,0,0,0
0,0,0,0,0,0,0,0,0,0,0,0,0,0,0,0,0,0,0,0,0,0,0,0,0,0,0,0,0
0,0,0,0,0,0,0,0,0,0,0,0,0,0,0,0,0,0,0,0,0,0,0,0,0,0,0,0,0
endlayer

layer
0,0,0,0,0,0,0,0,0,0,0,0,0,0,0,0,0,0,0,0,0,0,0,0,0,0,0,0,0
0,0,0,0,0,0,0,0,0,0,0,0,0,0,0,0,0,0,0,0,0,0,0,0,0,0,0,0,0
0,0,0,0,0,11,12,11,12,11,0,0,0,0,0,0,0,0,0,11,12,11,12,11,0,0,0,0,0
0,0,0,0,3,0,0,0,0,0,3,0,0,0,0,0,0,0,3,0,0,0,0,0,3,0,0,0,0
0,0,0,3,0,0,0,0,0,0,0,3,0,0,0,0,0,3,0,0,0,0,0,0,0,3,0,0,0
0,0,11,0,0,0,0,0,0,0,0,0,11,0,0,0,11,0,0,0,0,0,0,0,0,0,11,0,0
0,0,12,0,0,0,0,0,0,0,0,0,0,12,11,12,0,0,0,0,0,0,0,0,0,0,12,0,0
0,0,11,0,0,0,0,0,0,0,0,0,0,11,14,11,0,0,0,0,0,0,0,0,0,0,11,0,0
0,0,12,0,0,0,0,0,0,0,0,0,0,12,11,12,0,0,0,0,0,0,0,0,0,0,12,0,0
0,0,11,0,0,0,0,0,0,0,0,0,11,0,0,0,11,0,0,0,0,0,0,0,0,0,11,0,0
0,0,0,3,0,0,0,0,0,0,0,3,0,0,0,0,0,3,0,0,0,0,0,0,0,3,0,0,0
0,0,0,0,3,0,0,0,0,0,3,0,0,0,0,0,0,0,3,0,0,0,0,0,3,0,0,0,0
0,0,0,0,0,11,12,11,12,11,0,0,0,0,0,0,0,0,0,11,12,11,12,11,0,0,0,0,0
0,0,0,0,0,0,0,0,0,0,0,0,0,0,0,0,0,0,0,0,0,0,0,0,0,0,0,0,0
0,0,0,0,0,0,0,0,0,0,0,0,0,0,0,0,0,0,0,0,0,0,0,0,0,0,0,0,0
endlayer

layer
0,0,0,0,0,0,0,0,0,0,0,0,0,0,0,0,0,0,0,0,0,0,0,0,0,0,0,0,0
0,0,0,0,0,0,0,0,0,0,0,0,0,0,0,0,0,0,0,0,0,0,0,0,0,0,0,0,0
0,0,0,0,0,3,3,3,3,3,0,0,0,0,0,0,0,0,0,3,3,3,3,3,0,0,0,0,0
0,0,0,0,3,16,16,16,16,16,3,0,0,0,0,0,0,0,3,4,4,4,4,4,3,0,0,0,0
0,0,0,3,16,0,0,0,0,0,16,3,0,0,0,0,0,3,4,4,4,4,4,4,4,3,0,0,0
0,0,3,16,0,0,0,0,0,0,0,16,3,0,0,0,3,4,4,4,4,4,4,4,4,4,3,0,0
0,0,3,16,0,0,0,0,0,0,0,16,3,3,3,3,3,4,4,4,4,4,4,4,4,4,3,0,0
0,0,3,16,0,0,0,0,0,0,0,16,3,3,14,4,4,4,4,4,4,4,4,4,4,4,3,0,0
0,0,3,16,0,0,0,0,0,0,0,16,3,3,3,3,3,4,4,4,4,4,4,4,4,4,3,0,0
0,0,3,16,0,0,0,0,0,0,0,16,3,0,0,0,3,4,4,4,4,4,4,4,4,4,3,0,0
0,0,0,3,16,0,0,0,0,0,16,3,0,0,0,0,0,3,4,4,4,4,4,4,4,3,0,0,0
0,0,0,0,3,16,16,16,16,16,3,0,0,0,0,0,0,0,3,4,4,4,4,4,3,0,0,0,0
0,0,0,0,0,3,3,3,3,3,0,0,0,0,0,0,0,0,0,3,3,3,3,3,0,0,0,0,0
0,0,0,0,0,0,0,0,0,0,0,0,0,0,0,0,0,0,0,0,0,0,0,0,0,0,0,0,0
0,0,0,0,0,0,0,0,0,0,0,0,0,0,0,0,0,0,0,0,0,0,0,0,0,0,0,0,0
endlayer

layer
0,0,0,0,0,0,0,0,0,0,0,0,0,0,0,0,0,0,0,0,0,0,0,0,0,0,0,0,0
0,0,0,0,0,0,0,0,0,0,0,0,0,0,0,0,0,0,0,0,0,0,0,0,0,0,0,0,0
0,0,0,0,0,0,0,0,0,0,0,0,0,0,0,0,0,0,0,11,12,11,12,11,0,0,0,0,0
0,0,0,0,0,0,0,0,0,0,0,0,0,0,0,0,0,0,3,10,6,6,10,0,3,0,0,0,0
0,0,0,0,0,16,16,16,16,16,0,0,0,0,0,0,0,3,0,10,6,6,10,0,8,3,0,0,0
0,0,0,0,16,16,0,0,0,16,16,0,0,0,0,0,11,0,0,0,0,0,0,0,0,0,11,0,0
0,0,0,0,16,0,0,0,0,0,16,0,0,12,11,12,12,0,0,0,0,0,0,0,0,6,12,0,0
0,0,0,0,16,0,0,0,0,0,16,0,0,11,14,0,0,0,0,0,0,0,0,9,9,7,11,0,0
0,0,0,0,16,0,0,0,0,0,16,0,0,12,11,12,12,0,0,0,0,0,0,9,9,7,12,0,0
0,0,0,0,16,16,0,0,0,16,16,0,0,0,0,0,11,0,0,0,0,0,0,0,0,6,11,0,0
0,0,0,0,0,16,16,16,16,16,0,0,0,0,0,0,0,3,0,0,0,0,0,0,8,3,0,0,0
0,0,0,0,0,0,0,0,0,0,0,0,0,0,0,0,0,0,3,0,0,0,0,0,3,0,0,0,0
0,0,0,0,0,0,0,0,0,0,0,0,0,0,0,0,0,0,0,11,12,11,12,11,0,0,0,0,0
0,0,0,0,0,0,0,0,0,0,0,0,0,0,0,0,0,0,0,0,0,0,0,0,0,0,0,0,0
0,0,0,0,0,0,0,0,0,0,0,0,0,0,0,0,0,0,0,0,0,0,0,0,0,0,0,0,0
endlayer

layer
0,0,0,0,0,0,0,0,0,0,0,0,0,0,0,0,0,0,0,0,0,0,0,0,0,0,0,0,0
0,0,0,0,0,0,0,0,0,0,0,0,0,0,0,0,0,0,0,0,0,0,0,0,0,0,0,0,0
0,0,0,0,0,0,0,0,0,0,0,0,0,0,0,0,0,0,0,11,12,11,12,11,0,0,0,0,0
0,0,0,0,0,0,0,0,0,0,0,0,0,0,0,0,0,0,3,0,0,0,0,0,3,0,0,0,0
0,0,0,0,0,0,0,0,0,0,0,0,0,0,0,0,0,3,0,0,0,0,0,0,0,3,0,0,0
0,0,0,0,0,0,16,16,16,0,0,0,0,0,0,0,11,0,0,0,0,0,0,0,0,0,11,0,0
0,0,0,0,0,16,16,0,16,16,0,0,0,12,11,12,12,0,0,0,0,0,0,0,0,13,12,0,0
0,0,0,0,0,16,0,0,0,16,0,0,0,11,14,0,0,0,0,0,0,0,0,0,0,0,11,0,0
0,0,0,0,0,16,16,0,16,16,0,0,0,12,11,12,12,0,0,0,0,0,0,0,0,0,12,0,0
0,0,0,0,0,0,16,16,16,0,0,0,0,0,0,0,11,0,0,0,0,0,0,0,0,0,11,0,0
0,0,0,0,0,0,0,0,0,0,0,0,0,0,0,0,0,3,0,0,0,0,0,0,0,3,0,0,0
0,0,0,0,0,0,0,0,0,0,0,0,0,0,0,0,0,0,3,0,0,0,0,0,3,0,0,0,0
0,0,0,0,0,0,0,0,0,0,0,0,0,0,0,0,0,0,0,11,12,11,12,11,0,0,0,0,0
0,0,0,0,0,0,0,0,0,0,0,0,0,0,0,0,0,0,0,0,0,0,0,0,0,0,0,0,0
0,0,0,0,0,0,0,0,0,0,0,0,0,0,0,0,0,0,0,0,0,0,0,0,0,0,0,0,0
endlayer

layer
0,0,0,0,0,0,0,0,0,0,0,0,0,0,0,0,0,0,0,0,0,0,0,0,0,0,0,0,0
0,0,0,0,0,0,0,0,0,0,0,0,0,0,0,0,0,0,0,0,0,0,0,0,0,0,0,0,0
0,0,0,0,0,0,0,0,0,0,0,0,0,0,0,0,0,0,0,11,12,11,12,11,0,0,0,0,0
0,0,0,0,0,0,0,0,0,0,0,0,0,0,0,0,0,0,3,0,0,0,0,0,3,0,0,0,0
0,0,0,0,0,0,0,0,0,0,0,0,0,0,0,0,0,3,0,0,0,0,0,0,0,3,0,0,0
0,0,0,0,0,0,0,0,0,0,0,0,0,0,0,0,11,0,0,0,0,0,0,0,0,0,11,0,0
0,0,0,0,0,0,0,16,0,0,0,0,0,12,11,12,12,0,0,0,0,0,0,0,0,0,12,0,0
0,0,0,0,0,0,16,0,16,0,0,0,0,11,14,11,0,0,0,0,0,0,0,0,0,0,11,0,0
0,0,0,0,0,0,0,16,0,0,0,0,0,12,11,12,12,0,0,0,0,0,0,0,0,0,12,0,0
0,0,0,0,0,0,0,0,0,0,0,0,0,0,0,0,11,0,0,0,0,0,0,0,0,0,11,0,0
0,0,0,0,0,0,0,0,0,0,0,0,0,0,0,0,0,3,0,0,0,0,0,0,0,3,0,0,0
0,0,0,0,0,0,0,0,0,0,0,0,0,0,0,0,0,0,3,0,0,0,0,0,3,0,0,0,0
0,0,0,0,0,0,0,0,0,0,0,0,0,0,0,0,0,0,0,11,12,11,12,11,0,0,0,0,0
0,0,0,0,0,0,0,0,0,0,0,0,0,0,0,0,0,0,0,0,0,0,0,0,0,0,0,0,0
0,0,0,0,0,0,0,0,0,0,0,0,0,0,0,0,0,0,0,0,0,0,0,0,0,0,0,0,0
endlayer

layer
0,0,0,0,0,0,0,0,0,0,0,0,0,0,0,0,0,0,0,0,0,0,0,0,0,0,0,0,0
0,0,0,0,0,0,0,0,0,0,0,0,0,0,0,0,0,0,0,0,0,0,0,0,0,0,0,0,0
0,0,0,0,0,0,0,0,0,0,0,0,0,0,0,0,0,0,0,11,12,11,12,11,0,0,0,0,0
0,0,0,0,0,0,0,0,0,0,0,0,0,0,0,0,0,0,3,0,0,0,0,0,3,0,0,0,0
0,0,0,0,0,0,0,0,0,0,0,0,0,0,0,0,0,3,0,0,0,0,0,0,0,3,0,0,0
0,0,0,0,0,0,0,0,0,0,0,0,0,0,0,0,11,0,0,0,0,0,0,0,0,0,11,0,0
0,0,0,0,0,0,0,0,0,0,0,0,0,12,11,12,12,0,0,0,0,0,0,0,0,0,12,0,0
0,0,0,0,0,0,0,16,0,0,0,0,0,11,14,11,0,0,0,0,0,0,0,0,0,0,11,0,0
0,0,0,0,0,0,0,0,0,0,0,0,0,12,11,12,12,0,0,0,0,0,0,0,0,0,12,0,0
0,0,0,0,0,0,0,0,0,0,0,0,0,0,0,0,11,0,0,0,0,0,0,0,0,0,11,0,0
0,0,0,0,0,0,0,0,0,0,0,0,0,0,0,0,0,3,0,0,0,0,0,0,0,3,0,0,0
0,0,0,0,0,0,0,0,0,0,0,0,0,0,0,0,0,0,3,0,0,0,0,0,3,0,0,0,0
0,0,0,0,0,0,0,0,0,0,0,0,0,0,0,0,0,0,0,11,12,11,12,11,0,0,0,0,0
0,0,0,0,0,0,0,0,0,0,0,0,0,0,0,0,0,0,0,0,0,0,0,0,0,0,0,0,0
0,0,0,0,0,0,0,0,0,0,0,0,0,0,0,0,0,0,0,0,0,0,0,0,0,0,0,0,0
endlayer

layer
0,0,0,0,0,0,0,0,0,0,0,0,0,0,0,0,0,0,0,0,0,0,0,0,0,0,0,0,0
0,0,0,0,0,0,0,0,0,0,0,0,0,0,0,0,0,0,0,0,0,0,0,0,0,0,0,0,0
0,0,0,0,0,0,0,0,0,0,0,0,0,0,0,0,0,0,0,11,12,11,12,11,0,0,0,0,0
0,0,0,0,0,0,0,0,0,0,0,0,0,0,0,0,0,0,3,0,0,0,0,0,3,0,0,0,0
0,0,0,0,0,0,0,0,0,0,0,0,0,0,0,0,0,3,0,0,0,0,0,0,0,3,0,0,0
0,0,0,0,0,0,0,0,0,0,0,0,0,0,0,0,11,0,0,0,0,0,0,0,0,0,11,0,0
0,0,0,0,0,0,0,0,0,0,0,0,0,12,11,12,12,0,0,0,0,0,0,0,0,0,12,0,0
0,0,0,0,0,0,0,16,0,0,0,0,0,11,14,11,0,0,0,0,0,0,0,0,0,0,11,0,0
0,0,0,0,0,0,0,0,0,0,0,0,0,12,11,12,12,0,0,0,0,0,0,0,0,0,12,0,0
0,0,0,0,0,0,0,0,0,0,0,0,0,0,0,0,11,0,0,0,0,0,0,0,0,0,11,0,0
0,0,0,0,0,0,0,0,0,0,0,0,0,0,0,0,0,3,0,0,0,0,0,0,0,3,0,0,0
0,0,0,0,0,0,0,0,0,0,0,0,0,0,0,0,0,0,3,0,0,0,0,0,3,0,0,0,0
0,0,0,0,0,0,0,0,0,0,0,0,0,0,0,0,0,0,0,11,12,11,12,11,0,0,0,0,0
0,0,0,0,0,0,0,0,0,0,0,0,0,0,0,0,0,0,0,0,0,0,0,0,0,0,0,0,0
0,0,0,0,0,0,0,0,0,0,0,0,0,0,0,0,0,0,0,0,0,0,0,0,0,0,0,0,0
endlayer

layer
0,0,0,0,0,0,0,0,0,0,0,0,0,0,0,0,0,0,0,0,0,0,0,0,0,0,0,0,0
0,0,0,0,0,0,0,0,0,0,0,0,0,0,0,0,0,0,0,0,0,0,0,0,0,0,0,0,0
0,0,0,0,0,0,0,0,0,0,0,0,0,0,0,0,0,0,0,11,12,11,12,11,0,0,0,0,0
0,0,0,0,0,0,0,0,0,0,0,0,0,0,0,0,0,0,3,0,0,0,0,0,3,0,0,0,0
0,0,0,0,0,0,0,0,0,0,0,0,0,0,0,0,0,3,0,0,0,0,0,0,0,3,0,0,0
0,0,0,0,0,0,0,0,0,0,0,0,0,0,0,0,11,0,0,0,0,0,0,0,0,0,11,0,0
0,0,0,0,0,0,0,0,0,0,0,0,0,12,11,12,12,0,0,0,0,0,0,0,0,0,12,0,0
0,0,0,0,0,0,0,16,0,0,0,0,0,11,14,11,0,0,0,0,0,0,0,0,0,0,11,0,0
0,0,0,0,0,0,0,0,0,0,0,0,0,12,11,12,12,0,0,0,0,0,0,0,0,0,12,0,0
0,0,0,0,0,0,0,0,0,0,0,0,0,0,0,0,11,0,0,0,0,0,0,0,0,0,11,0,0
0,0,0,0,0,0,0,0,0,0,0,0,0,0,0,0,0,3,0,0,0,0,0,0,0,3,0,0,0
0,0,0,0,0,0,0,0,0,0,0,0,0,0,0,0,0,0,3,0,0,0,0,0,3,0,0,0,0
0,0,0,0,0,0,0,0,0,0,0,0,0,0,0,0,0,0,0,11,12,11,12,11,0,0,0,0,0
0,0,0,0,0,0,0,0,0,0,0,0,0,0,0,0,0,0,0,0,0,0,0,0,0,0,0,0,0
0,0,0,0,0,0,0,0,0,0,0,0,0,0,0,0,0,0,0,0,0,0,0,0,0,0,0,0,0
endlayer

layer
0,0,0,0,0,0,0,0,0,0,0,0,0,0,0,0,0,0,0,0,0,0,0,0,0,0,0,0,0
0,0,0,0,0,0,0,0,0,0,0,0,0,0,0,0,0,0,0,0,0,0,0,0,0,0,0,0,0
0,0,0,0,0,0,0,0,0,0,0,0,0,0,0,0,0,0,0,3,3,3,3,3,0,0,0,0,0
0,0,0,0,0,0,0,0,0,0,0,0,0,0,0,0,0,0,3,4,4,4,4,4,3,0,0,0,0
0,0,0,0,0,0,0,0,0,0,0,0,0,0,0,0,0,3,4,4,4,4,4,4,4,3,0,0,0
0,0,0,0,0,0,0,0,0,0,0,0,0,0,0,0,3,4,4,4,4,4,4,4,4,4,3,0,0
0,0,0,0,0,0,0,0,0,0,0,0,0,3,3,3,3,4,4,4,4,4,4,4,4,4,3,0,0
0,0,0,0,0,0,0,0,0,0,0,0,0,3,14,4,4,4,4,4,4,4,4,4,4,4,3,0,0
0,0,0,0,0,0,0,0,0,0,0,0,0,3,3,3,3,4,4,4,4,4,4,4,4,4,3,0,0
0,0,0,0,0,0,0,0,0,0,0,0,0,0,0,0,3,4,4,4,4,4,4,4,4,4,3,0,0
0,0,0,0,0,0,0,0,0,0,0,0,0,0,0,0,0,3,4,4,4,4,4,4,4,3,0,0,0
0,0,0,0,0,0,0,0,0,0,0,0,0,0,0,0,0,0,3,4,4,4,4,4,3,0,0,0,0
0,0,0,0,0,0,0,0,0,0,0,0,0,0,0,0,0,0,0,3,3,3,3,3,0,0,0,0,0
0,0,0,0,0,0,0,0,0,0,0,0,0,0,0,0,0,0,0,0,0,0,0,0,0,0,0,0,0
0,0,0,0,0,0,0,0,0,0,0,0,0,0,0,0,0,0,0,0,0,0,0,0,0,0,0,0,0
endlayer

layer
0,0,0,0,0,0,0,0,0,0,0,0,0,0,0,0,0,0,0,0,0,0,0,0,0,0,0,0,0
0,0,0,0,0,0,0,0,0,0,0,0,0,0,0,0,0,0,0,0,0,0,0,0,0,0,0,0,0
0,0,0,0,0,0,0,0,0,0,0,0,0,0,0,0,0,0,0,11,12,11,12,11,0,0,0,0,0
0,0,0,0,0,0,0,0,0,0,0,0,0,0,0,0,0,0,3,10,6,6,10,0,3,0,0,0,0
0,0,0,0,0,0,0,0,0,0,0,0,0,0,0,0,0,3,0,10,6,6,10,0,8,3,0,0,0
0,0,0,0,0,0,0,0,0,0,0,0,0,0,0,0,11,0,0,0,0,0,0,0,0,0,11,0,0
0,0,0,0,0,0,0,0,0,0,0,0,0,12,11,12,12,0,0,0,0,0,0,0,0,6,12,0,0
0,0,0,0,0,0,0,0,0,0,0,0,0,11,14,0,0,0,0,0,0,0,0,9,9,7,11,0,0
0,0,0,0,0,0,0,0,0,0,0,0,0,12,11,12,12,0,0,0,0,0,0,9,9,7,12,0,0
0,0,0,0,0,0,0,0,0,0,0,0,0,0,0,0,11,0,0,0,0,0,0,0,0,6,11,0,0
0,0,0,0,0,0,0,0,0,0,0,0,0,0,0,0,0,3,0,0,0,0,0,0,8,3,0,0,0
0,0,0,0,0,0,0,0,0,0,0,0,0,0,0,0,0,0,3,0,0,0,0,0,3,0,0,0,0
0,0,0,0,0,0,0,0,0,0,0,0,0,0,0,0,0,0,0,11,12,11,12,11,0,0,0,0,0
0,0,0,0,0,0,0,0,0,0,0,0,0,0,0,0,0,0,0,0,0,0,0,0,0,0,0,0,0
0,0,0,0,0,0,0,0,0,0,0,0,0,0,0,0,0,0,0,0,0,0,0,0,0,0,0,0,0
endlayer

layer
0,0,0,0,0,0,0,0,0,0,0,0,0,0,0,0,0,0,0,0,0,0,0,0,0,0,0,0,0
0,0,0,0,0,0,0,0,0,0,0,0,0,0,0,0,0,0,0,0,0,0,0,0,0,0,0,0,0
0,0,0,0,0,0,0,0,0,0,0,0,0,0,0,0,0,0,0,11,12,11,12,11,0,0,0,0,0
0,0,0,0,0,0,0,0,0,0,0,0,0,0,0,0,0,0,3,0,0,0,0,0,3,0,0,0,0
0,0,0,0,0,0,0,0,0,0,0,0,0,0,0,0,0,3,0,0,0,0,0,0,0,3,0,0,0
0,0,0,0,0,0,0,0,0,0,0,0,0,0,0,0,11,0,0,0,0,0,0,0,0,0,11,0,0
0,0,0,0,0,0,0,0,0,0,0,0,0,12,11,12,12,0,0,0,0,0,0,0,0,13,12,0,0
0,0,0,0,0,0,0,0,0,0,0,0,0,11,14,0,0,0,0,0,0,0,0,0,0,0,11,0,0
0,0,0,0,0,0,0,0,0,0,0,0,0,12,11,12,12,0,0,0,0,0,0,0,0,0,12,0,0
0,0,0,0,0,0,0,0,0,0,0,0,0,0,0,0,11,0,0,0,0,0,0,0,0,0,11,0,0
0,0,0,0,0,0,0,0,0,0,0,0,0,0,0,0,0,3,0,0,0,0,0,0,0,3,0,0,0
0,0,0,0,0,0,0,0,0,0,0,0,0,0,0,0,0,0,3,0,0,0,0,0,3,0,0,0,0
0,0,0,0,0,0,0,0,0,0,0,0,0,0,0,0,0,0,0,11,12,11,12,11,0,0,0,0,0
0,0,0,0,0,0,0,0,0,0,0,0,0,0,0,0,0,0,0,0,0,0,0,0,0,0,0,0,0
0,0,0,0,0,0,0,0,0,0,0,0,0,0,0,0,0,0,0,0,0,0,0,0,0,0,0,0,0
endlayer

layer
0,0,0,0,0,0,0,0,0,0,0,0,0,0,0,0,0,0,0,0,0,0,0,0,0,0,0,0,0
0,0,0,0,0,0,0,0,0,0,0,0,0,0,0,0,0,0,0,0,0,0,0,0,0,0,0,0,0
0,0,0,0,0,0,0,0,0,0,0,0,0,0,0,0,0,0,0,11,12,11,12,11,0,0,0,0,0
0,0,0,0,0,0,0,0,0,0,0,0,0,0,0,0,0,0,3,0,0,0,0,0,3,0,0,0,0
0,0,0,0,0,0,0,0,0,0,0,0,0,0,0,0,0,3,0,0,0,0,0,0,0,3,0,0,0
0,0,0,0,0,0,0,0,0,0,0,0,0,0,0,0,11,0,0,0,0,0,0,0,0,0,11,0,0
0,0,0,0,0,0,0,0,0,0,0,0,0,12,11,12,12,0,0,0,0,0,0,0,0,0,12,0,0
0,0,0,0,0,0,0,0,0,0,0,0,0,11,0,11,0,0,0,0,0,0,0,0,0,0,11,0,0
0,0,0,0,0,0,0,0,0,0,0,0,0,12,11,12,12,0,0,0,0,0,0,0,0,0,12,0,0
0,0,0,0,0,0,0,0,0,0,0,0,0,0,0,0,11,0,0,0,0,0,0,0,0,0,11,0,0
0,0,0,0,0,0,0,0,0,0,0,0,0,0,0,0,0,3,0,0,0,0,0,0,0,3,0,0,0
0,0,0,0,0,0,0,0,0,0,0,0,0,0,0,0,0,0,3,0,0,0,0,0,3,0,0,0,0
0,0,0,0,0,0,0,0,0,0,0,0,0,0,0,0,0,0,0,11,12,11,12,11,0,0,0,0,0
0,0,0,0,0,0,0,0,0,0,0,0,0,0,0,0,0,0,0,0,0,0,0,0,0,0,0,0,0
0,0,0,0,0,0,0,0,0,0,0,0,0,0,0,0,0,0,0,0,0,0,0,0,0,0,0,0,0
endlayer

layer
0,0,0,0,0,0,0,0,0,0,0,0,0,0,0,0,0,0,0,0,0,0,0,0,0,0,0,0,0
0,0,0,0,0,0,0,0,0,0,0,0,0,0,0,0,0,0,0,0,0,0,0,0,0,0,0,0,0
0,0,0,0,0,0,0,0,0,0,0,0,0,0,0,0,0,0,0,11,12,11,12,11,0,0,0,0,0
0,0,0,0,0,0,0,0,0,0,0,0,0,0,0,0,0,0,3,0,0,0,0,0,3,0,0,0,0
0,0,0,0,0,0,0,0,0,0,0,0,0,0,0,0,0,3,0,0,0,0,0,0,0,3,0,0,0
0,0,0,0,0,0,0,0,0,0,0,0,0,0,0,0,11,0,0,0,0,0,0,0,0,0,11,0,0
0,0,0,0,0,0,0,0,0,0,0,0,0,12,11,12,12,0,0,0,0,0,0,0,0,0,12,0,0
0,0,0,0,0,0,0,0,0,0,0,0,0,11,0,11,0,0,0,0,0,0,0,0,0,0,11,0,0
0,0,0,0,0,0,0,0,0,0,0,0,0,12,11,12,12,0,0,0,0,0,0,0,0,0,12,0,0
0,0,0,0,0,0,0,0,0,0,0,0,0,0,0,0,11,0,0,0,0,0,0,0,0,0,11,0,0
0,0,0,0,0,0,0,0,0,0,0,0,0,0,0,0,0,3,0,0,0,0,0,0,0,3,0,0,0
0,0,0,0,0,0,0,0,0,0,0,0,0,0,0,0,0,0,3,0,0,0,0,0,3,0,0,0,0
0,0,0,0,0,0,0,0,0,0,0,0,0,0,0,0,0,0,0,11,12,11,12,11,0,0,0,0,0
0,0,0,0,0,0,0,0,0,0,0,0,0,0,0,0,0,0,0,0,0,0,0,0,0,0,0,0,0
0,0,0,0,0,0,0,0,0,0,0,0,0,0,0,0,0,0,0,0,0,0,0,0,0,0,0,0,0
endlayer

layer
0,0,0,0,0,0,0,0,0,0,0,0,0,0,0,0,0,0,0,0,0,0,0,0,0,0,0,0,0
0,0,0,0,0,0,0,0,0,0,0,0,0,0,0,0,0,0,0,0,0,0,0,0,0,0,0,0,0
0,0,0,0,0,0,0,0,0,0,0,0,0,0,0,0,0,0,0,11,12,11,12,11,0,0,0,0,0
0,0,0,0,0,0,0,0,0,0,0,0,0,0,0,0,0,0,3,0,0,0,0,0,3,0,0,0,0
0,0,0,0,0,0,0,0,0,0,0,0,0,0,0,0,0,3,0,0,0,0,0,0,0,3,0,0,0
0,0,0,0,0,0,0,0,0,0,0,0,0,0,0,0,11,0,0,0,0,0,0,0,0,0,11,0,0
0,0,0,0,0,0,0,0,0,0,0,0,0,12,11,12,12,0,0,0,0,0,0,0,0,0,12,0,0
0,0,0,0,0,0,0,0,0,0,0,0,0,11,0,11,0,0,0,0,0,0,0,0,0,0,11,0,0
0,0,0,0,0,0,0,0,0,0,0,0,0,12,11,12,12,0,0,0,0,0,0,0,0,0,12,0,0
0,0,0,0,0,0,0,0,0,0,0,0,0,0,0,0,11,0,0,0,0,0,0,0,0,0,11,0,0
0,0,0,0,0,0,0,0,0,0,0,0,0,0,0,0,0,3,0,0,0,0,0,0,0,3,0,0,0
0,0,0,0,0,0,0,0,0,0,0,0,0,0,0,0,0,0,3,0,0,0,0,0,3,0,0,0,0
0,0,0,0,0,0,0,0,0,0,0,0,0,0,0,0,0,0,0,11,12,11,12,11,0,0,0,0,0
0,0,0,0,0,0,0,0,0,0,0,0,0,0,0,0,0,0,0,0,0,0,0,0,0,0,0,0,0
0,0,0,0,0,0,0,0,0,0,0,0,0,0,0,0,0,0,0,0,0,0,0,0,0,0,0,0,0
endlayer

layer
0,0,0,0,0,0,0,0,0,0,0,0,0,0,0,0,0,0,0,0,0,0,0,0,0,0,0,0,0
0,0,0,0,0,0,0,0,0,0,0,0,0,0,0,0,0,0,0,0,0,0,0,0,0,0,0,0,0
0,0,0,0,0,0,0,0,0,0,0,0,0,0,0,0,0,0,0,11,12,11,12,11,0,0,0,0,0
0,0,0,0,0,0,0,0,0,0,0,0,0,0,0,0,0,0,3,0,0,0,0,0,3,0,0,0,0
0,0,0,0,0,0,0,0,0,0,0,0,0,0,0,0,0,3,0,0,0,0,0,0,0,3,0,0,0
0,0,0,0,0,0,0,0,0,0,0,0,0,0,0,0,11,0,0,0,0,0,0,0,0,0,11,0,0
0,0,0,0,0,0,0,0,0,0,0,0,0,12,11,12,12,0,0,0,0,0,0,0,0,0,12,0,0
0,0,0,0,0,0,0,0,0,0,0,0,0,11,0,11,0,0,0,0,0,0,0,0,0,0,11,0,0
0,0,0,0,0,0,0,0,0,0,0,0,0,12,11,12,12,0,0,0,0,0,0,0,0,0,12,0,0
0,0,0,0,0,0,0,0,0,0,0,0,0,0,0,0,11,0,0,0,0,0,0,0,0,0,11,0,0
0,0,0,0,0,0,0,0,0,0,0,0,0,0,0,0,0,3,0,0,0,0,0,0,0,3,0,0,0
0,0,0,0,0,0,0,0,0,0,0,0,0,0,0,0,0,0,3,0,0,0,0,0,3,0,0,0,0
0,0,0,0,0,0,0,0,0,0,0,0,0,0,0,0,0,0,0,11,12,11,12,11,0,0,0,0,0
0,0,0,0,0,0,0,0,0,0,0,0,0,0,0,0,0,0,0,0,0,0,0,0,0,0,0,0,0
0,0,0,0,0,0,0,0,0,0,0,0,0,0,0,0,0,0,0,0,0,0,0,0,0,0,0,0,0
endlayer

layer
0,0,0,0,0,0,0,0,0,0,0,0,0,0,0,0,0,0,0,0,0,0,0,0,0,0,0,0,0
0,0,0,0,0,0,0,0,0,0,0,0,0,0,0,0,0,0,0,0,0,0,0,0,0,0,0,0,0
0,0,0,0,0,0,0,0,0,0,0,0,0,0,0,0,0,0,0,3,3,3,3,3,0,0,0,0,0
0,0,0,0,0,0,0,0,0,0,0,0,0,0,0,0,0,0,3,16,16,16,16,16,3,0,0,0,0
0,0,0,0,0,0,0,0,0,0,0,0,0,0,0,0,0,3,16,0,0,0,0,0,16,3,0,0,0
0,0,0,0,0,0,0,0,0,0,0,0,0,0,0,0,3,16,0,0,0,0,0,0,0,16,3,0,0
0,0,0,0,0,0,0,0,0,0,0,0,0,3,3,3,3,16,0,0,0,0,0,0,0,16,3,0,0
0,0,0,0,0,0,0,0,0,0,0,0,0,3,16,16,16,16,0,0,0,0,0,0,0,16,3,0,0
0,0,0,0,0,0,0,0,0,0,0,0,0,3,3,3,3,16,0,0,0,0,0,0,0,16,3,0,0
0,0,0,0,0,0,0,0,0,0,0,0,0,0,0,0,3,16,0,0,0,0,0,0,0,16,3,0,0
0,0,0,0,0,0,0,0,0,0,0,0,0,0,0,0,0,3,16,0,0,0,0,0,16,3,0,0,0
0,0,0,0,0,0,0,0,0,0,0,0,0,0,0,0,0,0,3,16,16,16,16,16,3,0,0,0,0
0,0,0,0,0,0,0,0,0,0,0,0,0,0,0,0,0,0,0,3,3,3,3,3,0,0,0,0,0
0,0,0,0,0,0,0,0,0,0,0,0,0,0,0,0,0,0,0,0,0,0,0,0,0,0,0,0,0
0,0,0,0,0,0,0,0,0,0,0,0,0,0,0,0,0,0,0,0,0,0,0,0,0,0,0,0,0
endlayer

layer
0,0,0,0,0,0,0,0,0,0,0,0,0,0,0,0,0,0,0,0,0,0,0,0,0,0,0,0,0
0,0,0,0,0,0,0,0,0,0,0,0,0,0,0,0,0,0,0,0,0,0,0,0,0,0,0,0,0
0,0,0,0,0,0,0,0,0,0,0,0,0,0,0,0,0,0,0,0,0,0,0,0,0,0,0,0,0
0,0,0,0,0,0,0,0,0,0,0,0,0,0,0,0,0,0,0,0,0,0,0,0,0,0,0,0,0
0,0,0,0,0,0,0,0,0,0,0,0,0,0,0,0,0,0,0,16,16,16,16,16,0,0,0,0,0
0,0,0,0,0,0,0,0,0,0,0,0,0,0,0,0,0,0,16,16,0,0,0,16,16,0,0,0,0
0,0,0,0,0,0,0,0,0,0,0,0,0,0,0,0,0,0,16,0,0,0,0,0,16,0,0,0,0
0,0,0,0,0,0,0,0,0,0,0,0,0,0,0,0,0,0,16,0,0,0,0,0,16,0,0,0,0
0,0,0,0,0,0,0,0,0,0,0,0,0,0,0,0,0,0,16,0,0,0,0,0,16,0,0,0,0
0,0,0,0,0,0,0,0,0,0,0,0,0,0,0,0,0,0,16,16,0,0,0,16,16,0,0,0,0
0,0,0,0,0,0,0,0,0,0,0,0,0,0,0,0,0,0,0,16,16,16,16,16,0,0,0,0,0
0,0,0,0,0,0,0,0,0,0,0,0,0,0,0,0,0,0,0,0,0,0,0,0,0,0,0,0,0
0,0,0,0,0,0,0,0,0,0,0,0,0,0,0,0,0,0,0,0,0,0,0,0,0,0,0,0,0
0,0,0,0,0,0,0,0,0,0,0,0,0,0,0,0,0,0,0,0,0,0,0,0,0,0,0,0,0
0,0,0,0,0,0,0,0,0,0,0,0,0,0,0,0,0,0,0,0,0,0,0,0,0,0,0,0,0
endlayer

layer
0,0,0,0,0,0,0,0,0,0,0,0,0,0,0,0,0,0,0,0,0,0,0,0,0,0,0,0,0
0,0,0,0,0,0,0,0,0,0,0,0,0,0,0,0,0,0,0,0,0,0,0,0,0,0,0,0,0
0,0,0,0,0,0,0,0,0,0,0,0,0,0,0,0,0,0,0,0,0,0,0,0,0,0,0,0,0
0,0,0,0,0,0,0,0,0,0,0,0,0,0,0,0,0,0,0,0,0,0,0,0,0,0,0,0,0
0,0,0,0,0,0,0,0,0,0,0,0,0,0,0,0,0,0,0,0,0,0,0,0,0,0,0,0,0
0,0,0,0,0,0,0,0,0,0,0,0,0,0,0,0,0,0,0,0,16,16,16,0,0,0,0,0,0
0,0,0,0,0,0,0,0,0,0,0,0,0,0,0,0,0,0,0,16,16,0,16,16,0,0,0,0,0
0,0,0,0,0,0,0,0,0,0,0,0,0,0,0,0,0,0,0,16,0,0,0,16,0,0,0,0,0
0,0,0,0,0,0,0,0,0,0,0,0,0,0,0,0,0,0,0,16,16,0,16,16,0,0,0,0,0
0,0,0,0,0,0,0,0,0,0,0,0,0,0,0,0,0,0,0,0,16,16,16,0,0,0,0,0,0
0,0,0,0,0,0,0,0,0,0,0,0,0,0,0,0,0,0,0,0,0,0,0,0,0,0,0,0,0
0,0,0,0,0,0,0,0,0,0,0,0,0,0,0,0,0,0,0,0,0,0,0,0,0,0,0,0,0
0,0,0,0,0,0,0,0,0,0,0,0,0,0,0,0,0,0,0,0,0,0,0,0,0,0,0,0,0
0,0,0,0,0,0,0,0,0,0,0,0,0,0,0,0,0,0,0,0,0,0,0,0,0,0,0,0,0
0,0,0,0,0,0,0,0,0,0,0,0,0,0,0,0,0,0,0,0,0,0,0,0,0,0,0,0,0
endlayer

layer
0,0,0,0,0,0,0,0,0,0,0,0,0,0,0,0,0,0,0,0,0,0,0,0,0,0,0,0,0
0,0,0,0,0,0,0,0,0,0,0,0,0,0,0,0,0,0,0,0,0,0,0,0,0,0,0,0,0
0,0,0,0,0,0,0,0,0,0,0,0,0,0,0,0,0,0,0,0,0,0,0,0,0,0,0,0,0
0,0,0,0,0,0,0,0,0,0,0,0,0,0,0,0,0,0,0,0,0,0,0,0,0,0,0,0,0
0,0,0,0,0,0,0,0,0,0,0,0,0,0,0,0,0,0,0,0,0,0,0,0,0,0,0,0,0
0,0,0,0,0,0,0,0,0,0,0,0,0,0,0,0,0,0,0,0,0,0,0,0,0,0,0,0,0
0,0,0,0,0,0,0,0,0,0,0,0,0,0,0,0,0,0,0,0,0,16,0,0,0,0,0,0,0
0,0,0,0,0,0,0,0,0,0,0,0,0,0,0,0,0,0,0,0,16,0,16,0,0,0,0,0,0
0,0,0,0,0,0,0,0,0,0,0,0,0,0,0,0,0,0,0,0,0,16,0,0,0,0,0,0,0
0,0,0,0,0,0,0,0,0,0,0,0,0,0,0,0,0,0,0,0,0,0,0,0,0,0,0,0,0
0,0,0,0,0,0,0,0,0,0,0,0,0,0,0,0,0,0,0,0,0,0,0,0,0,0,0,0,0
0,0,0,0,0,0,0,0,0,0,0,0,0,0,0,0,0,0,0,0,0,0,0,0,0,0,0,0,0
0,0,0,0,0,0,0,0,0,0,0,0,0,0,0,0,0,0,0,0,0,0,0,0,0,0,0,0,0
0,0,0,0,0,0,0,0,0,0,0,0,0,0,0,0,0,0,0,0,0,0,0,0,0,0,0,0,0
0,0,0,0,0,0,0,0,0,0,0,0,0,0,0,0,0,0,0,0,0,0,0,0,0,0,0,0,0
endlayer

layer
0,0,0,0,0,0,0,0,0,0,0,0,0,0,0,0,0,0,0,0,0,0,0,0,0,0,0,0,0
0,0,0,0,0,0,0,0,0,0,0,0,0,0,0,0,0,0,0,0,0,0,0,0,0,0,0,0,0
0,0,0,0,0,0,0,0,0,0,0,0,0,0,0,0,0,0,0,0,0,0,0,0,0,0,0,0,0
0,0,0,0,0,0,0,0,0,0,0,0,0,0,0,0,0,0,0,0,0,0,0,0,0,0,0,0,0
0,0,0,0,0,0,0,0,0,0,0,0,0,0,0,0,0,0,0,0,0,0,0,0,0,0,0,0,0
0,0,0,0,0,0,0,0,0,0,0,0,0,0,0,0,0,0,0,0,0,0,0,0,0,0,0,0,0
0,0,0,0,0,0,0,0,0,0,0,0,0,0,0,0,0,0,0,0,0,0,0,0,0,0,0,0,0
0,0,0,0,0,0,0,0,0,0,0,0,0,0,0,0,0,0,0,0,0,16,0,0,0,0,0,0,0
0,0,0,0,0,0,0,0,0,0,0,0,0,0,0,0,0,0,0,0,0,0,0,0,0,0,0,0,0
0,0,0,0,0,0,0,0,0,0,0,0,0,0,0,0,0,0,0,0,0,0,0,0,0,0,0,0,0
0,0,0,0,0,0,0,0,0,0,0,0,0,0,0,0,0,0,0,0,0,0,0,0,0,0,0,0,0
0,0,0,0,0,0,0,0,0,0,0,0,0,0,0,0,0,0,0,0,0,0,0,0,0,0,0,0,0
0,0,0,0,0,0,0,0,0,0,0,0,0,0,0,0,0,0,0,0,0,0,0,0,0,0,0,0,0
0,0,0,0,0,0,0,0,0,0,0,0,0,0,0,0,0,0,0,0,0,0,0,0,0,0,0,0,0
0,0,0,0,0,0,0,0,0,0,0,0,0,0,0,0,0,0,0,0,0,0,0,0,0,0,0,0,0
endlayer

layer
0,0,0,0,0,0,0,0,0,0,0,0,0,0,0,0,0,0,0,0,0,0,0,0,0,0,0,0,0
0,0,0,0,0,0,0,0,0,0,0,0,0,0,0,0,0,0,0,0,0,0,0,0,0,0,0,0,0
0,0,0,0,0,0,0,0,0,0,0,0,0,0,0,0,0,0,0,0,0,0,0,0,0,0,0,0,0
0,0,0,0,0,0,0,0,0,0,0,0,0,0,0,0,0,0,0,0,0,0,0,0,0,0,0,0,0
0,0,0,0,0,0,0,0,0,0,0,0,0,0,0,0,0,0,0,0,0,0,0,0,0,0,0,0,0
0,0,0,0,0,0,0,0,0,0,0,0,0,0,0,0,0,0,0,0,0,0,0,0,0,0,0,0,0
0,0,0,0,0,0,0,0,0,0,0,0,0,0,0,0,0,0,0,0,0,0,0,0,0,0,0,0,0
0,0,0,0,0,0,0,0,0,0,0,0,0,0,0,0,0,0,0,0,0,16,0,0,0,0,0,0,0
0,0,0,0,0,0,0,0,0,0,0,0,0,0,0,0,0,0,0,0,0,0,0,0,0,0,0,0,0
0,0,0,0,0,0,0,0,0,0,0,0,0,0,0,0,0,0,0,0,0,0,0,0,0,0,0,0,0
0,0,0,0,0,0,0,0,0,0,0,0,0,0,0,0,0,0,0,0,0,0,0,0,0,0,0,0,0
0,0,0,0,0,0,0,0,0,0,0,0,0,0,0,0,0,0,0,0,0,0,0,0,0,0,0,0,0
0,0,0,0,0,0,0,0,0,0,0,0,0,0,0,0,0,0,0,0,0,0,0,0,0,0,0,0,0
0,0,0,0,0,0,0,0,0,0,0,0,0,0,0,0,0,0,0,0,0,0,0,0,0,0,0,0,0
0,0,0,0,0,0,0,0,0,0,0,0,0,0,0,0,0,0,0,0,0,0,0,0,0,0,0,0,0
endlayer

layer
0,0,0,0,0,0,0,0,0,0,0,0,0,0,0,0,0,0,0,0,0,0,0,0,0,0,0,0,0
0,0,0,0,0,0,0,0,0,0,0,0,0,0,0,0,0,0,0,0,0,0,0,0,0,0,0,0,0
0,0,0,0,0,0,0,0,0,0,0,0,0,0,0,0,0,0,0,0,0,0,0,0,0,0,0,0,0
0,0,0,0,0,0,0,0,0,0,0,0,0,0,0,0,0,0,0,0,0,0,0,0,0,0,0,0,0
0,0,0,0,0,0,0,0,0,0,0,0,0,0,0,0,0,0,0,0,0,0,0,0,0,0,0,0,0
0,0,0,0,0,0,0,0,0,0,0,0,0,0,0,0,0,0,0,0,0,0,0,0,0,0,0,0,0
0,0,0,0,0,0,0,0,0,0,0,0,0,0,0,0,0,0,0,0,0,0,0,0,0,0,0,0,0
0,0,0,0,0,0,0,0,0,0,0,0,0,0,0,0,0,0,0,0,0,16,0,0,0,0,0,0,0
0,0,0,0,0,0,0,0,0,0,0,0,0,0,0,0,0,0,0,0,0,0,0,0,0,0,0,0,0
0,0,0,0,0,0,0,0,0,0,0,0,0,0,0,0,0,0,0,0,0,0,0,0,0,0,0,0,0
0,0,0,0,0,0,0,0,0,0,0,0,0,0,0,0,0,0,0,0,0,0,0,0,0,0,0,0,0
0,0,0,0,0,0,0,0,0,0,0,0,0,0,0,0,0,0,0,0,0,0,0,0,0,0,0,0,0
0,0,0,0,0,0,0,0,0,0,0,0,0,0,0,0,0,0,0,0,0,0,0,0,0,0,0,0,0
0,0,0,0,0,0,0,0,0,0,0,0,0,0,0,0,0,0,0,0,0,0,0,0,0,0,0,0,0
0,0,0,0,0,0,0,0,0,0,0,0,0,0,0,0,0,0,0,0,0,0,0,0,0,0,0,0,0
endlayer

