weight=25
embed_into_distance=1
dimensions=51,15,29
max_cut_in=0


rule1=0,100,3134-10
rule2=2,100,2843-4
rule3=0,100,2843-14,2843-14,2843-14,2843-14,2843
rule4=0,95,622
rule5=2,66,3225-3
rule6=0,95,2835-2,2835-2,2835-2,2835-2,2835-2,2835-2,2835-2,2835-1,2835-1,2835-0
rule7=0,100,2843-4
rule8=0,66,623
rule9=0,20,308,308,308,308,308,308,313,313,314,327
rule10=0,100,2781-4,2781-4,2781-4,2781-4,2781-4,2781-4,2781-4,2781-4,2781-4,2781-8
rule11=0,15,311
rule12= 0,75,327

layer
1,1,1,1,1,1,1,1,1,1,1,1,1,1,1,1,1,1,1,1,1,1,1,1,1,1,1,1,1
1,1,1,1,1,1,1,1,1,1,1,1,1,1,1,1,1,1,1,1,1,1,1,1,1,1,1,1,1
1,1,1,1,1,1,1,1,1,1,1,1,1,1,1,1,1,1,1,1,1,1,1,1,1,1,1,1,1
1,1,1,1,1,2,2,2,2,2,1,1,1,1,1,1,1,1,1,2,2,2,2,2,1,1,1,1,1
1,1,1,1,2,2,2,2,2,2,2,1,1,1,1,1,1,1,2,2,2,2,2,2,2,1,1,1,1
1,1,1,2,2,2,2,2,2,2,2,2,1,1,1,1,1,2,2,2,2,2,2,2,2,2,1,1,1
1,1,1,2,2,2,2,2,2,2,2,2,2,1,2,1,2,2,2,2,2,2,2,2,2,2,1,1,1
1,1,1,2,2,2,2,2,2,2,2,2,2,2,4,2,2,2,2,2,2,2,2,2,2,2,1,1,1
1,1,1,2,2,2,2,2,2,2,2,2,2,1,1,1,2,2,2,2,2,2,2,2,2,2,1,1,1
1,1,1,2,2,2,2,2,2,2,2,2,1,1,1,1,1,2,2,2,2,2,2,2,2,2,1,1,1
1,1,1,1,2,2,2,2,2,2,2,1,1,1,1,1,1,1,2,2,2,2,2,2,2,1,1,1,1
1,1,1,1,1,2,2,2,2,2,1,1,1,1,1,1,1,1,1,2,2,2,2,2,1,1,1,1,1
1,1,1,1,1,1,1,1,1,1,1,1,1,1,1,1,1,1,1,1,1,1,1,1,1,1,1,1,1
1,1,1,1,1,1,1,1,1,1,1,1,1,1,1,1,1,1,1,1,1,1,1,1,1,1,1,1,1
1,1,1,1,1,1,1,1,1,1,1,1,1,1,1,1,1,1,1,1,1,1,1,1,1,1,1,1,1
endlayer

layer
0,0,0,0,0,0,0,0,0,0,0,0,0,0,0,0,0,0,0,0,0,0,0,0,0,0,0,0,0
0,0,0,0,0,0,0,0,0,0,0,0,0,0,0,0,0,0,0,0,0,0,0,0,0,0,0,0,0
0,0,0,0,0,3,3,3,3,3,0,0,0,0,0,0,0,0,0,3,3,3,3,3,0,0,0,0,0
0,0,0,0,3,0,0,0,0,0,3,0,0,0,0,0,0,0,3,0,0,0,0,0,3,0,0,0,0
0,0,0,3,0,0,0,0,0,0,0,3,0,0,0,0,0,3,0,0,0,0,0,0,0,3,0,0,0
0,0,3,0,0,0,0,0,0,0,0,0,3,0,0,0,3,0,0,0,0,0,0,0,0,0,3,0,0
0,0,3,0,0,0,0,0,0,0,0,0,0,3,0,3,0,0,0,0,0,0,0,0,0,0,3,0,0
0,0,3,0,0,0,0,9,0,0,0,0,0,0,8,0,0,0,0,0,0,9,0,0,0,0,3,0,0
0,0,3,0,0,0,0,0,0,0,0,0,0,3,3,3,0,0,0,0,0,0,0,0,0,0,3,0,0
0,0,3,0,0,0,0,0,0,0,0,0,3,0,0,0,3,0,0,0,0,0,0,0,0,0,3,0,0
0,0,0,3,0,0,0,0,0,0,0,3,0,0,0,0,0,3,0,0,0,0,0,0,0,3,0,0,0
0,0,0,0,3,0,0,0,0,0,3,0,0,0,0,0,0,0,3,0,0,0,0,0,3,0,0,0,0
0,0,0,0,0,3,3,3,3,3,0,0,0,0,0,0,0,0,0,3,3,3,3,3,0,0,0,0,0
0,0,0,0,0,0,0,0,0,0,0,0,0,0,0,0,0,0,0,0,0,0,0,0,0,0,0,0,0
0,0,0,0,0,0,0,0,0,0,0,0,0,0,0,0,0,0,0,0,0,0,0,0,0,0,0,0,0
endlayer

layer
0,0,0,0,0,0,0,0,0,0,0,0,0,0,0,0,0,0,0,0,0,0,0,0,0,0,0,0,0
0,0,0,0,0,0,0,0,0,0,0,0,0,0,0,0,0,0,0,0,0,0,0,0,0,0,0,0,0
0,0,0,0,0,5,6,5,6,5,0,0,0,0,0,0,0,0,0,5,6,5,6,5,0,0,0,0,0
0,0,0,0,3,0,0,0,0,0,3,0,0,0,0,0,0,0,3,0,0,0,0,0,3,0,0,0,0
0,0,0,3,0,0,0,0,0,0,0,3,0,0,0,0,0,3,0,0,0,0,0,0,0,3,0,0,0
0,0,5,0,0,0,0,0,0,0,0,0,5,0,0,0,5,0,0,0,0,0,0,0,0,0,5,0,0
0,0,6,0,0,0,0,0,0,0,0,0,0,6,0,6,0,0,0,0,0,0,0,0,0,0,6,0,0
0,0,5,0,0,0,0,11,0,0,0,0,0,0,8,0,0,0,0,0,0,11,0,0,0,0,5,0,0
0,0,6,0,0,0,0,0,0,0,0,0,0,6,5,6,0,0,0,0,0,0,0,0,0,0,6,0,0
0,0,5,0,0,0,0,0,0,0,0,0,5,0,0,0,5,0,0,0,0,0,0,0,0,0,5,0,0
0,0,0,3,0,0,0,0,0,0,0,3,0,0,0,0,0,3,0,0,0,0,0,0,0,3,0,0,0
0,0,0,0,3,0,0,0,0,0,3,0,0,0,0,0,0,0,3,0,0,0,0,0,3,0,0,0,0
0,0,0,0,0,5,6,5,6,5,0,0,0,0,0,0,0,0,0,5,6,5,6,5,0,0,0,0,0
0,0,0,0,0,0,0,0,0,0,0,0,0,0,0,0,0,0,0,0,0,0,0,0,0,0,0,0,0
0,0,0,0,0,0,0,0,0,0,0,0,0,0,0,0,0,0,0,0,0,0,0,0,0,0,0,0,0
endlayer

layer
0,0,0,0,0,0,0,0,0,0,0,0,0,0,0,0,0,0,0,0,0,0,0,0,0,0,0,0,0
0,0,0,0,0,0,0,0,0,0,0,0,0,0,0,0,0,0,0,0,0,0,0,0,0,0,0,0,0
0,0,0,0,0,5,6,5,6,5,0,0,0,0,0,0,0,0,0,5,6,5,6,5,0,0,0,0,0
0,0,0,0,3,0,0,0,0,0,3,0,0,0,0,0,0,0,3,0,0,0,0,0,3,0,0,0,0
0,0,0,3,0,0,0,0,0,0,0,3,0,0,0,0,0,3,0,0,0,0,0,0,0,3,0,0,0
0,0,5,0,0,0,0,0,0,0,0,0,5,0,0,0,5,0,0,0,0,0,0,0,0,0,5,0,0
0,0,6,0,0,0,0,0,0,0,0,0,0,6,0,6,0,0,0,0,0,0,0,0,0,0,6,0,0
0,0,5,0,0,0,0,0,0,0,0,0,0,0,8,0,0,0,0,0,0,0,0,0,0,0,5,0,0
0,0,6,0,0,0,0,0,0,0,0,0,0,6,5,6,0,0,0,0,0,0,0,0,0,0,6,0,0
0,0,5,0,0,0,0,0,0,0,0,0,5,0,0,0,5,0,0,0,0,0,0,0,0,0,5,0,0
0,0,0,3,0,0,0,0,0,0,0,3,0,0,0,0,0,3,0,0,0,0,0,0,0,3,0,0,0
0,0,0,0,3,0,0,0,0,0,3,0,0,0,0,0,0,0,3,0,0,0,0,0,3,0,0,0,0
0,0,0,0,0,5,6,5,6,5,0,0,0,0,0,0,0,0,0,5,6,5,6,5,0,0,0,0,0
0,0,0,0,0,0,0,0,0,0,0,0,0,0,0,0,0,0,0,0,0,0,0,0,0,0,0,0,0
0,0,0,0,0,0,0,0,0,0,0,0,0,0,0,0,0,0,0,0,0,0,0,0,0,0,0,0,0
endlayer

layer
0,0,0,0,0,0,0,0,0,0,0,0,0,0,0,0,0,0,0,0,0,0,0,0,0,0,0,0,0
0,0,0,0,0,0,0,0,0,0,0,0,0,0,0,0,0,0,0,0,0,0,0,0,0,0,0,0,0
0,0,0,0,0,5,6,5,6,5,0,0,0,0,0,0,0,0,0,5,6,5,6,5,0,0,0,0,0
0,0,0,0,3,0,0,0,0,0,3,0,0,0,0,0,0,0,3,0,0,0,0,0,3,0,0,0,0
0,0,0,3,0,0,0,0,0,0,0,3,0,0,0,0,0,3,0,0,0,0,0,0,0,3,0,0,0
0,0,5,0,0,0,0,0,0,0,0,0,5,0,0,0,5,0,0,0,0,0,0,0,0,0,5,0,0
0,0,6,0,0,0,0,0,0,0,0,0,0,6,5,6,0,0,0,0,0,0,0,0,0,0,6,0,0
0,0,5,0,0,0,0,0,0,0,0,0,0,0,8,0,0,0,0,0,0,0,0,0,0,0,5,0,0
0,0,6,0,0,0,0,0,0,0,0,0,0,6,5,6,0,0,0,0,0,0,0,0,0,0,6,0,0
0,0,5,0,0,0,0,0,0,0,0,0,5,0,0,0,5,0,0,0,0,0,0,0,0,0,5,0,0
0,0,0,3,0,0,0,0,0,0,0,3,0,0,0,0,0,3,0,0,0,0,0,0,0,3,0,0,0
0,0,0,0,3,0,0,0,0,0,3,0,0,0,0,0,0,0,3,0,0,0,0,0,3,0,0,0,0
0,0,0,0,0,5,6,5,6,5,0,0,0,0,0,0,0,0,0,5,6,5,6,5,0,0,0,0,0
0,0,0,0,0,0,0,0,0,0,0,0,0,0,0,0,0,0,0,0,0,0,0,0,0,0,0,0,0
0,0,0,0,0,0,0,0,0,0,0,0,0,0,0,0,0,0,0,0,0,0,0,0,0,0,0,0,0
endlayer

layer
0,0,0,0,0,0,0,0,0,0,0,0,0,0,0,0,0,0,0,0,0,0,0,0,0,0,0,0,0
0,0,0,0,0,0,0,0,0,0,0,0,0,0,0,0,0,0,0,0,0,0,0,0,0,0,0,0,0
0,0,0,0,0,5,6,5,6,5,0,0,0,0,0,0,0,0,0,5,6,5,6,5,0,0,0,0,0
0,0,0,0,3,0,0,0,0,0,3,0,0,0,0,0,0,0,3,0,0,0,0,0,3,0,0,0,0
0,0,0,3,0,0,0,0,0,0,0,3,0,0,0,0,0,3,0,0,0,0,0,0,0,3,0,0,0
0,0,5,0,0,0,0,0,0,0,0,0,5,0,0,0,5,0,0,0,0,0,0,0,0,0,5,0,0
0,0,6,0,0,0,0,0,0,0,0,0,0,6,5,6,0,0,0,0,0,0,0,0,0,0,6,0,0
0,0,5,0,0,0,0,0,0,0,0,0,0,0,8,0,0,0,0,0,0,0,0,0,0,0,5,0,0
0,0,6,0,0,0,0,0,0,0,0,0,0,6,5,6,0,0,0,0,0,0,0,0,0,0,6,0,0
0,0,5,0,0,0,0,0,0,0,0,0,5,0,0,0,5,0,0,0,0,0,0,0,0,0,5,0,0
0,0,0,3,0,0,0,0,0,0,0,3,0,0,0,0,0,3,0,0,0,0,0,0,0,3,0,0,0
0,0,0,0,3,0,0,0,0,0,3,0,0,0,0,0,0,0,3,0,0,0,0,0,3,0,0,0,0
0,0,0,0,0,5,6,5,6,5,0,0,0,0,0,0,0,0,0,5,6,5,6,5,0,0,0,0,0
0,0,0,0,0,0,0,0,0,0,0,0,0,0,0,0,0,0,0,0,0,0,0,0,0,0,0,0,0
0,0,0,0,0,0,0,0,0,0,0,0,0,0,0,0,0,0,0,0,0,0,0,0,0,0,0,0,0
endlayer

layer
0,0,0,0,0,0,0,0,0,0,0,0,0,0,0,0,0,0,0,0,0,0,0,0,0,0,0,0,0
0,0,0,0,0,0,0,0,0,0,0,0,0,0,0,0,0,0,0,0,0,0,0,0,0,0,0,0,0
0,0,0,0,0,5,6,5,6,5,0,0,0,0,0,0,0,0,0,5,6,5,6,5,0,0,0,0,0
0,0,0,0,3,0,0,0,0,0,3,0,0,0,0,0,0,0,3,0,0,0,0,0,3,0,0,0,0
0,0,0,3,0,0,0,0,0,0,0,3,0,0,0,0,0,3,0,0,0,0,0,0,0,3,0,0,0
0,0,5,0,0,0,0,0,0,0,0,0,5,0,0,0,5,0,0,0,0,0,0,0,0,0,5,0,0
0,0,6,0,0,0,0,0,0,0,0,0,0,6,5,6,0,0,0,0,0,0,0,0,0,0,6,0,0
0,0,5,0,0,0,0,0,0,0,0,0,0,0,8,0,0,0,0,0,0,0,0,0,0,0,5,0,0
0,0,6,0,0,0,0,0,0,0,0,0,0,6,5,6,0,0,0,0,0,0,0,0,0,0,6,0,0
0,0,5,0,0,0,0,0,0,0,0,0,5,0,0,0,5,0,0,0,0,0,0,0,0,0,5,0,0
0,0,0,3,0,0,0,0,0,0,0,3,0,0,0,0,0,3,0,0,0,0,0,0,0,3,0,0,0
0,0,0,0,3,0,0,0,0,0,3,0,0,0,0,0,0,0,3,0,0,0,0,0,3,0,0,0,0
0,0,0,0,0,5,6,5,6,5,0,0,0,0,0,0,0,0,0,5,6,5,6,5,0,0,0,0,0
0,0,0,0,0,0,0,0,0,0,0,0,0,0,0,0,0,0,0,0,0,0,0,0,0,0,0,0,0
0,0,0,0,0,0,0,0,0,0,0,0,0,0,0,0,0,0,0,0,0,0,0,0,0,0,0,0,0
endlayer

layer
0,0,0,0,0,0,0,0,0,0,0,0,0,0,0,0,0,0,0,0,0,0,0,0,0,0,0,0,0
0,0,0,0,0,0,0,0,0,0,0,0,0,0,0,0,0,0,0,0,0,0,0,0,0,0,0,0,0
0,0,0,0,0,3,3,3,3,3,0,0,0,0,0,0,0,0,0,3,3,3,3,3,0,0,0,0,0
0,0,0,0,3,2,2,2,2,2,3,0,0,0,0,0,0,0,3,2,2,2,2,2,3,0,0,0,0
0,0,0,3,2,2,2,2,2,2,2,3,0,0,0,0,0,3,2,2,2,2,2,2,2,3,0,0,0
0,0,3,2,2,2,2,2,2,2,2,2,3,0,0,0,3,2,2,2,2,2,2,2,2,2,3,0,0
0,0,3,2,2,2,2,2,2,2,2,2,2,3,3,3,2,2,2,2,2,2,2,2,2,2,3,0,0
0,0,3,2,2,2,2,2,2,2,2,2,2,2,8,2,2,2,2,2,2,2,2,2,2,2,3,0,0
0,0,3,2,2,2,2,2,2,2,2,2,2,3,3,3,2,2,2,2,2,2,2,2,2,2,3,0,0
0,0,3,2,2,2,2,2,2,2,2,2,3,0,0,0,3,2,2,2,2,2,2,2,2,2,3,0,0
0,0,0,3,2,2,2,2,2,2,2,3,0,0,0,0,0,3,2,2,2,2,2,2,2,3,0,0,0
0,0,0,0,3,2,2,2,2,2,3,0,0,0,0,0,0,0,3,2,2,2,2,2,3,0,0,0,0
0,0,0,0,0,3,3,3,3,3,0,0,0,0,0,0,0,0,0,3,3,3,3,3,0,0,0,0,0
0,0,0,0,0,0,0,0,0,0,0,0,0,0,0,0,0,0,0,0,0,0,0,0,0,0,0,0,0
0,0,0,0,0,0,0,0,0,0,0,0,0,0,0,0,0,0,0,0,0,0,0,0,0,0,0,0,0
endlayer

layer
0,0,0,0,0,0,0,0,0,0,0,0,0,0,0,0,0,0,0,0,0,0,0,0,0,0,0,0,0
0,0,0,0,0,0,0,0,0,0,0,0,0,0,0,0,0,0,0,0,0,0,0,0,0,0,0,0,0
0,0,0,0,0,5,6,5,6,5,0,0,0,0,0,0,0,0,0,5,6,5,6,5,0,0,0,0,0
0,0,0,0,3,0,0,0,0,0,3,0,0,0,0,0,0,0,3,0,0,0,0,0,3,0,0,0,0
0,0,0,3,0,0,0,0,0,0,0,3,0,0,0,0,0,3,0,0,0,0,0,0,0,3,0,0,0
0,0,5,0,0,0,0,0,0,0,0,0,5,0,0,0,5,0,0,0,0,0,0,0,0,0,5,0,0
0,0,6,0,0,0,0,0,0,0,0,0,0,6,5,6,0,0,0,0,0,0,0,0,0,0,6,0,0
0,0,5,0,0,0,0,9,0,0,0,0,0,0,8,0,0,0,0,0,0,9,0,0,0,0,5,0,0
0,0,6,0,0,0,0,0,0,0,0,0,0,6,5,6,0,0,0,0,0,0,0,0,0,0,6,0,0
0,0,5,0,0,0,0,0,0,0,0,0,5,0,0,0,5,0,0,0,0,0,0,0,0,0,5,0,0
0,0,0,3,0,0,0,0,0,0,0,3,0,0,0,0,0,3,0,0,0,0,0,0,0,3,0,0,0
0,0,0,0,3,0,0,0,0,0,3,0,0,0,0,0,0,0,3,0,0,0,0,0,3,0,0,0,0
0,0,0,0,0,5,6,5,6,5,0,0,0,0,0,0,0,0,0,5,6,5,6,5,0,0,0,0,0
0,0,0,0,0,0,0,0,0,0,0,0,0,0,0,0,0,0,0,0,0,0,0,0,0,0,0,0,0
0,0,0,0,0,0,0,0,0,0,0,0,0,0,0,0,0,0,0,0,0,0,0,0,0,0,0,0,0
endlayer

layer
0,0,0,0,0,0,0,0,0,0,0,0,0,0,0,0,0,0,0,0,0,0,0,0,0,0,0,0,0
0,0,0,0,0,0,0,0,0,0,0,0,0,0,0,0,0,0,0,0,0,0,0,0,0,0,0,0,0
0,0,0,0,0,5,6,5,6,5,0,0,0,0,0,0,0,0,0,5,6,5,6,5,0,0,0,0,0
0,0,0,0,3,0,0,0,0,0,3,0,0,0,0,0,0,0,3,0,0,0,0,0,3,0,0,0,0
0,0,0,3,0,0,0,0,0,0,0,3,0,0,0,0,0,3,0,0,0,0,0,0,0,3,0,0,0
0,0,5,0,0,0,0,0,0,0,0,0,5,0,0,0,5,0,0,0,0,0,0,0,0,0,5,0,0
0,0,6,0,0,0,0,0,0,0,0,0,0,6,5,6,0,0,0,0,0,0,0,0,0,0,6,0,0
0,0,5,0,0,0,0,11,0,0,0,0,0,0,8,0,0,0,0,0,0,11,0,0,0,0,5,0,0
0,0,6,0,0,0,0,0,0,0,0,0,0,6,5,6,0,0,0,0,0,0,0,0,0,0,6,0,0
0,0,5,0,0,0,0,0,0,0,0,0,5,0,0,0,5,0,0,0,0,0,0,0,0,0,5,0,0
0,0,0,3,0,0,0,0,0,0,0,3,0,0,0,0,0,3,0,0,0,0,0,0,0,3,0,0,0
0,0,0,0,3,0,0,0,0,0,3,0,0,0,0,0,0,0,3,0,0,0,0,0,3,0,0,0,0
0,0,0,0,0,5,6,5,6,5,0,0,0,0,0,0,0,0,0,5,6,5,6,5,0,0,0,0,0
0,0,0,0,0,0,0,0,0,0,0,0,0,0,0,0,0,0,0,0,0,0,0,0,0,0,0,0,0
0,0,0,0,0,0,0,0,0,0,0,0,0,0,0,0,0,0,0,0,0,0,0,0,0,0,0,0,0
endlayer

layer
0,0,0,0,0,0,0,0,0,0,0,0,0,0,0,0,0,0,0,0,0,0,0,0,0,0,0,0,0
0,0,0,0,0,0,0,0,0,0,0,0,0,0,0,0,0,0,0,0,0,0,0,0,0,0,0,0,0
0,0,0,0,0,5,6,5,6,5,0,0,0,0,0,0,0,0,0,5,6,5,6,5,0,0,0,0,0
0,0,0,0,3,0,0,0,0,0,3,0,0,0,0,0,0,0,3,0,0,0,0,0,3,0,0,0,0
0,0,0,3,0,0,0,0,0,0,0,3,0,0,0,0,0,3,0,0,0,0,0,0,0,3,0,0,0
0,0,5,0,0,0,0,0,0,0,0,0,5,0,0,0,5,0,0,0,0,0,0,0,0,0,5,0,0
0,0,6,0,0,0,0,0,0,0,0,0,0,6,5,6,0,0,0,0,0,0,0,0,0,0,6,0,0
0,0,5,0,0,0,0,0,0,0,0,0,0,0,8,0,0,0,0,0,0,0,0,0,0,0,5,0,0
0,0,6,0,0,0,0,0,0,0,0,0,0,6,5,6,0,0,0,0,0,0,0,0,0,0,6,0,0
0,0,5,0,0,0,0,0,0,0,0,0,5,0,0,0,5,0,0,0,0,0,0,0,0,0,5,0,0
0,0,0,3,0,0,0,0,0,0,0,3,0,0,0,0,0,3,0,0,0,0,0,0,0,3,0,0,0
0,0,0,0,3,0,0,0,0,0,3,0,0,0,0,0,0,0,3,0,0,0,0,0,3,0,0,0,0
0,0,0,0,0,5,6,5,6,5,0,0,0,0,0,0,0,0,0,5,6,5,6,5,0,0,0,0,0
0,0,0,0,0,0,0,0,0,0,0,0,0,0,0,0,0,0,0,0,0,0,0,0,0,0,0,0,0
0,0,0,0,0,0,0,0,0,0,0,0,0,0,0,0,0,0,0,0,0,0,0,0,0,0,0,0,0
endlayer

layer
0,0,0,0,0,0,0,0,0,0,0,0,0,0,0,0,0,0,0,0,0,0,0,0,0,0,0,0,0
0,0,0,0,0,0,0,0,0,0,0,0,0,0,0,0,0,0,0,0,0,0,0,0,0,0,0,0,0
0,0,0,0,0,5,6,5,6,5,0,0,0,0,0,0,0,0,0,5,6,5,6,5,0,0,0,0,0
0,0,0,0,3,0,0,0,0,0,3,0,0,0,0,0,0,0,3,0,0,0,0,0,3,0,0,0,0
0,0,0,3,0,0,0,0,0,0,0,3,0,0,0,0,0,3,0,0,0,0,0,0,0,3,0,0,0
0,0,5,0,0,0,0,0,0,0,0,0,5,0,0,0,5,0,0,0,0,0,0,0,0,0,5,0,0
0,0,6,0,0,0,0,0,0,0,0,0,0,6,5,6,0,0,0,0,0,0,0,0,0,0,6,0,0
0,0,5,0,0,0,0,0,0,0,0,0,0,0,8,0,0,0,0,0,0,0,0,0,0,0,5,0,0
0,0,6,0,0,0,0,0,0,0,0,0,0,6,5,6,0,0,0,0,0,0,0,0,0,0,6,0,0
0,0,5,0,0,0,0,0,0,0,0,0,5,0,0,0,5,0,0,0,0,0,0,0,0,0,5,0,0
0,0,0,3,0,0,0,0,0,0,0,3,0,0,0,0,0,3,0,0,0,0,0,0,0,3,0,0,0
0,0,0,0,3,0,0,0,0,0,3,0,0,0,0,0,0,0,3,0,0,0,0,0,3,0,0,0,0
0,0,0,0,0,5,6,5,6,5,0,0,0,0,0,0,0,0,0,5,6,5,6,5,0,0,0,0,0
0,0,0,0,0,0,0,0,0,0,0,0,0,0,0,0,0,0,0,0,0,0,0,0,0,0,0,0,0
0,0,0,0,0,0,0,0,0,0,0,0,0,0,0,0,0,0,0,0,0,0,0,0,0,0,0,0,0
endlayer

layer
0,0,0,0,0,0,0,0,0,0,0,0,0,0,0,0,0,0,0,0,0,0,0,0,0,0,0,0,0
0,0,0,0,0,0,0,0,0,0,0,0,0,0,0,0,0,0,0,0,0,0,0,0,0,0,0,0,0
0,0,0,0,0,5,6,5,6,5,0,0,0,0,0,0,0,0,0,5,6,5,6,5,0,0,0,0,0
0,0,0,0,3,0,0,0,0,0,3,0,0,0,0,0,0,0,3,0,0,0,0,0,3,0,0,0,0
0,0,0,3,0,0,0,0,0,0,0,3,0,0,0,0,0,3,0,0,0,0,0,0,0,3,0,0,0
0,0,5,0,0,0,0,0,0,0,0,0,5,0,0,0,5,0,0,0,0,0,0,0,0,0,5,0,0
0,0,6,0,0,0,0,0,0,0,0,0,0,6,5,6,0,0,0,0,0,0,0,0,0,0,6,0,0
0,0,5,0,0,0,0,0,0,0,0,0,0,0,8,0,0,0,0,0,0,0,0,0,0,0,5,0,0
0,0,6,0,0,0,0,0,0,0,0,0,0,6,5,6,0,0,0,0,0,0,0,0,0,0,6,0,0
0,0,5,0,0,0,0,0,0,0,0,0,5,0,0,0,5,0,0,0,0,0,0,0,0,0,5,0,0
0,0,0,3,0,0,0,0,0,0,0,3,0,0,0,0,0,3,0,0,0,0,0,0,0,3,0,0,0
0,0,0,0,3,0,0,0,0,0,3,0,0,0,0,0,0,0,3,0,0,0,0,0,3,0,0,0,0
0,0,0,0,0,5,6,5,6,5,0,0,0,0,0,0,0,0,0,5,6,5,6,5,0,0,0,0,0
0,0,0,0,0,0,0,0,0,0,0,0,0,0,0,0,0,0,0,0,0,0,0,0,0,0,0,0,0
0,0,0,0,0,0,0,0,0,0,0,0,0,0,0,0,0,0,0,0,0,0,0,0,0,0,0,0,0
endlayer

layer
0,0,0,0,0,0,0,0,0,0,0,0,0,0,0,0,0,0,0,0,0,0,0,0,0,0,0,0,0
0,0,0,0,0,0,0,0,0,0,0,0,0,0,0,0,0,0,0,0,0,0,0,0,0,0,0,0,0
0,0,0,0,0,5,6,5,6,5,0,0,0,0,0,0,0,0,0,5,6,5,6,5,0,0,0,0,0
0,0,0,0,3,0,0,0,0,0,3,0,0,0,0,0,0,0,3,0,0,0,0,0,3,0,0,0,0
0,0,0,3,0,0,0,0,0,0,0,3,0,0,0,0,0,3,0,0,0,0,0,0,0,3,0,0,0
0,0,5,0,0,0,0,0,0,0,0,0,5,0,0,0,5,0,0,0,0,0,0,0,0,0,5,0,0
0,0,6,0,0,0,0,0,0,0,0,0,0,6,5,6,0,0,0,0,0,0,0,0,0,0,6,0,0
0,0,5,0,0,0,0,0,0,0,0,0,0,0,8,0,0,0,0,0,0,0,0,0,0,0,5,0,0
0,0,6,0,0,0,0,0,0,0,0,0,0,6,5,6,0,0,0,0,0,0,0,0,0,0,6,0,0
0,0,5,0,0,0,0,0,0,0,0,0,5,0,0,0,5,0,0,0,0,0,0,0,0,0,5,0,0
0,0,0,3,0,0,0,0,0,0,0,3,0,0,0,0,0,3,0,0,0,0,0,0,0,3,0,0,0
0,0,0,0,3,0,0,0,0,0,3,0,0,0,0,0,0,0,3,0,0,0,0,0,3,0,0,0,0
0,0,0,0,0,5,6,5,6,5,0,0,0,0,0,0,0,0,0,5,6,5,6,5,0,0,0,0,0
0,0,0,0,0,0,0,0,0,0,0,0,0,0,0,0,0,0,0,0,0,0,0,0,0,0,0,0,0
0,0,0,0,0,0,0,0,0,0,0,0,0,0,0,0,0,0,0,0,0,0,0,0,0,0,0,0,0
endlayer

layer
0,0,0,0,0,0,0,0,0,0,0,0,0,0,0,0,0,0,0,0,0,0,0,0,0,0,0,0,0
0,0,0,0,0,0,0,0,0,0,0,0,0,0,0,0,0,0,0,0,0,0,0,0,0,0,0,0,0
0,0,0,0,0,3,3,3,3,3,0,0,0,0,0,0,0,0,0,3,3,3,3,3,0,0,0,0,0
0,0,0,0,3,7,7,7,7,7,3,0,0,0,0,0,0,0,3,2,2,2,2,2,3,0,0,0,0
0,0,0,3,7,7,7,7,7,7,7,3,0,0,0,0,0,3,2,2,2,2,2,2,2,3,0,0,0
0,0,3,7,7,7,7,7,7,7,7,7,3,0,0,0,3,2,2,2,2,2,2,2,2,2,3,0,0
0,0,3,7,7,7,7,7,7,7,7,7,7,3,3,3,2,2,2,2,2,2,2,2,2,2,3,0,0
0,0,3,7,7,7,7,7,7,7,7,7,7,7,8,7,2,2,2,2,2,2,2,2,2,2,3,0,0
0,0,3,7,7,7,7,7,7,7,7,7,7,3,3,3,2,2,2,2,2,2,2,2,2,2,3,0,0
0,0,3,7,7,7,7,7,7,7,7,7,3,0,0,0,3,2,2,2,2,2,2,2,2,2,3,0,0
0,0,0,3,7,7,7,7,7,7,7,3,0,0,0,0,0,3,2,2,2,2,2,2,2,3,0,0,0
0,0,0,0,3,7,7,7,7,7,3,0,0,0,0,0,0,0,3,2,2,2,2,2,3,0,0,0,0
0,0,0,0,0,3,3,3,3,3,0,0,0,0,0,0,0,0,0,3,3,3,3,3,0,0,0,0,0
0,0,0,0,0,0,0,0,0,0,0,0,0,0,0,0,0,0,0,0,0,0,0,0,0,0,0,0,0
0,0,0,0,0,0,0,0,0,0,0,0,0,0,0,0,0,0,0,0,0,0,0,0,0,0,0,0,0
endlayer

layer
0,0,0,0,0,0,0,0,0,0,0,0,0,0,0,0,0,0,0,0,0,0,0,0,0,0,0,0,0
0,0,0,0,0,0,0,0,0,0,0,0,0,0,0,0,0,0,0,0,0,0,0,0,0,0,0,0,0
0,0,0,0,0,5,6,5,6,5,0,0,0,0,0,0,0,0,0,5,6,5,6,5,0,0,0,0,0
0,0,0,0,3,0,0,0,0,0,3,0,0,0,0,0,0,0,3,0,0,0,0,0,3,0,0,0,0
0,0,0,3,0,0,0,0,0,0,0,3,0,0,0,0,0,3,0,0,0,0,0,0,0,3,0,0,0
0,0,5,0,0,0,0,0,0,0,0,0,5,0,0,0,5,0,0,0,0,0,0,0,0,0,5,0,0
0,0,6,0,0,0,0,0,0,0,0,0,0,6,5,6,0,0,0,0,0,0,0,0,0,0,6,0,0
0,0,5,0,0,0,0,9,0,0,0,0,0,0,8,0,0,0,0,0,0,9,0,0,0,0,5,0,0
0,0,6,0,0,0,0,0,0,0,0,0,0,6,5,6,0,0,0,0,0,0,0,0,0,0,6,0,0
0,0,5,0,0,0,0,0,0,0,0,0,5,0,0,0,5,0,0,0,0,0,0,0,0,0,5,0,0
0,0,0,3,0,0,0,0,0,0,0,3,0,0,0,0,0,3,0,0,0,0,0,0,0,3,0,0,0
0,0,0,0,3,0,0,0,0,0,3,0,0,0,0,0,0,0,3,2,0,0,0,0,3,0,0,0,0
0,0,0,0,0,5,6,5,6,5,0,0,0,0,0,0,0,0,0,5,6,5,6,5,0,0,0,0,0
0,0,0,0,0,0,0,0,0,0,0,0,0,0,0,0,0,0,0,0,0,0,0,0,0,0,0,0,0
0,0,0,0,0,0,0,0,0,0,0,0,0,0,0,0,0,0,0,0,0,0,0,0,0,0,0,0,0
endlayer

layer
0,0,0,0,0,0,0,0,0,0,0,0,0,0,0,0,0,0,0,0,0,0,0,0,0,0,0,0,0
0,0,0,0,0,0,0,0,0,0,0,0,0,0,0,0,0,0,0,0,0,0,0,0,0,0,0,0,0
0,0,0,0,0,5,6,5,6,5,0,0,0,0,0,0,0,0,0,5,6,5,6,5,0,0,0,0,0
0,0,0,0,3,0,0,0,0,0,3,0,0,0,0,0,0,0,3,0,0,0,0,0,3,0,0,0,0
0,0,0,3,0,0,0,0,0,0,0,3,0,0,0,0,0,3,0,0,0,0,0,0,0,3,0,0,0
0,0,5,0,0,0,0,0,0,0,0,0,5,0,0,0,5,0,0,0,0,0,0,0,0,0,5,0,0
0,0,6,0,0,0,0,0,0,0,0,0,0,6,5,6,0,0,0,0,0,0,0,0,0,0,6,0,0
0,0,5,0,0,0,0,11,0,0,0,0,0,0,8,0,0,0,0,0,0,11,0,0,0,0,5,0,0
0,0,6,0,0,0,0,0,0,0,0,0,0,6,5,6,0,0,0,0,0,0,0,0,0,0,6,0,0
0,0,5,0,0,0,0,0,0,0,0,0,5,0,0,0,5,0,0,0,0,0,0,0,0,0,5,0,0
0,0,0,3,0,0,0,0,0,0,0,3,0,0,0,0,0,3,0,0,0,0,0,0,0,3,0,0,0
0,0,0,0,3,0,0,0,0,0,3,0,0,0,0,0,0,0,3,0,0,0,0,0,3,0,0,0,0
0,0,0,0,0,5,6,5,6,5,0,0,0,0,0,0,0,0,0,5,6,5,6,5,0,0,0,0,0
0,0,0,0,0,0,0,0,0,0,0,0,0,0,0,0,0,0,0,0,0,0,0,0,0,0,0,0,0
0,0,0,0,0,0,0,0,0,0,0,0,0,0,0,0,0,0,0,0,0,0,0,0,0,0,0,0,0
endlayer

layer
0,0,0,0,0,0,0,0,0,0,0,0,0,0,0,0,0,0,0,0,0,0,0,0,0,0,0,0,0
0,0,0,0,0,0,0,0,0,0,0,0,0,0,0,0,0,0,0,0,0,0,0,0,0,0,0,0,0
0,0,0,0,0,5,6,5,6,5,0,0,0,0,0,0,0,0,0,5,6,5,6,5,0,0,0,0,0
0,0,0,0,3,0,0,0,0,0,3,0,0,0,0,0,0,0,3,0,0,0,0,0,3,0,0,0,0
0,0,0,3,0,0,0,0,0,0,0,3,0,0,0,0,0,3,0,0,0,0,0,0,0,3,0,0,0
0,0,5,0,0,0,0,0,0,0,0,0,5,0,0,0,5,0,0,0,0,0,0,0,0,0,5,0,0
0,0,6,0,0,0,0,0,0,0,0,0,0,6,5,6,0,0,0,0,0,0,0,0,0,0,6,0,0
0,0,5,0,0,0,0,0,0,0,0,0,0,0,8,0,0,0,0,0,0,0,0,0,0,0,5,0,0
0,0,6,0,0,0,0,0,0,0,0,0,0,6,5,6,0,0,0,0,0,0,0,0,0,0,6,0,0
0,0,5,0,0,0,0,0,0,0,0,0,5,0,0,0,5,0,0,0,0,0,0,0,0,0,5,0,0
0,0,0,3,0,0,0,0,0,0,0,3,0,0,0,0,0,3,0,0,0,0,0,0,0,3,0,0,0
0,0,0,0,3,0,0,0,0,0,3,0,0,0,0,0,0,0,3,0,0,0,0,0,3,0,0,0,0
0,0,0,0,0,5,6,5,6,5,0,0,0,0,0,0,0,0,0,5,6,5,6,5,0,0,0,0,0
0,0,0,0,0,0,0,0,0,0,0,0,0,0,0,0,0,0,0,0,0,0,0,0,0,0,0,0,0
0,0,0,0,0,0,0,0,0,0,0,0,0,0,0,0,0,0,0,0,0,0,0,0,0,0,0,0,0
endlayer

layer
0,0,0,0,0,0,0,0,0,0,0,0,0,0,0,0,0,0,0,0,0,0,0,0,0,0,0,0,0
0,0,0,0,0,0,0,0,0,0,0,0,0,0,0,0,0,0,0,0,0,0,0,0,0,0,0,0,0
0,0,0,0,0,5,6,5,6,5,0,0,0,0,0,0,0,0,0,5,6,5,6,5,0,0,0,0,0
0,0,0,0,3,0,0,0,0,0,3,0,0,0,0,0,0,0,3,0,0,0,0,0,3,0,0,0,0
0,0,0,3,0,0,0,0,0,0,0,3,0,0,0,0,0,3,0,0,0,0,0,0,0,3,0,0,0
0,0,5,0,0,0,0,0,0,0,0,0,5,0,0,0,5,0,0,0,0,0,0,0,0,0,5,0,0
0,0,6,0,0,0,0,0,0,0,0,0,0,6,5,6,0,0,0,0,0,0,0,0,0,0,6,0,0
0,0,5,0,0,0,0,0,0,0,0,0,0,0,8,0,0,0,0,0,0,0,0,0,0,0,5,0,0
0,0,6,0,0,0,0,0,0,0,0,0,0,6,5,6,0,0,0,0,0,0,0,0,0,0,6,0,0
0,0,5,0,0,0,0,0,0,0,0,0,5,0,0,0,5,0,0,0,0,0,0,0,0,0,5,0,0
0,0,0,3,0,0,0,0,0,0,0,3,0,0,0,0,0,3,0,0,0,0,0,0,0,3,0,0,0
0,0,0,0,3,0,0,0,0,0,3,0,0,0,0,0,0,0,3,0,0,0,0,0,3,0,0,0,0
0,0,0,0,0,5,6,5,6,5,0,0,0,0,0,0,0,0,0,5,6,5,6,5,0,0,0,0,0
0,0,0,0,0,0,0,0,0,0,0,0,0,0,0,0,0,0,0,0,0,0,0,0,0,0,0,0,0
0,0,0,0,0,0,0,0,0,0,0,0,0,0,0,0,0,0,0,0,0,0,0,0,0,0,0,0,0
endlayer

layer
0,0,0,0,0,0,0,0,0,0,0,0,0,0,0,0,0,0,0,0,0,0,0,0,0,0,0,0,0
0,0,0,0,0,0,0,0,0,0,0,0,0,0,0,0,0,0,0,0,0,0,0,0,0,0,0,0,0
0,0,0,0,0,5,6,5,6,5,0,0,0,0,0,0,0,0,0,5,6,5,6,5,0,0,0,0,0
0,0,0,0,3,0,0,0,0,0,3,0,0,0,0,0,0,0,3,0,0,0,0,0,3,0,0,0,0
0,0,0,3,0,0,0,0,0,0,0,3,0,0,0,0,0,3,0,0,0,0,0,0,0,3,0,0,0
0,0,5,0,0,0,0,0,0,0,0,0,5,0,0,0,5,0,0,0,0,0,0,0,0,0,5,0,0
0,0,6,0,0,0,0,0,0,0,0,0,0,6,5,6,0,0,0,0,0,0,0,0,0,0,6,0,0
0,0,5,0,0,0,0,0,0,0,0,0,0,0,8,0,0,0,0,0,0,0,0,0,0,0,5,0,0
0,0,6,0,0,0,0,0,0,0,0,0,0,6,5,6,0,0,0,0,0,0,0,0,0,0,6,0,0
0,0,5,0,0,0,0,0,0,0,0,0,5,0,0,0,5,0,0,0,0,0,0,0,0,0,5,0,0
0,0,0,3,0,0,0,0,0,0,0,3,0,0,0,0,0,3,0,0,0,0,0,0,0,3,0,0,0
0,0,0,0,3,0,0,0,0,0,3,0,0,0,0,0,0,0,3,0,0,0,0,0,3,0,0,0,0
0,0,0,0,0,5,6,5,6,5,0,0,0,0,0,0,0,0,0,5,6,5,6,5,0,0,0,0,0
0,0,0,0,0,0,0,0,0,0,0,0,0,0,0,0,0,0,0,0,0,0,0,0,0,0,0,0,0
0,0,0,0,0,0,0,0,0,0,0,0,0,0,0,0,0,0,0,0,0,0,0,0,0,0,0,0,0
endlayer

layer
0,0,0,0,0,0,0,0,0,0,0,0,0,0,0,0,0,0,0,0,0,0,0,0,0,0,0,0,0
0,0,0,0,0,0,0,0,0,0,0,0,0,0,0,0,0,0,0,0,0,0,0,0,0,0,0,0,0
0,0,0,0,0,5,6,5,6,5,0,0,0,0,0,0,0,0,0,5,6,5,6,5,0,0,0,0,0
0,0,0,0,3,0,0,0,0,0,3,0,0,0,0,0,0,0,3,0,0,0,0,0,3,0,0,0,0
0,0,0,3,0,0,0,0,0,0,0,3,0,0,0,0,0,3,0,0,0,0,0,0,0,3,0,0,0
0,0,5,0,0,0,0,0,0,0,0,0,5,0,0,0,5,0,0,0,0,0,0,0,0,0,5,0,0
0,0,6,0,0,0,0,0,0,0,0,0,0,6,5,6,0,0,0,0,0,0,0,0,0,0,6,0,0
0,0,5,0,0,0,0,0,0,0,0,0,0,0,8,0,0,0,0,0,0,0,0,0,0,0,5,0,0
0,0,6,0,0,0,0,0,0,0,0,0,0,6,5,6,0,0,0,0,0,0,0,0,0,0,6,0,0
0,0,5,0,0,0,0,0,0,0,0,0,5,0,0,0,5,0,0,0,0,0,0,0,0,0,5,0,0
0,0,0,3,0,0,0,0,0,0,0,3,0,0,0,0,0,3,0,0,0,0,0,0,0,3,0,0,0
0,0,0,0,3,0,0,0,0,0,3,0,0,0,0,0,0,0,3,0,0,0,0,0,3,0,0,0,0
0,0,0,0,0,5,6,5,6,5,0,0,0,0,0,0,0,0,0,5,6,5,6,5,0,0,0,0,0
0,0,0,0,0,0,0,0,0,0,0,0,0,0,0,0,0,0,0,0,0,0,0,0,0,0,0,0,0
0,0,0,0,0,0,0,0,0,0,0,0,0,0,0,0,0,0,0,0,0,0,0,0,0,0,0,0,0
endlayer

layer
0,0,0,0,0,0,0,0,0,0,0,0,0,0,0,0,0,0,0,0,0,0,0,0,0,0,0,0,0
0,0,0,0,0,0,0,0,0,0,0,0,0,0,0,0,0,0,0,0,0,0,0,0,0,0,0,0,0
0,0,0,0,0,3,3,3,3,3,0,0,0,0,0,0,0,0,0,3,3,3,3,3,0,0,0,0,0
0,0,0,0,3,2,2,2,2,2,3,0,0,0,0,0,0,0,3,2,2,2,2,2,3,0,0,0,0
0,0,0,3,2,2,2,2,2,2,2,3,0,0,0,0,0,3,2,2,2,2,2,2,2,3,0,0,0
0,0,3,2,2,2,2,2,2,2,2,2,3,0,0,0,3,2,2,2,2,2,2,2,2,2,3,0,0
0,0,3,2,2,2,2,2,2,2,2,2,2,3,3,3,2,2,2,2,2,2,2,2,2,2,3,0,0
0,0,3,2,2,2,2,2,2,2,2,2,2,2,8,2,2,2,2,2,2,2,2,2,2,2,3,0,0
0,0,3,2,2,2,2,2,2,2,2,2,2,3,3,3,2,2,2,2,2,2,2,2,2,2,3,0,0
0,0,3,2,2,2,2,2,2,2,2,2,3,0,0,0,3,2,2,2,2,2,2,2,2,2,3,0,0
0,0,0,3,2,2,2,2,2,2,2,3,0,0,0,0,0,3,2,2,2,2,2,2,2,3,0,0,0
0,0,0,0,3,2,2,2,2,2,3,0,0,0,0,0,0,0,3,2,2,2,2,2,3,0,0,0,0
0,0,0,0,0,3,3,3,3,3,0,0,0,0,0,0,0,0,0,3,3,3,3,3,0,0,0,0,0
0,0,0,0,0,0,0,0,0,0,0,0,0,0,0,0,0,0,0,0,0,0,0,0,0,0,0,0,0
0,0,0,0,0,0,0,0,0,0,0,0,0,0,0,0,0,0,0,0,0,0,0,0,0,0,0,0,0
endlayer

layer
0,0,0,0,0,0,0,0,0,0,0,0,0,0,0,0,0,0,0,0,0,0,0,0,0,0,0,0,0
0,0,0,0,0,0,0,0,0,0,0,0,0,0,0,0,0,0,0,0,0,0,0,0,0,0,0,0,0
0,0,0,0,0,5,6,5,6,5,0,0,0,0,0,0,0,0,0,5,6,5,6,5,0,0,0,0,0
0,0,0,0,3,0,0,0,0,0,3,0,0,0,0,0,0,0,3,0,0,0,0,0,3,0,0,0,0
0,0,0,3,0,0,0,0,0,0,0,3,0,0,0,0,0,3,0,0,0,0,0,0,0,3,0,0,0
0,0,5,0,0,0,0,0,0,0,0,0,5,0,0,0,5,0,0,0,0,0,0,0,0,0,5,0,0
0,0,6,0,0,0,0,0,0,0,0,0,0,6,5,6,0,0,0,0,0,0,0,0,0,0,6,0,0
0,0,5,0,0,0,9,0,0,0,0,0,0,0,8,0,0,0,0,0,0,9,0,0,0,0,5,0,0
0,0,6,0,0,0,0,0,0,0,0,0,0,6,5,6,0,0,0,0,0,0,0,0,0,0,6,0,0
0,0,5,0,0,0,0,0,0,0,0,0,5,0,0,0,5,0,0,0,0,0,0,0,0,0,5,0,0
0,0,0,3,0,0,0,0,0,0,0,3,0,0,0,0,0,3,0,0,0,0,0,0,0,3,0,0,0
0,0,0,0,3,0,0,0,0,0,3,0,0,0,0,0,0,0,3,0,0,0,0,0,3,0,0,0,0
0,0,0,0,0,5,6,5,6,5,0,0,0,0,0,0,0,0,0,5,6,5,6,5,0,0,0,0,0
0,0,0,0,0,0,0,0,0,0,0,0,0,0,0,0,0,0,0,0,0,0,0,0,0,0,0,0,0
0,0,0,0,0,0,0,0,0,0,0,0,0,0,0,0,0,0,0,0,0,0,0,0,0,0,0,0,0
endlayer

layer
0,0,0,0,0,0,0,0,0,0,0,0,0,0,0,0,0,0,0,0,0,0,0,0,0,0,0,0,0
0,0,0,0,0,0,0,0,0,0,0,0,0,0,0,0,0,0,0,0,0,0,0,0,0,0,0,0,0
0,0,0,0,0,5,6,5,6,5,0,0,0,0,0,0,0,0,0,5,6,5,6,5,0,0,0,0,0
0,0,0,0,3,0,0,0,0,0,3,0,0,0,0,0,0,0,3,0,0,0,0,0,3,0,0,0,0
0,0,0,3,0,0,0,0,0,0,0,3,0,0,0,0,0,3,0,0,0,0,0,0,0,3,0,0,0
0,0,5,0,0,0,0,0,0,0,0,0,5,0,0,0,5,0,0,0,0,0,0,0,0,0,5,0,0
0,0,6,0,0,0,0,0,0,0,0,0,0,6,5,6,0,0,0,0,0,0,0,0,0,0,6,0,0
0,0,5,0,0,0,0,11,0,0,0,0,0,0,8,0,0,0,0,0,0,11,0,0,0,0,5,0,0
0,0,6,0,0,0,0,0,0,0,0,0,0,6,5,6,0,0,0,0,0,0,0,0,0,0,6,0,0
0,0,5,0,0,0,0,0,0,0,0,0,5,0,0,0,5,0,0,0,0,0,0,0,0,0,5,0,0
0,0,0,3,0,0,0,0,0,0,0,3,0,0,0,0,0,3,0,0,0,0,0,0,0,3,0,0,0
0,0,0,0,3,0,0,0,0,0,3,0,0,0,0,0,0,0,3,0,0,0,0,0,3,0,0,0,0
0,0,0,0,0,5,6,5,6,5,0,0,0,0,0,0,0,0,0,5,6,5,6,5,0,0,0,0,0
0,0,0,0,0,0,0,0,0,0,0,0,0,0,0,0,0,0,0,0,0,0,0,0,0,0,0,0,0
0,0,0,0,0,0,0,0,0,0,0,0,0,0,0,0,0,0,0,0,0,0,0,0,0,0,0,0,0
endlayer

layer
0,0,0,0,0,0,0,0,0,0,0,0,0,0,0,0,0,0,0,0,0,0,0,0,0,0,0,0,0
0,0,0,0,0,0,0,0,0,0,0,0,0,0,0,0,0,0,0,0,0,0,0,0,0,0,0,0,0
0,0,0,0,0,5,6,5,6,5,0,0,0,0,0,0,0,0,0,5,6,5,6,5,0,0,0,0,0
0,0,0,0,3,0,0,0,0,0,3,0,0,0,0,0,0,0,3,0,0,0,0,0,3,0,0,0,0
0,0,0,3,0,0,0,0,0,0,0,3,0,0,0,0,0,3,0,0,0,0,0,0,0,3,0,0,0
0,0,5,0,0,0,0,0,0,0,0,0,5,0,0,0,5,0,0,0,0,0,0,0,0,0,5,0,0
0,0,6,0,0,0,0,0,0,0,0,0,0,6,5,6,0,0,0,0,0,0,0,0,0,0,6,0,0
0,0,5,0,0,0,0,0,0,0,0,0,0,0,8,0,0,0,0,0,0,0,0,0,0,0,5,0,0
0,0,6,0,0,0,0,0,0,0,0,0,0,6,5,6,0,0,0,0,0,0,0,0,0,0,6,0,0
0,0,5,0,0,0,0,0,0,0,0,0,5,0,0,0,5,0,0,0,0,0,0,0,0,0,5,0,0
0,0,0,3,0,0,0,0,0,0,0,3,0,0,0,0,0,3,0,0,0,0,0,0,0,3,0,0,0
0,0,0,0,3,0,0,0,0,0,3,0,0,0,0,0,0,0,3,0,0,0,0,0,3,0,0,0,0
0,0,0,0,0,5,6,5,6,5,0,0,0,0,0,0,0,0,0,5,6,5,6,5,0,0,0,0,0
0,0,0,0,0,0,0,0,0,0,0,0,0,0,0,0,0,0,0,0,0,0,0,0,0,0,0,0,0
0,0,0,0,0,0,0,0,0,0,0,0,0,0,0,0,0,0,0,0,0,0,0,0,0,0,0,0,0
endlayer

layer
0,0,0,0,0,0,0,0,0,0,0,0,0,0,0,0,0,0,0,0,0,0,0,0,0,0,0,0,0
0,0,0,0,0,0,0,0,0,0,0,0,0,0,0,0,0,0,0,0,0,0,0,0,0,0,0,0,0
0,0,0,0,0,5,6,5,6,5,0,0,0,0,0,0,0,0,0,5,6,5,6,5,0,0,0,0,0
0,0,0,0,3,0,0,0,0,0,3,0,0,0,0,0,0,0,3,0,0,0,0,0,3,0,0,0,0
0,0,0,3,0,0,0,0,0,0,0,3,0,0,0,0,0,3,0,0,0,0,0,0,0,3,0,0,0
0,0,5,0,0,0,0,0,0,0,0,0,5,0,0,0,5,0,0,0,0,0,0,0,0,0,5,0,0
0,0,6,0,0,0,0,0,0,0,0,0,0,6,5,6,0,0,0,0,0,0,0,0,0,0,6,0,0
0,0,5,0,0,0,0,0,0,0,0,0,0,0,8,0,0,0,0,0,0,0,0,0,0,0,5,0,0
0,0,6,0,0,0,0,0,0,0,0,0,0,6,5,6,0,0,0,0,0,0,0,0,0,0,6,0,0
0,0,5,0,0,0,0,0,0,0,0,0,5,0,0,0,5,0,0,0,0,0,0,0,0,0,5,0,0
0,0,0,3,0,0,0,0,0,0,0,3,0,0,0,0,0,3,0,0,0,0,0,0,0,3,0,0,0
0,0,0,0,3,0,0,0,0,0,3,0,0,0,0,0,0,0,3,0,0,0,0,0,3,0,0,0,0
0,0,0,0,0,5,6,5,6,5,0,0,0,0,0,0,0,0,0,5,6,5,6,5,0,0,0,0,0
0,0,0,0,0,0,0,0,0,0,0,0,0,0,0,0,0,0,0,0,0,0,0,0,0,0,0,0,0
0,0,0,0,0,0,0,0,0,0,0,0,0,0,0,0,0,0,0,0,0,0,0,0,0,0,0,0,0
endlayer

layer
0,0,0,0,0,0,0,0,0,0,0,0,0,0,0,0,0,0,0,0,0,0,0,0,0,0,0,0,0
0,0,0,0,0,0,0,0,0,0,0,0,0,0,0,0,0,0,0,0,0,0,0,0,0,0,0,0,0
0,0,0,0,0,5,6,5,6,5,0,0,0,0,0,0,0,0,0,5,6,5,6,5,0,0,0,0,0
0,0,0,0,3,0,0,0,0,0,3,0,0,0,0,0,0,0,3,0,0,0,0,0,3,0,0,0,0
0,0,0,3,0,0,0,0,0,0,0,3,0,0,0,0,0,3,0,0,0,0,0,0,0,3,0,0,0
0,0,5,0,0,0,0,0,0,0,0,0,5,0,0,0,5,0,0,0,0,0,0,0,0,0,5,0,0
0,0,6,0,0,0,0,0,0,0,0,0,0,6,5,6,0,0,0,0,0,0,0,0,0,0,6,0,0
0,0,5,0,0,0,0,0,0,0,0,0,0,0,8,0,0,0,0,0,0,0,0,0,0,0,5,0,0
0,0,6,0,0,0,0,0,0,0,0,0,0,6,5,6,0,0,0,0,0,0,0,0,0,0,6,0,0
0,0,5,0,0,0,0,0,0,0,0,0,5,0,0,0,5,0,0,0,0,0,0,0,0,0,5,0,0
0,0,0,3,0,0,0,0,0,0,0,3,0,0,0,0,0,3,0,0,0,0,0,0,0,3,0,0,0
0,0,0,0,3,0,0,0,0,0,3,0,0,0,0,0,0,0,3,0,0,0,0,0,3,0,0,0,0
0,0,0,0,0,5,6,5,6,5,0,0,0,0,0,0,0,0,0,5,6,5,6,5,0,0,0,0,0
0,0,0,0,0,0,0,0,0,0,0,0,0,0,0,0,0,0,0,0,0,0,0,0,0,0,0,0,0
0,0,0,0,0,0,0,0,0,0,0,0,0,0,0,0,0,0,0,0,0,0,0,0,0,0,0,0,0
endlayer

layer
0,0,0,0,0,0,0,0,0,0,0,0,0,0,0,0,0,0,0,0,0,0,0,0,0,0,0,0,0
0,0,0,0,0,0,0,0,0,0,0,0,0,0,0,0,0,0,0,0,0,0,0,0,0,0,0,0,0
0,0,0,0,0,5,6,5,6,5,0,0,0,0,0,0,0,0,0,5,6,5,6,5,0,0,0,0,0
0,0,0,0,3,0,0,0,0,0,3,0,0,0,0,0,0,0,3,0,0,0,0,0,3,0,0,0,0
0,0,0,3,0,0,0,0,0,0,0,3,0,0,0,0,0,3,0,0,0,0,0,0,0,3,0,0,0
0,0,5,0,0,0,0,0,0,0,0,0,5,0,0,0,5,0,0,0,0,0,0,0,0,0,5,0,0
0,0,6,0,0,0,0,0,0,0,0,0,0,6,5,6,0,0,0,0,0,0,0,0,0,0,6,0,0
0,0,5,0,0,0,0,0,0,0,0,0,0,0,8,0,0,0,0,0,0,0,0,0,0,0,5,0,0
0,0,6,0,0,0,0,0,0,0,0,0,0,6,5,6,0,0,0,0,0,0,0,0,0,0,6,0,0
0,0,5,0,0,0,0,0,0,0,0,0,5,0,0,0,5,0,0,0,0,0,0,0,0,0,5,0,0
0,0,0,3,0,0,0,0,0,0,0,3,0,0,0,0,0,3,0,0,0,0,0,0,0,3,0,0,0
0,0,0,0,3,0,0,0,0,0,3,0,0,0,0,0,0,0,3,0,0,0,0,0,3,0,0,0,0
0,0,0,0,0,5,6,5,6,5,0,0,0,0,0,0,0,0,0,5,6,5,6,5,0,0,0,0,0
0,0,0,0,0,0,0,0,0,0,0,0,0,0,0,0,0,0,0,0,0,0,0,0,0,0,0,0,0
0,0,0,0,0,0,0,0,0,0,0,0,0,0,0,0,0,0,0,0,0,0,0,0,0,0,0,0,0
endlayer

layer
0,0,0,0,0,0,0,0,0,0,0,0,0,0,0,0,0,0,0,0,0,0,0,0,0,0,0,0,0
0,0,0,0,0,0,0,0,0,0,0,0,0,0,0,0,0,0,0,0,0,0,0,0,0,0,0,0,0
0,0,0,0,0,3,3,3,3,3,0,0,0,0,0,0,0,0,0,3,3,3,3,3,0,0,0,0,0
0,0,0,0,3,10,10,10,10,10,3,0,0,0,0,0,0,0,3,7,7,7,7,7,3,0,0,0,0
0,0,0,3,10,0,0,0,0,0,10,3,0,0,0,0,0,3,7,7,7,7,7,7,7,3,0,0,0
0,0,3,10,0,0,0,0,0,0,0,10,3,0,0,0,3,7,7,7,7,7,7,7,7,7,3,0,0
0,0,3,10,0,0,0,0,0,0,0,10,3,3,3,3,7,7,7,7,7,7,7,7,7,7,3,0,0
0,0,3,10,0,0,0,0,0,0,0,10,3,3,8,7,7,7,7,7,7,7,7,7,7,7,3,0,0
0,0,3,10,0,0,0,0,0,0,0,10,3,3,3,3,7,7,7,7,7,7,7,7,7,7,3,0,0
0,0,3,10,0,0,0,0,0,0,0,10,3,0,0,0,3,7,7,7,7,7,7,7,7,7,3,0,0
0,0,0,3,10,0,0,0,0,0,10,3,0,0,0,0,0,3,7,7,7,7,7,7,7,3,0,0,0
0,0,0,0,3,10,10,10,10,10,3,0,0,0,0,0,0,0,3,7,7,7,7,7,3,0,0,0,0
0,0,0,0,0,3,3,3,3,3,0,0,0,0,0,0,0,0,0,3,3,3,3,3,0,0,0,0,0
0,0,0,0,0,0,0,0,0,0,0,0,0,0,0,0,0,0,0,0,0,0,0,0,0,0,0,0,0
0,0,0,0,0,0,0,0,0,0,0,0,0,0,0,0,0,0,0,0,0,0,0,0,0,0,0,0,0
endlayer

layer
0,0,0,0,0,0,0,0,0,0,0,0,0,0,0,0,0,0,0,0,0,0,0,0,0,0,0,0,0
0,0,0,0,0,0,0,0,0,0,0,0,0,0,0,0,0,0,0,0,0,0,0,0,0,0,0,0,0
0,0,0,0,0,0,0,0,0,0,0,0,0,0,0,0,0,0,0,5,6,5,6,5,0,0,0,0,0
0,0,0,0,0,0,0,0,0,0,0,0,0,0,0,0,0,0,3,0,0,0,0,0,3,0,0,0,0
0,0,0,0,0,10,10,10,10,10,0,0,0,0,0,0,0,3,0,0,0,0,0,0,0,3,0,0,0
0,0,0,0,10,0,0,0,0,0,10,0,0,0,0,0,5,0,0,0,0,0,0,0,0,0,5,0,0
0,0,0,0,10,0,0,0,0,0,10,0,0,6,5,6,0,0,0,0,0,0,0,0,0,0,6,0,0
0,0,0,0,10,0,0,0,0,0,10,0,0,6,8,0,0,0,0,0,9,0,0,0,0,0,5,0,0
0,0,0,0,10,0,0,0,0,0,10,0,0,6,5,6,0,0,0,0,0,0,0,0,0,0,6,0,0
0,0,0,0,10,0,0,0,0,0,10,0,0,0,0,0,5,0,0,0,0,0,0,0,0,0,5,0,0
0,0,0,0,0,10,10,10,10,10,0,0,0,0,0,0,0,3,0,0,0,0,0,0,0,3,0,0,0
0,0,0,0,0,0,0,0,0,0,0,0,0,0,0,0,0,0,3,0,0,0,0,0,3,0,0,0,0
0,0,0,0,0,0,0,0,0,0,0,0,0,0,0,0,0,0,0,5,6,5,6,5,0,0,0,0,0
0,0,0,0,0,0,0,0,0,0,0,0,0,0,0,0,0,0,0,0,0,0,0,0,0,0,0,0,0
0,0,0,0,0,0,0,0,0,0,0,0,0,0,0,0,0,0,0,0,0,0,0,0,0,0,0,0,0
endlayer

layer
0,0,0,0,0,0,0,0,0,0,0,0,0,0,0,0,0,0,0,0,0,0,0,0,0,0,0,0,0
0,0,0,0,0,0,0,0,0,0,0,0,0,0,0,0,0,0,0,0,0,0,0,0,0,0,0,0,0
0,0,0,0,0,0,0,0,0,0,0,0,0,0,0,0,0,0,0,5,6,5,6,5,0,0,0,0,0
0,0,0,0,0,0,0,0,0,0,0,0,0,0,0,0,0,0,3,0,0,0,0,0,3,0,0,0,0
0,0,0,0,0,0,0,0,0,0,0,0,0,0,0,0,0,3,0,0,0,0,0,0,0,3,0,0,0
0,0,0,0,0,10,10,10,10,10,0,0,0,0,0,0,5,0,0,0,0,0,0,0,0,0,5,0,0
0,0,0,0,0,10,0,0,0,10,0,0,0,6,5,6,0,0,0,0,0,0,0,0,0,0,6,0,0
0,0,0,0,0,10,0,0,0,10,0,0,0,6,8,0,0,0,0,0,11,0,0,0,0,0,5,0,0
0,0,0,0,0,10,0,0,0,10,0,0,0,6,5,6,0,0,0,0,0,0,0,0,0,0,6,0,0
0,0,0,0,0,10,10,10,10,10,0,0,0,0,0,0,5,0,0,0,0,0,0,0,0,0,5,0,0
0,0,0,0,0,0,0,0,0,0,0,0,0,0,0,0,0,3,0,0,0,0,0,0,0,3,0,0,0
0,0,0,0,0,0,0,0,0,0,0,0,0,0,0,0,0,0,3,0,0,0,0,0,3,0,0,0,0
0,0,0,0,0,0,0,0,0,0,0,0,0,0,0,0,0,0,0,5,6,5,6,5,0,0,0,0,0
0,0,0,0,0,0,0,0,0,0,0,0,0,0,0,0,0,0,0,0,0,0,0,0,0,0,0,0,0
0,0,0,0,0,0,0,0,0,0,0,0,0,0,0,0,0,0,0,0,0,0,0,0,0,0,0,0,0
endlayer

layer
0,0,0,0,0,0,0,0,0,0,0,0,0,0,0,0,0,0,0,0,0,0,0,0,0,0,0,0,0
0,0,0,0,0,0,0,0,0,0,0,0,0,0,0,0,0,0,0,0,0,0,0,0,0,0,0,0,0
0,0,0,0,0,0,0,0,0,0,0,0,0,0,0,0,0,0,0,5,6,5,6,5,0,0,0,0,0
0,0,0,0,0,0,0,0,0,0,0,0,0,0,0,0,0,0,3,0,0,0,0,0,3,0,0,0,0
0,0,0,0,0,0,0,0,0,0,0,0,0,0,0,0,0,3,0,0,0,0,0,0,0,3,0,0,0
0,0,0,0,0,0,0,0,0,0,0,0,0,0,0,0,5,0,0,0,0,0,0,0,0,0,5,0,0
0,0,0,0,0,0,10,10,10,0,0,0,0,6,5,6,0,0,0,0,0,0,0,0,0,0,6,0,0
0,0,0,0,0,0,10,12,10,0,0,0,0,6,8,0,0,0,0,0,0,0,0,0,0,0,5,0,0
0,0,0,0,0,0,10,10,10,0,0,0,0,6,5,6,0,0,0,0,0,0,0,0,0,0,6,0,0
0,0,0,0,0,0,0,0,0,0,0,0,0,0,0,0,5,0,0,0,0,0,0,0,0,0,5,0,0
0,0,0,0,0,0,0,0,0,0,0,0,0,0,0,0,0,3,0,0,0,0,0,0,0,3,0,0,0
0,0,0,0,0,0,0,0,0,0,0,0,0,0,0,0,0,0,3,0,0,0,0,0,3,0,0,0,0
0,0,0,0,0,0,0,0,0,0,0,0,0,0,0,0,0,0,0,5,6,5,6,5,0,0,0,0,0
0,0,0,0,0,0,0,0,0,0,0,0,0,0,0,0,0,0,0,0,0,0,0,0,0,0,0,0,0
0,0,0,0,0,0,0,0,0,0,0,0,0,0,0,0,0,0,0,0,0,0,0,0,0,0,0,0,0
endlayer

layer
0,0,0,0,0,0,0,0,0,0,0,0,0,0,0,0,0,0,0,0,0,0,0,0,0,0,0,0,0
0,0,0,0,0,0,0,0,0,0,0,0,0,0,0,0,0,0,0,0,0,0,0,0,0,0,0,0,0
0,0,0,0,0,0,0,0,0,0,0,0,0,0,0,0,0,0,0,5,6,5,6,5,0,0,0,0,0
0,0,0,0,0,0,0,0,0,0,0,0,0,0,0,0,0,0,3,0,0,0,0,0,3,0,0,0,0
0,0,0,0,0,0,0,0,0,0,0,0,0,0,0,0,0,3,0,0,0,0,0,0,0,3,0,0,0
0,0,0,0,0,0,0,0,0,0,0,0,0,0,0,0,5,0,0,0,0,0,0,0,0,0,5,0,0
0,0,0,0,0,0,0,0,0,0,0,0,0,6,5,6,0,0,0,0,0,0,0,0,0,0,6,0,0
0,0,0,0,0,0,0,10,0,0,0,0,0,6,8,0,0,0,0,0,0,0,0,0,0,0,5,0,0
0,0,0,0,0,0,0,0,0,0,0,0,0,6,5,6,0,0,0,0,0,0,0,0,0,0,6,0,0
0,0,0,0,0,0,0,0,0,0,0,0,0,0,0,0,5,0,0,0,0,0,0,0,0,0,5,0,0
0,0,0,0,0,0,0,0,0,0,0,0,0,0,0,0,0,3,0,0,0,0,0,0,0,3,0,0,0
0,0,0,0,0,0,0,0,0,0,0,0,0,0,0,0,0,0,3,0,0,0,0,0,3,0,0,0,0
0,0,0,0,0,0,0,0,0,0,0,0,0,0,0,0,0,0,0,5,6,5,6,5,0,0,0,0,0
0,0,0,0,0,0,0,0,0,0,0,0,0,0,0,0,0,0,0,0,0,0,0,0,0,0,0,0,0
0,0,0,0,0,0,0,0,0,0,0,0,0,0,0,0,0,0,0,0,0,0,0,0,0,0,0,0,0
endlayer

layer
0,0,0,0,0,0,0,0,0,0,0,0,0,0,0,0,0,0,0,0,0,0,0,0,0,0,0,0,0
0,0,0,0,0,0,0,0,0,0,0,0,0,0,0,0,0,0,0,0,0,0,0,0,0,0,0,0,0
0,0,0,0,0,0,0,0,0,0,0,0,0,0,0,0,0,0,0,5,6,5,6,5,0,0,0,0,0
0,0,0,0,0,0,0,0,0,0,0,0,0,0,0,0,0,0,3,0,0,0,0,0,3,0,0,0,0
0,0,0,0,0,0,0,0,0,0,0,0,0,0,0,0,0,3,0,0,0,0,0,0,0,3,0,0,0
0,0,0,0,0,0,0,0,0,0,0,0,0,0,0,0,5,0,0,0,0,0,0,0,0,0,5,0,0
0,0,0,0,0,0,0,0,0,0,0,0,0,6,5,6,0,0,0,0,0,0,0,0,0,0,6,0,0
0,0,0,0,0,0,0,10,0,0,0,0,0,6,8,0,0,0,0,0,0,0,0,0,0,0,5,0,0
0,0,0,0,0,0,0,0,0,0,0,0,0,6,5,6,0,0,0,0,0,0,0,0,0,0,6,0,0
0,0,0,0,0,0,0,0,0,0,0,0,0,0,0,0,5,0,0,0,0,0,0,0,0,0,5,0,0
0,0,0,0,0,0,0,0,0,0,0,0,0,0,0,0,0,3,0,0,0,0,0,0,0,3,0,0,0
0,0,0,0,0,0,0,0,0,0,0,0,0,0,0,0,0,0,3,0,0,0,0,0,3,0,0,0,0
0,0,0,0,0,0,0,0,0,0,0,0,0,0,0,0,0,0,0,5,6,5,6,5,0,0,0,0,0
0,0,0,0,0,0,0,0,0,0,0,0,0,0,0,0,0,0,0,0,0,0,0,0,0,0,0,0,0
0,0,0,0,0,0,0,0,0,0,0,0,0,0,0,0,0,0,0,0,0,0,0,0,0,0,0,0,0
endlayer

layer
0,0,0,0,0,0,0,0,0,0,0,0,0,0,0,0,0,0,0,0,0,0,0,0,0,0,0,0,0
0,0,0,0,0,0,0,0,0,0,0,0,0,0,0,0,0,0,0,0,0,0,0,0,0,0,0,0,0
0,0,0,0,0,0,0,0,0,0,0,0,0,0,0,0,0,0,0,5,6,5,6,5,0,0,0,0,0
0,0,0,0,0,0,0,0,0,0,0,0,0,0,0,0,0,0,3,0,0,0,0,0,3,0,0,0,0
0,0,0,0,0,0,0,0,0,0,0,0,0,0,0,0,0,3,0,0,0,0,0,0,0,3,0,0,0
0,0,0,0,0,0,0,0,0,0,0,0,0,0,0,0,5,0,0,0,0,0,0,0,0,0,5,0,0
0,0,0,0,0,0,0,0,0,0,0,0,0,6,5,6,0,0,0,0,0,0,0,0,0,0,6,0,0
0,0,0,0,0,0,0,10,0,0,0,0,0,6,8,0,0,0,0,0,0,0,0,0,0,0,5,0,0
0,0,0,0,0,0,0,0,0,0,0,0,0,6,5,6,0,0,0,0,0,0,0,0,0,0,6,0,0
0,0,0,0,0,0,0,0,0,0,0,0,0,0,0,0,5,0,0,0,0,0,0,0,0,0,5,0,0
0,0,0,0,0,0,0,0,0,0,0,0,0,0,0,0,0,3,0,0,0,0,0,0,0,3,0,0,0
0,0,0,0,0,0,0,0,0,0,0,0,0,0,0,0,0,0,3,0,0,0,0,0,3,0,0,0,0
0,0,0,0,0,0,0,0,0,0,0,0,0,0,0,0,0,0,0,5,6,5,6,5,0,0,0,0,0
0,0,0,0,0,0,0,0,0,0,0,0,0,0,0,0,0,0,0,0,0,0,0,0,0,0,0,0,0
0,0,0,0,0,0,0,0,0,0,0,0,0,0,0,0,0,0,0,0,0,0,0,0,0,0,0,0,0
endlayer

layer
0,0,0,0,0,0,0,0,0,0,0,0,0,0,0,0,0,0,0,0,0,0,0,0,0,0,0,0,0
0,0,0,0,0,0,0,0,0,0,0,0,0,0,0,0,0,0,0,0,0,0,0,0,0,0,0,0,0
0,0,0,0,0,0,0,0,0,0,0,0,0,0,0,0,0,0,0,3,3,3,3,3,0,0,0,0,0
0,0,0,0,0,0,0,0,0,0,0,0,0,0,0,0,0,0,3,2,2,2,2,2,3,0,0,0,0
0,0,0,0,0,0,0,0,0,0,0,0,0,0,0,0,0,3,2,2,2,2,2,2,2,3,0,0,0
0,0,0,0,0,0,0,0,0,0,0,0,0,0,0,0,3,2,2,2,2,2,2,2,2,2,3,0,0
0,0,0,0,0,0,0,0,0,0,0,0,0,3,3,3,2,2,2,2,2,2,2,2,2,2,3,0,0
0,0,0,0,0,0,0,10,0,0,0,0,0,3,8,2,2,2,2,2,2,2,2,2,2,2,3,0,0
0,0,0,0,0,0,0,0,0,0,0,0,0,3,3,3,2,2,2,2,2,2,2,2,2,2,3,0,0
0,0,0,0,0,0,0,0,0,0,0,0,0,0,0,0,3,2,2,2,2,2,2,2,2,2,3,0,0
0,0,0,0,0,0,0,0,0,0,0,0,0,0,0,0,0,3,2,2,2,2,2,2,2,3,0,0,0
0,0,0,0,0,0,0,0,0,0,0,0,0,0,0,0,0,0,3,2,2,2,2,2,3,0,0,0,0
0,0,0,0,0,0,0,0,0,0,0,0,0,0,0,0,0,0,0,3,3,3,3,3,0,0,0,0,0
0,0,0,0,0,0,0,0,0,0,0,0,0,0,0,0,0,0,0,0,0,0,0,0,0,0,0,0,0
0,0,0,0,0,0,0,0,0,0,0,0,0,0,0,0,0,0,0,0,0,0,0,0,0,0,0,0,0
endlayer

layer
0,0,0,0,0,0,0,0,0,0,0,0,0,0,0,0,0,0,0,0,0,0,0,0,0,0,0,0,0
0,0,0,0,0,0,0,0,0,0,0,0,0,0,0,0,0,0,0,0,0,0,0,0,0,0,0,0,0
0,0,0,0,0,0,0,0,0,0,0,0,0,0,0,0,0,0,0,5,6,5,6,5,0,0,0,0,0
0,0,0,0,0,0,0,0,0,0,0,0,0,0,0,0,0,0,3,0,0,0,0,0,3,0,0,0,0
0,0,0,0,0,0,0,0,0,0,0,0,0,0,0,0,0,3,0,0,0,0,0,0,0,3,0,0,0
0,0,0,0,0,0,0,0,0,0,0,0,0,0,0,0,5,0,0,0,0,0,0,0,0,0,5,0,0
0,0,0,0,0,0,0,0,0,0,0,0,0,6,5,6,0,0,0,0,0,0,0,0,0,0,6,0,0
0,0,0,0,0,0,0,10,0,0,0,0,0,6,8,0,0,0,0,0,9,0,0,0,0,0,5,0,0
0,0,0,0,0,0,0,0,0,0,0,0,0,6,5,6,0,0,0,0,0,0,0,0,0,0,6,0,0
0,0,0,0,0,0,0,0,0,0,0,0,0,0,0,0,5,0,0,0,0,0,0,0,0,0,5,0,0
0,0,0,0,0,0,0,0,0,0,0,0,0,0,0,0,0,3,0,0,0,0,0,0,0,3,0,0,0
0,0,0,0,0,0,0,0,0,0,0,0,0,0,0,0,0,0,3,0,0,9,0,0,3,0,0,0,0
0,0,0,0,0,0,0,0,0,0,0,0,0,0,0,0,0,0,0,5,6,5,6,5,0,0,0,0,0
0,0,0,0,0,0,0,0,0,0,0,0,0,0,0,0,0,0,0,0,0,0,0,0,0,0,0,0,0
0,0,0,0,0,0,0,0,0,0,0,0,0,0,0,0,0,0,0,0,0,0,0,0,0,0,0,0,0
endlayer

layer
0,0,0,0,0,0,0,0,0,0,0,0,0,0,0,0,0,0,0,0,0,0,0,0,0,0,0,0,0
0,0,0,0,0,0,0,0,0,0,0,0,0,0,0,0,0,0,0,0,0,0,0,0,0,0,0,0,0
0,0,0,0,0,0,0,0,0,0,0,0,0,0,0,0,0,0,0,5,6,5,6,5,0,0,0,0,0
0,0,0,0,0,0,0,0,0,0,0,0,0,0,0,0,0,0,3,0,0,0,0,0,3,0,0,0,0
0,0,0,0,0,0,0,0,0,0,0,0,0,0,0,0,0,3,0,0,0,0,0,0,0,3,0,0,0
0,0,0,0,0,0,0,0,0,0,0,0,0,0,0,0,5,0,0,0,0,0,0,0,0,0,5,0,0
0,0,0,0,0,0,0,0,0,0,0,0,0,6,5,6,0,0,0,0,0,0,0,0,0,0,6,0,0
0,0,0,0,0,0,0,0,0,0,0,0,0,6,8,0,0,0,0,0,0,11,0,0,0,0,5,0,0
0,0,0,0,0,0,0,0,0,0,0,0,0,6,5,6,0,0,0,0,0,0,0,0,0,0,6,0,0
0,0,0,0,0,0,0,0,0,0,0,0,0,0,0,0,5,0,0,0,0,0,0,0,0,0,5,0,0
0,0,0,0,0,0,0,0,0,0,0,0,0,0,0,0,0,3,0,0,0,0,0,0,0,3,0,0,0
0,0,0,0,0,0,0,0,0,0,0,0,0,0,0,0,0,0,3,0,0,0,0,0,3,0,0,0,0
0,0,0,0,0,0,0,0,0,0,0,0,0,0,0,0,0,0,0,5,6,5,6,5,0,0,0,0,0
0,0,0,0,0,0,0,0,0,0,0,0,0,0,0,0,0,0,0,0,0,0,0,0,0,0,0,0,0
0,0,0,0,0,0,0,0,0,0,0,0,0,0,0,0,0,0,0,0,0,0,0,0,0,0,0,0,0
endlayer

layer
0,0,0,0,0,0,0,0,0,0,0,0,0,0,0,0,0,0,0,0,0,0,0,0,0,0,0,0,0
0,0,0,0,0,0,0,0,0,0,0,0,0,0,0,0,0,0,0,0,0,0,0,0,0,0,0,0,0
0,0,0,0,0,0,0,0,0,0,0,0,0,0,0,0,0,0,0,5,6,5,6,5,0,0,0,0,0
0,0,0,0,0,0,0,0,0,0,0,0,0,0,0,0,0,0,3,0,0,0,0,0,3,0,0,0,0
0,0,0,0,0,0,0,0,0,0,0,0,0,0,0,0,0,3,0,0,0,0,0,0,0,3,0,0,0
0,0,0,0,0,0,0,0,0,0,0,0,0,0,0,0,5,0,0,0,0,0,0,0,0,0,5,0,0
0,0,0,0,0,0,0,0,0,0,0,0,0,6,5,6,0,0,0,0,0,0,0,0,0,0,6,0,0
0,0,0,0,0,0,0,0,0,0,0,0,0,6,8,0,0,0,0,0,0,0,0,0,0,0,5,0,0
0,0,0,0,0,0,0,0,0,0,0,0,0,6,5,6,0,0,0,0,0,0,0,0,0,0,6,0,0
0,0,0,0,0,0,0,0,0,0,0,0,0,0,0,0,5,0,0,0,0,0,0,0,0,0,5,0,0
0,0,0,0,0,0,0,0,0,0,0,0,0,0,0,0,0,3,0,0,0,0,0,0,0,3,0,0,0
0,0,0,0,0,0,0,0,0,0,0,0,0,0,0,0,0,0,3,0,0,0,0,0,3,0,0,0,0
0,0,0,0,0,0,0,0,0,0,0,0,0,0,0,0,0,0,0,5,6,5,6,5,0,0,0,0,0
0,0,0,0,0,0,0,0,0,0,0,0,0,0,0,0,0,0,0,0,0,0,0,0,0,0,0,0,0
0,0,0,0,0,0,0,0,0,0,0,0,0,0,0,0,0,0,0,0,0,0,0,0,0,0,0,0,0
endlayer

layer
0,0,0,0,0,0,0,0,0,0,0,0,0,0,0,0,0,0,0,0,0,0,0,0,0,0,0,0,0
0,0,0,0,0,0,0,0,0,0,0,0,0,0,0,0,0,0,0,0,0,0,0,0,0,0,0,0,0
0,0,0,0,0,0,0,0,0,0,0,0,0,0,0,0,0,0,0,5,6,5,6,5,0,0,0,0,0
0,0,0,0,0,0,0,0,0,0,0,0,0,0,0,0,0,0,3,0,0,0,0,0,3,0,0,0,0
0,0,0,0,0,0,0,0,0,0,0,0,0,0,0,0,0,3,0,0,0,0,0,0,0,3,0,0,0
0,0,0,0,0,0,0,0,0,0,0,0,0,0,0,0,5,0,0,0,0,0,0,0,0,0,5,0,0
0,0,0,0,0,0,0,0,0,0,0,0,0,6,5,6,0,0,0,0,0,0,0,0,0,0,6,0,0
0,0,0,0,0,0,0,0,0,0,0,0,0,6,8,0,0,0,0,0,0,0,0,0,0,0,5,0,0
0,0,0,0,0,0,0,0,0,0,0,0,0,6,5,6,0,0,0,0,0,0,0,0,0,0,6,0,0
0,0,0,0,0,0,0,0,0,0,0,0,0,0,0,0,5,0,0,0,0,0,0,0,0,0,5,0,0
0,0,0,0,0,0,0,0,0,0,0,0,0,0,0,0,0,3,0,0,0,0,0,0,0,3,0,0,0
0,0,0,0,0,0,0,0,0,0,0,0,0,0,0,0,0,0,3,0,0,0,0,0,3,0,0,0,0
0,0,0,0,0,0,0,0,0,0,0,0,0,0,0,0,0,0,0,5,6,5,6,5,0,0,0,0,0
0,0,0,0,0,0,0,0,0,0,0,0,0,0,0,0,0,0,0,0,0,0,0,0,0,0,0,0,0
0,0,0,0,0,0,0,0,0,0,0,0,0,0,0,0,0,0,0,0,0,0,0,0,0,0,0,0,0
endlayer

layer
0,0,0,0,0,0,0,0,0,0,0,0,0,0,0,0,0,0,0,0,0,0,0,0,0,0,0,0,0
0,0,0,0,0,0,0,0,0,0,0,0,0,0,0,0,0,0,0,0,0,0,0,0,0,0,0,0,0
0,0,0,0,0,0,0,0,0,0,0,0,0,0,0,0,0,0,0,5,6,5,6,5,0,0,0,0,0
0,0,0,0,0,0,0,0,0,0,0,0,0,0,0,0,0,0,3,0,0,0,0,0,3,0,0,0,0
0,0,0,0,0,0,0,0,0,0,0,0,0,0,0,0,0,3,0,0,0,0,0,0,0,3,0,0,0
0,0,0,0,0,0,0,0,0,0,0,0,0,0,0,0,5,0,0,0,0,0,0,0,0,0,5,0,0
0,0,0,0,0,0,0,0,0,0,0,0,0,6,5,6,0,0,0,0,0,0,0,0,0,0,6,0,0
0,0,0,0,0,0,0,0,0,0,0,0,0,6,8,0,0,0,0,0,0,0,0,0,0,0,5,0,0
0,0,0,0,0,0,0,0,0,0,0,0,0,6,5,6,0,0,0,0,0,0,0,0,0,0,6,0,0
0,0,0,0,0,0,0,0,0,0,0,0,0,0,0,0,5,0,0,0,0,0,0,0,0,0,5,0,0
0,0,0,0,0,0,0,0,0,0,0,0,0,0,0,0,0,3,0,0,0,0,0,0,0,3,0,0,0
0,0,0,0,0,0,0,0,0,0,0,0,0,0,0,0,0,0,3,0,0,0,0,0,3,0,0,0,0
0,0,0,0,0,0,0,0,0,0,0,0,0,0,0,0,0,0,0,5,6,5,6,5,0,0,0,0,0
0,0,0,0,0,0,0,0,0,0,0,0,0,0,0,0,0,0,0,0,0,0,0,0,0,0,0,0,0
0,0,0,0,0,0,0,0,0,0,0,0,0,0,0,0,0,0,0,0,0,0,0,0,0,0,0,0,0
endlayer

layer
0,0,0,0,0,0,0,0,0,0,0,0,0,0,0,0,0,0,0,0,0,0,0,0,0,0,0,0,0
0,0,0,0,0,0,0,0,0,0,0,0,0,0,0,0,0,0,0,0,0,0,0,0,0,0,0,0,0
0,0,0,0,0,0,0,0,0,0,0,0,0,0,0,0,0,0,0,5,6,5,6,5,0,0,0,0,0
0,0,0,0,0,0,0,0,0,0,0,0,0,0,0,0,0,0,3,0,0,0,0,0,3,0,0,0,0
0,0,0,0,0,0,0,0,0,0,0,0,0,0,0,0,0,3,0,0,0,0,0,0,0,3,0,0,0
0,0,0,0,0,0,0,0,0,0,0,0,0,0,0,0,5,0,0,0,0,0,0,0,0,0,5,0,0
0,0,0,0,0,0,0,0,0,0,0,0,0,6,5,6,0,0,0,0,0,0,0,0,0,0,6,0,0
0,0,0,0,0,0,0,0,0,0,0,0,0,6,8,0,0,0,0,0,0,0,0,0,0,0,5,0,0
0,0,0,0,0,0,0,0,0,0,0,0,0,6,5,6,0,0,0,0,0,0,0,0,0,0,6,0,0
0,0,0,0,0,0,0,0,0,0,0,0,0,0,0,0,5,0,0,0,0,0,0,0,0,0,5,0,0
0,0,0,0,0,0,0,0,0,0,0,0,0,0,0,0,0,3,0,0,0,0,0,0,0,3,0,0,0
0,0,0,0,0,0,0,0,0,0,0,0,0,0,0,0,0,0,3,0,0,0,0,0,3,0,0,0,0
0,0,0,0,0,0,0,0,0,0,0,0,0,0,0,0,0,0,0,5,6,5,6,5,0,0,0,0,0
0,0,0,0,0,0,0,0,0,0,0,0,0,0,0,0,0,0,0,0,0,0,0,0,0,0,0,0,0
0,0,0,0,0,0,0,0,0,0,0,0,0,0,0,0,0,0,0,0,0,0,0,0,0,0,0,0,0
endlayer

layer
0,0,0,0,0,0,0,0,0,0,0,0,0,0,0,0,0,0,0,0,0,0,0,0,0,0,0,0,0
0,0,0,0,0,0,0,0,0,0,0,0,0,0,0,0,0,0,0,0,0,0,0,0,0,0,0,0,0
0,0,0,0,0,0,0,0,0,0,0,0,0,0,0,0,0,0,0,3,3,3,3,3,0,0,0,0,0
0,0,0,0,0,0,0,0,0,0,0,0,0,0,0,0,0,0,3,10,10,10,10,10,3,0,0,0,0
0,0,0,0,0,0,0,0,0,0,0,0,0,0,0,0,0,3,10,0,0,0,0,0,10,3,0,0,0
0,0,0,0,0,0,0,0,0,0,0,0,0,0,0,0,3,10,0,0,0,0,0,0,0,10,3,0,0
0,0,0,0,0,0,0,0,0,0,0,0,0,3,3,3,3,10,0,0,0,0,0,0,0,10,3,0,0
0,0,0,0,0,0,0,0,0,0,0,0,0,3,10,10,3,10,0,0,0,0,0,0,0,10,3,0,0
0,0,0,0,0,0,0,0,0,0,0,0,0,3,3,3,3,10,0,0,0,0,0,0,0,10,3,0,0
0,0,0,0,0,0,0,0,0,0,0,0,0,0,0,0,3,10,0,0,0,0,0,0,0,10,3,0,0
0,0,0,0,0,0,0,0,0,0,0,0,0,0,0,0,0,3,10,0,0,0,0,0,10,3,0,0,0
0,0,0,0,0,0,0,0,0,0,0,0,0,0,0,0,0,0,3,10,10,10,10,10,3,0,0,0,0
0,0,0,0,0,0,0,0,0,0,0,0,0,0,0,0,0,0,0,3,3,3,3,3,0,0,0,0,0
0,0,0,0,0,0,0,0,0,0,0,0,0,0,0,0,0,0,0,0,0,0,0,0,0,0,0,0,0
0,0,0,0,0,0,0,0,0,0,0,0,0,0,0,0,0,0,0,0,0,0,0,0,0,0,0,0,0
endlayer

layer
0,0,0,0,0,0,0,0,0,0,0,0,0,0,0,0,0,0,0,0,0,0,0,0,0,0,0,0,0
0,0,0,0,0,0,0,0,0,0,0,0,0,0,0,0,0,0,0,0,0,0,0,0,0,0,0,0,0
0,0,0,0,0,0,0,0,0,0,0,0,0,0,0,0,0,0,0,0,0,0,0,0,0,0,0,0,0
0,0,0,0,0,0,0,0,0,0,0,0,0,0,0,0,0,0,0,0,0,0,0,0,0,0,0,0,0
0,0,0,0,0,0,0,0,0,0,0,0,0,0,0,0,0,0,0,10,10,10,10,10,0,0,0,0,0
0,0,0,0,0,0,0,0,0,0,0,0,0,0,0,0,0,0,10,0,0,0,0,0,10,0,0,0,0
0,0,0,0,0,0,0,0,0,0,0,0,0,0,0,0,0,0,10,0,0,0,0,0,10,0,0,0,0
0,0,0,0,0,0,0,0,0,0,0,0,0,0,0,0,0,0,10,0,0,0,0,0,10,0,0,0,0
0,0,0,0,0,0,0,0,0,0,0,0,0,0,0,0,0,0,10,0,0,0,0,0,10,0,0,0,0
0,0,0,0,0,0,0,0,0,0,0,0,0,0,0,0,0,0,10,0,0,0,0,0,10,0,0,0,0
0,0,0,0,0,0,0,0,0,0,0,0,0,0,0,0,0,0,0,10,10,10,10,10,0,0,0,0,0
0,0,0,0,0,0,0,0,0,0,0,0,0,0,0,0,0,0,0,0,0,0,0,0,0,0,0,0,0
0,0,0,0,0,0,0,0,0,0,0,0,0,0,0,0,0,0,0,0,0,0,0,0,0,0,0,0,0
0,0,0,0,0,0,0,0,0,0,0,0,0,0,0,0,0,0,0,0,0,0,0,0,0,0,0,0,0
0,0,0,0,0,0,0,0,0,0,0,0,0,0,0,0,0,0,0,0,0,0,0,0,0,0,0,0,0
endlayer

layer
0,0,0,0,0,0,0,0,0,0,0,0,0,0,0,0,0,0,0,0,0,0,0,0,0,0,0,0,0
0,0,0,0,0,0,0,0,0,0,0,0,0,0,0,0,0,0,0,0,0,0,0,0,0,0,0,0,0
0,0,0,0,0,0,0,0,0,0,0,0,0,0,0,0,0,0,0,0,0,0,0,0,0,0,0,0,0
0,0,0,0,0,0,0,0,0,0,0,0,0,0,0,0,0,0,0,0,0,0,0,0,0,0,0,0,0
0,0,0,0,0,0,0,0,0,0,0,0,0,0,0,0,0,0,0,0,0,0,0,0,0,0,0,0,0
0,0,0,0,0,0,0,0,0,0,0,0,0,0,0,0,0,0,0,10,10,10,10,10,0,0,0,0,0
0,0,0,0,0,0,0,0,0,0,0,0,0,0,0,0,0,0,0,10,0,0,0,10,0,0,0,0,0
0,0,0,0,0,0,0,0,0,0,0,0,0,0,0,0,0,0,0,10,0,0,0,10,0,0,0,0,0
0,0,0,0,0,0,0,0,0,0,0,0,0,0,0,0,0,0,0,10,0,0,0,10,0,0,0,0,0
0,0,0,0,0,0,0,0,0,0,0,0,0,0,0,0,0,0,0,10,10,10,10,10,0,0,0,0,0
0,0,0,0,0,0,0,0,0,0,0,0,0,0,0,0,0,0,0,0,0,0,0,0,0,0,0,0,0
0,0,0,0,0,0,0,0,0,0,0,0,0,0,0,0,0,0,0,0,0,0,0,0,0,0,0,0,0
0,0,0,0,0,0,0,0,0,0,0,0,0,0,0,0,0,0,0,0,0,0,0,0,0,0,0,0,0
0,0,0,0,0,0,0,0,0,0,0,0,0,0,0,0,0,0,0,0,0,0,0,0,0,0,0,0,0
0,0,0,0,0,0,0,0,0,0,0,0,0,0,0,0,0,0,0,0,0,0,0,0,0,0,0,0,0
endlayer

layer
0,0,0,0,0,0,0,0,0,0,0,0,0,0,0,0,0,0,0,0,0,0,0,0,0,0,0,0,0
0,0,0,0,0,0,0,0,0,0,0,0,0,0,0,0,0,0,0,0,0,0,0,0,0,0,0,0,0
0,0,0,0,0,0,0,0,0,0,0,0,0,0,0,0,0,0,0,0,0,0,0,0,0,0,0,0,0
0,0,0,0,0,0,0,0,0,0,0,0,0,0,0,0,0,0,0,0,0,0,0,0,0,0,0,0,0
0,0,0,0,0,0,0,0,0,0,0,0,0,0,0,0,0,0,0,0,0,0,0,0,0,0,0,0,0
0,0,0,0,0,0,0,0,0,0,0,0,0,0,0,0,0,0,0,0,0,0,0,0,0,0,0,0,0
0,0,0,0,0,0,0,0,0,0,0,0,0,0,0,0,0,0,0,0,10,10,10,0,0,0,0,0,0
0,0,0,0,0,0,0,0,0,0,0,0,0,0,0,0,0,0,0,0,10,12,10,0,0,0,0,0,0
0,0,0,0,0,0,0,0,0,0,0,0,0,0,0,0,0,0,0,0,10,10,10,0,0,0,0,0,0
0,0,0,0,0,0,0,0,0,0,0,0,0,0,0,0,0,0,0,0,0,0,0,0,0,0,0,0,0
0,0,0,0,0,0,0,0,0,0,0,0,0,0,0,0,0,0,0,0,0,0,0,0,0,0,0,0,0
0,0,0,0,0,0,0,0,0,0,0,0,0,0,0,0,0,0,0,0,0,0,0,0,0,0,0,0,0
0,0,0,0,0,0,0,0,0,0,0,0,0,0,0,0,0,0,0,0,0,0,0,0,0,0,0,0,0
0,0,0,0,0,0,0,0,0,0,0,0,0,0,0,0,0,0,0,0,0,0,0,0,0,0,0,0,0
0,0,0,0,0,0,0,0,0,0,0,0,0,0,0,0,0,0,0,0,0,0,0,0,0,0,0,0,0
endlayer

layer
0,0,0,0,0,0,0,0,0,0,0,0,0,0,0,0,0,0,0,0,0,0,0,0,0,0,0,0,0
0,0,0,0,0,0,0,0,0,0,0,0,0,0,0,0,0,0,0,0,0,0,0,0,0,0,0,0,0
0,0,0,0,0,0,0,0,0,0,0,0,0,0,0,0,0,0,0,0,0,0,0,0,0,0,0,0,0
0,0,0,0,0,0,0,0,0,0,0,0,0,0,0,0,0,0,0,0,0,0,0,0,0,0,0,0,0
0,0,0,0,0,0,0,0,0,0,0,0,0,0,0,0,0,0,0,0,0,0,0,0,0,0,0,0,0
0,0,0,0,0,0,0,0,0,0,0,0,0,0,0,0,0,0,0,0,0,0,0,0,0,0,0,0,0
0,0,0,0,0,0,0,0,0,0,0,0,0,0,0,0,0,0,0,0,0,0,0,0,0,0,0,0,0
0,0,0,0,0,0,0,0,0,0,0,0,0,0,0,0,0,0,0,0,0,10,0,0,0,0,0,0,0
0,0,0,0,0,0,0,0,0,0,0,0,0,0,0,0,0,0,0,0,0,0,0,0,0,0,0,0,0
0,0,0,0,0,0,0,0,0,0,0,0,0,0,0,0,0,0,0,0,0,0,0,0,0,0,0,0,0
0,0,0,0,0,0,0,0,0,0,0,0,0,0,0,0,0,0,0,0,0,0,0,0,0,0,0,0,0
0,0,0,0,0,0,0,0,0,0,0,0,0,0,0,0,0,0,0,0,0,0,0,0,0,0,0,0,0
0,0,0,0,0,0,0,0,0,0,0,0,0,0,0,0,0,0,0,0,0,0,0,0,0,0,0,0,0
0,0,0,0,0,0,0,0,0,0,0,0,0,0,0,0,0,0,0,0,0,0,0,0,0,0,0,0,0
0,0,0,0,0,0,0,0,0,0,0,0,0,0,0,0,0,0,0,0,0,0,0,0,0,0,0,0,0
endlayer

layer
0,0,0,0,0,0,0,0,0,0,0,0,0,0,0,0,0,0,0,0,0,0,0,0,0,0,0,0,0
0,0,0,0,0,0,0,0,0,0,0,0,0,0,0,0,0,0,0,0,0,0,0,0,0,0,0,0,0
0,0,0,0,0,0,0,0,0,0,0,0,0,0,0,0,0,0,0,0,0,0,0,0,0,0,0,0,0
0,0,0,0,0,0,0,0,0,0,0,0,0,0,0,0,0,0,0,0,0,0,0,0,0,0,0,0,0
0,0,0,0,0,0,0,0,0,0,0,0,0,0,0,0,0,0,0,0,0,0,0,0,0,0,0,0,0
0,0,0,0,0,0,0,0,0,0,0,0,0,0,0,0,0,0,0,0,0,0,0,0,0,0,0,0,0
0,0,0,0,0,0,0,0,0,0,0,0,0,0,0,0,0,0,0,0,0,0,0,0,0,0,0,0,0
0,0,0,0,0,0,0,0,0,0,0,0,0,0,0,0,0,0,0,0,0,10,0,0,0,0,0,0,0
0,0,0,0,0,0,0,0,0,0,0,0,0,0,0,0,0,0,0,0,0,0,0,0,0,0,0,0,0
0,0,0,0,0,0,0,0,0,0,0,0,0,0,0,0,0,0,0,0,0,0,0,0,0,0,0,0,0
0,0,0,0,0,0,0,0,0,0,0,0,0,0,0,0,0,0,0,0,0,0,0,0,0,0,0,0,0
0,0,0,0,0,0,0,0,0,0,0,0,0,0,0,0,0,0,0,0,0,0,0,0,0,0,0,0,0
0,0,0,0,0,0,0,0,0,0,0,0,0,0,0,0,0,0,0,0,0,0,0,0,0,0,0,0,0
0,0,0,0,0,0,0,0,0,0,0,0,0,0,0,0,0,0,0,0,0,0,0,0,0,0,0,0,0
0,0,0,0,0,0,0,0,0,0,0,0,0,0,0,0,0,0,0,0,0,0,0,0,0,0,0,0,0
endlayer

layer
0,0,0,0,0,0,0,0,0,0,0,0,0,0,0,0,0,0,0,0,0,0,0,0,0,0,0,0,0
0,0,0,0,0,0,0,0,0,0,0,0,0,0,0,0,0,0,0,0,0,0,0,0,0,0,0,0,0
0,0,0,0,0,0,0,0,0,0,0,0,0,0,0,0,0,0,0,0,0,0,0,0,0,0,0,0,0
0,0,0,0,0,0,0,0,0,0,0,0,0,0,0,0,0,0,0,0,0,0,0,0,0,0,0,0,0
0,0,0,0,0,0,0,0,0,0,0,0,0,0,0,0,0,0,0,0,0,0,0,0,0,0,0,0,0
0,0,0,0,0,0,0,0,0,0,0,0,0,0,0,0,0,0,0,0,0,0,0,0,0,0,0,0,0
0,0,0,0,0,0,0,0,0,0,0,0,0,0,0,0,0,0,0,0,0,0,0,0,0,0,0,0,0
0,0,0,0,0,0,0,0,0,0,0,0,0,0,0,0,0,0,0,0,0,10,0,0,0,0,0,0,0
0,0,0,0,0,0,0,0,0,0,0,0,0,0,0,0,0,0,0,0,0,0,0,0,0,0,0,0,0
0,0,0,0,0,0,0,0,0,0,0,0,0,0,0,0,0,0,0,0,0,0,0,0,0,0,0,0,0
0,0,0,0,0,0,0,0,0,0,0,0,0,0,0,0,0,0,0,0,0,0,0,0,0,0,0,0,0
0,0,0,0,0,0,0,0,0,0,0,0,0,0,0,0,0,0,0,0,0,0,0,0,0,0,0,0,0
0,0,0,0,0,0,0,0,0,0,0,0,0,0,0,0,0,0,0,0,0,0,0,0,0,0,0,0,0
0,0,0,0,0,0,0,0,0,0,0,0,0,0,0,0,0,0,0,0,0,0,0,0,0,0,0,0,0
0,0,0,0,0,0,0,0,0,0,0,0,0,0,0,0,0,0,0,0,0,0,0,0,0,0,0,0,0
endlayer

layer
0,0,0,0,0,0,0,0,0,0,0,0,0,0,0,0,0,0,0,0,0,0,0,0,0,0,0,0,0
0,0,0,0,0,0,0,0,0,0,0,0,0,0,0,0,0,0,0,0,0,0,0,0,0,0,0,0,0
0,0,0,0,0,0,0,0,0,0,0,0,0,0,0,0,0,0,0,0,0,0,0,0,0,0,0,0,0
0,0,0,0,0,0,0,0,0,0,0,0,0,0,0,0,0,0,0,0,0,0,0,0,0,0,0,0,0
0,0,0,0,0,0,0,0,0,0,0,0,0,0,0,0,0,0,0,0,0,0,0,0,0,0,0,0,0
0,0,0,0,0,0,0,0,0,0,0,0,0,0,0,0,0,0,0,0,0,0,0,0,0,0,0,0,0
0,0,0,0,0,0,0,0,0,0,0,0,0,0,0,0,0,0,0,0,0,0,0,0,0,0,0,0,0
0,0,0,0,0,0,0,0,0,0,0,0,0,0,0,0,0,0,0,0,0,10,0,0,0,0,0,0,0
0,0,0,0,0,0,0,0,0,0,0,0,0,0,0,0,0,0,0,0,0,0,0,0,0,0,0,0,0
0,0,0,0,0,0,0,0,0,0,0,0,0,0,0,0,0,0,0,0,0,0,0,0,0,0,0,0,0
0,0,0,0,0,0,0,0,0,0,0,0,0,0,0,0,0,0,0,0,0,0,0,0,0,0,0,0,0
0,0,0,0,0,0,0,0,0,0,0,0,0,0,0,0,0,0,0,0,0,0,0,0,0,0,0,0,0
0,0,0,0,0,0,0,0,0,0,0,0,0,0,0,0,0,0,0,0,0,0,0,0,0,0,0,0,0
0,0,0,0,0,0,0,0,0,0,0,0,0,0,0,0,0,0,0,0,0,0,0,0,0,0,0,0,0
0,0,0,0,0,0,0,0,0,0,0,0,0,0,0,0,0,0,0,0,0,0,0,0,0,0,0,0,0
endlayer

layer
0,0,0,0,0,0,0,0,0,0,0,0,0,0,0,0,0,0,0,0,0,0,0,0,0,0,0,0,0
0,0,0,0,0,0,0,0,0,0,0,0,0,0,0,0,0,0,0,0,0,0,0,0,0,0,0,0,0
0,0,0,0,0,0,0,0,0,0,0,0,0,0,0,0,0,0,0,0,0,0,0,0,0,0,0,0,0
0,0,0,0,0,0,0,0,0,0,0,0,0,0,0,0,0,0,0,0,0,0,0,0,0,0,0,0,0
0,0,0,0,0,0,0,0,0,0,0,0,0,0,0,0,0,0,0,0,0,0,0,0,0,0,0,0,0
0,0,0,0,0,0,0,0,0,0,0,0,0,0,0,0,0,0,0,0,0,0,0,0,0,0,0,0,0
0,0,0,0,0,0,0,0,0,0,0,0,0,0,0,0,0,0,0,0,0,0,0,0,0,0,0,0,0
0,0,0,0,0,0,0,0,0,0,0,0,0,0,0,0,0,0,0,0,0,10,0,0,0,0,0,0,0
0,0,0,0,0,0,0,0,0,0,0,0,0,0,0,0,0,0,0,0,0,0,0,0,0,0,0,0,0
0,0,0,0,0,0,0,0,0,0,0,0,0,0,0,0,0,0,0,0,0,0,0,0,0,0,0,0,0
0,0,0,0,0,0,0,0,0,0,0,0,0,0,0,0,0,0,0,0,0,0,0,0,0,0,0,0,0
0,0,0,0,0,0,0,0,0,0,0,0,0,0,0,0,0,0,0,0,0,0,0,0,0,0,0,0,0
0,0,0,0,0,0,0,0,0,0,0,0,0,0,0,0,0,0,0,0,0,0,0,0,0,0,0,0,0
0,0,0,0,0,0,0,0,0,0,0,0,0,0,0,0,0,0,0,0,0,0,0,0,0,0,0,0,0
0,0,0,0,0,0,0,0,0,0,0,0,0,0,0,0,0,0,0,0,0,0,0,0,0,0,0,0,0
endlayer

