weight=1
embed_into_distance=11
acceptable_target_blocks=1,2,3,12,13,250
dimensions=45,15,29
allowable_overhang=0
max_cut_in=0
cut_in_buffer=0
max_leveling=2
leveling_buffer=1
preserve_water=0
preserve_lava=0
preserve_plants=0


rule1=0,100,3134-10
rule2=0,100,300
rule3=0,100,2843-14,2843-14,2843-14,2843-14,2843
rule4=0,100,2843-4
rule5=0,100,622,2838-4,2838-4,2838-4,2838-4,2838-4,2838-4,2838-4,2838-4,2838-4
rule6=0,66,308,308,308,308,308,308,313,313,314,327,311,311
rule7=0,25,3225-3
rule8=0,95,2835-2,2835-2,2835-2,2835-2,2835-2,2835-2,2835-2,2835-1,2835-1,2835-0
rule9=0,66,623
rule10=0,95,300
rule11=0,100,3134,3134,3134,3134-8,3134-2

layer
1,1,1,1,1,1,1,1,1,1,1,1,1,1,1,1,1,1,1,1,1,1,1,1,1,1,1,1,1
1,1,1,1,1,1,1,1,1,1,1,1,1,1,1,1,1,1,1,1,1,1,1,1,1,1,1,1,1
1,1,2,2,2,3,3,3,3,3,2,2,2,2,1,2,2,2,2,3,3,3,3,3,2,2,2,1,1
1,1,2,2,3,4,4,4,4,4,2,2,2,2,1,2,2,2,2,4,4,4,4,4,3,2,2,1,1
1,1,2,3,4,4,4,4,4,4,4,2,2,2,1,2,2,2,4,4,4,4,4,4,4,3,2,1,1
1,1,3,4,4,4,4,4,4,4,4,4,2,2,1,2,2,4,4,4,4,4,4,4,4,4,3,1,1
1,1,3,4,4,4,4,4,4,4,4,4,4,2,4,2,4,4,4,4,4,4,4,4,4,4,3,1,1
1,1,3,4,4,4,4,4,4,4,4,4,4,4,5,4,4,4,4,4,4,4,4,4,4,4,3,1,1
1,1,3,4,4,4,4,4,4,4,4,4,4,4,4,4,4,4,4,4,4,4,4,4,4,4,3,1,1
1,1,3,4,4,4,4,4,4,4,4,4,4,2,2,2,4,4,4,4,4,4,4,4,4,4,3,1,1
1,1,2,3,4,4,4,4,4,4,4,2,2,2,2,2,2,2,4,4,4,4,4,4,4,3,2,1,1
1,1,2,2,3,4,4,4,4,4,2,2,2,2,2,2,2,2,2,4,4,4,4,4,3,2,2,1,1
1,1,2,2,2,3,3,3,3,3,2,2,2,2,2,2,2,2,2,3,3,3,3,3,2,2,2,1,1
1,1,1,1,1,1,1,1,1,1,1,1,1,1,1,1,1,1,1,1,1,1,1,1,1,1,1,1,1
1,1,1,1,1,1,1,1,1,1,1,1,1,1,1,1,1,1,1,1,1,1,1,1,1,1,1,1,1
endlayer

layer
2,2,2,2,2,2,2,2,2,2,2,2,2,2,2,2,2,2,2,2,2,2,2,2,2,2,2,2,2
2,2,2,2,2,2,2,2,2,2,2,2,2,2,2,2,2,2,2,2,2,2,2,2,2,2,2,2,2
2,2,2,2,2,3,3,3,3,3,2,2,2,2,2,2,2,2,2,3,3,3,3,3,2,2,2,2,2
2,2,2,2,3,0,0,0,0,0,3,2,2,2,2,2,2,2,3,0,0,0,0,0,3,2,2,2,2
2,2,2,3,6,0,0,0,0,0,0,3,2,2,2,2,2,3,0,0,0,0,0,0,6,3,2,2,2
2,2,3,0,0,0,0,0,0,0,0,0,3,2,2,2,3,0,0,0,0,0,0,0,0,0,3,2,2
2,2,3,0,0,0,0,0,0,0,0,0,0,3,0,3,0,0,0,0,0,0,0,0,0,0,3,2,2
2,2,3,0,0,0,0,0,0,0,0,0,0,0,0,0,0,0,0,0,0,0,0,0,0,0,3,2,2
2,2,3,0,0,0,0,0,0,0,0,0,0,3,3,3,0,0,0,0,0,0,0,0,0,0,3,2,2
2,2,3,0,0,0,0,0,0,0,0,0,3,2,2,2,3,0,0,0,0,0,0,0,0,0,3,2,2
2,2,2,3,6,0,0,0,0,0,0,3,2,2,2,2,2,3,0,0,0,0,0,0,6,3,2,2,2
2,2,2,2,3,0,0,0,0,0,3,2,2,2,2,2,2,2,3,0,0,0,0,0,3,2,2,2,2
2,2,2,2,2,3,3,3,3,3,2,2,2,2,2,2,2,2,2,3,3,3,3,3,2,2,2,2,2
2,2,2,2,2,2,2,2,2,2,2,2,2,2,2,2,2,2,2,2,2,2,2,2,2,2,2,2,2
2,2,2,2,2,2,2,2,2,2,2,2,2,2,2,2,2,2,2,2,2,2,2,2,2,2,2,2,2
endlayer

layer
2,2,2,2,2,2,2,2,2,2,2,2,2,2,2,2,2,2,2,2,2,2,2,2,2,2,2,2,2
2,2,2,2,2,2,2,2,2,2,2,2,2,2,2,2,2,2,2,2,2,2,2,2,2,2,2,2,2
2,2,2,2,2,7,8,7,8,7,2,2,2,2,2,2,2,2,2,7,8,7,8,7,2,2,2,2,2
2,2,2,2,3,0,0,0,0,0,3,2,2,2,2,2,2,2,3,0,0,0,0,0,3,2,2,2,2
2,2,2,3,0,0,0,0,0,0,0,3,2,2,2,2,2,3,0,0,0,0,0,0,0,3,2,2,2
2,2,7,0,0,0,0,0,0,0,0,0,7,2,2,2,7,0,0,0,0,0,0,0,0,0,7,2,2
2,2,8,0,0,0,0,0,0,0,0,0,0,8,0,8,0,0,0,0,0,0,0,0,0,0,8,2,2
2,2,7,0,0,0,0,0,0,0,0,0,0,0,0,0,0,0,0,0,0,0,0,0,0,0,7,2,2
2,2,8,0,0,0,0,0,0,0,0,0,0,8,7,8,0,0,0,0,0,0,0,0,0,0,8,2,2
2,2,7,0,0,0,0,0,0,0,0,0,7,2,2,2,7,0,0,0,0,0,0,0,0,0,7,2,2
2,2,2,3,0,0,0,0,0,0,0,3,2,2,2,2,2,3,0,0,0,0,0,0,0,3,2,2,2
2,2,2,2,3,0,0,0,0,0,3,2,2,2,2,2,2,2,3,0,0,0,0,0,3,2,2,2,2
2,2,2,2,2,7,8,7,8,7,2,2,2,2,2,2,2,2,2,7,8,7,8,7,2,2,2,2,2
2,2,2,2,2,2,2,2,2,2,2,2,2,2,2,2,2,2,2,2,2,2,2,2,2,2,2,2,2
2,2,2,2,2,2,2,2,2,2,2,2,2,2,2,2,2,2,2,2,2,2,2,2,2,2,2,2,2
endlayer

layer
2,2,2,2,2,2,2,2,2,2,2,2,2,2,2,2,2,2,2,2,2,2,2,2,2,2,2,2,2
2,2,2,2,2,2,2,2,2,2,2,2,2,2,2,2,2,2,2,2,2,2,2,2,2,2,2,2,2
2,2,2,2,2,7,8,7,8,7,2,2,2,2,2,2,2,2,2,7,8,7,8,7,2,2,2,2,2
2,2,2,2,3,0,0,0,0,0,3,2,2,2,2,2,2,2,3,0,0,0,0,0,3,2,2,2,2
2,2,2,3,0,0,0,0,0,0,0,3,2,2,2,2,2,3,0,0,0,0,0,0,0,3,2,2,2
2,2,7,0,0,0,0,0,0,0,0,0,7,2,2,2,7,0,0,0,0,0,0,0,0,0,7,2,2
2,2,8,0,0,0,0,0,0,0,0,0,0,8,8,8,0,0,0,0,0,0,0,0,0,0,8,2,2
2,2,7,0,0,0,0,0,0,0,0,0,0,0,0,0,0,0,0,0,0,0,0,0,0,0,7,2,2
2,2,8,0,0,0,0,0,0,0,0,0,0,8,7,8,0,0,0,0,0,0,0,0,0,0,8,2,2
2,2,7,0,0,0,0,0,0,0,0,0,7,2,2,2,7,0,0,0,0,0,0,0,0,0,7,2,2
2,2,2,3,0,0,0,0,0,0,0,3,2,2,2,2,2,3,0,0,0,0,0,0,0,3,2,2,2
2,2,2,2,3,0,0,0,0,0,3,2,2,2,2,2,2,2,3,0,0,0,0,0,3,2,2,2,2
2,2,2,2,2,7,8,7,8,7,2,2,2,2,2,2,2,2,2,7,8,7,8,7,2,2,2,2,2
2,2,2,2,2,2,2,2,2,2,2,2,2,2,2,2,2,2,2,2,2,2,2,2,2,2,2,2,2
2,2,2,2,2,2,2,2,2,2,2,2,2,2,2,2,2,2,2,2,2,2,2,2,2,2,2,2,2
endlayer

layer
2,2,2,2,2,2,2,2,2,2,2,2,2,2,2,2,2,2,2,2,2,2,2,2,2,2,2,2,2
2,2,2,2,2,2,2,2,2,2,2,2,2,2,2,2,2,2,2,2,2,2,2,2,2,2,2,2,2
2,2,2,2,2,7,8,7,8,7,2,2,2,2,2,2,2,2,2,7,8,7,8,7,2,2,2,2,2
2,2,2,2,3,0,0,0,0,0,3,2,2,2,2,2,2,2,3,0,0,0,0,0,3,2,2,2,2
2,2,2,3,0,0,0,0,0,0,0,3,2,2,2,2,2,3,0,0,0,0,0,0,0,3,2,2,2
2,2,7,0,0,0,0,0,0,0,0,0,7,2,2,2,7,0,0,0,0,0,0,0,0,0,7,2,2
2,2,8,0,0,0,0,0,0,0,0,0,0,8,7,8,0,0,0,0,0,0,0,0,0,0,8,2,2
2,2,7,0,0,0,0,0,0,0,0,0,0,7,0,7,0,0,0,0,0,0,0,0,0,0,7,2,2
2,2,8,0,0,0,0,0,0,0,0,0,0,8,7,8,0,0,0,0,0,0,0,0,0,0,8,2,2
2,2,7,0,0,0,0,0,0,0,0,0,7,2,2,2,7,0,0,0,0,0,0,0,0,0,7,2,2
2,2,2,3,0,0,0,0,0,0,0,3,2,2,2,2,2,3,0,0,0,0,0,0,0,3,2,2,2
2,2,2,2,3,0,0,0,0,0,3,2,2,2,2,2,2,2,3,0,0,0,0,0,3,2,2,2,2
2,2,2,2,2,7,8,7,8,7,2,2,2,2,2,2,2,2,2,7,8,7,8,7,2,2,2,2,2
2,2,2,2,2,2,2,2,2,2,2,2,2,2,2,2,2,2,2,2,2,2,2,2,2,2,2,2,2
2,2,2,2,2,2,2,2,2,2,2,2,2,2,2,2,2,2,2,2,2,2,2,2,2,2,2,2,2
endlayer

layer
2,2,2,2,2,2,2,2,2,2,2,2,2,2,2,2,2,2,2,2,2,2,2,2,2,2,2,2,2
2,2,2,2,2,2,2,2,2,2,2,2,2,2,2,2,2,2,2,2,2,2,2,2,2,2,2,2,2
2,2,2,2,2,7,8,7,8,7,2,2,2,2,2,2,2,2,2,7,8,7,8,7,2,2,2,2,2
2,2,2,2,3,0,0,0,0,0,3,2,2,2,2,2,2,2,3,0,0,0,0,0,3,2,2,2,2
2,2,2,3,0,0,0,0,0,0,0,3,2,2,2,2,2,3,0,0,0,0,0,0,0,3,2,2,2
2,2,7,0,0,0,0,0,0,0,0,0,7,2,2,2,7,0,0,0,0,0,0,0,0,0,7,2,2
2,2,8,0,0,0,0,0,0,0,0,0,0,8,7,8,0,0,0,0,0,0,0,0,0,0,8,2,2
2,2,7,0,0,0,0,0,0,0,0,0,0,7,9,7,0,0,0,0,0,0,0,0,0,0,7,2,2
2,2,8,0,0,0,0,0,0,0,0,0,0,8,7,8,0,0,0,0,0,0,0,0,0,0,8,2,2
2,2,7,0,0,0,0,0,0,0,0,0,7,2,2,2,7,0,0,0,0,0,0,0,0,0,7,2,2
2,2,2,3,0,0,0,0,0,0,0,3,2,2,2,2,2,3,0,0,0,0,0,0,0,3,2,2,2
2,2,2,2,3,0,0,0,0,0,3,2,2,2,2,2,2,2,3,0,0,0,0,0,3,2,2,2,2
2,2,2,2,2,7,8,7,8,7,2,2,2,2,2,2,2,2,2,7,8,7,8,7,2,2,2,2,2
2,2,2,2,2,2,2,2,2,2,2,2,2,2,2,2,2,2,2,2,2,2,2,2,2,2,2,2,2
2,2,2,2,2,2,2,2,2,2,2,2,2,2,2,2,2,2,2,2,2,2,2,2,2,2,2,2,2
endlayer

layer
2,2,2,2,2,2,2,2,2,2,2,2,2,2,2,2,2,2,2,2,2,2,2,2,2,2,2,2,2
2,2,2,2,2,2,2,2,2,2,2,2,2,2,2,2,2,2,2,2,2,2,2,2,2,2,2,2,2
2,2,2,2,2,7,8,7,8,7,2,2,2,2,2,2,2,2,2,7,8,7,8,7,2,2,2,2,2
2,2,2,2,3,0,0,0,0,0,3,2,2,2,2,2,2,2,3,0,0,0,0,0,3,2,2,2,2
2,2,2,3,0,0,0,0,0,0,0,3,2,2,2,2,2,3,0,0,0,0,0,0,0,3,2,2,2
2,2,7,0,0,0,0,0,0,0,0,0,7,2,2,2,7,0,0,0,0,0,0,0,0,0,7,2,2
2,2,8,0,0,0,0,0,0,0,0,0,0,8,7,8,0,0,0,0,0,0,0,0,0,0,8,2,2
2,2,7,0,0,0,0,0,0,0,0,0,0,7,0,7,0,0,0,0,0,0,0,0,0,0,7,2,2
2,2,8,0,0,0,0,0,0,0,0,0,0,8,7,8,0,0,0,0,0,0,0,0,0,0,8,2,2
2,2,7,0,0,0,0,0,0,0,0,0,7,2,2,2,7,0,0,0,0,0,0,0,0,0,7,2,2
2,2,2,3,0,0,0,0,0,0,0,3,2,2,2,2,2,3,0,0,0,0,0,0,0,3,2,2,2
2,2,2,2,3,0,0,0,0,0,3,2,2,2,2,2,2,2,3,0,0,0,0,0,3,2,2,2,2
2,2,2,2,2,7,8,7,8,7,2,2,2,2,2,2,2,2,2,7,8,7,8,7,2,2,2,2,2
2,2,2,2,2,2,2,2,2,2,2,2,2,2,2,2,2,2,2,2,2,2,2,2,2,2,2,2,2
2,2,2,2,2,2,2,2,2,2,2,2,2,2,2,2,2,2,2,2,2,2,2,2,2,2,2,2,2
endlayer

layer
2,2,2,2,2,2,2,2,2,2,2,2,2,2,2,2,2,2,2,2,2,2,2,2,2,2,2,2,2
2,2,2,2,2,2,2,2,2,2,2,2,2,2,2,2,2,2,2,2,2,2,2,2,2,2,2,2,2
2,2,2,2,2,3,3,3,3,3,2,2,2,2,2,2,2,2,2,3,3,3,3,3,2,2,2,2,2
2,2,2,2,3,4,4,4,4,4,3,2,2,2,2,2,2,2,3,4,4,4,4,4,3,2,2,2,2
2,2,2,3,4,4,4,4,4,4,4,3,2,2,2,2,2,3,4,4,4,4,4,4,4,3,2,2,2
2,2,3,4,4,4,4,4,4,4,4,4,3,2,2,2,3,4,4,4,4,4,4,4,4,4,3,2,2
2,2,3,4,4,4,4,4,4,4,4,4,4,3,3,3,4,4,4,4,4,4,4,4,4,4,3,2,2
2,2,3,4,4,4,4,4,4,4,4,4,4,4,9,4,4,4,4,4,4,4,4,4,4,4,3,2,2
2,2,3,4,4,4,4,4,4,4,4,4,4,3,3,3,4,4,4,4,4,4,4,4,4,4,3,2,2
2,2,3,4,4,4,4,4,4,4,4,4,3,2,2,2,3,4,4,4,4,4,4,4,4,4,3,2,2
2,2,2,3,4,4,4,4,4,4,4,3,2,2,2,2,2,3,4,4,4,4,4,4,4,3,2,2,2
2,2,2,2,3,4,4,4,4,4,3,2,2,2,2,2,2,2,3,4,4,4,4,4,3,2,2,2,2
2,2,2,2,2,3,3,3,3,3,2,2,2,2,2,2,2,2,2,3,3,3,3,3,2,2,2,2,2
2,2,2,2,2,2,2,2,2,2,2,2,2,2,2,2,2,2,2,2,2,2,2,2,2,2,2,2,2
2,2,2,2,2,2,2,2,2,2,2,2,2,2,2,2,2,2,2,2,2,2,2,2,2,2,2,2,2
endlayer

layer
2,2,2,2,2,2,2,2,2,2,2,2,2,2,2,2,2,2,2,2,2,2,2,2,2,2,2,2,2
2,2,2,2,2,2,2,2,2,2,2,2,2,2,2,2,2,2,2,2,2,2,2,2,2,2,2,2,2
2,2,2,2,2,7,8,7,8,2,2,2,2,2,2,2,2,2,2,7,8,7,8,7,2,2,2,2,2
2,2,2,2,3,0,0,0,0,0,3,2,2,2,2,2,2,2,3,2,0,0,0,2,3,2,2,2,2
2,2,2,3,6,0,0,0,0,0,0,3,2,2,2,2,2,3,2,0,0,0,0,2,6,3,2,2,2
2,2,7,2,0,0,0,0,0,0,0,0,7,2,2,2,7,0,0,0,0,0,0,0,0,0,7,2,2
2,2,8,0,0,2,0,0,0,0,0,0,0,8,7,8,0,0,0,0,0,0,0,0,0,2,8,2,2
2,2,2,2,2,0,0,0,0,0,0,0,0,0,0,0,0,0,0,0,0,0,0,0,0,2,2,2,2
2,2,8,2,0,0,0,0,0,0,0,0,0,8,7,8,0,0,0,0,0,0,0,0,0,2,8,2,2
2,2,2,2,0,0,0,0,0,0,0,0,7,2,2,2,7,0,0,0,0,0,0,0,0,2,7,2,2
2,2,2,3,6,0,0,0,0,0,0,3,2,2,2,2,2,3,0,0,0,0,0,0,6,3,2,2,2
2,2,2,2,3,0,0,0,0,2,3,2,2,2,2,2,2,2,3,0,0,0,0,0,3,2,2,2,2
2,2,2,2,2,2,8,7,8,7,2,2,2,2,2,2,2,2,2,7,8,7,8,7,2,2,2,2,2
2,2,2,2,2,2,2,2,2,2,2,2,2,2,2,2,2,2,2,2,2,2,2,2,2,2,2,2,2
2,2,2,2,2,2,2,2,2,2,2,2,2,2,2,2,2,2,2,2,2,2,2,2,2,2,2,2,2
endlayer

layer
2,2,2,2,2,2,2,2,2,2,2,2,2,2,2,2,2,2,2,2,2,2,2,2,2,2,2,2,2
2,2,2,2,2,2,2,2,2,2,2,2,2,2,2,2,2,2,2,2,2,2,2,2,2,2,2,2,2
2,2,2,2,2,7,8,2,8,7,2,2,2,2,2,2,2,2,2,7,8,7,8,2,2,2,2,2,2
2,2,2,2,3,0,0,0,0,0,3,2,2,2,2,2,2,2,3,0,0,0,0,0,3,2,2,2,2
2,2,2,3,0,0,0,0,0,0,0,3,2,2,2,2,2,3,0,0,0,0,0,0,0,3,2,2,2
2,2,2,0,0,0,0,0,0,0,0,0,2,2,2,2,7,0,0,0,0,0,0,0,0,0,7,2,2
2,2,8,0,0,0,0,0,0,0,0,0,0,8,7,8,0,0,0,0,0,0,0,0,0,0,8,2,2
2,2,7,0,0,0,0,0,0,0,0,0,0,0,9,0,0,0,0,0,0,0,0,0,0,2,2,2,2
2,2,8,0,0,0,0,0,0,0,0,0,0,8,7,8,0,0,0,0,0,0,0,0,0,0,8,2,2
2,2,2,0,0,0,0,0,0,0,0,0,2,2,2,2,7,0,0,0,0,0,0,0,0,0,2,2,2
2,2,2,3,0,0,0,0,0,0,0,3,2,2,2,2,2,3,0,0,0,0,0,0,0,3,2,2,2
2,2,2,2,3,0,0,0,0,0,3,2,2,2,2,2,2,2,3,0,0,0,0,0,3,2,2,2,2
2,2,2,2,2,7,8,2,8,2,2,2,2,2,2,2,2,2,2,7,8,7,8,7,2,2,2,2,2
2,2,2,2,2,2,2,2,2,2,2,2,2,2,2,2,2,2,2,2,2,2,2,2,2,2,2,2,2
2,2,2,2,2,2,2,2,2,2,2,2,2,2,2,2,2,2,2,2,2,2,2,2,2,2,2,2,2
endlayer

layer
10,10,10,10,10,10,10,10,10,10,10,10,10,10,10,10,10,10,10,10,10,10,10,10,10,10,10,10,10
10,10,10,10,10,10,10,10,10,10,10,10,10,10,10,10,10,10,10,10,10,10,10,10,10,10,10,10,10
10,10,10,10,10,7,8,0,8,7,10,10,10,10,10,10,10,10,10,0,8,7,8,0,10,10,10,10,10
10,10,10,10,3,0,0,0,0,0,3,10,10,10,10,10,10,10,3,0,0,0,0,0,3,10,10,10,10
10,10,10,3,0,0,0,0,0,0,0,3,10,10,10,10,10,3,0,0,0,0,0,0,0,3,10,10,10
10,10,7,0,0,0,0,0,0,0,0,0,7,10,10,10,7,0,0,0,0,0,0,0,0,0,0,10,10
10,10,8,0,0,0,0,0,0,0,0,0,0,8,7,8,0,0,0,0,0,0,0,0,0,0,8,10,10
10,10,10,0,0,0,0,0,0,0,0,0,0,7,0,7,0,0,0,0,0,0,0,0,0,0,0,10,10
10,10,8,0,0,0,0,0,0,0,0,0,0,8,7,8,0,0,0,0,0,0,0,0,0,0,8,10,10
10,10,7,0,0,0,0,0,0,0,0,0,7,10,10,10,7,0,0,0,0,0,0,0,0,0,0,10,10
10,10,10,3,0,0,0,0,0,0,0,3,10,10,10,10,10,3,0,0,0,0,0,0,0,3,10,10,10
10,10,10,10,3,0,0,0,0,0,3,10,10,10,10,10,10,10,3,0,0,0,0,0,3,10,10,10,10
10,10,10,10,10,7,8,7,8,10,10,10,10,10,10,10,10,10,10,7,8,7,8,7,10,10,10,10,10
10,10,10,10,10,10,10,10,10,10,10,10,10,10,10,10,10,10,10,10,10,10,10,10,10,10,10,10,10
10,10,10,10,10,10,10,10,10,10,10,10,10,10,10,10,10,10,10,10,10,10,10,10,10,10,10,10,10
endlayer

layer
0,0,0,0,0,0,0,0,0,0,0,0,0,0,0,0,0,0,0,0,0,0,0,0,0,0,0,0,0
0,0,0,0,0,0,0,0,0,0,0,0,0,0,0,0,0,0,0,0,0,0,0,0,0,0,0,0,0
0,0,0,0,0,7,8,0,8,7,0,0,0,0,0,0,0,0,0,0,8,7,8,7,0,0,0,0,0
0,0,0,0,3,0,0,0,0,0,3,0,0,0,0,0,0,0,3,0,0,0,0,0,3,0,0,0,0
0,0,0,3,0,0,0,0,0,0,0,3,0,0,0,0,0,3,0,0,0,0,0,0,0,3,0,0,0
0,0,7,0,0,0,0,0,0,0,0,0,7,0,0,0,0,0,0,0,0,0,0,0,0,0,7,0,0
0,0,8,0,0,0,0,0,0,0,0,0,0,8,7,8,0,0,0,0,0,0,0,0,0,0,8,0,0
0,0,7,0,0,0,0,0,0,0,0,0,0,7,9,7,0,0,0,0,0,0,0,0,0,0,0,0,0
0,0,8,0,0,0,0,0,0,0,0,0,0,8,7,8,0,0,0,0,0,0,0,0,0,0,8,0,0
0,0,7,0,0,0,0,0,0,0,0,0,7,0,0,0,7,0,0,0,0,0,0,0,0,0,0,0,0
0,0,0,3,0,0,0,0,0,0,0,3,0,0,0,0,0,3,0,0,0,0,0,0,0,3,0,0,0
0,0,0,0,3,0,0,0,0,0,3,0,0,0,0,0,0,0,3,0,0,0,0,0,3,0,0,0,0
0,0,0,0,0,7,8,7,8,7,0,0,0,0,0,0,0,0,0,7,8,7,8,7,0,0,0,0,0
0,0,0,0,0,0,0,0,0,0,0,0,0,0,0,0,0,0,0,0,0,0,0,0,0,0,0,0,0
0,0,0,0,0,0,0,0,0,0,0,0,0,0,0,0,0,0,0,0,0,0,0,0,0,0,0,0,0
endlayer

layer
0,0,0,0,0,0,0,0,0,0,0,0,0,0,0,0,0,0,0,0,0,0,0,0,0,0,0,0,0
0,0,0,0,0,0,0,0,0,0,0,0,0,0,0,0,0,0,0,0,0,0,0,0,0,0,0,0,0
0,0,0,0,0,7,8,7,8,7,0,0,0,0,0,0,0,0,0,0,8,7,8,7,0,0,0,0,0
0,0,0,0,3,0,0,0,0,0,3,0,0,0,0,0,0,0,3,0,0,0,0,0,3,0,0,0,0
0,0,0,3,0,0,0,0,0,0,0,3,0,0,0,0,0,0,0,0,0,0,0,0,0,3,0,0,0
0,0,7,0,0,0,0,0,0,0,0,0,0,0,0,0,0,0,0,0,0,0,0,0,0,0,0,0,0
0,0,8,0,0,0,0,0,0,0,0,0,0,8,0,8,0,0,0,0,0,0,0,0,0,0,8,0,0
0,0,7,0,0,0,0,0,0,0,0,0,0,7,0,7,0,0,0,0,0,0,0,0,0,0,7,0,0
0,0,8,0,0,0,0,0,0,0,0,0,0,8,7,8,0,0,0,0,0,0,0,0,0,0,8,0,0
0,0,7,0,0,0,0,0,0,0,0,0,7,0,0,0,7,0,0,0,0,0,0,0,0,0,0,0,0
0,0,0,3,0,0,0,0,0,0,0,3,0,0,0,0,0,3,0,0,0,0,0,0,0,3,0,0,0
0,0,0,0,3,0,0,0,0,0,3,0,0,0,0,0,0,0,3,0,0,0,0,0,3,0,0,0,0
0,0,0,0,0,7,8,7,8,7,0,0,0,0,0,0,0,0,0,7,8,7,8,7,0,0,0,0,0
0,0,0,0,0,0,0,0,0,0,0,0,0,0,0,0,0,0,0,0,0,0,0,0,0,0,0,0,0
0,0,0,0,0,0,0,0,0,0,0,0,0,0,0,0,0,0,0,0,0,0,0,0,0,0,0,0,0
endlayer

layer
0,0,0,0,0,0,0,0,0,0,0,0,0,0,0,0,0,0,0,0,0,0,0,0,0,0,0,0,0
0,0,0,0,0,0,0,0,0,0,0,0,0,0,0,0,0,0,0,0,0,0,0,0,0,0,0,0,0
0,0,0,0,0,7,8,7,8,0,0,0,0,0,0,0,0,0,0,0,8,0,8,0,0,0,0,0,0
0,0,0,0,3,0,0,0,0,0,3,0,0,0,0,0,0,0,0,0,0,0,0,0,3,0,0,0,0
0,0,0,3,0,0,0,0,0,0,0,3,0,0,0,0,0,0,0,0,0,0,0,0,0,3,0,0,0
0,0,7,0,0,0,0,0,0,0,0,0,0,0,0,0,0,0,0,0,0,0,0,0,0,0,7,0,0
0,0,8,0,0,0,0,0,0,0,0,0,0,8,0,8,0,0,0,0,0,0,0,0,0,0,8,0,0
0,0,7,0,0,0,0,0,0,0,0,0,0,7,0,7,0,0,0,0,0,0,0,0,0,0,0,0,0
0,0,8,0,0,0,0,0,0,0,0,0,0,8,7,8,0,0,0,0,0,0,0,0,0,0,8,0,0
0,0,7,0,0,0,0,0,0,0,0,0,7,0,0,0,7,0,0,0,0,0,0,0,0,0,7,0,0
0,0,0,3,0,0,0,0,0,0,0,3,0,0,0,0,0,3,0,0,0,0,0,0,0,3,0,0,0
0,0,0,0,3,0,0,0,0,0,3,0,0,0,0,0,0,0,3,0,0,0,0,0,3,0,0,0,0
0,0,0,0,0,7,8,7,8,7,0,0,0,0,0,0,0,0,0,7,8,7,8,7,0,0,0,0,0
0,0,0,0,0,0,0,0,0,0,0,0,0,0,0,0,0,0,0,0,0,0,0,0,0,0,0,0,0
0,0,0,0,0,0,0,0,0,0,0,0,0,0,0,0,0,0,0,0,0,0,0,0,0,0,0,0,0
endlayer

layer
0,0,0,0,0,0,0,0,0,0,0,0,0,0,0,0,0,0,0,0,0,0,0,0,0,0,0,0,0
0,0,0,0,0,0,0,0,0,0,0,0,0,0,0,0,0,0,0,0,0,0,0,0,0,0,0,0,0
0,0,0,0,0,3,3,3,3,3,0,0,0,0,0,0,0,0,0,0,3,3,3,3,0,0,0,0,0
0,0,0,0,3,4,4,4,4,4,3,0,0,0,0,0,0,0,0,4,4,4,4,4,3,0,0,0,0
0,0,0,3,4,4,4,4,4,4,4,3,0,0,0,0,0,0,4,4,4,4,4,4,4,3,0,0,0
0,0,3,4,4,4,4,4,4,4,4,4,0,0,0,0,0,4,4,0,4,4,4,4,4,4,3,0,0
0,0,3,4,4,4,4,4,4,4,4,4,0,0,0,0,4,4,4,4,4,4,4,4,4,4,3,0,0
0,0,3,4,4,4,4,4,4,4,4,4,4,4,0,4,4,4,4,4,4,4,4,4,4,4,3,0,0
0,0,3,4,4,4,4,4,4,4,4,4,4,3,3,3,4,4,4,4,4,4,4,4,4,4,3,0,0
0,0,3,4,4,4,4,4,4,4,4,4,3,0,0,0,3,4,4,4,4,4,4,4,4,4,3,0,0
0,0,0,3,4,4,4,4,4,4,4,3,0,0,0,0,0,3,4,4,4,4,4,4,4,3,0,0,0
0,0,0,0,3,4,4,4,4,4,3,0,0,0,0,0,0,0,3,4,4,4,4,4,3,0,0,0,0
0,0,0,0,0,3,3,3,3,3,0,0,0,0,0,0,0,0,0,3,3,3,3,3,0,0,0,0,0
0,0,0,0,0,0,0,0,0,0,0,0,0,0,0,0,0,0,0,0,0,0,0,0,0,0,0,0,0
0,0,0,0,0,0,0,0,0,0,0,0,0,0,0,0,0,0,0,0,0,0,0,0,0,0,0,0,0
endlayer

layer
0,0,0,0,0,0,0,0,0,0,0,0,0,0,0,0,0,0,0,0,0,0,0,0,0,0,0,0,0
0,0,0,0,0,0,0,0,0,0,0,0,0,0,0,0,0,0,0,0,0,0,0,0,0,0,0,0,0
0,0,0,0,0,7,8,7,8,7,0,0,0,0,0,0,0,0,0,0,8,0,8,0,0,0,0,0,0
0,0,0,0,3,0,0,0,0,0,3,0,0,0,0,0,0,0,0,0,0,0,0,0,3,0,0,0,0
0,0,0,3,6,0,0,0,0,0,0,3,0,0,0,0,0,0,0,0,0,0,0,0,6,3,0,0,0
0,0,7,0,0,0,0,0,0,0,0,0,0,0,0,0,0,0,0,0,0,0,0,0,0,0,7,0,0
0,0,8,0,0,0,0,0,0,0,0,0,0,0,0,8,0,0,0,0,0,0,0,0,0,0,8,0,0
0,0,7,0,0,0,0,0,0,0,0,0,0,0,0,0,0,0,0,0,0,0,0,0,0,0,0,0,0
0,0,8,0,0,0,0,0,0,0,0,0,0,8,7,8,0,0,0,0,0,0,0,0,0,0,8,0,0
0,0,7,0,0,0,0,0,0,0,0,0,7,0,0,0,7,0,0,0,0,0,0,0,0,0,0,0,0
0,0,0,3,6,0,0,0,0,0,0,3,0,0,0,0,0,3,0,0,0,0,0,0,6,3,0,0,0
0,0,0,0,3,0,0,0,0,0,3,0,0,0,0,0,0,0,3,0,0,0,0,0,3,0,0,0,0
0,0,0,0,0,7,8,7,8,7,0,0,0,0,0,0,0,0,0,7,8,7,8,7,0,0,0,0,0
0,0,0,0,0,0,0,0,0,0,0,0,0,0,0,0,0,0,0,0,0,0,0,0,0,0,0,0,0
0,0,0,0,0,0,0,0,0,0,0,0,0,0,0,0,0,0,0,0,0,0,0,0,0,0,0,0,0
endlayer

layer
0,0,0,0,0,0,0,0,0,0,0,0,0,0,0,0,0,0,0,0,0,0,0,0,0,0,0,0,0
0,0,0,0,0,0,0,0,0,0,0,0,0,0,0,0,0,0,0,0,0,0,0,0,0,0,0,0,0
0,0,0,0,0,7,8,7,8,0,0,0,0,0,0,0,0,0,0,0,8,0,8,0,0,0,0,0,0
0,0,0,0,3,0,0,0,0,0,3,0,0,0,0,0,0,0,0,0,0,0,0,0,3,0,0,0,0
0,0,0,3,0,0,0,0,0,0,0,3,0,0,0,0,0,0,0,0,0,0,0,0,0,3,0,0,0
0,0,7,0,0,0,0,0,0,0,0,0,0,0,0,0,0,0,0,0,0,0,0,0,0,0,0,0,0
0,0,8,0,0,0,0,0,0,0,0,0,0,0,0,0,0,0,0,0,0,0,0,0,0,0,8,0,0
0,0,7,0,0,0,0,0,0,0,0,0,0,0,0,0,0,0,0,0,0,0,0,0,0,0,0,0,0
0,0,8,0,0,0,0,0,0,0,0,0,0,8,7,8,0,0,0,0,0,0,0,0,0,0,8,0,0
0,0,7,0,0,0,0,0,0,0,0,0,7,0,0,0,7,0,0,0,0,0,0,0,0,0,0,0,0
0,0,0,3,0,0,0,0,0,0,0,3,0,0,0,0,0,3,0,0,0,0,0,0,0,3,0,0,0
0,0,0,0,3,0,0,0,0,0,3,0,0,0,0,0,0,0,3,0,0,0,0,0,3,0,0,0,0
0,0,0,0,0,7,8,7,8,7,0,0,0,0,0,0,0,0,0,7,8,7,8,7,0,0,0,0,0
0,0,0,0,0,0,0,0,0,0,0,0,0,0,0,0,0,0,0,0,0,0,0,0,0,0,0,0,0
0,0,0,0,0,0,0,0,0,0,0,0,0,0,0,0,0,0,0,0,0,0,0,0,0,0,0,0,0
endlayer

layer
0,0,0,0,0,0,0,0,0,0,0,0,0,0,0,0,0,0,0,0,0,0,0,0,0,0,0,0,0
0,0,0,0,0,0,0,0,0,0,0,0,0,0,0,0,0,0,0,0,0,0,0,0,0,0,0,0,0
0,0,0,0,0,7,8,7,8,7,0,0,0,0,0,0,0,0,0,0,0,7,8,7,0,0,0,0,0
0,0,0,0,3,0,0,0,0,0,3,0,0,0,0,0,0,0,0,0,0,0,0,0,3,0,0,0,0
0,0,0,3,0,0,0,0,0,0,0,3,0,0,0,0,0,0,0,0,0,0,0,0,0,3,0,0,0
0,0,7,0,0,0,0,0,0,0,0,0,0,0,0,0,0,0,0,0,0,0,0,0,0,0,7,0,0
0,0,8,0,0,0,0,0,0,0,0,0,0,0,0,0,0,0,0,0,0,0,0,0,0,0,8,0,0
0,0,7,0,0,0,0,0,0,0,0,0,0,7,0,7,0,0,0,0,0,0,0,0,0,0,0,0,0
0,0,8,0,0,0,0,0,0,0,0,0,0,8,7,8,0,0,0,0,0,0,0,0,0,0,8,0,0
0,0,7,0,0,0,0,0,0,0,0,0,7,0,0,0,0,0,0,0,0,0,0,0,0,0,7,0,0
0,0,0,3,0,0,0,0,0,0,0,3,0,0,0,0,0,3,0,0,0,0,0,0,0,3,0,0,0
0,0,0,0,3,0,0,0,0,0,3,0,0,0,0,0,0,0,3,0,0,0,0,0,3,0,0,0,0
0,0,0,0,0,7,8,7,8,7,0,0,0,0,0,0,0,0,0,7,8,7,8,7,0,0,0,0,0
0,0,0,0,0,0,0,0,0,0,0,0,0,0,0,0,0,0,0,0,0,0,0,0,0,0,0,0,0
0,0,0,0,0,0,0,0,0,0,0,0,0,0,0,0,0,0,0,0,0,0,0,0,0,0,0,0,0
endlayer

layer
0,0,0,0,0,0,0,0,0,0,0,0,0,0,0,0,0,0,0,0,0,0,0,0,0,0,0,0,0
0,0,0,0,0,0,0,0,0,0,0,0,0,0,0,0,0,0,0,0,0,0,0,0,0,0,0,0,0
0,0,0,0,0,7,8,7,8,0,0,0,0,0,0,0,0,0,0,0,0,0,8,0,0,0,0,0,0
0,0,0,0,3,0,0,0,0,0,3,0,0,0,0,0,0,0,0,0,0,0,0,0,3,0,0,0,0
0,0,0,3,0,0,0,0,0,0,0,3,0,0,0,0,0,0,0,0,0,0,0,0,0,3,0,0,0
0,0,7,0,0,0,0,0,0,0,0,0,0,0,0,0,0,0,0,0,0,0,0,0,0,0,0,0,0
0,0,8,0,0,0,0,0,0,0,0,0,0,0,0,0,0,0,0,0,0,0,0,0,0,0,8,0,0
0,0,7,0,0,0,0,0,0,0,0,0,0,7,0,7,0,0,0,0,0,0,0,0,0,0,7,0,0
0,0,8,0,0,0,0,0,0,0,0,0,0,8,7,8,0,0,0,0,0,0,0,0,0,0,8,0,0
0,0,7,0,0,0,0,0,0,0,0,0,7,0,0,0,7,0,0,0,0,0,0,0,0,0,0,0,0
0,0,0,3,0,0,0,0,0,0,0,3,0,0,0,0,0,3,0,0,0,0,0,0,0,3,0,0,0
0,0,0,0,3,0,0,0,0,0,3,0,0,0,0,0,0,0,3,0,0,0,0,0,3,0,0,0,0
0,0,0,0,0,7,8,7,8,7,0,0,0,0,0,0,0,0,0,7,8,7,8,7,0,0,0,0,0
0,0,0,0,0,0,0,0,0,0,0,0,0,0,0,0,0,0,0,0,0,0,0,0,0,0,0,0,0
0,0,0,0,0,0,0,0,0,0,0,0,0,0,0,0,0,0,0,0,0,0,0,0,0,0,0,0,0
endlayer

layer
0,0,0,0,0,0,0,0,0,0,0,0,0,0,0,0,0,0,0,0,0,0,0,0,0,0,0,0,0
0,0,0,0,0,0,0,0,0,0,0,0,0,0,0,0,0,0,0,0,0,0,0,0,0,0,0,0,0
0,0,0,0,0,7,8,7,8,0,0,0,0,0,0,0,0,0,0,0,0,7,8,7,0,0,0,0,0
0,0,0,0,3,0,0,0,0,0,3,0,0,0,0,0,0,0,0,0,0,0,0,0,3,0,0,0,0
0,0,0,3,0,0,0,0,0,0,0,3,0,0,0,0,0,0,0,0,0,0,0,0,0,3,0,0,0
0,0,7,0,0,0,0,0,0,0,0,0,0,0,0,0,0,0,0,0,0,0,0,0,0,0,0,0,0
0,0,8,0,0,0,0,0,0,0,0,0,0,0,0,0,0,0,0,0,0,0,0,0,0,0,8,0,0
0,0,7,0,0,0,0,0,0,0,0,0,0,0,0,7,0,0,0,0,0,0,0,0,0,0,0,0,0
0,0,8,0,0,0,0,0,0,0,0,0,0,8,7,8,0,0,0,0,0,0,0,0,0,0,8,0,0
0,0,7,0,0,0,0,0,0,0,0,0,7,0,0,0,7,0,0,0,0,0,0,0,0,0,0,0,0
0,0,0,3,0,0,0,0,0,0,0,3,0,0,0,0,0,3,0,0,0,0,0,0,0,3,0,0,0
0,0,0,0,3,0,0,0,0,0,3,0,0,0,0,0,0,0,3,0,0,0,0,0,3,0,0,0,0
0,0,0,0,0,7,8,7,8,7,0,0,0,0,0,0,0,0,0,7,8,7,8,7,0,0,0,0,0
0,0,0,0,0,0,0,0,0,0,0,0,0,0,0,0,0,0,0,0,0,0,0,0,0,0,0,0,0
0,0,0,0,0,0,0,0,0,0,0,0,0,0,0,0,0,0,0,0,0,0,0,0,0,0,0,0,0
endlayer

layer
0,0,0,0,0,0,0,0,0,0,0,0,0,0,0,0,0,0,0,0,0,0,0,0,0,0,0,0,0
0,0,0,0,0,0,0,0,0,0,0,0,0,0,0,0,0,0,0,0,0,0,0,0,0,0,0,0,0
0,0,0,0,0,7,8,7,8,0,0,0,0,0,0,0,0,0,0,0,0,0,8,0,0,0,0,0,0
0,0,0,0,3,0,0,0,0,0,3,0,0,0,0,0,0,0,0,0,0,0,0,0,3,0,0,0,0
0,0,0,3,0,0,0,0,0,0,0,3,0,0,0,0,0,0,0,0,0,0,0,0,0,3,0,0,0
0,0,7,0,0,0,0,0,0,0,0,0,0,0,0,0,0,0,0,0,0,0,0,0,0,0,7,0,0
0,0,8,0,0,0,0,0,0,0,0,0,0,0,0,0,0,0,0,0,0,0,0,0,0,0,8,0,0
0,0,7,0,0,0,0,0,0,0,0,0,0,7,0,7,0,0,0,0,0,0,0,0,0,0,7,0,0
0,0,8,0,0,0,0,0,0,0,0,0,0,8,7,8,0,0,0,0,0,0,0,0,0,0,8,0,0
0,0,7,0,0,0,0,0,0,0,0,0,7,0,0,0,7,0,0,0,0,0,0,0,0,0,0,0,0
0,0,0,3,0,0,0,0,0,0,0,3,0,0,0,0,0,3,0,0,0,0,0,0,0,3,0,0,0
0,0,0,0,3,0,0,0,0,0,3,0,0,0,0,0,0,0,3,0,0,0,0,0,3,0,0,0,0
0,0,0,0,0,7,8,7,8,7,0,0,0,0,0,0,0,0,0,7,8,7,8,7,0,0,0,0,0
0,0,0,0,0,0,0,0,0,0,0,0,0,0,0,0,0,0,0,0,0,0,0,0,0,0,0,0,0
0,0,0,0,0,0,0,0,0,0,0,0,0,0,0,0,0,0,0,0,0,0,0,0,0,0,0,0,0
endlayer

layer
0,0,0,0,0,0,0,0,0,0,0,0,0,0,0,0,0,0,0,0,0,0,0,0,0,0,0,0,0
0,0,0,0,0,0,0,0,0,0,0,0,0,0,0,0,0,0,0,0,0,0,0,0,0,0,0,0,0
0,0,0,0,0,3,3,3,3,3,0,0,0,0,0,0,0,0,0,0,0,3,3,3,0,0,0,0,0
0,0,0,0,3,4,4,4,4,4,3,0,0,0,0,0,0,0,0,0,4,4,4,4,3,0,0,0,0
0,0,0,3,4,4,0,0,0,4,4,3,0,0,0,0,0,0,4,4,4,4,4,4,4,3,0,0,0
0,0,3,4,4,4,0,0,4,4,4,4,0,0,0,0,0,4,4,0,4,4,4,4,4,4,3,0,0
0,0,3,4,4,4,0,0,0,4,4,4,4,0,3,0,4,0,4,4,4,4,4,4,4,4,3,0,0
0,0,3,4,4,4,4,4,4,4,4,4,4,4,0,4,4,4,4,4,4,4,4,4,4,4,3,0,0
0,0,3,4,4,4,4,4,4,4,4,4,4,3,3,3,4,4,4,4,4,4,4,4,4,4,3,0,0
0,0,3,4,4,4,4,4,4,4,4,4,3,0,0,0,3,4,4,4,4,4,4,4,4,4,3,0,0
0,0,0,3,4,4,4,4,4,4,4,3,0,0,0,0,0,3,4,4,4,4,4,4,4,3,0,0,0
0,0,0,0,3,4,4,4,4,4,3,0,0,0,0,0,0,0,3,4,4,4,4,4,3,0,0,0,0
0,0,0,0,0,3,3,3,3,3,0,0,0,0,0,0,0,0,0,3,3,3,3,3,0,0,0,0,0
0,0,0,0,0,0,0,0,0,0,0,0,0,0,0,0,0,0,0,0,0,0,0,0,0,0,0,0,0
0,0,0,0,0,0,0,0,0,0,0,0,0,0,0,0,0,0,0,0,0,0,0,0,0,0,0,0,0
endlayer

layer
0,0,0,0,0,0,0,0,0,0,0,0,0,0,0,0,0,0,0,0,0,0,0,0,0,0,0,0,0
0,0,0,0,0,0,0,0,0,0,0,0,0,0,0,0,0,0,0,0,0,0,0,0,0,0,0,0,0
0,0,0,0,0,0,8,0,8,0,0,0,0,0,0,0,0,0,0,0,0,0,0,0,0,0,0,0,0
0,0,0,0,0,0,0,0,0,0,3,0,0,0,0,0,0,0,0,0,0,0,0,0,3,0,0,0,0
0,0,0,0,0,0,0,0,0,0,0,3,0,0,0,0,0,0,0,0,0,0,0,0,6,3,0,0,0
0,0,0,0,0,0,0,0,0,0,0,0,0,0,0,0,0,0,0,0,0,0,0,0,0,0,0,0,0
0,0,8,0,0,0,0,0,0,0,0,0,0,8,0,0,0,0,0,0,0,0,0,0,0,0,8,0,0
0,0,0,0,0,0,0,0,0,0,0,0,0,0,0,0,0,0,0,0,0,0,0,0,0,0,7,0,0
0,0,8,0,0,0,0,0,0,0,0,0,0,8,0,8,0,0,0,0,0,0,0,0,0,0,8,0,0
0,0,0,0,0,0,0,0,0,0,0,0,7,0,0,0,0,0,0,0,0,0,0,0,0,0,7,0,0
0,0,0,3,6,0,0,0,0,0,0,3,0,0,0,0,0,3,0,0,0,0,0,0,6,3,0,0,0
0,0,0,0,3,0,0,0,0,0,3,0,0,0,0,0,0,0,3,0,0,0,0,0,3,0,0,0,0
0,0,0,0,0,7,8,0,8,0,0,0,0,0,0,0,0,0,0,7,8,0,8,7,0,0,0,0,0
0,0,0,0,0,0,0,0,0,0,0,0,0,0,0,0,0,0,0,0,0,0,0,0,0,0,0,0,0
0,0,0,0,0,0,0,0,0,0,0,0,0,0,0,0,0,0,0,0,0,0,0,0,0,0,0,0,0
endlayer

layer
0,0,0,0,0,0,0,0,0,0,0,0,0,0,0,0,0,0,0,0,0,0,0,0,0,0,0,0,0
0,0,0,0,0,0,0,0,0,0,0,0,0,0,0,0,0,0,0,0,0,0,0,0,0,0,0,0,0
0,0,0,0,0,0,8,0,8,0,0,0,0,0,0,0,0,0,0,0,0,0,0,0,0,0,0,0,0
0,0,0,0,0,0,0,0,0,0,3,0,0,0,0,0,0,0,0,0,0,0,0,0,3,0,0,0,0
0,0,0,0,0,0,0,0,0,0,0,3,0,0,0,0,0,0,0,0,0,0,0,0,0,3,0,0,0
0,0,7,0,0,0,0,0,0,0,0,0,0,0,0,0,0,0,0,0,0,0,0,0,0,0,0,0,0
0,0,8,0,0,0,0,0,0,0,0,0,0,8,0,8,0,0,0,0,0,0,0,0,0,0,8,0,0
0,0,0,0,0,0,0,0,0,0,0,0,0,0,0,0,0,0,0,0,0,0,0,0,0,0,0,0,0
0,0,8,0,0,0,0,0,0,0,0,0,0,8,0,8,0,0,0,0,0,0,0,0,0,0,8,0,0
0,0,0,0,0,0,0,0,0,0,0,0,0,0,0,0,0,0,0,0,0,0,0,0,0,0,0,0,0
0,0,0,3,0,0,0,0,0,0,0,3,0,0,0,0,0,3,0,0,0,0,0,0,0,3,0,0,0
0,0,0,0,3,0,0,0,0,0,3,0,0,0,0,0,0,0,3,0,0,0,0,0,3,0,0,0,0
0,0,0,0,0,0,8,7,8,0,0,0,0,0,0,0,0,0,0,7,8,0,8,0,0,0,0,0,0
0,0,0,0,0,0,0,0,0,0,0,0,0,0,0,0,0,0,0,0,0,0,0,0,0,0,0,0,0
0,0,0,0,0,0,0,0,0,0,0,0,0,0,0,0,0,0,0,0,0,0,0,0,0,0,0,0,0
endlayer

layer
0,0,0,0,0,0,0,0,0,0,0,0,0,0,0,0,0,0,0,0,0,0,0,0,0,0,0,0,0
0,0,0,0,0,0,0,0,0,0,0,0,0,0,0,0,0,0,0,0,0,0,0,0,0,0,0,0,0
0,0,0,0,0,0,8,0,8,0,0,0,0,0,0,0,0,0,0,0,0,0,0,0,0,0,0,0,0
0,0,0,0,0,0,0,0,0,0,3,0,0,0,0,0,0,0,0,0,0,0,0,0,3,0,0,0,0
0,0,0,0,0,0,0,0,0,0,0,3,0,0,0,0,0,0,0,0,0,0,0,0,0,3,0,0,0
0,0,0,0,0,0,0,0,0,0,0,0,0,0,0,0,0,0,0,0,0,0,0,0,0,0,0,0,0
0,0,8,0,0,0,0,0,0,0,0,0,0,8,0,8,0,0,0,0,0,0,0,0,0,0,8,0,0
0,0,7,0,0,0,0,0,0,0,0,0,0,0,0,0,0,0,0,0,0,0,0,0,0,0,0,0,0
0,0,8,0,0,0,0,0,0,0,0,0,0,8,0,8,0,0,0,0,0,0,0,0,0,0,8,0,0
0,0,0,0,0,0,0,0,0,0,0,0,0,0,0,0,0,0,0,0,0,0,0,0,0,0,0,0,0
0,0,0,3,0,0,0,0,0,0,0,3,0,0,0,0,0,3,0,0,0,0,0,0,0,3,0,0,0
0,0,0,0,3,0,0,0,0,0,3,0,0,0,0,0,0,0,3,0,0,0,0,0,3,0,0,0,0
0,0,0,0,0,0,8,0,8,0,0,0,0,0,0,0,0,0,0,0,8,0,8,0,0,0,0,0,0
0,0,0,0,0,0,0,0,0,0,0,0,0,0,0,0,0,0,0,0,0,0,0,0,0,0,0,0,0
0,0,0,0,0,0,0,0,0,0,0,0,0,0,0,0,0,0,0,0,0,0,0,0,0,0,0,0,0
endlayer

layer
0,0,0,0,0,0,0,0,0,0,0,0,0,0,0,0,0,0,0,0,0,0,0,0,0,0,0,0,0
0,0,0,0,0,0,0,0,0,0,0,0,0,0,0,0,0,0,0,0,0,0,0,0,0,0,0,0,0
0,0,0,0,0,0,8,0,8,0,0,0,0,0,0,0,0,0,0,0,0,0,0,0,0,0,0,0,0
0,0,0,0,0,0,0,0,0,0,3,0,0,0,0,0,0,0,0,0,0,0,0,0,3,0,0,0,0
0,0,0,0,0,0,0,0,0,0,0,3,0,0,0,0,0,0,0,0,0,0,0,0,0,3,0,0,0
0,0,0,0,0,0,0,0,0,0,0,0,0,0,0,0,0,0,0,0,0,0,0,0,0,0,7,0,0
0,0,8,0,0,0,0,0,0,0,0,0,0,8,0,8,0,0,0,0,0,0,0,0,0,0,8,0,0
0,0,0,0,0,0,0,0,0,0,0,0,0,0,0,0,0,0,0,0,0,0,0,0,0,0,0,0,0
0,0,8,0,0,0,0,0,0,0,0,0,0,0,0,8,0,0,0,0,0,0,0,0,0,0,8,0,0
0,0,7,0,0,0,0,0,0,0,0,0,0,0,0,0,0,0,0,0,0,0,0,0,0,0,0,0,0
0,0,0,3,0,0,0,0,0,0,0,3,0,0,0,0,0,3,0,0,0,0,0,0,0,3,0,0,0
0,0,0,0,3,0,0,0,0,0,3,0,0,0,0,0,0,0,3,0,0,0,0,0,3,0,0,0,0
0,0,0,0,0,0,8,0,8,7,0,0,0,0,0,0,0,0,0,0,8,0,8,0,0,0,0,0,0
0,0,0,0,0,0,0,0,0,0,0,0,0,0,0,0,0,0,0,0,0,0,0,0,0,0,0,0,0
0,0,0,0,0,0,0,0,0,0,0,0,0,0,0,0,0,0,0,0,0,0,0,0,0,0,0,0,0
endlayer

layer
0,0,0,0,0,0,0,0,0,0,0,0,0,0,0,0,0,0,0,0,0,0,0,0,0,0,0,0,0
0,0,0,0,0,0,0,0,0,0,0,0,0,0,0,0,0,0,0,0,0,0,0,0,0,0,0,0,0
0,0,0,0,0,0,8,0,0,0,0,0,0,0,0,0,0,0,0,0,0,0,0,0,0,0,0,0,0
0,0,0,0,0,0,0,0,0,0,0,0,0,0,0,0,0,0,0,0,0,0,0,0,3,0,0,0,0
0,0,0,0,0,0,0,0,0,0,0,3,0,0,0,0,0,0,0,0,0,0,0,0,0,3,0,0,0
0,0,0,0,0,0,0,0,0,0,0,0,0,0,0,0,0,0,0,0,0,0,0,0,0,0,0,0,0
0,0,8,0,0,0,0,0,0,0,0,0,0,8,0,8,0,0,0,0,0,0,0,0,0,0,8,0,0
0,0,0,0,0,0,0,0,0,0,0,0,0,0,0,0,0,0,0,0,0,0,0,0,0,0,7,0,0
0,0,8,0,0,0,0,0,0,0,0,0,0,8,0,8,0,0,0,0,0,0,0,0,0,0,8,0,0
0,0,0,0,0,0,0,0,0,0,0,0,7,0,0,0,0,0,0,0,0,0,0,0,0,0,0,0,0
0,0,0,3,0,0,0,0,0,0,0,3,0,0,0,0,0,3,0,0,0,0,0,0,0,3,0,0,0
0,0,0,0,3,0,0,0,0,0,3,0,0,0,0,0,0,0,3,0,0,0,0,0,3,0,0,0,0
0,0,0,0,0,0,8,0,8,0,0,0,0,0,0,0,0,0,0,0,8,7,8,0,0,0,0,0,0
0,0,0,0,0,0,0,0,0,0,0,0,0,0,0,0,0,0,0,0,0,0,0,0,0,0,0,0,0
0,0,0,0,0,0,0,0,0,0,0,0,0,0,0,0,0,0,0,0,0,0,0,0,0,0,0,0,0
endlayer

layer
0,0,0,0,0,0,0,0,0,0,0,0,0,0,0,0,0,0,0,0,0,0,0,0,0,0,0,0,0
0,0,0,0,0,0,0,0,0,0,0,0,0,0,0,0,0,0,0,0,0,0,0,0,0,0,0,0,0
0,0,0,0,0,0,0,0,0,0,0,0,0,0,0,0,0,0,0,0,0,0,0,0,0,0,0,0,0
0,0,0,0,0,0,0,0,0,0,0,0,0,0,0,0,0,0,0,0,0,0,0,0,3,0,0,0,0
0,0,0,0,0,0,0,0,0,0,0,3,0,0,0,0,0,0,0,0,0,0,0,0,0,3,0,0,0
0,0,7,0,0,0,0,0,0,0,0,0,0,0,0,0,0,0,0,0,0,0,0,0,0,0,0,0,0
0,0,8,0,0,0,0,0,0,0,0,0,0,8,0,8,0,0,0,0,0,0,0,0,0,0,8,0,0
0,0,7,0,0,0,0,0,0,0,0,0,0,0,0,0,0,0,0,0,0,0,0,0,0,0,0,0,0
0,0,8,0,0,0,0,0,0,0,0,0,0,8,0,8,0,0,0,0,0,0,0,0,0,0,8,0,0
0,0,7,0,0,0,0,0,0,0,0,0,0,0,0,0,0,0,0,0,0,0,0,0,0,0,7,0,0
0,0,0,3,0,0,0,0,0,0,0,3,0,0,0,0,0,3,0,0,0,0,0,0,0,3,0,0,0
0,0,0,0,3,0,0,0,0,0,3,0,0,0,0,0,0,0,3,0,0,0,0,0,3,0,0,0,0
0,0,0,0,0,7,8,0,8,0,0,0,0,0,0,0,0,0,0,7,8,7,8,7,0,0,0,0,0
0,0,0,0,0,0,0,0,0,0,0,0,0,0,0,0,0,0,0,0,0,0,0,0,0,0,0,0,0
0,0,0,0,0,0,0,0,0,0,0,0,0,0,0,0,0,0,0,0,0,0,0,0,0,0,0,0,0
endlayer

layer
0,0,0,0,0,0,0,0,0,0,0,0,0,0,0,0,0,0,0,0,0,0,0,0,0,0,0,0,0
0,0,0,0,0,0,0,0,0,0,0,0,0,0,0,0,0,0,0,0,0,0,0,0,0,0,0,0,0
0,0,0,0,0,0,0,0,0,0,0,0,0,0,0,0,0,0,0,0,0,0,0,3,0,0,0,0,0
0,0,0,0,0,0,0,0,0,0,0,0,0,0,0,0,0,0,0,0,0,11,11,11,3,0,0,0,0
0,0,0,0,0,0,4,4,4,4,4,0,0,0,0,0,0,0,0,0,0,0,0,0,11,3,0,0,0
0,0,0,0,0,4,4,4,4,4,4,4,0,0,0,0,0,0,0,0,0,0,0,0,0,11,3,0,0
0,0,0,0,0,4,4,4,4,4,4,4,3,0,0,0,3,11,0,0,0,0,0,0,0,11,3,0,0
0,0,0,0,0,4,4,4,4,4,4,4,4,0,0,0,3,11,0,0,0,0,0,0,0,11,3,0,0
0,0,3,4,4,4,4,4,4,4,4,4,3,3,3,0,3,11,0,0,0,0,0,0,0,11,3,0,0
0,0,3,4,4,4,4,4,4,4,4,4,3,0,0,0,3,11,0,0,0,0,0,0,0,11,3,0,0
0,0,0,3,4,4,4,4,4,4,4,3,0,0,0,0,0,3,11,0,0,0,0,0,11,3,0,0,0
0,0,0,0,3,4,4,4,4,4,3,0,0,0,0,0,0,0,3,11,11,11,11,11,3,0,0,0,0
0,0,0,0,0,3,3,3,3,3,0,0,0,0,0,0,0,0,0,3,3,3,3,3,0,0,0,0,0
0,0,0,0,0,0,0,0,0,0,0,0,0,0,0,0,0,0,0,0,0,0,0,0,0,0,0,0,0
0,0,0,0,0,0,0,0,0,0,0,0,0,0,0,0,0,0,0,0,0,0,0,0,0,0,0,0,0
endlayer

layer
0,0,0,0,0,0,0,0,0,0,0,0,0,0,0,0,0,0,0,0,0,0,0,0,0,0,0,0,0
0,0,0,0,0,0,0,0,0,0,0,0,0,0,0,0,0,0,0,0,0,0,0,0,0,0,0,0,0
0,0,0,0,0,0,0,0,0,0,0,0,0,0,0,0,0,0,0,0,0,0,0,0,0,0,0,0,0
0,0,0,0,0,0,0,0,0,0,0,0,0,0,0,0,0,0,0,0,0,0,0,0,0,0,0,0,0
0,0,0,0,0,0,0,0,0,0,0,0,0,0,0,0,0,0,0,0,11,11,11,11,0,0,0,0,0
0,0,0,0,0,0,0,0,0,0,0,0,0,0,0,0,0,0,0,0,0,0,0,11,11,0,0,0,0
0,0,0,0,0,0,0,0,0,0,0,0,8,8,0,0,0,0,11,0,0,0,0,0,11,0,0,0,0
0,0,0,0,0,0,0,0,0,0,0,0,0,0,0,0,0,0,11,0,0,0,0,0,11,0,0,0,0
0,0,8,0,0,0,0,0,0,0,0,0,8,0,0,0,0,0,11,0,0,0,0,0,11,0,0,0,0
0,0,7,0,0,0,0,0,0,0,0,0,0,0,0,0,0,0,11,11,0,0,0,11,11,0,0,0,0
0,0,0,3,6,0,0,0,0,0,0,3,0,0,0,0,0,0,0,11,11,11,11,11,0,0,0,0,0
0,0,0,0,3,0,0,0,0,0,3,0,0,0,0,0,0,0,0,0,0,0,0,0,0,0,0,0,0
0,0,0,0,0,7,8,0,0,0,0,0,0,0,0,0,0,0,0,0,0,0,0,0,0,0,0,0,0
0,0,0,0,0,0,0,0,0,0,0,0,0,0,0,0,0,0,0,0,0,0,0,0,0,0,0,0,0
0,0,0,0,0,0,0,0,0,0,0,0,0,0,0,0,0,0,0,0,0,0,0,0,0,0,0,0,0
endlayer

layer
0,0,0,0,0,0,0,0,0,0,0,0,0,0,0,0,0,0,0,0,0,0,0,0,0,0,0,0,0
0,0,0,0,0,0,0,0,0,0,0,0,0,0,0,0,0,0,0,0,0,0,0,0,0,0,0,0,0
0,0,0,0,0,0,0,0,0,0,0,0,0,0,0,0,0,0,0,0,0,0,0,0,0,0,0,0,0
0,0,0,0,0,0,0,0,0,0,0,0,0,0,0,0,0,0,0,0,0,0,0,0,0,0,0,0,0
0,0,0,0,0,0,0,0,0,0,0,0,0,0,0,0,0,0,0,0,0,0,0,0,0,0,0,0,0
0,0,0,0,0,0,0,0,0,0,0,0,0,0,0,0,0,0,0,0,0,11,11,0,0,0,0,0,0
0,0,0,0,0,0,0,0,0,0,0,0,8,0,0,0,0,0,0,11,11,0,11,11,0,0,0,0,0
0,0,0,0,0,0,0,0,0,0,0,0,0,0,0,0,0,0,0,11,0,0,0,11,0,0,0,0,0
0,0,8,0,0,0,0,0,0,0,0,0,8,0,0,0,0,0,0,11,11,0,11,11,0,0,0,0,0
0,0,0,0,0,0,0,0,0,0,0,0,0,0,0,0,0,0,0,0,11,11,11,0,0,0,0,0,0
0,0,0,3,0,0,0,0,0,0,0,3,0,0,0,0,0,0,0,0,0,0,0,0,0,0,0,0,0
0,0,0,0,3,0,0,0,0,0,3,0,0,0,0,0,0,0,0,0,0,0,0,0,0,0,0,0,0
0,0,0,0,0,0,8,0,0,0,0,0,0,0,0,0,0,0,0,0,0,0,0,0,0,0,0,0,0
0,0,0,0,0,0,0,0,0,0,0,0,0,0,0,0,0,0,0,0,0,0,0,0,0,0,0,0,0
0,0,0,0,0,0,0,0,0,0,0,0,0,0,0,0,0,0,0,0,0,0,0,0,0,0,0,0,0
endlayer

layer
0,0,0,0,0,0,0,0,0,0,0,0,0,0,0,0,0,0,0,0,0,0,0,0,0,0,0,0,0
0,0,0,0,0,0,0,0,0,0,0,0,0,0,0,0,0,0,0,0,0,0,0,0,0,0,0,0,0
0,0,0,0,0,0,0,0,0,0,0,0,0,0,0,0,0,0,0,0,0,0,0,0,0,0,0,0,0
0,0,0,0,0,0,0,0,0,0,0,0,0,0,0,0,0,0,0,0,0,0,0,0,0,0,0,0,0
0,0,0,0,0,0,0,0,0,0,0,0,0,0,0,0,0,0,0,0,0,0,0,0,0,0,0,0,0
0,0,0,0,0,0,0,0,0,0,0,0,0,0,0,0,0,0,0,0,0,0,0,0,0,0,0,0,0
0,0,8,0,0,0,0,0,0,0,0,0,8,8,0,0,0,0,0,0,0,11,0,0,0,0,0,0,0
0,0,0,0,0,0,0,0,0,0,0,0,0,0,0,0,0,0,0,0,11,0,11,0,0,0,0,0,0
0,0,8,0,0,0,0,0,0,0,0,0,8,0,0,0,0,0,0,0,0,11,0,0,0,0,0,0,0
0,0,0,0,0,0,0,0,0,0,0,0,0,0,0,0,0,0,0,0,0,0,0,0,0,0,0,0,0
0,0,0,3,0,0,0,0,0,0,0,3,0,0,0,0,0,0,0,0,0,0,0,0,0,0,0,0,0
0,0,0,0,3,0,0,0,0,0,3,0,0,0,0,0,0,0,0,0,0,0,0,0,0,0,0,0,0
0,0,0,0,0,0,8,0,8,0,0,0,0,0,0,0,0,0,0,0,0,0,0,0,0,0,0,0,0
0,0,0,0,0,0,0,0,0,0,0,0,0,0,0,0,0,0,0,0,0,0,0,0,0,0,0,0,0
0,0,0,0,0,0,0,0,0,0,0,0,0,0,0,0,0,0,0,0,0,0,0,0,0,0,0,0,0
endlayer

layer
0,0,0,0,0,0,0,0,0,0,0,0,0,0,0,0,0,0,0,0,0,0,0,0,0,0,0,0,0
0,0,0,0,0,0,0,0,0,0,0,0,0,0,0,0,0,0,0,0,0,0,0,0,0,0,0,0,0
0,0,0,0,0,0,0,0,0,0,0,0,0,0,0,0,0,0,0,0,0,0,0,0,0,0,0,0,0
0,0,0,0,0,0,0,0,0,0,0,0,0,0,0,0,0,0,0,0,0,0,0,0,0,0,0,0,0
0,0,0,0,0,0,0,0,0,0,0,0,0,0,0,0,0,0,0,0,0,0,0,0,0,0,0,0,0
0,0,0,0,0,0,0,0,0,0,0,0,0,0,0,0,0,0,0,0,0,0,0,0,0,0,0,0,0
0,0,8,0,0,0,0,0,0,0,0,0,8,8,0,0,0,0,0,0,0,0,0,0,0,0,0,0,0
0,0,0,0,0,0,0,0,0,0,0,0,0,0,0,0,0,0,0,0,0,11,0,0,0,0,0,0,0
0,0,8,0,0,0,0,0,0,0,0,0,8,8,0,0,0,0,0,0,0,0,0,0,0,0,0,0,0
0,0,0,0,0,0,0,0,0,0,0,0,0,0,0,0,0,0,0,0,0,0,0,0,0,0,0,0,0
0,0,0,3,0,0,0,0,0,0,0,3,0,0,0,0,0,0,0,0,0,0,0,0,0,0,0,0,0
0,0,0,0,3,0,0,0,0,0,3,0,0,0,0,0,0,0,0,0,0,0,0,0,0,0,0,0,0
0,0,0,0,0,0,8,0,8,0,0,0,0,0,0,0,0,0,0,0,0,0,0,0,0,0,0,0,0
0,0,0,0,0,0,0,0,0,0,0,0,0,0,0,0,0,0,0,0,0,0,0,0,0,0,0,0,0
0,0,0,0,0,0,0,0,0,0,0,0,0,0,0,0,0,0,0,0,0,0,0,0,0,0,0,0,0
endlayer

layer
0,0,0,0,0,0,0,0,0,0,0,0,0,0,0,0,0,0,0,0,0,0,0,0,0,0,0,0,0
0,0,0,0,0,0,0,0,0,0,0,0,0,0,0,0,0,0,0,0,0,0,0,0,0,0,0,0,0
0,0,0,0,0,0,0,0,0,0,0,0,0,0,0,0,0,0,0,0,0,0,0,0,0,0,0,0,0
0,0,0,0,0,0,0,0,0,0,0,0,0,0,0,0,0,0,0,0,0,0,0,0,0,0,0,0,0
0,0,0,0,0,0,0,0,0,0,0,0,0,0,0,0,0,0,0,0,0,0,0,0,0,0,0,0,0
0,0,0,0,0,0,0,0,0,0,0,0,0,0,0,0,0,0,0,0,0,0,0,0,0,0,0,0,0
0,0,8,0,0,0,0,0,0,0,0,0,8,0,0,0,0,0,0,0,0,0,0,0,0,0,0,0,0
0,0,7,0,0,0,0,0,0,0,0,0,0,0,0,0,0,0,0,0,0,11,0,0,0,0,0,0,0
0,0,8,0,0,0,0,0,0,0,0,0,8,0,0,0,0,0,0,0,0,0,0,0,0,0,0,0,0
0,0,7,0,0,0,0,0,0,0,0,0,0,0,0,0,0,0,0,0,0,0,0,0,0,0,0,0,0
0,0,0,3,0,0,0,0,0,0,0,3,0,0,0,0,0,0,0,0,0,0,0,0,0,0,0,0,0
0,0,0,0,3,0,0,0,0,0,3,0,0,0,0,0,0,0,0,0,0,0,0,0,0,0,0,0,0
0,0,0,0,0,7,8,7,8,0,0,0,0,0,0,0,0,0,0,0,0,0,0,0,0,0,0,0,0
0,0,0,0,0,0,0,0,0,0,0,0,0,0,0,0,0,0,0,0,0,0,0,0,0,0,0,0,0
0,0,0,0,0,0,0,0,0,0,0,0,0,0,0,0,0,0,0,0,0,0,0,0,0,0,0,0,0
endlayer

layer
0,0,0,0,0,0,0,0,0,0,0,0,0,0,0,0,0,0,0,0,0,0,0,0,0,0,0,0,0
0,0,0,0,0,0,0,0,0,0,0,0,0,0,0,0,0,0,0,0,0,0,0,0,0,0,0,0,0
0,0,0,0,0,0,0,0,0,0,0,0,0,0,0,0,0,0,0,0,0,0,0,0,0,0,0,0,0
0,0,0,0,0,0,0,0,0,0,0,0,0,0,0,0,0,0,0,0,0,0,0,0,0,0,0,0,0
0,0,0,0,0,0,0,0,0,0,0,0,0,0,0,0,0,0,0,0,0,0,0,0,0,0,0,0,0
0,0,0,0,0,0,0,0,0,0,0,0,0,0,0,0,0,0,0,0,0,0,0,0,0,0,0,0,0
0,0,8,0,0,0,0,0,0,0,0,0,8,0,0,0,0,0,0,0,0,0,0,0,0,0,0,0,0
0,0,7,0,0,0,0,0,0,0,0,0,0,0,0,0,0,0,0,0,0,11,0,0,0,0,0,0,0
0,0,8,0,0,0,0,0,0,0,0,0,8,8,0,0,0,0,0,0,0,0,0,0,0,0,0,0,0
0,0,0,0,0,0,0,0,0,0,0,0,0,0,0,0,0,0,0,0,0,0,0,0,0,0,0,0,0
0,0,0,3,0,0,0,0,0,0,0,3,0,0,0,0,0,0,0,0,0,0,0,0,0,0,0,0,0
0,0,0,0,3,0,0,0,0,0,3,0,0,0,0,0,0,0,0,0,0,0,0,0,0,0,0,0,0
0,0,0,0,0,0,8,0,8,0,0,0,0,0,0,0,0,0,0,0,0,0,0,0,0,0,0,0,0
0,0,0,0,0,0,0,0,0,0,0,0,0,0,0,0,0,0,0,0,0,0,0,0,0,0,0,0,0
0,0,0,0,0,0,0,0,0,0,0,0,0,0,0,0,0,0,0,0,0,0,0,0,0,0,0,0,0
endlayer

layer
0,0,0,0,0,0,0,0,0,0,0,0,0,0,0,0,0,0,0,0,0,0,0,0,0,0,0,0,0
0,0,0,0,0,0,0,0,0,0,0,0,0,0,0,0,0,0,0,0,0,0,0,0,0,0,0,0,0
0,0,0,0,0,0,0,0,0,0,0,0,0,0,0,0,0,0,0,0,0,0,0,0,0,0,0,0,0
0,0,0,0,0,0,0,0,0,0,0,0,0,0,0,0,0,0,0,0,0,0,0,0,0,0,0,0,0
0,0,0,0,4,0,0,0,0,0,0,0,0,0,0,0,0,0,0,0,0,0,0,0,0,0,0,0,0
0,0,0,4,4,4,4,0,4,0,0,0,0,0,0,0,0,0,0,0,0,0,0,0,0,0,0,0,0
0,0,3,4,4,4,4,4,4,4,0,4,0,0,0,0,0,0,0,0,0,0,0,0,0,0,0,0,0
0,0,3,4,4,4,4,4,4,4,0,4,4,0,0,0,0,0,0,0,0,0,0,0,0,0,0,0,0
0,0,3,4,4,4,4,4,4,4,4,4,3,0,0,0,0,0,0,0,0,0,0,0,0,0,0,0,0
0,0,3,4,4,4,4,4,4,4,4,4,3,0,0,0,0,0,0,0,0,0,0,0,0,0,0,0,0
0,0,0,3,4,4,4,4,4,4,4,3,0,0,0,0,0,0,0,0,0,0,0,0,0,0,0,0,0
0,0,0,0,3,4,4,4,4,4,3,0,0,0,0,0,0,0,0,0,0,0,0,0,0,0,0,0,0
0,0,0,0,0,3,3,3,3,3,0,0,0,0,0,0,0,0,0,0,0,0,0,0,0,0,0,0,0
0,0,0,0,0,0,0,0,0,0,0,0,0,0,0,0,0,0,0,0,0,0,0,0,0,0,0,0,0
0,0,0,0,0,0,0,0,0,0,0,0,0,0,0,0,0,0,0,0,0,0,0,0,0,0,0,0,0
endlayer

layer
0,0,0,0,0,0,0,0,0,0,0,0,0,0,0,0,0,0,0,0,0,0,0,0,0,0,0,0,0
0,0,0,0,0,0,0,0,0,0,0,0,0,0,0,0,0,0,0,0,0,0,0,0,0,0,0,0,0
0,0,0,0,0,0,0,0,0,0,0,0,0,0,0,0,0,0,0,0,0,0,0,0,0,0,0,0,0
0,0,0,0,0,0,0,0,0,0,0,0,0,0,0,0,0,0,0,0,0,0,0,0,0,0,0,0,0
0,0,0,0,0,0,0,0,0,0,0,0,0,0,0,0,0,0,0,0,0,0,0,0,0,0,0,0,0
0,0,0,0,0,0,0,0,0,0,0,0,0,0,0,0,0,0,0,0,0,0,0,0,0,0,0,0,0
0,0,8,0,0,0,0,0,0,0,0,0,0,0,0,0,0,0,0,0,0,0,0,0,0,0,0,0,0
0,0,0,0,0,0,0,0,0,0,0,0,0,0,0,0,0,0,0,0,0,0,0,0,0,0,0,0,0
0,0,8,0,0,0,0,0,0,0,0,0,8,0,0,0,0,0,0,0,0,0,0,0,0,0,0,0,0
0,0,0,0,0,0,0,0,0,0,0,0,0,0,0,0,0,0,0,0,0,0,0,0,0,0,0,0,0
0,0,0,3,6,0,0,0,0,0,0,3,0,0,0,0,0,0,0,0,0,0,0,0,0,0,0,0,0
0,0,0,0,3,0,0,0,0,0,3,0,0,0,0,0,0,0,0,0,0,0,0,0,0,0,0,0,0
0,0,0,0,0,0,0,0,0,0,0,0,0,0,0,0,0,0,0,0,0,0,0,0,0,0,0,0,0
0,0,0,0,0,0,0,0,0,0,0,0,0,0,0,0,0,0,0,0,0,0,0,0,0,0,0,0,0
0,0,0,0,0,0,0,0,0,0,0,0,0,0,0,0,0,0,0,0,0,0,0,0,0,0,0,0,0
endlayer

layer
0,0,0,0,0,0,0,0,0,0,0,0,0,0,0,0,0,0,0,0,0,0,0,0,0,0,0,0,0
0,0,0,0,0,0,0,0,0,0,0,0,0,0,0,0,0,0,0,0,0,0,0,0,0,0,0,0,0
0,0,0,0,0,0,0,0,0,0,0,0,0,0,0,0,0,0,0,0,0,0,0,0,0,0,0,0,0
0,0,0,0,0,0,0,0,0,0,0,0,0,0,0,0,0,0,0,0,0,0,0,0,0,0,0,0,0
0,0,0,0,0,0,0,0,0,0,0,0,0,0,0,0,0,0,0,0,0,0,0,0,0,0,0,0,0
0,0,0,0,0,0,0,0,0,0,0,0,0,0,0,0,0,0,0,0,0,0,0,0,0,0,0,0,0
0,0,8,0,0,0,0,0,0,0,0,0,0,0,0,0,0,0,0,0,0,0,0,0,0,0,0,0,0
0,0,7,0,0,0,0,0,0,0,0,0,0,0,0,0,0,0,0,0,0,0,0,0,0,0,0,0,0
0,0,8,0,0,0,0,0,0,0,0,0,0,0,0,0,0,0,0,0,0,0,0,0,0,0,0,0,0
0,0,0,0,0,0,0,0,0,0,0,0,0,0,0,0,0,0,0,0,0,0,0,0,0,0,0,0,0
0,0,0,3,0,0,0,0,0,0,0,3,0,0,0,0,0,0,0,0,0,0,0,0,0,0,0,0,0
0,0,0,0,3,0,0,0,0,0,3,0,0,0,0,0,0,0,0,0,0,0,0,0,0,0,0,0,0
0,0,0,0,0,0,0,0,0,0,0,0,0,0,0,0,0,0,0,0,0,0,0,0,0,0,0,0,0
0,0,0,0,0,0,0,0,0,0,0,0,0,0,0,0,0,0,0,0,0,0,0,0,0,0,0,0,0
0,0,0,0,0,0,0,0,0,0,0,0,0,0,0,0,0,0,0,0,0,0,0,0,0,0,0,0,0
endlayer

layer
0,0,0,0,0,0,0,0,0,0,0,0,0,0,0,0,0,0,0,0,0,0,0,0,0,0,0,0,0
0,0,0,0,0,0,0,0,0,0,0,0,0,0,0,0,0,0,0,0,0,0,0,0,0,0,0,0,0
0,0,0,0,0,0,0,0,0,0,0,0,0,0,0,0,0,0,0,0,0,0,0,0,0,0,0,0,0
0,0,0,0,0,0,0,0,0,0,0,0,0,0,0,0,0,0,0,0,0,0,0,0,0,0,0,0,0
0,0,0,0,0,0,0,0,0,0,0,0,0,0,0,0,0,0,0,0,0,0,0,0,0,0,0,0,0
0,0,0,0,0,0,0,0,0,0,0,0,0,0,0,0,0,0,0,0,0,0,0,0,0,0,0,0,0
0,0,8,0,0,0,0,0,0,0,0,0,0,0,0,0,0,0,0,0,0,0,0,0,0,0,0,0,0
0,0,0,0,0,0,0,0,0,0,0,0,0,0,0,0,0,0,0,0,0,0,0,0,0,0,0,0,0
0,0,8,0,0,0,0,0,0,0,0,0,0,0,0,0,0,0,0,0,0,0,0,0,0,0,0,0,0
0,0,7,0,0,0,0,0,0,0,0,0,0,0,0,0,0,0,0,0,0,0,0,0,0,0,0,0,0
0,0,0,3,0,0,0,0,0,0,0,3,0,0,0,0,0,0,0,0,0,0,0,0,0,0,0,0,0
0,0,0,0,3,0,0,0,0,0,3,0,0,0,0,0,0,0,0,0,0,0,0,0,0,0,0,0,0
0,0,0,0,0,0,0,0,8,0,0,0,0,0,0,0,0,0,0,0,0,0,0,0,0,0,0,0,0
0,0,0,0,0,0,0,0,0,0,0,0,0,0,0,0,0,0,0,0,0,0,0,0,0,0,0,0,0
0,0,0,0,0,0,0,0,0,0,0,0,0,0,0,0,0,0,0,0,0,0,0,0,0,0,0,0,0
endlayer

layer
0,0,0,0,0,0,0,0,0,0,0,0,0,0,0,0,0,0,0,0,0,0,0,0,0,0,0,0,0
0,0,0,0,0,0,0,0,0,0,0,0,0,0,0,0,0,0,0,0,0,0,0,0,0,0,0,0,0
0,0,0,0,0,0,0,0,0,0,0,0,0,0,0,0,0,0,0,0,0,0,0,0,0,0,0,0,0
0,0,0,0,0,0,0,0,0,0,0,0,0,0,0,0,0,0,0,0,0,0,0,0,0,0,0,0,0
0,0,0,0,0,0,0,0,0,0,0,0,0,0,0,0,0,0,0,0,0,0,0,0,0,0,0,0,0
0,0,0,0,0,0,0,0,0,0,0,0,0,0,0,0,0,0,0,0,0,0,0,0,0,0,0,0,0
0,0,0,0,0,0,0,0,0,0,0,0,0,0,0,0,0,0,0,0,0,0,0,0,0,0,0,0,0
0,0,0,0,0,0,0,0,0,0,0,0,0,0,0,0,0,0,0,0,0,0,0,0,0,0,0,0,0
0,0,8,0,0,0,0,0,0,0,0,0,0,0,0,0,0,0,0,0,0,0,0,0,0,0,0,0,0
0,0,0,0,0,0,0,0,0,0,0,0,0,0,0,0,0,0,0,0,0,0,0,0,0,0,0,0,0
0,0,0,3,0,0,0,0,0,0,0,3,0,0,0,0,0,0,0,0,0,0,0,0,0,0,0,0,0
0,0,0,0,3,0,0,0,0,0,3,0,0,0,0,0,0,0,0,0,0,0,0,0,0,0,0,0,0
0,0,0,0,0,0,8,0,8,7,0,0,0,0,0,0,0,0,0,0,0,0,0,0,0,0,0,0,0
0,0,0,0,0,0,0,0,0,0,0,0,0,0,0,0,0,0,0,0,0,0,0,0,0,0,0,0,0
0,0,0,0,0,0,0,0,0,0,0,0,0,0,0,0,0,0,0,0,0,0,0,0,0,0,0,0,0
endlayer

layer
0,0,0,0,0,0,0,0,0,0,0,0,0,0,0,0,0,0,0,0,0,0,0,0,0,0,0,0,0
0,0,0,0,0,0,0,0,0,0,0,0,0,0,0,0,0,0,0,0,0,0,0,0,0,0,0,0,0
0,0,0,0,0,0,0,0,0,0,0,0,0,0,0,0,0,0,0,0,0,0,0,0,0,0,0,0,0
0,0,0,0,0,0,0,0,0,0,0,0,0,0,0,0,0,0,0,0,0,0,0,0,0,0,0,0,0
0,0,0,0,0,0,0,0,0,0,0,0,0,0,0,0,0,0,0,0,0,0,0,0,0,0,0,0,0
0,0,0,0,0,0,0,0,0,0,0,0,0,0,0,0,0,0,0,0,0,0,0,0,0,0,0,0,0
0,0,8,0,0,0,0,0,0,0,0,0,0,0,0,0,0,0,0,0,0,0,0,0,0,0,0,0,0
0,0,7,0,0,0,0,0,0,0,0,0,0,0,0,0,0,0,0,0,0,0,0,0,0,0,0,0,0
0,0,8,0,0,0,0,0,0,0,0,0,0,0,0,0,0,0,0,0,0,0,0,0,0,0,0,0,0
0,0,7,0,0,0,0,0,0,0,0,0,0,0,0,0,0,0,0,0,0,0,0,0,0,0,0,0,0
0,0,0,3,0,0,0,0,0,0,0,3,0,0,0,0,0,0,0,0,0,0,0,0,0,0,0,0,0
0,0,0,0,3,0,0,0,0,0,3,0,0,0,0,0,0,0,0,0,0,0,0,0,0,0,0,0,0
0,0,0,0,0,7,8,7,8,0,0,0,0,0,0,0,0,0,0,0,0,0,0,0,0,0,0,0,0
0,0,0,0,0,0,0,0,0,0,0,0,0,0,0,0,0,0,0,0,0,0,0,0,0,0,0,0,0
0,0,0,0,0,0,0,0,0,0,0,0,0,0,0,0,0,0,0,0,0,0,0,0,0,0,0,0,0
endlayer

layer
0,0,0,0,0,0,0,0,0,0,0,0,0,0,0,0,0,0,0,0,0,0,0,0,0,0,0,0,0
0,0,0,0,0,0,0,0,0,0,0,0,0,0,0,0,0,0,0,0,0,0,0,0,0,0,0,0,0
0,0,0,0,0,0,0,0,0,0,0,0,0,0,0,0,0,0,0,0,0,0,0,0,0,0,0,0,0
0,0,0,0,0,0,0,0,0,0,0,0,0,0,0,0,0,0,0,0,0,0,0,0,0,0,0,0,0
0,0,0,0,0,0,0,0,0,0,0,0,0,0,0,0,0,0,0,0,0,0,0,0,0,0,0,0,0
0,0,0,0,0,0,0,0,0,0,0,0,0,0,0,0,0,0,0,0,0,0,0,0,0,0,0,0,0
0,0,8,0,0,0,0,0,0,0,0,0,0,0,0,0,0,0,0,0,0,0,0,0,0,0,0,0,0
0,0,0,0,0,0,0,0,0,0,0,0,0,0,0,0,0,0,0,0,0,0,0,0,0,0,0,0,0
0,0,8,0,0,0,0,0,0,0,0,0,0,0,0,0,0,0,0,0,0,0,0,0,0,0,0,0,0
0,0,0,0,0,0,0,0,0,0,0,0,0,0,0,0,0,0,0,0,0,0,0,0,0,0,0,0,0
0,0,0,3,0,0,0,0,0,0,0,3,0,0,0,0,0,0,0,0,0,0,0,0,0,0,0,0,0
0,0,0,0,3,0,0,0,0,0,3,0,0,0,0,0,0,0,0,0,0,0,0,0,0,0,0,0,0
0,0,0,0,0,0,8,0,8,7,0,0,0,0,0,0,0,0,0,0,0,0,0,0,0,0,0,0,0
0,0,0,0,0,0,0,0,0,0,0,0,0,0,0,0,0,0,0,0,0,0,0,0,0,0,0,0,0
0,0,0,0,0,0,0,0,0,0,0,0,0,0,0,0,0,0,0,0,0,0,0,0,0,0,0,0,0
endlayer

layer
0,0,0,0,0,0,0,0,0,0,0,0,0,0,0,0,0,0,0,0,0,0,0,0,0,0,0,0,0
0,0,0,0,0,0,0,0,0,0,0,0,0,0,0,0,0,0,0,0,0,0,0,0,0,0,0,0,0
0,0,0,0,0,0,0,0,0,0,0,0,0,0,0,0,0,0,0,0,0,0,0,0,0,0,0,0,0
0,0,0,0,0,0,0,0,0,0,0,0,0,0,0,0,0,0,0,0,0,0,0,0,0,0,0,0,0
0,0,0,0,0,0,0,0,0,0,0,0,0,0,0,0,0,0,0,0,0,0,0,0,0,0,0,0,0
0,0,0,11,0,0,0,0,0,0,0,0,0,0,0,0,0,0,0,0,0,0,0,0,0,0,0,0,0
0,0,3,11,0,0,0,0,0,0,0,0,0,0,0,0,0,0,0,0,0,0,0,0,0,0,0,0,0
0,0,3,11,0,0,0,0,0,0,0,0,0,0,0,0,0,0,0,0,0,0,0,0,0,0,0,0,0
0,0,3,11,0,0,0,0,0,0,0,0,0,0,0,0,0,0,0,0,0,0,0,0,0,0,0,0,0
0,0,3,11,0,0,0,0,0,0,0,0,0,0,0,0,0,0,0,0,0,0,0,0,0,0,0,0,0
0,0,0,3,11,0,0,0,0,0,0,3,0,0,0,0,0,0,0,0,0,0,0,0,0,0,0,0,0
0,0,0,0,3,11,11,11,11,11,3,0,0,0,0,0,0,0,0,0,0,0,0,0,0,0,0,0,0
0,0,0,0,0,3,3,3,3,3,0,0,0,0,0,0,0,0,0,0,0,0,0,0,0,0,0,0,0
0,0,0,0,0,0,0,0,0,0,0,0,0,0,0,0,0,0,0,0,0,0,0,0,0,0,0,0,0
0,0,0,0,0,0,0,0,0,0,0,0,0,0,0,0,0,0,0,0,0,0,0,0,0,0,0,0,0
endlayer

layer
0,0,0,0,0,0,0,0,0,0,0,0,0,0,0,0,0,0,0,0,0,0,0,0,0,0,0,0,0
0,0,0,0,0,0,0,0,0,0,0,0,0,0,0,0,0,0,0,0,0,0,0,0,0,0,0,0,0
0,0,0,0,0,0,0,0,0,0,0,0,0,0,0,0,0,0,0,0,0,0,0,0,0,0,0,0,0
0,0,0,0,0,0,0,0,0,0,0,0,0,0,0,0,0,0,0,0,0,0,0,0,0,0,0,0,0
0,0,0,0,0,0,0,0,0,0,0,0,0,0,0,0,0,0,0,0,0,0,0,0,0,0,0,0,0
0,0,0,0,0,0,0,0,0,0,0,0,0,0,0,0,0,0,0,0,0,0,0,0,0,0,0,0,0
0,0,0,0,11,0,0,0,0,0,0,0,0,0,0,0,0,0,0,0,0,0,0,0,0,0,0,0,0
0,0,0,0,11,0,0,0,0,0,0,0,0,0,0,0,0,0,0,0,0,0,0,0,0,0,0,0,0
0,0,0,0,11,0,0,0,0,0,0,0,0,0,0,0,0,0,0,0,0,0,0,0,0,0,0,0,0
0,0,0,0,11,11,0,0,0,0,0,0,0,0,0,0,0,0,0,0,0,0,0,0,0,0,0,0,0
0,0,0,0,0,11,11,11,11,11,0,0,0,0,0,0,0,0,0,0,0,0,0,0,0,0,0,0,0
0,0,0,0,0,0,0,0,0,0,0,0,0,0,0,0,0,0,0,0,0,0,0,0,0,0,0,0,0
0,0,0,0,0,0,0,0,0,0,0,0,0,0,0,0,0,0,0,0,0,0,0,0,0,0,0,0,0
0,0,0,0,0,0,0,0,0,0,0,0,0,0,0,0,0,0,0,0,0,0,0,0,0,0,0,0,0
0,0,0,0,0,0,0,0,0,0,0,0,0,0,0,0,0,0,0,0,0,0,0,0,0,0,0,0,0
endlayer

layer
0,0,0,0,0,0,0,0,0,0,0,0,0,0,0,0,0,0,0,0,0,0,0,0,0,0,0,0,0
0,0,0,0,0,0,0,0,0,0,0,0,0,0,0,0,0,0,0,0,0,0,0,0,0,0,0,0,0
0,0,0,0,0,0,0,0,0,0,0,0,0,0,0,0,0,0,0,0,0,0,0,0,0,0,0,0,0
0,0,0,0,0,0,0,0,0,0,0,0,0,0,0,0,0,0,0,0,0,0,0,0,0,0,0,0,0
0,0,0,0,0,0,0,0,0,0,0,0,0,0,0,0,0,0,0,0,0,0,0,0,0,0,0,0,0
0,0,0,0,0,0,0,0,0,0,0,0,0,0,0,0,0,0,0,0,0,0,0,0,0,0,0,0,0
0,0,0,0,0,11,11,0,0,0,0,0,0,0,0,0,0,0,0,0,0,0,0,0,0,0,0,0,0
0,0,0,0,0,11,0,0,0,0,0,0,0,0,0,0,0,0,0,0,0,0,0,0,0,0,0,0,0
0,0,0,0,0,11,0,0,0,0,0,0,0,0,0,0,0,0,0,0,0,0,0,0,0,0,0,0,0
0,0,0,0,0,0,11,0,0,0,0,0,0,0,0,0,0,0,0,0,0,0,0,0,0,0,0,0,0
0,0,0,0,0,0,0,0,0,0,0,0,0,0,0,0,0,0,0,0,0,0,0,0,0,0,0,0,0
0,0,0,0,0,0,0,0,0,0,0,0,0,0,0,0,0,0,0,0,0,0,0,0,0,0,0,0,0
0,0,0,0,0,0,0,0,0,0,0,0,0,0,0,0,0,0,0,0,0,0,0,0,0,0,0,0,0
0,0,0,0,0,0,0,0,0,0,0,0,0,0,0,0,0,0,0,0,0,0,0,0,0,0,0,0,0
0,0,0,0,0,0,0,0,0,0,0,0,0,0,0,0,0,0,0,0,0,0,0,0,0,0,0,0,0
endlayer

