weight=20
embed_into_distance=1
dimensions=49,15,29
max_cut_in=2


rule1=0,100,3134-10
rule2=0,100,250
rule3=0,100,2843-14,2843-14,2843-14,2843-14,2843
rule4=0,100,2843-4
rule5=0,100,159-15
rule6=0,100,622,2838-4,2838-4,2838-4,2838-4,2838-4,2838-4,2838-4,2838-4,2838-4
rule7=0,75,2245-1,2245-1,2245-1,2245-1,2245-1,2245-1,2245-1,311
rule8=0,100,35
rule9=0,100,35-14
rule10=0,66,2291-1
rule11=0,100,35-8
rule12=0,100,35-1
rule13=0,100,126
rule14=0,50,308,308,308,308,308,308,313,313,314,327
rule15=0,66,623
rule16=0,25,3225-3
rule17=0,95,2835-2,2835-2,2835-2,2835-2,2835-2,2835-2,2835-2,2835-1,2835-1,2835-0
rule18=1,25,140-10
rule19=0,100,2781-4,2781-4,2781-4,2781-4,2781-8


layer
1,1,1,1,1,1,1,1,1,1,1,1,1,1,1,1,1,1,1,1,1,1,1,1,1,1,1,1,1
1,1,1,1,1,1,1,1,1,1,1,1,1,1,1,1,1,1,1,1,1,1,1,1,1,1,1,1,1
1,1,2,2,2,3,3,3,3,3,2,2,2,2,1,2,2,2,2,3,3,3,3,3,2,2,2,1,1
1,1,2,2,3,4,4,4,4,4,2,2,2,2,1,2,2,2,2,4,4,4,4,4,3,2,2,1,1
1,1,2,3,4,4,4,4,4,4,4,2,2,2,1,2,2,2,4,4,4,4,4,4,4,3,2,1,1
1,1,3,4,4,4,4,4,4,4,4,4,2,2,1,2,2,4,4,4,4,4,4,4,4,4,3,1,1
1,1,3,4,4,4,4,4,4,4,4,4,4,2,4,2,4,4,4,4,4,4,4,4,4,4,3,1,1
1,1,3,4,4,4,4,4,4,4,4,4,4,4,6,4,4,4,4,4,4,4,4,4,4,4,3,1,1
1,1,3,4,4,4,4,4,4,4,4,4,4,2,2,2,4,4,4,4,4,4,4,4,4,4,3,1,1
1,1,3,4,4,4,4,4,4,4,4,4,2,2,2,2,2,4,4,4,4,4,4,4,4,4,3,1,1
1,1,2,3,4,4,4,4,4,4,4,2,2,2,2,2,2,2,4,4,4,4,4,4,4,3,2,1,1
1,1,2,2,3,4,4,4,4,4,2,2,2,2,2,2,2,2,2,4,4,4,4,4,3,2,2,1,1
1,1,2,2,2,3,3,3,3,3,2,2,2,2,2,2,2,2,2,3,3,3,3,3,2,2,2,1,1
1,1,1,1,1,1,1,1,1,1,1,1,1,1,1,1,1,1,1,1,1,1,1,1,1,1,1,1,1
1,1,1,1,1,1,1,1,1,1,1,1,1,1,1,1,1,1,1,1,1,1,1,1,1,1,1,1,1
endlayer

layer
0,0,0,0,0,0,0,0,0,0,0,0,0,0,0,0,0,0,0,0,0,0,0,0,0,0,0,0,0
0,0,0,0,0,0,0,0,0,0,0,0,0,0,0,0,0,0,0,0,0,0,0,0,0,0,0,0,0
0,0,0,0,0,3,3,3,3,3,0,0,0,0,0,0,0,0,0,3,3,3,3,3,0,0,0,0,0
0,0,0,0,3,0,10,7,7,10,3,0,0,0,0,0,0,0,3,10,7,7,10,0,3,0,0,0,0
0,0,0,3,14,0,10,7,7,10,0,3,0,0,0,0,0,3,0,10,7,7,10,0,14,3,0,0,0
0,0,3,0,0,0,0,0,0,0,0,0,3,0,0,0,3,0,0,0,0,0,0,0,0,0,3,0,0
0,0,3,7,0,0,0,0,0,0,0,0,0,3,0,3,0,0,0,0,0,0,0,0,0,7,3,0,0
0,0,3,8,9,9,0,0,0,0,0,0,0,0,15,0,0,0,0,0,0,0,0,9,9,8,3,0,0
0,0,3,8,9,9,0,0,0,0,0,0,0,3,3,3,0,0,0,0,0,0,0,9,9,8,3,0,0
0,0,3,7,0,0,0,0,0,0,0,0,3,0,0,0,3,0,0,0,0,0,0,0,0,7,3,0,0
0,0,0,3,14,0,0,0,0,0,0,3,0,0,0,0,0,3,0,0,0,0,0,0,14,3,0,0,0
0,0,0,0,3,0,0,0,0,0,3,0,0,0,0,0,0,0,3,0,0,0,0,0,3,0,0,0,0
0,0,0,0,0,3,3,3,3,3,0,0,0,0,0,0,0,0,0,3,3,3,3,3,0,0,0,0,0
0,0,0,0,0,0,0,0,0,0,0,0,0,0,0,0,0,0,0,0,0,0,0,0,0,0,0,0,0
0,0,0,0,0,0,0,0,0,0,0,0,0,0,0,0,0,0,0,0,0,0,0,0,0,0,0,0,0
endlayer

layer
0,0,0,0,0,0,0,0,0,0,0,0,0,0,0,0,0,0,0,0,0,0,0,0,0,0,0,0,0
0,0,0,0,0,0,0,0,0,0,0,0,0,0,0,0,0,0,0,0,0,0,0,0,0,0,0,0,0
0,0,0,0,0,16,17,16,17,16,0,0,0,0,0,0,0,0,0,16,17,16,17,16,0,0,0,0,0
0,0,0,0,3,0,0,0,0,0,3,0,0,0,0,0,0,0,3,0,0,0,0,0,3,0,0,0,0
0,0,0,3,0,0,0,0,0,0,0,3,0,0,0,0,0,3,0,0,0,0,0,0,0,3,0,0,0
0,0,16,0,0,0,0,0,0,0,0,0,16,0,0,0,16,0,0,0,0,0,0,0,0,0,16,0,0
0,0,17,18,0,0,0,0,0,0,0,0,0,17,0,17,0,0,0,0,0,0,0,0,0,18,17,0,0
0,0,16,0,0,0,0,0,0,0,0,0,0,0,15,0,0,0,0,0,0,0,0,0,0,0,16,0,0
0,0,17,0,0,0,0,0,0,0,0,0,0,17,16,17,0,0,0,0,0,0,0,0,0,0,17,0,0
0,0,16,0,0,0,0,0,0,0,0,0,16,0,0,0,16,0,0,0,0,0,0,0,0,0,16,0,0
0,0,0,3,0,0,0,0,0,0,0,3,0,0,0,0,0,3,0,0,0,0,0,0,0,3,0,0,0
0,0,0,0,3,0,0,0,0,0,3,0,0,0,0,0,0,0,3,0,0,0,0,0,3,0,0,0,0
0,0,0,0,0,16,17,16,17,16,0,0,0,0,0,0,0,0,0,16,17,16,17,16,0,0,0,0,0
0,0,0,0,0,0,0,0,0,0,0,0,0,0,0,0,0,0,0,0,0,0,0,0,0,0,0,0,0
0,0,0,0,0,0,0,0,0,0,0,0,0,0,0,0,0,0,0,0,0,0,0,0,0,0,0,0,0
endlayer

layer
0,0,0,0,0,0,0,0,0,0,0,0,0,0,0,0,0,0,0,0,0,0,0,0,0,0,0,0,0
0,0,0,0,0,0,0,0,0,0,0,0,0,0,0,0,0,0,0,0,0,0,0,0,0,0,0,0,0
0,0,0,0,0,16,17,16,17,16,0,0,0,0,0,0,0,0,0,16,17,16,17,16,0,0,0,0,0
0,0,0,0,3,0,0,0,0,0,3,0,0,0,0,0,0,0,3,0,0,0,0,0,3,0,0,0,0
0,0,0,3,0,0,0,0,0,0,0,3,0,0,0,0,0,3,0,0,0,0,0,0,0,3,0,0,0
0,0,16,0,0,0,0,0,0,0,0,0,16,0,0,0,16,0,0,0,0,0,0,0,0,0,16,0,0
0,0,17,0,0,0,0,0,0,0,0,0,0,17,17,17,0,0,0,0,0,0,0,0,0,0,17,0,0
0,0,16,0,0,0,0,0,0,0,0,0,0,16,15,16,0,0,0,0,0,0,0,0,0,0,16,0,0
0,0,17,0,0,0,0,0,0,0,0,0,0,17,16,17,0,0,0,0,0,0,0,0,0,0,17,0,0
0,0,16,0,0,0,0,0,0,0,0,0,16,0,0,0,16,0,0,0,0,0,0,0,0,0,16,0,0
0,0,0,3,0,0,0,0,0,0,0,3,0,0,0,0,0,3,0,0,0,0,0,0,0,3,0,0,0
0,0,0,0,3,0,0,0,0,0,3,0,0,0,0,0,0,0,3,0,0,0,0,0,3,0,0,0,0
0,0,0,0,0,16,17,16,17,16,0,0,0,0,0,0,0,0,0,16,17,16,17,16,0,0,0,0,0
0,0,0,0,0,0,0,0,0,0,0,0,0,0,0,0,0,0,0,0,0,0,0,0,0,0,0,0,0
0,0,0,0,0,0,0,0,0,0,0,0,0,0,0,0,0,0,0,0,0,0,0,0,0,0,0,0,0
endlayer

layer
0,0,0,0,0,0,0,0,0,0,0,0,0,0,0,0,0,0,0,0,0,0,0,0,0,0,0,0,0
0,0,0,0,0,0,0,0,0,0,0,0,0,0,0,0,0,0,0,0,0,0,0,0,0,0,0,0,0
0,0,0,0,0,16,17,16,17,16,0,0,0,0,0,0,0,0,0,16,17,16,17,16,0,0,0,0,0
0,0,0,0,3,0,0,0,0,0,3,0,0,0,0,0,0,0,3,0,0,0,0,0,3,0,0,0,0
0,0,0,3,0,0,0,0,0,0,0,3,0,0,0,0,0,3,0,0,0,0,0,0,0,3,0,0,0
0,0,16,0,0,0,0,0,0,0,0,0,16,0,0,0,16,0,0,0,0,0,0,0,0,0,16,0,0
0,0,17,0,0,0,0,0,0,0,0,0,0,17,16,17,0,0,0,0,0,0,0,0,0,0,17,0,0
0,0,16,0,0,0,0,0,0,0,0,0,0,16,15,16,0,0,0,0,0,0,0,0,0,0,16,0,0
0,0,17,0,0,0,0,0,0,0,0,0,0,17,16,17,0,0,0,0,0,0,0,0,0,0,17,0,0
0,0,16,0,0,0,0,0,0,0,0,0,16,0,0,0,16,0,0,0,0,0,0,0,0,0,16,0,0
0,0,0,3,0,0,0,0,0,0,0,3,0,0,0,0,0,3,0,0,0,0,0,0,0,3,0,0,0
0,0,0,0,3,0,0,0,0,0,3,0,0,0,0,0,0,0,3,0,0,0,0,0,3,0,0,0,0
0,0,0,0,0,16,17,16,17,16,0,0,0,0,0,0,0,0,0,16,17,16,17,16,0,0,0,0,0
0,0,0,0,0,0,0,0,0,0,0,0,0,0,0,0,0,0,0,0,0,0,0,0,0,0,0,0,0
0,0,0,0,0,0,0,0,0,0,0,0,0,0,0,0,0,0,0,0,0,0,0,0,0,0,0,0,0
endlayer

layer
0,0,0,0,0,0,0,0,0,0,0,0,0,0,0,0,0,0,0,0,0,0,0,0,0,0,0,0,0
0,0,0,0,0,0,0,0,0,0,0,0,0,0,0,0,0,0,0,0,0,0,0,0,0,0,0,0,0
0,0,0,0,0,16,17,16,17,16,0,0,0,0,0,0,0,0,0,16,17,16,17,16,0,0,0,0,0
0,0,0,0,3,0,0,0,0,0,3,0,0,0,0,0,0,0,3,0,0,0,0,0,3,0,0,0,0
0,0,0,3,0,0,0,0,0,0,0,3,0,0,0,0,0,3,0,0,0,0,0,0,0,3,0,0,0
0,0,16,0,0,0,0,0,0,0,0,0,16,0,0,0,16,0,0,0,0,0,0,0,0,0,16,0,0
0,0,17,0,0,0,0,0,0,0,0,0,0,17,16,17,0,0,0,0,0,0,0,0,0,0,17,0,0
0,0,16,0,0,0,0,0,0,0,0,0,0,16,15,16,0,0,0,0,0,0,0,0,0,0,16,0,0
0,0,17,0,0,0,0,0,0,0,0,0,0,17,16,17,0,0,0,0,0,0,0,0,0,0,17,0,0
0,0,16,0,0,0,0,0,0,0,0,0,16,0,0,0,16,0,0,0,0,0,0,0,0,0,16,0,0
0,0,0,3,0,0,0,0,0,0,0,3,0,0,0,0,0,3,0,0,0,0,0,0,0,3,0,0,0
0,0,0,0,3,0,0,0,0,0,3,0,0,0,0,0,0,0,3,0,0,0,0,0,3,0,0,0,0
0,0,0,0,0,16,17,16,17,16,0,0,0,0,0,0,0,0,0,16,17,16,17,16,0,0,0,0,0
0,0,0,0,0,0,0,0,0,0,0,0,0,0,0,0,0,0,0,0,0,0,0,0,0,0,0,0,0
0,0,0,0,0,0,0,0,0,0,0,0,0,0,0,0,0,0,0,0,0,0,0,0,0,0,0,0,0
endlayer

layer
0,0,0,0,0,0,0,0,0,0,0,0,0,0,0,0,0,0,0,0,0,0,0,0,0,0,0,0,0
0,0,0,0,0,0,0,0,0,0,0,0,0,0,0,0,0,0,0,0,0,0,0,0,0,0,0,0,0
0,0,0,0,0,16,17,16,17,16,0,0,0,0,0,0,0,0,0,16,17,16,17,16,0,0,0,0,0
0,0,0,0,3,0,0,0,0,0,3,0,0,0,0,0,0,0,3,0,0,0,0,0,3,0,0,0,0
0,0,0,3,0,0,0,0,0,0,0,3,0,0,0,0,0,3,0,0,0,0,0,0,0,3,0,0,0
0,0,16,0,0,0,0,0,0,0,0,0,16,0,0,0,16,0,0,0,0,0,0,0,0,0,16,0,0
0,0,17,0,0,0,0,0,0,0,0,0,0,17,16,17,0,0,0,0,0,0,0,0,0,0,17,0,0
0,0,16,0,0,0,0,0,0,0,0,0,0,16,15,16,0,0,0,0,0,0,0,0,0,0,16,0,0
0,0,17,0,0,0,0,0,0,0,0,0,0,17,16,17,0,0,0,0,0,0,0,0,0,0,17,0,0
0,0,16,0,0,0,0,0,0,0,0,0,16,0,0,0,16,0,0,0,0,0,0,0,0,0,16,0,0
0,0,0,3,0,0,0,0,0,0,0,3,0,0,0,0,0,3,0,0,0,0,0,0,0,3,0,0,0
0,0,0,0,3,0,0,0,0,0,3,0,0,0,0,0,0,0,3,0,0,0,0,0,3,0,0,0,0
0,0,0,0,0,16,17,16,17,16,0,0,0,0,0,0,0,0,0,16,17,16,17,16,0,0,0,0,0
0,0,0,0,0,0,0,0,0,0,0,0,0,0,0,0,0,0,0,0,0,0,0,0,0,0,0,0,0
0,0,0,0,0,0,0,0,0,0,0,0,0,0,0,0,0,0,0,0,0,0,0,0,0,0,0,0,0
endlayer

layer
0,0,0,0,0,0,0,0,0,0,0,0,0,0,0,0,0,0,0,0,0,0,0,0,0,0,0,0,0
0,0,0,0,0,0,0,0,0,0,0,0,0,0,0,0,0,0,0,0,0,0,0,0,0,0,0,0,0
0,0,0,0,0,3,3,3,3,3,0,0,0,0,0,0,0,0,0,3,3,3,3,3,0,0,0,0,0
0,0,0,0,3,4,4,4,4,4,3,0,0,0,0,0,0,0,3,4,4,4,4,4,3,0,0,0,0
0,0,0,3,4,4,4,4,4,4,4,3,0,0,0,0,0,3,4,4,4,4,4,4,4,3,0,0,0
0,0,3,4,4,4,4,4,4,4,4,4,3,0,0,0,3,4,4,4,4,4,4,4,4,4,3,0,0
0,0,3,4,4,4,4,4,4,4,4,4,4,3,3,3,4,4,4,4,4,4,4,4,4,4,3,0,0
0,0,3,4,4,4,4,4,4,4,4,4,4,4,15,4,4,4,4,4,4,4,4,4,4,4,3,0,0
0,0,3,4,4,4,4,4,4,4,4,4,4,3,3,3,4,4,4,4,4,4,4,4,4,4,3,0,0
0,0,3,4,4,4,4,4,4,4,4,4,3,0,0,0,3,4,4,4,4,4,4,4,4,4,3,0,0
0,0,0,3,4,4,4,4,4,4,4,3,0,0,0,0,0,3,4,4,4,4,4,4,4,3,0,0,0
0,0,0,0,3,4,4,4,4,4,3,0,0,0,0,0,0,0,3,4,4,4,4,4,3,0,0,0,0
0,0,0,0,0,3,3,3,3,3,0,0,0,0,0,0,0,0,0,3,3,3,3,3,0,0,0,0,0
0,0,0,0,0,0,0,0,0,0,0,0,0,0,0,0,0,0,0,0,0,0,0,0,0,0,0,0,0
0,0,0,0,0,0,0,0,0,0,0,0,0,0,0,0,0,0,0,0,0,0,0,0,0,0,0,0,0
endlayer

layer
0,0,0,0,0,0,0,0,0,0,0,0,0,0,0,0,0,0,0,0,0,0,0,0,0,0,0,0,0
0,0,0,0,0,0,0,0,0,0,0,0,0,0,0,0,0,0,0,0,0,0,0,0,0,0,0,0,0
0,0,0,0,0,16,17,16,17,16,0,0,0,0,0,0,0,0,0,16,17,16,17,16,0,0,0,0,0
0,0,0,0,3,0,10,7,7,10,3,0,0,0,0,0,0,0,3,10,7,7,10,0,3,0,0,0,0
0,0,0,3,14,0,10,7,7,10,0,3,0,0,0,0,0,3,0,10,7,7,10,0,14,3,0,0,0
0,0,16,0,0,0,0,0,0,0,0,0,16,0,0,0,16,0,0,0,0,0,0,0,0,0,16,0,0
0,0,17,7,0,0,0,0,0,0,0,0,0,17,16,17,0,0,0,0,0,0,0,0,0,7,17,0,0
0,0,16,8,9,9,0,0,0,0,0,0,0,0,15,0,0,0,0,0,0,0,0,9,9,8,16,0,0
0,0,17,8,9,9,0,0,0,0,0,0,0,17,16,17,0,0,0,0,0,0,0,9,9,8,17,0,0
0,0,16,7,0,0,0,0,0,0,0,0,16,0,0,0,16,0,0,0,0,0,0,0,0,7,16,0,0
0,0,0,3,14,0,0,0,0,0,0,3,0,0,0,0,0,3,0,0,0,0,0,0,14,3,0,0,0
0,0,0,0,3,0,0,0,0,0,3,0,0,0,0,0,0,0,3,0,0,0,0,0,3,0,0,0,0
0,0,0,0,0,16,17,16,17,16,0,0,0,0,0,0,0,0,0,16,17,16,17,16,0,0,0,0,0
0,0,0,0,0,0,0,0,0,0,0,0,0,0,0,0,0,0,0,0,0,0,0,0,0,0,0,0,0
0,0,0,0,0,0,0,0,0,0,0,0,0,0,0,0,0,0,0,0,0,0,0,0,0,0,0,0,0
endlayer

layer
0,0,0,0,0,0,0,0,0,0,0,0,0,0,0,0,0,0,0,0,0,0,0,0,0,0,0,0,0
0,0,0,0,0,0,0,0,0,0,0,0,0,0,0,0,0,0,0,0,0,0,0,0,0,0,0,0,0
0,0,0,0,0,16,17,16,17,16,0,0,0,0,0,0,0,0,0,16,17,16,17,16,0,0,0,0,0
0,0,0,0,3,0,0,0,0,0,3,0,0,0,0,0,0,0,3,0,0,0,0,0,3,0,0,0,0
0,0,0,3,0,0,0,0,0,0,0,3,0,0,0,0,0,3,0,0,0,0,0,0,0,3,0,0,0
0,0,16,0,0,0,0,0,0,0,0,0,16,0,0,0,16,0,0,0,0,0,0,0,0,0,16,0,0
0,0,17,18,0,0,0,0,0,0,0,0,0,17,16,17,0,0,0,0,0,0,0,0,0,18,17,0,0
0,0,16,0,0,0,0,0,0,0,0,0,0,0,15,0,0,0,0,0,0,0,0,0,0,0,16,0,0
0,0,17,0,0,0,0,0,0,0,0,0,0,17,16,17,0,0,0,0,0,0,0,0,0,0,17,0,0
0,0,16,0,0,0,0,0,0,0,0,0,16,0,0,0,16,0,0,0,0,0,0,0,0,0,16,0,0
0,0,0,3,0,0,0,0,0,0,0,3,0,0,0,0,0,3,0,0,0,0,0,0,0,3,0,0,0
0,0,0,0,3,0,0,0,0,0,3,0,0,0,0,0,0,0,3,0,0,0,0,0,3,0,0,0,0
0,0,0,0,0,16,17,16,17,16,0,0,0,0,0,0,0,0,0,16,17,16,17,16,0,0,0,0,0
0,0,0,0,0,0,0,0,0,0,0,0,0,0,0,0,0,0,0,0,0,0,0,0,0,0,0,0,0
0,0,0,0,0,0,0,0,0,0,0,0,0,0,0,0,0,0,0,0,0,0,0,0,0,0,0,0,0
endlayer

layer
0,0,0,0,0,0,0,0,0,0,0,0,0,0,0,0,0,0,0,0,0,0,0,0,0,0,0,0,0
0,0,0,0,0,0,0,0,0,0,0,0,0,0,0,0,0,0,0,0,0,0,0,0,0,0,0,0,0
0,0,0,0,0,16,17,16,17,16,0,0,0,0,0,0,0,0,0,16,17,16,17,16,0,0,0,0,0
0,0,0,0,3,0,0,0,0,0,3,0,0,0,0,0,0,0,3,0,0,0,0,0,3,0,0,0,0
0,0,0,3,0,0,0,0,0,0,0,3,0,0,0,0,0,3,0,0,0,0,0,0,0,3,0,0,0
0,0,16,0,0,0,0,0,0,0,0,0,16,0,0,0,16,0,0,0,0,0,0,0,0,0,16,0,0
0,0,17,0,0,0,0,0,0,0,0,0,0,17,16,17,0,0,0,0,0,0,0,0,0,0,17,0,0
0,0,16,0,0,0,0,0,0,0,0,0,0,16,15,16,0,0,0,0,0,0,0,0,0,0,16,0,0
0,0,17,0,0,0,0,0,0,0,0,0,0,17,16,17,0,0,0,0,0,0,0,0,0,0,17,0,0
0,0,16,0,0,0,0,0,0,0,0,0,16,0,0,0,16,0,0,0,0,0,0,0,0,0,16,0,0
0,0,0,3,0,0,0,0,0,0,0,3,0,0,0,0,0,3,0,0,0,0,0,0,0,3,0,0,0
0,0,0,0,3,0,0,0,0,0,3,0,0,0,0,0,0,0,3,0,0,0,0,0,3,0,0,0,0
0,0,0,0,0,16,17,16,17,16,0,0,0,0,0,0,0,0,0,16,17,16,17,16,0,0,0,0,0
0,0,0,0,0,0,0,0,0,0,0,0,0,0,0,0,0,0,0,0,0,0,0,0,0,0,0,0,0
0,0,0,0,0,0,0,0,0,0,0,0,0,0,0,0,0,0,0,0,0,0,0,0,0,0,0,0,0
endlayer

layer
0,0,0,0,0,0,0,0,0,0,0,0,0,0,0,0,0,0,0,0,0,0,0,0,0,0,0,0,0
0,0,0,0,0,0,0,0,0,0,0,0,0,0,0,0,0,0,0,0,0,0,0,0,0,0,0,0,0
0,0,0,0,0,16,17,16,17,16,0,0,0,0,0,0,0,0,0,16,17,16,17,16,0,0,0,0,0
0,0,0,0,3,0,0,0,0,0,3,0,0,0,0,0,0,0,3,0,0,0,0,0,3,0,0,0,0
0,0,0,3,0,0,0,0,0,0,0,3,0,0,0,0,0,3,0,0,0,0,0,0,0,3,0,0,0
0,0,16,0,0,0,0,0,0,0,0,0,16,0,0,0,16,0,0,0,0,0,0,0,0,0,16,0,0
0,0,17,0,0,0,0,0,0,0,0,0,0,17,16,17,0,0,0,0,0,0,0,0,0,0,17,0,0
0,0,16,0,0,0,0,0,0,0,0,0,0,16,15,16,0,0,0,0,0,0,0,0,0,0,16,0,0
0,0,17,0,0,0,0,0,0,0,0,0,0,17,16,17,0,0,0,0,0,0,0,0,0,0,17,0,0
0,0,16,0,0,0,0,0,0,0,0,0,16,0,0,0,16,0,0,0,0,0,0,0,0,0,16,0,0
0,0,0,3,0,0,0,0,0,0,0,3,0,0,0,0,0,3,0,0,0,0,0,0,0,3,0,0,0
0,0,0,0,3,0,0,0,0,0,3,0,0,0,0,0,0,0,3,0,0,0,0,0,3,0,0,0,0
0,0,0,0,0,16,17,16,17,16,0,0,0,0,0,0,0,0,0,16,17,16,17,16,0,0,0,0,0
0,0,0,0,0,0,0,0,0,0,0,0,0,0,0,0,0,0,0,0,0,0,0,0,0,0,0,0,0
0,0,0,0,0,0,0,0,0,0,0,0,0,0,0,0,0,0,0,0,0,0,0,0,0,0,0,0,0
endlayer

layer
0,0,0,0,0,0,0,0,0,0,0,0,0,0,0,0,0,0,0,0,0,0,0,0,0,0,0,0,0
0,0,0,0,0,0,0,0,0,0,0,0,0,0,0,0,0,0,0,0,0,0,0,0,0,0,0,0,0
0,0,0,0,0,16,17,16,17,16,0,0,0,0,0,0,0,0,0,16,17,16,17,16,0,0,0,0,0
0,0,0,0,3,0,0,0,0,0,3,0,0,0,0,0,0,0,3,0,0,0,0,0,3,0,0,0,0
0,0,0,3,0,0,0,0,0,0,0,3,0,0,0,0,0,3,0,0,0,0,0,0,0,3,0,0,0
0,0,16,0,0,0,0,0,0,0,0,0,16,0,0,0,16,0,0,0,0,0,0,0,0,0,16,0,0
0,0,17,0,0,0,0,0,0,0,0,0,0,17,16,17,0,0,0,0,0,0,0,0,0,0,17,0,0
0,0,16,0,0,0,0,0,0,0,0,0,0,16,15,16,0,0,0,0,0,0,0,0,0,0,16,0,0
0,0,17,0,0,0,0,0,0,0,0,0,0,17,16,17,0,0,0,0,0,0,0,0,0,0,17,0,0
0,0,16,0,0,0,0,0,0,0,0,0,16,0,0,0,16,0,0,0,0,0,0,0,0,0,16,0,0
0,0,0,3,0,0,0,0,0,0,0,3,0,0,0,0,0,3,0,0,0,0,0,0,0,3,0,0,0
0,0,0,0,3,0,0,0,0,0,3,0,0,0,0,0,0,0,3,0,0,0,0,0,3,0,0,0,0
0,0,0,0,0,16,17,16,17,16,0,0,0,0,0,0,0,0,0,16,17,16,17,16,0,0,0,0,0
0,0,0,0,0,0,0,0,0,0,0,0,0,0,0,0,0,0,0,0,0,0,0,0,0,0,0,0,0
0,0,0,0,0,0,0,0,0,0,0,0,0,0,0,0,0,0,0,0,0,0,0,0,0,0,0,0,0
endlayer

layer
0,0,0,0,0,0,0,0,0,0,0,0,0,0,0,0,0,0,0,0,0,0,0,0,0,0,0,0,0
0,0,0,0,0,0,0,0,0,0,0,0,0,0,0,0,0,0,0,0,0,0,0,0,0,0,0,0,0
0,0,0,0,0,16,17,16,17,16,0,0,0,0,0,0,0,0,0,16,17,16,17,16,0,0,0,0,0
0,0,0,0,3,0,0,0,0,0,3,0,0,0,0,0,0,0,3,0,0,0,0,0,3,0,0,0,0
0,0,0,3,0,0,0,0,0,0,0,3,0,0,0,0,0,3,0,0,0,0,0,0,0,3,0,0,0
0,0,16,0,0,0,0,0,0,0,0,0,16,0,0,0,16,0,0,0,0,0,0,0,0,0,16,0,0
0,0,17,0,0,0,0,0,0,0,0,0,0,17,16,17,0,0,0,0,0,0,0,0,0,0,17,0,0
0,0,16,0,0,0,0,0,0,0,0,0,0,16,15,16,0,0,0,0,0,0,0,0,0,0,16,0,0
0,0,17,0,0,0,0,0,0,0,0,0,0,17,16,17,0,0,0,0,0,0,0,0,0,0,17,0,0
0,0,16,0,0,0,0,0,0,0,0,0,16,0,0,0,16,0,0,0,0,0,0,0,0,0,16,0,0
0,0,0,3,0,0,0,0,0,0,0,3,0,0,0,0,0,3,0,0,0,0,0,0,0,3,0,0,0
0,0,0,0,3,0,0,0,0,0,3,0,0,0,0,0,0,0,3,0,0,0,0,0,3,0,0,0,0
0,0,0,0,0,16,17,16,17,16,0,0,0,0,0,0,0,0,0,16,17,16,17,16,0,0,0,0,0
0,0,0,0,0,0,0,0,0,0,0,0,0,0,0,0,0,0,0,0,0,0,0,0,0,0,0,0,0
0,0,0,0,0,0,0,0,0,0,0,0,0,0,0,0,0,0,0,0,0,0,0,0,0,0,0,0,0
endlayer

layer
0,0,0,0,0,0,0,0,0,0,0,0,0,0,0,0,0,0,0,0,0,0,0,0,0,0,0,0,0
0,0,0,0,0,0,0,0,0,0,0,0,0,0,0,0,0,0,0,0,0,0,0,0,0,0,0,0,0
0,0,0,0,0,3,3,3,3,3,0,0,0,0,0,0,0,0,0,3,3,3,3,3,0,0,0,0,0
0,0,0,0,3,4,4,4,4,4,3,0,0,0,0,0,0,0,3,4,4,4,4,4,3,0,0,0,0
0,0,0,3,4,4,4,4,4,4,4,3,0,0,0,0,0,3,4,4,4,4,4,4,4,3,0,0,0
0,0,3,4,4,4,4,4,4,4,4,4,3,0,0,0,3,4,4,4,4,4,4,4,4,4,3,0,0
0,0,3,4,4,4,4,4,4,4,4,4,4,3,3,3,4,4,4,4,4,4,4,4,4,4,3,0,0
0,0,3,4,4,4,4,4,4,4,4,4,4,4,15,4,4,4,4,4,4,4,4,4,4,4,3,0,0
0,0,3,4,4,4,4,4,4,4,4,4,4,3,3,3,4,4,4,4,4,4,4,4,4,4,3,0,0
0,0,3,4,4,4,4,4,4,4,4,4,3,0,0,0,3,4,4,4,4,4,4,4,4,4,3,0,0
0,0,0,3,4,4,4,4,4,4,4,3,0,0,0,0,0,3,4,4,4,4,4,4,4,3,0,0,0
0,0,0,0,3,4,4,4,4,4,3,0,0,0,0,0,0,0,3,4,4,4,4,4,3,0,0,0,0
0,0,0,0,0,3,3,3,3,3,0,0,0,0,0,0,0,0,0,3,3,3,3,3,0,0,0,0,0
0,0,0,0,0,0,0,0,0,0,0,0,0,0,0,0,0,0,0,0,0,0,0,0,0,0,0,0,0
0,0,0,0,0,0,0,0,0,0,0,0,0,0,0,0,0,0,0,0,0,0,0,0,0,0,0,0,0
endlayer

layer
0,0,0,0,0,0,0,0,0,0,0,0,0,0,0,0,0,0,0,0,0,0,0,0,0,0,0,0,0
0,0,0,0,0,0,0,0,0,0,0,0,0,0,0,0,0,0,0,0,0,0,0,0,0,0,0,0,0
0,0,0,0,0,16,17,16,17,16,0,0,0,0,0,0,0,0,0,16,17,16,17,16,0,0,0,0,0
0,0,0,0,3,0,10,7,7,10,3,0,0,0,0,0,0,0,3,10,7,7,10,0,3,0,0,0,0
0,0,0,3,14,0,10,7,7,10,0,3,0,0,0,0,0,3,0,10,7,7,10,0,14,3,0,0,0
0,0,16,0,0,0,0,0,0,0,0,0,16,0,0,0,16,0,0,0,0,0,0,0,0,0,16,0,0
0,0,17,7,0,0,0,0,0,0,0,0,0,17,16,17,0,0,0,0,0,0,0,0,0,7,17,0,0
0,0,16,8,9,9,0,0,0,0,0,0,0,0,15,0,0,0,0,0,0,0,0,9,9,8,16,0,0
0,0,17,8,9,9,0,0,0,0,0,0,0,17,16,17,0,0,0,0,0,0,0,9,9,8,17,0,0
0,0,16,7,0,0,0,0,0,0,0,0,16,0,0,0,16,0,0,0,0,0,0,0,0,7,16,0,0
0,0,0,3,14,0,0,0,0,0,0,3,0,0,0,0,0,3,0,0,0,0,0,0,14,3,0,0,0
0,0,0,0,3,0,0,0,0,0,3,0,0,0,0,0,0,0,3,0,0,0,0,0,3,0,0,0,0
0,0,0,0,0,16,17,16,17,16,0,0,0,0,0,0,0,0,0,16,17,16,17,16,0,0,0,0,0
0,0,0,0,0,0,0,0,0,0,0,0,0,0,0,0,0,0,0,0,0,0,0,0,0,0,0,0,0
0,0,0,0,0,0,0,0,0,0,0,0,0,0,0,0,0,0,0,0,0,0,0,0,0,0,0,0,0
endlayer

layer
0,0,0,0,0,0,0,0,0,0,0,0,0,0,0,0,0,0,0,0,0,0,0,0,0,0,0,0,0
0,0,0,0,0,0,0,0,0,0,0,0,0,0,0,0,0,0,0,0,0,0,0,0,0,0,0,0,0
0,0,0,0,0,16,17,16,17,16,0,0,0,0,0,0,0,0,0,16,17,16,17,16,0,0,0,0,0
0,0,0,0,3,0,0,0,0,0,3,0,0,0,0,0,0,0,3,0,0,0,0,0,3,0,0,0,0
0,0,0,3,0,0,0,0,0,0,0,3,0,0,0,0,0,3,0,0,0,0,0,0,0,3,0,0,0
0,0,16,0,0,0,0,0,0,0,0,0,16,0,0,0,16,0,0,0,0,0,0,0,0,0,16,0,0
0,0,17,18,0,0,0,0,0,0,0,0,0,17,16,17,0,0,0,0,0,0,0,0,0,18,17,0,0
0,0,16,0,0,0,0,0,0,0,0,0,0,0,15,0,0,0,0,0,0,0,0,0,0,0,16,0,0
0,0,17,0,0,0,0,0,0,0,0,0,0,17,16,17,0,0,0,0,0,0,0,0,0,0,17,0,0
0,0,16,0,0,0,0,0,0,0,0,0,16,0,0,0,16,0,0,0,0,0,0,0,0,0,16,0,0
0,0,0,3,0,0,0,0,0,0,0,3,0,0,0,0,0,3,0,0,0,0,0,0,0,3,0,0,0
0,0,0,0,3,0,0,0,0,0,3,0,0,0,0,0,0,0,3,0,0,0,0,0,3,0,0,0,0
0,0,0,0,0,16,17,16,17,16,0,0,0,0,0,0,0,0,0,16,17,16,17,16,0,0,0,0,0
0,0,0,0,0,0,0,0,0,0,0,0,0,0,0,0,0,0,0,0,0,0,0,0,0,0,0,0,0
0,0,0,0,0,0,0,0,0,0,0,0,0,0,0,0,0,0,0,0,0,0,0,0,0,0,0,0,0
endlayer

layer
0,0,0,0,0,0,0,0,0,0,0,0,0,0,0,0,0,0,0,0,0,0,0,0,0,0,0,0,0
0,0,0,0,0,0,0,0,0,0,0,0,0,0,0,0,0,0,0,0,0,0,0,0,0,0,0,0,0
0,0,0,0,0,16,17,16,17,16,0,0,0,0,0,0,0,0,0,16,17,16,17,16,0,0,0,0,0
0,0,0,0,3,0,0,0,0,0,3,0,0,0,0,0,0,0,3,0,0,0,0,0,3,0,0,0,0
0,0,0,3,0,0,0,0,0,0,0,3,0,0,0,0,0,3,0,0,0,0,0,0,0,3,0,0,0
0,0,16,0,0,0,0,0,0,0,0,0,16,0,0,0,16,0,0,0,0,0,0,0,0,0,16,0,0
0,0,17,0,0,0,0,0,0,0,0,0,0,17,16,17,0,0,0,0,0,0,0,0,0,0,17,0,0
0,0,16,0,0,0,0,0,0,0,0,0,0,16,15,16,0,0,0,0,0,0,0,0,0,0,16,0,0
0,0,17,0,0,0,0,0,0,0,0,0,0,17,16,17,0,0,0,0,0,0,0,0,0,0,17,0,0
0,0,16,0,0,0,0,0,0,0,0,0,16,0,0,0,16,0,0,0,0,0,0,0,0,0,16,0,0
0,0,0,3,0,0,0,0,0,0,0,3,0,0,0,0,0,3,0,0,0,0,0,0,0,3,0,0,0
0,0,0,0,3,0,0,0,0,0,3,0,0,0,0,0,0,0,3,0,0,0,0,0,3,0,0,0,0
0,0,0,0,0,16,17,16,17,16,0,0,0,0,0,0,0,0,0,16,17,16,17,16,0,0,0,0,0
0,0,0,0,0,0,0,0,0,0,0,0,0,0,0,0,0,0,0,0,0,0,0,0,0,0,0,0,0
0,0,0,0,0,0,0,0,0,0,0,0,0,0,0,0,0,0,0,0,0,0,0,0,0,0,0,0,0
endlayer

layer
0,0,0,0,0,0,0,0,0,0,0,0,0,0,0,0,0,0,0,0,0,0,0,0,0,0,0,0,0
0,0,0,0,0,0,0,0,0,0,0,0,0,0,0,0,0,0,0,0,0,0,0,0,0,0,0,0,0
0,0,0,0,0,16,17,16,17,16,0,0,0,0,0,0,0,0,0,16,17,16,17,16,0,0,0,0,0
0,0,0,0,3,0,0,0,0,0,3,0,0,0,0,0,0,0,3,0,0,0,0,0,3,0,0,0,0
0,0,0,3,0,0,0,0,0,0,0,3,0,0,0,0,0,3,0,0,0,0,0,0,0,3,0,0,0
0,0,16,0,0,0,0,0,0,0,0,0,16,0,0,0,16,0,0,0,0,0,0,0,0,0,16,0,0
0,0,17,0,0,0,0,0,0,0,0,0,0,17,16,17,0,0,0,0,0,0,0,0,0,0,17,0,0
0,0,16,0,0,0,0,0,0,0,0,0,0,16,15,16,0,0,0,0,0,0,0,0,0,0,16,0,0
0,0,17,0,0,0,0,0,0,0,0,0,0,17,16,17,0,0,0,0,0,0,0,0,0,0,17,0,0
0,0,16,0,0,0,0,0,0,0,0,0,16,0,0,0,16,0,0,0,0,0,0,0,0,0,16,0,0
0,0,0,3,0,0,0,0,0,0,0,3,0,0,0,0,0,3,0,0,0,0,0,0,0,3,0,0,0
0,0,0,0,3,0,0,0,0,0,3,0,0,0,0,0,0,0,3,0,0,0,0,0,3,0,0,0,0
0,0,0,0,0,16,17,16,17,16,0,0,0,0,0,0,0,0,0,16,17,16,17,16,0,0,0,0,0
0,0,0,0,0,0,0,0,0,0,0,0,0,0,0,0,0,0,0,0,0,0,0,0,0,0,0,0,0
0,0,0,0,0,0,0,0,0,0,0,0,0,0,0,0,0,0,0,0,0,0,0,0,0,0,0,0,0
endlayer

layer
0,0,0,0,0,0,0,0,0,0,0,0,0,0,0,0,0,0,0,0,0,0,0,0,0,0,0,0,0
0,0,0,0,0,0,0,0,0,0,0,0,0,0,0,0,0,0,0,0,0,0,0,0,0,0,0,0,0
0,0,0,0,0,16,17,16,17,16,0,0,0,0,0,0,0,0,0,16,17,16,17,16,0,0,0,0,0
0,0,0,0,3,0,0,0,0,0,3,0,0,0,0,0,0,0,3,0,0,0,0,0,3,0,0,0,0
0,0,0,3,0,0,0,0,0,0,0,3,0,0,0,0,0,3,0,0,0,0,0,0,0,3,0,0,0
0,0,16,0,0,0,0,0,0,0,0,0,16,0,0,0,16,0,0,0,0,0,0,0,0,0,16,0,0
0,0,17,0,0,0,0,0,0,0,0,0,0,17,16,17,0,0,0,0,0,0,0,0,0,0,17,0,0
0,0,16,0,0,0,0,0,0,0,0,0,0,16,15,16,0,0,0,0,0,0,0,0,0,0,16,0,0
0,0,17,0,0,0,0,0,0,0,0,0,0,17,16,17,0,0,0,0,0,0,0,0,0,0,17,0,0
0,0,16,0,0,0,0,0,0,0,0,0,16,0,0,0,16,0,0,0,0,0,0,0,0,0,16,0,0
0,0,0,3,0,0,0,0,0,0,0,3,0,0,0,0,0,3,0,0,0,0,0,0,0,3,0,0,0
0,0,0,0,3,0,0,0,0,0,3,0,0,0,0,0,0,0,3,0,0,0,0,0,3,0,0,0,0
0,0,0,0,0,16,17,16,17,16,0,0,0,0,0,0,0,0,0,16,17,16,17,16,0,0,0,0,0
0,0,0,0,0,0,0,0,0,0,0,0,0,0,0,0,0,0,0,0,0,0,0,0,0,0,0,0,0
0,0,0,0,0,0,0,0,0,0,0,0,0,0,0,0,0,0,0,0,0,0,0,0,0,0,0,0,0
endlayer

layer
0,0,0,0,0,0,0,0,0,0,0,0,0,0,0,0,0,0,0,0,0,0,0,0,0,0,0,0,0
0,0,0,0,0,0,0,0,0,0,0,0,0,0,0,0,0,0,0,0,0,0,0,0,0,0,0,0,0
0,0,0,0,0,16,17,16,17,16,0,0,0,0,0,0,0,0,0,16,17,16,17,16,0,0,0,0,0
0,0,0,0,3,0,0,0,0,0,3,0,0,0,0,0,0,0,3,0,0,0,0,0,3,0,0,0,0
0,0,0,3,0,0,0,0,0,0,0,3,0,0,0,0,0,3,0,0,0,0,0,0,0,3,0,0,0
0,0,16,0,0,0,0,0,0,0,0,0,16,0,0,0,16,0,0,0,0,0,0,0,0,0,16,0,0
0,0,17,0,0,0,0,0,0,0,0,0,0,17,16,17,0,0,0,0,0,0,0,0,0,0,17,0,0
0,0,16,0,0,0,0,0,0,0,0,0,0,16,15,16,0,0,0,0,0,0,0,0,0,0,16,0,0
0,0,17,0,0,0,0,0,0,0,0,0,0,17,16,17,0,0,0,0,0,0,0,0,0,0,17,0,0
0,0,16,0,0,0,0,0,0,0,0,0,16,0,0,0,16,0,0,0,0,0,0,0,0,0,16,0,0
0,0,0,3,0,0,0,0,0,0,0,3,0,0,0,0,0,3,0,0,0,0,0,0,0,3,0,0,0
0,0,0,0,3,0,0,0,0,0,3,0,0,0,0,0,0,0,3,0,0,0,0,0,3,0,0,0,0
0,0,0,0,0,16,17,16,17,16,0,0,0,0,0,0,0,0,0,16,17,16,17,16,0,0,0,0,0
0,0,0,0,0,0,0,0,0,0,0,0,0,0,0,0,0,0,0,0,0,0,0,0,0,0,0,0,0
0,0,0,0,0,0,0,0,0,0,0,0,0,0,0,0,0,0,0,0,0,0,0,0,0,0,0,0,0
endlayer

layer
0,0,0,0,0,0,0,0,0,0,0,0,0,0,0,0,0,0,0,0,0,0,0,0,0,0,0,0,0
0,0,0,0,0,0,0,0,0,0,0,0,0,0,0,0,0,0,0,0,0,0,0,0,0,0,0,0,0
0,0,0,0,0,3,3,3,3,3,0,0,0,0,0,0,0,0,0,3,3,3,3,3,0,0,0,0,0
0,0,0,0,3,4,4,4,4,4,3,0,0,0,0,0,0,0,3,4,4,4,4,4,3,0,0,0,0
0,0,0,3,4,4,4,4,4,4,4,3,0,0,0,0,0,3,4,4,4,4,4,4,4,3,0,0,0
0,0,3,4,4,4,4,4,4,4,4,4,3,0,0,0,3,4,4,4,4,4,4,4,4,4,3,0,0
0,0,3,4,4,4,4,4,4,4,4,4,4,3,3,3,4,4,4,4,4,4,4,4,4,4,3,0,0
0,0,3,4,4,4,4,4,4,4,4,4,4,4,15,4,4,4,4,4,4,4,4,4,4,4,3,0,0
0,0,3,4,4,4,4,4,4,4,4,4,4,3,3,3,4,4,4,4,4,4,4,4,4,4,3,0,0
0,0,3,4,4,4,4,4,4,4,4,4,3,0,0,0,3,4,4,4,4,4,4,4,4,4,3,0,0
0,0,0,3,4,4,4,4,4,4,4,3,0,0,0,0,0,3,4,4,4,4,4,4,4,3,0,0,0
0,0,0,0,3,4,4,4,4,4,3,0,0,0,0,0,0,0,3,4,4,4,4,4,3,0,0,0,0
0,0,0,0,0,3,3,3,3,3,0,0,0,0,0,0,0,0,0,3,3,3,3,3,0,0,0,0,0
0,0,0,0,0,0,0,0,0,0,0,0,0,0,0,0,0,0,0,0,0,0,0,0,0,0,0,0,0
0,0,0,0,0,0,0,0,0,0,0,0,0,0,0,0,0,0,0,0,0,0,0,0,0,0,0,0,0
endlayer

layer
0,0,0,0,0,0,0,0,0,0,0,0,0,0,0,0,0,0,0,0,0,0,0,0,0,0,0,0,0
0,0,0,0,0,0,0,0,0,0,0,0,0,0,0,0,0,0,0,0,0,0,0,0,0,0,0,0,0
0,0,0,0,0,16,17,16,17,16,0,0,0,0,0,0,0,0,0,16,17,16,17,16,0,0,0,0,0
0,0,0,0,3,0,10,7,7,10,3,0,0,0,0,0,0,0,3,10,7,7,10,0,3,0,0,0,0
0,0,0,3,14,0,10,7,7,10,0,3,0,0,0,0,0,3,0,10,7,7,10,0,14,3,0,0,0
0,0,16,0,0,0,0,0,0,0,0,0,16,0,0,0,16,0,0,0,0,0,0,0,0,0,16,0,0
0,0,17,7,0,0,0,0,0,0,0,0,0,17,16,17,0,0,0,0,0,0,0,0,0,7,17,0,0
0,0,16,8,9,9,0,0,0,0,0,0,0,0,15,0,0,0,0,0,0,0,0,9,9,8,16,0,0
0,0,17,8,9,9,0,0,0,0,0,0,0,17,16,17,0,0,0,0,0,0,0,9,9,8,17,0,0
0,0,16,7,0,0,0,0,0,0,0,0,16,0,0,0,16,0,0,0,0,0,0,0,0,7,16,0,0
0,0,0,3,14,0,0,0,0,0,0,3,0,0,0,0,0,3,0,0,0,0,0,0,14,3,0,0,0
0,0,0,0,3,0,0,0,0,0,3,0,0,0,0,0,0,0,3,0,0,0,0,0,3,0,0,0,0
0,0,0,0,0,16,17,16,17,16,0,0,0,0,0,0,0,0,0,16,17,16,17,16,0,0,0,0,0
0,0,0,0,0,0,0,0,0,0,0,0,0,0,0,0,0,0,0,0,0,0,0,0,0,0,0,0,0
0,0,0,0,0,0,0,0,0,0,0,0,0,0,0,0,0,0,0,0,0,0,0,0,0,0,0,0,0
endlayer

layer
0,0,0,0,0,0,0,0,0,0,0,0,0,0,0,0,0,0,0,0,0,0,0,0,0,0,0,0,0
0,0,0,0,0,0,0,0,0,0,0,0,0,0,0,0,0,0,0,0,0,0,0,0,0,0,0,0,0
0,0,0,0,0,16,17,16,17,16,0,0,0,0,0,0,0,0,0,16,17,16,17,16,0,0,0,0,0
0,0,0,0,3,0,0,0,0,0,3,0,0,0,0,0,0,0,3,0,0,0,0,0,3,0,0,0,0
0,0,0,3,0,0,0,0,0,0,0,3,0,0,0,0,0,3,0,0,0,0,0,0,0,3,0,0,0
0,0,16,0,0,0,0,0,0,0,0,0,16,0,0,0,16,0,0,0,0,0,0,0,0,0,16,0,0
0,0,17,18,0,0,0,0,0,0,0,0,0,17,16,17,0,0,0,0,0,0,0,0,0,18,17,0,0
0,0,16,0,0,0,0,0,0,0,0,0,0,0,15,0,0,0,0,0,0,0,0,0,0,0,16,0,0
0,0,17,0,0,0,0,0,0,0,0,0,0,17,16,17,0,0,0,0,0,0,0,0,0,0,17,0,0
0,0,16,0,0,0,0,0,0,0,0,0,16,0,0,0,16,0,0,0,0,0,0,0,0,0,16,0,0
0,0,0,3,0,0,0,0,0,0,0,3,0,0,0,0,0,3,0,0,0,0,0,0,0,3,0,0,0
0,0,0,0,3,0,0,0,0,0,3,0,0,0,0,0,0,0,3,0,0,0,0,0,3,0,0,0,0
0,0,0,0,0,16,17,16,17,16,0,0,0,0,0,0,0,0,0,16,17,16,17,16,0,0,0,0,0
0,0,0,0,0,0,0,0,0,0,0,0,0,0,0,0,0,0,0,0,0,0,0,0,0,0,0,0,0
0,0,0,0,0,0,0,0,0,0,0,0,0,0,0,0,0,0,0,0,0,0,0,0,0,0,0,0,0
endlayer

layer
0,0,0,0,0,0,0,0,0,0,0,0,0,0,0,0,0,0,0,0,0,0,0,0,0,0,0,0,0
0,0,0,0,0,0,0,0,0,0,0,0,0,0,0,0,0,0,0,0,0,0,0,0,0,0,0,0,0
0,0,0,0,0,16,17,16,17,16,0,0,0,0,0,0,0,0,0,16,17,16,17,16,0,0,0,0,0
0,0,0,0,3,0,0,0,0,0,3,0,0,0,0,0,0,0,3,0,0,0,0,0,3,0,0,0,0
0,0,0,3,0,0,0,0,0,0,0,3,0,0,0,0,0,3,0,0,0,0,0,0,0,3,0,0,0
0,0,16,0,0,0,0,0,0,0,0,0,16,0,0,0,16,0,0,0,0,0,0,0,0,0,16,0,0
0,0,17,0,0,0,0,0,0,0,0,0,0,17,16,17,0,0,0,0,0,0,0,0,0,0,17,0,0
0,0,16,0,0,0,0,0,0,0,0,0,0,16,15,16,0,0,0,0,0,0,0,0,0,0,16,0,0
0,0,17,0,0,0,0,0,0,0,0,0,0,17,16,17,0,0,0,0,0,0,0,0,0,0,17,0,0
0,0,16,0,0,0,0,0,0,0,0,0,16,0,0,0,16,0,0,0,0,0,0,0,0,0,16,0,0
0,0,0,3,0,0,0,0,0,0,0,3,0,0,0,0,0,3,0,0,0,0,0,0,0,3,0,0,0
0,0,0,0,3,0,0,0,0,0,3,0,0,0,0,0,0,0,3,0,0,0,0,0,3,0,0,0,0
0,0,0,0,0,16,17,16,17,16,0,0,0,0,0,0,0,0,0,16,17,16,17,16,0,0,0,0,0
0,0,0,0,0,0,0,0,0,0,0,0,0,0,0,0,0,0,0,0,0,0,0,0,0,0,0,0,0
0,0,0,0,0,0,0,0,0,0,0,0,0,0,0,0,0,0,0,0,0,0,0,0,0,0,0,0,0
endlayer

layer
0,0,0,0,0,0,0,0,0,0,0,0,0,0,0,0,0,0,0,0,0,0,0,0,0,0,0,0,0
0,0,0,0,0,0,0,0,0,0,0,0,0,0,0,0,0,0,0,0,0,0,0,0,0,0,0,0,0
0,0,0,0,0,16,17,16,17,16,0,0,0,0,0,0,0,0,0,16,17,16,17,16,0,0,0,0,0
0,0,0,0,3,0,0,0,0,0,3,0,0,0,0,0,0,0,3,0,0,0,0,0,3,0,0,0,0
0,0,0,3,0,0,0,0,0,0,0,3,0,0,0,0,0,3,0,0,0,0,0,0,0,3,0,0,0
0,0,16,0,0,0,0,0,0,0,0,0,16,0,0,0,16,0,0,0,0,0,0,0,0,0,16,0,0
0,0,17,0,0,0,0,0,0,0,0,0,0,17,16,17,0,0,0,0,0,0,0,0,0,0,17,0,0
0,0,16,0,0,0,0,0,0,0,0,0,0,16,15,16,0,0,0,0,0,0,0,0,0,0,16,0,0
0,0,17,0,0,0,0,0,0,0,0,0,0,17,16,17,0,0,0,0,0,0,0,0,0,0,17,0,0
0,0,16,0,0,0,0,0,0,0,0,0,16,0,0,0,16,0,0,0,0,0,0,0,0,0,16,0,0
0,0,0,3,0,0,0,0,0,0,0,3,0,0,0,0,0,3,0,0,0,0,0,0,0,3,0,0,0
0,0,0,0,3,0,0,0,0,0,3,0,0,0,0,0,0,0,3,0,0,0,0,0,3,0,0,0,0
0,0,0,0,0,16,17,16,17,16,0,0,0,0,0,0,0,0,0,16,17,16,17,16,0,0,0,0,0
0,0,0,0,0,0,0,0,0,0,0,0,0,0,0,0,0,0,0,0,0,0,0,0,0,0,0,0,0
0,0,0,0,0,0,0,0,0,0,0,0,0,0,0,0,0,0,0,0,0,0,0,0,0,0,0,0,0
endlayer

layer
0,0,0,0,0,0,0,0,0,0,0,0,0,0,0,0,0,0,0,0,0,0,0,0,0,0,0,0,0
0,0,0,0,0,0,0,0,0,0,0,0,0,0,0,0,0,0,0,0,0,0,0,0,0,0,0,0,0
0,0,0,0,0,16,17,16,17,16,0,0,0,0,0,0,0,0,0,16,17,16,17,16,0,0,0,0,0
0,0,0,0,3,0,0,0,0,0,3,0,0,0,0,0,0,0,3,0,0,0,0,0,3,0,0,0,0
0,0,0,3,0,0,0,0,0,0,0,3,0,0,0,0,0,3,0,0,0,0,0,0,0,3,0,0,0
0,0,16,0,0,0,0,0,0,0,0,0,16,0,0,0,16,0,0,0,0,0,0,0,0,0,16,0,0
0,0,17,0,0,0,0,0,0,0,0,0,0,17,16,17,0,0,0,0,0,0,0,0,0,0,17,0,0
0,0,16,0,0,0,0,0,0,0,0,0,0,16,15,16,0,0,0,0,0,0,0,0,0,0,16,0,0
0,0,17,0,0,0,0,0,0,0,0,0,0,17,16,17,0,0,0,0,0,0,0,0,0,0,17,0,0
0,0,16,0,0,0,0,0,0,0,0,0,16,0,0,0,16,0,0,0,0,0,0,0,0,0,16,0,0
0,0,0,3,0,0,0,0,0,0,0,3,0,0,0,0,0,3,0,0,0,0,0,0,0,3,0,0,0
0,0,0,0,3,0,0,0,0,0,3,0,0,0,0,0,0,0,3,0,0,0,0,0,3,0,0,0,0
0,0,0,0,0,16,17,16,17,16,0,0,0,0,0,0,0,0,0,16,17,16,17,16,0,0,0,0,0
0,0,0,0,0,0,0,0,0,0,0,0,0,0,0,0,0,0,0,0,0,0,0,0,0,0,0,0,0
0,0,0,0,0,0,0,0,0,0,0,0,0,0,0,0,0,0,0,0,0,0,0,0,0,0,0,0,0
endlayer

layer
0,0,0,0,0,0,0,0,0,0,0,0,0,0,0,0,0,0,0,0,0,0,0,0,0,0,0,0,0
0,0,0,0,0,0,0,0,0,0,0,0,0,0,0,0,0,0,0,0,0,0,0,0,0,0,0,0,0
0,0,0,0,0,16,17,16,17,16,0,0,0,0,0,0,0,0,0,16,17,16,17,16,0,0,0,0,0
0,0,0,0,3,0,0,0,0,0,3,0,0,0,0,0,0,0,3,0,0,0,0,0,3,0,0,0,0
0,0,0,3,0,0,0,0,0,0,0,3,0,0,0,0,0,3,0,0,0,0,0,0,0,3,0,0,0
0,0,16,0,0,0,0,0,0,0,0,0,16,0,0,0,16,0,0,0,0,0,0,0,0,0,16,0,0
0,0,17,0,0,0,0,0,0,0,0,0,0,17,16,17,0,0,0,0,0,0,0,0,0,0,17,0,0
0,0,16,0,0,0,0,0,0,0,0,0,0,16,15,16,0,0,0,0,0,0,0,0,0,0,16,0,0
0,0,17,0,0,0,0,0,0,0,0,0,0,17,16,17,0,0,0,0,0,0,0,0,0,0,17,0,0
0,0,16,0,0,0,0,0,0,0,0,0,16,0,0,0,16,0,0,0,0,0,0,0,0,0,16,0,0
0,0,0,3,0,0,0,0,0,0,0,3,0,0,0,0,0,3,0,0,0,0,0,0,0,3,0,0,0
0,0,0,0,3,0,0,0,0,0,3,0,0,0,0,0,0,0,3,0,0,0,0,0,3,0,0,0,0
0,0,0,0,0,16,17,16,17,16,0,0,0,0,0,0,0,0,0,16,17,16,17,16,0,0,0,0,0
0,0,0,0,0,0,0,0,0,0,0,0,0,0,0,0,0,0,0,0,0,0,0,0,0,0,0,0,0
0,0,0,0,0,0,0,0,0,0,0,0,0,0,0,0,0,0,0,0,0,0,0,0,0,0,0,0,0
endlayer

layer
0,0,0,0,0,0,0,0,0,0,0,0,0,0,0,0,0,0,0,0,0,0,0,0,0,0,0,0,0
0,0,0,0,0,0,0,0,0,0,0,0,0,0,0,0,0,0,0,0,0,0,0,0,0,0,0,0,0
0,0,0,0,0,3,3,3,3,3,0,0,0,0,0,0,0,0,0,3,3,3,3,3,0,0,0,0,0
0,0,0,0,3,19,19,19,19,19,3,0,0,0,0,0,0,0,3,4,4,4,4,4,3,0,0,0,0
0,0,0,3,19,0,0,0,0,0,19,3,0,0,0,0,0,3,4,4,4,4,4,4,4,3,0,0,0
0,0,3,19,0,0,0,0,0,0,0,19,3,0,0,0,3,4,4,4,4,4,4,4,4,4,3,0,0
0,0,3,19,0,0,0,0,0,0,0,19,3,3,3,3,3,4,4,4,4,4,4,4,4,4,3,0,0
0,0,3,19,0,0,0,0,0,0,0,19,3,3,15,4,4,4,4,4,4,4,4,4,4,4,3,0,0
0,0,3,19,0,0,0,0,0,0,0,19,3,3,3,3,3,4,4,4,4,4,4,4,4,4,3,0,0
0,0,3,19,0,0,0,0,0,0,0,19,3,0,0,0,3,4,4,4,4,4,4,4,4,4,3,0,0
0,0,0,3,19,0,0,0,0,0,19,3,0,0,0,0,0,3,4,4,4,4,4,4,4,3,0,0,0
0,0,0,0,3,19,19,19,19,19,3,0,0,0,0,0,0,0,3,4,4,4,4,4,3,0,0,0,0
0,0,0,0,0,3,3,3,3,3,0,0,0,0,0,0,0,0,0,3,3,3,3,3,0,0,0,0,0
0,0,0,0,0,0,0,0,0,0,0,0,0,0,0,0,0,0,0,0,0,0,0,0,0,0,0,0,0
0,0,0,0,0,0,0,0,0,0,0,0,0,0,0,0,0,0,0,0,0,0,0,0,0,0,0,0,0
endlayer

layer
0,0,0,0,0,0,0,0,0,0,0,0,0,0,0,0,0,0,0,0,0,0,0,0,0,0,0,0,0
0,0,0,0,0,0,0,0,0,0,0,0,0,0,0,0,0,0,0,0,0,0,0,0,0,0,0,0,0
0,0,0,0,0,0,0,0,0,0,0,0,0,0,0,0,0,0,0,16,17,16,17,16,0,0,0,0,0
0,0,0,0,0,0,0,0,0,0,0,0,0,0,0,0,0,0,3,10,7,7,10,0,3,0,0,0,0
0,0,0,0,0,19,19,19,19,19,0,0,0,0,0,0,0,3,0,10,7,7,10,0,14,3,0,0,0
0,0,0,0,19,19,0,0,0,19,19,0,0,0,0,0,16,0,0,0,0,0,0,0,0,0,16,0,0
0,0,0,0,19,0,0,0,0,0,19,0,0,17,16,17,17,0,0,0,0,0,0,0,0,7,17,0,0
0,0,0,0,19,0,0,0,0,0,19,0,0,16,15,0,0,0,0,0,0,0,0,9,9,8,16,0,0
0,0,0,0,19,0,0,0,0,0,19,0,0,17,16,17,17,0,0,0,0,0,0,9,9,8,17,0,0
0,0,0,0,19,19,0,0,0,19,19,0,0,0,0,0,16,0,0,0,0,0,0,0,0,7,16,0,0
0,0,0,0,0,19,19,19,19,19,0,0,0,0,0,0,0,3,0,0,0,0,0,0,14,3,0,0,0
0,0,0,0,0,0,0,0,0,0,0,0,0,0,0,0,0,0,3,0,0,0,0,0,3,0,0,0,0
0,0,0,0,0,0,0,0,0,0,0,0,0,0,0,0,0,0,0,16,17,16,17,16,0,0,0,0,0
0,0,0,0,0,0,0,0,0,0,0,0,0,0,0,0,0,0,0,0,0,0,0,0,0,0,0,0,0
0,0,0,0,0,0,0,0,0,0,0,0,0,0,0,0,0,0,0,0,0,0,0,0,0,0,0,0,0
endlayer

layer
0,0,0,0,0,0,0,0,0,0,0,0,0,0,0,0,0,0,0,0,0,0,0,0,0,0,0,0,0
0,0,0,0,0,0,0,0,0,0,0,0,0,0,0,0,0,0,0,0,0,0,0,0,0,0,0,0,0
0,0,0,0,0,0,0,0,0,0,0,0,0,0,0,0,0,0,0,16,17,16,17,16,0,0,0,0,0
0,0,0,0,0,0,0,0,0,0,0,0,0,0,0,0,0,0,3,0,0,0,0,0,3,0,0,0,0
0,0,0,0,0,0,0,0,0,0,0,0,0,0,0,0,0,3,0,0,0,0,0,0,0,3,0,0,0
0,0,0,0,0,0,19,19,19,0,0,0,0,0,0,0,16,0,0,0,0,0,0,0,0,0,16,0,0
0,0,0,0,0,19,19,0,19,19,0,0,0,17,16,17,17,0,0,0,0,0,0,0,0,18,17,0,0
0,0,0,0,0,19,0,0,0,19,0,0,0,16,15,0,0,0,0,0,0,0,0,0,0,0,16,0,0
0,0,0,0,0,19,19,0,19,19,0,0,0,17,16,17,17,0,0,0,0,0,0,0,0,0,17,0,0
0,0,0,0,0,0,19,19,19,0,0,0,0,0,0,0,16,0,0,0,0,0,0,0,0,0,16,0,0
0,0,0,0,0,0,0,0,0,0,0,0,0,0,0,0,0,3,0,0,0,0,0,0,0,3,0,0,0
0,0,0,0,0,0,0,0,0,0,0,0,0,0,0,0,0,0,3,0,0,0,0,0,3,0,0,0,0
0,0,0,0,0,0,0,0,0,0,0,0,0,0,0,0,0,0,0,16,17,16,17,16,0,0,0,0,0
0,0,0,0,0,0,0,0,0,0,0,0,0,0,0,0,0,0,0,0,0,0,0,0,0,0,0,0,0
0,0,0,0,0,0,0,0,0,0,0,0,0,0,0,0,0,0,0,0,0,0,0,0,0,0,0,0,0
endlayer

layer
0,0,0,0,0,0,0,0,0,0,0,0,0,0,0,0,0,0,0,0,0,0,0,0,0,0,0,0,0
0,0,0,0,0,0,0,0,0,0,0,0,0,0,0,0,0,0,0,0,0,0,0,0,0,0,0,0,0
0,0,0,0,0,0,0,0,0,0,0,0,0,0,0,0,0,0,0,16,17,16,17,16,0,0,0,0,0
0,0,0,0,0,0,0,0,0,0,0,0,0,0,0,0,0,0,3,0,0,0,0,0,3,0,0,0,0
0,0,0,0,0,0,0,0,0,0,0,0,0,0,0,0,0,3,0,0,0,0,0,0,0,3,0,0,0
0,0,0,0,0,0,0,0,0,0,0,0,0,0,0,0,16,0,0,0,0,0,0,0,0,0,16,0,0
0,0,0,0,0,0,0,19,0,0,0,0,0,17,16,17,17,0,0,0,0,0,0,0,0,0,17,0,0
0,0,0,0,0,0,19,0,19,0,0,0,0,16,15,16,0,0,0,0,0,0,0,0,0,0,16,0,0
0,0,0,0,0,0,0,19,0,0,0,0,0,17,16,17,17,0,0,0,0,0,0,0,0,0,17,0,0
0,0,0,0,0,0,0,0,0,0,0,0,0,0,0,0,16,0,0,0,0,0,0,0,0,0,16,0,0
0,0,0,0,0,0,0,0,0,0,0,0,0,0,0,0,0,3,0,0,0,0,0,0,0,3,0,0,0
0,0,0,0,0,0,0,0,0,0,0,0,0,0,0,0,0,0,3,0,0,0,0,0,3,0,0,0,0
0,0,0,0,0,0,0,0,0,0,0,0,0,0,0,0,0,0,0,16,17,16,17,16,0,0,0,0,0
0,0,0,0,0,0,0,0,0,0,0,0,0,0,0,0,0,0,0,0,0,0,0,0,0,0,0,0,0
0,0,0,0,0,0,0,0,0,0,0,0,0,0,0,0,0,0,0,0,0,0,0,0,0,0,0,0,0
endlayer

layer
0,0,0,0,0,0,0,0,0,0,0,0,0,0,0,0,0,0,0,0,0,0,0,0,0,0,0,0,0
0,0,0,0,0,0,0,0,0,0,0,0,0,0,0,0,0,0,0,0,0,0,0,0,0,0,0,0,0
0,0,0,0,0,0,0,0,0,0,0,0,0,0,0,0,0,0,0,16,17,16,17,16,0,0,0,0,0
0,0,0,0,0,0,0,0,0,0,0,0,0,0,0,0,0,0,3,0,0,0,0,0,3,0,0,0,0
0,0,0,0,0,0,0,0,0,0,0,0,0,0,0,0,0,3,0,0,0,0,0,0,0,3,0,0,0
0,0,0,0,0,0,0,0,0,0,0,0,0,0,0,0,16,0,0,0,0,0,0,0,0,0,16,0,0
0,0,0,0,0,0,0,0,0,0,0,0,0,17,16,17,17,0,0,0,0,0,0,0,0,0,17,0,0
0,0,0,0,0,0,0,19,0,0,0,0,0,16,15,16,0,0,0,0,0,0,0,0,0,0,16,0,0
0,0,0,0,0,0,0,0,0,0,0,0,0,17,16,17,17,0,0,0,0,0,0,0,0,0,17,0,0
0,0,0,0,0,0,0,0,0,0,0,0,0,0,0,0,16,0,0,0,0,0,0,0,0,0,16,0,0
0,0,0,0,0,0,0,0,0,0,0,0,0,0,0,0,0,3,0,0,0,0,0,0,0,3,0,0,0
0,0,0,0,0,0,0,0,0,0,0,0,0,0,0,0,0,0,3,0,0,0,0,0,3,0,0,0,0
0,0,0,0,0,0,0,0,0,0,0,0,0,0,0,0,0,0,0,16,17,16,17,16,0,0,0,0,0
0,0,0,0,0,0,0,0,0,0,0,0,0,0,0,0,0,0,0,0,0,0,0,0,0,0,0,0,0
0,0,0,0,0,0,0,0,0,0,0,0,0,0,0,0,0,0,0,0,0,0,0,0,0,0,0,0,0
endlayer

layer
0,0,0,0,0,0,0,0,0,0,0,0,0,0,0,0,0,0,0,0,0,0,0,0,0,0,0,0,0
0,0,0,0,0,0,0,0,0,0,0,0,0,0,0,0,0,0,0,0,0,0,0,0,0,0,0,0,0
0,0,0,0,0,0,0,0,0,0,0,0,0,0,0,0,0,0,0,16,17,16,17,16,0,0,0,0,0
0,0,0,0,0,0,0,0,0,0,0,0,0,0,0,0,0,0,3,0,0,0,0,0,3,0,0,0,0
0,0,0,0,0,0,0,0,0,0,0,0,0,0,0,0,0,3,0,0,0,0,0,0,0,3,0,0,0
0,0,0,0,0,0,0,0,0,0,0,0,0,0,0,0,16,0,0,0,0,0,0,0,0,0,16,0,0
0,0,0,0,0,0,0,0,0,0,0,0,0,17,16,17,17,0,0,0,0,0,0,0,0,0,17,0,0
0,0,0,0,0,0,0,19,0,0,0,0,0,16,15,16,0,0,0,0,0,0,0,0,0,0,16,0,0
0,0,0,0,0,0,0,0,0,0,0,0,0,17,16,17,17,0,0,0,0,0,0,0,0,0,17,0,0
0,0,0,0,0,0,0,0,0,0,0,0,0,0,0,0,16,0,0,0,0,0,0,0,0,0,16,0,0
0,0,0,0,0,0,0,0,0,0,0,0,0,0,0,0,0,3,0,0,0,0,0,0,0,3,0,0,0
0,0,0,0,0,0,0,0,0,0,0,0,0,0,0,0,0,0,3,0,0,0,0,0,3,0,0,0,0
0,0,0,0,0,0,0,0,0,0,0,0,0,0,0,0,0,0,0,16,17,16,17,16,0,0,0,0,0
0,0,0,0,0,0,0,0,0,0,0,0,0,0,0,0,0,0,0,0,0,0,0,0,0,0,0,0,0
0,0,0,0,0,0,0,0,0,0,0,0,0,0,0,0,0,0,0,0,0,0,0,0,0,0,0,0,0
endlayer

layer
0,0,0,0,0,0,0,0,0,0,0,0,0,0,0,0,0,0,0,0,0,0,0,0,0,0,0,0,0
0,0,0,0,0,0,0,0,0,0,0,0,0,0,0,0,0,0,0,0,0,0,0,0,0,0,0,0,0
0,0,0,0,0,0,0,0,0,0,0,0,0,0,0,0,0,0,0,16,17,16,17,16,0,0,0,0,0
0,0,0,0,0,0,0,0,0,0,0,0,0,0,0,0,0,0,3,0,0,0,0,0,3,0,0,0,0
0,0,0,0,0,0,0,0,0,0,0,0,0,0,0,0,0,3,0,0,0,0,0,0,0,3,0,0,0
0,0,0,0,0,0,0,0,0,0,0,0,0,0,0,0,16,0,0,0,0,0,0,0,0,0,16,0,0
0,0,0,0,0,0,0,0,0,0,0,0,0,17,16,17,17,0,0,0,0,0,0,0,0,0,17,0,0
0,0,0,0,0,0,0,19,0,0,0,0,0,16,15,16,0,0,0,0,0,0,0,0,0,0,16,0,0
0,0,0,0,0,0,0,0,0,0,0,0,0,17,16,17,17,0,0,0,0,0,0,0,0,0,17,0,0
0,0,0,0,0,0,0,0,0,0,0,0,0,0,0,0,16,0,0,0,0,0,0,0,0,0,16,0,0
0,0,0,0,0,0,0,0,0,0,0,0,0,0,0,0,0,3,0,0,0,0,0,0,0,3,0,0,0
0,0,0,0,0,0,0,0,0,0,0,0,0,0,0,0,0,0,3,0,0,0,0,0,3,0,0,0,0
0,0,0,0,0,0,0,0,0,0,0,0,0,0,0,0,0,0,0,16,17,16,17,16,0,0,0,0,0
0,0,0,0,0,0,0,0,0,0,0,0,0,0,0,0,0,0,0,0,0,0,0,0,0,0,0,0,0
0,0,0,0,0,0,0,0,0,0,0,0,0,0,0,0,0,0,0,0,0,0,0,0,0,0,0,0,0
endlayer

layer
0,0,0,0,0,0,0,0,0,0,0,0,0,0,0,0,0,0,0,0,0,0,0,0,0,0,0,0,0
0,0,0,0,0,0,0,0,0,0,0,0,0,0,0,0,0,0,0,0,0,0,0,0,0,0,0,0,0
0,0,0,0,0,0,0,0,0,0,0,0,0,0,0,0,0,0,0,3,3,3,3,3,0,0,0,0,0
0,0,0,0,0,0,0,0,0,0,0,0,0,0,0,0,0,0,3,4,4,4,4,4,3,0,0,0,0
0,0,0,0,0,0,0,0,0,0,0,0,0,0,0,0,0,3,4,4,4,4,4,4,4,3,0,0,0
0,0,0,0,0,0,0,0,0,0,0,0,0,0,0,0,3,4,4,4,4,4,4,4,4,4,3,0,0
0,0,0,0,0,0,0,0,0,0,0,0,0,3,3,3,3,4,4,4,4,4,4,4,4,4,3,0,0
0,0,0,0,0,0,0,0,0,0,0,0,0,3,15,4,4,4,4,4,4,4,4,4,4,4,3,0,0
0,0,0,0,0,0,0,0,0,0,0,0,0,3,3,3,3,4,4,4,4,4,4,4,4,4,3,0,0
0,0,0,0,0,0,0,0,0,0,0,0,0,0,0,0,3,4,4,4,4,4,4,4,4,4,3,0,0
0,0,0,0,0,0,0,0,0,0,0,0,0,0,0,0,0,3,4,4,4,4,4,4,4,3,0,0,0
0,0,0,0,0,0,0,0,0,0,0,0,0,0,0,0,0,0,3,4,4,4,4,4,3,0,0,0,0
0,0,0,0,0,0,0,0,0,0,0,0,0,0,0,0,0,0,0,3,3,3,3,3,0,0,0,0,0
0,0,0,0,0,0,0,0,0,0,0,0,0,0,0,0,0,0,0,0,0,0,0,0,0,0,0,0,0
0,0,0,0,0,0,0,0,0,0,0,0,0,0,0,0,0,0,0,0,0,0,0,0,0,0,0,0,0
endlayer

layer
0,0,0,0,0,0,0,0,0,0,0,0,0,0,0,0,0,0,0,0,0,0,0,0,0,0,0,0,0
0,0,0,0,0,0,0,0,0,0,0,0,0,0,0,0,0,0,0,0,0,0,0,0,0,0,0,0,0
0,0,0,0,0,0,0,0,0,0,0,0,0,0,0,0,0,0,0,16,17,16,17,16,0,0,0,0,0
0,0,0,0,0,0,0,0,0,0,0,0,0,0,0,0,0,0,3,10,7,7,10,0,3,0,0,0,0
0,0,0,0,0,0,0,0,0,0,0,0,0,0,0,0,0,3,0,10,7,7,10,0,14,3,0,0,0
0,0,0,0,0,0,0,0,0,0,0,0,0,0,0,0,16,0,0,0,0,0,0,0,0,0,16,0,0
0,0,0,0,0,0,0,0,0,0,0,0,0,17,16,17,17,0,0,0,0,0,0,0,0,7,17,0,0
0,0,0,0,0,0,0,0,0,0,0,0,0,16,15,0,0,0,0,0,0,0,0,9,9,8,16,0,0
0,0,0,0,0,0,0,0,0,0,0,0,0,17,16,17,17,0,0,0,0,0,0,9,9,8,17,0,0
0,0,0,0,0,0,0,0,0,0,0,0,0,0,0,0,16,0,0,0,0,0,0,0,0,7,16,0,0
0,0,0,0,0,0,0,0,0,0,0,0,0,0,0,0,0,3,0,0,0,0,0,0,14,3,0,0,0
0,0,0,0,0,0,0,0,0,0,0,0,0,0,0,0,0,0,3,0,0,0,0,0,3,0,0,0,0
0,0,0,0,0,0,0,0,0,0,0,0,0,0,0,0,0,0,0,16,17,16,17,16,0,0,0,0,0
0,0,0,0,0,0,0,0,0,0,0,0,0,0,0,0,0,0,0,0,0,0,0,0,0,0,0,0,0
0,0,0,0,0,0,0,0,0,0,0,0,0,0,0,0,0,0,0,0,0,0,0,0,0,0,0,0,0
endlayer

layer
0,0,0,0,0,0,0,0,0,0,0,0,0,0,0,0,0,0,0,0,0,0,0,0,0,0,0,0,0
0,0,0,0,0,0,0,0,0,0,0,0,0,0,0,0,0,0,0,0,0,0,0,0,0,0,0,0,0
0,0,0,0,0,0,0,0,0,0,0,0,0,0,0,0,0,0,0,16,17,16,17,16,0,0,0,0,0
0,0,0,0,0,0,0,0,0,0,0,0,0,0,0,0,0,0,3,0,0,0,0,0,3,0,0,0,0
0,0,0,0,0,0,0,0,0,0,0,0,0,0,0,0,0,3,0,0,0,0,0,0,0,3,0,0,0
0,0,0,0,0,0,0,0,0,0,0,0,0,0,0,0,16,0,0,0,0,0,0,0,0,0,16,0,0
0,0,0,0,0,0,0,0,0,0,0,0,0,17,16,17,17,0,0,0,0,0,0,0,0,18,17,0,0
0,0,0,0,0,0,0,0,0,0,0,0,0,16,15,0,0,0,0,0,0,0,0,0,0,0,16,0,0
0,0,0,0,0,0,0,0,0,0,0,0,0,17,16,17,17,0,0,0,0,0,0,0,0,0,17,0,0
0,0,0,0,0,0,0,0,0,0,0,0,0,0,0,0,16,0,0,0,0,0,0,0,0,0,16,0,0
0,0,0,0,0,0,0,0,0,0,0,0,0,0,0,0,0,3,0,0,0,0,0,0,0,3,0,0,0
0,0,0,0,0,0,0,0,0,0,0,0,0,0,0,0,0,0,3,0,0,0,0,0,3,0,0,0,0
0,0,0,0,0,0,0,0,0,0,0,0,0,0,0,0,0,0,0,16,17,16,17,16,0,0,0,0,0
0,0,0,0,0,0,0,0,0,0,0,0,0,0,0,0,0,0,0,0,0,0,0,0,0,0,0,0,0
0,0,0,0,0,0,0,0,0,0,0,0,0,0,0,0,0,0,0,0,0,0,0,0,0,0,0,0,0
endlayer

layer
0,0,0,0,0,0,0,0,0,0,0,0,0,0,0,0,0,0,0,0,0,0,0,0,0,0,0,0,0
0,0,0,0,0,0,0,0,0,0,0,0,0,0,0,0,0,0,0,0,0,0,0,0,0,0,0,0,0
0,0,0,0,0,0,0,0,0,0,0,0,0,0,0,0,0,0,0,16,17,16,17,16,0,0,0,0,0
0,0,0,0,0,0,0,0,0,0,0,0,0,0,0,0,0,0,3,0,0,0,0,0,3,0,0,0,0
0,0,0,0,0,0,0,0,0,0,0,0,0,0,0,0,0,3,0,0,0,0,0,0,0,3,0,0,0
0,0,0,0,0,0,0,0,0,0,0,0,0,0,0,0,16,0,0,0,0,0,0,0,0,0,16,0,0
0,0,0,0,0,0,0,0,0,0,0,0,0,17,16,17,17,0,0,0,0,0,0,0,0,0,17,0,0
0,0,0,0,0,0,0,0,0,0,0,0,0,16,0,16,0,0,0,0,0,0,0,0,0,0,16,0,0
0,0,0,0,0,0,0,0,0,0,0,0,0,17,16,17,17,0,0,0,0,0,0,0,0,0,17,0,0
0,0,0,0,0,0,0,0,0,0,0,0,0,0,0,0,16,0,0,0,0,0,0,0,0,0,16,0,0
0,0,0,0,0,0,0,0,0,0,0,0,0,0,0,0,0,3,0,0,0,0,0,0,0,3,0,0,0
0,0,0,0,0,0,0,0,0,0,0,0,0,0,0,0,0,0,3,0,0,0,0,0,3,0,0,0,0
0,0,0,0,0,0,0,0,0,0,0,0,0,0,0,0,0,0,0,16,17,16,17,16,0,0,0,0,0
0,0,0,0,0,0,0,0,0,0,0,0,0,0,0,0,0,0,0,0,0,0,0,0,0,0,0,0,0
0,0,0,0,0,0,0,0,0,0,0,0,0,0,0,0,0,0,0,0,0,0,0,0,0,0,0,0,0
endlayer

layer
0,0,0,0,0,0,0,0,0,0,0,0,0,0,0,0,0,0,0,0,0,0,0,0,0,0,0,0,0
0,0,0,0,0,0,0,0,0,0,0,0,0,0,0,0,0,0,0,0,0,0,0,0,0,0,0,0,0
0,0,0,0,0,0,0,0,0,0,0,0,0,0,0,0,0,0,0,16,17,16,17,16,0,0,0,0,0
0,0,0,0,0,0,0,0,0,0,0,0,0,0,0,0,0,0,3,0,0,0,0,0,3,0,0,0,0
0,0,0,0,0,0,0,0,0,0,0,0,0,0,0,0,0,3,0,0,0,0,0,0,0,3,0,0,0
0,0,0,0,0,0,0,0,0,0,0,0,0,0,0,0,16,0,0,0,0,0,0,0,0,0,16,0,0
0,0,0,0,0,0,0,0,0,0,0,0,0,17,16,17,17,0,0,0,0,0,0,0,0,0,17,0,0
0,0,0,0,0,0,0,0,0,0,0,0,0,16,0,16,0,0,0,0,0,0,0,0,0,0,16,0,0
0,0,0,0,0,0,0,0,0,0,0,0,0,17,16,17,17,0,0,0,0,0,0,0,0,0,17,0,0
0,0,0,0,0,0,0,0,0,0,0,0,0,0,0,0,16,0,0,0,0,0,0,0,0,0,16,0,0
0,0,0,0,0,0,0,0,0,0,0,0,0,0,0,0,0,3,0,0,0,0,0,0,0,3,0,0,0
0,0,0,0,0,0,0,0,0,0,0,0,0,0,0,0,0,0,3,0,0,0,0,0,3,0,0,0,0
0,0,0,0,0,0,0,0,0,0,0,0,0,0,0,0,0,0,0,16,17,16,17,16,0,0,0,0,0
0,0,0,0,0,0,0,0,0,0,0,0,0,0,0,0,0,0,0,0,0,0,0,0,0,0,0,0,0
0,0,0,0,0,0,0,0,0,0,0,0,0,0,0,0,0,0,0,0,0,0,0,0,0,0,0,0,0
endlayer

layer
0,0,0,0,0,0,0,0,0,0,0,0,0,0,0,0,0,0,0,0,0,0,0,0,0,0,0,0,0
0,0,0,0,0,0,0,0,0,0,0,0,0,0,0,0,0,0,0,0,0,0,0,0,0,0,0,0,0
0,0,0,0,0,0,0,0,0,0,0,0,0,0,0,0,0,0,0,16,17,16,17,16,0,0,0,0,0
0,0,0,0,0,0,0,0,0,0,0,0,0,0,0,0,0,0,3,0,0,0,0,0,3,0,0,0,0
0,0,0,0,0,0,0,0,0,0,0,0,0,0,0,0,0,3,0,0,0,0,0,0,0,3,0,0,0
0,0,0,0,0,0,0,0,0,0,0,0,0,0,0,0,16,0,0,0,0,0,0,0,0,0,16,0,0
0,0,0,0,0,0,0,0,0,0,0,0,0,17,16,17,17,0,0,0,0,0,0,0,0,0,17,0,0
0,0,0,0,0,0,0,0,0,0,0,0,0,16,0,16,0,0,0,0,0,0,0,0,0,0,16,0,0
0,0,0,0,0,0,0,0,0,0,0,0,0,17,16,17,17,0,0,0,0,0,0,0,0,0,17,0,0
0,0,0,0,0,0,0,0,0,0,0,0,0,0,0,0,16,0,0,0,0,0,0,0,0,0,16,0,0
0,0,0,0,0,0,0,0,0,0,0,0,0,0,0,0,0,3,0,0,0,0,0,0,0,3,0,0,0
0,0,0,0,0,0,0,0,0,0,0,0,0,0,0,0,0,0,3,0,0,0,0,0,3,0,0,0,0
0,0,0,0,0,0,0,0,0,0,0,0,0,0,0,0,0,0,0,16,17,16,17,16,0,0,0,0,0
0,0,0,0,0,0,0,0,0,0,0,0,0,0,0,0,0,0,0,0,0,0,0,0,0,0,0,0,0
0,0,0,0,0,0,0,0,0,0,0,0,0,0,0,0,0,0,0,0,0,0,0,0,0,0,0,0,0
endlayer

layer
0,0,0,0,0,0,0,0,0,0,0,0,0,0,0,0,0,0,0,0,0,0,0,0,0,0,0,0,0
0,0,0,0,0,0,0,0,0,0,0,0,0,0,0,0,0,0,0,0,0,0,0,0,0,0,0,0,0
0,0,0,0,0,0,0,0,0,0,0,0,0,0,0,0,0,0,0,16,17,16,17,16,0,0,0,0,0
0,0,0,0,0,0,0,0,0,0,0,0,0,0,0,0,0,0,3,0,0,0,0,0,3,0,0,0,0
0,0,0,0,0,0,0,0,0,0,0,0,0,0,0,0,0,3,0,0,0,0,0,0,0,3,0,0,0
0,0,0,0,0,0,0,0,0,0,0,0,0,0,0,0,16,0,0,0,0,0,0,0,0,0,16,0,0
0,0,0,0,0,0,0,0,0,0,0,0,0,17,16,17,17,0,0,0,0,0,0,0,0,0,17,0,0
0,0,0,0,0,0,0,0,0,0,0,0,0,16,0,16,0,0,0,0,0,0,0,0,0,0,16,0,0
0,0,0,0,0,0,0,0,0,0,0,0,0,17,16,17,17,0,0,0,0,0,0,0,0,0,17,0,0
0,0,0,0,0,0,0,0,0,0,0,0,0,0,0,0,16,0,0,0,0,0,0,0,0,0,16,0,0
0,0,0,0,0,0,0,0,0,0,0,0,0,0,0,0,0,3,0,0,0,0,0,0,0,3,0,0,0
0,0,0,0,0,0,0,0,0,0,0,0,0,0,0,0,0,0,3,0,0,0,0,0,3,0,0,0,0
0,0,0,0,0,0,0,0,0,0,0,0,0,0,0,0,0,0,0,16,17,16,17,16,0,0,0,0,0
0,0,0,0,0,0,0,0,0,0,0,0,0,0,0,0,0,0,0,0,0,0,0,0,0,0,0,0,0
0,0,0,0,0,0,0,0,0,0,0,0,0,0,0,0,0,0,0,0,0,0,0,0,0,0,0,0,0
endlayer

layer
0,0,0,0,0,0,0,0,0,0,0,0,0,0,0,0,0,0,0,0,0,0,0,0,0,0,0,0,0
0,0,0,0,0,0,0,0,0,0,0,0,0,0,0,0,0,0,0,0,0,0,0,0,0,0,0,0,0
0,0,0,0,0,0,0,0,0,0,0,0,0,0,0,0,0,0,0,3,3,3,3,3,0,0,0,0,0
0,0,0,0,0,0,0,0,0,0,0,0,0,0,0,0,0,0,3,19,19,19,19,19,3,0,0,0,0
0,0,0,0,0,0,0,0,0,0,0,0,0,0,0,0,0,3,19,0,0,0,0,0,19,3,0,0,0
0,0,0,0,0,0,0,0,0,0,0,0,0,0,0,0,3,19,0,0,0,0,0,0,0,19,3,0,0
0,0,0,0,0,0,0,0,0,0,0,0,0,3,3,3,3,19,0,0,0,0,0,0,0,19,3,0,0
0,0,0,0,0,0,0,0,0,0,0,0,0,3,19,19,19,19,0,0,0,0,0,0,0,19,3,0,0
0,0,0,0,0,0,0,0,0,0,0,0,0,3,3,3,3,19,0,0,0,0,0,0,0,19,3,0,0
0,0,0,0,0,0,0,0,0,0,0,0,0,0,0,0,3,19,0,0,0,0,0,0,0,19,3,0,0
0,0,0,0,0,0,0,0,0,0,0,0,0,0,0,0,0,3,19,0,0,0,0,0,19,3,0,0,0
0,0,0,0,0,0,0,0,0,0,0,0,0,0,0,0,0,0,3,19,19,19,19,19,3,0,0,0,0
0,0,0,0,0,0,0,0,0,0,0,0,0,0,0,0,0,0,0,3,3,3,3,3,0,0,0,0,0
0,0,0,0,0,0,0,0,0,0,0,0,0,0,0,0,0,0,0,0,0,0,0,0,0,0,0,0,0
0,0,0,0,0,0,0,0,0,0,0,0,0,0,0,0,0,0,0,0,0,0,0,0,0,0,0,0,0
endlayer

layer
0,0,0,0,0,0,0,0,0,0,0,0,0,0,0,0,0,0,0,0,0,0,0,0,0,0,0,0,0
0,0,0,0,0,0,0,0,0,0,0,0,0,0,0,0,0,0,0,0,0,0,0,0,0,0,0,0,0
0,0,0,0,0,0,0,0,0,0,0,0,0,0,0,0,0,0,0,0,0,0,0,0,0,0,0,0,0
0,0,0,0,0,0,0,0,0,0,0,0,0,0,0,0,0,0,0,0,0,0,0,0,0,0,0,0,0
0,0,0,0,0,0,0,0,0,0,0,0,0,0,0,0,0,0,0,19,19,19,19,19,0,0,0,0,0
0,0,0,0,0,0,0,0,0,0,0,0,0,0,0,0,0,0,19,19,0,0,0,19,19,0,0,0,0
0,0,0,0,0,0,0,0,0,0,0,0,0,0,0,0,0,0,19,0,0,0,0,0,19,0,0,0,0
0,0,0,0,0,0,0,0,0,0,0,0,0,0,0,0,0,0,19,0,0,0,0,0,19,0,0,0,0
0,0,0,0,0,0,0,0,0,0,0,0,0,0,0,0,0,0,19,0,0,0,0,0,19,0,0,0,0
0,0,0,0,0,0,0,0,0,0,0,0,0,0,0,0,0,0,19,19,0,0,0,19,19,0,0,0,0
0,0,0,0,0,0,0,0,0,0,0,0,0,0,0,0,0,0,0,19,19,19,19,19,0,0,0,0,0
0,0,0,0,0,0,0,0,0,0,0,0,0,0,0,0,0,0,0,0,0,0,0,0,0,0,0,0,0
0,0,0,0,0,0,0,0,0,0,0,0,0,0,0,0,0,0,0,0,0,0,0,0,0,0,0,0,0
0,0,0,0,0,0,0,0,0,0,0,0,0,0,0,0,0,0,0,0,0,0,0,0,0,0,0,0,0
0,0,0,0,0,0,0,0,0,0,0,0,0,0,0,0,0,0,0,0,0,0,0,0,0,0,0,0,0
endlayer

layer
0,0,0,0,0,0,0,0,0,0,0,0,0,0,0,0,0,0,0,0,0,0,0,0,0,0,0,0,0
0,0,0,0,0,0,0,0,0,0,0,0,0,0,0,0,0,0,0,0,0,0,0,0,0,0,0,0,0
0,0,0,0,0,0,0,0,0,0,0,0,0,0,0,0,0,0,0,0,0,0,0,0,0,0,0,0,0
0,0,0,0,0,0,0,0,0,0,0,0,0,0,0,0,0,0,0,0,0,0,0,0,0,0,0,0,0
0,0,0,0,0,0,0,0,0,0,0,0,0,0,0,0,0,0,0,0,0,0,0,0,0,0,0,0,0
0,0,0,0,0,0,0,0,0,0,0,0,0,0,0,0,0,0,0,0,19,19,19,0,0,0,0,0,0
0,0,0,0,0,0,0,0,0,0,0,0,0,0,0,0,0,0,0,19,19,0,19,19,0,0,0,0,0
0,0,0,0,0,0,0,0,0,0,0,0,0,0,0,0,0,0,0,19,0,0,0,19,0,0,0,0,0
0,0,0,0,0,0,0,0,0,0,0,0,0,0,0,0,0,0,0,19,19,0,19,19,0,0,0,0,0
0,0,0,0,0,0,0,0,0,0,0,0,0,0,0,0,0,0,0,0,19,19,19,0,0,0,0,0,0
0,0,0,0,0,0,0,0,0,0,0,0,0,0,0,0,0,0,0,0,0,0,0,0,0,0,0,0,0
0,0,0,0,0,0,0,0,0,0,0,0,0,0,0,0,0,0,0,0,0,0,0,0,0,0,0,0,0
0,0,0,0,0,0,0,0,0,0,0,0,0,0,0,0,0,0,0,0,0,0,0,0,0,0,0,0,0
0,0,0,0,0,0,0,0,0,0,0,0,0,0,0,0,0,0,0,0,0,0,0,0,0,0,0,0,0
0,0,0,0,0,0,0,0,0,0,0,0,0,0,0,0,0,0,0,0,0,0,0,0,0,0,0,0,0
endlayer

layer
0,0,0,0,0,0,0,0,0,0,0,0,0,0,0,0,0,0,0,0,0,0,0,0,0,0,0,0,0
0,0,0,0,0,0,0,0,0,0,0,0,0,0,0,0,0,0,0,0,0,0,0,0,0,0,0,0,0
0,0,0,0,0,0,0,0,0,0,0,0,0,0,0,0,0,0,0,0,0,0,0,0,0,0,0,0,0
0,0,0,0,0,0,0,0,0,0,0,0,0,0,0,0,0,0,0,0,0,0,0,0,0,0,0,0,0
0,0,0,0,0,0,0,0,0,0,0,0,0,0,0,0,0,0,0,0,0,0,0,0,0,0,0,0,0
0,0,0,0,0,0,0,0,0,0,0,0,0,0,0,0,0,0,0,0,0,0,0,0,0,0,0,0,0
0,0,0,0,0,0,0,0,0,0,0,0,0,0,0,0,0,0,0,0,0,19,0,0,0,0,0,0,0
0,0,0,0,0,0,0,0,0,0,0,0,0,0,0,0,0,0,0,0,19,0,19,0,0,0,0,0,0
0,0,0,0,0,0,0,0,0,0,0,0,0,0,0,0,0,0,0,0,0,19,0,0,0,0,0,0,0
0,0,0,0,0,0,0,0,0,0,0,0,0,0,0,0,0,0,0,0,0,0,0,0,0,0,0,0,0
0,0,0,0,0,0,0,0,0,0,0,0,0,0,0,0,0,0,0,0,0,0,0,0,0,0,0,0,0
0,0,0,0,0,0,0,0,0,0,0,0,0,0,0,0,0,0,0,0,0,0,0,0,0,0,0,0,0
0,0,0,0,0,0,0,0,0,0,0,0,0,0,0,0,0,0,0,0,0,0,0,0,0,0,0,0,0
0,0,0,0,0,0,0,0,0,0,0,0,0,0,0,0,0,0,0,0,0,0,0,0,0,0,0,0,0
0,0,0,0,0,0,0,0,0,0,0,0,0,0,0,0,0,0,0,0,0,0,0,0,0,0,0,0,0
endlayer

layer
0,0,0,0,0,0,0,0,0,0,0,0,0,0,0,0,0,0,0,0,0,0,0,0,0,0,0,0,0
0,0,0,0,0,0,0,0,0,0,0,0,0,0,0,0,0,0,0,0,0,0,0,0,0,0,0,0,0
0,0,0,0,0,0,0,0,0,0,0,0,0,0,0,0,0,0,0,0,0,0,0,0,0,0,0,0,0
0,0,0,0,0,0,0,0,0,0,0,0,0,0,0,0,0,0,0,0,0,0,0,0,0,0,0,0,0
0,0,0,0,0,0,0,0,0,0,0,0,0,0,0,0,0,0,0,0,0,0,0,0,0,0,0,0,0
0,0,0,0,0,0,0,0,0,0,0,0,0,0,0,0,0,0,0,0,0,0,0,0,0,0,0,0,0
0,0,0,0,0,0,0,0,0,0,0,0,0,0,0,0,0,0,0,0,0,0,0,0,0,0,0,0,0
0,0,0,0,0,0,0,0,0,0,0,0,0,0,0,0,0,0,0,0,0,19,0,0,0,0,0,0,0
0,0,0,0,0,0,0,0,0,0,0,0,0,0,0,0,0,0,0,0,0,0,0,0,0,0,0,0,0
0,0,0,0,0,0,0,0,0,0,0,0,0,0,0,0,0,0,0,0,0,0,0,0,0,0,0,0,0
0,0,0,0,0,0,0,0,0,0,0,0,0,0,0,0,0,0,0,0,0,0,0,0,0,0,0,0,0
0,0,0,0,0,0,0,0,0,0,0,0,0,0,0,0,0,0,0,0,0,0,0,0,0,0,0,0,0
0,0,0,0,0,0,0,0,0,0,0,0,0,0,0,0,0,0,0,0,0,0,0,0,0,0,0,0,0
0,0,0,0,0,0,0,0,0,0,0,0,0,0,0,0,0,0,0,0,0,0,0,0,0,0,0,0,0
0,0,0,0,0,0,0,0,0,0,0,0,0,0,0,0,0,0,0,0,0,0,0,0,0,0,0,0,0
endlayer

layer
0,0,0,0,0,0,0,0,0,0,0,0,0,0,0,0,0,0,0,0,0,0,0,0,0,0,0,0,0
0,0,0,0,0,0,0,0,0,0,0,0,0,0,0,0,0,0,0,0,0,0,0,0,0,0,0,0,0
0,0,0,0,0,0,0,0,0,0,0,0,0,0,0,0,0,0,0,0,0,0,0,0,0,0,0,0,0
0,0,0,0,0,0,0,0,0,0,0,0,0,0,0,0,0,0,0,0,0,0,0,0,0,0,0,0,0
0,0,0,0,0,0,0,0,0,0,0,0,0,0,0,0,0,0,0,0,0,0,0,0,0,0,0,0,0
0,0,0,0,0,0,0,0,0,0,0,0,0,0,0,0,0,0,0,0,0,0,0,0,0,0,0,0,0
0,0,0,0,0,0,0,0,0,0,0,0,0,0,0,0,0,0,0,0,0,0,0,0,0,0,0,0,0
0,0,0,0,0,0,0,0,0,0,0,0,0,0,0,0,0,0,0,0,0,19,0,0,0,0,0,0,0
0,0,0,0,0,0,0,0,0,0,0,0,0,0,0,0,0,0,0,0,0,0,0,0,0,0,0,0,0
0,0,0,0,0,0,0,0,0,0,0,0,0,0,0,0,0,0,0,0,0,0,0,0,0,0,0,0,0
0,0,0,0,0,0,0,0,0,0,0,0,0,0,0,0,0,0,0,0,0,0,0,0,0,0,0,0,0
0,0,0,0,0,0,0,0,0,0,0,0,0,0,0,0,0,0,0,0,0,0,0,0,0,0,0,0,0
0,0,0,0,0,0,0,0,0,0,0,0,0,0,0,0,0,0,0,0,0,0,0,0,0,0,0,0,0
0,0,0,0,0,0,0,0,0,0,0,0,0,0,0,0,0,0,0,0,0,0,0,0,0,0,0,0,0
0,0,0,0,0,0,0,0,0,0,0,0,0,0,0,0,0,0,0,0,0,0,0,0,0,0,0,0,0
endlayer

layer
0,0,0,0,0,0,0,0,0,0,0,0,0,0,0,0,0,0,0,0,0,0,0,0,0,0,0,0,0
0,0,0,0,0,0,0,0,0,0,0,0,0,0,0,0,0,0,0,0,0,0,0,0,0,0,0,0,0
0,0,0,0,0,0,0,0,0,0,0,0,0,0,0,0,0,0,0,0,0,0,0,0,0,0,0,0,0
0,0,0,0,0,0,0,0,0,0,0,0,0,0,0,0,0,0,0,0,0,0,0,0,0,0,0,0,0
0,0,0,0,0,0,0,0,0,0,0,0,0,0,0,0,0,0,0,0,0,0,0,0,0,0,0,0,0
0,0,0,0,0,0,0,0,0,0,0,0,0,0,0,0,0,0,0,0,0,0,0,0,0,0,0,0,0
0,0,0,0,0,0,0,0,0,0,0,0,0,0,0,0,0,0,0,0,0,0,0,0,0,0,0,0,0
0,0,0,0,0,0,0,0,0,0,0,0,0,0,0,0,0,0,0,0,0,19,0,0,0,0,0,0,0
0,0,0,0,0,0,0,0,0,0,0,0,0,0,0,0,0,0,0,0,0,0,0,0,0,0,0,0,0
0,0,0,0,0,0,0,0,0,0,0,0,0,0,0,0,0,0,0,0,0,0,0,0,0,0,0,0,0
0,0,0,0,0,0,0,0,0,0,0,0,0,0,0,0,0,0,0,0,0,0,0,0,0,0,0,0,0
0,0,0,0,0,0,0,0,0,0,0,0,0,0,0,0,0,0,0,0,0,0,0,0,0,0,0,0,0
0,0,0,0,0,0,0,0,0,0,0,0,0,0,0,0,0,0,0,0,0,0,0,0,0,0,0,0,0
0,0,0,0,0,0,0,0,0,0,0,0,0,0,0,0,0,0,0,0,0,0,0,0,0,0,0,0,0
0,0,0,0,0,0,0,0,0,0,0,0,0,0,0,0,0,0,0,0,0,0,0,0,0,0,0,0,0
endlayer

