weight=3
embed_into_distance=1
dimensions=17,13,24
max_cut_in=0


rule1=0,100,3134-10
rule2=2,100,2843-4
rule3=0,100,2761-11
rule4=0,100,2843-14,2843-14,2843-14,2843-14,2843
rule5=0,100,308,308,308,308,308,308,313,313,314,327
rule6=0,100,2843-7
rule7=0,100,603,603,2838-4,2838-4,2838-4,2838-4,2838-4,2838-4,2838-4,2838-4
rule8=0,50,621-2
rule9=0,33,2004-3,2004-3,2004-3,2004-3,2004-3,2004-3,2015,2015,2015
rule10=0,50,642
rule11=0,50,632
rule12=0,50,629
rule13=0,95,2835-2,2835-2,2835-2,2835-2,2835-2,2835-2,2835-2,2835-1,2835-1,2835-0
rule14=2,66,3225-3
rule15=0,50,628
rule16=0,50,630
rule17=0,100,2781-4,2781-4,2781-4,2781-4,2781-8
rule18=0,100,2524 
rule19=0,100,2245 
rule20=0,100,2248 
rule21=0,100,2291 
rule22=0,100,2843-15
rule23=0,100,622
rule24=0,100,623
rule25=0,90,310

layer
1,1,1,1,1,1,1,1,1,1,1,1,1,1,1,1,1,1,1,1,1,1,1,1
1,1,1,1,1,1,1,1,1,1,1,1,1,1,1,1,1,1,1,1,1,1,1,1
1,1,1,1,1,1,1,1,1,1,1,1,1,1,1,1,1,1,1,1,1,1,1,1
1,1,1,2,2,2,2,2,2,2,2,2,2,2,2,2,2,2,2,2,23,1,1,1
1,1,1,2,2,2,2,2,2,2,2,2,2,2,2,2,2,2,2,2,2,1,1,1
1,1,1,2,2,2,2,2,2,2,2,2,2,2,2,2,2,2,2,2,2,1,1,1
1,1,1,2,2,2,2,2,2,2,2,2,2,2,2,2,2,2,2,2,2,1,1,1
1,1,1,2,2,2,2,2,2,2,2,2,2,2,2,2,2,2,2,2,2,1,1,1
1,1,1,2,2,2,2,2,2,2,2,2,2,2,2,2,2,2,2,2,2,1,1,1
1,1,1,2,2,2,2,2,2,2,2,2,2,2,2,2,2,2,2,2,2,1,1,1
1,1,1,1,1,1,1,2,2,1,1,1,1,1,1,1,1,2,1,1,1,1,1,1
1,1,1,1,1,1,1,1,1,1,1,1,1,1,1,1,1,1,1,1,1,1,1,1
1,1,1,1,1,1,1,1,1,1,1,1,1,1,1,1,1,1,1,1,1,1,1,1
endlayer

layer
0,0,0,0,0,0,0,0,0,0,0,0,0,0,0,0,0,0,0,0,0,0,0,0
0,0,0,0,0,0,0,0,0,0,0,0,0,0,0,0,0,0,0,0,0,0,0,0
0,0,4,4,4,4,4,4,4,4,4,4,4,4,4,4,4,4,4,4,4,4,0,0
0,0,4,0,0,0,0,9,0,10,25,0,0,0,0,0,0,0,0,0,24,4,0,0
0,0,4,0,7,7,7,0,0,0,15,15,0,0,0,0,0,0,0,0,0,4,0,0
0,0,4,0,7,7,7,0,0,0,12,16,0,0,0,0,0,0,0,0,0,4,0,0
0,0,4,0,7,7,7,0,8,0,0,0,0,0,0,0,0,0,0,0,0,4,0,0
0,0,4,0,0,0,0,0,0,0,0,0,0,0,0,0,0,0,0,0,0,4,0,0
0,0,4,0,0,0,0,0,0,0,0,0,0,0,0,0,0,0,0,0,0,4,0,0
0,0,4,0,0,0,0,0,0,0,0,0,0,0,0,0,0,0,0,0,0,4,0,0
0,0,4,4,4,4,4,0,0,4,4,4,4,4,4,4,4,4,4,4,4,4,0,0
0,0,0,0,0,0,0,0,0,0,0,0,0,0,0,0,0,0,0,0,0,0,0,0
0,0,0,0,0,0,0,0,0,0,0,0,0,0,0,0,0,0,0,0,0,0,0,0
endlayer

layer
0,0,0,0,0,0,0,0,0,0,0,0,0,0,0,0,0,0,0,0,0,0,0,0
0,0,0,0,0,0,0,0,0,0,0,0,0,0,0,0,0,0,0,0,0,0,0,0
0,0,4,13,14,14,13,14,14,13,14,14,13,4,13,14,13,14,13,14,13,4,0,0
0,0,13,0,0,0,0,0,0,0,0,0,0,0,0,0,0,0,0,0,24,13,0,0
0,0,14,0,7,7,7,0,0,0,0,0,0,0,0,0,0,0,0,0,0,14,0,0
0,0,13,0,7,5,7,0,0,0,0,0,0,0,0,0,0,0,0,0,0,13,0,0
0,0,14,0,7,7,7,0,0,0,0,0,0,0,0,0,0,0,0,0,0,14,0,0
0,0,13,0,0,0,0,0,0,0,0,0,0,0,0,0,0,0,0,0,0,13,0,0
0,0,14,0,0,0,0,0,0,0,0,0,0,0,0,0,0,0,0,0,0,14,0,0
0,0,13,0,0,0,0,0,0,0,0,0,0,0,0,0,0,0,0,0,0,13,0,0
0,0,4,13,14,14,13,0,0,13,14,14,13,4,13,14,13,14,13,14,13,4,0,0
0,0,0,0,0,0,0,0,0,0,0,0,0,0,0,0,0,0,0,0,0,0,0,0
0,0,0,0,0,0,0,0,0,0,0,0,0,0,0,0,0,0,0,0,0,0,0,0
endlayer

layer
0,0,0,0,0,0,0,0,0,0,0,0,0,0,0,0,0,0,0,0,0,0,0,0
0,0,0,0,0,0,0,0,0,0,0,0,0,0,0,0,0,0,0,0,0,0,0,0
0,0,4,13,14,14,13,14,14,13,14,14,13,4,13,14,13,14,13,14,13,4,0,0
0,0,13,0,0,0,0,0,0,0,0,0,0,0,0,0,0,0,0,0,24,13,0,0
0,0,14,0,7,7,7,0,0,0,0,0,0,0,0,0,0,0,0,0,0,14,0,0
0,0,13,0,7,7,7,0,0,0,0,0,0,0,0,0,0,0,0,0,0,13,0,0
0,0,14,0,7,7,7,0,0,0,0,0,0,0,0,0,0,0,0,0,0,14,0,0
0,0,13,0,0,0,0,0,0,0,0,0,0,0,0,0,0,0,0,0,0,13,0,0
0,0,14,0,0,0,0,0,0,0,0,0,0,0,0,0,0,0,0,0,0,14,0,0
0,0,13,0,0,0,0,0,0,0,0,0,0,0,0,0,0,0,0,0,0,13,0,0
0,0,4,13,14,14,13,13,13,13,14,14,13,4,13,14,13,14,13,14,13,4,0,0
0,0,0,0,0,0,0,0,0,0,0,0,0,0,0,0,0,0,0,0,0,0,0,0
0,0,0,0,0,0,0,0,0,0,0,0,0,0,0,0,0,0,0,0,0,0,0,0
endlayer

layer
0,0,0,0,0,0,0,0,0,0,0,0,0,0,0,0,0,0,0,0,0,0,0,0
0,0,0,0,0,0,0,0,0,0,0,0,0,0,0,0,0,0,0,0,0,0,0,0
0,0,4,13,14,14,13,14,14,13,14,14,13,4,13,14,13,14,13,14,13,4,0,0
0,0,13,0,0,0,0,0,0,0,0,0,0,0,0,0,0,0,0,0,24,13,0,0
0,0,14,0,0,0,0,0,0,0,0,0,0,0,0,0,0,0,0,0,0,14,0,0
0,0,13,0,0,0,22,0,0,0,0,0,0,0,0,0,0,0,0,0,0,13,0,0
0,0,14,0,0,0,0,0,0,0,0,0,0,0,0,0,0,0,0,0,0,14,0,0
0,0,13,0,0,0,0,0,0,0,0,0,0,0,0,0,0,0,0,0,0,13,0,0
0,0,14,0,0,0,0,0,0,0,0,0,0,0,0,0,0,0,0,0,0,14,0,0
0,0,13,0,0,0,0,0,0,0,0,0,0,0,0,0,0,0,0,0,0,13,0,0
0,0,4,13,14,14,13,14,14,13,14,14,13,4,13,14,13,14,13,14,13,4,0,0
0,0,0,0,0,0,0,0,0,0,0,0,0,0,0,0,0,0,0,0,0,0,0,0
0,0,0,0,0,0,0,0,0,0,0,0,0,0,0,0,0,0,0,0,0,0,0,0
endlayer

layer
0,0,0,0,0,0,0,0,0,0,0,0,0,0,0,0,0,0,0,0,0,0,0,0
0,0,0,0,0,0,0,0,0,0,0,0,0,0,0,0,0,0,0,0,0,0,0,0
0,0,4,13,14,14,13,14,14,13,14,14,13,4,13,14,13,14,13,14,13,4,0,0
0,0,13,0,0,0,0,0,0,0,0,0,0,0,0,0,0,0,0,0,24,13,0,0
0,0,14,0,0,0,0,0,0,0,0,0,0,0,0,0,0,0,0,0,0,14,0,0
0,0,13,0,0,0,22,0,0,0,0,0,0,0,0,0,0,0,0,0,0,13,0,0
0,0,14,0,0,0,0,0,0,0,0,0,0,0,0,0,0,0,0,0,0,14,0,0
0,0,13,0,0,0,0,0,0,0,0,0,0,0,0,0,0,0,0,0,0,13,0,0
0,0,14,0,0,0,0,0,0,0,0,0,0,0,0,0,0,0,0,0,0,14,0,0
0,0,13,0,0,0,0,0,0,0,0,0,0,0,0,0,0,0,0,0,0,13,0,0
0,0,4,13,14,14,13,14,14,13,14,14,13,4,13,14,13,14,13,14,13,4,0,0
0,0,0,0,0,0,0,0,0,0,0,0,0,0,0,0,0,0,0,0,0,0,0,0
0,0,0,0,0,0,0,0,0,0,0,0,0,0,0,0,0,0,0,0,0,0,0,0
endlayer

layer
0,0,0,0,0,0,0,0,0,0,0,0,0,0,0,0,0,0,0,0,0,0,0,0
0,0,0,0,0,0,0,0,0,0,0,0,0,0,0,0,0,0,0,0,0,0,0,0
0,0,4,13,14,14,13,14,14,13,14,14,13,4,13,14,13,14,13,14,13,4,0,0
0,0,13,0,0,0,0,0,0,0,0,0,0,0,0,0,0,0,0,0,24,13,0,0
0,0,14,0,0,0,0,0,0,0,0,0,0,0,0,0,0,0,0,0,0,14,0,0
0,0,13,0,0,0,22,0,0,0,0,0,0,0,0,0,0,0,0,0,0,13,0,0
0,0,14,0,0,0,0,0,0,0,0,0,0,0,0,0,0,0,0,0,0,14,0,0
0,0,13,0,0,0,0,0,0,0,0,0,0,0,0,0,0,0,0,0,0,13,0,0
0,0,14,0,0,0,0,0,0,0,0,0,0,0,0,0,0,0,0,0,0,14,0,0
0,0,13,0,0,0,0,0,0,0,0,0,0,0,0,0,0,0,0,0,0,13,0,0
0,0,4,13,14,14,13,14,14,13,14,14,13,4,13,14,13,14,13,14,13,4,0,0
0,0,0,0,0,0,0,0,0,0,0,0,0,0,0,0,0,0,0,0,0,0,0,0
0,0,0,0,0,0,0,0,0,0,0,0,0,0,0,0,0,0,0,0,0,0,0,0
endlayer

layer
0,0,0,0,0,0,0,0,0,0,0,0,0,0,0,0,0,0,0,0,0,0,0,0
0,0,0,0,0,0,0,0,0,0,0,0,0,0,0,0,0,0,0,0,0,0,0,0
0,0,4,13,14,14,13,14,14,13,14,14,13,4,13,14,13,14,13,14,13,4,0,0
0,0,13,0,0,0,0,0,0,0,0,0,0,0,0,0,0,0,0,0,24,13,0,0
0,0,14,0,0,0,0,0,0,0,0,0,0,0,0,0,0,0,0,0,0,14,0,0
0,0,13,0,0,0,22,0,0,0,0,0,0,0,0,0,0,0,0,0,0,13,0,0
0,0,14,0,0,0,0,0,0,0,0,0,0,0,0,0,0,0,0,0,0,14,0,0
0,0,13,0,0,0,0,0,0,0,0,0,0,0,0,0,0,0,0,0,0,13,0,0
0,0,14,0,0,0,0,0,0,0,0,0,0,0,0,0,0,0,0,0,0,14,0,0
0,0,13,0,0,0,0,0,0,0,0,0,0,0,0,0,0,0,0,0,0,13,0,0
0,0,4,13,14,14,13,14,14,13,14,14,13,4,13,14,13,14,13,14,13,4,0,0
0,0,0,0,0,0,0,0,0,0,0,0,0,0,0,0,0,0,0,0,0,0,0,0
0,0,0,0,0,0,0,0,0,0,0,0,0,0,0,0,0,0,0,0,0,0,0,0
endlayer

layer
0,0,0,0,0,0,0,0,0,0,0,0,0,0,0,0,0,0,0,0,0,0,0,0
0,0,0,0,0,0,0,0,0,0,0,0,0,0,0,0,0,0,0,0,0,0,0,0
0,0,4,4,4,4,4,4,4,4,4,4,4,4,4,4,4,4,4,4,4,4,0,0
0,0,4,17,17,17,17,17,17,17,17,17,17,4,3,3,3,3,3,3,24,4,0,0
0,0,4,17,17,17,17,17,17,17,17,17,17,4,3,3,3,3,3,3,3,4,0,0
0,0,4,17,17,17,22,17,17,17,17,17,17,4,3,3,3,3,3,3,3,4,0,0
0,0,4,17,17,17,17,17,17,17,17,17,17,4,3,3,3,3,3,3,3,4,0,0
0,0,4,17,17,17,17,17,17,17,17,17,17,4,3,3,3,3,3,3,3,4,0,0
0,0,4,17,17,17,17,17,17,17,17,17,17,4,3,3,3,3,3,3,3,4,0,0
0,0,4,17,17,17,17,17,17,17,17,17,17,4,3,3,3,3,3,3,3,4,0,0
0,0,4,4,4,4,4,4,4,4,4,4,4,4,4,4,4,4,4,4,4,4,0,0
0,0,0,0,0,0,0,0,0,0,0,0,0,0,0,0,0,0,0,0,0,0,0,0
0,0,0,0,0,0,0,0,0,0,0,0,0,0,0,0,0,0,0,0,0,0,0,0
endlayer

layer
0,0,0,0,0,0,0,0,0,0,0,0,0,0,0,0,0,0,0,0,0,0,0,0
0,0,0,0,0,0,0,0,0,0,0,0,0,0,0,0,0,0,0,0,0,0,0,0
0,0,0,0,0,0,0,0,0,0,0,0,0,4,13,14,13,14,13,14,13,4,0,0
0,0,0,0,0,0,0,0,0,0,0,0,0,13,0,0,0,0,0,0,24,13,0,0
0,0,0,0,0,0,0,0,0,0,0,0,0,14,0,0,0,0,0,0,0,14,0,0
0,0,0,0,0,0,22,0,0,0,0,0,0,13,0,0,19,0,0,0,0,13,0,0
0,0,0,0,0,0,0,0,0,0,0,0,0,14,0,21,20,0,0,0,0,14,0,0
0,0,0,0,0,0,0,0,0,0,0,0,0,13,0,5,19,0,0,0,0,13,0,0
0,0,0,0,0,0,0,0,0,0,0,0,0,14,0,0,0,0,0,0,0,14,0,0
0,0,0,0,0,0,0,0,0,0,0,0,0,13,0,0,0,0,0,0,25,13,0,0
0,0,0,0,0,0,0,0,0,0,0,0,0,4,13,14,13,14,13,14,13,4,0,0
0,0,0,0,0,0,0,0,0,0,0,0,0,0,0,0,0,0,0,0,0,0,0,0
0,0,0,0,0,0,0,0,0,0,0,0,0,0,0,0,0,0,0,0,0,0,0,0
endlayer

layer
0,0,0,0,0,0,0,0,0,0,0,0,0,0,0,0,0,0,0,0,0,0,0,0
0,0,0,0,0,0,0,0,0,0,0,0,0,0,0,0,0,0,0,0,0,0,0,0
0,0,0,0,0,0,0,0,0,0,0,0,0,4,13,14,13,14,13,14,13,4,0,0
0,0,0,0,0,0,0,0,0,0,0,0,0,13,0,0,0,0,0,0,24,13,0,0
0,0,0,0,0,0,0,0,0,0,0,0,0,14,0,0,0,0,0,0,0,14,0,0
0,0,0,0,0,0,22,0,0,0,0,0,0,13,0,0,0,0,0,0,0,13,0,0
0,0,0,0,0,0,0,0,0,0,0,0,0,14,0,0,0,0,0,0,0,14,0,0
0,0,0,0,0,0,0,0,0,0,0,0,0,13,0,0,0,0,0,0,0,13,0,0
0,0,0,0,0,0,0,0,0,0,0,0,0,14,0,0,0,0,0,0,0,14,0,0
0,0,0,0,0,0,0,0,0,0,0,0,0,13,0,0,0,0,0,0,0,13,0,0
0,0,0,0,0,0,0,0,0,0,0,0,0,4,13,14,13,14,13,14,13,4,0,0
0,0,0,0,0,0,0,0,0,0,0,0,0,0,0,0,0,0,0,0,0,0,0,0
0,0,0,0,0,0,0,0,0,0,0,0,0,0,0,0,0,0,0,0,0,0,0,0
endlayer

layer
0,0,0,0,0,0,0,0,0,0,0,0,0,0,0,0,0,0,0,0,0,0,0,0
0,0,0,0,0,0,0,0,0,0,0,0,0,0,0,0,0,0,0,0,0,0,0,0
0,0,0,0,0,0,0,0,0,0,0,0,0,4,13,14,13,14,13,14,13,4,0,0
0,0,0,0,0,0,0,0,0,0,0,0,0,13,0,0,0,0,0,0,0,13,0,0
0,0,0,0,0,0,0,0,0,0,0,0,0,14,0,0,0,0,0,0,0,14,0,0
0,0,0,0,0,0,6,0,0,0,0,0,0,13,0,0,0,0,0,0,0,13,0,0
0,0,0,0,0,0,0,0,0,0,0,0,0,14,0,0,0,0,0,0,0,14,0,0
0,0,0,0,0,0,0,0,0,0,0,0,0,13,0,0,0,0,0,0,0,13,0,0
0,0,0,0,0,0,0,0,0,0,0,0,0,14,0,0,0,0,0,0,0,14,0,0
0,0,0,0,0,0,0,0,0,0,0,0,0,13,0,0,0,0,0,0,0,13,0,0
0,0,0,0,0,0,0,0,0,0,0,0,0,4,13,14,13,14,13,14,13,4,0,0
0,0,0,0,0,0,0,0,0,0,0,0,0,0,0,0,0,0,0,0,0,0,0,0
0,0,0,0,0,0,0,0,0,0,0,0,0,0,0,0,0,0,0,0,0,0,0,0
endlayer

layer
0,0,0,0,0,0,0,0,0,0,0,0,0,0,0,0,0,0,0,0,0,0,0,0
0,0,0,0,0,0,0,0,0,0,0,0,0,0,0,0,0,0,0,0,0,0,0,0
0,0,0,0,0,0,0,0,0,0,0,0,0,4,13,14,13,14,13,14,13,4,0,0
0,0,0,0,0,0,0,0,0,0,0,0,0,13,0,0,0,0,0,0,0,13,0,0
0,0,0,0,0,0,0,0,0,0,0,0,0,14,0,0,0,0,0,0,0,14,0,0
0,0,0,0,0,0,22,0,0,0,0,0,0,13,0,0,0,0,0,0,0,13,0,0
0,0,0,0,0,0,0,0,0,0,0,0,0,14,0,0,0,0,0,0,0,14,0,0
0,0,0,0,0,0,0,0,0,0,0,0,0,13,0,0,0,0,0,0,0,13,0,0
0,0,0,0,0,0,0,0,0,0,0,0,0,14,0,0,0,0,0,0,0,14,0,0
0,0,0,0,0,0,0,0,0,0,0,0,0,13,0,0,0,0,0,0,0,13,0,0
0,0,0,0,0,0,0,0,0,0,0,0,0,4,13,14,13,14,13,14,13,4,0,0
0,0,0,0,0,0,0,0,0,0,0,0,0,0,0,0,0,0,0,0,0,0,0,0
0,0,0,0,0,0,0,0,0,0,0,0,0,0,0,0,0,0,0,0,0,0,0,0
endlayer

layer
0,0,0,0,0,0,0,0,0,0,0,0,0,0,0,0,0,0,0,0,0,0,0,0
0,0,0,0,0,0,0,0,0,0,0,0,0,0,0,0,0,0,0,0,0,0,0,0
0,0,0,0,0,0,0,0,0,0,0,0,0,4,13,14,13,14,13,14,13,4,0,0
0,0,0,0,0,0,0,0,0,0,0,0,0,13,0,0,0,0,0,0,0,13,0,0
0,0,0,0,0,0,0,0,0,0,0,0,0,14,0,0,0,0,0,0,0,14,0,0
0,0,0,0,0,0,22,0,0,0,0,0,0,13,0,0,0,0,0,0,0,13,0,0
0,0,0,0,0,0,0,0,0,0,0,0,0,14,0,0,0,0,0,0,0,14,0,0
0,0,0,0,0,0,0,0,0,0,0,0,0,13,0,0,0,0,0,0,0,13,0,0
0,0,0,0,0,0,0,0,0,0,0,0,0,14,0,0,0,0,0,0,0,14,0,0
0,0,0,0,0,0,0,0,0,0,0,0,0,13,0,0,0,0,0,0,0,13,0,0
0,0,0,0,0,0,0,0,0,0,0,0,0,4,13,14,13,14,13,14,13,4,0,0
0,0,0,0,0,0,0,0,0,0,0,0,0,0,0,0,0,0,0,0,0,0,0,0
0,0,0,0,0,0,0,0,0,0,0,0,0,0,0,0,0,0,0,0,0,0,0,0
endlayer

layer
0,0,0,0,0,0,0,0,0,0,0,0,0,0,0,0,0,0,0,0,0,0,0,0
0,0,0,0,0,0,0,0,0,0,0,0,0,0,0,0,0,0,0,0,0,0,0,0
0,0,0,0,0,0,0,0,0,0,0,0,0,4,13,14,13,14,13,14,13,4,0,0
0,0,0,0,0,0,0,0,0,0,0,0,0,13,0,0,0,0,0,0,0,13,0,0
0,0,0,0,0,0,0,0,0,0,0,0,0,14,0,0,0,0,0,0,0,14,0,0
0,0,0,0,0,0,6,0,0,0,0,0,0,13,0,0,0,0,0,0,0,13,0,0
0,0,0,0,0,0,0,0,0,0,0,0,0,14,0,0,0,0,0,0,0,14,0,0
0,0,0,0,0,0,0,0,0,0,0,0,0,13,0,0,0,0,0,0,0,13,0,0
0,0,0,0,0,0,0,0,0,0,0,0,0,14,0,0,0,0,0,0,0,14,0,0
0,0,0,0,0,0,0,0,0,0,0,0,0,13,0,0,0,0,0,0,0,13,0,0
0,0,0,0,0,0,0,0,0,0,0,0,0,4,13,14,13,14,13,14,13,4,0,0
0,0,0,0,0,0,0,0,0,0,0,0,0,0,0,0,0,0,0,0,0,0,0,0
0,0,0,0,0,0,0,0,0,0,0,0,0,0,0,0,0,0,0,0,0,0,0,0
endlayer

layer
0,0,0,0,0,0,0,0,0,0,0,0,0,0,0,0,0,0,0,0,0,0,0,0
0,0,0,0,0,0,0,0,0,0,0,0,0,0,0,0,0,0,0,0,0,0,0,0
0,0,0,0,0,0,0,0,0,0,0,0,0,4,13,14,13,14,13,14,13,4,0,0
0,0,0,0,0,0,0,0,0,0,0,0,0,13,0,0,0,0,0,0,0,13,0,0
0,0,0,0,0,0,0,0,0,0,0,0,0,14,0,0,0,0,0,0,0,14,0,0
0,0,0,0,0,0,22,0,0,0,0,0,0,13,0,0,0,0,0,0,0,13,0,0
0,0,0,0,0,0,0,0,0,0,0,0,0,14,0,0,0,0,0,0,0,14,0,0
0,0,0,0,0,0,0,0,0,0,0,0,0,13,0,0,0,0,0,0,0,13,0,0
0,0,0,0,0,0,0,0,0,0,0,0,0,14,0,0,0,0,0,0,0,14,0,0
0,0,0,0,0,0,0,0,0,0,0,0,0,13,0,0,0,0,0,0,0,13,0,0
0,0,0,0,0,0,0,0,0,0,0,0,0,4,13,14,13,14,13,14,13,4,0,0
0,0,0,0,0,0,0,0,0,0,0,0,0,0,0,0,0,0,0,0,0,0,0,0
0,0,0,0,0,0,0,0,0,0,0,0,0,0,0,0,0,0,0,0,0,0,0,0
endlayer

layer
0,0,0,0,0,0,0,0,0,0,0,0,0,0,0,0,0,0,0,0,0,0,0,0
0,0,0,0,0,0,0,0,0,0,0,0,0,0,0,0,0,0,0,0,0,0,0,0
0,0,0,0,0,0,0,0,0,0,0,0,0,4,4,4,4,4,4,4,4,4,0,0
0,0,0,0,0,0,0,0,0,0,0,0,0,4,17,17,17,17,17,17,17,4,0,0
0,0,0,0,0,0,0,0,0,0,0,0,0,4,17,17,17,17,17,17,17,4,0,0
0,0,0,0,0,0,22,0,0,0,0,0,0,4,17,17,17,17,17,17,17,4,0,0
0,0,0,0,0,0,0,0,0,0,0,0,0,4,17,17,17,17,17,17,17,4,0,0
0,0,0,0,0,0,0,0,0,0,0,0,0,4,17,17,17,17,17,17,17,4,0,0
0,0,0,0,0,0,0,0,0,0,0,0,0,4,17,17,17,17,17,17,17,4,0,0
0,0,0,0,0,0,0,0,0,0,0,0,0,4,17,17,17,17,17,17,17,4,0,0
0,0,0,0,0,0,0,0,0,0,0,0,0,4,4,4,4,4,4,4,4,4,0,0
0,0,0,0,0,0,0,0,0,0,0,0,0,0,0,0,0,0,0,0,0,0,0,0
0,0,0,0,0,0,0,0,0,0,0,0,0,0,0,0,0,0,0,0,0,0,0,0
endlayer

