# Converted from schematic
# THIS TEMPLATE USES DEFAULTS!  Please edit for corrections.
# If you need help, consult template_rules.txt

weight=3
embed_into_distance=5
acceptable_target_blocks=1,2,3,12,13,250
dimensions=17,24,13
allowable_overhang=0
max_cut_in=2
cut_in_buffer=1
max_leveling=2
leveling_buffer=1
preserve_water=0
preserve_lava=0
preserve_plants=0


rule1=0,100,3134-10
rule2=0,100,250
rule3=0,100,2843-4
rule4=0,100,622,2838-4,2838-4,2838-4,2838-4,2838-4,2838-4
rule5=0,100,2843-14,2843-14,2843-14,2843-14,2843
rule6=0,100,310,310,311
rule7=0,100,603,603,3509,3509,3509,3509,3509,3509,3509,3509
rule8=0,95,2835-2,2835-2,2835-2,2835-2,2835-2,2835-2,2835-2,2835-1,2835-1,2835-0
rule9=0,66,3225-3
rule10=0,100,308
rule11=0,95,300
rule12=0,100,2843-15
rule13=0,100,3134,3134,3134,3134,3134-8,3134-2
rule14=0,100,2761-11
rule15=0,100,2843-7
rule16=1,100,3538
rule17=1,50,603,603,3509,3509,3509,3509,3509,3509,3509,3509
rule18=1,25,603,603,3509,3509,3509,3509,3509,3509,3509,3509


layer
1,1,1,1,1,1,1,1,1,1,1,1,1
1,1,1,1,1,1,1,1,1,1,1,1,1
1,1,1,1,1,1,1,1,1,1,1,1,1
1,1,1,3,3,3,3,3,3,3,1,1,1
1,1,1,3,3,3,3,3,3,3,1,1,1
1,1,1,3,3,3,3,10,3,3,1,1,1
1,1,1,3,3,3,3,3,3,3,1,1,1
1,1,3,3,3,3,3,3,3,3,1,1,1
1,1,3,3,3,3,3,3,3,3,1,1,1
1,1,1,3,3,3,3,3,3,3,1,1,1
1,1,1,3,3,3,3,3,3,3,1,2,2
1,1,1,3,3,3,3,3,3,3,1,2,2
1,1,1,3,3,3,3,3,3,3,1,2,2
1,1,1,3,3,3,3,3,3,3,1,2,2
1,1,1,3,3,3,3,3,3,3,1,2,2
1,1,1,3,3,3,3,3,3,3,1,2,2
1,1,1,3,3,3,3,3,3,3,1,2,2
1,1,3,3,3,3,3,3,3,3,1,2,2
1,1,1,3,3,3,3,3,3,3,1,1,1
1,1,1,3,3,3,3,3,3,3,1,1,1
1,1,1,3,3,3,3,3,3,4,1,1,1
1,1,1,1,1,1,1,1,1,1,1,1,1
1,1,1,1,1,1,1,1,1,1,1,1,1
1,1,1,1,1,1,1,1,1,1,1,1,1
endlayer

layer
2,2,2,2,2,2,2,2,2,2,2,2,2
2,2,2,2,2,2,2,2,2,2,2,2,2
2,2,5,5,5,5,5,5,5,5,5,2,2
2,2,5,0,0,0,0,0,0,0,5,2,2
2,2,5,0,0,0,7,7,7,0,5,2,2
2,2,5,0,0,0,7,7,7,0,5,2,2
2,2,5,0,0,0,7,7,7,0,5,2,2
2,2,2,0,0,0,0,0,0,0,5,2,2
2,2,2,2,2,0,0,0,0,0,5,2,2
2,2,5,2,2,0,0,0,2,2,5,2,2
2,2,5,0,0,0,0,0,2,6,2,2,2
2,2,5,0,0,0,0,0,2,2,2,2,2
2,2,5,0,0,0,0,0,0,2,2,2,2
2,2,5,0,0,0,2,2,2,2,2,2,2
2,2,5,0,0,0,0,2,2,2,2,2,2
2,2,5,0,0,0,2,2,2,2,2,2,2
2,2,5,0,0,0,0,2,2,2,2,2,2
2,2,5,0,0,0,0,0,2,2,5,2,2
2,2,5,0,0,0,0,0,2,2,5,2,2
2,2,5,0,0,0,0,0,0,0,5,2,2
2,2,5,0,0,0,0,0,0,0,5,2,2
2,2,5,5,5,5,5,5,5,5,5,2,2
2,2,2,2,2,2,2,2,2,2,2,2,2
2,2,2,2,2,2,2,2,2,2,2,2,2
endlayer

layer
2,2,2,2,2,2,2,2,2,2,2,2,2
2,2,2,2,2,2,2,2,2,2,2,2,2
2,2,5,8,9,8,9,8,9,8,5,2,2
2,2,8,0,0,0,0,0,0,0,8,2,2
2,2,9,0,0,0,17,17,17,0,9,2,2
2,2,9,0,0,0,17,0,17,0,9,2,2
2,2,8,0,0,0,17,17,17,0,8,2,2
2,2,0,0,0,0,0,0,0,0,9,2,2
2,2,0,0,0,0,0,0,0,0,2,2,2
2,2,8,0,0,0,0,0,0,0,8,2,2
2,2,9,0,0,0,0,0,0,2,2,2,2
2,2,9,0,0,0,0,0,0,0,2,2,2
2,2,8,0,0,0,0,0,0,2,2,2,2
2,2,5,0,0,0,0,0,0,2,2,2,2
2,2,8,0,0,0,0,0,0,0,2,2,2
2,2,9,0,0,0,0,0,2,2,2,2,2
2,2,8,0,0,0,0,0,2,2,2,2,2
2,2,9,0,0,0,0,0,0,2,2,2,2
2,2,8,0,0,0,0,0,0,2,8,2,2
2,2,9,0,0,0,0,0,0,0,9,2,2
2,2,8,0,0,0,0,0,0,0,8,2,2
2,2,5,8,9,8,9,8,9,8,5,2,2
2,2,2,2,2,2,2,2,2,2,2,2,2
2,2,2,2,2,2,2,2,2,2,2,2,2
endlayer

layer
2,2,2,2,2,2,2,2,2,2,2,2,2
2,2,2,2,2,2,2,2,2,2,2,2,2
2,2,5,8,9,8,9,8,9,8,5,2,2
2,2,8,0,0,0,0,0,0,0,8,2,2
2,2,9,0,0,0,18,18,18,0,9,2,2
2,2,9,0,0,0,18,18,18,0,9,2,2
2,2,8,0,0,0,18,18,18,0,8,2,2
2,2,8,0,0,0,0,0,0,0,9,2,2
2,2,8,0,0,0,0,0,0,0,2,2,2
2,2,8,0,0,0,0,0,0,0,8,2,2
2,2,9,0,0,0,0,0,0,0,2,2,2
2,2,9,0,0,0,0,0,0,0,0,2,2
2,2,8,0,0,0,0,0,0,0,2,2,2
2,2,5,0,0,0,0,0,0,0,2,2,2
2,2,8,0,0,0,0,0,0,0,2,2,2
2,2,9,0,0,0,0,0,0,0,2,2,2
2,2,8,0,0,0,0,0,0,0,2,2,2
2,2,9,0,0,0,0,0,0,2,2,2,2
2,2,8,0,0,0,0,0,0,0,2,2,2
2,2,9,0,0,0,0,0,0,0,0,2,2
2,2,8,0,0,0,0,0,0,0,8,2,2
2,2,5,8,9,8,9,8,9,8,5,2,2
2,2,2,2,2,2,2,2,2,2,2,2,2
2,2,2,2,2,2,2,2,2,2,2,2,2
endlayer

layer
11,11,11,11,11,11,11,11,11,11,11,11,11
11,11,11,11,11,11,11,11,11,11,11,11,11
11,11,5,8,9,8,9,8,9,8,5,11,11
11,11,8,0,0,0,0,0,0,0,8,11,11
11,11,9,0,0,0,0,0,0,0,9,11,11
11,11,9,0,0,0,0,0,0,0,9,11,11
11,11,8,0,0,0,0,12,0,0,8,11,11
11,11,9,0,0,0,0,0,0,0,9,11,11
11,11,9,0,0,0,0,0,0,0,11,11,11
11,11,8,0,0,0,0,0,0,0,11,11,11
11,11,9,0,0,0,0,0,0,0,0,11,11
11,11,9,0,0,0,0,0,0,0,0,11,11
11,11,8,0,0,0,0,0,0,0,0,11,11
11,11,5,0,0,0,0,0,0,0,0,11,11
11,11,8,0,0,0,0,0,0,0,0,11,11
11,11,9,0,0,0,0,0,0,0,0,11,11
11,11,8,0,0,0,0,0,0,0,0,11,11
11,11,9,0,0,0,0,0,0,0,11,11,11
11,11,8,0,0,0,0,0,0,0,11,11,11
11,11,9,0,0,0,0,0,0,0,0,11,11
11,11,8,0,0,0,0,0,0,0,8,11,11
11,11,5,8,9,8,9,8,9,8,5,11,11
11,11,11,11,11,11,11,11,11,11,11,11,11
11,11,11,11,11,11,11,11,11,11,11,11,11
endlayer

layer
0,0,0,0,0,0,0,0,0,0,0,0,0
0,0,0,0,0,0,0,0,0,0,0,0,0
0,0,5,8,9,8,9,8,9,8,5,0,0
0,0,8,0,0,0,0,0,0,0,8,0,0
0,0,9,0,0,0,0,0,0,0,9,0,0
0,0,9,0,0,0,0,0,0,0,9,0,0
0,0,8,0,0,0,0,12,0,0,8,0,0
0,0,9,0,0,0,0,0,0,0,9,0,0
0,0,9,0,0,0,0,0,0,0,0,0,0
0,0,8,0,0,0,0,0,0,0,0,0,0
0,0,9,0,0,0,0,0,0,0,0,0,0
0,0,9,0,0,0,0,0,0,0,0,0,0
0,0,8,0,0,0,0,0,0,0,0,0,0
0,0,5,0,0,0,0,0,0,0,0,0,0
0,0,8,0,0,0,0,0,0,0,0,0,0
0,0,9,0,0,0,0,0,0,0,0,0,0
0,0,8,0,0,0,0,0,0,0,0,0,0
0,0,9,0,0,0,0,0,0,0,0,0,0
0,0,8,0,0,0,0,0,0,0,0,0,0
0,0,9,0,0,0,0,0,0,0,0,0,0
0,0,8,0,0,0,0,0,0,0,8,0,0
0,0,5,8,9,8,9,8,9,8,5,0,0
0,0,0,0,0,0,0,0,0,0,0,0,0
0,0,0,0,0,0,0,0,0,0,0,0,0
endlayer

layer
0,0,0,0,0,0,0,0,0,0,0,0,0
0,0,0,0,0,0,0,0,0,0,0,0,0
0,0,5,8,9,8,9,8,9,8,5,0,0
0,0,8,0,0,0,0,0,0,0,8,0,0
0,0,9,0,0,0,0,0,0,0,9,0,0
0,0,9,0,0,0,0,0,0,0,0,0,0
0,0,8,0,0,0,0,12,0,0,8,0,0
0,0,9,0,0,0,0,0,0,0,9,0,0
0,0,9,0,0,0,0,0,0,0,0,0,0
0,0,8,0,0,0,0,0,0,0,0,0,0
0,0,9,0,0,0,0,0,0,0,0,0,0
0,0,9,0,0,0,0,0,0,0,0,0,0
0,0,8,0,0,0,0,0,0,0,0,0,0
0,0,5,0,0,0,0,0,0,0,0,0,0
0,0,8,0,0,0,0,0,0,0,0,0,0
0,0,9,0,0,0,0,0,0,0,0,0,0
0,0,8,0,0,0,0,0,0,0,0,0,0
0,0,9,0,0,0,0,0,0,0,0,0,0
0,0,8,0,0,0,0,0,0,0,0,0,0
0,0,9,0,0,0,0,0,0,0,0,0,0
0,0,8,0,0,0,0,0,0,0,8,0,0
0,0,5,8,9,8,0,8,9,8,5,0,0
0,0,0,0,0,0,0,0,0,0,0,0,0
0,0,0,0,0,0,0,0,0,0,0,0,0
endlayer

layer
0,0,0,0,0,0,0,0,0,0,0,0,0
0,0,0,0,0,0,0,0,0,0,0,0,0
0,0,5,8,9,8,9,8,9,8,5,0,0
0,0,8,0,0,0,0,0,0,0,8,0,0
0,0,9,0,0,0,0,0,0,0,9,0,0
0,0,9,0,0,0,0,0,0,0,9,0,0
0,0,8,0,0,0,0,12,0,0,8,0,0
0,0,9,0,0,0,0,0,0,0,9,0,0
0,0,9,0,0,0,0,0,0,0,9,0,0
0,0,8,0,0,0,0,0,0,0,8,0,0
0,0,9,0,0,0,0,0,0,0,0,0,0
0,0,9,0,0,0,0,0,0,0,0,0,0
0,0,8,0,0,0,0,0,0,0,8,0,0
0,0,5,0,0,0,0,0,0,0,0,0,0
0,0,8,0,0,0,0,0,0,0,0,0,0
0,0,9,0,0,0,0,0,0,0,0,0,0
0,0,8,0,0,0,0,0,0,0,0,0,0
0,0,9,0,0,0,0,0,0,0,0,0,0
0,0,8,0,0,0,0,0,0,0,0,0,0
0,0,9,0,0,0,0,0,0,0,0,0,0
0,0,8,0,0,0,0,0,0,0,8,0,0
0,0,5,8,9,8,9,8,9,8,5,0,0
0,0,0,0,0,0,0,0,0,0,0,0,0
0,0,0,0,0,0,0,0,0,0,0,0,0
endlayer

layer
0,0,0,0,0,0,0,0,0,0,0,0,0
0,0,0,0,0,0,0,0,0,0,0,0,0
0,0,5,5,5,5,5,5,5,5,5,0,0
0,0,5,13,13,13,13,13,13,13,5,0,0
0,0,5,13,13,13,13,13,13,13,5,0,0
0,0,5,13,13,13,13,13,13,13,5,0,0
0,0,5,13,13,13,13,12,13,13,5,0,0
0,0,5,13,13,13,13,13,13,13,5,0,0
0,0,5,13,13,13,13,13,13,13,5,0,0
0,0,5,13,13,13,13,13,13,13,5,0,0
0,0,5,13,13,13,13,13,13,13,5,0,0
0,0,5,13,13,13,13,13,13,0,5,0,0
0,0,5,13,13,13,13,13,13,13,5,0,0
0,0,5,5,5,5,5,0,5,5,0,0,0
0,0,5,14,14,14,14,14,0,0,0,0,0
0,0,5,14,14,14,14,14,14,0,0,0,0
0,0,5,14,14,14,14,14,0,0,0,0,0
0,0,5,14,14,14,14,14,14,14,0,0,0
0,0,5,14,14,14,14,14,14,14,0,0,0
0,0,5,14,14,14,14,14,14,14,0,0,0
0,0,5,14,14,14,14,14,14,0,5,0,0
0,0,5,5,5,5,5,5,5,5,5,0,0
0,0,0,0,0,0,0,0,0,0,0,0,0
0,0,0,0,0,0,0,0,0,0,0,0,0
endlayer

layer
0,0,0,0,0,0,0,0,0,0,0,0,0
0,0,0,0,0,0,0,0,0,0,0,0,0
0,0,0,0,0,0,0,0,0,0,0,0,0
0,0,0,0,0,0,0,0,0,0,0,0,0
0,0,0,0,0,0,0,0,0,0,0,0,0
0,0,0,0,0,0,0,0,0,0,0,0,0
0,0,0,0,0,0,0,12,0,0,0,0,0
0,0,0,0,0,16,16,0,0,0,0,0,0
0,0,0,0,0,16,16,0,0,0,0,0,0
0,0,0,0,0,0,0,0,0,0,0,0,0
0,0,0,0,0,0,0,0,0,0,0,0,0
0,0,0,0,0,0,0,0,0,0,0,0,0
0,0,0,0,0,0,0,0,0,0,0,0,0
0,0,5,8,9,8,9,8,9,8,0,0,0
0,0,8,0,0,0,0,0,0,0,0,0,0
0,0,9,0,0,10,0,0,0,0,0,0,0
0,0,8,0,0,0,0,0,0,0,0,0,0
0,0,9,0,0,0,0,0,0,0,0,0,0
0,0,8,0,0,0,0,0,0,0,0,0,0
0,0,9,0,0,0,0,0,0,0,0,0,0
0,0,8,0,0,0,0,0,0,0,8,0,0
0,0,5,8,9,8,9,8,9,8,5,0,0
0,0,0,0,0,0,0,0,0,0,0,0,0
0,0,0,0,0,0,0,0,0,0,0,0,0
endlayer

layer
0,0,0,0,0,0,0,0,0,0,0,0,0
0,0,0,0,0,0,0,0,0,0,0,0,0
0,0,0,0,0,0,0,0,0,0,0,0,0
0,0,0,0,0,0,0,0,0,0,0,0,0
0,0,0,0,0,0,0,0,0,0,0,0,0
0,0,0,0,0,0,0,0,0,0,0,0,0
0,0,0,0,0,0,0,12,0,0,0,0,0
0,0,0,0,0,0,0,0,0,0,0,0,0
0,0,0,0,0,0,0,0,0,0,0,0,0
0,0,0,0,0,0,0,0,0,0,0,0,0
0,0,0,0,0,0,0,0,0,0,0,0,0
0,0,0,0,0,0,0,0,0,0,0,0,0
0,0,0,0,0,0,0,0,0,0,0,0,0
0,0,5,8,9,8,9,8,9,8,0,0,0
0,0,8,0,0,0,0,0,0,0,0,0,0
0,0,9,0,0,0,0,0,0,0,0,0,0
0,0,8,0,0,0,0,0,0,0,0,0,0
0,0,9,0,0,0,0,0,0,0,0,0,0
0,0,8,0,0,0,0,0,0,0,0,0,0
0,0,9,0,0,0,0,0,0,0,0,0,0
0,0,8,0,0,0,0,0,0,0,8,0,0
0,0,5,8,9,8,9,8,9,8,5,0,0
0,0,0,0,0,0,0,0,0,0,0,0,0
0,0,0,0,0,0,0,0,0,0,0,0,0
endlayer

layer
0,0,0,0,0,0,0,0,0,0,0,0,0
0,0,0,0,0,0,0,0,0,0,0,0,0
0,0,0,0,0,0,0,0,0,0,0,0,0
0,0,0,0,0,0,0,0,0,0,0,0,0
0,0,0,0,0,0,0,0,0,0,0,0,0
0,0,0,0,0,0,0,0,0,0,0,0,0
0,0,0,0,0,0,0,15,0,0,0,0,0
0,0,0,0,0,0,0,0,0,0,0,0,0
0,0,0,0,0,0,0,0,0,0,0,0,0
0,0,0,0,0,0,0,0,0,0,0,0,0
0,0,0,0,0,0,0,0,0,0,0,0,0
0,0,0,0,0,0,0,0,0,0,0,0,0
0,0,0,0,0,0,0,0,0,0,0,0,0
0,0,5,8,9,8,9,8,0,0,0,0,0
0,0,8,0,0,0,0,0,0,0,0,0,0
0,0,9,0,0,0,0,0,0,0,0,0,0
0,0,8,0,0,0,0,0,0,0,0,0,0
0,0,9,0,0,0,0,0,0,0,0,0,0
0,0,8,0,0,0,0,0,0,0,0,0,0
0,0,9,0,0,0,0,0,0,0,0,0,0
0,0,8,0,0,0,0,0,0,0,8,0,0
0,0,5,8,9,8,9,8,9,8,5,0,0
0,0,0,0,0,0,0,0,0,0,0,0,0
0,0,0,0,0,0,0,0,0,0,0,0,0
endlayer

layer
0,0,0,0,0,0,0,0,0,0,0,0,0
0,0,0,0,0,0,0,0,0,0,0,0,0
0,0,0,0,0,0,0,0,0,0,0,0,0
0,0,0,0,0,0,0,0,0,0,0,0,0
0,0,0,0,0,0,0,0,0,0,0,0,0
0,0,0,0,0,0,0,0,0,0,0,0,0
0,0,0,0,0,0,0,12,0,0,0,0,0
0,0,0,0,0,0,0,0,0,0,0,0,0
0,0,0,0,0,0,0,0,0,0,0,0,0
0,0,0,0,0,0,0,0,0,0,0,0,0
0,0,0,0,0,0,0,0,0,0,0,0,0
0,0,0,0,0,0,0,0,0,0,0,0,0
0,0,0,0,0,0,0,0,0,0,0,0,0
0,0,5,8,9,8,9,0,0,0,0,0,0
0,0,8,0,0,0,0,0,0,0,0,0,0
0,0,9,0,0,0,0,0,0,0,0,0,0
0,0,8,0,0,0,0,0,0,0,0,0,0
0,0,9,0,0,0,0,0,0,0,0,0,0
0,0,8,0,0,0,0,0,0,0,0,0,0
0,0,9,0,0,0,0,0,0,0,0,0,0
0,0,8,0,0,0,0,0,0,0,8,0,0
0,0,5,8,9,8,9,8,9,8,5,0,0
0,0,0,0,0,0,0,0,0,0,0,0,0
0,0,0,0,0,0,0,0,0,0,0,0,0
endlayer

layer
0,0,0,0,0,0,0,0,0,0,0,0,0
0,0,0,0,0,0,0,0,0,0,0,0,0
0,0,0,0,0,0,0,0,0,0,0,0,0
0,0,0,0,0,0,0,0,0,0,0,0,0
0,0,0,0,0,0,0,0,0,0,0,0,0
0,0,0,0,0,0,0,0,0,0,0,0,0
0,0,0,0,0,0,0,12,0,0,0,0,0
0,0,0,0,0,0,0,0,0,0,0,0,0
0,0,0,0,0,0,0,0,0,0,0,0,0
0,0,0,0,0,0,0,0,0,0,0,0,0
0,0,0,0,0,0,0,0,0,0,0,0,0
0,0,0,0,0,0,0,0,0,0,0,0,0
0,0,0,0,0,0,0,0,0,0,0,0,0
0,0,5,8,9,8,9,0,0,0,0,0,0
0,0,8,0,0,0,0,0,0,0,0,0,0
0,0,9,0,0,0,0,0,0,0,0,0,0
0,0,8,0,0,0,0,0,0,0,0,0,0
0,0,9,0,0,0,0,0,0,0,0,0,0
0,0,8,0,0,0,0,0,0,0,0,0,0
0,0,9,0,0,0,0,0,0,0,0,0,0
0,0,8,0,0,0,0,0,0,0,8,0,0
0,0,5,8,9,8,0,8,9,8,5,0,0
0,0,0,0,0,0,0,0,0,0,0,0,0
0,0,0,0,0,0,0,0,0,0,0,0,0
endlayer

layer
0,0,0,0,0,0,0,0,0,0,0,0,0
0,0,0,0,0,0,0,0,0,0,0,0,0
0,0,0,0,0,0,0,0,0,0,0,0,0
0,0,0,0,0,0,0,0,0,0,0,0,0
0,0,0,0,0,0,0,0,0,0,0,0,0
0,0,0,0,0,0,0,0,0,0,0,0,0
0,0,0,0,0,0,0,15,0,0,0,0,0
0,0,0,0,0,0,0,0,0,0,0,0,0
0,0,0,0,0,0,0,0,0,0,0,0,0
0,0,0,0,0,0,0,0,0,0,0,0,0
0,0,0,0,0,0,0,0,0,0,0,0,0
0,0,0,0,0,0,0,0,0,0,0,0,0
0,0,0,0,0,0,0,0,0,0,0,0,0
0,0,5,8,9,8,9,0,0,0,0,0,0
0,0,8,0,0,0,0,0,0,0,0,0,0
0,0,9,0,0,0,0,0,0,0,0,0,0
0,0,8,0,0,0,0,0,0,0,0,0,0
0,0,9,0,0,0,0,0,0,0,0,0,0
0,0,8,0,0,0,0,0,0,0,0,0,0
0,0,9,0,0,0,0,0,0,0,0,0,0
0,0,8,0,0,0,0,0,0,0,8,0,0
0,0,5,8,9,8,9,8,0,8,5,0,0
0,0,0,0,0,0,0,0,0,0,0,0,0
0,0,0,0,0,0,0,0,0,0,0,0,0
endlayer

layer
0,0,0,0,0,0,0,0,0,0,0,0,0
0,0,0,0,0,0,0,0,0,0,0,0,0
0,0,0,0,0,0,0,0,0,0,0,0,0
0,0,0,0,0,0,0,0,0,0,0,0,0
0,0,0,0,0,0,0,0,0,0,0,0,0
0,0,0,0,0,0,0,0,0,0,0,0,0
0,0,0,0,0,0,0,12,0,0,0,0,0
0,0,0,0,0,0,0,0,0,0,0,0,0
0,0,0,0,0,0,0,0,0,0,0,0,0
0,0,0,0,0,0,0,0,0,0,0,0,0
0,0,0,0,0,0,0,0,0,0,0,0,0
0,0,0,0,0,0,0,0,0,0,0,0,0
0,0,0,0,0,0,0,0,0,0,0,0,0
0,0,5,8,9,8,9,0,0,0,0,0,0
0,0,8,0,0,0,0,0,0,0,0,0,0
0,0,9,0,0,0,0,0,0,0,0,0,0
0,0,8,0,0,0,0,0,0,0,0,0,0
0,0,9,0,0,0,0,0,0,0,0,0,0
0,0,8,0,0,0,0,0,0,0,0,0,0
0,0,9,0,0,0,0,0,0,0,0,0,0
0,0,8,0,0,0,0,0,0,0,8,0,0
0,0,5,8,9,8,0,8,0,8,5,0,0
0,0,0,0,0,0,0,0,0,0,0,0,0
0,0,0,0,0,0,0,0,0,0,0,0,0
endlayer

layer
0,0,0,0,0,0,0,0,0,0,0,0,0
0,0,0,0,0,0,0,0,0,0,0,0,0
0,0,0,0,0,0,0,0,0,0,0,0,0
0,0,0,0,0,0,0,0,0,0,0,0,0
0,0,0,0,0,0,0,0,0,0,0,0,0
0,0,0,0,0,0,0,0,0,0,0,0,0
0,0,0,0,0,0,0,12,0,0,0,0,0
0,0,0,0,0,0,0,0,0,0,0,0,0
0,0,0,0,0,0,0,0,0,0,0,0,0
0,0,0,0,0,0,0,0,0,0,0,0,0
0,0,0,0,0,0,0,0,0,0,0,0,0
0,0,0,0,0,0,0,0,0,0,0,0,0
0,0,0,0,0,0,0,0,0,0,0,0,0
0,0,5,5,5,5,5,5,0,0,0,0,0
0,0,5,13,13,13,13,0,0,0,0,0,0
0,0,5,13,13,0,0,0,0,0,0,0,0
0,0,5,13,13,0,0,0,0,0,0,0,0
0,0,5,13,13,13,0,0,0,0,0,0,0
0,0,5,13,13,0,0,0,0,13,5,0,0
0,0,5,13,13,13,13,13,13,13,5,0,0
0,0,5,13,13,13,13,13,13,13,5,0,0
0,0,5,5,5,5,5,5,5,5,5,0,0
0,0,0,0,0,0,0,0,0,0,0,0,0
0,0,0,0,0,0,0,0,0,0,0,0,0
endlayer

