# Converted from schematic
# THIS TEMPLATE USES DEFAULTS!  Please edit for corrections.
# If you need help, consult template_rules.txt

weight=2
embed_into_distance=5
acceptable_target_blocks=1,2,3,12,13,250
dimensions=31,27,27
allowable_overhang=0
max_cut_in=2
cut_in_buffer=1
max_leveling=2
leveling_buffer=1
preserve_water=0
preserve_lava=0
preserve_plants=0


rule1=0,100,3134-10
rule2=0,100,300
rule3=0,100,2843-4
rule4=0,100,2542-0
rule5=0,66,308
rule6=0,100,2843-6
rule7=0,75,1752,3511,3511,3511,3511
rule8=0,100,1752-15,3511,3511,3511,3511
rule9=0,100,1759,3511,3511,3511,3511
rule10=0,100,1752-9,3511,3511,3511,3511
rule11=0,100,3507
rule12=0,100,1752-11,3511,3511,3511,3511
rule13=0,33,2018-0
rule14=0,66,1757
rule15=0,100,2843-8
rule16=0,95,300
rule17=0,100,2781-5,2781-5,2781-5,2781-5,2781-9
rule18=0,100,2838-8
rule19=0,75,2788-15
rule20=0,100,3223-0
rule21=0,100,1760-0,3510,3510,3510,3510
rule22=0,100,1760-4
rule23=0,100,3508
rule24=0,100,1760-3
rule25=0,100,1760-2,3510,3510,3510,3510
rule26=0,66,1757-1
rule27=0,100,1761-0
rule28=0,100,2838-4
rule29=0,75,327
rule30=0,100,4094-10
rule31=0,100,311


layer
1,1,1,1,1,1,1,1,1,1,1,1,1,1,1,1,1,1,1,1,1,1,1,1,1,1,1
1,1,1,1,1,1,1,1,1,1,1,1,1,1,1,1,1,1,1,1,1,1,1,1,1,1,1
1,1,2,2,2,2,2,2,2,2,2,2,2,2,2,2,2,2,2,2,2,2,2,2,2,1,1
1,1,2,2,2,2,2,2,2,2,3,3,3,3,3,3,3,2,2,2,2,2,2,2,2,1,1
1,1,2,2,2,2,2,2,3,3,3,3,3,3,3,3,3,3,3,2,2,2,2,2,2,1,1
1,1,2,2,2,2,3,3,3,3,3,3,3,3,3,3,3,3,3,3,3,2,2,2,2,1,1
1,1,2,2,2,3,3,3,3,3,3,3,3,3,3,3,3,3,3,3,3,3,2,2,2,1,1
1,1,2,2,2,3,3,3,3,3,3,3,3,3,3,3,3,3,3,3,3,3,2,2,2,1,1
1,1,2,2,3,3,3,3,3,3,3,3,3,3,3,3,3,3,3,3,3,3,3,2,2,1,1
1,1,2,2,3,3,3,3,3,3,3,3,3,3,3,3,3,3,3,3,3,3,3,2,2,1,1
1,1,2,3,3,3,3,3,3,3,3,3,5,3,3,3,3,3,3,3,3,3,3,3,2,1,1
1,1,2,3,3,3,3,3,3,3,3,3,3,3,3,3,3,3,3,3,3,3,3,3,2,1,1
1,1,2,3,3,3,3,3,3,3,3,3,3,3,3,3,3,3,3,3,3,3,3,3,3,1,1
1,1,2,3,3,3,3,3,3,3,5,3,3,3,3,3,3,3,3,3,3,4,3,3,3,1,1
1,1,2,3,3,3,3,3,3,3,3,3,3,3,3,3,3,3,3,3,3,3,3,3,3,1,1
1,1,2,3,3,3,3,3,3,3,3,3,3,3,3,3,3,3,3,3,3,3,3,3,2,1,1
1,1,2,3,3,3,3,3,3,3,3,3,5,3,3,3,3,3,3,3,3,3,3,3,2,1,1
1,1,2,2,3,3,3,3,3,3,3,3,3,3,3,3,3,3,3,3,3,3,3,2,2,1,1
1,1,2,2,3,3,3,3,3,3,3,3,3,3,3,3,3,3,3,3,3,3,3,2,2,1,1
1,1,2,2,2,3,3,3,3,3,3,3,3,3,3,3,3,3,3,3,3,3,2,2,2,1,1
1,1,2,2,2,3,3,3,3,3,3,3,3,3,3,3,3,3,3,3,3,3,2,2,2,1,1
1,1,2,2,2,2,3,3,3,3,3,3,3,3,3,3,3,3,3,3,3,2,2,2,2,1,1
1,1,2,2,2,2,2,2,3,3,3,3,3,3,3,3,3,3,3,2,2,2,2,2,2,1,1
1,1,2,2,2,2,2,2,2,2,3,3,3,3,3,3,3,2,2,2,2,2,2,2,2,1,1
1,1,2,2,2,2,2,2,2,2,2,2,2,2,2,2,2,2,2,2,2,2,2,2,2,1,1
1,1,1,1,1,1,1,1,1,1,1,1,1,1,1,1,1,1,1,1,1,1,1,1,1,1,1
1,1,1,1,1,1,1,1,1,1,1,1,1,1,1,1,1,1,1,1,1,1,1,1,1,1,1
endlayer

layer
2,2,2,2,2,2,2,2,2,2,2,2,2,2,2,2,2,2,2,2,2,2,2,2,2,2,2
2,2,2,2,2,2,2,2,2,2,2,2,2,2,2,2,2,2,2,2,2,2,2,2,2,2,2
2,2,2,2,2,2,2,2,2,2,6,6,6,6,6,6,6,2,2,2,2,2,2,2,2,2,2
2,2,2,2,2,2,2,2,6,6,0,0,0,0,0,0,0,6,6,2,2,2,2,2,2,2,2
2,2,2,2,2,2,6,6,0,0,0,0,0,0,0,0,0,0,0,6,6,2,2,2,2,2,2
2,2,2,2,2,6,6,0,0,0,0,0,0,0,0,0,0,0,0,0,6,6,2,2,2,2,2
2,2,2,2,6,6,0,0,0,0,0,0,0,0,0,0,0,0,0,0,0,6,6,2,2,2,2
2,2,2,2,6,0,0,0,0,0,0,0,0,0,0,0,0,0,0,0,0,0,6,2,2,2,2
2,2,2,6,0,0,0,0,0,0,0,0,0,0,0,0,0,0,0,0,0,0,0,6,2,2,2
2,2,2,6,0,0,0,0,0,0,0,0,0,0,0,0,0,0,0,0,2,0,2,6,2,2,2
2,2,6,0,0,0,0,0,0,0,7,7,7,7,7,7,7,0,0,2,2,2,2,2,6,2,2
2,2,6,0,0,0,0,0,0,0,7,7,7,7,7,7,7,0,0,0,2,2,2,2,6,2,2
2,2,6,0,0,0,0,0,0,0,7,7,7,7,7,7,7,0,0,0,0,2,2,2,2,2,2
2,2,6,0,0,0,0,0,0,0,7,7,7,7,7,7,7,0,0,0,0,2,2,2,2,2,2
2,2,6,0,0,0,0,0,0,0,7,7,7,7,7,7,7,0,0,0,0,2,2,2,2,2,2
2,2,6,0,0,0,0,0,0,0,7,7,7,7,7,0,0,0,0,0,0,0,2,2,6,2,2
2,2,6,0,0,0,0,0,0,0,7,7,7,7,7,7,0,0,0,0,0,0,0,2,6,2,2
2,2,2,6,0,0,0,0,0,0,0,0,0,31,0,0,0,0,0,0,0,0,0,6,2,2,2
2,2,2,6,0,0,0,0,0,0,0,0,0,0,0,0,0,0,0,0,0,0,0,6,2,2,2
2,2,2,2,6,0,0,0,0,0,0,0,0,0,0,0,0,0,0,0,0,0,6,2,2,2,2
2,2,2,2,6,6,0,0,0,0,0,0,0,0,0,0,0,0,0,0,0,6,6,2,2,2,2
2,2,2,2,2,6,6,0,0,0,0,0,0,0,0,0,0,0,0,0,6,6,2,2,2,2,2
2,2,2,2,2,2,6,6,0,0,0,0,0,0,0,0,0,0,0,6,6,2,2,2,2,2,2
2,2,2,2,2,2,2,2,6,6,0,0,0,0,0,0,0,6,6,2,2,2,2,2,2,2,2
2,2,2,2,2,2,2,2,2,2,6,6,6,6,6,6,6,2,2,2,2,2,2,2,2,2,2
2,2,2,2,2,2,2,2,2,2,2,2,2,2,2,2,2,2,2,2,2,2,2,2,2,2,2
2,2,2,2,2,2,2,2,2,2,2,2,2,2,2,2,2,2,2,2,2,2,2,2,2,2,2
endlayer

layer
2,2,2,2,2,2,2,2,2,2,2,2,2,2,2,2,2,2,2,2,2,2,2,2,2,2,2
2,2,2,2,2,2,2,2,2,2,2,2,2,2,2,2,2,2,2,2,2,2,2,2,2,2,2
2,2,2,2,2,2,2,2,2,2,6,6,6,6,6,6,6,2,2,2,2,2,2,2,2,2,2
2,2,2,2,2,2,2,2,6,6,0,0,0,0,0,0,0,6,6,2,2,2,2,2,2,2,2
2,2,2,2,2,2,6,6,0,0,0,0,0,0,0,0,0,0,0,6,6,2,2,2,2,2,2
2,2,2,2,2,6,6,0,0,0,0,0,0,0,0,0,0,0,0,0,6,6,2,2,2,2,2
2,2,2,2,6,6,0,0,0,0,0,0,0,0,0,0,0,0,0,0,0,6,6,2,2,2,2
2,2,2,2,6,0,0,0,0,0,0,0,0,0,0,0,0,0,0,0,0,0,6,2,2,2,2
2,2,2,6,0,0,0,0,0,0,0,0,0,0,0,0,0,0,0,0,0,0,0,6,2,2,2
2,2,2,6,0,0,0,0,0,0,0,0,0,0,0,0,0,0,0,0,0,0,0,6,2,2,2
2,2,6,0,0,0,0,0,0,0,7,14,14,14,12,12,7,0,0,0,0,0,0,2,6,2,2
2,2,6,0,0,0,0,0,0,0,14,13,13,13,13,13,8,0,0,0,0,0,0,2,6,2,2
2,2,6,0,0,0,0,0,0,0,14,13,13,13,13,13,9,0,0,0,0,0,0,2,2,2,2
2,2,6,0,0,0,0,0,0,0,14,13,13,13,13,13,7,0,0,0,0,0,2,2,2,2,2
2,2,6,0,0,0,0,0,0,0,14,13,13,13,13,13,10,0,0,0,0,0,0,2,2,2,2
2,2,6,0,0,0,0,0,0,0,14,13,13,13,13,0,11,0,0,0,0,0,0,0,6,2,2
2,2,6,0,0,0,0,0,0,0,7,14,14,14,14,14,7,0,0,0,0,0,0,0,6,2,2
2,2,2,6,0,0,0,0,0,0,0,0,0,0,0,0,0,0,0,0,0,0,0,6,2,2,2
2,2,2,6,0,0,0,0,0,0,0,0,0,0,0,0,0,0,0,0,0,0,0,6,2,2,2
2,2,2,2,6,0,0,0,0,0,0,0,0,0,0,0,0,0,0,0,0,0,6,2,2,2,2
2,2,2,2,6,6,0,0,0,0,0,0,0,0,0,0,0,0,0,0,0,6,6,2,2,2,2
2,2,2,2,2,6,6,0,0,0,0,0,0,0,0,0,0,0,0,0,6,6,2,2,2,2,2
2,2,2,2,2,2,6,6,0,0,0,0,0,0,0,0,0,0,0,6,6,2,2,2,2,2,2
2,2,2,2,2,2,2,2,6,6,0,0,0,0,0,0,0,6,6,2,2,2,2,2,2,2,2
2,2,2,2,2,2,2,2,2,2,6,6,6,6,6,6,6,2,2,2,2,2,2,2,2,2,2
2,2,2,2,2,2,2,2,2,2,2,2,2,2,2,2,2,2,2,2,2,2,2,2,2,2,2
2,2,2,2,2,2,2,2,2,2,2,2,2,2,2,2,2,2,2,2,2,2,2,2,2,2,2
endlayer

layer
2,2,2,2,2,2,2,2,2,2,2,2,2,2,2,2,2,2,2,2,2,2,2,2,2,2,2
2,2,2,2,2,2,2,2,2,2,2,2,2,2,2,2,2,2,2,2,2,2,2,2,2,2,2
2,2,2,2,2,2,2,2,2,2,2,2,2,2,2,2,2,2,2,2,2,2,2,2,2,2,2
2,2,2,2,2,2,2,2,2,2,15,15,15,15,15,15,15,2,2,2,2,2,2,2,2,2,2
2,2,2,2,2,2,2,2,15,15,0,0,0,0,0,0,0,15,15,2,2,2,2,2,2,2,2
2,2,2,2,2,2,2,15,0,0,0,0,0,0,0,0,0,0,0,15,2,2,2,2,2,2,2
2,2,2,2,2,2,15,0,0,0,0,0,0,0,0,0,0,0,0,0,15,2,2,2,2,2,2
2,2,2,2,2,15,0,0,0,0,0,0,0,0,0,0,0,0,0,0,0,15,2,2,2,2,2
2,2,2,2,15,0,0,0,0,0,0,0,0,0,0,0,0,0,0,0,0,0,15,2,2,2,2
2,2,2,2,15,0,0,0,0,0,0,0,0,0,0,0,0,0,0,0,0,0,15,2,2,2,2
2,2,2,15,0,0,0,0,0,0,7,14,14,14,14,14,7,0,0,0,0,0,0,15,2,2,2
2,2,2,15,0,0,0,0,0,0,14,0,0,0,0,0,14,0,0,0,0,0,0,15,2,2,2
2,2,2,15,0,0,0,0,0,0,14,0,0,0,0,0,14,0,0,0,0,0,0,2,2,2,2
2,2,2,15,0,0,0,0,0,0,14,0,0,0,0,0,14,0,0,0,0,0,0,2,2,2,2
2,2,2,15,0,0,0,0,0,0,14,0,0,0,0,0,14,0,0,0,0,0,0,2,2,2,2
2,2,2,15,0,0,0,0,0,0,14,0,0,0,0,0,14,0,0,0,0,0,0,15,2,2,2
2,2,2,15,0,0,0,0,0,0,7,14,14,14,14,14,7,0,0,0,0,0,0,15,2,2,2
2,2,2,2,15,0,0,0,0,0,0,0,0,0,0,0,0,0,0,0,0,0,15,2,2,2,2
2,2,2,2,15,0,0,0,0,0,0,0,0,0,0,0,0,0,0,0,0,0,15,2,2,2,2
2,2,2,2,2,15,0,0,0,0,0,0,0,0,0,0,0,0,0,0,0,15,2,2,2,2,2
2,2,2,2,2,2,15,0,0,0,0,0,0,0,0,0,0,0,0,0,15,2,2,2,2,2,2
2,2,2,2,2,2,2,15,0,0,0,0,0,0,0,0,0,0,0,15,2,2,2,2,2,2,2
2,2,2,2,2,2,2,2,15,15,0,0,0,0,0,0,0,15,15,2,2,2,2,2,2,2,2
2,2,2,2,2,2,2,2,2,2,15,15,15,15,15,15,15,2,2,2,2,2,2,2,2,2,2
2,2,2,2,2,2,2,2,2,2,2,2,2,2,2,2,2,2,2,2,2,2,2,2,2,2,2
2,2,2,2,2,2,2,2,2,2,2,2,2,2,2,2,2,2,2,2,2,2,2,2,2,2,2
2,2,2,2,2,2,2,2,2,2,2,2,2,2,2,2,2,2,2,2,2,2,2,2,2,2,2
endlayer

layer
16,16,16,16,16,16,16,16,16,16,16,16,16,16,16,16,16,16,16,16,16,16,16,16,16,16,16
16,16,16,16,16,16,16,16,16,16,16,16,16,16,16,16,16,16,16,16,16,16,16,16,16,16,16
16,16,16,16,16,16,16,16,16,16,16,16,16,16,16,16,16,16,16,16,16,16,16,16,16,16,16
16,16,16,16,16,16,16,16,16,16,15,15,15,15,15,15,15,16,16,16,16,16,16,16,16,16,16
16,16,16,16,16,16,16,16,15,15,0,0,0,0,0,0,0,15,15,16,16,16,16,16,16,16,16
16,16,16,16,16,16,16,15,0,0,0,0,0,0,0,0,0,0,0,15,16,16,16,16,16,16,16
16,16,16,16,16,16,15,0,0,0,0,0,0,0,0,0,0,0,0,0,15,16,16,16,16,16,16
16,16,16,16,16,15,0,0,0,0,0,0,0,0,0,0,0,0,0,0,0,15,16,16,16,16,16
16,16,16,16,15,0,0,0,0,0,0,0,0,0,0,0,0,0,0,0,0,0,15,16,16,16,16
16,16,16,16,15,0,0,0,0,0,0,0,0,0,0,0,0,0,0,0,0,0,15,16,16,16,16
16,16,16,15,0,0,0,0,0,0,7,14,14,14,14,14,7,0,0,0,0,0,0,15,16,16,16
16,16,16,15,0,0,0,0,0,0,14,0,0,0,0,0,14,0,0,0,0,0,0,15,16,16,16
16,16,16,15,0,0,0,0,0,0,14,0,0,0,0,0,14,0,0,0,0,0,0,15,16,16,16
16,16,16,15,0,0,0,0,0,0,14,0,0,0,0,0,14,0,0,0,0,0,0,0,0,16,16
16,16,16,15,0,0,0,0,0,0,14,0,0,0,0,0,14,0,0,0,0,0,0,15,16,16,16
16,16,16,15,0,0,0,0,0,0,14,0,0,0,0,0,14,0,0,0,0,0,0,15,16,16,16
16,16,16,15,0,0,0,0,0,0,7,14,14,14,14,14,7,0,0,0,0,0,0,15,16,16,16
16,16,16,16,15,0,0,0,0,0,0,0,0,0,0,0,0,0,0,0,0,0,15,16,16,16,16
16,16,16,16,15,0,0,0,0,0,0,0,0,0,0,0,0,0,0,0,0,0,15,16,16,16,16
16,16,16,16,16,15,0,0,0,0,0,0,0,0,0,0,0,0,0,0,0,15,16,16,16,16,16
16,16,16,16,16,16,15,0,0,0,0,0,0,0,0,0,0,0,0,0,15,16,16,16,16,16,16
16,16,16,16,16,16,16,15,0,0,0,0,0,0,0,0,0,0,0,15,16,16,16,16,16,16,16
16,16,16,16,16,16,16,16,15,15,0,0,0,0,0,0,0,15,15,16,16,16,16,16,16,16,16
16,16,16,16,16,16,16,16,16,16,15,15,15,15,15,15,15,16,16,16,16,16,16,16,16,16,16
16,16,16,16,16,16,16,16,16,16,16,16,16,16,16,16,16,16,16,16,16,16,16,16,16,16,16
16,16,16,16,16,16,16,16,16,16,16,16,16,16,16,16,16,16,16,16,16,16,16,16,16,16,16
16,16,16,16,16,16,16,16,16,16,16,16,16,16,16,16,16,16,16,16,16,16,16,16,16,16,16
endlayer

layer
0,0,0,0,0,0,0,0,0,0,0,0,0,0,0,0,0,0,0,0,0,0,0,0,0,0,0
0,0,0,0,0,0,0,0,0,0,0,0,0,0,0,0,0,0,0,0,0,0,0,0,0,0,0
0,0,0,0,0,0,0,0,0,0,0,0,0,0,0,0,0,0,0,0,0,0,0,0,0,0,0
0,0,0,0,0,0,0,0,0,0,15,15,15,15,15,15,15,0,0,0,0,0,0,0,0,0,0
0,0,0,0,0,0,0,0,15,15,0,0,0,0,0,0,0,15,15,0,0,0,0,0,0,0,0
0,0,0,0,0,0,0,15,0,0,0,0,0,0,0,0,0,0,0,15,0,0,0,0,0,0,0
0,0,0,0,0,0,15,0,0,0,0,0,0,0,0,0,0,0,0,0,15,0,0,0,0,0,0
0,0,0,0,0,15,0,0,0,0,0,0,0,0,0,0,0,0,0,0,0,15,0,0,0,0,0
0,0,0,0,15,0,0,0,0,0,0,0,0,0,0,0,0,0,0,0,0,0,15,0,0,0,0
0,0,0,0,15,0,0,0,0,0,0,0,0,0,0,0,0,0,0,0,0,0,15,0,0,0,0
0,0,0,15,0,0,0,0,0,0,7,14,14,14,14,14,7,0,0,0,0,0,0,15,0,0,0
0,0,0,15,0,0,0,0,0,0,14,0,0,0,0,0,14,0,0,0,0,0,0,15,0,0,0
0,0,0,15,0,0,0,0,0,0,14,0,0,0,0,0,14,0,0,0,0,0,0,15,0,0,0
0,0,0,15,0,0,0,0,0,0,14,0,0,0,0,0,14,0,0,0,0,0,0,15,0,0,0
0,0,0,15,0,0,0,0,0,0,14,0,0,0,0,0,14,0,0,0,0,0,0,15,0,0,0
0,0,0,15,0,0,0,0,0,0,14,0,0,0,0,0,14,0,0,0,0,0,0,15,0,0,0
0,0,0,15,0,0,0,0,0,0,7,14,14,14,14,14,7,0,0,0,0,0,0,15,0,0,0
0,0,0,0,15,0,0,0,0,0,0,0,0,0,0,0,0,0,0,0,0,0,15,0,0,0,0
0,0,0,0,15,0,0,0,0,0,0,0,0,0,0,0,0,0,0,0,0,0,15,0,0,0,0
0,0,0,0,0,15,0,0,0,0,0,0,0,0,0,0,0,0,0,0,0,15,0,0,0,0,0
0,0,0,0,0,0,15,0,0,0,0,0,0,0,0,0,0,0,0,0,15,0,0,0,0,0,0
0,0,0,0,0,0,0,15,0,0,0,0,0,0,0,0,0,0,0,15,0,0,0,0,0,0,0
0,0,0,0,0,0,0,0,15,15,0,0,0,0,0,0,0,15,15,0,0,0,0,0,0,0,0
0,0,0,0,0,0,0,0,0,0,15,15,15,15,15,15,15,0,0,0,0,0,0,0,0,0,0
0,0,0,0,0,0,0,0,0,0,0,0,0,0,0,0,0,0,0,0,0,0,0,0,0,0,0
0,0,0,0,0,0,0,0,0,0,0,0,0,0,0,0,0,0,0,0,0,0,0,0,0,0,0
0,0,0,0,0,0,0,0,0,0,0,0,0,0,0,0,0,0,0,0,0,0,0,0,0,0,0
endlayer

layer
0,0,0,0,0,0,0,0,0,0,0,0,0,0,0,0,0,0,0,0,0,0,0,0,0,0,0
0,0,0,0,0,0,0,0,0,0,0,0,0,0,0,0,0,0,0,0,0,0,0,0,0,0,0
0,0,0,0,0,0,0,0,0,0,0,0,0,0,0,0,0,0,0,0,0,0,0,0,0,0,0
0,0,0,0,0,0,0,0,0,0,0,0,0,0,0,0,0,0,0,0,0,0,0,0,0,0,0
0,0,0,0,0,0,0,0,0,0,17,17,17,17,17,17,17,0,0,0,0,0,0,0,0,0,0
0,0,0,0,0,0,0,0,17,17,0,0,0,0,0,0,0,17,17,0,0,0,0,0,0,0,0
0,0,0,0,0,0,0,17,0,0,0,0,0,0,0,0,0,0,0,17,0,0,0,0,0,0,0
0,0,0,0,0,0,17,0,0,0,0,0,0,0,0,0,0,0,0,0,17,0,0,0,0,0,0
0,0,0,0,0,17,0,0,0,0,0,0,0,0,0,0,0,0,0,0,0,17,0,0,0,0,0
0,0,0,0,0,17,0,0,0,0,0,0,0,0,0,0,0,0,0,0,0,17,0,0,0,0,0
0,0,0,0,17,0,0,0,0,0,7,14,14,14,14,14,7,0,0,0,0,0,17,0,0,0,0
0,0,0,0,17,0,0,0,0,0,14,0,0,0,0,0,14,0,0,0,0,0,17,0,0,0,0
0,0,0,0,17,0,0,0,0,0,14,0,0,0,0,0,14,0,0,0,0,0,17,0,0,0,0
0,0,0,0,17,0,0,0,0,0,14,0,0,0,0,0,14,0,0,0,0,0,17,0,0,0,0
0,0,0,0,17,0,0,0,0,0,14,0,0,0,0,0,14,0,0,0,0,0,17,0,0,0,0
0,0,0,0,17,0,0,0,0,0,14,0,0,0,0,0,14,0,0,0,0,0,17,0,0,0,0
0,0,0,0,17,0,0,0,0,0,7,14,14,14,14,14,7,0,0,0,0,0,17,0,0,0,0
0,0,0,0,0,17,0,0,0,0,0,0,0,0,0,0,0,0,0,0,0,17,0,0,0,0,0
0,0,0,0,0,17,0,0,0,0,0,0,0,0,0,0,0,0,0,0,0,17,0,0,0,0,0
0,0,0,0,0,0,17,0,0,0,0,0,0,0,0,0,0,0,0,0,17,0,0,0,0,0,0
0,0,0,0,0,0,0,17,0,0,0,0,0,0,0,0,0,0,0,17,0,0,0,0,0,0,0
0,0,0,0,0,0,0,0,17,17,0,0,0,0,0,0,0,17,17,0,0,0,0,0,0,0,0
0,0,0,0,0,0,0,0,0,0,17,17,17,17,17,17,17,0,0,0,0,0,0,0,0,0,0
0,0,0,0,0,0,0,0,0,0,0,0,0,0,0,0,0,0,0,0,0,0,0,0,0,0,0
0,0,0,0,0,0,0,0,0,0,0,0,0,0,0,0,0,0,0,0,0,0,0,0,0,0,0
0,0,0,0,0,0,0,0,0,0,0,0,0,0,0,0,0,0,0,0,0,0,0,0,0,0,0
0,0,0,0,0,0,0,0,0,0,0,0,0,0,0,0,0,0,0,0,0,0,0,0,0,0,0
endlayer

layer
0,0,0,0,0,0,0,0,0,0,0,0,0,0,0,0,0,0,0,0,0,0,0,0,0,0,0
0,0,0,0,0,0,0,0,0,0,0,0,0,0,0,0,0,0,0,0,0,0,0,0,0,0,0
0,0,0,0,0,0,0,0,0,0,0,0,0,0,0,0,0,0,0,0,0,0,0,0,0,0,0
0,0,0,0,0,0,0,0,0,0,0,0,0,0,0,0,0,0,0,0,0,0,0,0,0,0,0
0,0,0,0,0,0,0,0,0,0,17,17,17,17,17,17,17,0,0,0,0,0,0,0,0,0,0
0,0,0,0,0,0,0,0,17,17,0,0,0,0,0,0,0,17,17,0,0,0,0,0,0,0,0
0,0,0,0,0,0,0,17,0,0,0,0,0,0,0,0,0,0,0,17,0,0,0,0,0,0,0
0,0,0,0,0,0,17,0,0,0,0,0,0,0,0,0,0,0,0,0,17,0,0,0,0,0,0
0,0,0,0,0,17,0,0,0,0,0,0,0,0,0,0,0,0,0,0,0,17,0,0,0,0,0
0,0,0,0,0,17,0,0,0,0,0,0,0,0,0,0,0,0,0,0,0,17,0,0,0,0,0
0,0,0,0,17,0,0,0,0,0,7,7,7,7,7,7,7,0,0,0,0,0,17,0,0,0,0
0,0,0,0,17,0,0,0,0,0,7,14,14,14,14,14,7,0,0,0,0,0,17,0,0,0,0
0,0,0,0,17,0,0,0,0,0,7,14,14,14,14,14,7,0,0,0,0,0,17,0,0,0,0
0,0,0,0,17,0,0,0,0,0,7,14,14,14,14,14,7,0,0,0,0,0,17,0,0,0,0
0,0,0,0,17,0,0,0,0,0,7,14,14,14,14,14,7,0,0,0,0,0,17,0,0,0,0
0,0,0,0,17,0,0,0,0,0,7,14,14,14,14,14,7,0,0,0,0,0,17,0,0,0,0
0,0,0,0,17,0,0,0,0,0,7,7,7,7,7,7,7,0,0,0,0,0,17,0,0,0,0
0,0,0,0,0,17,0,0,0,0,0,0,0,0,0,0,0,0,0,0,0,17,0,0,0,0,0
0,0,0,0,0,17,0,0,0,0,0,0,0,0,0,0,0,0,0,0,0,17,0,0,0,0,0
0,0,0,0,0,0,17,0,0,0,0,0,0,0,0,0,0,0,0,0,17,0,0,0,0,0,0
0,0,0,0,0,0,0,17,0,0,0,0,0,0,0,0,0,0,0,17,0,0,0,0,0,0,0
0,0,0,0,0,0,0,0,17,17,0,0,0,0,0,0,0,17,17,0,0,0,0,0,0,0,0
0,0,0,0,0,0,0,0,0,0,17,17,17,17,17,17,17,0,0,0,0,0,0,0,0,0,0
0,0,0,0,0,0,0,0,0,0,0,0,0,0,0,0,0,0,0,0,0,0,0,0,0,0,0
0,0,0,0,0,0,0,0,0,0,0,0,0,0,0,0,0,0,0,0,0,0,0,0,0,0,0
0,0,0,0,0,0,0,0,0,0,0,0,0,0,0,0,0,0,0,0,0,0,0,0,0,0,0
0,0,0,0,0,0,0,0,0,0,0,0,0,0,0,0,0,0,0,0,0,0,0,0,0,0,0
endlayer

layer
0,0,0,0,0,0,0,0,0,0,0,0,0,0,0,0,0,0,0,0,0,0,0,0,0,0,0
0,0,0,0,0,0,0,0,0,0,0,0,0,0,0,0,0,0,0,0,0,0,0,0,0,0,0
0,0,0,0,0,0,0,0,0,0,0,0,0,0,0,0,0,0,0,0,0,0,0,0,0,0,0
0,0,0,0,0,0,0,0,0,0,0,0,0,0,0,0,0,0,0,0,0,0,0,0,0,0,0
0,0,0,0,0,0,0,0,0,0,17,17,17,17,17,17,17,0,0,0,0,0,0,0,0,0,0
0,0,0,0,0,0,0,0,17,17,0,0,0,0,0,0,0,17,17,0,0,0,0,0,0,0,0
0,0,0,0,0,0,0,17,0,0,0,0,0,0,0,0,0,0,0,17,0,0,0,0,0,0,0
0,0,0,0,0,0,17,0,0,0,0,0,0,0,0,0,0,0,0,0,17,0,0,0,0,0,0
0,0,0,0,0,17,0,0,0,0,0,0,0,0,0,0,0,0,0,0,0,17,0,0,0,0,0
0,0,0,0,0,17,0,0,0,0,0,0,0,0,0,0,0,0,0,0,0,17,0,0,0,0,0
0,0,0,0,17,0,0,0,0,0,0,0,0,0,0,0,0,0,0,0,0,0,17,0,0,0,0
0,0,0,0,17,0,0,0,0,0,0,0,0,0,0,0,0,0,0,0,0,0,17,0,0,0,0
0,0,0,0,17,0,0,0,0,0,0,0,0,0,0,0,0,0,0,0,0,0,17,0,0,0,0
0,0,0,0,17,0,0,0,0,0,0,0,0,0,0,0,0,0,0,0,0,0,17,0,0,0,0
0,0,0,0,17,0,0,0,0,0,0,0,0,0,0,0,0,0,0,0,0,0,17,0,0,0,0
0,0,0,0,17,0,0,0,0,0,0,0,0,0,0,0,0,0,0,0,0,0,17,0,0,0,0
0,0,0,0,17,0,0,0,0,0,0,0,0,0,0,0,0,0,0,0,0,0,17,0,0,0,0
0,0,0,0,0,17,0,0,0,0,0,0,0,0,0,0,0,0,0,0,0,17,0,0,0,0,0
0,0,0,0,0,17,0,0,0,0,0,0,0,0,0,0,0,0,0,0,0,17,0,0,0,0,0
0,0,0,0,0,0,17,0,0,0,0,0,0,0,0,0,0,0,0,0,17,0,0,0,0,0,0
0,0,0,0,0,0,0,17,0,0,0,0,0,0,0,0,0,0,0,17,0,0,0,0,0,0,0
0,0,0,0,0,0,0,0,17,17,0,0,0,0,0,0,0,17,17,0,0,0,0,0,0,0,0
0,0,0,0,0,0,0,0,0,0,17,17,17,17,17,17,17,0,0,0,0,0,0,0,0,0,0
0,0,0,0,0,0,0,0,0,0,0,0,0,0,0,0,0,0,0,0,0,0,0,0,0,0,0
0,0,0,0,0,0,0,0,0,0,0,0,0,0,0,0,0,0,0,0,0,0,0,0,0,0,0
0,0,0,0,0,0,0,0,0,0,0,0,0,0,0,0,0,0,0,0,0,0,0,0,0,0,0
0,0,0,0,0,0,0,0,0,0,0,0,0,0,0,0,0,0,0,0,0,0,0,0,0,0,0
endlayer

layer
0,0,0,0,0,0,0,0,0,0,0,0,0,0,0,0,0,0,0,0,0,0,0,0,0,0,0
0,0,0,0,0,0,0,0,0,0,0,0,0,0,0,0,0,0,0,0,0,0,0,0,0,0,0
0,0,0,0,0,0,0,0,0,0,0,0,0,0,0,0,0,0,0,0,0,0,0,0,0,0,0
0,0,0,0,0,0,0,0,0,0,0,0,0,0,0,0,0,0,0,0,0,0,0,0,0,0,0
0,0,0,0,0,0,0,0,0,0,17,17,17,17,17,17,17,0,0,0,0,0,0,0,0,0,0
0,0,0,0,0,0,0,0,17,17,0,0,0,0,0,0,0,17,17,0,0,0,0,0,0,0,0
0,0,0,0,0,0,0,17,0,0,0,0,0,0,0,0,0,0,0,17,0,0,0,0,0,0,0
0,0,0,0,0,0,17,0,0,0,0,0,0,0,0,0,0,0,0,0,17,0,0,0,0,0,0
0,0,0,0,0,17,0,0,0,0,0,0,0,0,0,0,0,0,0,0,0,17,0,0,0,0,0
0,0,0,0,0,17,0,0,0,0,0,0,0,0,0,0,0,0,0,0,0,17,0,0,0,0,0
0,0,0,0,17,0,0,0,0,0,0,0,0,0,0,0,0,0,0,0,0,0,17,0,0,0,0
0,0,0,0,17,0,0,0,0,0,0,0,0,0,0,0,0,0,0,0,0,0,17,0,0,0,0
0,0,0,0,17,0,0,0,0,0,0,0,0,0,0,0,0,0,0,0,0,0,17,0,0,0,0
0,0,0,0,17,0,0,0,0,0,0,0,0,0,0,0,0,0,0,0,0,0,17,0,0,0,0
0,0,0,0,17,0,0,0,0,0,0,0,0,0,0,0,0,0,0,0,0,0,17,0,0,0,0
0,0,0,0,17,0,0,0,0,0,0,0,0,0,0,0,0,0,0,0,0,0,17,0,0,0,0
0,0,0,0,17,0,0,0,0,0,0,0,0,0,0,0,0,0,0,0,0,0,17,0,0,0,0
0,0,0,0,0,17,0,0,0,0,0,0,0,0,0,0,0,0,0,0,0,17,0,0,0,0,0
0,0,0,0,0,17,0,0,0,0,0,0,0,0,0,0,0,0,0,0,0,17,0,0,0,0,0
0,0,0,0,0,0,17,0,0,0,0,0,0,0,0,0,0,0,0,0,17,0,0,0,0,0,0
0,0,0,0,0,0,0,17,0,0,0,0,0,0,0,0,0,0,0,17,0,0,0,0,0,0,0
0,0,0,0,0,0,0,0,17,17,0,0,0,0,0,0,0,17,17,0,0,0,0,0,0,0,0
0,0,0,0,0,0,0,0,0,0,17,17,17,17,17,17,17,0,0,0,0,0,0,0,0,0,0
0,0,0,0,0,0,0,0,0,0,0,0,0,0,0,0,0,0,0,0,0,0,0,0,0,0,0
0,0,0,0,0,0,0,0,0,0,0,0,0,0,0,0,0,0,0,0,0,0,0,0,0,0,0
0,0,0,0,0,0,0,0,0,0,0,0,0,0,0,0,0,0,0,0,0,0,0,0,0,0,0
0,0,0,0,0,0,0,0,0,0,0,0,0,0,0,0,0,0,0,0,0,0,0,0,0,0,0
endlayer

layer
0,0,0,0,0,0,0,0,0,0,0,0,0,0,0,0,0,0,0,0,0,0,0,0,0,0,0
0,0,0,0,0,0,0,0,0,0,0,0,0,0,0,0,0,0,0,0,0,0,0,0,0,0,0
0,0,0,0,0,0,0,0,0,0,0,0,0,0,0,0,0,0,0,0,0,0,0,0,0,0,0
0,0,0,0,0,0,0,0,0,0,0,0,0,0,0,0,0,0,0,0,0,0,0,0,0,0,0
0,0,0,0,0,0,0,0,0,0,17,17,17,17,17,17,17,0,0,0,0,0,0,0,0,0,0
0,0,0,0,0,0,0,0,17,17,0,0,0,0,0,0,0,17,17,0,0,0,0,0,0,0,0
0,0,0,0,0,0,0,17,0,0,0,0,0,0,0,0,0,0,0,17,0,0,0,0,0,0,0
0,0,0,0,0,0,17,0,0,0,0,0,0,0,0,0,0,0,0,0,17,0,0,0,0,0,0
0,0,0,0,0,17,0,0,0,0,0,0,0,0,0,0,0,0,0,0,0,17,0,0,0,0,0
0,0,0,0,0,17,0,0,0,0,0,0,0,0,0,0,0,0,0,0,0,17,0,0,0,0,0
0,0,0,0,17,0,0,0,0,0,0,0,0,0,0,0,0,0,0,0,0,0,17,0,0,0,0
0,0,0,0,17,0,0,0,0,0,0,0,0,0,0,0,0,0,0,0,0,0,17,0,0,0,0
0,0,0,0,17,0,0,0,0,0,0,0,0,0,0,0,0,0,0,0,0,0,17,0,0,0,0
0,0,0,0,17,0,0,0,0,0,0,0,0,0,0,0,0,0,0,0,0,0,17,0,0,0,0
0,0,0,0,17,0,0,0,0,0,0,0,0,0,0,0,0,0,0,0,0,0,17,0,0,0,0
0,0,0,0,17,0,0,0,0,0,0,0,0,0,0,0,0,0,0,0,0,0,17,0,0,0,0
0,0,0,0,17,0,0,0,0,0,0,0,0,0,0,0,0,0,0,0,0,0,17,0,0,0,0
0,0,0,0,0,17,0,0,0,0,0,0,0,0,0,0,0,0,0,0,0,17,0,0,0,0,0
0,0,0,0,0,17,0,0,0,0,0,0,0,0,0,0,0,0,0,0,0,17,0,0,0,0,0
0,0,0,0,0,0,17,0,0,0,0,0,0,0,0,0,0,0,0,0,17,0,0,0,0,0,0
0,0,0,0,0,0,0,17,0,0,0,0,0,0,0,0,0,0,0,17,0,0,0,0,0,0,0
0,0,0,0,0,0,0,0,17,17,0,0,0,0,0,0,0,17,17,0,0,0,0,0,0,0,0
0,0,0,0,0,0,0,0,0,0,17,17,17,17,17,17,17,0,0,0,0,0,0,0,0,0,0
0,0,0,0,0,0,0,0,0,0,0,0,0,0,0,0,0,0,0,0,0,0,0,0,0,0,0
0,0,0,0,0,0,0,0,0,0,0,0,0,0,0,0,0,0,0,0,0,0,0,0,0,0,0
0,0,0,0,0,0,0,0,0,0,0,0,0,0,0,0,0,0,0,0,0,0,0,0,0,0,0
0,0,0,0,0,0,0,0,0,0,0,0,0,0,0,0,0,0,0,0,0,0,0,0,0,0,0
endlayer

layer
0,0,0,0,0,0,0,0,0,0,0,0,0,0,0,0,0,0,0,0,0,0,0,0,0,0,0
0,0,0,0,0,0,0,0,0,0,0,0,0,0,0,0,0,0,0,0,0,0,0,0,0,0,0
0,0,0,0,0,0,0,0,0,0,0,0,0,0,0,0,0,0,0,0,0,0,0,0,0,0,0
0,0,0,0,0,0,0,0,0,0,0,0,0,0,0,0,0,0,0,0,0,0,0,0,0,0,0
0,0,0,0,0,0,0,0,0,0,17,17,17,17,17,17,17,0,0,0,0,0,0,0,0,0,0
0,0,0,0,0,0,0,0,17,17,0,0,0,0,0,0,0,17,17,0,0,0,0,0,0,0,0
0,0,0,0,0,0,0,17,0,0,0,0,0,0,0,0,0,0,0,17,0,0,0,0,0,0,0
0,0,0,0,0,0,17,0,0,0,0,0,0,0,0,0,0,0,0,0,17,0,0,0,0,0,0
0,0,0,0,0,17,0,0,0,0,0,0,0,0,0,0,0,0,0,0,0,17,0,0,0,0,0
0,0,0,0,0,17,0,0,0,0,0,0,0,0,0,0,0,0,0,0,0,17,0,0,0,0,0
0,0,0,0,17,0,0,0,0,0,0,0,0,0,0,0,0,0,0,0,0,0,17,0,0,0,0
0,0,0,0,17,0,0,0,0,0,0,0,0,0,0,0,0,0,0,0,0,0,17,0,0,0,0
0,0,0,0,17,0,0,0,0,0,0,0,0,0,0,0,0,0,0,0,0,0,17,0,0,0,0
0,0,0,0,17,0,0,0,0,0,0,0,0,0,0,0,0,0,0,0,0,0,17,0,0,0,0
0,0,0,0,17,0,0,0,0,0,0,0,0,0,0,0,0,0,0,0,0,0,17,0,0,0,0
0,0,0,0,17,0,0,0,0,0,0,0,0,0,0,0,0,0,0,0,0,0,17,0,0,0,0
0,0,0,0,17,0,0,0,0,0,0,0,0,0,0,0,0,0,0,0,0,0,17,0,0,0,0
0,0,0,0,0,17,0,0,0,0,0,0,0,0,0,0,0,0,0,0,0,17,0,0,0,0,0
0,0,0,0,0,17,0,0,0,0,0,0,0,0,0,0,0,0,0,0,0,17,0,0,0,0,0
0,0,0,0,0,0,17,0,0,0,0,0,0,0,0,0,0,0,0,0,17,0,0,0,0,0,0
0,0,0,0,0,0,0,17,0,0,0,0,0,0,0,0,0,0,0,17,0,0,0,0,0,0,0
0,0,0,0,0,0,0,0,17,17,0,0,0,0,0,0,0,17,17,0,0,0,0,0,0,0,0
0,0,0,0,0,0,0,0,0,0,17,17,17,17,17,17,17,0,0,0,0,0,0,0,0,0,0
0,0,0,0,0,0,0,0,0,0,0,0,0,0,0,0,0,0,0,0,0,0,0,0,0,0,0
0,0,0,0,0,0,0,0,0,0,0,0,0,0,0,0,0,0,0,0,0,0,0,0,0,0,0
0,0,0,0,0,0,0,0,0,0,0,0,0,0,0,0,0,0,0,0,0,0,0,0,0,0,0
0,0,0,0,0,0,0,0,0,0,0,0,0,0,0,0,0,0,0,0,0,0,0,0,0,0,0
endlayer

layer
0,0,0,0,0,0,0,0,0,0,0,0,0,0,0,0,0,0,0,0,0,0,0,0,0,0,0
0,0,0,0,0,0,0,0,0,0,0,0,0,0,0,0,0,0,0,0,0,0,0,0,0,0,0
0,0,0,0,0,0,0,0,0,0,0,0,0,0,0,0,0,0,0,0,0,0,0,0,0,0,0
0,0,0,0,0,0,0,0,0,0,0,0,0,0,0,0,0,0,0,0,0,0,0,0,0,0,0
0,0,0,0,0,0,0,0,0,0,17,17,17,17,17,17,17,0,0,0,0,0,0,0,0,0,0
0,0,0,0,0,0,0,0,17,17,0,0,0,0,0,0,0,17,17,0,0,0,0,0,0,0,0
0,0,0,0,0,0,0,17,0,0,0,0,0,0,0,0,0,0,0,17,0,0,0,0,0,0,0
0,0,0,0,0,0,17,0,0,0,0,0,0,0,0,0,0,0,0,0,17,0,0,0,0,0,0
0,0,0,0,0,17,0,0,0,0,0,0,0,0,0,0,0,0,0,0,0,17,0,0,0,0,0
0,0,0,0,0,17,0,0,0,0,0,0,0,0,0,0,0,0,0,0,0,17,0,0,0,0,0
0,0,0,0,17,0,0,0,0,0,0,0,0,0,0,0,0,0,0,0,0,0,17,0,0,0,0
0,0,0,0,17,0,0,0,0,0,0,0,0,0,0,0,0,0,0,0,0,0,17,0,0,0,0
0,0,0,0,17,0,0,0,0,0,0,0,0,0,0,0,0,0,0,0,0,0,17,0,0,0,0
0,0,0,0,17,0,0,0,0,0,0,0,0,0,0,0,0,0,0,0,0,0,17,0,0,0,0
0,0,0,0,17,0,0,0,0,0,0,0,0,0,0,0,0,0,0,0,0,0,17,0,0,0,0
0,0,0,0,17,0,0,0,0,0,0,0,0,0,0,0,0,0,0,0,0,0,17,0,0,0,0
0,0,0,0,17,0,0,0,0,0,0,0,0,0,0,0,0,0,0,0,0,0,17,0,0,0,0
0,0,0,0,0,17,0,0,0,0,0,0,0,0,0,0,0,0,0,0,0,17,0,0,0,0,0
0,0,0,0,0,17,0,0,0,0,0,0,0,0,0,0,0,0,0,0,0,17,0,0,0,0,0
0,0,0,0,0,0,17,0,0,0,0,0,0,0,0,0,0,0,0,0,17,0,0,0,0,0,0
0,0,0,0,0,0,0,17,0,0,0,0,0,0,0,0,0,0,0,17,0,0,0,0,0,0,0
0,0,0,0,0,0,0,0,17,17,0,0,0,0,0,0,0,17,17,0,0,0,0,0,0,0,0
0,0,0,0,0,0,0,0,0,0,17,17,17,17,17,17,17,0,0,0,0,0,0,0,0,0,0
0,0,0,0,0,0,0,0,0,0,0,0,0,0,0,0,0,0,0,0,0,0,0,0,0,0,0
0,0,0,0,0,0,0,0,0,0,0,0,0,0,0,0,0,0,0,0,0,0,0,0,0,0,0
0,0,0,0,0,0,0,0,0,0,0,0,0,0,0,0,0,0,0,0,0,0,0,0,0,0,0
0,0,0,0,0,0,0,0,0,0,0,0,0,0,0,0,0,0,0,0,0,0,0,0,0,0,0
endlayer

layer
0,0,0,0,0,0,0,0,0,0,0,0,0,0,0,0,0,0,0,0,0,0,0,0,0,0,0
0,0,0,0,0,0,0,0,0,0,0,0,0,0,0,0,0,0,0,0,0,0,0,0,0,0,0
0,0,0,0,0,0,0,0,0,0,0,0,0,0,0,0,0,0,0,0,0,0,0,0,0,0,0
0,0,0,0,0,0,0,0,0,0,0,0,0,0,0,0,0,0,0,0,0,0,0,0,0,0,0
0,0,0,0,0,0,0,0,0,0,18,18,18,18,18,18,18,0,0,0,0,0,0,0,0,0,0
0,0,0,0,0,0,0,0,18,18,19,19,19,19,19,19,19,18,18,0,0,0,0,0,0,0,0
0,0,0,0,0,0,0,18,19,19,19,19,19,19,19,19,19,19,19,18,0,0,0,0,0,0,0
0,0,0,0,0,0,18,19,19,19,20,20,20,20,20,20,20,19,19,19,18,0,0,0,0,0,0
0,0,0,0,0,18,19,19,19,20,20,20,20,20,20,20,20,20,19,19,19,18,0,0,0,0,0
0,0,0,0,0,18,19,19,20,20,20,20,20,20,20,20,20,20,20,19,19,18,0,0,0,0,0
0,0,0,0,18,19,19,20,20,20,20,20,20,20,20,20,20,20,20,20,19,19,18,0,0,0,0
0,0,0,0,18,19,19,20,20,20,20,20,20,20,20,20,20,20,20,20,19,19,18,0,0,0,0
0,0,0,0,18,19,19,20,20,20,20,20,20,20,20,20,19,19,19,19,19,19,18,0,0,0,0
0,0,0,0,18,19,19,20,20,20,20,20,20,20,20,20,19,19,19,19,19,4,18,0,0,0,0
0,0,0,0,18,19,19,20,20,20,20,20,20,20,20,20,19,19,19,19,19,19,18,0,0,0,0
0,0,0,0,18,19,19,20,20,20,20,20,20,20,20,20,20,20,20,20,19,19,18,0,0,0,0
0,0,0,0,18,19,19,20,20,20,20,20,20,20,20,20,20,20,20,20,19,19,18,0,0,0,0
0,0,0,0,0,18,19,19,20,20,20,20,20,20,20,20,20,20,20,19,19,18,0,0,0,0,0
0,0,0,0,0,18,19,19,19,20,20,20,20,20,20,20,20,20,19,19,19,18,0,0,0,0,0
0,0,0,0,0,0,18,19,19,19,20,20,20,20,20,20,20,19,19,19,18,0,0,0,0,0,0
0,0,0,0,0,0,0,18,19,19,19,19,19,19,19,19,19,19,19,18,0,0,0,0,0,0,0
0,0,0,0,0,0,0,0,18,18,19,19,19,19,19,19,19,18,18,0,0,0,0,0,0,0,0
0,0,0,0,0,0,0,0,0,0,18,18,18,18,18,18,18,0,0,0,0,0,0,0,0,0,0
0,0,0,0,0,0,0,0,0,0,0,0,0,0,0,0,0,0,0,0,0,0,0,0,0,0,0
0,0,0,0,0,0,0,0,0,0,0,0,0,0,0,0,0,0,0,0,0,0,0,0,0,0,0
0,0,0,0,0,0,0,0,0,0,0,0,0,0,0,0,0,0,0,0,0,0,0,0,0,0,0
0,0,0,0,0,0,0,0,0,0,0,0,0,0,0,0,0,0,0,0,0,0,0,0,0,0,0
endlayer

layer
0,0,0,0,0,0,0,0,0,0,0,0,0,0,0,0,0,0,0,0,0,0,0,0,0,0,0
0,0,0,0,0,0,0,0,0,0,0,0,0,0,0,0,0,0,0,0,0,0,0,0,0,0,0
0,0,0,0,0,0,0,0,0,0,0,0,0,0,0,0,0,0,0,0,0,0,0,0,0,0,0
0,0,0,0,0,0,0,0,0,0,0,0,0,0,0,0,0,0,0,0,0,0,0,0,0,0,0
0,0,0,0,0,0,0,0,0,0,17,17,17,17,17,17,17,0,0,0,0,0,0,0,0,0,0
0,0,0,0,0,0,0,0,17,17,0,0,0,0,0,0,0,17,17,0,0,0,0,0,0,0,0
0,0,0,0,0,0,0,17,0,0,0,0,0,0,0,0,0,0,0,17,0,0,0,0,0,0,0
0,0,0,0,0,0,17,0,0,0,0,0,0,0,0,0,0,0,0,0,17,0,0,0,0,0,0
0,0,0,0,0,17,0,0,0,0,0,0,0,0,0,0,0,0,0,0,0,17,0,0,0,0,0
0,0,0,0,0,17,0,0,0,0,0,0,0,0,0,0,0,0,0,0,0,17,0,0,0,0,0
0,0,0,0,17,0,0,0,0,0,0,0,0,0,0,0,0,0,0,0,0,0,17,0,0,0,0
0,0,0,0,17,0,0,0,0,0,0,21,21,21,21,21,0,0,0,0,0,0,17,0,0,0,0
0,0,0,0,17,0,0,0,0,0,0,21,21,21,21,21,0,0,0,0,0,0,17,0,0,0,0
0,0,0,0,17,0,0,0,0,0,0,21,21,22,21,21,0,0,0,0,0,0,17,0,0,0,0
0,0,0,0,17,0,0,0,0,0,0,21,21,21,21,21,0,0,0,0,0,0,17,0,0,0,0
0,0,0,0,17,0,0,0,0,0,0,21,21,21,21,21,0,0,0,0,0,0,17,0,0,0,0
0,0,0,0,17,0,0,0,0,0,0,0,0,0,0,0,0,0,0,0,0,0,17,0,0,0,0
0,0,0,0,0,17,0,0,0,0,0,0,0,0,0,0,0,0,0,0,0,17,0,0,0,0,0
0,0,0,0,0,17,0,0,0,0,0,0,0,0,0,0,0,0,0,0,0,17,0,0,0,0,0
0,0,0,0,0,0,17,0,0,0,0,0,0,0,0,0,0,0,0,0,17,0,0,0,0,0,0
0,0,0,0,0,0,0,17,0,0,0,0,0,0,0,0,0,0,0,17,0,0,0,0,0,0,0
0,0,0,0,0,0,0,0,17,17,0,0,0,0,0,0,0,17,17,0,0,0,0,0,0,0,0
0,0,0,0,0,0,0,0,0,0,17,17,17,17,17,17,17,0,0,0,0,0,0,0,0,0,0
0,0,0,0,0,0,0,0,0,0,0,0,0,0,0,0,0,0,0,0,0,0,0,0,0,0,0
0,0,0,0,0,0,0,0,0,0,0,0,0,0,0,0,0,0,0,0,0,0,0,0,0,0,0
0,0,0,0,0,0,0,0,0,0,0,0,0,0,0,0,0,0,0,0,0,0,0,0,0,0,0
0,0,0,0,0,0,0,0,0,0,0,0,0,0,0,0,0,0,0,0,0,0,0,0,0,0,0
endlayer

layer
0,0,0,0,0,0,0,0,0,0,0,0,0,0,0,0,0,0,0,0,0,0,0,0,0,0,0
0,0,0,0,0,0,0,0,0,0,0,0,0,0,0,0,0,0,0,0,0,0,0,0,0,0,0
0,0,0,0,0,0,0,0,0,0,0,0,0,0,0,0,0,0,0,0,0,0,0,0,0,0,0
0,0,0,0,0,0,0,0,0,0,0,0,0,0,0,0,0,0,0,0,0,0,0,0,0,0,0
0,0,0,0,0,0,0,0,0,0,17,17,17,17,17,17,17,0,0,0,0,0,0,0,0,0,0
0,0,0,0,0,0,0,0,17,17,0,0,0,0,0,0,0,17,17,0,0,0,0,0,0,0,0
0,0,0,0,0,0,0,17,0,0,0,0,0,0,0,0,0,0,0,17,0,0,0,0,0,0,0
0,0,0,0,0,0,17,0,0,0,0,0,0,0,0,0,0,0,0,0,17,0,0,0,0,0,0
0,0,0,0,0,17,0,0,0,0,0,0,0,0,0,0,0,0,0,0,0,17,0,0,0,0,0
0,0,0,0,0,17,0,0,0,0,0,0,0,0,0,0,0,0,0,0,0,17,0,0,0,0,0
0,0,0,0,17,0,0,0,0,0,0,0,0,0,0,0,0,0,0,0,0,0,17,0,0,0,0
0,0,0,0,17,0,0,0,0,0,0,21,26,26,26,21,0,0,0,0,0,0,17,0,0,0,0
0,0,0,0,17,0,0,0,0,0,0,26,0,0,0,23,0,0,0,0,0,0,17,0,0,0,0
0,0,0,0,17,0,0,0,0,0,0,26,0,27,0,24,0,0,0,0,0,0,17,0,0,0,0
0,0,0,0,17,0,0,0,0,0,0,26,0,0,0,25,0,0,0,0,0,0,17,0,0,0,0
0,0,0,0,17,0,0,0,0,0,0,21,26,26,26,21,0,0,0,0,0,0,17,0,0,0,0
0,0,0,0,17,0,0,0,0,0,0,0,0,0,0,0,0,0,0,0,0,0,17,0,0,0,0
0,0,0,0,0,17,0,0,0,0,0,0,0,0,0,0,0,0,0,0,0,17,0,0,0,0,0
0,0,0,0,0,17,0,0,0,0,0,0,0,0,0,0,0,0,0,0,0,17,0,0,0,0,0
0,0,0,0,0,0,17,0,0,0,0,0,0,0,0,0,0,0,0,0,17,0,0,0,0,0,0
0,0,0,0,0,0,0,17,0,0,0,0,0,0,0,0,0,0,0,17,0,0,0,0,0,0,0
0,0,0,0,0,0,0,0,17,17,0,0,0,0,0,0,0,17,17,0,0,0,0,0,0,0,0
0,0,0,0,0,0,0,0,0,0,17,17,17,17,17,17,17,0,0,0,0,0,0,0,0,0,0
0,0,0,0,0,0,0,0,0,0,0,0,0,0,0,0,0,0,0,0,0,0,0,0,0,0,0
0,0,0,0,0,0,0,0,0,0,0,0,0,0,0,0,0,0,0,0,0,0,0,0,0,0,0
0,0,0,0,0,0,0,0,0,0,0,0,0,0,0,0,0,0,0,0,0,0,0,0,0,0,0
0,0,0,0,0,0,0,0,0,0,0,0,0,0,0,0,0,0,0,0,0,0,0,0,0,0,0
endlayer

layer
0,0,0,0,0,0,0,0,0,0,0,0,0,0,0,0,0,0,0,0,0,0,0,0,0,0,0
0,0,0,0,0,0,0,0,0,0,0,0,0,0,0,0,0,0,0,0,0,0,0,0,0,0,0
0,0,0,0,0,0,0,0,0,0,0,0,0,0,0,0,0,0,0,0,0,0,0,0,0,0,0
0,0,0,0,0,0,0,0,0,0,0,0,0,0,0,0,0,0,0,0,0,0,0,0,0,0,0
0,0,0,0,0,0,0,0,0,0,17,17,17,17,17,17,17,0,0,0,0,0,0,0,0,0,0
0,0,0,0,0,0,0,0,17,17,0,0,0,0,0,0,0,17,17,0,0,0,0,0,0,0,0
0,0,0,0,0,0,0,17,0,0,0,0,0,0,0,0,0,0,0,17,0,0,0,0,0,0,0
0,0,0,0,0,0,17,0,0,0,0,0,0,0,0,0,0,0,0,0,17,0,0,0,0,0,0
0,0,0,0,0,17,0,0,0,0,0,0,0,0,0,0,0,0,0,0,0,17,0,0,0,0,0
0,0,0,0,0,17,0,0,0,0,0,0,0,0,0,0,0,0,0,0,0,17,0,0,0,0,0
0,0,0,0,17,0,0,0,0,0,0,0,0,0,0,0,0,0,0,0,0,0,17,0,0,0,0
0,0,0,0,17,0,0,0,0,0,0,21,26,26,26,21,0,0,0,0,0,0,17,0,0,0,0
0,0,0,0,17,0,0,0,0,0,0,26,0,0,0,26,0,0,0,0,0,0,17,0,0,0,0
0,0,0,0,17,0,0,0,0,0,0,26,0,27,0,26,0,0,0,0,0,0,17,0,0,0,0
0,0,0,0,17,0,0,0,0,0,0,26,0,0,0,26,0,0,0,0,0,0,17,0,0,0,0
0,0,0,0,17,0,0,0,0,0,0,21,26,26,26,21,0,0,0,0,0,0,17,0,0,0,0
0,0,0,0,17,0,0,0,0,0,0,0,0,0,0,0,0,0,0,0,0,0,17,0,0,0,0
0,0,0,0,0,17,0,0,0,0,0,0,0,0,0,0,0,0,0,0,0,17,0,0,0,0,0
0,0,0,0,0,17,0,0,0,0,0,0,0,0,0,0,0,0,0,0,0,17,0,0,0,0,0
0,0,0,0,0,0,17,0,0,0,0,0,0,0,0,0,0,0,0,0,17,0,0,0,0,0,0
0,0,0,0,0,0,0,17,0,0,0,0,0,0,0,0,0,0,0,17,0,0,0,0,0,0,0
0,0,0,0,0,0,0,0,17,17,0,0,0,0,0,0,0,17,17,0,0,0,0,0,0,0,0
0,0,0,0,0,0,0,0,0,0,17,17,17,17,17,17,17,0,0,0,0,0,0,0,0,0,0
0,0,0,0,0,0,0,0,0,0,0,0,0,0,0,0,0,0,0,0,0,0,0,0,0,0,0
0,0,0,0,0,0,0,0,0,0,0,0,0,0,0,0,0,0,0,0,0,0,0,0,0,0,0
0,0,0,0,0,0,0,0,0,0,0,0,0,0,0,0,0,0,0,0,0,0,0,0,0,0,0
0,0,0,0,0,0,0,0,0,0,0,0,0,0,0,0,0,0,0,0,0,0,0,0,0,0,0
endlayer

layer
0,0,0,0,0,0,0,0,0,0,0,0,0,0,0,0,0,0,0,0,0,0,0,0,0,0,0
0,0,0,0,0,0,0,0,0,0,0,0,0,0,0,0,0,0,0,0,0,0,0,0,0,0,0
0,0,0,0,0,0,0,0,0,0,0,0,0,0,0,0,0,0,0,0,0,0,0,0,0,0,0
0,0,0,0,0,0,0,0,0,0,0,0,0,0,0,0,0,0,0,0,0,0,0,0,0,0,0
0,0,0,0,0,0,0,0,0,0,17,17,17,17,17,17,17,0,0,0,0,0,0,0,0,0,0
0,0,0,0,0,0,0,0,17,17,0,0,0,0,0,0,0,17,17,0,0,0,0,0,0,0,0
0,0,0,0,0,0,0,17,0,0,0,0,0,0,0,0,0,0,0,17,0,0,0,0,0,0,0
0,0,0,0,0,0,17,0,0,0,0,0,0,0,0,0,0,0,0,0,17,0,0,0,0,0,0
0,0,0,0,0,17,0,0,0,0,0,0,0,0,0,0,0,0,0,0,0,17,0,0,0,0,0
0,0,0,0,0,17,0,0,0,0,0,0,0,0,0,0,0,0,0,0,0,17,0,0,0,0,0
0,0,0,0,17,0,0,0,0,0,0,0,0,0,0,0,0,0,0,0,0,0,17,0,0,0,0
0,0,0,0,17,0,0,0,0,0,0,21,26,26,26,21,0,0,0,0,0,0,17,0,0,0,0
0,0,0,0,17,0,0,0,0,0,0,26,0,0,0,26,0,0,0,0,0,0,17,0,0,0,0
0,0,0,0,17,0,0,0,0,0,0,26,0,27,0,26,0,0,0,0,0,0,17,0,0,0,0
0,0,0,0,17,0,0,0,0,0,0,26,0,0,0,26,0,0,0,0,0,0,17,0,0,0,0
0,0,0,0,17,0,0,0,0,0,0,21,26,26,26,21,0,0,0,0,0,0,17,0,0,0,0
0,0,0,0,17,0,0,0,0,0,0,0,0,0,0,0,0,0,0,0,0,0,17,0,0,0,0
0,0,0,0,0,17,0,0,0,0,0,0,0,0,0,0,0,0,0,0,0,17,0,0,0,0,0
0,0,0,0,0,17,0,0,0,0,0,0,0,0,0,0,0,0,0,0,0,17,0,0,0,0,0
0,0,0,0,0,0,17,0,0,0,0,0,0,0,0,0,0,0,0,0,17,0,0,0,0,0,0
0,0,0,0,0,0,0,17,0,0,0,0,0,0,0,0,0,0,0,17,0,0,0,0,0,0,0
0,0,0,0,0,0,0,0,17,17,0,0,0,0,0,0,0,17,17,0,0,0,0,0,0,0,0
0,0,0,0,0,0,0,0,0,0,17,17,17,17,17,17,17,0,0,0,0,0,0,0,0,0,0
0,0,0,0,0,0,0,0,0,0,0,0,0,0,0,0,0,0,0,0,0,0,0,0,0,0,0
0,0,0,0,0,0,0,0,0,0,0,0,0,0,0,0,0,0,0,0,0,0,0,0,0,0,0
0,0,0,0,0,0,0,0,0,0,0,0,0,0,0,0,0,0,0,0,0,0,0,0,0,0,0
0,0,0,0,0,0,0,0,0,0,0,0,0,0,0,0,0,0,0,0,0,0,0,0,0,0,0
endlayer

layer
0,0,0,0,0,0,0,0,0,0,0,0,0,0,0,0,0,0,0,0,0,0,0,0,0,0,0
0,0,0,0,0,0,0,0,0,0,0,0,0,0,0,0,0,0,0,0,0,0,0,0,0,0,0
0,0,0,0,0,0,0,0,0,0,0,0,0,0,0,0,0,0,0,0,0,0,0,0,0,0,0
0,0,0,0,0,0,0,0,0,0,0,0,0,0,0,0,0,0,0,0,0,0,0,0,0,0,0
0,0,0,0,0,0,0,0,0,0,17,17,17,17,17,17,17,0,0,0,0,0,0,0,0,0,0
0,0,0,0,0,0,0,0,17,17,0,0,0,0,0,0,0,17,17,0,0,0,0,0,0,0,0
0,0,0,0,0,0,0,17,0,0,0,0,0,0,0,0,0,0,0,17,0,0,0,0,0,0,0
0,0,0,0,0,0,17,0,0,0,0,0,0,0,0,0,0,0,0,0,17,0,0,0,0,0,0
0,0,0,0,0,17,0,0,0,0,0,0,0,0,0,0,0,0,0,0,0,17,0,0,0,0,0
0,0,0,0,0,17,0,0,0,0,0,0,0,0,0,0,0,0,0,0,0,17,0,0,0,0,0
0,0,0,0,17,0,0,0,0,0,0,0,0,0,0,0,0,0,0,0,0,0,17,0,0,0,0
0,0,0,0,17,0,0,0,0,0,0,21,26,26,26,21,0,0,0,0,0,0,17,0,0,0,0
0,0,0,0,17,0,0,0,0,0,0,26,0,0,0,26,0,0,0,0,0,0,17,0,0,0,0
0,0,0,0,17,0,0,0,0,0,0,26,0,27,0,26,0,0,0,0,0,0,17,0,0,0,0
0,0,0,0,17,0,0,0,0,0,0,26,0,0,0,26,0,0,0,0,0,0,17,0,0,0,0
0,0,0,0,17,0,0,0,0,0,0,21,26,26,26,21,0,0,0,0,0,0,17,0,0,0,0
0,0,0,0,17,0,0,0,0,0,0,0,0,0,0,0,0,0,0,0,0,0,17,0,0,0,0
0,0,0,0,0,17,0,0,0,0,0,0,0,0,0,0,0,0,0,0,0,17,0,0,0,0,0
0,0,0,0,0,17,0,0,0,0,0,0,0,0,0,0,0,0,0,0,0,17,0,0,0,0,0
0,0,0,0,0,0,17,0,0,0,0,0,0,0,0,0,0,0,0,0,17,0,0,0,0,0,0
0,0,0,0,0,0,0,17,0,0,0,0,0,0,0,0,0,0,0,17,0,0,0,0,0,0,0
0,0,0,0,0,0,0,0,17,17,0,0,0,0,0,0,0,17,17,0,0,0,0,0,0,0,0
0,0,0,0,0,0,0,0,0,0,17,17,17,17,17,17,17,0,0,0,0,0,0,0,0,0,0
0,0,0,0,0,0,0,0,0,0,0,0,0,0,0,0,0,0,0,0,0,0,0,0,0,0,0
0,0,0,0,0,0,0,0,0,0,0,0,0,0,0,0,0,0,0,0,0,0,0,0,0,0,0
0,0,0,0,0,0,0,0,0,0,0,0,0,0,0,0,0,0,0,0,0,0,0,0,0,0,0
0,0,0,0,0,0,0,0,0,0,0,0,0,0,0,0,0,0,0,0,0,0,0,0,0,0,0
endlayer

layer
0,0,0,0,0,0,0,0,0,0,0,0,0,0,0,0,0,0,0,0,0,0,0,0,0,0,0
0,0,0,0,0,0,0,0,0,0,0,0,0,0,0,0,0,0,0,0,0,0,0,0,0,0,0
0,0,0,0,0,0,0,0,0,0,0,0,0,0,0,0,0,0,0,0,0,0,0,0,0,0,0
0,0,0,0,0,0,0,0,0,0,0,0,0,0,0,0,0,0,0,0,0,0,0,0,0,0,0
0,0,0,0,0,0,0,0,0,0,17,17,17,17,17,17,17,0,0,0,0,0,0,0,0,0,0
0,0,0,0,0,0,0,0,17,17,0,0,0,0,0,0,0,17,17,0,0,0,0,0,0,0,0
0,0,0,0,0,0,0,17,0,0,0,0,0,0,0,0,0,0,0,17,0,0,0,0,0,0,0
0,0,0,0,0,0,17,0,0,0,0,0,0,0,0,0,0,0,0,0,17,0,0,0,0,0,0
0,0,0,0,0,17,0,0,0,0,0,0,0,0,0,0,0,0,0,0,0,17,0,0,0,0,0
0,0,0,0,0,17,0,0,0,0,0,0,0,0,0,0,0,0,0,0,0,17,0,0,0,0,0
0,0,0,0,17,0,0,0,0,0,0,0,0,0,0,0,0,0,0,0,0,0,17,0,0,0,0
0,0,0,0,17,0,0,0,0,0,0,21,26,26,26,21,0,0,0,0,0,0,17,0,0,0,0
0,0,0,0,17,0,0,0,0,0,0,26,0,0,0,26,0,0,0,0,0,0,17,0,0,0,0
0,0,0,0,17,0,0,0,0,0,0,26,0,27,0,26,0,0,0,0,0,0,17,0,0,0,0
0,0,0,0,17,0,0,0,0,0,0,26,0,0,0,26,0,0,0,0,0,0,17,0,0,0,0
0,0,0,0,17,0,0,0,0,0,0,21,26,26,26,21,0,0,0,0,0,0,17,0,0,0,0
0,0,0,0,17,0,0,0,0,0,0,0,0,0,0,0,0,0,0,0,0,0,17,0,0,0,0
0,0,0,0,0,17,0,0,0,0,0,0,0,0,0,0,0,0,0,0,0,17,0,0,0,0,0
0,0,0,0,0,17,0,0,0,0,0,0,0,0,0,0,0,0,0,0,0,17,0,0,0,0,0
0,0,0,0,0,0,17,0,0,0,0,0,0,0,0,0,0,0,0,0,17,0,0,0,0,0,0
0,0,0,0,0,0,0,17,0,0,0,0,0,0,0,0,0,0,0,17,0,0,0,0,0,0,0
0,0,0,0,0,0,0,0,17,17,0,0,0,0,0,0,0,17,17,0,0,0,0,0,0,0,0
0,0,0,0,0,0,0,0,0,0,17,17,17,17,17,17,17,0,0,0,0,0,0,0,0,0,0
0,0,0,0,0,0,0,0,0,0,0,0,0,0,0,0,0,0,0,0,0,0,0,0,0,0,0
0,0,0,0,0,0,0,0,0,0,0,0,0,0,0,0,0,0,0,0,0,0,0,0,0,0,0
0,0,0,0,0,0,0,0,0,0,0,0,0,0,0,0,0,0,0,0,0,0,0,0,0,0,0
0,0,0,0,0,0,0,0,0,0,0,0,0,0,0,0,0,0,0,0,0,0,0,0,0,0,0
endlayer

layer
0,0,0,0,0,0,0,0,0,0,0,0,0,0,0,0,0,0,0,0,0,0,0,0,0,0,0
0,0,0,0,0,0,0,0,0,0,0,0,0,0,0,0,0,0,0,0,0,0,0,0,0,0,0
0,0,0,0,0,0,0,0,0,0,0,0,0,0,0,0,0,0,0,0,0,0,0,0,0,0,0
0,0,0,0,0,0,0,0,0,0,0,0,0,0,0,0,0,0,0,0,0,0,0,0,0,0,0
0,0,0,0,0,0,0,0,0,0,17,17,17,17,17,17,17,0,0,0,0,0,0,0,0,0,0
0,0,0,0,0,0,0,0,17,17,0,0,0,0,0,0,0,17,17,0,0,0,0,0,0,0,0
0,0,0,0,0,0,0,17,0,0,0,0,0,0,0,0,0,0,0,17,0,0,0,0,0,0,0
0,0,0,0,0,0,17,0,0,0,0,0,0,0,0,0,0,0,0,0,17,0,0,0,0,0,0
0,0,0,0,0,17,0,0,0,0,0,0,0,0,0,0,0,0,0,0,0,17,0,0,0,0,0
0,0,0,0,0,17,0,0,0,0,0,0,0,0,0,0,0,0,0,0,0,17,0,0,0,0,0
0,0,0,0,17,0,0,0,0,0,0,0,0,0,0,0,0,0,0,0,0,0,17,0,0,0,0
0,0,0,0,17,0,0,0,0,0,0,21,26,26,26,21,0,0,0,0,0,0,17,0,0,0,0
0,0,0,0,17,0,0,0,0,0,0,26,0,0,0,26,0,0,0,0,0,0,17,0,0,0,0
0,0,0,0,17,0,0,0,0,0,0,26,0,27,0,26,0,0,0,0,0,0,17,0,0,0,0
0,0,0,0,17,0,0,0,0,0,0,26,0,0,0,26,0,0,0,0,0,0,17,0,0,0,0
0,0,0,0,17,0,0,0,0,0,0,21,26,26,26,21,0,0,0,0,0,0,17,0,0,0,0
0,0,0,0,17,0,0,0,0,0,0,0,0,0,0,0,0,0,0,0,0,0,17,0,0,0,0
0,0,0,0,0,17,0,0,0,0,0,0,0,0,0,0,0,0,0,0,0,17,0,0,0,0,0
0,0,0,0,0,17,0,0,0,0,0,0,0,0,0,0,0,0,0,0,0,17,0,0,0,0,0
0,0,0,0,0,0,17,0,0,0,0,0,0,0,0,0,0,0,0,0,17,0,0,0,0,0,0
0,0,0,0,0,0,0,17,0,0,0,0,0,0,0,0,0,0,0,17,0,0,0,0,0,0,0
0,0,0,0,0,0,0,0,17,17,0,0,0,0,0,0,0,17,17,0,0,0,0,0,0,0,0
0,0,0,0,0,0,0,0,0,0,17,17,17,17,17,17,17,0,0,0,0,0,0,0,0,0,0
0,0,0,0,0,0,0,0,0,0,0,0,0,0,0,0,0,0,0,0,0,0,0,0,0,0,0
0,0,0,0,0,0,0,0,0,0,0,0,0,0,0,0,0,0,0,0,0,0,0,0,0,0,0
0,0,0,0,0,0,0,0,0,0,0,0,0,0,0,0,0,0,0,0,0,0,0,0,0,0,0
0,0,0,0,0,0,0,0,0,0,0,0,0,0,0,0,0,0,0,0,0,0,0,0,0,0,0
endlayer

layer
0,0,0,0,0,0,0,0,0,0,0,0,0,0,0,0,0,0,0,0,0,0,0,0,0,0,0
0,0,0,0,0,0,0,0,0,0,0,0,0,0,0,0,0,0,0,0,0,0,0,0,0,0,0
0,0,0,0,0,0,0,0,0,0,0,0,0,0,0,0,0,0,0,0,0,0,0,0,0,0,0
0,0,0,0,0,0,0,0,0,0,0,0,0,0,0,0,0,0,0,0,0,0,0,0,0,0,0
0,0,0,0,0,0,0,0,0,0,17,17,17,17,17,17,17,0,0,0,0,0,0,0,0,0,0
0,0,0,0,0,0,0,0,17,17,0,0,0,0,0,0,0,17,17,0,0,0,0,0,0,0,0
0,0,0,0,0,0,0,17,0,0,0,0,0,0,0,0,0,0,0,17,0,0,0,0,0,0,0
0,0,0,0,0,0,17,0,0,0,0,0,0,0,0,0,0,0,0,0,17,0,0,0,0,0,0
0,0,0,0,0,17,0,0,0,0,0,0,0,0,0,0,0,0,0,0,0,17,0,0,0,0,0
0,0,0,0,0,17,0,0,0,0,0,0,0,0,0,0,0,0,0,0,0,17,0,0,0,0,0
0,0,0,0,17,0,0,0,0,0,0,0,0,0,0,0,0,0,0,0,0,0,17,0,0,0,0
0,0,0,0,17,0,0,0,0,0,0,21,26,26,26,21,0,0,0,0,0,0,17,0,0,0,0
0,0,0,0,17,0,0,0,0,0,0,26,28,28,28,26,0,0,0,0,0,0,17,0,0,0,0
0,0,0,0,17,0,0,0,0,0,0,26,28,27,28,26,0,0,0,0,0,0,17,0,0,0,0
0,0,0,0,17,0,0,0,0,0,0,26,28,28,28,26,0,0,0,0,0,0,17,0,0,0,0
0,0,0,0,17,0,0,0,0,0,0,21,21,26,26,21,0,0,0,0,0,0,17,0,0,0,0
0,0,0,0,17,0,0,0,0,0,0,0,0,0,0,0,0,0,0,0,0,0,17,0,0,0,0
0,0,0,0,0,17,0,0,0,0,0,0,0,0,0,0,0,0,0,0,0,17,0,0,0,0,0
0,0,0,0,0,17,0,0,0,0,0,0,0,0,0,0,0,0,0,0,0,17,0,0,0,0,0
0,0,0,0,0,0,17,0,0,0,0,0,0,0,0,0,0,0,0,0,17,0,0,0,0,0,0
0,0,0,0,0,0,0,17,0,0,0,0,0,0,0,0,0,0,0,17,0,0,0,0,0,0,0
0,0,0,0,0,0,0,0,17,17,0,0,0,0,0,0,0,17,17,0,0,0,0,0,0,0,0
0,0,0,0,0,0,0,0,0,0,17,17,17,17,17,17,17,0,0,0,0,0,0,0,0,0,0
0,0,0,0,0,0,0,0,0,0,0,0,0,0,0,0,0,0,0,0,0,0,0,0,0,0,0
0,0,0,0,0,0,0,0,0,0,0,0,0,0,0,0,0,0,0,0,0,0,0,0,0,0,0
0,0,0,0,0,0,0,0,0,0,0,0,0,0,0,0,0,0,0,0,0,0,0,0,0,0,0
0,0,0,0,0,0,0,0,0,0,0,0,0,0,0,0,0,0,0,0,0,0,0,0,0,0,0
endlayer

layer
0,0,0,0,0,0,0,0,0,0,0,0,0,0,0,0,0,0,0,0,0,0,0,0,0,0,0
0,0,0,0,0,0,0,0,0,0,0,0,0,0,0,0,0,0,0,0,0,0,0,0,0,0,0
0,0,0,0,0,0,0,0,0,0,0,0,0,0,0,0,0,0,0,0,0,0,0,0,0,0,0
0,0,0,0,0,0,0,0,0,0,0,0,0,0,0,0,0,0,0,0,0,0,0,0,0,0,0
0,0,0,0,0,0,0,0,0,0,17,17,17,17,17,17,17,0,0,0,0,0,0,0,0,0,0
0,0,0,0,0,0,0,0,17,17,0,0,0,0,0,0,0,17,17,0,0,0,0,0,0,0,0
0,0,0,0,0,0,0,17,0,0,0,0,0,0,0,0,0,0,0,17,0,0,0,0,0,0,0
0,0,0,0,0,0,17,0,0,0,0,0,0,0,0,0,0,0,0,0,17,0,0,0,0,0,0
0,0,0,0,0,17,0,0,0,0,0,0,0,0,0,0,0,0,0,0,0,17,0,0,0,0,0
0,0,0,0,0,17,0,0,0,0,0,0,0,0,0,0,0,0,0,0,0,17,0,0,0,0,0
0,0,0,0,17,0,0,0,0,0,0,0,0,0,0,0,0,0,0,0,0,0,17,0,0,0,0
0,0,0,0,17,0,0,0,0,0,0,21,21,21,21,21,0,0,0,0,0,0,17,0,0,0,0
0,0,0,0,17,0,0,0,0,0,0,21,21,21,21,21,0,0,0,0,0,0,17,0,0,0,0
0,0,0,0,17,0,0,0,0,0,0,21,21,21,21,21,0,0,0,0,0,0,17,0,0,0,0
0,0,0,0,17,0,0,0,0,0,0,21,21,21,21,21,0,0,0,0,0,0,17,0,0,0,0
0,0,0,0,17,0,0,0,0,0,0,21,21,21,21,21,0,0,0,0,0,0,17,0,0,0,0
0,0,0,0,17,0,0,0,0,0,0,0,0,0,0,0,0,0,0,0,0,0,17,0,0,0,0
0,0,0,0,0,17,0,0,0,0,0,0,0,0,0,0,0,0,0,0,0,17,0,0,0,0,0
0,0,0,0,0,17,0,0,0,0,0,0,0,0,0,0,0,0,0,0,0,17,0,0,0,0,0
0,0,0,0,0,0,17,0,0,0,0,0,0,0,0,0,0,0,0,0,17,0,0,0,0,0,0
0,0,0,0,0,0,0,17,0,0,0,0,0,0,0,0,0,0,0,17,0,0,0,0,0,0,0
0,0,0,0,0,0,0,0,17,17,0,0,0,0,0,0,0,17,17,0,0,0,0,0,0,0,0
0,0,0,0,0,0,0,0,0,0,17,17,17,17,17,17,17,0,0,0,0,0,0,0,0,0,0
0,0,0,0,0,0,0,0,0,0,0,0,0,0,0,0,0,0,0,0,0,0,0,0,0,0,0
0,0,0,0,0,0,0,0,0,0,0,0,0,0,0,0,0,0,0,0,0,0,0,0,0,0,0
0,0,0,0,0,0,0,0,0,0,0,0,0,0,0,0,0,0,0,0,0,0,0,0,0,0,0
0,0,0,0,0,0,0,0,0,0,0,0,0,0,0,0,0,0,0,0,0,0,0,0,0,0,0
endlayer

layer
0,0,0,0,0,0,0,0,0,0,0,0,0,0,0,0,0,0,0,0,0,0,0,0,0,0,0
0,0,0,0,0,0,0,0,0,0,0,0,0,0,0,0,0,0,0,0,0,0,0,0,0,0,0
0,0,0,0,0,0,0,0,0,0,0,0,0,0,0,0,0,0,0,0,0,0,0,0,0,0,0
0,0,0,0,0,0,0,0,0,0,0,0,0,0,0,0,0,0,0,0,0,0,0,0,0,0,0
0,0,0,0,0,0,0,0,0,0,17,17,17,17,17,17,17,0,0,0,0,0,0,0,0,0,0
0,0,0,0,0,0,0,0,17,17,0,0,0,0,0,0,0,17,17,0,0,0,0,0,0,0,0
0,0,0,0,0,0,0,17,0,0,0,0,0,0,0,0,0,0,0,17,0,0,0,0,0,0,0
0,0,0,0,0,0,17,0,0,0,0,0,0,0,0,0,0,0,0,0,17,0,0,0,0,0,0
0,0,0,0,0,17,0,0,0,0,0,0,0,0,0,0,0,0,0,0,0,17,0,0,0,0,0
0,0,0,0,0,17,0,0,0,0,0,0,0,0,0,0,0,0,0,0,0,17,0,0,0,0,0
0,0,0,0,17,0,0,0,0,0,0,0,0,0,0,0,0,0,0,0,0,0,17,0,0,0,0
0,0,0,0,17,0,0,0,0,0,0,0,0,0,0,0,0,0,0,0,0,0,17,0,0,0,0
0,0,0,0,17,0,0,0,0,0,0,0,0,0,0,0,0,0,0,0,0,0,17,0,0,0,0
0,0,0,0,17,0,0,0,0,0,0,0,0,0,0,0,0,0,0,0,0,0,17,0,0,0,0
0,0,0,0,17,0,0,0,0,0,0,0,0,0,0,0,0,0,0,0,0,0,17,0,0,0,0
0,0,0,0,17,0,0,0,0,0,0,0,0,0,0,0,0,0,0,0,0,0,17,0,0,0,0
0,0,0,0,17,0,0,0,0,0,0,0,0,0,0,0,0,0,0,0,0,0,17,0,0,0,0
0,0,0,0,0,17,0,0,0,0,0,0,0,0,0,0,0,0,0,0,0,17,0,0,0,0,0
0,0,0,0,0,17,0,0,0,0,0,0,0,0,0,0,0,0,0,0,0,17,0,0,0,0,0
0,0,0,0,0,0,17,0,0,0,0,0,0,0,0,0,0,0,0,0,17,0,0,0,0,0,0
0,0,0,0,0,0,0,17,0,0,0,0,0,0,0,0,0,0,0,17,0,0,0,0,0,0,0
0,0,0,0,0,0,0,0,17,17,0,0,0,0,0,0,0,17,17,0,0,0,0,0,0,0,0
0,0,0,0,0,0,0,0,0,0,17,17,17,17,17,17,17,0,0,0,0,0,0,0,0,0,0
0,0,0,0,0,0,0,0,0,0,0,0,0,0,0,0,0,0,0,0,0,0,0,0,0,0,0
0,0,0,0,0,0,0,0,0,0,0,0,0,0,0,0,0,0,0,0,0,0,0,0,0,0,0
0,0,0,0,0,0,0,0,0,0,0,0,0,0,0,0,0,0,0,0,0,0,0,0,0,0,0
0,0,0,0,0,0,0,0,0,0,0,0,0,0,0,0,0,0,0,0,0,0,0,0,0,0,0
endlayer

layer
0,0,0,0,0,0,0,0,0,0,0,0,0,0,0,0,0,0,0,0,0,0,0,0,0,0,0
0,0,0,0,0,0,0,0,0,0,0,0,0,0,0,0,0,0,0,0,0,0,0,0,0,0,0
0,0,0,0,0,0,0,0,0,0,0,0,0,0,0,0,0,0,0,0,0,0,0,0,0,0,0
0,0,0,0,0,0,0,0,0,0,0,0,0,0,0,0,0,0,0,0,0,0,0,0,0,0,0
0,0,0,0,0,0,0,0,0,0,17,17,17,17,17,17,17,0,0,0,0,0,0,0,0,0,0
0,0,0,0,0,0,0,0,17,17,0,0,0,0,0,0,0,17,17,0,0,0,0,0,0,0,0
0,0,0,0,0,0,0,17,0,0,0,0,0,0,0,0,0,0,0,17,0,0,0,0,0,0,0
0,0,0,0,0,0,17,0,0,0,0,0,0,0,0,0,0,0,0,0,17,0,0,0,0,0,0
0,0,0,0,0,17,0,0,0,0,0,0,0,0,0,0,0,0,0,0,0,17,0,0,0,0,0
0,0,0,0,0,17,0,0,0,0,0,0,0,0,0,0,0,0,0,0,0,17,0,0,0,0,0
0,0,0,0,17,0,0,0,0,0,0,0,0,0,0,0,0,0,0,0,0,0,17,0,0,0,0
0,0,0,0,17,0,0,0,0,0,0,0,0,0,0,0,0,0,0,0,0,0,17,0,0,0,0
0,0,0,0,17,0,0,0,0,0,0,0,0,0,0,0,0,0,0,0,0,0,17,0,0,0,0
0,0,0,0,17,0,0,0,0,0,0,0,0,0,0,0,0,0,0,0,0,0,17,0,0,0,0
0,0,0,0,17,0,0,0,0,0,0,0,0,0,0,0,0,0,0,0,0,0,17,0,0,0,0
0,0,0,0,17,0,0,0,0,0,0,0,0,0,0,0,0,0,0,0,0,0,17,0,0,0,0
0,0,0,0,17,0,0,0,0,0,0,0,0,0,0,0,0,0,0,0,0,0,17,0,0,0,0
0,0,0,0,0,17,0,0,0,0,0,0,0,0,0,0,0,0,0,0,0,17,0,0,0,0,0
0,0,0,0,0,17,0,0,0,0,0,0,0,0,0,0,0,0,0,0,0,17,0,0,0,0,0
0,0,0,0,0,0,17,0,0,0,0,0,0,0,0,0,0,0,0,0,17,0,0,0,0,0,0
0,0,0,0,0,0,0,17,0,0,0,0,0,0,0,0,0,0,0,17,0,0,0,0,0,0,0
0,0,0,0,0,0,0,0,17,17,0,0,0,0,0,0,0,17,17,0,0,0,0,0,0,0,0
0,0,0,0,0,0,0,0,0,0,17,17,17,17,17,17,17,0,0,0,0,0,0,0,0,0,0
0,0,0,0,0,0,0,0,0,0,0,0,0,0,0,0,0,0,0,0,0,0,0,0,0,0,0
0,0,0,0,0,0,0,0,0,0,0,0,0,0,0,0,0,0,0,0,0,0,0,0,0,0,0
0,0,0,0,0,0,0,0,0,0,0,0,0,0,0,0,0,0,0,0,0,0,0,0,0,0,0
0,0,0,0,0,0,0,0,0,0,0,0,0,0,0,0,0,0,0,0,0,0,0,0,0,0,0
endlayer

layer
0,0,0,0,0,0,0,0,0,0,0,0,0,0,0,0,0,0,0,0,0,0,0,0,0,0,0
0,0,0,0,0,0,0,0,0,0,0,0,0,0,0,0,0,0,0,0,0,0,0,0,0,0,0
0,0,0,0,0,0,0,0,0,0,0,0,0,0,0,0,0,0,0,0,0,0,0,0,0,0,0
0,0,0,0,0,0,0,0,0,0,15,15,15,15,15,15,15,0,0,0,0,0,0,0,0,0,0
0,0,0,0,0,0,0,0,15,15,0,0,0,0,0,0,0,15,15,0,0,0,0,0,0,0,0
0,0,0,0,0,0,0,15,0,0,0,0,0,0,0,0,0,0,0,15,0,0,0,0,0,0,0
0,0,0,0,0,0,15,0,0,0,0,0,0,0,0,0,0,0,0,0,15,0,0,0,0,0,0
0,0,0,0,0,15,0,0,0,0,0,0,0,0,0,0,0,0,0,0,0,15,0,0,0,0,0
0,0,0,0,15,0,0,0,0,0,0,0,0,0,0,0,0,0,0,0,0,0,15,0,0,0,0
0,0,0,0,15,0,0,0,0,0,0,0,0,0,0,0,0,0,0,0,0,0,15,0,0,0,0
0,0,0,15,0,0,0,0,0,0,0,0,0,0,0,0,0,0,0,0,0,0,0,15,0,0,0
0,0,0,15,0,0,0,0,0,0,0,0,0,0,0,0,0,0,0,0,0,0,0,15,0,0,0
0,0,0,15,0,0,0,0,0,0,0,0,0,0,0,0,0,0,0,0,0,0,0,15,0,0,0
0,0,0,15,0,0,0,0,0,0,0,0,0,0,0,0,0,0,0,0,0,0,0,15,0,0,0
0,0,0,15,0,0,0,0,0,0,0,0,0,0,0,0,0,0,0,0,0,0,0,15,0,0,0
0,0,0,15,0,0,0,0,0,0,0,0,0,0,0,0,0,0,0,0,0,0,0,15,0,0,0
0,0,0,15,0,0,0,0,0,0,0,0,0,0,0,0,0,0,0,0,0,0,0,15,0,0,0
0,0,0,0,15,0,0,0,0,0,0,0,0,0,0,0,0,0,0,0,0,0,15,0,0,0,0
0,0,0,0,15,0,0,0,0,0,0,0,0,0,0,0,0,0,0,0,0,0,15,0,0,0,0
0,0,0,0,0,15,0,0,0,0,0,0,0,0,0,0,0,0,0,0,0,15,0,0,0,0,0
0,0,0,0,0,0,15,0,0,0,0,0,0,0,0,0,0,0,0,0,15,0,0,0,0,0,0
0,0,0,0,0,0,0,15,0,0,0,0,0,0,0,0,0,0,0,15,0,0,0,0,0,0,0
0,0,0,0,0,0,0,0,15,15,0,0,0,0,0,0,0,15,15,0,0,0,0,0,0,0,0
0,0,0,0,0,0,0,0,0,0,15,15,15,15,15,15,15,0,0,0,0,0,0,0,0,0,0
0,0,0,0,0,0,0,0,0,0,0,0,0,0,0,0,0,0,0,0,0,0,0,0,0,0,0
0,0,0,0,0,0,0,0,0,0,0,0,0,0,0,0,0,0,0,0,0,0,0,0,0,0,0
0,0,0,0,0,0,0,0,0,0,0,0,0,0,0,0,0,0,0,0,0,0,0,0,0,0,0
endlayer

layer
0,0,0,0,0,0,0,0,0,0,0,0,0,0,0,0,0,0,0,0,0,0,0,0,0,0,0
0,0,0,0,0,0,0,0,0,0,0,0,0,0,0,0,0,0,0,0,0,0,0,0,0,0,0
0,0,0,0,0,0,0,0,0,0,0,0,0,0,0,0,0,0,0,0,0,0,0,0,0,0,0
0,0,0,0,0,0,0,0,0,0,15,15,15,15,15,15,15,0,0,0,0,0,0,0,0,0,0
0,0,0,0,0,0,0,0,15,15,0,0,0,0,0,0,0,15,15,0,0,0,0,0,0,0,0
0,0,0,0,0,0,0,15,0,0,0,0,0,0,0,0,0,0,0,15,0,0,0,0,0,0,0
0,0,0,0,0,0,15,29,0,0,0,0,0,0,0,0,0,0,0,29,15,0,0,0,0,0,0
0,0,0,0,0,15,29,0,0,0,0,0,0,0,0,0,0,0,0,0,29,15,0,0,0,0,0
0,0,0,0,15,0,0,0,0,0,0,0,0,0,0,0,0,0,0,0,0,0,15,0,0,0,0
0,0,0,0,15,0,0,0,0,0,0,0,0,0,0,0,0,0,0,0,0,0,15,0,0,0,0
0,0,0,15,0,0,0,0,0,0,0,0,0,0,0,0,0,0,0,0,0,0,0,15,0,0,0
0,0,0,15,0,0,0,0,0,0,0,0,0,0,0,0,0,0,0,0,0,0,0,15,0,0,0
0,0,0,15,0,0,0,0,0,0,0,0,0,0,0,0,0,0,0,0,0,0,0,15,0,0,0
0,0,0,15,0,0,0,0,0,0,0,0,0,0,0,0,0,0,0,0,0,0,0,15,0,0,0
0,0,0,15,0,0,0,0,0,0,0,0,0,0,0,0,0,0,0,0,0,0,0,15,0,0,0
0,0,0,15,0,0,0,0,0,0,0,0,0,0,0,0,0,0,0,0,0,0,0,15,0,0,0
0,0,0,15,0,0,0,0,0,0,0,0,0,0,0,0,0,0,0,0,0,0,0,15,0,0,0
0,0,0,0,15,0,0,0,0,0,0,0,0,0,0,0,0,0,0,0,0,0,15,0,0,0,0
0,0,0,0,15,0,0,0,0,0,0,0,0,0,0,0,0,0,0,0,0,0,15,0,0,0,0
0,0,0,0,0,15,29,0,0,0,0,0,0,0,0,0,0,0,0,0,29,15,0,0,0,0,0
0,0,0,0,0,0,15,29,0,0,0,0,0,0,0,0,0,0,0,29,15,0,0,0,0,0,0
0,0,0,0,0,0,0,15,0,0,0,0,0,0,0,0,0,0,0,15,0,0,0,0,0,0,0
0,0,0,0,0,0,0,0,15,15,0,0,0,0,0,0,0,15,15,0,0,0,0,0,0,0,0
0,0,0,0,0,0,0,0,0,0,15,15,15,15,15,15,15,0,0,0,0,0,0,0,0,0,0
0,0,0,0,0,0,0,0,0,0,0,0,0,0,0,0,0,0,0,0,0,0,0,0,0,0,0
0,0,0,0,0,0,0,0,0,0,0,0,0,0,0,0,0,0,0,0,0,0,0,0,0,0,0
0,0,0,0,0,0,0,0,0,0,0,0,0,0,0,0,0,0,0,0,0,0,0,0,0,0,0
endlayer

layer
0,0,0,0,0,0,0,0,0,0,0,0,0,0,0,0,0,0,0,0,0,0,0,0,0,0,0
0,0,0,0,0,0,0,0,0,0,0,0,0,0,0,0,0,0,0,0,0,0,0,0,0,0,0
0,0,0,0,0,0,0,0,0,0,0,0,0,0,0,0,0,0,0,0,0,0,0,0,0,0,0
0,0,0,0,0,0,0,0,0,0,18,18,18,18,18,18,18,0,0,0,0,0,0,0,0,0,0
0,0,0,0,0,0,0,0,18,18,0,0,0,0,0,0,0,18,18,0,0,0,0,0,0,0,0
0,0,0,0,0,0,18,18,0,0,0,0,0,0,0,0,0,0,0,18,18,0,0,0,0,0,0
0,0,0,0,0,18,0,0,0,0,0,0,0,0,0,0,0,0,0,0,0,18,0,0,0,0,0
0,0,0,0,0,18,0,0,0,0,0,0,0,0,0,0,0,0,0,0,0,18,0,0,0,0,0
0,0,0,0,18,0,0,0,0,0,0,0,0,0,0,0,0,0,0,0,0,0,18,0,0,0,0
0,0,0,0,18,0,0,0,0,0,0,0,0,0,0,0,0,0,0,0,0,0,18,0,0,0,0
0,0,0,18,0,0,0,0,0,0,0,0,0,0,0,0,0,0,0,0,0,0,0,18,0,0,0
0,0,0,18,0,0,0,0,0,0,0,0,0,0,0,0,0,0,0,0,0,0,0,18,0,0,0
0,0,0,18,0,0,0,0,0,0,0,0,0,0,0,0,0,0,0,0,0,0,0,18,0,0,0
0,0,0,18,0,0,0,0,0,0,0,0,0,0,0,0,0,0,0,0,0,0,0,18,0,0,0
0,0,0,18,0,0,0,0,0,0,0,0,0,0,0,0,0,0,0,0,0,0,0,18,0,0,0
0,0,0,18,0,0,0,0,0,0,0,0,0,0,0,0,0,0,0,0,0,0,0,18,0,0,0
0,0,0,18,0,0,0,0,0,0,0,0,0,0,0,0,0,0,0,0,0,0,0,18,0,0,0
0,0,0,0,18,0,0,0,0,0,0,0,0,0,0,0,0,0,0,0,0,0,18,0,0,0,0
0,0,0,0,18,0,0,0,0,0,0,0,0,0,0,0,0,0,0,0,0,0,18,0,0,0,0
0,0,0,0,0,18,0,0,0,0,0,0,0,0,0,0,0,0,0,0,0,18,0,0,0,0,0
0,0,0,0,0,18,0,0,0,0,0,0,0,0,0,0,0,0,0,0,0,18,0,0,0,0,0
0,0,0,0,0,0,18,18,0,0,0,0,0,0,0,0,0,0,0,18,18,0,0,0,0,0,0
0,0,0,0,0,0,0,0,18,18,0,0,0,0,0,0,0,18,18,0,0,0,0,0,0,0,0
0,0,0,0,0,0,0,0,0,0,18,18,18,18,18,18,18,0,0,0,0,0,0,0,0,0,0
0,0,0,0,0,0,0,0,0,0,0,0,0,0,0,0,0,0,0,0,0,0,0,0,0,0,0
0,0,0,0,0,0,0,0,0,0,0,0,0,0,0,0,0,0,0,0,0,0,0,0,0,0,0
0,0,0,0,0,0,0,0,0,0,0,0,0,0,0,0,0,0,0,0,0,0,0,0,0,0,0
endlayer

layer
0,0,0,0,0,0,0,0,0,0,0,0,0,0,0,0,0,0,0,0,0,0,0,0,0,0,0
0,0,0,0,0,0,0,0,0,0,0,0,0,0,0,0,0,0,0,0,0,0,0,0,0,0,0
0,0,0,0,0,0,0,0,0,0,18,18,18,18,18,18,18,0,0,0,0,0,0,0,0,0,0
0,0,0,0,0,0,0,0,18,18,0,0,0,0,0,0,0,18,18,0,0,0,0,0,0,0,0
0,0,0,0,0,0,18,18,0,0,0,0,0,0,0,0,0,0,0,18,18,0,0,0,0,0,0
0,0,0,0,0,18,0,0,0,0,0,0,0,0,0,0,0,0,0,0,0,18,0,0,0,0,0
0,0,0,0,18,0,0,0,0,0,0,0,0,0,0,0,0,0,0,0,0,0,18,0,0,0,0
0,0,0,0,18,0,0,0,0,0,0,0,0,0,0,0,0,0,0,0,0,0,18,0,0,0,0
0,0,0,18,0,0,0,0,0,0,0,0,0,0,0,0,0,0,0,0,0,0,0,18,0,0,0
0,0,0,18,0,0,0,0,0,0,0,0,0,0,0,0,0,0,0,0,0,0,0,18,0,0,0
0,0,18,0,0,0,0,0,0,0,0,0,0,0,0,0,0,0,0,0,0,0,0,0,18,0,0
0,0,18,0,0,0,0,0,0,0,0,0,0,0,0,0,0,0,0,0,0,0,0,0,18,0,0
0,0,18,0,0,0,0,0,0,0,0,0,0,0,0,0,0,0,0,0,0,0,0,0,18,0,0
0,0,18,0,0,0,0,0,0,0,0,0,0,0,0,0,0,0,0,0,0,0,0,0,18,0,0
0,0,18,0,0,0,0,0,0,0,0,0,0,0,0,0,0,0,0,0,0,0,0,0,18,0,0
0,0,18,0,0,0,0,0,0,0,0,0,0,0,0,0,0,0,0,0,0,0,0,0,18,0,0
0,0,18,0,0,0,0,0,0,0,0,0,0,0,0,0,0,0,0,0,0,0,0,0,18,0,0
0,0,0,18,0,0,0,0,0,0,0,0,0,0,0,0,0,0,0,0,0,0,0,18,0,0,0
0,0,0,18,0,0,0,0,0,0,0,0,0,0,0,0,0,0,0,0,0,0,0,18,0,0,0
0,0,0,0,18,0,0,0,0,0,0,0,0,0,0,0,0,0,0,0,0,0,18,0,0,0,0
0,0,0,0,18,0,0,0,0,0,0,0,0,0,0,0,0,0,0,0,0,0,18,0,0,0,0
0,0,0,0,0,18,0,0,0,0,0,0,0,0,0,0,0,0,0,0,0,18,0,0,0,0,0
0,0,0,0,0,0,18,18,0,0,0,0,0,0,0,0,0,0,0,18,18,0,0,0,0,0,0
0,0,0,0,0,0,0,0,18,18,0,0,0,0,0,0,0,18,18,0,0,0,0,0,0,0,0
0,0,0,0,0,0,0,0,0,0,18,18,18,18,18,18,18,0,0,0,0,0,0,0,0,0,0
0,0,0,0,0,0,0,0,0,0,0,0,0,0,0,0,0,0,0,0,0,0,0,0,0,0,0
0,0,0,0,0,0,0,0,0,0,0,0,0,0,0,0,0,0,0,0,0,0,0,0,0,0,0
endlayer

layer
0,0,0,0,0,0,0,0,0,0,0,0,0,0,0,0,0,0,0,0,0,0,0,0,0,0,0
0,0,0,0,0,0,0,0,0,0,0,0,0,0,0,0,0,0,0,0,0,0,0,0,0,0,0
0,0,0,0,0,0,0,0,0,0,6,6,6,6,6,6,6,0,0,0,0,0,0,0,0,0,0
0,0,0,0,0,0,0,0,6,6,0,0,0,0,0,0,0,6,6,0,0,0,0,0,0,0,0
0,0,0,0,0,0,6,6,0,0,0,0,0,0,0,0,0,0,0,6,6,0,0,0,0,0,0
0,0,0,0,0,6,0,0,0,0,0,0,0,0,0,0,0,0,0,0,0,6,0,0,0,0,0
0,0,0,0,6,0,0,0,0,0,0,0,0,0,0,0,0,0,0,0,0,0,6,0,0,0,0
0,0,0,0,6,0,0,0,0,0,0,0,0,0,0,0,0,0,0,0,0,0,6,0,0,0,0
0,0,0,6,0,0,0,0,0,0,0,0,0,0,0,0,0,0,0,0,0,0,0,6,0,0,0
0,0,0,6,0,0,0,0,0,0,0,0,0,0,0,0,0,0,0,0,0,0,0,6,0,0,0
0,0,6,0,0,0,0,0,0,0,0,0,0,0,0,0,0,0,0,0,0,0,0,0,6,0,0
0,0,6,0,0,0,0,0,0,0,0,0,0,0,0,0,0,0,0,0,0,0,0,0,6,0,0
0,0,6,0,0,0,0,0,0,0,0,0,0,0,0,0,0,0,0,0,0,0,0,0,6,0,0
0,0,6,0,0,0,0,0,0,0,0,0,0,0,0,0,0,0,0,0,0,0,0,0,6,0,0
0,0,6,0,0,0,0,0,0,0,0,0,0,0,0,0,0,0,0,0,0,0,0,0,6,0,0
0,0,6,0,0,0,0,0,0,0,0,0,0,0,0,0,0,0,0,0,0,0,0,0,6,0,0
0,0,6,0,0,0,0,0,0,0,0,0,0,0,0,0,0,0,0,0,0,0,0,0,6,0,0
0,0,0,6,0,0,0,0,0,0,0,0,0,0,0,0,0,0,0,0,0,0,0,6,0,0,0
0,0,0,6,0,0,0,0,0,0,0,0,0,0,0,0,0,0,0,0,0,0,0,6,0,0,0
0,0,0,0,6,0,0,0,0,0,0,0,0,0,0,0,0,0,0,0,0,0,6,0,0,0,0
0,0,0,0,6,0,0,0,0,0,0,0,0,0,0,0,0,0,0,0,0,0,6,0,0,0,0
0,0,0,0,0,6,0,0,0,0,0,0,0,0,0,0,0,0,0,0,0,6,0,0,0,0,0
0,0,0,0,0,0,6,6,0,0,0,0,0,0,0,0,0,0,0,6,6,0,0,0,0,0,0
0,0,0,0,0,0,0,0,6,6,0,0,0,0,0,0,0,6,6,0,0,0,0,0,0,0,0
0,0,0,0,0,0,0,0,0,0,6,6,6,6,6,6,6,0,0,0,0,0,0,0,0,0,0
0,0,0,0,0,0,0,0,0,0,0,0,0,0,0,0,0,0,0,0,0,0,0,0,0,0,0
0,0,0,0,0,0,0,0,0,0,0,0,0,0,0,0,0,0,0,0,0,0,0,0,0,0,0
endlayer

layer
0,0,0,0,0,0,0,0,0,0,0,0,0,0,0,0,0,0,0,0,0,0,0,0,0,0,0
0,0,0,0,0,0,0,0,0,0,0,0,0,0,0,0,0,0,0,0,0,0,0,0,0,0,0
0,0,0,0,0,0,0,0,0,0,6,6,6,6,6,6,6,0,0,0,0,0,0,0,0,0,0
0,0,0,0,0,0,0,0,6,6,30,30,30,30,30,30,30,6,6,0,0,0,0,0,0,0,0
0,0,0,0,0,0,6,6,30,30,30,30,30,30,30,30,30,30,30,6,6,0,0,0,0,0,0
0,0,0,0,0,6,30,30,30,30,30,30,30,30,30,30,30,30,30,30,30,6,0,0,0,0,0
0,0,0,0,6,30,30,30,30,30,30,30,30,30,30,30,30,30,30,30,30,30,6,0,0,0,0
0,0,0,0,6,30,30,30,30,30,30,30,30,30,30,30,30,30,30,30,30,30,6,0,0,0,0
0,0,0,6,30,30,30,30,30,30,30,30,30,30,30,30,30,30,30,30,30,30,30,6,0,0,0
0,0,0,6,30,30,30,30,30,30,30,30,30,30,30,30,30,30,30,30,30,30,30,6,0,0,0
0,0,6,30,30,30,30,30,30,30,30,30,30,30,30,30,30,30,30,30,30,30,30,30,6,0,0
0,0,6,30,30,30,30,30,30,30,30,30,30,30,30,30,30,30,30,30,30,30,30,30,6,0,0
0,0,6,30,30,30,30,30,30,30,30,30,30,30,30,30,30,30,30,30,30,30,30,30,6,0,0
0,0,6,30,30,30,30,30,30,30,30,30,30,30,30,30,30,30,30,30,30,30,30,30,6,0,0
0,0,6,30,30,30,30,30,30,30,30,30,30,30,30,30,30,30,30,30,30,30,30,30,6,0,0
0,0,6,30,30,30,30,30,30,30,30,30,30,30,30,30,30,30,30,30,30,30,30,30,6,0,0
0,0,6,30,30,30,30,30,30,30,30,30,30,30,30,30,30,30,30,30,30,30,30,30,6,0,0
0,0,0,6,30,30,30,30,30,30,30,30,30,30,30,30,30,30,30,30,30,30,30,6,0,0,0
0,0,0,6,30,30,30,30,30,30,30,30,30,30,30,30,30,30,30,30,30,30,30,6,0,0,0
0,0,0,0,6,30,30,30,30,30,30,30,30,30,30,30,30,30,30,30,30,30,6,0,0,0,0
0,0,0,0,6,30,30,30,30,30,30,30,30,30,30,30,30,30,30,30,30,30,6,0,0,0,0
0,0,0,0,0,6,30,30,30,30,30,30,30,30,30,30,30,30,30,30,30,6,0,0,0,0,0
0,0,0,0,0,0,6,6,30,30,30,30,30,30,30,30,30,30,30,6,6,0,0,0,0,0,0
0,0,0,0,0,0,0,0,6,6,30,30,30,30,30,30,30,6,6,0,0,0,0,0,0,0,0
0,0,0,0,0,0,0,0,0,0,6,6,6,6,6,6,6,0,0,0,0,0,0,0,0,0,0
0,0,0,0,0,0,0,0,0,0,0,0,0,0,0,0,0,0,0,0,0,0,0,0,0,0,0
0,0,0,0,0,0,0,0,0,0,0,0,0,0,0,0,0,0,0,0,0,0,0,0,0,0,0
endlayer

