# Converted from schematic
# THIS TEMPLATE USES DEFAULTS!  Please edit for corrections.
# If you need help, consult template_rules.txt

weight=2
embed_into_distance=11
acceptable_target_blocks=1,2,3,12,13,250
dimensions=31,27,27
allowable_overhang=0
max_cut_in=2
cut_in_buffer=1
max_leveling=2
leveling_buffer=1
preserve_water=0
preserve_lava=0
preserve_plants=0


rule1=0,100,3134-10
rule2=0,100,300
rule3=0,100,2843-4
rule4=0,66,308
rule5=0,100,2843-6
rule6=0,100,2018
rule7=0,75,1752,3511,3511,3511,3511
rule8=0,100,3507
rule9=0,100,2843-8
rule10=0,66,1757
rule11=0,100,2781-5,2781-5,2781-5,2781-5,2781-9
rule12=0,95,300
rule13=0,100,2838-8
rule14=0,100,2788-15
rule15=0,100,3223
rule16=0,100,327
rule17=0,100,1760-0,3510,3510,3510,3510
rule18=0,66,1757-1
rule19=0,100,3508
rule20=0,100,2838-4
rule21=0,100,327
rule22=0,100,4094-10


layer
2,2,2,2,2,2,2,2,2,2,2,2,2,2,2,2,2,2,2,2,2,1,1,1,1,1,1
2,2,2,2,2,2,2,2,2,2,2,2,2,2,2,2,2,2,2,2,2,2,1,1,1,1,1
2,2,2,2,2,2,2,2,2,2,2,2,2,2,2,2,2,2,2,2,2,2,2,2,2,1,1
2,2,2,2,2,2,2,2,2,2,3,3,2,2,3,3,3,2,2,2,2,2,2,2,2,1,1
2,1,2,2,2,2,2,2,2,2,2,3,3,2,3,3,3,3,3,2,2,2,2,2,2,1,1
2,1,2,2,2,2,2,2,3,2,2,2,3,2,3,3,2,3,3,3,3,2,2,2,2,1,1
1,2,2,2,2,3,2,2,2,3,2,2,3,3,3,3,3,3,3,3,3,3,2,2,2,1,1
1,1,2,2,2,2,2,2,3,3,2,2,3,2,3,2,3,3,3,3,2,3,2,2,2,1,1
1,1,2,2,2,2,2,2,3,2,2,3,2,3,3,3,3,2,3,3,2,3,3,2,2,1,1
1,1,2,2,2,2,2,2,2,2,2,3,3,3,3,3,3,3,2,3,3,3,3,2,2,1,1
1,1,2,2,2,2,2,2,2,0,0,0,3,4,3,0,3,3,2,3,2,3,3,3,2,1,1
1,1,2,3,2,2,2,2,2,0,0,3,3,0,3,3,0,3,3,0,0,3,3,3,2,1,1
1,1,2,3,2,2,2,2,0,0,0,3,3,0,0,0,0,0,0,3,3,3,3,3,2,1,1
1,2,2,2,2,2,2,2,0,0,3,3,3,0,3,0,0,3,3,3,3,3,3,3,2,1,1
1,1,2,2,3,2,2,2,0,3,0,3,3,0,3,0,0,3,3,3,3,3,3,3,2,1,1
1,1,2,3,2,3,2,2,0,0,3,3,3,0,0,0,3,3,3,3,3,3,3,3,2,1,1
1,1,2,3,3,2,3,2,0,3,3,3,3,4,0,3,3,3,3,3,3,3,3,3,2,1,1
1,1,2,2,3,3,2,2,0,3,3,3,3,3,0,3,3,3,3,3,3,3,3,2,2,1,1
1,1,2,2,3,2,3,3,3,3,3,3,3,3,3,3,3,3,3,3,3,3,3,2,2,1,1
1,1,2,2,2,2,2,3,3,3,3,0,3,3,0,3,3,3,3,3,3,3,2,2,2,1,1
1,1,2,2,2,3,2,3,0,0,3,0,3,3,3,3,3,3,3,3,2,3,2,2,2,1,1
1,1,2,2,2,2,3,0,3,3,3,3,3,2,3,3,3,3,3,3,3,2,2,2,2,1,1
1,1,2,2,2,2,2,2,3,3,0,3,3,3,3,3,3,3,3,2,2,2,2,2,2,1,1
1,1,2,2,2,2,2,2,2,2,3,3,3,2,3,3,3,2,2,2,2,2,2,2,2,1,1
1,1,2,2,2,2,2,2,2,2,2,2,3,3,3,2,2,2,2,2,2,2,2,2,2,1,1
1,1,1,1,1,1,1,1,1,1,1,1,1,1,1,1,1,1,1,1,1,1,1,1,1,1,1
1,1,1,1,1,1,1,1,1,1,1,1,1,1,1,1,1,1,1,1,1,1,1,1,1,1,1
endlayer

layer
2,2,2,2,2,2,2,2,2,2,2,2,2,2,2,2,2,2,2,2,2,2,2,2,2,2,2
2,2,2,2,2,2,2,2,2,2,2,2,2,2,2,2,2,2,2,2,2,2,2,2,2,2,2
2,2,2,2,2,2,2,2,2,2,2,2,2,2,2,5,2,2,2,2,2,2,2,2,2,2,2
2,2,2,2,2,2,2,2,5,2,2,2,2,2,2,2,2,0,5,2,2,2,2,2,2,2,2
2,2,2,2,2,2,2,5,2,2,2,2,2,2,2,2,2,0,0,5,5,2,2,2,2,2,2
2,2,2,2,2,5,5,2,2,2,2,2,2,2,2,2,2,2,2,2,5,2,2,2,2,2,2
2,2,2,2,2,2,2,2,2,2,2,2,2,2,2,2,2,2,2,2,2,2,5,2,2,2,2
2,2,2,2,2,2,2,2,2,2,2,2,2,2,2,2,2,2,2,2,2,2,2,2,2,2,2
2,2,2,2,2,2,2,2,2,2,2,2,2,2,2,2,2,2,2,2,2,2,0,5,2,2,2
2,2,2,2,2,2,2,2,2,0,0,0,0,0,0,0,0,2,2,2,2,0,0,5,2,2,2
2,2,5,2,2,2,2,2,0,0,0,0,0,7,7,0,7,2,2,2,0,2,2,0,5,2,2
2,2,5,2,2,2,2,2,0,0,0,0,7,0,0,7,0,0,0,0,0,0,0,0,5,2,2
2,2,2,2,2,2,2,2,0,0,0,7,0,0,0,0,0,0,0,0,0,0,0,0,5,2,2
2,2,2,2,2,2,2,2,0,0,0,0,0,0,6,0,0,6,0,0,0,0,0,0,5,2,2
2,2,2,2,2,2,2,2,0,0,0,0,7,0,0,0,0,0,0,0,0,0,0,0,5,2,2
2,2,5,0,2,2,2,2,0,0,7,0,7,0,0,0,6,0,0,0,0,0,0,0,5,2,2
2,2,5,2,2,2,2,2,0,0,7,0,7,7,0,6,0,0,0,0,0,0,0,0,5,2,2
2,2,2,5,0,2,2,2,0,0,0,0,0,0,0,0,0,0,0,0,0,0,0,5,2,2,2
2,2,2,5,0,2,2,2,0,0,0,0,0,0,0,0,0,0,0,0,0,0,0,5,2,2,2
2,2,2,2,0,2,2,2,0,0,0,0,0,0,0,0,0,2,2,2,2,0,5,2,2,2,2
2,2,2,2,5,5,0,0,0,0,0,0,0,0,0,0,0,2,2,2,2,5,5,2,2,2,2
2,2,2,2,2,5,5,0,0,0,0,0,0,0,0,0,2,0,0,0,5,5,2,2,2,2,2
2,2,2,2,2,2,5,5,0,0,0,0,2,2,2,0,0,0,0,5,5,2,2,2,2,2,2
2,2,2,2,2,2,2,2,5,5,0,0,2,2,2,0,0,5,5,2,2,2,2,2,2,2,2
2,2,2,2,2,2,2,2,2,2,5,5,2,2,2,5,5,2,2,2,2,2,2,2,2,2,2
2,2,2,2,2,2,2,2,2,2,2,2,2,2,2,2,2,2,2,2,2,2,2,2,2,2,2
2,2,2,2,2,2,2,2,2,2,2,2,2,2,2,2,2,2,2,2,2,2,2,2,2,2,2
endlayer

layer
2,2,2,2,2,2,2,2,2,2,2,2,2,2,2,2,2,2,2,2,2,2,2,2,2,2,2
2,2,2,2,2,2,2,2,2,2,2,2,2,2,2,2,2,2,2,2,2,2,2,2,2,2,2
2,2,2,2,2,2,2,2,2,2,2,2,2,2,2,5,5,2,2,2,2,2,2,2,2,2,2
2,2,2,2,2,2,2,2,2,2,2,2,2,2,2,2,2,5,5,2,2,2,2,2,2,2,2
2,2,2,2,2,2,2,2,2,2,2,2,2,2,2,2,2,0,0,5,5,2,2,2,2,2,2
2,2,2,2,2,5,2,2,2,2,2,2,2,2,2,2,2,2,2,0,5,5,2,2,2,2,2
2,2,2,2,5,2,2,2,2,2,2,2,2,2,2,2,2,2,2,0,0,2,2,2,2,2,2
2,2,2,2,5,2,2,2,2,2,2,2,2,2,2,2,2,2,2,2,2,2,2,2,2,2,2
2,2,2,2,2,2,2,2,2,2,2,2,2,2,2,0,0,2,2,2,2,2,0,5,2,2,2
2,2,2,2,2,2,2,2,0,0,0,0,0,0,0,0,0,2,2,2,2,0,0,5,2,2,2
2,2,5,2,2,0,0,0,0,0,0,0,0,0,0,0,0,0,0,2,0,2,2,0,5,2,2
2,2,2,2,2,2,2,2,0,0,0,0,0,0,0,0,0,0,0,0,0,0,0,0,5,2,2
2,2,2,2,2,2,2,2,0,0,0,0,0,0,0,0,0,0,0,0,0,0,0,0,5,2,2
2,2,5,0,2,2,2,2,0,0,0,0,0,0,0,0,0,0,0,0,0,0,0,0,5,2,2
2,2,5,2,2,2,2,2,0,0,0,0,0,0,0,0,0,0,0,0,0,0,0,0,5,2,2
2,2,5,0,2,2,2,0,0,0,0,0,0,0,0,0,0,0,0,0,0,0,0,0,5,2,2
2,2,5,2,2,2,2,0,0,0,7,8,7,7,0,0,0,0,0,0,0,0,0,0,5,2,2
2,2,2,5,0,2,2,0,0,0,0,0,0,0,0,0,0,0,0,0,0,0,0,5,2,2,2
2,2,2,5,0,2,2,2,0,0,0,0,0,0,0,0,0,0,0,0,0,0,0,5,2,2,2
2,2,2,2,5,2,2,2,0,0,0,0,0,0,0,0,0,0,2,0,0,0,5,2,2,2,2
2,2,2,2,5,5,0,0,0,0,0,0,0,0,0,0,0,0,2,2,0,5,5,2,2,2,2
2,2,2,2,2,5,5,0,0,0,0,0,0,0,0,0,0,0,0,0,5,5,2,2,2,2,2
2,2,2,2,2,2,5,5,0,0,0,0,0,0,0,0,0,0,0,5,5,2,2,2,2,2,2
2,2,2,2,2,2,2,2,5,5,0,0,0,2,0,0,0,5,5,2,2,2,2,2,2,2,2
2,2,2,2,2,2,2,2,2,2,5,5,2,2,2,5,5,2,2,2,2,2,2,2,2,2,2
2,2,2,2,2,2,2,2,2,2,2,2,2,2,2,2,2,2,2,2,2,2,2,2,2,2,2
2,2,2,2,2,2,2,2,2,2,2,2,2,2,2,2,2,2,2,2,2,2,2,2,2,2,2
endlayer

layer
2,2,2,2,2,2,2,2,2,2,2,2,2,2,2,2,2,2,2,2,2,2,2,2,2,2,2
2,2,2,2,2,2,2,2,2,2,2,2,2,2,2,2,2,2,2,2,2,2,2,2,2,2,2
2,2,2,2,2,2,2,2,2,2,2,2,2,2,2,2,2,2,2,2,2,2,2,2,2,2,2
2,2,2,2,2,2,2,2,2,2,2,2,2,2,2,2,2,2,2,2,2,2,2,2,2,2,2
2,2,2,2,2,2,2,2,2,2,2,2,2,2,2,2,2,9,9,2,2,2,2,2,2,2,2
2,2,2,2,2,2,2,2,2,2,2,2,2,2,2,2,2,2,2,9,2,2,2,2,2,2,2
2,2,2,2,2,2,2,2,2,2,2,2,2,2,2,2,2,2,2,0,9,2,2,2,2,2,2
2,2,2,2,2,2,2,2,2,2,2,2,0,2,2,0,2,2,2,2,0,2,2,2,2,2,2
2,2,2,2,2,2,2,2,2,2,0,2,0,2,0,0,0,2,2,2,0,0,9,2,2,2,2
2,2,2,2,2,2,2,2,0,0,0,0,0,0,0,0,0,0,0,2,0,0,0,2,2,2,2
2,2,2,9,2,0,0,0,0,0,0,0,0,0,0,0,0,0,0,0,0,0,2,9,2,2,2
2,2,2,9,2,2,2,2,0,0,0,0,0,0,0,0,0,0,0,0,0,0,0,9,2,2,2
2,2,2,9,2,2,2,2,0,0,0,0,0,0,0,0,0,0,0,0,0,0,0,9,2,2,2
2,2,2,9,2,2,2,2,0,0,0,0,0,0,0,0,0,0,0,0,0,0,0,9,2,2,2
2,2,2,0,2,2,2,0,0,0,0,0,0,0,0,0,0,0,0,0,0,0,0,9,2,2,2
2,2,2,9,2,0,0,0,0,0,0,0,0,0,0,0,0,0,0,0,0,0,0,9,2,2,2
2,2,2,0,2,2,2,0,0,0,7,0,0,0,0,0,0,0,0,0,0,0,0,9,2,2,2
2,2,2,2,9,2,2,0,0,0,0,0,0,0,0,0,0,0,0,0,0,0,9,2,2,2,2
2,2,2,2,9,2,2,2,0,0,0,0,0,0,0,0,0,0,0,0,0,0,9,2,2,2,2
2,2,2,2,2,9,2,2,0,0,0,0,0,0,0,0,0,0,0,0,0,9,2,2,2,2,2
2,2,2,2,2,2,0,0,0,0,0,0,0,0,0,0,0,0,0,0,9,2,2,2,2,2,2
2,2,2,2,2,2,2,9,0,0,0,0,0,0,0,0,0,0,0,9,2,2,2,2,2,2,2
2,2,2,2,2,2,2,2,9,9,0,0,0,0,0,0,0,9,9,2,2,2,2,2,2,2,2
2,2,2,2,2,2,2,2,2,2,9,9,0,0,0,9,9,2,2,2,2,2,2,2,2,2,2
2,2,2,2,2,2,2,2,2,2,2,2,2,2,2,2,2,2,2,2,2,2,2,2,2,2,2
2,2,2,2,2,2,2,2,2,2,2,2,2,2,2,2,2,2,2,2,2,2,2,2,2,2,2
2,2,2,2,2,2,2,2,2,2,2,2,2,2,2,2,2,2,2,2,2,2,2,2,2,2,2
endlayer

layer
2,2,2,2,2,2,2,2,2,2,2,2,2,2,2,2,2,2,2,2,2,2,2,2,2,2,2
2,2,2,2,2,2,2,2,2,2,2,2,2,2,2,2,2,2,2,2,2,2,2,2,2,2,2
2,2,2,2,2,2,2,2,2,2,2,2,2,2,2,2,2,2,2,2,2,2,2,2,2,2,2
2,2,2,2,2,2,2,2,2,2,2,2,2,2,2,2,2,2,2,2,2,2,2,2,2,2,2
2,2,2,2,2,2,2,2,2,2,2,2,2,2,2,2,2,9,9,2,2,2,2,2,2,2,2
2,2,2,2,2,2,2,2,2,2,2,2,2,2,2,2,2,2,2,9,2,2,2,2,2,2,2
2,2,2,2,2,2,2,2,2,2,2,2,2,2,2,2,2,2,2,0,2,2,2,2,2,2,2
2,2,2,2,2,2,2,2,2,2,0,2,0,2,0,0,2,2,2,2,0,9,2,2,2,2,2
2,2,2,2,2,2,2,2,0,0,0,2,0,0,0,0,0,0,2,2,0,0,9,2,2,2,2
2,2,2,2,2,2,2,0,0,0,0,0,0,0,0,0,0,0,0,0,0,0,9,2,2,2,2
2,2,2,2,2,0,0,0,0,0,0,0,0,0,0,0,0,0,0,0,0,0,0,9,2,2,2
2,2,2,2,2,0,0,0,0,0,0,0,0,0,0,0,0,0,0,0,0,0,0,9,2,2,2
2,2,2,2,2,2,0,0,0,0,0,0,0,0,0,0,0,0,0,0,0,0,0,9,2,2,2
2,2,2,9,2,2,2,0,0,0,0,0,0,0,0,0,0,0,0,0,0,0,0,9,2,2,2
2,2,2,9,2,2,0,0,0,0,0,0,0,0,0,0,0,0,0,0,0,0,0,9,2,2,2
2,2,2,9,2,0,0,0,0,0,0,0,0,0,0,0,0,0,0,0,0,0,0,9,2,2,2
2,2,2,9,2,2,0,0,0,0,7,0,0,0,0,0,0,0,0,0,0,0,0,9,2,2,2
2,2,2,2,2,2,2,0,0,0,0,0,0,0,0,0,0,0,0,0,0,0,9,2,2,2,2
2,2,2,2,9,2,2,2,0,0,0,0,0,0,0,0,0,0,0,0,0,0,9,2,2,2,2
2,2,2,2,2,9,2,0,0,0,0,0,0,0,0,0,0,0,0,0,0,9,2,2,2,2,2
2,2,2,2,2,2,9,0,0,0,0,0,0,0,0,0,0,0,0,0,9,2,2,2,2,2,2
2,2,2,2,2,2,2,9,0,0,0,0,0,0,0,0,0,0,0,9,2,2,2,2,2,2,2
2,2,2,2,2,2,2,2,2,9,0,0,0,0,0,0,0,9,9,2,2,2,2,2,2,2,2
2,2,2,2,2,2,2,2,2,2,9,9,9,0,9,9,9,2,2,2,2,2,2,2,2,2,2
2,2,2,2,2,2,2,2,2,2,2,2,2,2,2,2,2,2,2,2,2,2,2,2,2,2,2
2,2,2,2,2,2,2,2,2,2,2,2,2,2,2,2,2,2,2,2,2,2,2,2,2,2,2
2,2,2,2,2,2,2,2,2,2,2,2,2,2,2,2,2,2,2,2,2,2,2,2,2,2,2
endlayer

layer
2,2,2,2,2,2,2,2,2,2,2,2,2,2,2,2,2,2,2,2,2,2,2,2,2,2,2
2,2,2,2,2,2,2,2,2,2,2,2,2,2,2,2,2,2,2,2,2,2,2,2,2,2,2
2,2,2,2,2,2,2,2,2,2,2,2,2,2,2,2,2,2,2,2,2,2,2,2,2,2,2
2,2,2,2,2,2,2,2,2,2,2,2,2,2,2,2,2,2,2,2,2,2,2,2,2,2,2
2,2,2,2,2,2,2,2,2,2,2,2,2,2,2,2,2,9,9,2,2,2,2,2,2,2,2
2,2,2,2,2,2,2,2,2,2,2,2,2,2,2,2,2,2,2,9,2,2,2,2,2,2,2
2,2,2,2,2,2,2,2,2,2,0,2,2,0,0,0,2,2,2,0,9,2,2,2,2,2,2
2,2,2,2,2,2,2,2,2,2,0,2,0,0,0,0,0,2,2,2,0,9,2,2,2,2,2
2,2,2,2,2,2,2,2,0,0,0,0,0,0,0,0,0,0,0,2,0,0,9,2,2,2,2
2,2,2,2,2,2,0,0,0,0,0,0,0,0,0,0,0,0,0,0,0,0,9,2,2,2,2
2,2,2,2,0,0,0,0,0,0,0,0,0,0,0,0,0,0,0,0,0,0,0,9,2,2,2
2,2,2,2,0,0,0,0,0,0,0,0,0,0,0,0,0,0,0,0,0,0,0,9,2,2,2
2,2,2,2,2,2,0,0,0,0,0,0,0,0,0,0,0,0,0,0,0,0,0,9,2,2,2
2,2,2,2,2,0,0,0,0,0,0,0,0,0,0,0,0,0,0,0,0,0,0,9,2,2,2
2,2,2,2,2,0,0,0,0,0,0,0,0,0,0,0,0,0,0,0,0,0,0,9,2,2,2
2,2,2,9,2,0,0,0,0,0,10,0,0,0,0,0,0,0,0,0,0,0,0,9,2,2,2
2,2,2,2,2,2,0,0,0,0,7,0,0,0,0,0,0,0,0,0,0,0,0,9,2,2,2
2,2,2,2,9,2,2,0,0,0,0,0,0,0,0,0,0,0,0,0,0,0,9,2,2,2,2
2,2,2,2,9,2,2,0,0,0,0,0,0,0,0,0,0,0,0,0,0,0,9,2,2,2,2
2,2,2,2,2,9,0,0,0,0,0,0,0,0,0,0,0,0,0,0,0,9,2,2,2,2,2
2,2,2,2,2,2,9,0,0,0,0,0,0,0,0,0,0,0,0,0,9,2,2,2,2,2,2
2,2,2,2,2,2,2,2,0,0,0,0,0,0,0,0,0,0,0,9,2,2,2,2,2,2,2
2,2,2,2,2,2,2,2,9,9,0,0,0,0,0,0,0,9,9,2,2,2,2,2,2,2,2
2,2,2,2,2,2,2,2,2,2,9,9,9,9,9,9,9,2,2,2,2,2,2,2,2,2,2
2,2,2,2,2,2,2,2,2,2,2,2,2,2,2,2,2,2,2,2,2,2,2,2,2,2,2
2,2,2,2,2,2,2,2,2,2,2,2,2,2,2,2,2,2,2,2,2,2,2,2,2,2,2
2,2,2,2,2,2,2,2,2,2,2,2,2,2,2,2,2,2,2,2,2,2,2,2,2,2,2
endlayer

layer
2,2,2,2,2,2,2,2,2,2,2,2,2,2,2,2,2,2,2,2,2,2,2,2,2,2,2
2,2,2,2,2,2,2,2,2,2,2,2,2,2,2,2,2,2,2,2,2,2,2,2,2,2,2
2,2,2,2,2,2,2,2,2,2,2,2,2,2,2,2,2,2,2,2,2,2,2,2,2,2,2
2,2,2,2,2,2,2,2,2,2,2,2,2,2,2,2,2,2,2,2,2,2,2,2,2,2,2
2,2,2,2,2,2,2,2,2,2,2,2,2,2,2,2,2,2,2,2,2,2,2,2,2,2,2
2,2,2,2,2,2,2,2,2,2,2,2,2,2,2,0,2,2,2,2,2,2,2,2,2,2,2
2,2,2,2,2,2,2,2,2,2,0,2,2,0,0,0,0,2,2,11,2,2,2,2,2,2,2
2,2,2,2,2,2,2,2,2,0,0,0,0,0,0,0,0,0,0,2,11,2,2,2,2,2,2
2,2,2,2,2,2,2,2,0,0,0,0,0,0,0,0,0,0,0,0,0,0,2,2,2,2,2
2,2,2,2,2,2,0,0,0,0,0,0,0,0,0,0,0,0,0,0,0,0,2,2,2,2,2
2,2,2,2,0,0,0,0,0,0,0,0,0,0,0,0,0,0,0,0,0,0,0,2,2,2,2
2,2,2,2,0,0,0,0,0,0,0,0,0,0,0,0,0,0,0,0,0,0,0,2,2,2,2
2,2,2,2,2,2,0,0,0,0,0,0,0,0,0,0,0,0,0,0,0,0,11,2,2,2,2
2,2,2,2,2,0,0,0,0,0,0,0,0,0,0,0,0,0,0,0,0,0,11,2,2,2,2
2,2,2,2,2,0,0,0,0,0,0,0,0,0,0,0,0,0,0,0,0,0,11,2,2,2,2
2,2,2,2,0,0,0,0,0,0,0,0,0,0,0,0,0,0,0,0,0,0,11,2,2,2,2
2,2,2,2,2,0,0,0,0,0,7,0,0,0,0,0,0,0,0,0,0,0,11,2,2,2,2
2,2,2,2,2,0,0,0,0,0,0,0,0,0,0,0,0,0,0,0,0,11,2,2,2,2,2
2,2,2,2,2,0,0,0,0,0,0,0,0,0,0,0,0,0,0,0,0,11,2,2,2,2,2
2,2,2,2,2,2,11,0,0,0,0,0,0,0,0,0,0,0,0,0,11,2,2,2,2,2,2
2,2,2,2,2,2,0,11,0,0,0,0,0,0,0,0,0,0,0,11,2,2,2,2,2,2,2
2,2,2,2,2,2,2,2,11,0,0,0,0,0,0,0,0,11,11,2,2,2,2,2,2,2,2
2,2,2,2,2,2,2,2,2,2,0,0,11,11,11,11,11,2,2,2,2,2,2,2,2,2,2
2,2,2,2,2,2,2,2,2,2,2,2,2,2,2,2,2,2,2,2,2,2,2,2,2,2,2
2,2,2,2,2,2,2,2,2,2,2,2,2,2,2,2,2,2,2,2,2,2,2,2,2,2,2
2,2,2,2,2,2,2,2,2,2,2,2,2,2,2,2,2,2,2,2,2,2,2,2,2,2,2
2,2,2,2,2,2,2,2,2,2,2,2,2,2,2,2,2,2,2,2,2,2,2,2,2,2,2
endlayer

layer
2,2,2,2,2,2,2,2,2,2,2,2,2,2,2,2,2,2,2,2,2,2,2,2,2,2,2
2,2,2,2,2,2,2,2,2,2,2,2,2,2,2,2,2,2,2,2,2,2,2,2,2,2,2
2,2,2,2,2,2,2,2,2,2,2,2,2,2,2,2,2,2,2,2,2,2,2,2,2,2,2
2,2,2,2,2,2,2,2,2,2,2,2,2,2,2,2,2,2,2,2,2,2,2,2,2,2,2
2,2,2,2,2,2,2,2,2,2,2,2,2,2,2,2,2,2,2,2,2,2,2,2,2,2,2
2,2,2,2,2,2,2,2,2,2,2,0,2,0,2,0,0,2,2,2,2,2,2,2,2,2,2
2,2,2,2,2,2,0,0,0,0,0,0,2,0,0,0,0,2,2,2,2,2,2,2,2,2,2
2,2,2,2,0,2,0,0,0,0,0,0,0,0,0,0,0,0,0,0,11,2,2,2,2,2,2
2,2,2,2,2,2,0,0,0,0,0,0,0,0,0,0,0,0,0,0,0,11,2,2,2,2,2
2,2,2,2,2,0,0,0,0,0,0,0,0,0,0,0,0,0,0,0,0,0,2,2,2,2,2
2,2,2,2,0,0,0,0,0,0,0,0,0,0,0,0,0,0,0,0,0,0,0,2,2,2,2
2,2,2,2,0,0,0,0,0,0,0,0,0,0,0,0,0,0,0,0,0,0,0,2,2,2,2
2,2,2,2,0,0,0,0,0,0,0,0,0,0,0,0,0,0,0,0,0,0,11,2,2,2,2
2,2,2,2,0,0,0,0,0,0,0,0,0,0,0,0,0,0,0,0,0,0,11,2,2,2,2
2,2,2,2,2,0,0,0,0,0,0,0,0,0,0,0,0,0,0,0,0,0,11,2,2,2,2
2,2,2,2,0,0,0,0,0,0,0,0,10,0,0,0,0,0,0,0,0,0,11,2,2,2,2
2,2,2,2,0,0,0,0,0,0,7,7,7,0,0,0,0,0,0,0,0,0,11,2,2,2,2
2,2,2,0,0,0,0,0,0,0,0,0,0,0,0,0,0,0,0,0,0,11,2,2,2,2,2
2,2,2,2,2,0,0,0,0,0,0,0,0,0,0,0,0,0,0,0,0,11,2,2,2,2,2
2,2,2,2,2,2,11,0,0,0,0,0,0,0,0,0,0,0,0,0,11,2,2,2,2,2,2
2,2,2,2,2,2,0,11,0,0,0,0,0,0,0,0,0,0,0,2,2,2,2,2,2,2,2
2,2,2,2,2,2,2,2,11,0,0,0,0,0,0,0,0,11,11,2,2,2,2,2,2,2,2
2,2,2,2,2,2,2,2,2,2,0,0,11,11,11,11,11,2,2,2,2,2,2,2,2,2,2
2,2,2,2,2,2,2,2,2,2,2,2,2,2,2,2,2,2,2,2,2,2,2,2,2,2,2
2,2,2,2,2,2,2,2,2,2,2,2,2,2,2,2,2,2,2,2,2,2,2,2,2,2,2
2,2,2,2,2,2,2,2,2,2,2,2,2,2,2,2,2,2,2,2,2,2,2,2,2,2,2
2,2,2,2,2,2,2,2,2,2,2,2,2,2,2,2,2,2,2,2,2,2,2,2,2,2,2
endlayer

layer
2,2,2,2,2,2,2,2,2,2,2,2,2,2,2,2,2,2,2,2,2,2,2,2,2,2,2
2,2,2,2,2,2,2,2,2,2,2,2,2,2,2,2,2,2,2,2,2,2,2,2,2,2,2
2,2,2,2,2,2,2,2,2,2,2,2,2,2,2,2,2,2,2,2,2,2,2,2,2,2,2
2,2,2,2,2,2,2,2,2,2,2,2,2,2,2,2,2,2,2,2,2,2,2,2,2,2,2
2,2,2,2,0,0,2,2,2,2,2,2,2,2,2,0,2,2,2,2,2,2,2,2,2,2,2
2,2,2,2,2,0,0,0,0,0,0,0,0,0,0,0,0,0,2,2,2,2,2,2,2,2,2
2,2,2,2,2,0,0,0,0,0,0,0,0,0,0,0,0,0,2,2,2,2,2,2,2,2,2
2,2,2,2,0,0,0,0,0,0,0,0,0,0,0,0,0,0,0,0,11,2,2,2,2,2,2
2,2,2,0,0,0,0,0,0,0,0,0,0,0,0,0,0,0,0,0,0,11,2,2,2,2,2
2,2,2,2,0,0,0,0,0,0,0,0,0,0,0,0,0,0,0,0,0,11,2,2,2,2,2
2,2,2,2,0,0,0,0,0,0,0,0,0,0,0,0,0,0,0,0,0,0,0,2,2,2,2
2,2,2,2,0,0,0,0,0,0,0,0,0,0,0,0,0,0,0,0,0,0,11,2,2,2,2
2,2,2,2,0,0,0,0,0,0,0,0,0,0,0,0,0,0,0,0,0,0,11,2,2,2,2
2,2,2,2,0,0,0,0,0,0,0,0,0,0,0,0,0,0,0,0,0,0,11,2,2,2,2
2,2,2,2,0,0,0,0,0,0,0,0,0,0,0,0,0,0,0,0,0,0,11,2,2,2,2
2,2,2,2,0,0,0,0,0,0,0,0,0,0,0,0,0,0,0,0,0,0,11,2,2,2,2
2,2,2,2,0,0,0,0,0,0,0,0,0,0,0,0,0,0,0,0,0,0,11,2,2,2,2
2,2,2,0,0,0,0,0,0,0,0,0,0,0,0,0,0,0,0,0,0,11,2,2,2,2,2
2,2,2,2,0,0,0,0,0,0,0,0,0,0,0,0,0,0,0,0,0,11,2,2,2,2,2
2,2,2,2,2,2,0,0,0,0,0,0,0,0,0,0,0,0,0,0,11,2,2,2,2,2,2
2,2,2,2,2,2,0,11,0,0,0,0,0,0,0,0,0,0,0,2,2,2,2,2,2,2,2
2,2,2,2,2,2,0,0,11,11,0,0,0,0,0,0,0,2,2,2,2,2,2,2,2,2,2
2,2,2,2,2,2,2,2,2,2,0,11,11,11,11,11,11,2,2,2,2,2,2,2,2,2,2
2,2,2,2,2,2,2,2,2,2,2,2,2,2,2,2,2,2,2,2,2,2,2,2,2,2,2
2,2,2,2,2,2,2,2,2,2,2,2,2,2,2,2,2,2,2,2,2,2,2,2,2,2,2
2,2,2,2,2,2,2,2,2,2,2,2,2,2,2,2,2,2,2,2,2,2,2,2,2,2,2
2,2,2,2,2,2,2,2,2,2,2,2,2,2,2,2,2,2,2,2,2,2,2,2,2,2,2
endlayer

layer
2,2,2,2,2,2,2,2,2,2,2,2,2,2,2,2,2,2,2,2,2,2,2,2,2,2,2
2,2,2,2,2,2,2,2,2,2,2,2,2,2,2,2,2,2,2,2,2,2,2,2,2,2,2
2,2,2,2,2,2,2,2,2,2,2,2,2,2,2,2,2,2,2,2,2,2,2,2,2,2,2
2,2,2,2,2,2,2,2,2,2,2,2,2,2,2,2,2,2,2,2,2,2,2,2,2,2,2
2,2,2,0,0,0,2,2,2,2,2,2,2,2,2,0,0,2,2,2,2,2,2,2,2,2,2
2,2,2,2,0,0,0,0,0,0,0,0,0,0,0,0,0,0,2,2,2,2,2,2,2,2,2
2,2,2,2,2,0,0,0,0,0,0,0,0,0,0,0,0,0,2,2,2,2,2,2,2,2,2
2,2,2,2,0,0,0,0,0,0,0,0,0,0,0,0,0,0,0,0,11,2,2,2,2,2,2
2,2,2,0,0,0,0,0,0,0,0,0,0,0,0,0,0,0,0,0,0,11,2,2,2,2,2
2,2,2,2,0,0,0,0,0,0,0,0,0,0,0,0,0,0,0,0,0,2,2,2,2,2,2
2,2,2,2,0,0,0,0,0,0,0,0,0,0,0,0,0,0,0,0,0,0,11,2,2,2,2
2,2,2,2,0,0,0,0,0,0,0,0,0,0,0,0,0,0,0,0,0,0,11,2,2,2,2
2,2,2,2,0,0,0,0,0,0,0,0,0,0,0,0,0,0,0,0,0,0,11,2,2,2,2
2,2,2,2,0,0,0,0,0,0,0,0,0,0,0,0,0,0,0,0,0,0,11,2,2,2,2
2,2,2,0,0,0,0,0,0,0,0,0,0,0,0,0,0,0,0,0,0,0,11,2,2,2,2
2,2,2,2,0,0,0,0,0,0,0,0,0,0,0,0,0,0,0,0,0,0,11,2,2,2,2
2,2,2,2,0,0,0,0,0,0,0,0,0,0,0,0,0,0,0,0,0,0,11,2,2,2,2
2,2,2,0,0,0,0,0,0,0,0,0,0,0,0,0,0,0,0,0,0,11,2,2,2,2,2
2,2,2,2,0,0,0,0,0,0,0,0,0,0,0,0,0,0,0,0,0,11,2,2,2,2,2
2,2,2,2,2,0,0,0,0,0,0,0,0,0,0,0,0,0,0,0,11,2,2,2,2,2,2
2,2,2,2,2,2,0,11,0,0,0,0,0,0,0,0,0,0,0,2,2,2,2,2,2,2,2
2,2,2,2,2,2,0,0,11,11,0,0,0,0,0,0,0,2,2,2,2,2,2,2,2,2,2
2,2,2,2,2,2,2,2,2,2,11,11,11,11,11,11,11,2,2,2,2,2,2,2,2,2,2
2,2,2,2,2,2,2,2,2,2,2,2,2,2,2,2,2,2,2,2,2,2,2,2,2,2,2
2,2,2,2,2,2,2,2,2,2,2,2,2,2,2,2,2,2,2,2,2,2,2,2,2,2,2
2,2,2,2,2,2,2,2,2,2,2,2,2,2,2,2,2,2,2,2,2,2,2,2,2,2,2
2,2,2,2,2,2,2,2,2,2,2,2,2,2,2,2,2,2,2,2,2,2,2,2,2,2,2
endlayer

layer
12,12,12,12,12,12,12,12,12,12,12,12,12,12,12,12,12,12,12,12,12,12,12,12,12,12,12
12,12,12,12,12,12,12,12,12,12,12,12,12,12,12,12,12,12,12,12,12,12,12,12,12,12,12
12,12,12,12,12,12,12,12,12,12,12,12,12,12,12,12,12,12,12,12,12,12,12,12,12,12,12
12,12,12,12,12,12,12,12,12,12,12,12,12,12,12,12,12,12,12,12,12,12,12,12,12,12,12
12,12,12,0,0,0,0,0,0,0,0,12,12,12,12,0,0,12,12,12,12,12,12,12,12,12,12
12,12,12,12,0,0,0,0,0,0,0,0,0,0,0,0,0,0,0,12,12,12,12,12,12,12,12
12,12,12,12,12,0,0,0,0,0,0,0,0,0,0,0,0,0,0,12,12,12,12,12,12,12,12
12,12,12,0,0,0,0,0,0,0,0,0,0,0,0,0,0,0,0,0,11,12,12,12,12,12,12
12,12,12,0,0,0,0,0,0,0,0,0,0,0,0,0,0,0,0,0,0,12,12,12,12,12,12
12,12,12,12,0,0,0,0,0,0,0,0,0,0,0,0,0,0,0,0,0,0,0,12,12,12,12
12,12,12,0,0,0,0,0,0,0,0,0,0,0,0,0,0,0,0,0,0,0,12,12,12,12,12
12,12,12,0,0,0,0,0,0,0,0,0,0,0,0,0,0,0,0,0,0,0,11,12,12,12,12
12,12,12,12,0,0,0,0,0,0,0,0,0,0,0,0,0,0,0,0,0,0,11,12,12,12,12
12,12,12,0,0,0,0,0,0,0,0,0,0,0,0,0,0,0,0,0,0,0,11,12,12,12,12
12,12,0,0,0,0,0,0,0,0,0,0,0,0,0,0,0,0,0,0,0,0,11,12,12,12,12
12,12,0,0,0,0,0,0,0,0,0,0,0,0,0,0,0,0,0,0,0,0,11,12,12,12,12
12,12,12,12,0,0,0,0,0,0,0,0,0,0,0,0,0,0,0,0,0,0,11,12,12,12,12
12,12,12,0,0,0,0,0,0,0,0,0,0,0,0,0,0,0,0,0,0,11,12,12,12,12,12
12,12,0,0,0,0,0,0,0,0,0,0,0,0,0,0,0,0,0,0,0,11,12,12,12,12,12
12,12,0,12,0,0,0,0,0,0,0,0,0,0,0,0,0,0,0,0,11,12,12,12,12,12,12
12,12,12,12,12,0,0,11,0,0,0,0,0,0,0,0,0,0,0,11,12,12,12,12,12,12,12
12,12,12,0,0,0,0,0,11,11,0,0,0,0,0,0,0,11,11,12,12,12,12,12,12,12,12
12,12,0,0,0,12,12,12,12,12,11,11,11,11,11,11,11,12,12,12,12,12,12,12,12,12,12
12,12,12,0,12,12,12,12,12,12,12,12,12,12,12,12,12,12,12,12,12,12,12,12,12,12,12
12,12,12,12,12,12,12,12,12,12,12,12,12,12,12,12,12,12,12,12,12,12,12,12,12,12,12
12,12,12,12,12,12,12,12,12,12,12,12,12,12,12,12,12,12,12,12,12,12,12,12,12,12,12
12,12,12,12,12,12,12,12,12,12,12,12,12,12,12,12,12,12,12,12,12,12,12,12,12,12,12
endlayer

layer
0,0,0,0,0,0,0,0,0,0,0,0,0,0,0,0,0,0,0,0,0,0,0,0,0,0,0
0,0,0,0,0,0,0,0,0,0,0,0,0,0,0,0,0,0,0,0,0,0,0,0,0,0,0
0,0,0,0,0,0,0,0,0,0,0,0,0,0,0,0,0,0,0,0,0,0,0,0,0,0,0
0,0,0,0,0,0,0,0,0,0,0,0,0,0,0,0,0,0,0,0,0,0,0,0,0,0,0
0,0,0,0,0,0,0,0,0,0,0,0,0,0,0,0,0,0,0,0,0,0,0,0,0,0,0
0,0,0,0,0,0,0,0,0,0,0,0,0,0,0,0,0,0,0,0,0,0,0,0,0,0,0
0,0,0,0,0,0,0,0,0,0,0,0,0,0,0,0,0,0,0,11,0,0,0,0,0,0,0
0,0,0,0,0,0,0,0,0,0,0,0,0,0,0,0,0,0,0,0,11,0,0,0,0,0,0
0,0,0,0,0,0,0,0,0,0,0,0,0,0,0,0,0,0,0,0,0,0,0,0,0,0,0
0,0,0,0,0,0,0,0,0,0,0,0,0,0,0,0,0,0,0,0,0,0,0,0,0,0,0
0,0,0,0,0,0,0,0,0,0,0,0,0,0,0,0,0,0,0,0,0,0,0,0,0,0,0
0,0,0,0,0,0,0,0,0,0,0,0,0,0,0,0,0,0,0,0,0,0,11,0,0,0,0
0,0,0,0,0,0,0,0,0,0,0,0,0,0,0,0,0,0,0,0,0,0,11,0,0,0,0
0,0,0,0,0,0,0,0,0,0,0,0,0,0,0,0,0,0,0,0,0,0,11,0,0,0,0
0,0,0,0,0,0,0,0,0,0,0,0,0,0,0,0,0,0,0,0,0,0,11,0,0,0,0
0,0,0,0,0,0,0,0,0,0,0,0,0,0,0,0,0,0,0,0,0,0,11,0,0,0,0
0,0,0,0,0,0,0,0,0,0,0,0,0,0,0,0,0,0,0,0,0,0,11,0,0,0,0
0,0,0,0,0,0,0,0,0,0,0,0,0,0,0,0,0,0,0,0,0,11,0,0,0,0,0
0,0,0,0,0,0,0,0,0,0,0,0,0,0,0,0,0,0,0,0,0,11,0,0,0,0,0
0,0,0,0,0,0,0,0,0,0,0,0,0,0,0,0,0,0,0,0,11,0,0,0,0,0,0
0,0,0,0,0,0,0,11,0,0,0,0,0,0,0,0,0,0,0,11,0,0,0,0,0,0,0
0,0,0,0,0,0,0,0,11,11,0,0,0,0,0,0,0,11,11,0,0,0,0,0,0,0,0
0,0,0,0,0,0,0,0,0,0,11,11,11,11,11,11,11,0,0,0,0,0,0,0,0,0,0
0,0,0,0,0,0,0,0,0,0,0,0,0,0,0,0,0,0,0,0,0,0,0,0,0,0,0
0,0,0,0,0,0,0,0,0,0,0,0,0,0,0,0,0,0,0,0,0,0,0,0,0,0,0
0,0,0,0,0,0,0,0,0,0,0,0,0,0,0,0,0,0,0,0,0,0,0,0,0,0,0
0,0,0,0,0,0,0,0,0,0,0,0,0,0,0,0,0,0,0,0,0,0,0,0,0,0,0
endlayer

layer
0,0,0,0,0,0,0,0,0,0,0,0,0,0,0,0,0,0,0,0,0,0,0,0,0,0,0
0,0,0,0,0,0,0,0,0,0,0,0,0,0,0,0,0,0,0,0,0,0,0,0,0,0,0
0,0,0,0,0,0,0,0,0,0,0,0,0,0,0,0,0,0,0,0,0,0,0,0,0,0,0
0,0,0,0,0,0,0,0,0,0,0,0,0,0,0,0,0,0,0,0,0,0,0,0,0,0,0
0,0,0,0,0,0,0,0,0,0,0,0,0,0,0,0,0,0,0,0,0,0,0,0,0,0,0
0,0,0,0,0,0,0,0,0,0,0,0,0,0,0,0,0,0,11,0,0,0,0,0,0,0,0
0,0,0,0,0,0,0,0,0,0,0,0,0,0,0,0,0,0,0,11,0,0,0,0,0,0,0
0,0,0,0,0,0,0,0,0,0,0,0,0,0,0,0,0,0,0,0,11,0,0,0,0,0,0
0,0,0,0,0,0,0,0,0,0,0,0,0,0,0,0,0,0,0,0,0,11,0,0,0,0,0
0,0,0,0,0,0,0,0,0,0,0,0,0,0,0,0,0,0,0,0,0,0,0,0,0,0,0
0,0,0,0,0,0,0,0,0,0,0,0,0,0,0,0,0,0,0,0,0,0,11,0,0,0,0
0,0,0,0,0,0,0,0,0,0,0,0,0,0,0,0,0,0,0,0,0,0,11,0,0,0,0
0,0,0,0,0,0,0,0,0,0,0,0,0,0,0,0,0,0,0,0,0,0,11,0,0,0,0
0,0,0,0,0,0,0,0,0,0,0,0,0,0,0,0,0,0,0,0,0,0,11,0,0,0,0
0,0,0,0,0,0,0,0,0,0,0,0,0,0,0,0,0,0,0,0,0,0,11,0,0,0,0
0,0,0,0,0,0,0,0,0,0,0,0,0,0,0,0,0,0,0,0,0,0,11,0,0,0,0
0,0,0,0,0,0,0,0,0,0,0,0,0,0,0,0,0,0,0,0,0,0,11,0,0,0,0
0,0,0,0,0,0,0,0,0,0,0,0,0,0,0,0,0,0,0,0,0,11,0,0,0,0,0
0,0,0,0,0,0,0,0,0,0,0,0,0,0,0,0,0,0,0,0,0,11,0,0,0,0,0
0,0,0,0,0,0,0,0,0,0,0,0,0,0,0,0,0,0,0,0,11,0,0,0,0,0,0
0,0,0,0,0,0,0,11,0,0,0,0,0,0,0,0,0,0,0,11,0,0,0,0,0,0,0
0,0,0,0,0,0,0,0,11,0,0,0,0,0,0,0,0,11,11,0,0,0,0,0,0,0,0
0,0,0,0,0,0,0,0,0,0,11,11,11,11,11,11,11,0,0,0,0,0,0,0,0,0,0
0,0,0,0,0,0,0,0,0,0,0,0,0,0,0,0,0,0,0,0,0,0,0,0,0,0,0
0,0,0,0,0,0,0,0,0,0,0,0,0,0,0,0,0,0,0,0,0,0,0,0,0,0,0
0,0,0,0,0,0,0,0,0,0,0,0,0,0,0,0,0,0,0,0,0,0,0,0,0,0,0
0,0,0,0,0,0,0,0,0,0,0,0,0,0,0,0,0,0,0,0,0,0,0,0,0,0,0
endlayer

layer
0,0,0,0,0,0,0,0,0,0,0,0,0,0,0,0,0,0,0,0,0,0,0,0,0,0,0
0,0,0,0,0,0,0,0,0,0,0,0,0,0,0,0,0,0,0,0,0,0,0,0,0,0,0
0,0,0,0,0,0,0,0,0,0,0,0,0,0,0,0,0,0,0,0,0,0,0,0,0,0,0
0,0,0,0,0,0,0,0,0,0,0,0,0,0,0,0,0,0,0,0,0,0,0,0,0,0,0
0,0,0,0,0,0,0,0,0,0,0,0,0,0,0,0,0,0,0,0,0,0,0,0,0,0,0
0,0,0,0,0,0,0,0,0,0,0,0,0,0,0,0,0,13,13,0,0,0,0,0,0,0,0
0,0,0,0,0,0,0,0,0,0,0,0,0,0,0,0,0,0,14,13,0,0,0,0,0,0,0
0,0,0,0,0,0,0,0,0,0,0,0,0,0,0,0,0,0,14,14,13,0,0,0,0,0,0
0,0,0,0,0,0,0,0,0,0,0,0,0,0,0,0,0,0,14,14,0,13,0,0,0,0,0
0,0,0,0,0,0,0,0,0,0,0,0,0,0,0,0,0,0,15,0,14,13,0,0,0,0,0
0,0,0,0,0,0,0,0,0,0,0,0,0,0,0,0,15,15,15,15,0,14,13,0,0,0,0
0,0,0,0,0,0,0,0,0,0,0,0,0,0,15,15,15,15,15,15,14,14,13,0,0,0,0
0,0,0,0,0,0,0,0,0,0,0,0,0,0,0,15,15,15,15,15,14,14,13,0,0,0,0
0,0,0,0,0,0,0,0,0,0,0,0,0,15,15,15,15,15,15,15,14,14,13,0,0,0,0
0,0,0,0,0,0,0,0,0,0,0,0,15,15,15,15,15,15,15,15,0,0,13,0,0,0,0
0,0,0,0,0,0,0,0,0,0,0,0,0,0,15,15,15,15,15,15,14,14,13,0,0,0,0
0,0,0,0,0,0,0,0,0,0,0,0,0,15,15,15,15,15,15,15,14,0,13,0,0,0,0
0,0,0,0,0,0,0,0,0,0,0,0,14,14,14,15,15,15,15,0,14,13,0,0,0,0,0
0,0,0,0,0,0,0,0,0,0,0,0,0,14,14,15,15,15,0,14,0,13,0,0,0,0,0
0,0,0,0,0,0,0,0,0,0,0,0,0,14,14,15,15,14,14,0,13,0,0,0,0,0,0
0,0,0,0,0,0,0,13,0,0,0,0,0,14,14,14,14,14,14,13,0,0,0,0,0,0,0
0,0,0,0,0,0,0,0,13,13,0,14,14,16,14,0,14,13,13,0,0,0,0,0,0,0,0
0,0,0,0,0,0,0,0,0,0,13,13,13,13,13,13,13,0,0,0,0,0,0,0,0,0,0
0,0,0,0,0,0,0,0,0,0,0,0,0,0,0,0,0,0,0,0,0,0,0,0,0,0,0
0,0,0,0,0,0,0,0,0,0,0,0,0,0,0,0,0,0,0,0,0,0,0,0,0,0,0
0,0,0,0,0,0,0,0,0,0,0,0,0,0,0,0,0,0,0,0,0,0,0,0,0,0,0
0,0,0,0,0,0,0,0,0,0,0,0,0,0,0,0,0,0,0,0,0,0,0,0,0,0,0
endlayer

layer
0,0,0,0,0,0,0,0,0,0,0,0,0,0,0,0,0,0,0,0,0,0,0,0,0,0,0
0,0,0,0,0,0,0,0,0,0,0,0,0,0,0,0,0,0,0,0,0,0,0,0,0,0,0
0,0,0,0,0,0,0,0,0,0,0,0,0,0,0,0,0,0,0,0,0,0,0,0,0,0,0
0,0,0,0,0,0,0,0,0,0,0,0,0,0,0,0,0,0,0,0,0,0,0,0,0,0,0
0,0,0,0,0,0,0,0,0,0,0,0,0,0,0,0,0,0,0,0,0,0,0,0,0,0,0
0,0,0,0,0,0,0,0,0,0,0,0,0,0,0,0,0,0,11,0,0,0,0,0,0,0,0
0,0,0,0,0,0,0,0,0,0,0,0,0,0,0,0,0,0,0,11,0,0,0,0,0,0,0
0,0,0,0,0,0,0,0,0,0,0,0,0,0,0,0,0,0,0,0,11,0,0,0,0,0,0
0,0,0,0,0,0,0,0,0,0,0,0,0,0,0,0,0,0,0,0,0,11,0,0,0,0,0
0,0,0,0,0,0,0,0,0,0,0,0,0,0,0,0,0,0,0,0,0,11,0,0,0,0,0
0,0,0,0,0,0,0,0,0,0,0,0,0,0,0,0,0,0,0,0,0,0,11,0,0,0,0
0,0,0,0,0,0,0,0,0,0,0,0,0,0,17,17,0,0,0,0,0,0,11,0,0,0,0
0,0,0,0,0,0,0,0,0,0,0,0,0,0,17,17,0,0,0,0,0,0,11,0,0,0,0
0,0,0,0,0,0,0,0,0,0,0,0,0,0,17,0,0,0,0,0,0,0,11,0,0,0,0
0,0,0,0,0,0,0,0,0,0,0,0,0,0,17,17,0,0,0,0,0,0,11,0,0,0,0
0,0,0,0,0,0,0,0,0,0,0,0,17,17,17,17,0,0,0,0,0,0,11,0,0,0,0
0,0,0,0,0,0,0,0,0,0,0,0,0,0,0,0,0,0,0,0,0,0,11,0,0,0,0
0,0,0,0,0,0,0,0,0,0,0,0,0,0,0,0,0,0,0,0,0,11,0,0,0,0,0
0,0,0,0,0,0,0,0,0,0,0,0,0,0,0,0,0,0,0,0,0,11,0,0,0,0,0
0,0,0,0,0,0,0,0,0,0,0,0,0,0,0,0,0,0,0,0,11,0,0,0,0,0,0
0,0,0,0,0,0,0,0,0,0,0,0,0,0,0,0,0,0,0,11,0,0,0,0,0,0,0
0,0,0,0,0,0,0,0,11,11,0,0,0,0,0,0,0,11,11,0,0,0,0,0,0,0,0
0,0,0,0,0,0,0,0,0,0,0,11,11,11,11,11,11,0,0,0,0,0,0,0,0,0,0
0,0,0,0,0,0,0,0,0,0,0,0,0,0,0,0,0,0,0,0,0,0,0,0,0,0,0
0,0,0,0,0,0,0,0,0,0,0,0,0,0,0,0,0,0,0,0,0,0,0,0,0,0,0
0,0,0,0,0,0,0,0,0,0,0,0,0,0,0,0,0,0,0,0,0,0,0,0,0,0,0
0,0,0,0,0,0,0,0,0,0,0,0,0,0,0,0,0,0,0,0,0,0,0,0,0,0,0
endlayer

layer
0,0,0,0,0,0,0,0,0,0,0,0,0,0,0,0,0,0,0,0,0,0,0,0,0,0,0
0,0,0,0,0,0,0,0,0,0,0,0,0,0,0,0,0,0,0,0,0,0,0,0,0,0,0
0,0,0,0,0,0,0,0,0,0,0,0,0,0,0,0,0,0,0,0,0,0,0,0,0,0,0
0,0,0,0,0,0,0,0,0,0,0,0,0,0,0,0,0,0,0,0,0,0,0,0,0,0,0
0,0,0,0,0,0,0,0,0,0,0,0,0,0,0,0,0,0,0,0,0,0,0,0,0,0,0
0,0,0,0,0,0,0,0,0,0,0,0,0,0,0,0,0,0,11,0,0,0,0,0,0,0,0
0,0,0,0,0,0,0,0,0,0,0,0,0,0,0,0,0,0,0,11,0,0,0,0,0,0,0
0,0,0,0,0,0,0,0,0,0,0,0,0,0,0,0,0,0,0,0,11,0,0,0,0,0,0
0,0,0,0,0,0,0,0,0,0,0,0,0,0,0,0,0,0,0,0,0,11,0,0,0,0,0
0,0,0,0,0,0,0,0,0,0,0,0,0,0,0,0,0,0,0,0,0,11,0,0,0,0,0
0,0,0,0,0,0,0,0,0,0,0,0,0,0,0,0,0,0,0,0,0,0,11,0,0,0,0
0,0,0,0,0,0,0,0,0,0,0,0,0,0,18,17,0,0,0,0,0,0,11,0,0,0,0
0,0,0,0,0,0,0,0,0,0,0,0,0,0,0,18,0,0,0,0,0,0,11,0,0,0,0
0,0,0,0,0,0,0,0,0,0,0,0,0,0,0,0,0,0,0,0,0,0,11,0,0,0,0
0,0,0,0,0,0,0,0,0,0,0,0,0,0,0,18,0,0,0,0,0,0,11,0,0,0,0
0,0,0,0,0,0,0,0,0,0,0,0,0,17,19,17,0,0,0,0,0,0,11,0,0,0,0
0,0,0,0,0,0,0,0,0,0,0,0,0,0,0,0,0,0,0,0,0,0,11,0,0,0,0
0,0,0,0,0,0,0,0,0,0,0,0,0,0,0,0,0,0,0,0,0,11,0,0,0,0,0
0,0,0,0,0,0,0,0,0,0,0,0,0,0,0,0,0,0,0,0,0,11,0,0,0,0,0
0,0,0,0,0,0,0,0,0,0,0,0,0,0,0,0,0,0,0,0,11,0,0,0,0,0,0
0,0,0,0,0,0,0,0,0,0,0,0,0,0,0,0,0,0,0,11,0,0,0,0,0,0,0
0,0,0,0,0,0,0,0,0,0,0,0,0,0,0,0,0,11,11,0,0,0,0,0,0,0,0
0,0,0,0,0,0,0,0,0,0,0,11,11,11,11,11,11,0,0,0,0,0,0,0,0,0,0
0,0,0,0,0,0,0,0,0,0,0,0,0,0,0,0,0,0,0,0,0,0,0,0,0,0,0
0,0,0,0,0,0,0,0,0,0,0,0,0,0,0,0,0,0,0,0,0,0,0,0,0,0,0
0,0,0,0,0,0,0,0,0,0,0,0,0,0,0,0,0,0,0,0,0,0,0,0,0,0,0
0,0,0,0,0,0,0,0,0,0,0,0,0,0,0,0,0,0,0,0,0,0,0,0,0,0,0
endlayer

layer
0,0,0,0,0,0,0,0,0,0,0,0,0,0,0,0,0,0,0,0,0,0,0,0,0,0,0
0,0,0,0,0,0,0,0,0,0,0,0,0,0,0,0,0,0,0,0,0,0,0,0,0,0,0
0,0,0,0,0,0,0,0,0,0,0,0,0,0,0,0,0,0,0,0,0,0,0,0,0,0,0
0,0,0,0,0,0,0,0,0,0,0,0,0,0,0,0,0,0,0,0,0,0,0,0,0,0,0
0,0,0,0,0,0,0,0,0,0,0,0,0,0,0,0,0,0,0,0,0,0,0,0,0,0,0
0,0,0,0,0,0,0,0,0,0,0,0,0,0,0,0,0,0,0,0,0,0,0,0,0,0,0
0,0,0,0,0,0,0,0,0,0,0,0,0,0,0,0,0,0,0,11,0,0,0,0,0,0,0
0,0,0,0,0,0,0,0,0,0,0,0,0,0,0,0,0,0,0,0,11,0,0,0,0,0,0
0,0,0,0,0,0,0,0,0,0,0,0,0,0,0,0,0,0,0,0,0,11,0,0,0,0,0
0,0,0,0,0,0,0,0,0,0,0,0,0,0,0,0,0,0,0,0,0,11,0,0,0,0,0
0,0,0,0,0,0,0,0,0,0,0,0,0,0,0,0,0,0,0,0,0,0,11,0,0,0,0
0,0,0,0,0,0,0,0,0,0,0,0,0,0,0,17,0,0,0,0,0,0,11,0,0,0,0
0,0,0,0,0,0,0,0,0,0,0,0,0,0,0,18,0,0,0,0,0,0,11,0,0,0,0
0,0,0,0,0,0,0,0,0,0,0,0,0,0,0,0,0,0,0,0,0,0,11,0,0,0,0
0,0,0,0,0,0,0,0,0,0,0,0,0,0,0,0,0,0,0,0,0,0,11,0,0,0,0
0,0,0,0,0,0,0,0,0,0,0,0,0,18,18,17,0,0,0,0,0,0,11,0,0,0,0
0,0,0,0,0,0,0,0,0,0,0,0,0,0,0,0,0,0,0,0,0,0,11,0,0,0,0
0,0,0,0,0,0,0,0,0,0,0,0,0,0,0,0,0,0,0,0,0,11,0,0,0,0,0
0,0,0,0,0,0,0,0,0,0,0,0,0,0,0,0,0,0,0,0,0,11,0,0,0,0,0
0,0,0,0,0,0,0,0,0,0,0,0,0,0,0,0,0,0,0,0,11,0,0,0,0,0,0
0,0,0,0,0,0,0,0,0,0,0,0,0,0,0,0,0,0,0,11,0,0,0,0,0,0,0
0,0,0,0,0,0,0,0,0,0,0,0,0,0,0,0,0,11,11,0,0,0,0,0,0,0,0
0,0,0,0,0,0,0,0,0,0,11,11,0,11,11,11,11,0,0,0,0,0,0,0,0,0,0
0,0,0,0,0,0,0,0,0,0,0,0,0,0,0,0,0,0,0,0,0,0,0,0,0,0,0
0,0,0,0,0,0,0,0,0,0,0,0,0,0,0,0,0,0,0,0,0,0,0,0,0,0,0
0,0,0,0,0,0,0,0,0,0,0,0,0,0,0,0,0,0,0,0,0,0,0,0,0,0,0
0,0,0,0,0,0,0,0,0,0,0,0,0,0,0,0,0,0,0,0,0,0,0,0,0,0,0
endlayer

layer
0,0,0,0,0,0,0,0,0,0,0,0,0,0,0,0,0,0,0,0,0,0,0,0,0,0,0
0,0,0,0,0,0,0,0,0,0,0,0,0,0,0,0,0,0,0,0,0,0,0,0,0,0,0
0,0,0,0,0,0,0,0,0,0,0,0,0,0,0,0,0,0,0,0,0,0,0,0,0,0,0
0,0,0,0,0,0,0,0,0,0,0,0,0,0,0,0,0,0,0,0,0,0,0,0,0,0,0
0,0,0,0,0,0,0,0,0,0,0,0,0,0,0,0,0,0,0,0,0,0,0,0,0,0,0
0,0,0,0,0,0,0,0,0,0,0,0,0,0,0,0,0,0,0,0,0,0,0,0,0,0,0
0,0,0,0,0,0,0,0,0,0,0,0,0,0,0,0,0,0,0,11,0,0,0,0,0,0,0
0,0,0,0,0,0,0,0,0,0,0,0,0,0,0,0,0,0,0,0,11,0,0,0,0,0,0
0,0,0,0,0,0,0,0,0,0,0,0,0,0,0,0,0,0,0,0,0,11,0,0,0,0,0
0,0,0,0,0,0,0,0,0,0,0,0,0,0,0,0,0,0,0,0,0,11,0,0,0,0,0
0,0,0,0,0,0,0,0,0,0,0,0,0,0,0,0,0,0,0,0,0,0,11,0,0,0,0
0,0,0,0,0,0,0,0,0,0,0,0,0,0,0,17,0,0,0,0,0,0,11,0,0,0,0
0,0,0,0,0,0,0,0,0,0,0,0,0,0,0,0,0,0,0,0,0,0,11,0,0,0,0
0,0,0,0,0,0,0,0,0,0,0,0,0,0,0,0,0,0,0,0,0,0,11,0,0,0,0
0,0,0,0,0,0,0,0,0,0,0,0,0,0,0,18,0,0,0,0,0,0,11,0,0,0,0
0,0,0,0,0,0,0,0,0,0,0,0,0,0,0,17,0,0,0,0,0,0,11,0,0,0,0
0,0,0,0,0,0,0,0,0,0,0,0,0,0,0,0,0,0,0,0,0,0,11,0,0,0,0
0,0,0,0,0,0,0,0,0,0,0,0,0,0,0,0,0,0,0,0,0,11,0,0,0,0,0
0,0,0,0,0,0,0,0,0,0,0,0,0,0,0,0,0,0,0,0,0,11,0,0,0,0,0
0,0,0,0,0,0,0,0,0,0,0,0,0,0,0,0,0,0,0,0,11,0,0,0,0,0,0
0,0,0,0,0,0,0,0,0,0,0,0,0,0,0,0,0,0,0,11,0,0,0,0,0,0,0
0,0,0,0,0,0,0,0,0,0,0,0,0,0,0,0,0,11,11,0,0,0,0,0,0,0,0
0,0,0,0,0,0,0,0,0,0,0,11,11,11,11,11,11,0,0,0,0,0,0,0,0,0,0
0,0,0,0,0,0,0,0,0,0,0,0,0,0,0,0,0,0,0,0,0,0,0,0,0,0,0
0,0,0,0,0,0,0,0,0,0,0,0,0,0,0,0,0,0,0,0,0,0,0,0,0,0,0
0,0,0,0,0,0,0,0,0,0,0,0,0,0,0,0,0,0,0,0,0,0,0,0,0,0,0
0,0,0,0,0,0,0,0,0,0,0,0,0,0,0,0,0,0,0,0,0,0,0,0,0,0,0
endlayer

layer
0,0,0,0,0,0,0,0,0,0,0,0,0,0,0,0,0,0,0,0,0,0,0,0,0,0,0
0,0,0,0,0,0,0,0,0,0,0,0,0,0,0,0,0,0,0,0,0,0,0,0,0,0,0
0,0,0,0,0,0,0,0,0,0,0,0,0,0,0,0,0,0,0,0,0,0,0,0,0,0,0
0,0,0,0,0,0,0,0,0,0,0,0,0,0,0,0,0,0,0,0,0,0,0,0,0,0,0
0,0,0,0,0,0,0,0,0,0,0,0,0,0,0,0,0,0,0,0,0,0,0,0,0,0,0
0,0,0,0,0,0,0,0,0,0,0,0,0,0,0,0,0,0,0,0,0,0,0,0,0,0,0
0,0,0,0,0,0,0,0,0,0,0,0,0,0,0,0,0,0,0,11,0,0,0,0,0,0,0
0,0,0,0,0,0,0,0,0,0,0,0,0,0,0,0,0,0,0,0,11,0,0,0,0,0,0
0,0,0,0,0,0,0,0,0,0,0,0,0,0,0,0,0,0,0,0,0,11,0,0,0,0,0
0,0,0,0,0,0,0,0,0,0,0,0,0,0,0,0,0,0,0,0,0,11,0,0,0,0,0
0,0,0,0,0,0,0,0,0,0,0,0,0,0,0,0,0,0,0,0,0,0,11,0,0,0,0
0,0,0,0,0,0,0,0,0,0,0,0,0,0,0,17,0,0,0,0,0,0,11,0,0,0,0
0,0,0,0,0,0,0,0,0,0,0,0,0,0,0,0,0,0,0,0,0,0,11,0,0,0,0
0,0,0,0,0,0,0,0,0,0,0,0,0,0,0,0,0,0,0,0,0,0,11,0,0,0,0
0,0,0,0,0,0,0,0,0,0,0,0,0,0,0,0,0,0,0,0,0,0,11,0,0,0,0
0,0,0,0,0,0,0,0,0,0,0,0,0,0,0,17,0,0,0,0,0,0,11,0,0,0,0
0,0,0,0,0,0,0,0,0,0,0,0,0,0,0,0,0,0,0,0,0,0,11,0,0,0,0
0,0,0,0,0,0,0,0,0,0,0,0,0,0,0,0,0,0,0,0,0,11,0,0,0,0,0
0,0,0,0,0,0,0,0,0,0,0,0,0,0,0,0,0,0,0,0,0,11,0,0,0,0,0
0,0,0,0,0,0,0,0,0,0,0,0,0,0,0,0,0,0,0,0,11,0,0,0,0,0,0
0,0,0,0,0,0,0,0,0,0,0,0,0,0,0,0,0,0,0,11,0,0,0,0,0,0,0
0,0,0,0,0,0,0,0,0,0,0,0,0,0,0,0,0,11,11,0,0,0,0,0,0,0,0
0,0,0,0,0,0,0,0,0,0,0,0,11,11,11,11,11,0,0,0,0,0,0,0,0,0,0
0,0,0,0,0,0,0,0,0,0,0,0,0,0,0,0,0,0,0,0,0,0,0,0,0,0,0
0,0,0,0,0,0,0,0,0,0,0,0,0,0,0,0,0,0,0,0,0,0,0,0,0,0,0
0,0,0,0,0,0,0,0,0,0,0,0,0,0,0,0,0,0,0,0,0,0,0,0,0,0,0
0,0,0,0,0,0,0,0,0,0,0,0,0,0,0,0,0,0,0,0,0,0,0,0,0,0,0
endlayer

layer
0,0,0,0,0,0,0,0,0,0,0,0,0,0,0,0,0,0,0,0,0,0,0,0,0,0,0
0,0,0,0,0,0,0,0,0,0,0,0,0,0,0,0,0,0,0,0,0,0,0,0,0,0,0
0,0,0,0,0,0,0,0,0,0,0,0,0,0,0,0,0,0,0,0,0,0,0,0,0,0,0
0,0,0,0,0,0,0,0,0,0,0,0,0,0,0,0,0,0,0,0,0,0,0,0,0,0,0
0,0,0,0,0,0,0,0,0,0,0,0,0,0,0,0,0,0,0,0,0,0,0,0,0,0,0
0,0,0,0,0,0,0,0,0,0,0,0,0,0,0,0,0,0,0,0,0,0,0,0,0,0,0
0,0,0,0,0,0,0,0,0,0,0,0,0,0,0,0,0,0,0,0,0,0,0,0,0,0,0
0,0,0,0,0,0,0,0,0,0,0,0,0,0,0,0,0,0,0,0,11,0,0,0,0,0,0
0,0,0,0,0,0,0,0,0,0,0,0,0,0,0,0,0,0,0,0,0,11,0,0,0,0,0
0,0,0,0,0,0,0,0,0,0,0,0,0,0,0,0,0,0,0,0,0,11,0,0,0,0,0
0,0,0,0,0,0,0,0,0,0,0,0,0,0,0,0,0,0,0,0,0,0,11,0,0,0,0
0,0,0,0,0,0,0,0,0,0,0,0,0,0,0,17,0,0,0,0,0,0,11,0,0,0,0
0,0,0,0,0,0,0,0,0,0,0,0,0,0,0,0,0,0,0,0,0,0,11,0,0,0,0
0,0,0,0,0,0,0,0,0,0,0,0,0,0,0,0,0,0,0,0,0,0,11,0,0,0,0
0,0,0,0,0,0,0,0,0,0,0,0,0,0,0,0,0,0,0,0,0,0,11,0,0,0,0
0,0,0,0,0,0,0,0,0,0,0,0,0,0,0,17,0,0,0,0,0,0,11,0,0,0,0
0,0,0,0,0,0,0,0,0,0,0,0,0,0,0,0,0,0,0,0,0,0,11,0,0,0,0
0,0,0,0,0,0,0,0,0,0,0,0,0,0,0,0,0,0,0,0,0,11,0,0,0,0,0
0,0,0,0,0,0,0,0,0,0,0,0,0,0,0,0,0,0,0,0,0,11,0,0,0,0,0
0,0,0,0,0,0,0,0,0,0,0,0,0,0,0,0,0,0,0,0,11,0,0,0,0,0,0
0,0,0,0,0,0,0,0,0,0,0,0,0,0,0,0,0,0,0,11,0,0,0,0,0,0,0
0,0,0,0,0,0,0,0,0,0,0,0,0,0,0,0,0,11,11,0,0,0,0,0,0,0,0
0,0,0,0,0,0,0,0,0,0,0,11,11,11,11,11,11,0,0,0,0,0,0,0,0,0,0
0,0,0,0,0,0,0,0,0,0,0,0,0,0,0,0,0,0,0,0,0,0,0,0,0,0,0
0,0,0,0,0,0,0,0,0,0,0,0,0,0,0,0,0,0,0,0,0,0,0,0,0,0,0
0,0,0,0,0,0,0,0,0,0,0,0,0,0,0,0,0,0,0,0,0,0,0,0,0,0,0
0,0,0,0,0,0,0,0,0,0,0,0,0,0,0,0,0,0,0,0,0,0,0,0,0,0,0
endlayer

layer
0,0,0,0,0,0,0,0,0,0,0,0,0,0,0,0,0,0,0,0,0,0,0,0,0,0,0
0,0,0,0,0,0,0,0,0,0,0,0,0,0,0,0,0,0,0,0,0,0,0,0,0,0,0
0,0,0,0,0,0,0,0,0,0,0,0,0,0,0,0,0,0,0,0,0,0,0,0,0,0,0
0,0,0,0,0,0,0,0,0,0,0,0,0,0,0,0,0,0,0,0,0,0,0,0,0,0,0
0,0,0,0,0,0,0,0,0,0,0,0,0,0,0,0,0,0,0,0,0,0,0,0,0,0,0
0,0,0,0,0,0,0,0,0,0,0,0,0,0,0,0,0,0,0,0,0,0,0,0,0,0,0
0,0,0,0,0,0,0,0,0,0,0,0,0,0,0,0,0,0,0,11,0,0,0,0,0,0,0
0,0,0,0,0,0,0,0,0,0,0,0,0,0,0,0,0,0,0,0,11,0,0,0,0,0,0
0,0,0,0,0,0,0,0,0,0,0,0,0,0,0,0,0,0,0,0,0,11,0,0,0,0,0
0,0,0,0,0,0,0,0,0,0,0,0,0,0,0,0,0,0,0,0,0,11,0,0,0,0,0
0,0,0,0,0,0,0,0,0,0,0,0,0,0,0,0,0,0,0,0,0,0,11,0,0,0,0
0,0,0,0,0,0,0,0,0,0,0,0,0,0,18,17,0,0,0,0,0,0,11,0,0,0,0
0,0,0,0,0,0,0,0,0,0,0,0,0,0,0,18,0,0,0,0,0,0,11,0,0,0,0
0,0,0,0,0,0,0,0,0,0,0,0,0,0,0,0,0,0,0,0,0,0,11,0,0,0,0
0,0,0,0,0,0,0,0,0,0,0,0,0,0,0,0,0,0,0,0,0,0,11,0,0,0,0
0,0,0,0,0,0,0,0,0,0,0,0,0,0,0,17,0,0,0,0,0,0,11,0,0,0,0
0,0,0,0,0,0,0,0,0,0,0,0,0,0,0,0,0,0,0,0,0,0,11,0,0,0,0
0,0,0,0,0,0,0,0,0,0,0,0,0,0,0,0,0,0,0,0,0,11,0,0,0,0,0
0,0,0,0,0,0,0,0,0,0,0,0,0,0,0,0,0,0,0,0,0,11,0,0,0,0,0
0,0,0,0,0,0,0,0,0,0,0,0,0,0,0,0,0,0,0,0,11,0,0,0,0,0,0
0,0,0,0,0,0,0,0,0,0,0,0,0,0,0,0,0,0,0,11,0,0,0,0,0,0,0
0,0,0,0,0,0,0,0,0,0,0,0,0,0,0,0,0,11,11,0,0,0,0,0,0,0,0
0,0,0,0,0,0,0,0,0,0,0,0,11,11,11,11,11,0,0,0,0,0,0,0,0,0,0
0,0,0,0,0,0,0,0,0,0,0,0,0,0,0,0,0,0,0,0,0,0,0,0,0,0,0
0,0,0,0,0,0,0,0,0,0,0,0,0,0,0,0,0,0,0,0,0,0,0,0,0,0,0
0,0,0,0,0,0,0,0,0,0,0,0,0,0,0,0,0,0,0,0,0,0,0,0,0,0,0
0,0,0,0,0,0,0,0,0,0,0,0,0,0,0,0,0,0,0,0,0,0,0,0,0,0,0
endlayer

layer
0,0,0,0,0,0,0,0,0,0,0,0,0,0,0,0,0,0,0,0,0,0,0,0,0,0,0
0,0,0,0,0,0,0,0,0,0,0,0,0,0,0,0,0,0,0,0,0,0,0,0,0,0,0
0,0,0,0,0,0,0,0,0,0,0,0,0,0,0,0,0,0,0,0,0,0,0,0,0,0,0
0,0,0,0,0,0,0,0,0,0,0,0,0,0,0,0,0,0,0,0,0,0,0,0,0,0,0
0,0,0,0,0,0,0,0,0,0,0,0,0,0,0,0,0,0,0,0,0,0,0,0,0,0,0
0,0,0,0,0,0,0,0,0,0,0,0,0,0,0,0,0,0,0,0,0,0,0,0,0,0,0
0,0,0,0,0,0,0,0,0,0,0,0,0,0,0,0,0,0,0,11,0,0,0,0,0,0,0
0,0,0,0,0,0,0,0,0,0,0,0,0,0,0,0,0,0,0,0,11,0,0,0,0,0,0
0,0,0,0,0,0,0,0,0,0,0,0,0,0,0,0,0,0,0,0,0,11,0,0,0,0,0
0,0,0,0,0,0,0,0,0,0,0,0,0,0,0,0,0,0,0,0,0,11,0,0,0,0,0
0,0,0,0,0,0,0,0,0,0,0,0,0,0,0,0,0,0,0,0,0,0,11,0,0,0,0
0,0,0,0,0,0,0,0,0,0,0,0,0,0,0,17,0,0,0,0,0,0,11,0,0,0,0
0,0,0,0,0,0,0,0,0,0,0,0,0,0,0,18,0,0,0,0,0,0,11,0,0,0,0
0,0,0,0,0,0,0,0,0,0,0,0,0,0,20,18,0,0,0,0,0,0,11,0,0,0,0
0,0,0,0,0,0,0,0,0,0,0,0,0,20,20,0,0,0,0,0,0,0,11,0,0,0,0
0,0,0,0,0,0,0,0,0,0,0,0,0,0,18,17,0,0,0,0,0,0,11,0,0,0,0
0,0,0,0,0,0,0,0,0,0,0,0,0,0,0,0,0,0,0,0,0,0,11,0,0,0,0
0,0,0,0,0,0,0,0,0,0,0,0,0,0,0,0,0,0,0,0,0,11,0,0,0,0,0
0,0,0,0,0,0,0,0,0,0,0,0,0,0,0,0,0,0,0,0,0,11,0,0,0,0,0
0,0,0,0,0,0,0,0,0,0,0,0,0,0,0,0,0,0,0,0,11,0,0,0,0,0,0
0,0,0,0,0,0,0,0,0,0,0,0,0,0,0,0,0,0,0,11,0,0,0,0,0,0,0
0,0,0,0,0,0,0,0,0,0,0,0,0,0,0,0,0,0,11,0,0,0,0,0,0,0,0
0,0,0,0,0,0,0,0,0,0,0,0,11,11,0,11,11,0,0,0,0,0,0,0,0,0,0
0,0,0,0,0,0,0,0,0,0,0,0,0,0,0,0,0,0,0,0,0,0,0,0,0,0,0
0,0,0,0,0,0,0,0,0,0,0,0,0,0,0,0,0,0,0,0,0,0,0,0,0,0,0
0,0,0,0,0,0,0,0,0,0,0,0,0,0,0,0,0,0,0,0,0,0,0,0,0,0,0
0,0,0,0,0,0,0,0,0,0,0,0,0,0,0,0,0,0,0,0,0,0,0,0,0,0,0
endlayer

layer
0,0,0,0,0,0,0,0,0,0,0,0,0,0,0,0,0,0,0,0,0,0,0,0,0,0,0
0,0,0,0,0,0,0,0,0,0,0,0,0,0,0,0,0,0,0,0,0,0,0,0,0,0,0
0,0,0,0,0,0,0,0,0,0,0,0,0,0,0,0,0,0,0,0,0,0,0,0,0,0,0
0,0,0,0,0,0,0,0,0,0,0,0,0,0,0,0,0,0,0,0,0,0,0,0,0,0,0
0,0,0,0,0,0,0,0,0,0,0,0,0,0,0,0,0,0,0,0,0,0,0,0,0,0,0
0,0,0,0,0,0,0,0,0,0,0,0,0,0,0,0,0,0,0,0,0,0,0,0,0,0,0
0,0,0,0,0,0,0,0,0,0,0,0,0,0,0,0,0,0,0,0,0,0,0,0,0,0,0
0,0,0,0,0,0,0,0,0,0,0,0,0,0,0,0,0,0,0,0,11,0,0,0,0,0,0
0,0,0,0,0,0,0,0,0,0,0,0,0,0,0,0,0,0,0,0,0,11,0,0,0,0,0
0,0,0,0,0,0,0,0,0,0,0,0,0,0,0,0,0,0,0,0,0,11,0,0,0,0,0
0,0,0,0,0,0,0,0,0,0,0,0,0,0,0,0,0,0,0,0,0,0,11,0,0,0,0
0,0,0,0,0,0,0,0,0,0,0,0,0,0,0,0,0,0,0,0,0,0,11,0,0,0,0
0,0,0,0,0,0,0,0,0,0,0,0,0,0,0,0,0,0,0,0,0,0,11,0,0,0,0
0,0,0,0,0,0,0,0,0,0,0,0,0,0,0,17,0,0,0,0,0,0,11,0,0,0,0
0,0,0,0,0,0,0,0,0,0,0,0,0,0,0,17,0,0,0,0,0,0,11,0,0,0,0
0,0,0,0,0,0,0,0,0,0,0,0,0,0,17,17,0,0,0,0,0,0,11,0,0,0,0
0,0,0,0,0,0,0,0,0,0,0,0,0,0,0,0,0,0,0,0,0,0,11,0,0,0,0
0,0,0,0,0,0,0,0,0,0,0,0,0,0,0,0,0,0,0,0,0,11,0,0,0,0,0
0,0,0,0,0,0,0,0,0,0,0,0,0,0,0,0,0,0,0,0,0,11,0,0,0,0,0
0,0,0,0,0,0,0,0,0,0,0,0,0,0,0,0,0,0,0,0,11,0,0,0,0,0,0
0,0,0,0,0,0,0,0,0,0,0,0,0,0,0,0,0,0,0,11,0,0,0,0,0,0,0
0,0,0,0,0,0,0,0,0,0,0,0,0,0,0,0,0,11,11,0,0,0,0,0,0,0,0
0,0,0,0,0,0,0,0,0,0,0,11,11,11,0,11,11,0,0,0,0,0,0,0,0,0,0
0,0,0,0,0,0,0,0,0,0,0,0,0,0,0,0,0,0,0,0,0,0,0,0,0,0,0
0,0,0,0,0,0,0,0,0,0,0,0,0,0,0,0,0,0,0,0,0,0,0,0,0,0,0
0,0,0,0,0,0,0,0,0,0,0,0,0,0,0,0,0,0,0,0,0,0,0,0,0,0,0
0,0,0,0,0,0,0,0,0,0,0,0,0,0,0,0,0,0,0,0,0,0,0,0,0,0,0
endlayer

layer
0,0,0,0,0,0,0,0,0,0,0,0,0,0,0,0,0,0,0,0,0,0,0,0,0,0,0
0,0,0,0,0,0,0,0,0,0,0,0,0,0,0,0,0,0,0,0,0,0,0,0,0,0,0
0,0,0,0,0,0,0,0,0,0,0,0,0,0,0,0,0,0,0,0,0,0,0,0,0,0,0
0,0,0,0,0,0,0,0,0,0,0,0,0,0,0,0,0,0,0,0,0,0,0,0,0,0,0
0,0,0,0,0,0,0,0,0,0,0,0,0,0,0,0,0,0,0,0,0,0,0,0,0,0,0
0,0,0,0,0,0,0,0,0,0,0,0,0,0,0,0,0,0,0,0,0,0,0,0,0,0,0
0,0,0,0,0,0,0,0,0,0,0,0,0,0,0,0,0,0,0,11,0,0,0,0,0,0,0
0,0,0,0,0,0,0,0,0,0,0,0,0,0,0,0,0,0,0,0,11,0,0,0,0,0,0
0,0,0,0,0,0,0,0,0,0,0,0,0,0,0,0,0,0,0,0,0,11,0,0,0,0,0
0,0,0,0,0,0,0,0,0,0,0,0,0,0,0,0,0,0,0,0,0,11,0,0,0,0,0
0,0,0,0,0,0,0,0,0,0,0,0,0,0,0,0,0,0,0,0,0,0,11,0,0,0,0
0,0,0,0,0,0,0,0,0,0,0,0,0,0,0,0,0,0,0,0,0,0,11,0,0,0,0
0,0,0,0,0,0,0,0,0,0,0,0,0,0,0,0,0,0,0,0,0,0,11,0,0,0,0
0,0,0,0,0,0,0,0,0,0,0,0,0,0,0,0,0,0,0,0,0,0,11,0,0,0,0
0,0,0,0,0,0,0,0,0,0,0,0,0,0,0,0,0,0,0,0,0,0,11,0,0,0,0
0,0,0,0,0,0,0,0,0,0,0,0,0,0,0,0,0,0,0,0,0,0,11,0,0,0,0
0,0,0,0,0,0,0,0,0,0,0,0,0,0,0,0,0,0,0,0,0,0,11,0,0,0,0
0,0,0,0,0,0,0,0,0,0,0,0,0,0,0,0,0,0,0,0,0,11,0,0,0,0,0
0,0,0,0,0,0,0,0,0,0,0,0,0,0,0,0,0,0,0,0,0,11,0,0,0,0,0
0,0,0,0,0,0,0,0,0,0,0,0,0,0,0,0,0,0,0,0,11,0,0,0,0,0,0
0,0,0,0,0,0,0,0,0,0,0,0,0,0,0,0,0,0,0,11,0,0,0,0,0,0,0
0,0,0,0,0,0,0,0,0,0,0,0,0,0,0,0,0,11,11,0,0,0,0,0,0,0,0
0,0,0,0,0,0,0,0,0,0,0,0,0,0,0,0,11,0,0,0,0,0,0,0,0,0,0
0,0,0,0,0,0,0,0,0,0,0,0,0,0,0,0,0,0,0,0,0,0,0,0,0,0,0
0,0,0,0,0,0,0,0,0,0,0,0,0,0,0,0,0,0,0,0,0,0,0,0,0,0,0
0,0,0,0,0,0,0,0,0,0,0,0,0,0,0,0,0,0,0,0,0,0,0,0,0,0,0
0,0,0,0,0,0,0,0,0,0,0,0,0,0,0,0,0,0,0,0,0,0,0,0,0,0,0
endlayer

layer
0,0,0,0,0,0,0,0,0,0,0,0,0,0,0,0,0,0,0,0,0,0,0,0,0,0,0
0,0,0,0,0,0,0,0,0,0,0,0,0,0,0,0,0,0,0,0,0,0,0,0,0,0,0
0,0,0,0,0,0,0,0,0,0,0,0,0,0,0,0,0,0,0,0,0,0,0,0,0,0,0
0,0,0,0,0,0,0,0,0,0,0,0,0,0,0,0,0,0,0,0,0,0,0,0,0,0,0
0,0,0,0,0,0,0,0,0,0,0,0,0,0,0,0,0,0,0,0,0,0,0,0,0,0,0
0,0,0,0,0,0,0,0,0,0,0,0,0,0,0,0,0,0,0,0,0,0,0,0,0,0,0
0,0,0,0,0,0,0,0,0,0,0,0,0,0,0,0,0,0,0,11,0,0,0,0,0,0,0
0,0,0,0,0,0,0,0,0,0,0,0,0,0,0,0,0,0,0,0,11,0,0,0,0,0,0
0,0,0,0,0,0,0,0,0,0,0,0,0,0,0,0,0,0,0,0,0,11,0,0,0,0,0
0,0,0,0,0,0,0,0,0,0,0,0,0,0,0,0,0,0,0,0,0,11,0,0,0,0,0
0,0,0,0,0,0,0,0,0,0,0,0,0,0,0,0,0,0,0,0,0,0,11,0,0,0,0
0,0,0,0,0,0,0,0,0,0,0,0,0,0,0,0,0,0,0,0,0,0,11,0,0,0,0
0,0,0,0,0,0,0,0,0,0,0,0,0,0,0,0,0,0,0,0,0,0,11,0,0,0,0
0,0,0,0,0,0,0,0,0,0,0,0,0,0,0,0,0,0,0,0,0,0,11,0,0,0,0
0,0,0,0,0,0,0,0,0,0,0,0,0,0,0,0,0,0,0,0,0,0,11,0,0,0,0
0,0,0,0,0,0,0,0,0,0,0,0,0,0,0,0,0,0,0,0,0,0,11,0,0,0,0
0,0,0,0,0,0,0,0,0,0,0,0,0,0,0,0,0,0,0,0,0,0,11,0,0,0,0
0,0,0,0,0,0,0,0,0,0,0,0,0,0,0,0,0,0,0,0,0,11,0,0,0,0,0
0,0,0,0,0,0,0,0,0,0,0,0,0,0,0,0,0,0,0,0,0,11,0,0,0,0,0
0,0,0,0,0,0,0,0,0,0,0,0,0,0,0,0,0,0,0,0,11,0,0,0,0,0,0
0,0,0,0,0,0,0,0,0,0,0,0,0,0,0,0,0,0,0,11,0,0,0,0,0,0,0
0,0,0,0,0,0,0,0,0,0,0,0,0,0,0,0,0,11,11,0,0,0,0,0,0,0,0
0,0,0,0,0,0,0,0,0,0,0,0,0,0,11,11,11,0,0,0,0,0,0,0,0,0,0
0,0,0,0,0,0,0,0,0,0,0,0,0,0,0,0,0,0,0,0,0,0,0,0,0,0,0
0,0,0,0,0,0,0,0,0,0,0,0,0,0,0,0,0,0,0,0,0,0,0,0,0,0,0
0,0,0,0,0,0,0,0,0,0,0,0,0,0,0,0,0,0,0,0,0,0,0,0,0,0,0
0,0,0,0,0,0,0,0,0,0,0,0,0,0,0,0,0,0,0,0,0,0,0,0,0,0,0
endlayer

layer
0,0,0,0,0,0,0,0,0,0,0,0,0,0,0,0,0,0,0,0,0,0,0,0,0,0,0
0,0,0,0,0,0,0,0,0,0,0,0,0,0,0,0,0,0,0,0,0,0,0,0,0,0,0
0,0,0,0,0,0,0,0,0,0,0,0,0,0,0,0,0,0,0,0,0,0,0,0,0,0,0
0,0,0,0,0,0,0,0,0,0,0,0,0,0,0,0,0,0,0,0,0,0,0,0,0,0,0
0,0,0,0,0,0,0,0,0,0,0,0,0,0,0,0,0,0,0,0,0,0,0,0,0,0,0
0,0,0,0,0,0,0,0,0,0,0,0,0,0,0,0,0,0,0,9,0,0,0,0,0,0,0
0,0,0,0,0,0,0,0,0,0,0,0,0,0,0,0,0,0,0,0,9,0,0,0,0,0,0
0,0,0,0,0,0,0,0,0,0,0,0,0,0,0,0,0,0,0,0,0,9,0,0,0,0,0
0,0,0,0,0,0,0,0,0,0,0,0,0,0,0,0,0,0,0,0,0,0,9,0,0,0,0
0,0,0,0,0,0,0,0,0,0,0,0,0,0,0,0,0,0,0,0,0,0,9,0,0,0,0
0,0,0,0,0,0,0,0,0,0,0,0,0,0,0,0,0,0,0,0,0,0,0,9,0,0,0
0,0,0,0,0,0,0,0,0,0,0,0,0,0,0,0,0,0,0,0,0,0,0,9,0,0,0
0,0,0,0,0,0,0,0,0,0,0,0,0,0,0,0,0,0,0,0,0,0,0,9,0,0,0
0,0,0,0,0,0,0,0,0,0,0,0,0,0,0,0,0,0,0,0,0,0,0,9,0,0,0
0,0,0,0,0,0,0,0,0,0,0,0,0,0,0,0,0,0,0,0,0,0,0,9,0,0,0
0,0,0,0,0,0,0,0,0,0,0,0,0,0,0,0,0,0,0,0,0,0,0,9,0,0,0
0,0,0,0,0,0,0,0,0,0,0,0,0,0,0,0,0,0,0,0,0,0,0,9,0,0,0
0,0,0,0,0,0,0,0,0,0,0,0,0,0,0,0,0,0,0,0,0,0,9,0,0,0,0
0,0,0,0,0,0,0,0,0,0,0,0,0,0,0,0,0,0,0,0,0,0,9,0,0,0,0
0,0,0,0,0,0,0,0,0,0,0,0,0,0,0,0,0,0,0,0,0,9,0,0,0,0,0
0,0,0,0,0,0,0,0,0,0,0,0,0,0,0,0,0,0,0,0,9,0,0,0,0,0,0
0,0,0,0,0,0,0,0,0,0,0,0,0,0,0,0,0,0,0,9,0,0,0,0,0,0,0
0,0,0,0,0,0,0,0,0,0,0,0,0,0,0,0,0,9,9,0,0,0,0,0,0,0,0
0,0,0,0,0,0,0,0,0,0,0,0,0,9,9,9,9,0,0,0,0,0,0,0,0,0,0
0,0,0,0,0,0,0,0,0,0,0,0,0,0,0,0,0,0,0,0,0,0,0,0,0,0,0
0,0,0,0,0,0,0,0,0,0,0,0,0,0,0,0,0,0,0,0,0,0,0,0,0,0,0
0,0,0,0,0,0,0,0,0,0,0,0,0,0,0,0,0,0,0,0,0,0,0,0,0,0,0
endlayer

layer
0,0,0,0,0,0,0,0,0,0,0,0,0,0,0,0,0,0,0,0,0,0,0,0,0,0,0
0,0,0,0,0,0,0,0,0,0,0,0,0,0,0,0,0,0,0,0,0,0,0,0,0,0,0
0,0,0,0,0,0,0,0,0,0,0,0,0,0,0,0,0,0,0,0,0,0,0,0,0,0,0
0,0,0,0,0,0,0,0,0,0,0,0,0,0,0,0,0,0,0,0,0,0,0,0,0,0,0
0,0,0,0,0,0,0,0,0,0,0,0,0,0,0,0,0,0,0,0,0,0,0,0,0,0,0
0,0,0,0,0,0,0,0,0,0,0,0,0,0,0,0,0,0,0,9,0,0,0,0,0,0,0
0,0,0,0,0,0,0,0,0,0,0,0,0,0,0,0,0,0,0,0,9,0,0,0,0,0,0
0,0,0,0,0,0,0,0,0,0,0,0,0,0,0,0,0,0,0,0,21,9,0,0,0,0,0
0,0,0,0,0,0,0,0,0,0,0,0,0,0,0,0,0,0,0,0,0,0,9,0,0,0,0
0,0,0,0,0,0,0,0,0,0,0,0,0,0,0,0,0,0,0,0,0,0,9,0,0,0,0
0,0,0,0,0,0,0,0,0,0,0,0,0,0,0,0,0,0,0,0,0,0,0,9,0,0,0
0,0,0,0,0,0,0,0,0,0,0,0,0,0,0,0,0,0,0,0,0,0,0,9,0,0,0
0,0,0,0,0,0,0,0,0,0,0,0,0,0,0,0,0,0,0,0,0,0,0,9,0,0,0
0,0,0,0,0,0,0,0,0,0,0,0,0,0,0,0,0,0,0,0,0,0,0,9,0,0,0
0,0,0,0,0,0,0,0,0,0,0,0,0,0,0,0,0,0,0,0,0,0,0,9,0,0,0
0,0,0,0,0,0,0,0,0,0,0,0,0,0,0,0,0,0,0,0,0,0,0,9,0,0,0
0,0,0,0,0,0,0,0,0,0,0,0,0,0,0,0,0,0,0,0,0,0,0,9,0,0,0
0,0,0,0,0,0,0,0,0,0,0,0,0,0,0,0,0,0,0,0,0,0,9,0,0,0,0
0,0,0,0,0,0,0,0,0,0,0,0,0,0,0,0,0,0,0,0,0,0,9,0,0,0,0
0,0,0,0,0,0,0,0,0,0,0,0,0,0,0,0,0,0,0,0,21,9,0,0,0,0,0
0,0,0,0,0,0,0,0,0,0,0,0,0,0,0,0,0,0,0,0,9,0,0,0,0,0,0
0,0,0,0,0,0,0,0,0,0,0,0,0,0,0,0,0,0,0,9,0,0,0,0,0,0,0
0,0,0,0,0,0,0,0,0,0,0,0,0,0,0,0,0,9,9,0,0,0,0,0,0,0,0
0,0,0,0,0,0,0,0,0,0,0,0,0,9,9,9,9,0,0,0,0,0,0,0,0,0,0
0,0,0,0,0,0,0,0,0,0,0,0,0,0,0,0,0,0,0,0,0,0,0,0,0,0,0
0,0,0,0,0,0,0,0,0,0,0,0,0,0,0,0,0,0,0,0,0,0,0,0,0,0,0
0,0,0,0,0,0,0,0,0,0,0,0,0,0,0,0,0,0,0,0,0,0,0,0,0,0,0
endlayer

layer
0,0,0,0,0,0,0,0,0,0,0,0,0,0,0,0,0,0,0,0,0,0,0,0,0,0,0
0,0,0,0,0,0,0,0,0,0,0,0,0,0,0,0,0,0,0,0,0,0,0,0,0,0,0
0,0,0,0,0,0,0,0,0,0,0,0,0,0,0,0,0,0,0,0,0,0,0,0,0,0,0
0,0,0,0,0,0,0,0,0,0,0,0,0,0,0,0,0,0,0,0,0,0,0,0,0,0,0
0,0,0,0,0,0,0,0,0,0,0,0,0,0,0,0,0,0,0,0,0,0,0,0,0,0,0
0,0,0,0,0,0,0,0,0,0,0,0,0,0,0,0,0,0,0,13,13,0,0,0,0,0,0
0,0,0,0,0,0,0,0,0,0,0,0,0,0,0,0,0,0,0,0,0,13,0,0,0,0,0
0,0,0,0,0,0,0,0,0,0,0,0,0,0,0,0,0,0,0,0,0,13,0,0,0,0,0
0,0,0,0,0,0,0,0,0,0,0,0,0,0,0,0,0,0,0,0,0,0,13,0,0,0,0
0,0,0,0,0,0,0,0,0,0,0,0,0,0,0,0,0,0,0,0,0,0,13,0,0,0,0
0,0,0,0,0,0,0,0,0,0,0,0,0,0,0,0,0,0,0,0,0,0,0,13,0,0,0
0,0,0,0,0,0,0,0,0,0,0,0,0,0,0,0,0,0,0,0,0,0,0,13,0,0,0
0,0,0,0,0,0,0,0,0,0,0,0,0,0,0,0,0,0,0,0,0,0,0,13,0,0,0
0,0,0,0,0,0,0,0,0,0,0,0,0,0,0,0,0,0,0,0,0,0,0,13,0,0,0
0,0,0,0,0,0,0,0,0,0,0,0,0,0,0,0,0,0,0,0,0,0,0,13,0,0,0
0,0,0,0,0,0,0,0,0,0,0,0,0,0,0,0,0,0,0,0,0,0,0,13,0,0,0
0,0,0,0,0,0,0,0,0,0,0,0,0,0,0,0,0,0,0,0,0,0,0,13,0,0,0
0,0,0,0,0,0,0,0,0,0,0,0,0,0,0,0,0,0,0,0,0,0,13,0,0,0,0
0,0,0,0,0,0,0,0,0,0,0,0,0,0,0,0,0,0,0,0,0,0,13,0,0,0,0
0,0,0,0,0,0,0,0,0,0,0,0,0,0,0,0,0,0,0,0,0,13,0,0,0,0,0
0,0,0,0,0,0,0,0,0,0,0,0,0,0,0,0,0,0,0,0,0,13,0,0,0,0,0
0,0,0,0,0,0,0,0,0,0,0,0,0,0,0,0,0,0,0,13,13,0,0,0,0,0,0
0,0,0,0,0,0,0,0,0,0,0,0,0,0,0,0,0,13,13,0,0,0,0,0,0,0,0
0,0,0,0,0,0,0,0,0,0,0,0,13,13,13,13,13,0,0,0,0,0,0,0,0,0,0
0,0,0,0,0,0,0,0,0,0,0,0,0,0,0,0,0,0,0,0,0,0,0,0,0,0,0
0,0,0,0,0,0,0,0,0,0,0,0,0,0,0,0,0,0,0,0,0,0,0,0,0,0,0
0,0,0,0,0,0,0,0,0,0,0,0,0,0,0,0,0,0,0,0,0,0,0,0,0,0,0
endlayer

layer
0,0,0,0,0,0,0,0,0,0,0,0,0,0,0,0,0,0,0,0,0,0,0,0,0,0,0
0,0,0,0,0,0,0,0,0,0,0,0,0,0,0,0,0,0,0,0,0,0,0,0,0,0,0
0,0,0,0,0,0,0,0,0,0,0,0,0,0,0,0,0,0,0,0,0,0,0,0,0,0,0
0,0,0,0,0,0,0,0,0,0,0,0,0,0,0,0,0,0,0,0,0,0,0,0,0,0,0
0,0,0,0,0,0,0,0,0,0,0,0,0,0,0,0,0,0,0,0,0,0,0,0,0,0,0
0,0,0,0,0,0,0,0,0,0,0,0,0,0,0,0,0,0,0,0,0,13,0,0,0,0,0
0,0,0,0,0,0,0,0,0,0,0,0,0,0,0,0,0,0,0,0,0,0,13,0,0,0,0
0,0,0,0,0,0,0,0,0,0,0,0,0,0,0,0,0,0,0,0,0,0,13,0,0,0,0
0,0,0,0,0,0,0,0,0,0,0,0,0,0,0,0,0,0,0,0,0,0,0,13,0,0,0
0,0,0,0,0,0,0,0,0,0,0,0,0,0,0,0,0,0,0,0,0,0,0,13,0,0,0
0,0,0,0,0,0,0,0,0,0,0,0,0,0,0,0,0,0,0,0,0,0,0,0,13,0,0
0,0,0,0,0,0,0,0,0,0,0,0,0,0,0,0,0,0,0,0,0,0,0,0,13,0,0
0,0,0,0,0,0,0,0,0,0,0,0,0,0,0,0,0,0,0,0,0,0,0,0,13,0,0
0,0,0,0,0,0,0,0,0,0,0,0,0,0,0,0,0,0,0,0,0,0,0,0,13,0,0
0,0,0,0,0,0,0,0,0,0,0,0,0,0,0,0,0,0,0,0,0,0,0,0,13,0,0
0,0,0,0,0,0,0,0,0,0,0,0,0,0,0,0,0,0,0,0,0,0,0,0,13,0,0
0,0,0,0,0,0,0,0,0,0,0,0,0,0,0,0,0,0,0,0,0,0,0,0,13,0,0
0,0,0,0,0,0,0,0,0,0,0,0,0,0,0,0,0,0,0,0,0,0,0,13,0,0,0
0,0,0,0,0,0,0,0,0,0,0,0,0,0,0,0,0,0,0,0,0,0,0,13,0,0,0
0,0,0,0,0,0,0,0,0,0,0,0,0,0,0,0,0,0,0,0,0,0,13,0,0,0,0
0,0,0,0,0,0,0,0,0,0,0,0,0,0,0,0,0,0,0,0,0,0,13,0,0,0,0
0,0,0,0,0,0,0,0,0,0,0,0,0,0,0,0,0,0,0,0,0,13,0,0,0,0,0
0,0,0,0,0,0,0,0,0,0,0,0,0,0,0,0,0,0,0,13,13,0,0,0,0,0,0
0,0,0,0,0,0,0,0,0,0,0,0,0,0,0,0,0,13,13,0,0,0,0,0,0,0,0
0,0,0,0,0,0,0,0,0,0,0,13,13,13,13,13,13,0,0,0,0,0,0,0,0,0,0
0,0,0,0,0,0,0,0,0,0,0,0,0,0,0,0,0,0,0,0,0,0,0,0,0,0,0
0,0,0,0,0,0,0,0,0,0,0,0,0,0,0,0,0,0,0,0,0,0,0,0,0,0,0
endlayer

layer
0,0,0,0,0,0,0,0,0,0,0,0,0,0,0,0,0,0,0,0,0,0,0,0,0,0,0
0,0,0,0,0,0,0,0,0,0,0,0,0,0,0,0,0,0,0,0,0,0,0,0,0,0,0
0,0,0,0,0,0,0,0,0,0,0,0,0,0,0,0,0,0,0,0,0,0,0,0,0,0,0
0,0,0,0,0,0,0,0,0,0,0,0,0,0,0,0,0,0,0,0,0,0,0,0,0,0,0
0,0,0,0,0,0,0,0,0,0,0,0,0,0,0,0,0,0,0,0,0,0,0,0,0,0,0
0,0,0,0,0,0,0,0,0,0,0,0,0,0,0,0,0,0,0,0,0,5,0,0,0,0,0
0,0,0,0,0,0,0,0,0,0,0,0,0,0,0,0,0,0,0,0,0,0,5,0,0,0,0
0,0,0,0,0,0,0,0,0,0,0,0,0,0,0,0,0,0,0,0,0,0,5,0,0,0,0
0,0,0,0,0,0,0,0,0,0,0,0,0,0,0,0,0,0,0,0,0,0,0,5,0,0,0
0,0,0,0,0,0,0,0,0,0,0,0,0,0,0,0,0,0,0,0,0,0,0,5,0,0,0
0,0,0,0,0,0,0,0,0,0,0,0,0,0,0,0,0,0,0,0,0,0,0,0,5,0,0
0,0,0,0,0,0,0,0,0,0,0,0,0,0,0,0,0,0,0,0,0,0,0,0,5,0,0
0,0,0,0,0,0,0,0,0,0,0,0,0,0,0,0,0,0,0,0,0,0,0,0,5,0,0
0,0,0,0,0,0,0,0,0,0,0,0,0,0,0,0,0,0,0,0,0,0,0,0,5,0,0
0,0,0,0,0,0,0,0,0,0,0,0,0,0,0,0,0,0,0,0,0,0,0,0,5,0,0
0,0,0,0,0,0,0,0,0,0,0,0,0,0,0,0,0,0,0,0,0,0,0,0,5,0,0
0,0,0,0,0,0,0,0,0,0,0,0,0,0,0,0,0,0,0,0,0,0,0,0,5,0,0
0,0,0,0,0,0,0,0,0,0,0,0,0,0,0,0,0,0,0,0,0,0,0,5,0,0,0
0,0,0,0,0,0,0,0,0,0,0,0,0,0,0,0,0,0,0,0,0,0,0,5,0,0,0
0,0,0,0,0,0,0,0,0,0,0,0,0,0,0,0,0,0,0,0,0,0,5,0,0,0,0
0,0,0,0,0,0,0,0,0,0,0,0,0,0,0,0,0,0,0,0,0,0,5,0,0,0,0
0,0,0,0,0,0,0,0,0,0,0,0,0,0,0,0,0,0,0,0,0,5,0,0,0,0,0
0,0,0,0,0,0,0,0,0,0,0,0,0,0,0,0,0,0,0,5,5,0,0,0,0,0,0
0,0,0,0,0,0,0,0,0,0,0,0,0,0,0,0,0,5,5,0,0,0,0,0,0,0,0
0,0,0,0,0,0,0,0,0,0,0,5,5,5,5,5,5,0,0,0,0,0,0,0,0,0,0
0,0,0,0,0,0,0,0,0,0,0,0,0,0,0,0,0,0,0,0,0,0,0,0,0,0,0
0,0,0,0,0,0,0,0,0,0,0,0,0,0,0,0,0,0,0,0,0,0,0,0,0,0,0
endlayer

layer
0,0,0,0,0,0,0,0,0,0,0,0,0,0,0,0,0,0,0,0,0,0,0,0,0,0,0
0,0,0,0,0,0,0,0,0,0,0,0,0,0,0,0,0,0,0,0,0,0,0,0,0,0,0
0,0,0,0,0,0,0,0,0,0,0,0,0,0,0,0,0,0,0,0,0,0,0,0,0,0,0
0,0,0,0,0,0,0,0,0,0,0,0,0,0,0,0,0,0,0,0,0,0,0,0,0,0,0
0,0,0,0,0,0,0,0,0,0,0,0,0,0,0,0,0,0,0,0,0,0,0,0,0,0,0
0,0,0,0,0,0,0,0,0,0,0,0,0,0,0,0,0,22,22,22,22,5,0,0,0,0,0
0,0,0,0,0,0,0,0,0,0,0,0,0,0,0,0,0,0,22,22,22,22,5,0,0,0,0
0,0,0,0,0,0,0,0,0,0,0,0,0,0,0,0,22,22,22,22,22,22,5,0,0,0,0
0,0,0,0,0,0,0,0,0,0,0,0,0,0,0,0,22,22,22,22,22,22,22,5,0,0,0
0,0,0,0,0,0,0,0,0,0,0,0,0,0,0,0,0,22,22,22,22,22,22,5,0,0,0
0,0,0,0,0,0,0,0,0,0,0,0,0,0,0,0,0,22,22,22,22,22,22,22,5,0,0
0,0,0,0,0,0,0,0,0,0,0,0,0,0,0,0,0,22,22,22,22,22,22,22,5,0,0
0,0,0,0,0,0,0,0,0,0,0,0,0,0,0,0,0,0,22,22,22,22,22,22,5,0,0
0,0,0,0,0,0,0,0,0,0,0,0,0,0,0,0,0,22,22,22,22,22,22,22,5,0,0
0,0,0,0,0,0,0,0,0,0,0,0,0,0,0,0,0,0,0,0,22,22,22,22,5,0,0
0,0,0,0,0,0,0,0,0,0,0,0,0,0,0,0,0,0,22,22,22,22,22,22,5,0,0
0,0,0,0,0,0,0,0,0,0,0,0,0,0,0,0,0,22,22,22,22,22,22,22,5,0,0
0,0,0,0,0,0,0,0,0,0,0,0,0,0,0,0,0,0,22,22,22,22,22,5,0,0,0
0,0,0,0,0,0,0,0,0,0,0,0,0,0,0,0,0,22,22,22,22,22,22,5,0,0,0
0,0,0,0,0,0,0,0,0,0,0,0,0,22,0,0,0,22,22,22,22,22,5,0,0,0,0
0,0,0,0,0,0,0,0,0,0,0,0,0,22,22,0,22,22,22,22,22,22,5,0,0,0,0
0,0,0,0,0,0,0,0,0,0,22,22,22,22,22,0,0,22,22,22,22,5,0,0,0,0,0
0,0,0,0,0,0,0,0,0,22,22,22,22,22,22,22,22,22,22,5,5,0,0,0,0,0,0
0,0,0,0,0,0,0,0,0,0,22,22,22,0,0,22,22,5,5,0,0,0,0,0,0,0,0
0,0,0,0,0,0,0,0,0,0,5,5,5,5,5,5,5,0,0,0,0,0,0,0,0,0,0
0,0,0,0,0,0,0,0,0,0,0,0,0,0,0,0,0,0,0,0,0,0,0,0,0,0,0
0,0,0,0,0,0,0,0,0,0,0,0,0,0,0,0,0,0,0,0,0,0,0,0,0,0,0
endlayer

