weight=1
embed_into_distance=5
acceptable_target_blocks=1,2,3,12,13,250
dimensions=32,21,21
allowable_overhang=0
max_cut_in=2
cut_in_buffer=1
max_leveling=2
leveling_buffer=1
preserve_water=0
preserve_lava=0
preserve_plants=0


rule1=0,100,3134-10
rule2=0,100,300
rule3=0,100,2843-4
rule4=0,100,54
rule5=0,100,2542-0
rule6=0,100,2843-14,2843-14,2843-14,2843-14,2843
rule7=0,95,2835-2,2835-2,2835-2,2835-2,2835-2,2835-2,2835-2,2835-1,2835-1,2835-0
rule8=0,100,2843-15,2843-15,2843-15,2843-15,2843-15,2843-15,2843-15,2843-15,311,308
rule9=0,100,2761-6,2761-6,2761-6,2761-7,2761-7
rule10=0,100,2761-7
rule11=0,25,3225-3
rule12=0,95,300
rule13=0,100,3134,3134,3134,3134-8,3134-2


layer
1,1,1,1,1,1,1,1,1,1,1,1,1,1,1,1,1,1,1,1,1
1,1,1,1,1,1,1,1,1,1,1,1,1,1,1,1,1,1,1,1,1
1,1,2,2,2,2,2,2,2,2,2,2,2,2,2,2,2,2,2,1,1
1,1,2,2,2,2,3,3,3,3,3,3,3,3,3,2,2,2,2,1,1
1,1,2,2,2,3,3,3,3,3,3,3,3,3,3,3,2,2,2,1,1
1,1,2,2,3,3,3,3,3,3,3,3,3,3,3,3,3,2,2,1,1
1,1,2,3,3,3,3,3,3,3,3,3,3,3,3,3,3,3,2,1,1
1,1,2,3,3,3,3,3,3,3,3,3,3,3,3,3,3,3,2,1,1
2,1,2,3,3,3,3,3,3,3,3,3,3,3,3,3,3,3,2,1,1
2,2,2,3,3,3,3,3,3,3,3,3,3,3,3,3,3,3,3,1,1
2,2,2,3,3,3,3,3,3,3,3,3,3,3,3,3,3,3,3,1,1
2,2,2,2,2,2,3,3,3,3,3,3,3,4,3,3,3,3,3,1,1
2,2,2,2,2,2,3,3,3,3,3,3,3,3,3,3,3,3,2,1,1
2,2,2,2,2,2,3,3,3,3,3,3,3,5,3,3,3,3,2,1,1
2,2,2,2,2,2,3,3,3,3,3,3,3,3,3,3,3,3,2,1,1
2,2,2,2,2,2,3,3,3,3,3,3,3,3,3,3,3,2,2,1,1
2,2,2,2,2,3,3,3,3,3,3,3,3,3,3,3,2,2,2,1,1
2,2,2,2,2,2,3,3,3,3,3,3,3,3,3,2,2,2,2,1,1
2,2,2,2,2,2,2,2,2,2,2,2,2,2,2,2,2,2,2,1,1
2,2,2,2,2,2,1,1,1,1,1,1,1,1,1,1,1,1,1,1,1
2,2,2,2,2,2,1,1,1,1,1,1,1,1,1,1,1,1,1,1,1
endlayer

layer
2,2,2,2,2,2,2,2,2,2,2,2,2,2,2,2,2,2,2,2,2
2,2,2,2,2,2,2,2,2,2,2,2,2,2,2,2,2,2,2,2,2
2,2,2,2,2,2,6,6,6,6,6,6,6,6,6,2,2,2,2,2,2
2,2,2,2,2,6,0,0,8,2,2,0,8,0,0,6,2,2,2,2,2
2,2,2,2,6,0,0,0,8,2,0,0,8,0,0,0,6,2,2,2,2
2,2,2,6,8,8,8,0,8,8,0,8,8,0,8,8,8,6,2,2,2
2,2,6,2,2,8,0,0,0,0,0,0,0,0,0,0,0,0,6,2,2
2,2,6,2,2,8,0,0,0,0,0,0,0,0,0,0,0,0,6,2,2
2,2,2,2,2,8,0,0,0,0,0,0,0,0,0,0,0,0,6,2,2
2,2,2,2,2,2,0,0,0,0,0,0,10,9,9,0,0,0,7,2,2
2,2,2,2,2,8,0,0,0,0,0,0,0,0,9,0,0,0,0,2,2
2,2,2,2,2,2,2,0,0,0,0,0,10,9,9,0,0,0,7,2,2
2,2,2,2,2,0,2,2,0,0,0,0,0,0,0,0,0,0,6,2,2
2,2,2,2,2,2,2,2,0,0,0,0,0,0,0,0,0,0,6,2,2
2,2,2,2,2,2,2,0,0,0,0,0,0,0,0,0,0,0,6,2,2
2,2,2,2,2,2,8,0,8,8,0,8,8,0,8,8,8,6,2,2,2
2,2,2,2,2,2,0,0,8,0,0,0,8,0,0,0,6,2,2,2,2
2,2,2,2,2,6,0,0,8,0,0,0,8,0,0,6,2,2,2,2,2
2,2,2,2,2,2,6,6,6,6,6,6,6,6,6,2,2,2,2,2,2
2,2,2,2,2,2,2,2,2,2,2,2,2,2,2,2,2,2,2,2,2
2,2,2,2,2,2,2,2,2,2,2,2,2,2,2,2,2,2,2,2,2
endlayer

layer
2,2,2,2,2,2,2,2,2,2,2,2,2,2,2,2,2,2,2,2,2
2,2,2,2,2,2,2,2,2,2,2,2,2,2,2,2,2,2,2,2,2
2,2,2,2,2,2,6,7,0,7,2,7,0,7,6,2,2,2,2,2,2
2,2,2,2,2,7,0,0,8,0,2,0,8,0,0,7,2,2,2,2,2
2,2,2,2,6,0,0,0,8,0,0,0,8,0,0,0,6,2,2,2,2
2,2,2,7,8,8,8,0,8,8,0,8,8,0,8,8,8,7,2,2,2
2,2,6,0,0,8,0,0,0,0,0,0,0,0,0,0,0,0,6,2,2
2,2,7,2,0,8,0,0,0,0,0,0,0,0,0,0,0,0,7,2,2
2,2,2,2,0,8,0,0,0,0,0,0,0,0,0,0,0,0,0,2,2
2,2,2,2,2,0,0,0,0,0,0,0,0,0,0,0,0,0,7,2,2
2,2,2,2,0,8,0,0,0,0,0,0,0,0,0,0,0,0,0,2,2
2,2,2,2,0,0,0,0,0,0,0,0,0,0,0,0,0,0,0,2,2
2,2,2,2,0,0,0,0,0,0,0,0,0,0,0,0,0,0,0,2,2
2,2,2,2,2,0,0,0,0,0,0,0,0,0,0,0,0,0,7,2,2
2,2,2,2,2,0,0,0,0,0,0,0,0,0,0,0,0,0,6,2,2
2,2,2,2,2,2,8,0,8,8,0,8,8,0,8,8,8,7,2,2,2
2,2,2,2,2,2,0,0,8,0,0,0,8,0,0,0,6,2,2,2,2
2,2,2,2,2,7,0,0,8,0,0,0,8,0,0,7,2,2,2,2,2
2,2,2,2,2,2,6,7,0,7,0,7,11,7,6,2,2,2,2,2,2
2,2,2,2,2,2,2,2,2,2,2,2,2,2,2,2,2,2,2,2,2
2,2,2,2,2,2,2,2,2,2,2,2,2,2,2,2,2,2,2,2,2
endlayer

layer
2,2,2,2,2,2,2,2,2,2,2,2,2,2,2,2,2,2,2,2,2
2,2,2,2,2,2,2,2,2,2,2,2,2,2,2,2,2,2,2,2,2
2,2,2,2,2,2,6,7,0,7,2,7,11,7,6,2,2,2,2,2,2
2,2,2,2,2,7,0,0,0,0,0,0,0,0,0,7,2,2,2,2,2
2,2,2,2,6,0,0,0,0,0,0,0,0,0,0,0,6,2,2,2,2
2,2,2,7,0,0,0,0,0,0,0,0,0,0,0,0,0,7,2,2,2
2,2,6,0,0,0,0,0,0,0,0,0,0,0,0,0,0,0,6,2,2
2,2,7,0,0,0,0,0,0,0,0,0,0,0,0,0,0,0,7,2,2
2,2,2,2,0,0,0,0,0,0,0,0,0,0,0,0,0,0,0,2,2
2,2,2,0,0,0,0,0,0,0,0,0,0,0,0,0,0,0,7,2,2
2,2,2,0,0,0,0,0,0,0,0,0,0,0,0,0,0,0,7,2,2
2,2,2,0,0,0,0,0,0,0,0,0,0,0,0,0,0,0,0,2,2
2,2,2,2,0,0,0,0,0,0,0,0,0,0,0,0,0,0,0,2,2
2,2,2,2,0,0,0,0,0,0,0,0,0,0,0,0,0,0,7,2,2
2,2,2,2,0,0,0,0,0,0,0,0,0,0,0,0,0,0,6,2,2
2,2,2,2,2,0,0,0,0,0,0,0,0,0,0,0,0,7,2,2,2
2,2,2,2,2,2,0,0,0,0,0,0,0,0,0,0,6,2,2,2,2
2,2,2,2,2,2,0,0,0,0,0,0,0,0,0,7,2,2,2,2,2
2,2,2,2,2,2,6,7,0,7,11,7,0,7,6,2,2,2,2,2,2
2,2,2,2,2,2,2,2,2,2,2,2,2,2,2,2,2,2,2,2,2
2,2,2,2,2,2,2,2,2,2,2,2,2,2,2,2,2,2,2,2,2
endlayer

layer
12,12,12,12,12,12,12,12,12,12,12,12,12,12,12,12,12,12,12,12,12
12,12,12,12,12,12,12,12,12,12,12,12,12,12,12,12,12,12,12,12,12
12,12,12,12,12,12,6,7,0,7,0,7,0,7,6,12,12,12,12,12,12
12,12,12,12,12,7,0,0,0,0,0,0,0,0,0,7,12,12,12,12,12
12,12,12,12,6,0,0,0,0,0,0,0,0,0,0,0,6,12,12,12,12
12,12,12,7,0,0,0,0,0,0,0,0,0,0,0,0,0,7,12,12,12
12,12,6,0,0,0,0,0,0,0,0,0,0,0,0,0,0,0,6,12,12
12,12,7,0,0,0,0,0,0,0,0,0,0,0,0,0,0,0,7,12,12
12,12,12,0,0,0,0,0,0,0,0,0,0,0,0,0,0,0,7,12,12
12,12,12,0,0,0,0,0,0,0,0,0,0,0,0,0,0,0,7,12,12
12,12,12,0,0,0,0,0,0,0,0,0,0,0,0,0,0,0,7,12,12
12,12,12,0,0,0,0,0,0,0,0,0,0,0,0,0,0,0,0,12,12
12,12,12,0,0,0,0,0,0,0,0,0,0,0,0,0,0,0,7,12,12
12,12,12,0,0,0,0,0,0,0,0,0,0,0,0,0,0,0,7,12,12
12,12,12,0,0,0,0,0,0,0,0,0,0,0,0,0,0,0,6,12,12
12,12,12,12,0,0,0,0,0,0,0,0,0,0,0,0,0,7,12,12,12
12,12,12,12,12,0,0,0,0,0,0,0,0,0,0,0,6,12,12,12,12
12,12,12,12,12,12,0,0,0,0,0,0,0,0,0,7,12,12,12,12,12
12,12,12,12,12,12,6,7,0,7,0,0,0,7,6,12,12,12,12,12,12
12,12,12,12,12,12,12,12,12,12,12,12,12,12,12,12,12,12,12,12,12
12,12,12,12,12,12,12,12,12,12,12,12,12,12,12,12,12,12,12,12,12
endlayer

layer
0,0,0,0,0,0,0,0,0,0,0,0,0,0,0,0,0,0,0,0,0
0,0,0,0,0,0,0,0,0,0,0,0,0,0,0,0,0,0,0,0,0
0,0,0,0,0,0,6,7,0,0,11,7,0,7,6,0,0,0,0,0,0
0,0,0,0,0,7,0,0,0,0,0,0,0,0,0,7,0,0,0,0,0
0,0,0,0,6,0,0,0,0,0,0,0,0,0,0,0,6,0,0,0,0
0,0,0,7,0,0,0,0,0,0,0,0,0,0,0,0,0,7,0,0,0
0,0,6,0,0,0,0,0,0,0,0,0,0,0,0,0,0,0,6,0,0
0,0,7,0,0,0,0,0,0,0,0,0,0,0,0,0,0,0,7,0,0
0,0,0,0,0,0,0,0,0,0,0,0,0,0,0,0,0,0,0,0,0
0,0,0,0,0,0,0,0,0,0,0,0,0,0,0,0,0,0,7,0,0
0,0,0,0,0,0,0,0,0,0,0,0,0,0,0,0,0,0,0,0,0
0,0,0,0,0,0,0,0,0,0,0,0,0,0,0,0,0,0,7,0,0
0,0,0,0,0,0,0,0,0,0,0,0,0,0,0,0,0,0,0,0,0
0,0,0,0,0,0,0,0,0,0,0,0,0,0,0,0,0,0,7,0,0
0,0,0,0,0,0,0,0,0,0,0,0,0,0,0,0,0,0,6,0,0
0,0,0,0,0,0,0,0,0,0,0,0,0,0,0,0,0,7,0,0,0
0,0,0,0,0,0,0,0,0,0,0,0,0,0,0,0,6,0,0,0,0
0,0,0,0,0,0,0,0,0,0,0,0,0,0,0,7,0,0,0,0,0
0,0,0,0,0,0,6,7,0,7,0,7,11,7,6,0,0,0,0,0,0
0,0,0,0,0,0,0,0,0,0,0,0,0,0,0,0,0,0,0,0,0
0,0,0,0,0,0,0,0,0,0,0,0,0,0,0,0,0,0,0,0,0
endlayer

layer
0,0,0,0,0,0,0,0,0,0,0,0,0,0,0,0,0,0,0,0,0
0,0,0,0,0,0,0,0,0,0,0,0,0,0,0,0,0,0,0,0,0
0,0,0,0,0,0,6,7,11,7,11,7,0,7,6,0,0,0,0,0,0
0,0,0,0,0,7,0,0,0,0,0,0,0,0,0,7,0,0,0,0,0
0,0,0,0,6,0,0,0,0,0,0,0,0,0,0,0,6,0,0,0,0
0,0,0,7,0,0,0,0,0,0,0,0,0,0,0,0,0,7,0,0,0
0,0,6,0,0,0,0,0,0,0,0,0,0,0,0,0,0,0,6,0,0
0,0,7,0,0,0,0,0,0,0,0,0,0,0,0,0,0,0,7,0,0
0,0,0,0,0,0,0,0,0,0,0,0,0,0,0,0,0,0,0,0,0
0,0,0,0,0,0,0,0,0,0,0,0,0,0,0,0,0,0,0,0,0
0,0,0,0,0,0,0,0,0,0,0,0,0,0,0,0,0,0,0,0,0
0,0,0,0,0,0,0,0,0,0,0,0,0,0,0,0,0,0,7,0,0
0,0,0,0,0,0,0,0,0,0,0,0,0,0,0,0,0,0,11,0,0
0,0,0,0,0,0,0,0,0,0,0,0,0,0,0,0,0,0,7,0,0
0,0,0,0,0,0,0,0,0,0,0,0,0,0,0,0,0,0,6,0,0
0,0,0,0,0,0,0,0,0,0,0,0,0,0,0,0,0,7,0,0,0
0,0,0,0,0,0,0,0,0,0,0,0,0,0,0,0,6,0,0,0,0
0,0,0,0,0,0,0,0,0,0,0,0,0,0,0,7,0,0,0,0,0
0,0,0,0,0,0,6,7,0,7,0,7,0,7,6,0,0,0,0,0,0
0,0,0,0,0,0,0,0,0,0,0,0,0,0,0,0,0,0,0,0,0
0,0,0,0,0,0,0,0,0,0,0,0,0,0,0,0,0,0,0,0,0
endlayer

layer
0,0,0,0,0,0,0,0,0,0,0,0,0,0,0,0,0,0,0,0,0
0,0,0,0,0,0,0,0,0,0,0,0,0,0,0,0,0,0,0,0,0
0,0,0,0,0,0,6,6,6,6,6,6,6,6,6,0,0,0,0,0,0
0,0,0,0,0,6,0,0,0,0,0,0,0,0,0,6,0,0,0,0,0
0,0,0,0,6,0,0,0,0,0,0,0,0,0,0,0,6,0,0,0,0
0,0,0,6,0,0,0,0,0,0,0,0,0,0,0,0,0,6,0,0,0
0,0,6,0,0,0,0,0,0,0,0,0,0,0,0,0,0,0,6,0,0
0,0,6,0,0,0,0,0,0,0,0,0,0,0,0,0,0,0,6,0,0
0,0,0,0,0,0,0,0,0,0,0,0,0,0,0,0,0,0,6,0,0
0,0,0,0,0,0,0,0,0,0,0,0,0,0,0,0,0,0,6,0,0
0,0,0,0,0,0,0,0,0,0,0,0,0,0,0,0,0,0,6,0,0
0,0,0,0,0,0,0,0,0,0,0,0,0,0,0,0,0,0,6,0,0
0,0,0,0,0,0,0,0,0,0,0,0,0,0,0,0,0,0,6,0,0
0,0,0,0,0,0,0,0,0,0,0,0,0,0,0,0,0,0,6,0,0
0,0,0,0,0,0,0,0,0,0,0,0,0,0,0,0,0,0,6,0,0
0,0,0,0,0,0,0,0,0,0,0,0,0,0,0,0,0,6,0,0,0
0,0,0,0,0,0,0,0,0,0,0,0,0,0,0,0,6,0,0,0,0
0,0,0,0,0,0,0,0,0,0,0,0,0,0,0,6,0,0,0,0,0
0,0,0,0,0,0,6,6,6,6,6,6,6,6,6,0,0,0,0,0,0
0,0,0,0,0,0,0,0,0,0,0,0,0,0,0,0,0,0,0,0,0
0,0,0,0,0,0,0,0,0,0,0,0,0,0,0,0,0,0,0,0,0
endlayer

layer
0,0,0,0,0,0,0,0,0,0,0,0,0,0,0,0,0,0,0,0,0
0,0,0,0,0,0,0,0,0,0,0,0,0,0,0,0,0,0,0,0,0
0,0,0,0,0,0,0,0,0,0,0,0,0,0,0,0,0,0,0,0,0
0,0,0,0,0,0,6,6,6,6,6,6,6,6,6,0,0,0,0,0,0
0,0,0,0,0,7,3,3,3,3,3,3,3,3,3,6,0,0,0,0,0
0,0,0,0,7,3,3,3,3,3,3,3,3,3,3,3,6,0,0,0,0
0,0,0,6,3,3,3,3,3,3,3,3,3,3,3,3,3,6,0,0,0
0,0,0,6,3,3,3,3,3,3,3,3,3,3,3,3,3,6,0,0,0
0,0,0,6,3,3,3,3,3,3,3,3,3,3,3,3,3,6,0,0,0
0,0,0,6,3,3,3,3,3,3,3,3,3,3,3,3,3,6,0,0,0
0,0,0,6,3,3,3,3,3,3,3,3,3,3,3,3,3,6,0,0,0
0,0,0,6,3,3,3,3,3,3,3,3,3,3,3,3,3,6,0,0,0
0,0,0,6,3,3,3,3,3,3,3,3,3,3,3,3,3,6,0,0,0
0,0,0,6,0,3,3,3,3,3,3,3,3,5,3,3,3,6,0,0,0
0,0,0,0,0,0,3,3,3,3,3,3,3,3,3,3,3,6,0,0,0
0,0,0,0,6,3,3,3,3,3,3,3,3,3,3,3,6,0,0,0,0
0,0,0,0,0,6,3,3,3,3,3,3,3,3,3,6,0,0,0,0,0
0,0,0,0,0,0,6,6,6,6,6,6,6,6,6,0,0,0,0,0,0
0,0,0,0,0,0,0,0,0,0,0,0,0,0,0,0,0,0,0,0,0
0,0,0,0,0,0,0,0,0,0,0,0,0,0,0,0,0,0,0,0,0
0,0,0,0,0,0,0,0,0,0,0,0,0,0,0,0,0,0,0,0,0
endlayer

layer
0,0,0,0,0,0,0,0,0,0,0,0,0,0,0,0,0,0,0,0,0
0,0,0,0,0,0,0,0,0,0,0,0,0,0,0,0,0,0,0,0,0
0,0,0,0,0,0,0,0,0,0,0,0,0,0,0,0,0,0,0,0,0
0,0,0,0,0,0,6,7,0,7,0,7,0,7,6,0,0,0,0,0,0
0,0,0,0,0,7,8,0,0,0,0,0,0,0,8,7,0,0,0,0,0
0,0,0,0,7,0,8,0,0,0,0,0,0,0,8,0,7,0,0,0,0
0,0,0,6,0,0,8,0,8,8,8,8,0,0,8,0,0,6,0,0,0
0,0,0,7,0,0,8,0,8,0,0,8,0,0,0,0,0,7,0,0,0
0,0,0,0,0,0,0,0,0,0,0,8,0,0,8,8,8,0,0,0,0
0,0,0,7,8,8,8,0,8,8,0,8,0,0,0,0,0,7,0,0,0
0,0,0,0,0,0,8,0,8,0,0,0,0,0,8,0,0,0,0,0,0
0,0,0,7,0,0,0,0,8,0,0,8,0,0,8,0,0,7,0,0,0
0,0,0,0,8,8,8,0,8,8,8,8,0,0,8,8,8,0,0,0,0
0,0,0,7,0,0,0,0,0,0,0,0,0,0,0,0,0,7,0,0,0
0,0,0,0,0,0,8,8,0,8,8,0,8,0,8,0,0,6,0,0,0
0,0,0,0,7,0,8,0,0,8,0,0,8,0,8,0,7,0,0,0,0
0,0,0,0,0,7,8,0,0,8,0,0,8,0,8,7,0,0,0,0,0
0,0,0,0,0,0,6,7,0,7,0,7,0,7,6,0,0,0,0,0,0
0,0,0,0,0,0,0,0,0,0,0,0,0,0,0,0,0,0,0,0,0
0,0,0,0,0,0,0,0,0,0,0,0,0,0,0,0,0,0,0,0,0
0,0,0,0,0,0,0,0,0,0,0,0,0,0,0,0,0,0,0,0,0
endlayer

layer
0,0,0,0,0,0,0,0,0,0,0,0,0,0,0,0,0,0,0,0,0
0,0,0,0,0,0,0,0,0,0,0,0,0,0,0,0,0,0,0,0,0
0,0,0,0,0,0,0,0,0,0,0,0,0,0,0,0,0,0,0,0,0
0,0,0,0,0,0,6,7,0,7,0,7,0,7,6,0,0,0,0,0,0
0,0,0,0,0,7,8,0,0,0,0,0,0,0,8,7,0,0,0,0,0
0,0,0,0,7,0,8,0,0,0,0,0,0,0,8,0,7,0,0,0,0
0,0,0,6,0,0,8,0,8,8,8,8,0,0,8,0,0,6,0,0,0
0,0,0,7,0,0,8,0,8,0,0,8,0,0,0,0,0,0,0,0,0
0,0,0,0,0,0,0,0,0,0,0,8,0,0,8,8,8,0,0,0,0
0,0,0,7,8,8,8,0,8,8,0,8,0,0,0,0,0,7,0,0,0
0,0,0,0,0,0,8,0,8,0,0,0,0,0,8,0,0,0,0,0,0
0,0,0,7,0,0,0,0,8,0,0,8,0,0,8,0,0,7,0,0,0
0,0,0,0,8,8,8,0,8,8,8,8,0,0,8,8,8,0,0,0,0
0,0,0,7,0,0,0,0,0,0,0,0,0,0,0,0,0,7,0,0,0
0,0,0,6,0,0,8,8,0,8,8,0,8,0,8,0,0,6,0,0,0
0,0,0,0,7,0,8,0,0,8,0,0,8,0,8,0,7,0,0,0,0
0,0,0,0,0,7,8,0,0,8,0,0,8,0,8,7,0,0,0,0,0
0,0,0,0,0,0,6,7,0,7,0,7,0,7,6,0,0,0,0,0,0
0,0,0,0,0,0,0,0,0,0,0,0,0,0,0,0,0,0,0,0,0
0,0,0,0,0,0,0,0,0,0,0,0,0,0,0,0,0,0,0,0,0
0,0,0,0,0,0,0,0,0,0,0,0,0,0,0,0,0,0,0,0,0
endlayer

layer
0,0,0,0,0,0,0,0,0,0,0,0,0,0,0,0,0,0,0,0,0
0,0,0,0,0,0,0,0,0,0,0,0,0,0,0,0,0,0,0,0,0
0,0,0,0,0,0,0,0,0,0,0,0,0,0,0,0,0,0,0,0,0
0,0,0,0,0,0,6,7,11,7,0,7,0,7,6,0,0,0,0,0,0
0,0,0,0,0,7,0,0,0,0,0,0,0,0,0,0,0,0,0,0,0
0,0,0,0,7,0,0,0,0,0,0,0,0,0,0,0,7,0,0,0,0
0,0,0,6,0,0,0,0,0,0,0,0,0,0,0,0,0,6,0,0,0
0,0,0,7,0,0,0,0,0,0,0,0,0,0,0,0,0,7,0,0,0
0,0,0,11,0,0,0,0,0,0,0,0,0,0,0,0,0,11,0,0,0
0,0,0,7,0,0,0,0,0,0,0,0,0,0,0,0,0,7,0,0,0
0,0,0,0,0,0,0,0,0,0,0,0,0,0,0,0,0,11,0,0,0
0,0,0,7,0,0,0,0,0,0,0,0,0,0,0,0,0,7,0,0,0
0,0,0,0,0,0,0,0,0,0,0,0,0,0,0,0,0,0,0,0,0
0,0,0,7,0,0,0,0,0,0,0,0,0,0,0,0,0,7,0,0,0
0,0,0,6,0,0,0,0,0,0,0,0,0,0,0,0,0,6,0,0,0
0,0,0,0,7,0,0,0,0,0,0,0,0,0,0,0,7,0,0,0,0
0,0,0,0,0,7,0,0,0,0,0,0,0,0,0,7,0,0,0,0,0
0,0,0,0,0,0,6,7,0,7,11,7,0,7,6,0,0,0,0,0,0
0,0,0,0,0,0,0,0,0,0,0,0,0,0,0,0,0,0,0,0,0
0,0,0,0,0,0,0,0,0,0,0,0,0,0,0,0,0,0,0,0,0
0,0,0,0,0,0,0,0,0,0,0,0,0,0,0,0,0,0,0,0,0
endlayer

layer
0,0,0,0,0,0,0,0,0,0,0,0,0,0,0,0,0,0,0,0,0
0,0,0,0,0,0,0,0,0,0,0,0,0,0,0,0,0,0,0,0,0
0,0,0,0,0,0,0,0,0,0,0,0,0,0,0,0,0,0,0,0,0
0,0,0,0,0,0,6,0,0,7,0,7,0,7,6,0,0,0,0,0,0
0,0,0,0,0,7,0,0,0,0,0,0,0,0,0,0,0,0,0,0,0
0,0,0,0,7,0,0,0,0,0,0,0,0,0,0,0,7,0,0,0,0
0,0,0,6,0,0,0,0,0,0,0,0,0,0,0,0,0,6,0,0,0
0,0,0,7,0,0,0,0,0,0,0,0,0,0,0,0,0,7,0,0,0
0,0,0,11,0,0,0,0,0,0,0,0,0,0,0,0,0,0,0,0,0
0,0,0,7,0,0,0,0,0,0,0,0,0,0,0,0,0,7,0,0,0
0,0,0,0,0,0,0,0,0,0,0,0,0,0,0,0,0,11,0,0,0
0,0,0,7,0,0,0,0,0,0,0,0,0,0,0,0,0,7,0,0,0
0,0,0,0,0,0,0,0,0,0,0,0,0,0,0,0,0,0,0,0,0
0,0,0,7,0,0,0,0,0,0,0,0,0,0,0,0,0,7,0,0,0
0,0,0,6,0,0,0,0,0,0,0,0,0,0,0,0,0,6,0,0,0
0,0,0,0,7,0,0,0,0,0,0,0,0,0,0,0,7,0,0,0,0
0,0,0,0,0,7,0,0,0,0,0,0,0,0,0,7,0,0,0,0,0
0,0,0,0,0,0,6,0,0,7,0,7,0,7,6,0,0,0,0,0,0
0,0,0,0,0,0,0,0,0,0,0,0,0,0,0,0,0,0,0,0,0
0,0,0,0,0,0,0,0,0,0,0,0,0,0,0,0,0,0,0,0,0
0,0,0,0,0,0,0,0,0,0,0,0,0,0,0,0,0,0,0,0,0
endlayer

layer
0,0,0,0,0,0,0,0,0,0,0,0,0,0,0,0,0,0,0,0,0
0,0,0,0,0,0,0,0,0,0,0,0,0,0,0,0,0,0,0,0,0
0,0,0,0,0,0,0,0,0,0,0,0,0,0,0,0,0,0,0,0,0
0,0,0,0,0,0,6,7,0,7,11,7,0,7,6,0,0,0,0,0,0
0,0,0,0,0,7,0,0,0,0,0,0,0,0,0,7,0,0,0,0,0
0,0,0,0,7,0,0,0,0,0,0,0,0,0,0,0,7,0,0,0,0
0,0,0,6,0,0,0,0,0,0,0,0,0,0,0,0,0,6,0,0,0
0,0,0,7,0,0,0,0,0,0,0,0,0,0,0,0,0,7,0,0,0
0,0,0,11,0,0,0,0,0,0,0,0,0,0,0,0,0,0,0,0,0
0,0,0,7,0,0,0,0,0,0,0,0,0,0,0,0,0,7,0,0,0
0,0,0,11,0,0,0,0,0,0,0,0,0,0,0,0,0,0,0,0,0
0,0,0,7,0,0,0,0,0,0,0,0,0,0,0,0,0,7,0,0,0
0,0,0,0,0,0,0,0,0,0,0,0,0,0,0,0,0,11,0,0,0
0,0,0,7,0,0,0,0,0,0,0,0,0,0,0,0,0,7,0,0,0
0,0,0,6,0,0,0,0,0,0,0,0,0,0,0,0,0,6,0,0,0
0,0,0,0,0,0,0,0,0,0,0,0,0,0,0,0,7,0,0,0,0
0,0,0,0,0,7,0,0,0,0,0,0,0,0,0,7,0,0,0,0,0
0,0,0,0,0,0,6,7,0,7,11,7,0,7,6,0,0,0,0,0,0
0,0,0,0,0,0,0,0,0,0,0,0,0,0,0,0,0,0,0,0,0
0,0,0,0,0,0,0,0,0,0,0,0,0,0,0,0,0,0,0,0,0
0,0,0,0,0,0,0,0,0,0,0,0,0,0,0,0,0,0,0,0,0
endlayer

layer
0,0,0,0,0,0,0,0,0,0,0,0,0,0,0,0,0,0,0,0,0
0,0,0,0,0,0,0,0,0,0,0,0,0,0,0,0,0,0,0,0,0
0,0,0,0,0,0,0,0,0,0,0,0,0,0,0,0,0,0,0,0,0
0,0,0,0,0,0,6,7,11,7,0,7,11,7,6,0,0,0,0,0,0
0,0,0,0,0,7,0,0,0,0,0,0,0,0,0,7,0,0,0,0,0
0,0,0,0,7,0,0,0,0,0,0,0,0,0,0,0,7,0,0,0,0
0,0,0,6,0,0,0,0,0,0,0,0,0,0,0,0,0,6,0,0,0
0,0,0,7,0,0,0,0,0,0,0,0,0,0,0,0,0,7,0,0,0
0,0,0,0,0,0,0,0,0,0,0,0,0,0,0,0,0,11,0,0,0
0,0,0,7,0,0,0,0,0,0,0,0,0,0,0,0,0,7,0,0,0
0,0,0,0,0,0,0,0,0,0,0,0,0,0,0,0,0,0,0,0,0
0,0,0,7,0,0,0,0,0,0,0,0,0,0,0,0,0,7,0,0,0
0,0,0,11,0,0,0,0,0,0,0,0,0,0,0,0,0,0,0,0,0
0,0,0,7,0,0,0,0,0,0,0,0,0,0,0,0,0,7,0,0,0
0,0,0,6,0,0,0,0,0,0,0,0,0,0,0,0,0,6,0,0,0
0,0,0,0,7,0,0,0,0,0,0,0,0,0,0,0,7,0,0,0,0
0,0,0,0,0,0,0,0,0,0,0,0,0,0,0,0,0,0,0,0,0
0,0,0,0,0,0,6,7,11,7,0,7,0,7,6,0,0,0,0,0,0
0,0,0,0,0,0,0,0,0,0,0,0,0,0,0,0,0,0,0,0,0
0,0,0,0,0,0,0,0,0,0,0,0,0,0,0,0,0,0,0,0,0
0,0,0,0,0,0,0,0,0,0,0,0,0,0,0,0,0,0,0,0,0
endlayer

layer
0,0,0,0,0,0,0,0,0,0,0,0,0,0,0,0,0,0,0,0,0
0,0,0,0,0,0,0,0,0,0,0,0,0,0,0,0,0,0,0,0,0
0,0,0,0,0,0,0,0,0,0,0,0,0,0,0,0,0,0,0,0,0
0,0,0,0,0,0,6,6,6,6,6,6,6,6,6,0,0,0,0,0,0
0,0,0,0,0,6,0,0,0,0,0,0,0,0,0,6,0,0,0,0,0
0,0,0,0,6,0,0,0,0,0,0,0,0,0,0,0,6,0,0,0,0
0,0,0,6,0,0,0,0,0,0,0,0,0,0,0,0,0,6,0,0,0
0,0,0,6,0,0,0,0,0,0,0,0,0,0,0,0,0,6,0,0,0
0,0,0,6,0,0,0,0,0,0,0,0,0,0,0,0,0,6,0,0,0
0,0,0,6,0,0,0,0,0,0,0,0,0,0,0,0,0,6,0,0,0
0,0,0,6,0,0,0,0,0,0,0,0,0,0,0,0,0,6,0,0,0
0,0,0,6,0,0,0,0,0,0,0,0,0,0,0,0,0,6,0,0,0
0,0,0,6,0,0,0,0,0,0,0,0,0,0,0,0,0,6,0,0,0
0,0,0,6,0,0,0,0,0,0,0,0,0,0,0,0,0,6,0,0,0
0,0,0,6,0,0,0,0,0,0,0,0,0,0,0,0,0,6,0,0,0
0,0,0,0,6,0,0,0,0,0,0,0,0,0,0,0,6,0,0,0,0
0,0,0,0,0,6,0,0,0,0,0,0,0,0,0,6,0,0,0,0,0
0,0,0,0,0,0,6,6,6,6,6,6,6,6,6,0,0,0,0,0,0
0,0,0,0,0,0,0,0,0,0,0,0,0,0,0,0,0,0,0,0,0
0,0,0,0,0,0,0,0,0,0,0,0,0,0,0,0,0,0,0,0,0
0,0,0,0,0,0,0,0,0,0,0,0,0,0,0,0,0,0,0,0,0
endlayer

layer
0,0,0,0,0,0,0,0,0,0,0,0,0,0,0,0,0,0,0,0,0
0,0,0,0,0,0,0,0,0,0,0,0,0,0,0,0,0,0,0,0,0
0,0,0,0,0,0,0,0,0,0,0,0,0,0,0,0,0,0,0,0,0
0,0,0,0,0,0,0,0,0,0,0,0,0,0,0,0,0,0,0,0,0
0,0,0,0,0,0,6,6,6,6,6,6,6,6,6,0,0,0,0,0,0
0,0,0,0,0,6,0,0,0,0,0,0,0,0,0,6,0,0,0,0,0
0,0,0,0,6,0,0,0,0,0,0,0,0,0,0,0,6,0,0,0,0
0,0,0,0,6,0,0,0,0,0,0,0,0,0,0,0,6,0,0,0,0
0,0,0,0,6,0,0,0,0,0,0,0,0,0,0,0,6,0,0,0,0
0,0,0,0,6,0,0,0,0,0,0,0,0,0,0,0,6,0,0,0,0
0,0,0,0,6,0,0,0,0,0,0,0,0,0,0,0,6,0,0,0,0
0,0,0,0,6,0,0,0,0,0,0,0,0,0,0,0,6,0,0,0,0
0,0,0,0,6,0,0,0,0,0,0,0,0,0,0,0,6,0,0,0,0
0,0,0,0,6,0,0,0,0,0,0,0,0,0,0,0,6,0,0,0,0
0,0,0,0,6,0,0,0,0,0,0,0,0,0,0,0,6,0,0,0,0
0,0,0,0,0,6,0,0,0,0,0,0,0,0,0,6,0,0,0,0,0
0,0,0,0,0,0,6,6,6,6,6,6,6,6,6,0,0,0,0,0,0
0,0,0,0,0,0,0,0,0,0,0,0,0,0,0,0,0,0,0,0,0
0,0,0,0,0,0,0,0,0,0,0,0,0,0,0,0,0,0,0,0,0
0,0,0,0,0,0,0,0,0,0,0,0,0,0,0,0,0,0,0,0,0
0,0,0,0,0,0,0,0,0,0,0,0,0,0,0,0,0,0,0,0,0
endlayer

layer
0,0,0,0,0,0,0,0,0,0,0,0,0,0,0,0,0,0,0,0,0
0,0,0,0,0,0,0,0,0,0,0,0,0,0,0,0,0,0,0,0,0
0,0,0,0,0,0,0,0,0,0,0,0,0,0,0,0,0,0,0,0,0
0,0,0,0,0,0,0,0,0,0,0,0,0,0,0,0,0,0,0,0,0
0,0,0,0,0,0,0,0,0,0,0,0,0,0,0,0,0,0,0,0,0
0,0,0,0,0,0,6,6,6,6,6,6,6,6,6,0,0,0,0,0,0
0,0,0,0,0,6,6,3,3,3,3,3,3,3,3,6,0,0,0,0,0
0,0,0,0,0,6,3,3,3,3,3,3,3,3,3,6,0,0,0,0,0
0,0,0,0,0,6,3,3,3,3,3,3,3,3,3,6,0,0,0,0,0
0,0,0,0,0,6,3,3,3,3,3,3,3,3,3,6,0,0,0,0,0
0,0,0,0,0,6,3,3,3,3,3,3,3,3,3,6,0,0,0,0,0
0,0,0,0,0,6,3,3,3,3,3,3,3,3,3,6,0,0,0,0,0
0,0,0,0,0,6,3,3,3,3,3,3,3,3,3,6,0,0,0,0,0
0,0,0,0,0,6,3,3,3,3,3,3,3,5,3,6,0,0,0,0,0
0,0,0,0,0,6,3,3,3,3,3,3,3,3,6,6,0,0,0,0,0
0,0,0,0,0,0,6,6,6,6,6,6,6,6,6,0,0,0,0,0,0
0,0,0,0,0,0,0,0,0,0,0,0,0,0,0,0,0,0,0,0,0
0,0,0,0,0,0,0,0,0,0,0,0,0,0,0,0,0,0,0,0,0
0,0,0,0,0,0,0,0,0,0,0,0,0,0,0,0,0,0,0,0,0
0,0,0,0,0,0,0,0,0,0,0,0,0,0,0,0,0,0,0,0,0
0,0,0,0,0,0,0,0,0,0,0,0,0,0,0,0,0,0,0,0,0
endlayer

layer
0,0,0,0,0,0,0,0,0,0,0,0,0,0,0,0,0,0,0,0,0
0,0,0,0,0,0,0,0,0,0,0,0,0,0,0,0,0,0,0,0,0
0,0,0,0,0,0,0,0,0,0,0,0,0,0,0,0,0,0,0,0,0
0,0,0,0,0,0,0,0,0,0,0,0,0,0,0,0,0,0,0,0,0
0,0,0,0,0,0,0,0,0,0,0,0,0,0,0,0,0,0,0,0,0
0,0,0,0,0,0,0,0,0,0,0,0,0,0,0,0,0,0,0,0,0
0,0,0,0,0,0,6,7,0,7,0,7,0,7,6,0,0,0,0,0,0
0,0,0,0,0,0,7,0,0,0,0,0,0,0,7,0,0,0,0,0,0
0,0,0,0,0,0,0,0,0,0,0,0,0,0,0,0,0,0,0,0,0
0,0,0,0,0,0,7,0,0,0,0,0,0,0,7,0,0,0,0,0,0
0,0,0,0,0,0,11,0,0,0,0,0,0,0,0,0,0,0,0,0,0
0,0,0,0,0,0,7,0,0,0,0,0,0,0,7,0,0,0,0,0,0
0,0,0,0,0,0,0,0,0,0,0,0,0,0,11,0,0,0,0,0,0
0,0,0,0,0,0,7,0,0,0,0,0,0,0,7,0,0,0,0,0,0
0,0,0,0,0,0,6,7,11,7,0,7,11,7,6,0,0,0,0,0,0
0,0,0,0,0,0,0,0,0,0,0,0,0,0,0,0,0,0,0,0,0
0,0,0,0,0,0,0,0,0,0,0,0,0,0,0,0,0,0,0,0,0
0,0,0,0,0,0,0,0,0,0,0,0,0,0,0,0,0,0,0,0,0
0,0,0,0,0,0,0,0,0,0,0,0,0,0,0,0,0,0,0,0,0
0,0,0,0,0,0,0,0,0,0,0,0,0,0,0,0,0,0,0,0,0
0,0,0,0,0,0,0,0,0,0,0,0,0,0,0,0,0,0,0,0,0
endlayer

layer
0,0,0,0,0,0,0,0,0,0,0,0,0,0,0,0,0,0,0,0,0
0,0,0,0,0,0,0,0,0,0,0,0,0,0,0,0,0,0,0,0,0
0,0,0,0,0,0,0,0,0,0,0,0,0,0,0,0,0,0,0,0,0
0,0,0,0,0,0,0,0,0,0,0,0,0,0,0,0,0,0,0,0,0
0,0,0,0,0,0,0,0,0,0,0,0,0,0,0,0,0,0,0,0,0
0,0,0,0,0,0,0,0,0,0,0,0,0,0,0,0,0,0,0,0,0
0,0,0,0,0,0,6,7,11,7,0,7,11,7,6,0,0,0,0,0,0
0,0,0,0,0,0,7,0,0,0,0,0,0,0,7,0,0,0,0,0,0
0,0,0,0,0,0,0,0,0,0,0,0,0,0,11,0,0,0,0,0,0
0,0,0,0,0,0,7,0,0,0,0,0,0,0,7,0,0,0,0,0,0
0,0,0,0,0,0,0,0,0,0,0,0,0,0,0,0,0,0,0,0,0
0,0,0,0,0,0,7,0,0,0,0,0,0,0,7,0,0,0,0,0,0
0,0,0,0,0,0,0,0,0,0,0,0,0,0,0,0,0,0,0,0,0
0,0,0,0,0,0,7,0,0,0,0,0,0,0,7,0,0,0,0,0,0
0,0,0,0,0,0,6,7,0,7,0,7,0,7,6,0,0,0,0,0,0
0,0,0,0,0,0,0,0,0,0,0,0,0,0,0,0,0,0,0,0,0
0,0,0,0,0,0,0,0,0,0,0,0,0,0,0,0,0,0,0,0,0
0,0,0,0,0,0,0,0,0,0,0,0,0,0,0,0,0,0,0,0,0
0,0,0,0,0,0,0,0,0,0,0,0,0,0,0,0,0,0,0,0,0
0,0,0,0,0,0,0,0,0,0,0,0,0,0,0,0,0,0,0,0,0
0,0,0,0,0,0,0,0,0,0,0,0,0,0,0,0,0,0,0,0,0
endlayer

layer
0,0,0,0,0,0,0,0,0,0,0,0,0,0,0,0,0,0,0,0,0
0,0,0,0,0,0,0,0,0,0,0,0,0,0,0,0,0,0,0,0,0
0,0,0,0,0,0,0,0,0,0,0,0,0,0,0,0,0,0,0,0,0
0,0,0,0,0,0,0,0,0,0,0,0,0,0,0,0,0,0,0,0,0
0,0,0,0,0,0,0,0,0,0,0,0,0,0,0,0,0,0,0,0,0
0,0,0,0,0,0,0,0,0,0,0,0,0,0,0,0,0,0,0,0,0
0,0,0,0,0,0,6,7,0,7,0,7,0,7,6,0,0,0,0,0,0
0,0,0,0,0,0,7,0,0,0,0,0,0,0,7,0,0,0,0,0,0
0,0,0,0,0,0,11,0,0,0,0,0,0,0,0,0,0,0,0,0,0
0,0,0,0,0,0,7,0,0,0,0,0,0,0,7,0,0,0,0,0,0
0,0,0,0,0,0,0,0,0,0,0,0,0,0,0,0,0,0,0,0,0
0,0,0,0,0,0,7,0,0,0,0,0,0,0,7,0,0,0,0,0,0
0,0,0,0,0,0,0,0,0,0,0,0,0,0,11,0,0,0,0,0,0
0,0,0,0,0,0,7,0,0,0,0,0,0,0,7,0,0,0,0,0,0
0,0,0,0,0,0,6,7,0,7,0,7,0,7,6,0,0,0,0,0,0
0,0,0,0,0,0,0,0,0,0,0,0,0,0,0,0,0,0,0,0,0
0,0,0,0,0,0,0,0,0,0,0,0,0,0,0,0,0,0,0,0,0
0,0,0,0,0,0,0,0,0,0,0,0,0,0,0,0,0,0,0,0,0
0,0,0,0,0,0,0,0,0,0,0,0,0,0,0,0,0,0,0,0,0
0,0,0,0,0,0,0,0,0,0,0,0,0,0,0,0,0,0,0,0,0
0,0,0,0,0,0,0,0,0,0,0,0,0,0,0,0,0,0,0,0,0
endlayer

layer
0,0,0,0,0,0,0,0,0,0,0,0,0,0,0,0,0,0,0,0,0
0,0,0,0,0,0,0,0,0,0,0,0,0,0,0,0,0,0,0,0,0
0,0,0,0,0,0,0,0,0,0,0,0,0,0,0,0,0,0,0,0,0
0,0,0,0,0,0,0,0,0,0,0,0,0,0,0,0,0,0,0,0,0
0,0,0,0,0,0,0,0,0,0,0,0,0,0,0,0,0,0,0,0,0
0,0,0,0,0,0,0,0,0,0,0,0,0,0,0,0,0,0,0,0,0
0,0,0,0,0,0,6,7,0,7,0,7,0,0,6,0,0,0,0,0,0
0,0,0,0,0,0,7,0,0,0,0,0,0,0,7,0,0,0,0,0,0
0,0,0,0,0,0,0,0,0,0,0,0,0,0,0,0,0,0,0,0,0
0,0,0,0,0,0,7,0,0,0,0,0,0,0,7,0,0,0,0,0,0
0,0,0,0,0,0,0,0,0,0,0,0,0,0,11,0,0,0,0,0,0
0,0,0,0,0,0,7,0,0,0,0,0,0,0,7,0,0,0,0,0,0
0,0,0,0,0,0,0,0,0,0,0,0,0,0,0,0,0,0,0,0,0
0,0,0,0,0,0,7,0,0,0,0,0,0,0,7,0,0,0,0,0,0
0,0,0,0,0,0,6,7,0,7,0,7,0,7,6,0,0,0,0,0,0
0,0,0,0,0,0,0,0,0,0,0,0,0,0,0,0,0,0,0,0,0
0,0,0,0,0,0,0,0,0,0,0,0,0,0,0,0,0,0,0,0,0
0,0,0,0,0,0,0,0,0,0,0,0,0,0,0,0,0,0,0,0,0
0,0,0,0,0,0,0,0,0,0,0,0,0,0,0,0,0,0,0,0,0
0,0,0,0,0,0,0,0,0,0,0,0,0,0,0,0,0,0,0,0,0
0,0,0,0,0,0,0,0,0,0,0,0,0,0,0,0,0,0,0,0,0
endlayer

layer
0,0,0,0,0,0,0,0,0,0,0,0,0,0,0,0,0,0,0,0,0
0,0,0,0,0,0,0,0,0,0,0,0,0,0,0,0,0,0,0,0,0
0,0,0,0,0,0,0,0,0,0,0,0,0,0,0,0,0,0,0,0,0
0,0,0,0,0,0,0,0,0,0,0,0,0,0,0,0,0,0,0,0,0
0,0,0,0,0,0,0,0,0,0,0,0,0,0,0,0,0,0,0,0,0
0,0,0,0,0,0,0,0,0,0,0,0,0,0,0,0,0,0,0,0,0
0,0,0,0,0,0,6,7,0,7,0,7,11,7,6,0,0,0,0,0,0
0,0,0,0,0,0,7,0,0,0,0,0,0,0,7,0,0,0,0,0,0
0,0,0,0,0,0,11,0,0,0,0,0,0,0,0,0,0,0,0,0,0
0,0,0,0,0,0,7,0,0,0,0,0,0,0,7,0,0,0,0,0,0
0,0,0,0,0,0,11,0,0,0,0,0,0,0,0,0,0,0,0,0,0
0,0,0,0,0,0,7,0,0,0,0,0,0,0,7,0,0,0,0,0,0
0,0,0,0,0,0,0,0,0,0,0,0,0,0,0,0,0,0,0,0,0
0,0,0,0,0,0,7,0,0,0,0,0,0,0,7,0,0,0,0,0,0
0,0,0,0,0,0,6,7,0,7,0,7,11,0,6,0,0,0,0,0,0
0,0,0,0,0,0,0,0,0,0,0,0,0,0,0,0,0,0,0,0,0
0,0,0,0,0,0,0,0,0,0,0,0,0,0,0,0,0,0,0,0,0
0,0,0,0,0,0,0,0,0,0,0,0,0,0,0,0,0,0,0,0,0
0,0,0,0,0,0,0,0,0,0,0,0,0,0,0,0,0,0,0,0,0
0,0,0,0,0,0,0,0,0,0,0,0,0,0,0,0,0,0,0,0,0
0,0,0,0,0,0,0,0,0,0,0,0,0,0,0,0,0,0,0,0,0
endlayer

layer
0,0,0,0,0,0,0,0,0,0,0,0,0,0,0,0,0,0,0,0,0
0,0,0,0,0,0,0,0,0,0,0,0,0,0,0,0,0,0,0,0,0
0,0,0,0,0,0,0,0,0,0,0,0,0,0,0,0,0,0,0,0,0
0,0,0,0,0,0,0,0,0,0,0,0,0,0,0,0,0,0,0,0,0
0,0,0,0,0,0,0,0,0,0,0,0,0,0,0,0,0,0,0,0,0
0,0,0,0,0,0,0,0,0,0,0,0,0,0,0,0,0,0,0,0,0
0,0,0,0,0,0,6,7,0,7,0,7,11,0,6,0,0,0,0,0,0
0,0,0,0,0,0,7,0,0,0,0,0,0,0,7,0,0,0,0,0,0
0,0,0,0,0,0,0,0,0,0,0,0,0,0,11,0,0,0,0,0,0
0,0,0,0,0,0,7,0,0,0,0,0,0,0,7,0,0,0,0,0,0
0,0,0,0,0,0,0,0,0,0,0,0,0,0,11,0,0,0,0,0,0
0,0,0,0,0,0,7,0,0,0,0,0,0,0,7,0,0,0,0,0,0
0,0,0,0,0,0,0,0,0,0,0,0,0,0,0,0,0,0,0,0,0
0,0,0,0,0,0,7,0,0,0,0,0,0,0,7,0,0,0,0,0,0
0,0,0,0,0,0,6,7,0,7,0,7,0,7,6,0,0,0,0,0,0
0,0,0,0,0,0,0,0,0,0,0,0,0,0,0,0,0,0,0,0,0
0,0,0,0,0,0,0,0,0,0,0,0,0,0,0,0,0,0,0,0,0
0,0,0,0,0,0,0,0,0,0,0,0,0,0,0,0,0,0,0,0,0
0,0,0,0,0,0,0,0,0,0,0,0,0,0,0,0,0,0,0,0,0
0,0,0,0,0,0,0,0,0,0,0,0,0,0,0,0,0,0,0,0,0
0,0,0,0,0,0,0,0,0,0,0,0,0,0,0,0,0,0,0,0,0
endlayer

layer
0,0,0,0,0,0,0,0,0,0,0,0,0,0,0,0,0,0,0,0,0
0,0,0,0,0,0,0,0,0,0,0,0,0,0,0,0,0,0,0,0,0
0,0,0,0,0,0,0,0,0,0,0,0,0,0,0,0,0,0,0,0,0
0,0,0,0,0,0,0,0,0,0,0,0,0,0,0,0,0,0,0,0,0
0,0,0,0,0,0,0,0,0,0,0,0,0,0,0,0,0,0,0,0,0
0,0,0,0,0,0,0,0,0,0,0,0,0,0,0,0,0,0,0,0,0
0,0,0,0,0,0,6,7,0,7,0,7,0,7,6,0,0,0,0,0,0
0,0,0,0,0,0,7,0,0,0,0,0,0,0,7,0,0,0,0,0,0
0,0,0,0,0,0,0,0,0,0,0,0,0,0,11,0,0,0,0,0,0
0,0,0,0,0,0,7,0,0,0,0,0,0,0,7,0,0,0,0,0,0
0,0,0,0,0,0,0,0,0,0,0,0,0,0,11,0,0,0,0,0,0
0,0,0,0,0,0,7,0,0,0,0,0,0,0,7,0,0,0,0,0,0
0,0,0,0,0,0,11,0,0,0,0,0,0,0,0,0,0,0,0,0,0
0,0,0,0,0,0,7,0,0,0,0,0,0,0,7,0,0,0,0,0,0
0,0,0,0,0,0,6,7,0,7,0,7,11,7,6,0,0,0,0,0,0
0,0,0,0,0,0,0,0,0,0,0,0,0,0,0,0,0,0,0,0,0
0,0,0,0,0,0,0,0,0,0,0,0,0,0,0,0,0,0,0,0,0
0,0,0,0,0,0,0,0,0,0,0,0,0,0,0,0,0,0,0,0,0
0,0,0,0,0,0,0,0,0,0,0,0,0,0,0,0,0,0,0,0,0
0,0,0,0,0,0,0,0,0,0,0,0,0,0,0,0,0,0,0,0,0
0,0,0,0,0,0,0,0,0,0,0,0,0,0,0,0,0,0,0,0,0
endlayer

layer
0,0,0,0,0,0,0,0,0,0,0,0,0,0,0,0,0,0,0,0,0
0,0,0,0,0,0,0,0,0,0,0,0,0,0,0,0,0,0,0,0,0
0,0,0,0,0,0,0,0,0,0,0,0,0,0,0,0,0,0,0,0,0
0,0,0,0,0,0,0,0,0,0,0,0,0,0,0,0,0,0,0,0,0
0,0,0,0,0,0,0,0,0,0,0,0,0,0,0,0,0,0,0,0,0
0,0,0,0,0,0,0,0,0,0,0,0,0,0,0,0,0,0,0,0,0
0,0,0,0,0,0,6,7,0,7,0,7,11,7,6,0,0,0,0,0,0
0,0,0,0,0,0,7,0,0,0,0,0,0,0,7,0,0,0,0,0,0
0,0,0,0,0,0,11,0,0,0,0,0,0,0,0,0,0,0,0,0,0
0,0,0,0,0,0,7,0,0,0,0,0,0,0,7,0,0,0,0,0,0
0,0,0,0,0,0,0,0,0,0,0,0,0,0,0,0,0,0,0,0,0
0,0,0,0,0,0,7,0,0,0,0,0,0,0,0,0,0,0,0,0,0
0,0,0,0,0,0,0,0,0,0,0,0,0,0,11,0,0,0,0,0,0
0,0,0,0,0,0,7,0,0,0,0,0,0,0,7,0,0,0,0,0,0
0,0,0,0,0,0,6,7,11,7,0,7,11,7,6,0,0,0,0,0,0
0,0,0,0,0,0,0,0,0,0,0,0,0,0,0,0,0,0,0,0,0
0,0,0,0,0,0,0,0,0,0,0,0,0,0,0,0,0,0,0,0,0
0,0,0,0,0,0,0,0,0,0,0,0,0,0,0,0,0,0,0,0,0
0,0,0,0,0,0,0,0,0,0,0,0,0,0,0,0,0,0,0,0,0
0,0,0,0,0,0,0,0,0,0,0,0,0,0,0,0,0,0,0,0,0
0,0,0,0,0,0,0,0,0,0,0,0,0,0,0,0,0,0,0,0,0
endlayer

layer
0,0,0,0,0,0,0,0,0,0,0,0,0,0,0,0,0,0,0,0,0
0,0,0,0,0,0,0,0,0,0,0,0,0,0,0,0,0,0,0,0,0
0,0,0,0,0,0,0,0,0,0,0,0,0,0,0,0,0,0,0,0,0
0,0,0,0,0,0,0,0,0,0,0,0,0,0,0,0,0,0,0,0,0
0,0,0,0,0,0,0,0,0,0,0,0,0,0,0,0,0,0,0,0,0
0,0,0,0,0,0,0,0,0,0,0,0,0,0,0,0,0,0,0,0,0
0,0,0,0,0,0,6,7,0,0,11,7,11,7,6,0,0,0,0,0,0
0,0,0,0,0,0,7,0,0,0,0,0,0,0,7,0,0,0,0,0,0
0,0,0,0,0,0,0,0,0,0,0,0,0,0,0,0,0,0,0,0,0
0,0,0,0,0,0,0,0,0,0,0,0,0,0,7,0,0,0,0,0,0
0,0,0,0,0,0,0,0,0,0,0,0,0,0,0,0,0,0,0,0,0
0,0,0,0,0,0,7,0,0,0,0,0,0,0,7,0,0,0,0,0,0
0,0,0,0,0,0,0,0,0,0,0,0,0,0,0,0,0,0,0,0,0
0,0,0,0,0,0,7,0,0,0,0,0,0,0,7,0,0,0,0,0,0
0,0,0,0,0,0,6,7,0,7,11,7,0,7,6,0,0,0,0,0,0
0,0,0,0,0,0,0,0,0,0,0,0,0,0,0,0,0,0,0,0,0
0,0,0,0,0,0,0,0,0,0,0,0,0,0,0,0,0,0,0,0,0
0,0,0,0,0,0,0,0,0,0,0,0,0,0,0,0,0,0,0,0,0
0,0,0,0,0,0,0,0,0,0,0,0,0,0,0,0,0,0,0,0,0
0,0,0,0,0,0,0,0,0,0,0,0,0,0,0,0,0,0,0,0,0
0,0,0,0,0,0,0,0,0,0,0,0,0,0,0,0,0,0,0,0,0
endlayer

layer
0,0,0,0,0,0,0,0,0,0,0,0,0,0,0,0,0,0,0,0,0
0,0,0,0,0,0,0,0,0,0,0,0,0,0,0,0,0,0,0,0,0
0,0,0,0,0,0,0,0,0,0,0,0,0,0,0,0,0,0,0,0,0
0,0,0,0,0,0,0,0,0,0,0,0,0,0,0,0,0,0,0,0,0
0,0,0,0,0,0,0,0,0,0,0,0,0,0,0,0,0,0,0,0,0
0,0,0,0,0,0,0,0,0,0,0,0,0,0,0,0,0,0,0,0,0
0,0,0,0,0,0,6,6,6,6,6,6,6,6,6,0,0,0,0,0,0
0,0,0,0,0,0,6,13,13,13,13,13,13,13,6,0,0,0,0,0,0
0,0,0,0,0,0,6,13,0,0,0,0,0,13,6,0,0,0,0,0,0
0,0,0,0,0,0,6,13,0,0,0,0,0,13,6,0,0,0,0,0,0
0,0,0,0,0,0,6,13,0,0,0,0,0,13,6,0,0,0,0,0,0
0,0,0,0,0,0,6,13,0,0,0,0,0,13,6,0,0,0,0,0,0
0,0,0,0,0,0,6,13,0,0,0,0,0,13,6,0,0,0,0,0,0
0,0,0,0,0,0,6,13,13,13,13,13,13,13,6,0,0,0,0,0,0
0,0,0,0,0,0,6,6,6,6,6,6,6,6,6,0,0,0,0,0,0
0,0,0,0,0,0,0,0,0,0,0,0,0,0,0,0,0,0,0,0,0
0,0,0,0,0,0,0,0,0,0,0,0,0,0,0,0,0,0,0,0,0
0,0,0,0,0,0,0,0,0,0,0,0,0,0,0,0,0,0,0,0,0
0,0,0,0,0,0,0,0,0,0,0,0,0,0,0,0,0,0,0,0,0
0,0,0,0,0,0,0,0,0,0,0,0,0,0,0,0,0,0,0,0,0
0,0,0,0,0,0,0,0,0,0,0,0,0,0,0,0,0,0,0,0,0
endlayer

layer
0,0,0,0,0,0,0,0,0,0,0,0,0,0,0,0,0,0,0,0,0
0,0,0,0,0,0,0,0,0,0,0,0,0,0,0,0,0,0,0,0,0
0,0,0,0,0,0,0,0,0,0,0,0,0,0,0,0,0,0,0,0,0
0,0,0,0,0,0,0,0,0,0,0,0,0,0,0,0,0,0,0,0,0
0,0,0,0,0,0,0,0,0,0,0,0,0,0,0,0,0,0,0,0,0
0,0,0,0,0,0,0,0,0,0,0,0,0,0,0,0,0,0,0,0,0
0,0,0,0,0,0,0,0,0,0,0,0,0,0,0,0,0,0,0,0,0
0,0,0,0,0,0,0,0,0,0,0,0,0,0,0,0,0,0,0,0,0
0,0,0,0,0,0,0,0,13,13,13,13,13,0,0,0,0,0,0,0,0
0,0,0,0,0,0,0,0,13,0,0,0,13,0,0,0,0,0,0,0,0
0,0,0,0,0,0,0,0,13,0,0,0,13,0,0,0,0,0,0,0,0
0,0,0,0,0,0,0,0,13,0,0,0,13,0,0,0,0,0,0,0,0
0,0,0,0,0,0,0,0,13,13,13,13,13,0,0,0,0,0,0,0,0
0,0,0,0,0,0,0,0,0,0,0,0,0,0,0,0,0,0,0,0,0
0,0,0,0,0,0,0,0,0,0,0,0,0,0,0,0,0,0,0,0,0
0,0,0,0,0,0,0,0,0,0,0,0,0,0,0,0,0,0,0,0,0
0,0,0,0,0,0,0,0,0,0,0,0,0,0,0,0,0,0,0,0,0
0,0,0,0,0,0,0,0,0,0,0,0,0,0,0,0,0,0,0,0,0
0,0,0,0,0,0,0,0,0,0,0,0,0,0,0,0,0,0,0,0,0
0,0,0,0,0,0,0,0,0,0,0,0,0,0,0,0,0,0,0,0,0
0,0,0,0,0,0,0,0,0,0,0,0,0,0,0,0,0,0,0,0,0
endlayer

layer
0,0,0,0,0,0,0,0,0,0,0,0,0,0,0,0,0,0,0,0,0
0,0,0,0,0,0,0,0,0,0,0,0,0,0,0,0,0,0,0,0,0
0,0,0,0,0,0,0,0,0,0,0,0,0,0,0,0,0,0,0,0,0
0,0,0,0,0,0,0,0,0,0,0,0,0,0,0,0,0,0,0,0,0
0,0,0,0,0,0,0,0,0,0,0,0,0,0,0,0,0,0,0,0,0
0,0,0,0,0,0,0,0,0,0,0,0,0,0,0,0,0,0,0,0,0
0,0,0,0,0,0,0,0,0,0,0,0,0,0,0,0,0,0,0,0,0
0,0,0,0,0,0,0,0,0,0,0,0,0,0,0,0,0,0,0,0,0
0,0,0,0,0,0,0,0,0,0,0,0,0,0,0,0,0,0,0,0,0
0,0,0,0,0,0,0,0,0,13,13,13,0,0,0,0,0,0,0,0,0
0,0,0,0,0,0,0,0,0,13,0,13,0,0,0,0,0,0,0,0,0
0,0,0,0,0,0,0,0,0,13,13,13,0,0,0,0,0,0,0,0,0
0,0,0,0,0,0,0,0,0,0,0,0,0,0,0,0,0,0,0,0,0
0,0,0,0,0,0,0,0,0,0,0,0,0,0,0,0,0,0,0,0,0
0,0,0,0,0,0,0,0,0,0,0,0,0,0,0,0,0,0,0,0,0
0,0,0,0,0,0,0,0,0,0,0,0,0,0,0,0,0,0,0,0,0
0,0,0,0,0,0,0,0,0,0,0,0,0,0,0,0,0,0,0,0,0
0,0,0,0,0,0,0,0,0,0,0,0,0,0,0,0,0,0,0,0,0
0,0,0,0,0,0,0,0,0,0,0,0,0,0,0,0,0,0,0,0,0
0,0,0,0,0,0,0,0,0,0,0,0,0,0,0,0,0,0,0,0,0
0,0,0,0,0,0,0,0,0,0,0,0,0,0,0,0,0,0,0,0,0
endlayer

layer
0,0,0,0,0,0,0,0,0,0,0,0,0,0,0,0,0,0,0,0,0
0,0,0,0,0,0,0,0,0,0,0,0,0,0,0,0,0,0,0,0,0
0,0,0,0,0,0,0,0,0,0,0,0,0,0,0,0,0,0,0,0,0
0,0,0,0,0,0,0,0,0,0,0,0,0,0,0,0,0,0,0,0,0
0,0,0,0,0,0,0,0,0,0,0,0,0,0,0,0,0,0,0,0,0
0,0,0,0,0,0,0,0,0,0,0,0,0,0,0,0,0,0,0,0,0
0,0,0,0,0,0,0,0,0,0,0,0,0,0,0,0,0,0,0,0,0
0,0,0,0,0,0,0,0,0,0,0,0,0,0,0,0,0,0,0,0,0
0,0,0,0,0,0,0,0,0,0,0,0,0,0,0,0,0,0,0,0,0
0,0,0,0,0,0,0,0,0,0,0,0,0,0,0,0,0,0,0,0,0
0,0,0,0,0,0,0,0,0,0,13,0,0,0,0,0,0,0,0,0,0
0,0,0,0,0,0,0,0,0,0,0,0,0,0,0,0,0,0,0,0,0
0,0,0,0,0,0,0,0,0,0,0,0,0,0,0,0,0,0,0,0,0
0,0,0,0,0,0,0,0,0,0,0,0,0,0,0,0,0,0,0,0,0
0,0,0,0,0,0,0,0,0,0,0,0,0,0,0,0,0,0,0,0,0
0,0,0,0,0,0,0,0,0,0,0,0,0,0,0,0,0,0,0,0,0
0,0,0,0,0,0,0,0,0,0,0,0,0,0,0,0,0,0,0,0,0
0,0,0,0,0,0,0,0,0,0,0,0,0,0,0,0,0,0,0,0,0
0,0,0,0,0,0,0,0,0,0,0,0,0,0,0,0,0,0,0,0,0
0,0,0,0,0,0,0,0,0,0,0,0,0,0,0,0,0,0,0,0,0
0,0,0,0,0,0,0,0,0,0,0,0,0,0,0,0,0,0,0,0,0
endlayer

layer
0,0,0,0,0,0,0,0,0,0,0,0,0,0,0,0,0,0,0,0,0
0,0,0,0,0,0,0,0,0,0,0,0,0,0,0,0,0,0,0,0,0
0,0,0,0,0,0,0,0,0,0,0,0,0,0,0,0,0,0,0,0,0
0,0,0,0,0,0,0,0,0,0,0,0,0,0,0,0,0,0,0,0,0
0,0,0,0,0,0,0,0,0,0,0,0,0,0,0,0,0,0,0,0,0
0,0,0,0,0,0,0,0,0,0,0,0,0,0,0,0,0,0,0,0,0
0,0,0,0,0,0,0,0,0,0,0,0,0,0,0,0,0,0,0,0,0
0,0,0,0,0,0,0,0,0,0,0,0,0,0,0,0,0,0,0,0,0
0,0,0,0,0,0,0,0,0,0,0,0,0,0,0,0,0,0,0,0,0
0,0,0,0,0,0,0,0,0,0,0,0,0,0,0,0,0,0,0,0,0
0,0,0,0,0,0,0,0,0,0,13,0,0,0,0,0,0,0,0,0,0
0,0,0,0,0,0,0,0,0,0,0,0,0,0,0,0,0,0,0,0,0
0,0,0,0,0,0,0,0,0,0,0,0,0,0,0,0,0,0,0,0,0
0,0,0,0,0,0,0,0,0,0,0,0,0,0,0,0,0,0,0,0,0
0,0,0,0,0,0,0,0,0,0,0,0,0,0,0,0,0,0,0,0,0
0,0,0,0,0,0,0,0,0,0,0,0,0,0,0,0,0,0,0,0,0
0,0,0,0,0,0,0,0,0,0,0,0,0,0,0,0,0,0,0,0,0
0,0,0,0,0,0,0,0,0,0,0,0,0,0,0,0,0,0,0,0,0
0,0,0,0,0,0,0,0,0,0,0,0,0,0,0,0,0,0,0,0,0
0,0,0,0,0,0,0,0,0,0,0,0,0,0,0,0,0,0,0,0,0
0,0,0,0,0,0,0,0,0,0,0,0,0,0,0,0,0,0,0,0,0
endlayer

