# Converted from schematic
# THIS TEMPLATE USES DEFAULTS!  Please edit for corrections.
# If you need help, consult template_rules.txt

weight=1
embed_into_distance=11
acceptable_target_blocks=1,2,3,12,13,250
dimensions=33,21,21
allowable_overhang=0
max_cut_in=2
cut_in_buffer=1
max_leveling=2
leveling_buffer=1
preserve_water=0
preserve_lava=0
preserve_plants=0


rule1=0,100,3134-10
rule2=0,100,300
rule3=0,100,2843-4
rule4=0,100,308,308,308,308,308,308,313,313,314,327
rule5=0,100,2542
rule6=0,100,47,2837-7,2837-5,2837-8,47,2837-7,2837-5,2837-8,311,250,250
rule7=0,100,2843-14,2843-14,2843-14,2843-14,2843
rule8=0,95,2835-2,2835-2,2835-2,2835-2,2835-2,2835-2,2835-2,2835-1,2835-1,2835-0
rule9=0,100,2843-12
rule10=0,25,3225-3
rule11=0,95,300
rule12=0,100,3134,3134,3134,3134,3134,3134,3134,3134,3134,3134-8,3134-2


layer
1,1,1,1,1,1,1,1,1,1,1,1,1,1,1,1,1,1,1,1,1
1,1,1,1,1,1,1,1,1,1,1,1,1,1,1,1,1,1,1,1,1
1,1,2,2,2,2,2,2,2,2,2,2,2,2,2,2,2,2,2,1,1
1,1,2,2,2,2,3,3,3,3,3,3,3,3,3,2,2,2,2,1,1
1,1,2,2,2,3,3,3,3,3,3,3,3,3,3,3,2,2,2,1,1
1,1,2,2,3,3,3,3,3,3,3,3,3,3,3,3,3,2,2,1,1
1,1,2,3,3,3,3,3,3,3,3,3,3,3,3,3,3,3,2,1,1
2,2,2,3,3,3,3,3,3,3,3,3,3,3,3,3,3,3,2,1,1
2,2,2,3,3,3,3,3,3,3,3,3,3,3,3,3,3,3,2,1,1
2,2,2,3,3,3,3,3,3,3,3,3,3,3,3,3,3,3,3,1,1
2,2,2,3,3,3,3,3,3,3,3,3,3,3,3,3,3,3,3,1,1
2,2,2,2,2,2,3,3,3,3,3,3,3,0,3,3,4,3,3,1,1
2,2,2,2,2,2,6,3,3,3,3,3,3,3,3,3,3,3,2,1,1
2,2,2,2,2,2,3,3,3,3,3,3,3,5,3,3,3,3,2,1,1
2,2,2,2,2,2,3,3,3,3,3,3,3,3,3,3,3,3,2,1,1
2,2,2,2,2,2,3,3,3,3,3,3,3,3,3,3,3,2,2,1,1
2,2,2,2,2,3,3,3,3,3,3,3,3,3,3,3,2,2,2,1,1
2,2,2,2,2,2,3,3,3,3,3,3,3,3,3,2,2,2,2,1,1
2,2,2,2,2,2,2,2,2,2,2,2,2,2,2,2,2,2,2,1,1
2,2,2,2,2,1,1,1,1,1,1,1,1,1,1,1,1,1,1,1,1
2,2,2,2,1,1,1,1,1,1,1,1,1,1,1,1,1,1,1,1,1
endlayer

layer
2,2,2,2,2,2,2,2,2,2,2,2,2,2,2,2,2,2,2,2,2
2,2,2,2,2,2,2,2,2,2,2,2,2,2,2,2,2,2,2,2,2
2,2,2,2,2,2,7,7,7,7,7,7,7,7,7,2,2,2,2,2,2
2,2,2,2,2,7,0,0,9,0,0,0,9,0,0,7,2,2,2,2,2
2,2,2,2,7,0,0,0,9,0,0,0,9,0,0,0,7,2,2,2,2
2,2,2,7,9,9,9,0,9,9,0,9,9,0,9,9,9,7,2,2,2
2,2,2,0,0,9,2,0,0,0,0,0,0,0,0,0,0,0,7,2,2
2,2,7,2,2,9,2,2,0,0,0,0,0,0,0,0,0,0,7,2,2
2,2,2,2,2,9,2,2,2,0,0,0,0,0,0,0,0,2,7,2,2
2,2,2,2,2,2,2,2,0,0,0,0,0,0,0,0,0,0,8,2,2
2,2,7,2,2,9,2,2,2,0,0,0,0,0,0,0,0,2,2,2,2
2,2,2,2,2,2,2,2,0,0,0,0,0,0,0,0,2,2,8,2,2
2,2,2,2,2,2,2,2,0,0,0,0,0,0,0,0,0,2,7,2,2
2,2,2,2,2,2,2,0,0,0,0,0,0,0,0,0,0,2,7,2,2
2,2,2,2,2,2,0,0,0,0,0,0,0,0,0,0,0,0,7,2,2
2,2,2,2,2,2,9,0,9,9,0,9,9,0,9,9,9,7,2,2,2
2,2,2,2,2,2,2,2,9,0,0,0,9,0,0,0,7,2,2,2,2
2,2,2,2,2,7,2,2,9,0,0,0,9,0,0,7,2,2,2,2,2
2,2,2,2,2,2,7,7,7,7,7,7,7,7,7,2,2,2,2,2,2
2,2,2,2,2,2,2,2,2,2,2,2,2,2,2,2,2,2,2,2,2
2,2,2,2,2,2,2,2,2,2,2,2,2,2,2,2,2,2,2,2,2
endlayer

layer
2,2,2,2,2,2,2,2,2,2,2,2,2,2,2,2,2,2,2,2,2
2,2,2,2,2,2,2,2,2,2,2,2,2,2,2,2,2,2,2,2,2
2,2,2,2,2,2,7,8,2,8,2,8,0,8,7,2,2,2,2,2,2
2,2,2,2,2,8,0,0,9,0,0,0,9,0,0,8,2,2,2,2,2
2,2,2,2,7,0,0,0,9,0,0,0,9,0,0,0,7,2,2,2,2
2,2,2,8,9,9,9,0,9,9,0,9,9,0,9,9,9,8,2,2,2
2,2,7,0,0,9,0,0,0,0,0,0,0,0,0,0,0,0,7,2,2
2,2,2,2,2,9,0,0,0,0,0,0,0,0,0,0,0,0,8,2,2
2,2,2,2,2,9,0,0,0,0,0,0,0,0,0,0,0,0,2,2,2
2,2,2,2,2,2,0,0,0,0,0,0,0,0,0,0,0,0,8,2,2
2,2,2,2,2,9,2,0,0,0,0,0,0,0,0,0,0,0,2,2,2
2,2,2,2,2,2,2,0,0,0,0,0,0,0,0,0,0,2,2,2,2
2,2,2,2,2,2,2,0,0,0,0,0,0,0,0,0,0,0,2,2,2
2,2,2,2,2,2,2,0,0,0,0,0,0,0,0,0,0,0,8,2,2
2,2,2,2,2,2,0,0,0,0,0,0,0,0,0,0,0,0,7,2,2
2,2,2,2,2,2,9,0,9,9,0,9,9,0,9,9,9,8,2,2,2
2,2,2,2,2,2,2,0,9,0,0,0,9,0,0,0,7,2,2,2,2
2,2,2,2,2,8,2,2,9,0,0,0,9,0,0,8,2,2,2,2,2
2,2,2,2,2,2,7,8,2,8,2,8,10,8,7,2,2,2,2,2,2
2,2,2,2,2,2,2,2,2,2,2,2,2,2,2,2,2,2,2,2,2
2,2,2,2,2,2,2,2,2,2,2,2,2,2,2,2,2,2,2,2,2
endlayer

layer
2,2,2,2,2,2,2,2,2,2,2,2,2,2,2,2,2,2,2,2,2
2,2,2,2,2,2,2,2,2,2,2,2,2,2,2,2,2,2,2,2,2
2,2,2,2,2,2,7,8,2,8,2,8,10,8,7,2,2,2,2,2,2
2,2,2,2,2,8,0,0,0,0,0,0,0,0,0,8,2,2,2,2,2
2,2,2,2,7,0,0,0,0,0,0,0,0,0,0,0,7,2,2,2,2
2,2,2,8,0,0,0,0,0,0,0,0,0,0,0,0,0,8,2,2,2
2,2,7,0,0,0,0,0,0,0,0,0,0,0,0,0,0,0,7,2,2
2,2,8,2,2,0,0,0,0,0,0,0,0,0,0,0,0,0,8,2,2
2,2,2,2,2,2,0,0,0,0,0,0,0,0,0,0,0,0,2,2,2
2,2,2,2,2,0,0,0,0,0,0,0,0,0,0,0,0,0,8,2,2
2,2,2,2,2,2,0,0,0,0,0,0,0,0,0,0,0,0,8,2,2
2,2,2,2,2,2,2,0,0,0,0,0,0,0,0,0,0,0,2,2,2
2,2,2,2,2,2,0,0,0,0,0,0,0,0,0,0,0,0,2,2,2
2,2,2,2,2,2,0,0,0,0,0,0,0,0,0,0,0,0,8,2,2
2,2,2,2,2,2,0,0,0,0,0,0,0,0,0,0,0,0,7,2,2
2,2,2,2,2,2,0,0,0,0,0,0,0,0,0,0,0,8,2,2,2
2,2,2,2,2,2,0,0,0,0,0,0,0,0,0,0,7,2,2,2,2
2,2,2,2,2,2,2,0,0,0,0,0,0,0,0,8,2,2,2,2,2
2,2,2,2,2,2,7,8,2,8,10,8,2,8,7,2,2,2,2,2,2
2,2,2,2,2,2,2,2,2,2,2,2,2,2,2,2,2,2,2,2,2
2,2,2,2,2,2,2,2,2,2,2,2,2,2,2,2,2,2,2,2,2
endlayer

layer
2,2,2,2,2,2,2,2,2,2,2,2,2,2,2,2,2,2,2,2,2
2,2,2,2,2,2,2,2,2,2,2,2,2,2,2,2,2,2,2,2,2
2,2,2,2,2,2,7,8,2,8,2,8,2,8,7,2,2,2,2,2,2
2,2,2,2,2,8,0,0,0,0,0,0,0,0,0,8,2,2,2,2,2
2,2,2,2,7,0,0,0,0,0,0,0,0,0,0,0,7,2,2,2,2
2,2,2,8,0,0,0,0,0,0,0,0,0,0,0,0,0,8,2,2,2
2,2,7,0,0,0,0,0,0,0,0,0,0,0,0,0,0,0,7,2,2
2,2,8,2,2,0,0,0,0,0,0,0,0,0,0,0,0,0,8,2,2
2,2,2,2,2,0,0,0,0,0,0,0,0,0,0,0,0,0,8,2,2
2,2,2,2,2,0,0,0,0,0,0,0,0,0,0,0,0,0,8,2,2
2,2,2,2,2,0,0,0,0,0,0,0,0,0,0,0,0,0,8,2,2
2,2,2,2,2,0,0,0,0,0,0,0,0,0,0,0,0,0,2,2,2
2,2,2,2,2,2,0,0,0,0,0,0,0,0,0,0,0,0,8,2,2
2,2,2,2,2,0,0,0,0,0,0,0,0,0,0,0,0,0,8,2,2
2,2,2,2,2,2,0,0,0,0,0,0,0,0,0,0,0,0,7,2,2
2,2,2,2,2,0,0,0,0,0,0,0,0,0,0,0,0,8,2,2,2
2,2,2,2,2,2,0,0,0,0,0,0,0,0,0,0,7,2,2,2,2
2,2,2,2,2,2,0,0,0,0,0,0,0,0,0,8,2,2,2,2,2
2,2,2,2,2,2,7,8,0,8,2,2,2,8,7,2,2,2,2,2,2
2,2,2,2,2,2,2,2,2,2,2,2,2,2,2,2,2,2,2,2,2
2,2,2,2,2,2,2,2,2,2,2,2,2,2,2,2,2,2,2,2,2
endlayer

layer
2,2,2,2,2,2,2,2,2,2,2,2,2,2,2,2,2,2,2,2,2
2,2,2,2,2,2,2,2,2,2,2,2,2,2,2,2,2,2,2,2,2
2,2,2,2,2,2,7,8,0,0,10,8,0,8,7,2,2,2,2,2,2
2,2,2,2,2,8,0,0,0,0,0,0,0,0,0,8,2,2,2,2,2
2,2,2,2,7,0,0,0,0,0,0,0,0,0,0,0,7,2,2,2,2
2,2,2,8,0,0,0,0,0,0,0,0,0,0,0,0,0,8,2,2,2
2,2,7,0,0,0,0,0,0,0,0,0,0,0,0,0,0,0,7,2,2
2,2,8,2,2,0,0,0,0,0,0,0,0,0,0,0,0,0,8,2,2
2,2,2,2,2,0,0,0,0,0,0,0,0,0,0,0,0,0,0,2,2
2,2,2,2,2,0,0,0,0,0,0,0,0,0,0,0,0,0,8,2,2
2,2,2,2,0,0,0,0,0,0,0,0,0,0,0,0,0,0,0,2,2
2,2,2,2,0,0,0,0,0,0,0,0,0,0,0,0,0,0,8,2,2
2,2,2,0,0,0,0,0,0,0,0,0,0,0,0,0,0,0,0,2,2
2,2,2,2,2,0,0,0,0,0,0,0,0,0,0,0,0,0,8,2,2
2,2,2,2,2,2,0,0,0,0,0,0,0,0,0,0,0,0,7,2,2
2,2,2,2,2,0,0,0,0,0,0,0,0,0,0,0,0,8,2,2,2
2,2,2,2,2,2,0,0,0,0,0,0,0,0,0,0,7,2,2,2,2
2,2,2,2,2,2,0,0,0,0,0,0,0,0,0,8,2,2,2,2,2
2,2,2,2,2,2,7,8,0,8,0,8,10,8,7,2,2,2,2,2,2
2,2,2,2,2,2,2,2,2,2,2,2,2,2,2,2,2,2,2,2,2
2,2,2,2,2,2,2,2,2,2,2,2,2,2,2,2,2,2,2,2,2
endlayer

layer
2,2,2,2,2,2,2,2,2,2,2,2,2,2,2,2,2,2,2,2,2
2,2,2,2,2,2,2,2,2,2,2,2,2,2,2,2,2,2,2,2,2
2,2,2,2,2,2,7,8,10,8,10,8,0,8,7,2,2,2,2,2,2
2,2,2,2,2,8,0,0,0,0,0,0,0,0,0,8,2,2,2,2,2
2,2,2,2,7,0,0,0,0,0,0,0,0,0,0,0,7,2,2,2,2
2,2,2,8,0,0,0,0,0,0,0,0,0,0,0,0,0,8,2,2,2
2,2,7,0,0,0,0,0,0,0,0,0,0,0,0,0,0,0,7,2,2
2,2,8,2,2,0,0,0,0,0,0,0,0,0,0,0,0,0,8,2,2
2,2,2,2,0,0,0,0,0,0,0,0,0,0,0,0,0,0,0,2,2
2,2,2,2,0,0,0,0,0,0,0,0,0,0,0,0,0,0,0,2,2
2,2,2,2,0,0,0,0,0,0,0,0,0,0,0,0,0,0,0,2,2
2,2,2,0,0,0,0,0,0,0,0,0,0,0,0,0,0,0,8,2,2
2,2,2,0,0,0,0,0,0,0,0,0,0,0,0,0,0,0,10,2,2
2,2,2,2,0,0,0,0,0,0,0,0,0,0,0,0,0,0,8,2,2
2,2,2,2,2,2,0,0,0,0,0,0,0,0,0,0,0,0,7,2,2
2,2,2,2,2,0,0,0,0,0,0,0,0,0,0,0,0,8,2,2,2
2,2,2,2,2,2,0,0,0,0,0,0,0,0,0,0,7,2,2,2,2
2,2,2,2,2,2,0,0,0,0,0,0,0,0,0,8,2,2,2,2,2
2,2,2,2,2,2,7,8,0,8,0,8,0,8,7,2,2,2,2,2,2
2,2,2,2,2,2,2,2,2,2,2,2,2,2,2,2,2,2,2,2,2
2,2,2,2,2,2,2,2,2,2,2,2,2,2,2,2,2,2,2,2,2
endlayer

layer
2,2,2,2,2,2,2,2,2,2,2,2,2,2,2,2,2,2,2,2,2
2,2,2,2,2,2,2,2,2,2,2,2,2,2,2,2,2,2,2,2,2
2,2,2,2,2,2,7,7,7,7,7,7,7,7,7,2,2,2,2,2,2
2,2,2,2,2,7,0,0,0,0,0,0,0,0,0,7,2,2,2,2,2
2,2,2,2,7,0,0,0,0,0,0,0,0,0,0,0,7,2,2,2,2
2,2,2,7,0,0,0,0,0,0,0,0,0,0,0,0,0,7,2,2,2
2,2,7,0,0,0,0,0,0,0,0,0,0,0,0,0,0,0,7,2,2
2,2,7,2,2,0,0,0,0,0,0,0,0,0,0,0,0,0,7,2,2
2,2,2,2,0,0,0,0,0,0,0,0,0,0,0,0,0,0,7,2,2
2,2,2,0,0,0,0,0,0,0,0,0,0,0,0,0,0,0,7,2,2
2,2,2,0,0,0,0,0,0,0,0,0,0,0,0,0,0,0,7,2,2
2,2,2,0,0,0,0,0,0,0,0,0,0,0,0,0,0,0,7,2,2
2,2,2,0,0,0,0,0,0,0,0,0,0,0,0,0,0,0,7,2,2
2,2,2,2,0,0,0,0,0,0,0,0,0,0,0,0,0,0,7,2,2
2,2,2,2,2,0,0,0,0,0,0,0,0,0,0,0,0,0,7,2,2
2,2,2,2,2,0,0,0,0,0,0,0,0,0,0,0,0,7,2,2,2
2,2,2,2,2,2,0,0,0,0,0,0,0,0,0,0,7,2,2,2,2
2,2,2,2,2,2,0,0,0,0,0,0,0,0,0,7,2,2,2,2,2
2,2,2,2,2,2,7,7,7,7,7,7,7,7,7,2,2,2,2,2,2
2,2,2,2,2,2,2,2,2,2,2,2,2,2,2,2,2,2,2,2,2
2,2,2,2,2,2,2,2,2,2,2,2,2,2,2,2,2,2,2,2,2
endlayer

layer
2,2,2,2,2,2,2,2,2,2,2,2,2,2,2,2,2,2,2,2,2
2,2,2,2,2,2,2,2,2,2,2,2,2,2,2,2,2,2,2,2,2
2,2,2,2,2,2,2,2,2,2,2,2,2,2,2,2,2,2,2,2,2
2,2,2,2,2,2,7,7,7,7,7,7,7,7,7,2,2,2,2,2,2
2,2,2,2,2,7,3,3,3,3,3,3,3,3,3,7,2,2,2,2,2
2,2,2,2,7,3,3,3,3,3,3,3,3,3,3,3,7,2,2,2,2
2,2,2,7,3,3,3,3,3,3,3,3,3,3,3,3,3,7,2,2,2
2,2,2,7,3,3,3,3,3,3,3,3,3,3,3,3,3,7,2,2,2
2,2,2,7,3,3,3,3,3,3,3,3,3,3,3,3,3,7,2,2,2
2,2,2,7,3,3,3,3,3,3,3,3,3,3,3,3,3,7,2,2,2
2,2,2,7,3,3,3,3,3,3,3,3,3,3,3,3,3,7,2,2,2
2,2,2,7,3,3,3,3,3,3,3,3,3,3,3,3,3,7,2,2,2
2,2,2,7,3,3,3,3,3,3,3,3,3,3,3,3,3,7,2,2,2
2,2,2,7,0,3,3,3,3,3,3,3,3,5,3,3,3,7,2,2,2
2,2,2,2,0,0,3,3,3,3,3,3,3,3,3,3,3,7,2,2,2
2,2,2,2,7,3,3,3,3,3,3,3,3,3,3,3,7,2,2,2,2
2,2,2,2,2,7,3,3,3,3,3,3,3,3,3,7,2,2,2,2,2
2,2,2,2,2,2,7,7,7,7,7,7,7,7,7,2,2,2,2,2,2
2,2,2,2,2,2,2,2,2,2,2,2,2,2,2,2,2,2,2,2,2
2,2,2,2,2,2,2,2,2,2,2,2,2,2,2,2,2,2,2,2,2
2,2,2,2,2,2,2,2,2,2,2,2,2,2,2,2,2,2,2,2,2
endlayer

layer
2,2,2,2,2,2,2,2,2,2,2,2,2,2,2,2,2,2,2,2,2
2,2,2,2,2,2,2,2,2,2,2,2,2,2,2,2,2,2,2,2,2
2,2,2,2,2,2,2,2,2,2,2,2,2,2,2,2,2,2,2,2,2
2,2,2,2,2,2,7,8,2,8,2,8,2,8,7,2,2,2,2,2,2
2,2,2,2,2,8,9,2,2,2,2,2,2,2,9,8,2,2,2,2,2
2,2,2,2,8,0,9,0,2,2,2,2,0,0,9,0,8,2,2,2,2
2,2,2,7,0,0,9,0,9,9,9,9,0,0,9,0,0,7,2,2,2
2,2,2,8,0,0,9,0,9,0,0,9,0,0,0,0,0,8,2,2,2
2,2,2,2,2,0,0,0,0,0,0,9,0,0,9,9,9,2,2,2,2
2,2,2,8,9,9,9,0,9,9,0,9,0,0,0,0,0,8,2,2,2
2,2,2,2,2,2,9,0,9,0,0,0,0,0,9,0,2,2,2,2,2
2,2,2,8,2,0,0,0,9,0,0,9,0,0,9,0,0,8,2,2,2
2,2,2,2,9,9,9,0,9,9,9,9,0,0,9,9,9,2,2,2,2
2,2,2,8,0,0,0,0,0,0,0,0,0,0,0,0,0,8,2,2,2
2,2,2,2,0,0,9,9,0,9,9,0,9,0,9,0,0,7,2,2,2
2,2,2,2,8,0,9,2,0,9,0,0,9,0,9,0,8,2,2,2,2
2,2,2,2,2,8,9,2,0,9,2,2,9,0,9,8,2,2,2,2,2
2,2,2,2,2,2,7,8,2,8,2,8,2,8,7,2,2,2,2,2,2
2,2,2,2,2,2,2,2,2,2,2,2,2,2,2,2,2,2,2,2,2
2,2,2,2,2,2,2,2,2,2,2,2,2,2,2,2,2,2,2,2,2
2,2,2,2,2,2,2,2,2,2,2,2,2,2,2,2,2,2,2,2,2
endlayer

layer
11,11,11,11,11,11,11,11,11,11,11,11,11,11,11,11,11,11,11,11,11
11,11,11,11,11,11,11,11,11,11,11,11,11,11,11,11,11,11,11,11,11
11,11,11,11,11,11,11,11,11,11,11,11,11,11,11,11,11,11,11,11,11
11,11,11,11,11,11,7,8,11,8,11,8,11,8,7,11,11,11,11,11,11
11,11,11,11,11,8,9,0,0,0,11,0,11,0,9,8,11,11,11,11,11
11,11,11,11,8,0,9,0,0,0,0,0,0,0,9,0,8,11,11,11,11
11,11,11,7,0,0,9,0,9,9,9,9,0,0,9,0,0,7,11,11,11
11,11,11,8,0,0,9,0,9,0,0,9,0,0,0,0,0,11,11,11,11
11,11,11,0,0,0,0,0,0,0,0,9,0,0,9,9,9,11,11,11,11
11,11,11,8,9,9,9,0,9,9,0,9,0,0,0,0,0,8,11,11,11
11,11,11,11,0,0,9,0,9,0,0,0,0,0,9,0,0,11,11,11,11
11,11,11,8,0,0,0,0,9,0,0,9,0,0,9,0,0,8,11,11,11
11,11,11,11,9,9,9,0,9,9,9,9,0,0,9,9,9,0,11,11,11
11,11,11,8,0,0,0,0,0,0,0,0,0,0,0,0,0,8,11,11,11
11,11,11,7,0,0,9,9,0,9,9,0,9,0,9,0,0,7,11,11,11
11,11,11,11,8,0,9,0,0,9,0,0,9,0,9,0,8,11,11,11,11
11,11,11,11,11,8,9,0,0,9,0,0,9,0,9,8,11,11,11,11,11
11,11,11,11,11,11,7,8,0,8,11,8,11,8,7,11,11,11,11,11,11
11,11,11,11,11,11,11,11,11,11,11,11,11,11,11,11,11,11,11,11,11
11,11,11,11,11,11,11,11,11,11,11,11,11,11,11,11,11,11,11,11,11
11,11,11,11,11,11,11,11,11,11,11,11,11,11,11,11,11,11,11,11,11
endlayer

layer
0,0,0,0,0,0,0,0,0,0,0,0,0,0,0,0,0,0,0,0,0
0,0,0,0,0,0,0,0,0,0,0,0,0,0,0,0,0,0,0,0,0
0,0,0,0,0,0,0,0,0,0,0,0,0,0,0,0,0,0,0,0,0
0,0,0,0,0,0,7,8,10,8,0,8,0,8,7,0,0,0,0,0,0
0,0,0,0,0,8,0,0,0,0,0,0,0,0,0,0,0,0,0,0,0
0,0,0,0,8,0,0,0,0,0,0,0,0,0,0,0,8,0,0,0,0
0,0,0,7,0,0,0,0,0,0,0,0,0,0,0,0,0,7,0,0,0
0,0,0,8,0,0,0,0,0,0,0,0,0,0,0,0,0,8,0,0,0
0,0,0,10,0,0,0,0,0,0,0,0,0,0,0,0,0,10,0,0,0
0,0,0,8,0,0,0,0,0,0,0,0,0,0,0,0,0,8,0,0,0
0,0,0,0,0,0,0,0,0,0,0,0,0,0,0,0,0,10,0,0,0
0,0,0,8,0,0,0,0,0,0,0,0,0,0,0,0,0,8,0,0,0
0,0,0,0,0,0,0,0,0,0,0,0,0,0,0,0,0,0,0,0,0
0,0,0,8,0,0,0,0,0,0,0,0,0,0,0,0,0,8,0,0,0
0,0,0,7,0,0,0,0,0,0,0,0,0,0,0,0,0,7,0,0,0
0,0,0,0,8,0,0,0,0,0,0,0,0,0,0,0,8,0,0,0,0
0,0,0,0,0,8,0,0,0,0,0,0,0,0,0,8,0,0,0,0,0
0,0,0,0,0,0,7,8,0,8,10,8,0,8,7,0,0,0,0,0,0
0,0,0,0,0,0,0,0,0,0,0,0,0,0,0,0,0,0,0,0,0
0,0,0,0,0,0,0,0,0,0,0,0,0,0,0,0,0,0,0,0,0
0,0,0,0,0,0,0,0,0,0,0,0,0,0,0,0,0,0,0,0,0
endlayer

layer
0,0,0,0,0,0,0,0,0,0,0,0,0,0,0,0,0,0,0,0,0
0,0,0,0,0,0,0,0,0,0,0,0,0,0,0,0,0,0,0,0,0
0,0,0,0,0,0,0,0,0,0,0,0,0,0,0,0,0,0,0,0,0
0,0,0,0,0,0,7,0,0,8,0,8,0,8,7,0,0,0,0,0,0
0,0,0,0,0,8,0,0,0,0,0,0,0,0,0,0,0,0,0,0,0
0,0,0,0,8,0,0,0,0,0,0,0,0,0,0,0,8,0,0,0,0
0,0,0,7,0,0,0,0,0,0,0,0,0,0,0,0,0,7,0,0,0
0,0,0,8,0,0,0,0,0,0,0,0,0,0,0,0,0,8,0,0,0
0,0,0,10,0,0,0,0,0,0,0,0,0,0,0,0,0,0,0,0,0
0,0,0,8,0,0,0,0,0,0,0,0,0,0,0,0,0,8,0,0,0
0,0,0,0,0,0,0,0,0,0,0,0,0,0,0,0,0,10,0,0,0
0,0,0,8,0,0,0,0,0,0,0,0,0,0,0,0,0,8,0,0,0
0,0,0,0,0,0,0,0,0,0,0,0,0,0,0,0,0,0,0,0,0
0,0,0,8,0,0,0,0,0,0,0,0,0,0,0,0,0,8,0,0,0
0,0,0,7,0,0,0,0,0,0,0,0,0,0,0,0,0,7,0,0,0
0,0,0,0,8,0,0,0,0,0,0,0,0,0,0,0,8,0,0,0,0
0,0,0,0,0,8,0,0,0,0,0,0,0,0,0,8,0,0,0,0,0
0,0,0,0,0,0,7,0,0,8,0,8,0,8,7,0,0,0,0,0,0
0,0,0,0,0,0,0,0,0,0,0,0,0,0,0,0,0,0,0,0,0
0,0,0,0,0,0,0,0,0,0,0,0,0,0,0,0,0,0,0,0,0
0,0,0,0,0,0,0,0,0,0,0,0,0,0,0,0,0,0,0,0,0
endlayer

layer
0,0,0,0,0,0,0,0,0,0,0,0,0,0,0,0,0,0,0,0,0
0,0,0,0,0,0,0,0,0,0,0,0,0,0,0,0,0,0,0,0,0
0,0,0,0,0,0,0,0,0,0,0,0,0,0,0,0,0,0,0,0,0
0,0,0,0,0,0,7,8,0,8,10,8,0,8,7,0,0,0,0,0,0
0,0,0,0,0,8,0,0,0,0,0,0,0,0,0,8,0,0,0,0,0
0,0,0,0,8,0,0,0,0,0,0,0,0,0,0,0,8,0,0,0,0
0,0,0,7,0,0,0,0,0,0,0,0,0,0,0,0,0,7,0,0,0
0,0,0,8,0,0,0,0,0,0,0,0,0,0,0,0,0,8,0,0,0
0,0,0,10,0,0,0,0,0,0,0,0,0,0,0,0,0,0,0,0,0
0,0,0,8,0,0,0,0,0,0,0,0,0,0,0,0,0,8,0,0,0
0,0,0,10,0,0,0,0,0,0,0,0,0,0,0,0,0,0,0,0,0
0,0,0,8,0,0,0,0,0,0,0,0,0,0,0,0,0,8,0,0,0
0,0,0,0,0,0,0,0,0,0,0,0,0,0,0,0,0,10,0,0,0
0,0,0,8,0,0,0,0,0,0,0,0,0,0,0,0,0,8,0,0,0
0,0,0,7,0,0,0,0,0,0,0,0,0,0,0,0,0,7,0,0,0
0,0,0,0,0,0,0,0,0,0,0,0,0,0,0,0,8,0,0,0,0
0,0,0,0,0,8,0,0,0,0,0,0,0,0,0,8,0,0,0,0,0
0,0,0,0,0,0,7,8,0,8,10,8,0,8,7,0,0,0,0,0,0
0,0,0,0,0,0,0,0,0,0,0,0,0,0,0,0,0,0,0,0,0
0,0,0,0,0,0,0,0,0,0,0,0,0,0,0,0,0,0,0,0,0
0,0,0,0,0,0,0,0,0,0,0,0,0,0,0,0,0,0,0,0,0
endlayer

layer
0,0,0,0,0,0,0,0,0,0,0,0,0,0,0,0,0,0,0,0,0
0,0,0,0,0,0,0,0,0,0,0,0,0,0,0,0,0,0,0,0,0
0,0,0,0,0,0,0,0,0,0,0,0,0,0,0,0,0,0,0,0,0
0,0,0,0,0,0,7,8,10,8,0,8,10,8,7,0,0,0,0,0,0
0,0,0,0,0,8,0,0,0,0,0,0,0,0,0,8,0,0,0,0,0
0,0,0,0,8,0,0,0,0,0,0,0,0,0,0,0,8,0,0,0,0
0,0,0,7,0,0,0,0,0,0,0,0,0,0,0,0,0,7,0,0,0
0,0,0,8,0,0,0,0,0,0,0,0,0,0,0,0,0,8,0,0,0
0,0,0,0,0,0,0,0,0,0,0,0,0,0,0,0,0,10,0,0,0
0,0,0,8,0,0,0,0,0,0,0,0,0,0,0,0,0,8,0,0,0
0,0,0,0,0,0,0,0,0,0,0,0,0,0,0,0,0,0,0,0,0
0,0,0,8,0,0,0,0,0,0,0,0,0,0,0,0,0,8,0,0,0
0,0,0,10,0,0,0,0,0,0,0,0,0,0,0,0,0,0,0,0,0
0,0,0,8,0,0,0,0,0,0,0,0,0,0,0,0,0,8,0,0,0
0,0,0,7,0,0,0,0,0,0,0,0,0,0,0,0,0,7,0,0,0
0,0,0,0,8,0,0,0,0,0,0,0,0,0,0,0,8,0,0,0,0
0,0,0,0,0,0,0,0,0,0,0,0,0,0,0,0,0,0,0,0,0
0,0,0,0,0,0,7,8,10,8,0,8,0,8,7,0,0,0,0,0,0
0,0,0,0,0,0,0,0,0,0,0,0,0,0,0,0,0,0,0,0,0
0,0,0,0,0,0,0,0,0,0,0,0,0,0,0,0,0,0,0,0,0
0,0,0,0,0,0,0,0,0,0,0,0,0,0,0,0,0,0,0,0,0
endlayer

layer
0,0,0,0,0,0,0,0,0,0,0,0,0,0,0,0,0,0,0,0,0
0,0,0,0,0,0,0,0,0,0,0,0,0,0,0,0,0,0,0,0,0
0,0,0,0,0,0,0,0,0,0,0,0,0,0,0,0,0,0,0,0,0
0,0,0,0,0,0,7,7,7,7,7,7,7,7,7,0,0,0,0,0,0
0,0,0,0,0,7,0,0,0,0,0,0,0,0,0,7,0,0,0,0,0
0,0,0,0,7,0,0,0,0,0,0,0,0,0,0,0,7,0,0,0,0
0,0,0,7,0,0,0,0,0,0,0,0,0,0,0,0,0,7,0,0,0
0,0,0,7,0,0,0,0,0,0,0,0,0,0,0,0,0,7,0,0,0
0,0,0,7,0,0,0,0,0,0,0,0,0,0,0,0,0,7,0,0,0
0,0,0,7,0,0,0,0,0,0,0,0,0,0,0,0,0,7,0,0,0
0,0,0,7,0,0,0,0,0,0,0,0,0,0,0,0,0,7,0,0,0
0,0,0,7,0,0,0,0,0,0,0,0,0,0,0,0,0,7,0,0,0
0,0,0,7,0,0,0,0,0,0,0,0,0,0,0,0,0,7,0,0,0
0,0,0,7,0,0,0,0,0,0,0,0,0,0,0,0,0,7,0,0,0
0,0,0,7,0,0,0,0,0,0,0,0,0,0,0,0,0,7,0,0,0
0,0,0,0,7,0,0,0,0,0,0,0,0,0,0,0,7,0,0,0,0
0,0,0,0,0,7,0,0,0,0,0,0,0,0,0,7,0,0,0,0,0
0,0,0,0,0,0,7,7,7,7,7,7,7,7,7,0,0,0,0,0,0
0,0,0,0,0,0,0,0,0,0,0,0,0,0,0,0,0,0,0,0,0
0,0,0,0,0,0,0,0,0,0,0,0,0,0,0,0,0,0,0,0,0
0,0,0,0,0,0,0,0,0,0,0,0,0,0,0,0,0,0,0,0,0
endlayer

layer
0,0,0,0,0,0,0,0,0,0,0,0,0,0,0,0,0,0,0,0,0
0,0,0,0,0,0,0,0,0,0,0,0,0,0,0,0,0,0,0,0,0
0,0,0,0,0,0,0,0,0,0,0,0,0,0,0,0,0,0,0,0,0
0,0,0,0,0,0,0,0,0,0,0,0,0,0,0,0,0,0,0,0,0
0,0,0,0,0,0,7,7,7,7,7,7,7,7,7,0,0,0,0,0,0
0,0,0,0,0,7,0,0,0,0,0,0,0,0,0,7,0,0,0,0,0
0,0,0,0,7,0,0,0,0,0,0,0,0,0,0,0,7,0,0,0,0
0,0,0,0,7,0,0,0,0,0,0,0,0,0,0,0,7,0,0,0,0
0,0,0,0,7,0,0,0,0,0,0,0,0,0,0,0,7,0,0,0,0
0,0,0,0,7,0,0,0,0,0,0,0,0,0,0,0,7,0,0,0,0
0,0,0,0,7,0,0,0,0,0,0,0,0,0,0,0,7,0,0,0,0
0,0,0,0,7,0,0,0,0,0,0,0,0,0,0,0,7,0,0,0,0
0,0,0,0,7,0,0,0,0,0,0,0,0,0,0,0,7,0,0,0,0
0,0,0,0,7,0,0,0,0,0,0,0,0,0,0,0,7,0,0,0,0
0,0,0,0,7,0,0,0,0,0,0,0,0,0,0,0,7,0,0,0,0
0,0,0,0,0,7,0,0,0,0,0,0,0,0,0,7,0,0,0,0,0
0,0,0,0,0,0,7,7,7,7,7,7,7,7,7,0,0,0,0,0,0
0,0,0,0,0,0,0,0,0,0,0,0,0,0,0,0,0,0,0,0,0
0,0,0,0,0,0,0,0,0,0,0,0,0,0,0,0,0,0,0,0,0
0,0,0,0,0,0,0,0,0,0,0,0,0,0,0,0,0,0,0,0,0
0,0,0,0,0,0,0,0,0,0,0,0,0,0,0,0,0,0,0,0,0
endlayer

layer
0,0,0,0,0,0,0,0,0,0,0,0,0,0,0,0,0,0,0,0,0
0,0,0,0,0,0,0,0,0,0,0,0,0,0,0,0,0,0,0,0,0
0,0,0,0,0,0,0,0,0,0,0,0,0,0,0,0,0,0,0,0,0
0,0,0,0,0,0,0,0,0,0,0,0,0,0,0,0,0,0,0,0,0
0,0,0,0,0,0,0,0,0,0,0,0,0,0,0,0,0,0,0,0,0
0,0,0,0,0,0,7,7,7,7,7,7,7,7,7,0,0,0,0,0,0
0,0,0,0,0,7,7,3,3,3,3,3,3,3,3,7,0,0,0,0,0
0,0,0,0,0,7,3,3,3,3,3,3,3,3,3,7,0,0,0,0,0
0,0,0,0,0,7,3,3,3,3,3,3,3,3,3,7,0,0,0,0,0
0,0,0,0,0,7,3,3,3,3,3,3,3,3,3,7,0,0,0,0,0
0,0,0,0,0,7,3,3,3,3,3,3,3,3,3,7,0,0,0,0,0
0,0,0,0,0,7,3,3,3,3,3,3,3,3,3,7,0,0,0,0,0
0,0,0,0,0,7,3,3,3,3,3,3,3,3,3,7,0,0,0,0,0
0,0,0,0,0,7,3,3,3,3,3,3,3,5,3,7,0,0,0,0,0
0,0,0,0,0,7,3,3,3,3,3,3,3,3,7,7,0,0,0,0,0
0,0,0,0,0,0,7,7,7,7,7,7,7,7,7,0,0,0,0,0,0
0,0,0,0,0,0,0,0,0,0,0,0,0,0,0,0,0,0,0,0,0
0,0,0,0,0,0,0,0,0,0,0,0,0,0,0,0,0,0,0,0,0
0,0,0,0,0,0,0,0,0,0,0,0,0,0,0,0,0,0,0,0,0
0,0,0,0,0,0,0,0,0,0,0,0,0,0,0,0,0,0,0,0,0
0,0,0,0,0,0,0,0,0,0,0,0,0,0,0,0,0,0,0,0,0
endlayer

layer
0,0,0,0,0,0,0,0,0,0,0,0,0,0,0,0,0,0,0,0,0
0,0,0,0,0,0,0,0,0,0,0,0,0,0,0,0,0,0,0,0,0
0,0,0,0,0,0,0,0,0,0,0,0,0,0,0,0,0,0,0,0,0
0,0,0,0,0,0,0,0,0,0,0,0,0,0,0,0,0,0,0,0,0
0,0,0,0,0,0,0,0,0,0,0,0,0,0,0,0,0,0,0,0,0
0,0,0,0,0,0,0,0,0,0,0,0,0,0,0,0,0,0,0,0,0
0,0,0,0,0,0,7,8,0,8,0,8,0,8,7,0,0,0,0,0,0
0,0,0,0,0,0,8,0,0,0,0,0,0,0,8,0,0,0,0,0,0
0,0,0,0,0,0,0,0,0,0,0,0,0,0,0,0,0,0,0,0,0
0,0,0,0,0,0,8,0,0,0,0,0,0,0,8,0,0,0,0,0,0
0,0,0,0,0,0,10,0,0,0,0,0,0,0,0,0,0,0,0,0,0
0,0,0,0,0,0,8,0,0,0,0,0,0,0,0,0,0,0,0,0,0
0,0,0,0,0,0,0,0,0,0,0,0,0,0,10,0,0,0,0,0,0
0,0,0,0,0,0,8,0,0,0,0,0,0,0,8,0,0,0,0,0,0
0,0,0,0,0,0,7,8,10,8,0,8,10,8,7,0,0,0,0,0,0
0,0,0,0,0,0,0,0,0,0,0,0,0,0,0,0,0,0,0,0,0
0,0,0,0,0,0,0,0,0,0,0,0,0,0,0,0,0,0,0,0,0
0,0,0,0,0,0,0,0,0,0,0,0,0,0,0,0,0,0,0,0,0
0,0,0,0,0,0,0,0,0,0,0,0,0,0,0,0,0,0,0,0,0
0,0,0,0,0,0,0,0,0,0,0,0,0,0,0,0,0,0,0,0,0
0,0,0,0,0,0,0,0,0,0,0,0,0,0,0,0,0,0,0,0,0
endlayer

layer
0,0,0,0,0,0,0,0,0,0,0,0,0,0,0,0,0,0,0,0,0
0,0,0,0,0,0,0,0,0,0,0,0,0,0,0,0,0,0,0,0,0
0,0,0,0,0,0,0,0,0,0,0,0,0,0,0,0,0,0,0,0,0
0,0,0,0,0,0,0,0,0,0,0,0,0,0,0,0,0,0,0,0,0
0,0,0,0,0,0,0,0,0,0,0,0,0,0,0,0,0,0,0,0,0
0,0,0,0,0,0,0,0,0,0,0,0,0,0,0,0,0,0,0,0,0
0,0,0,0,0,0,7,8,10,8,0,8,10,8,7,0,0,0,0,0,0
0,0,0,0,0,0,8,0,0,0,0,0,0,0,8,0,0,0,0,0,0
0,0,0,0,0,0,0,0,0,0,0,0,0,0,10,0,0,0,0,0,0
0,0,0,0,0,0,8,0,0,0,0,0,0,0,8,0,0,0,0,0,0
0,0,0,0,0,0,0,0,0,0,0,0,0,0,0,0,0,0,0,0,0
0,0,0,0,0,0,8,0,0,0,0,0,0,0,8,0,0,0,0,0,0
0,0,0,0,0,0,0,0,0,0,0,0,0,0,0,0,0,0,0,0,0
0,0,0,0,0,0,8,0,0,0,0,0,0,0,8,0,0,0,0,0,0
0,0,0,0,0,0,7,8,0,8,0,8,0,8,7,0,0,0,0,0,0
0,0,0,0,0,0,0,0,0,0,0,0,0,0,0,0,0,0,0,0,0
0,0,0,0,0,0,0,0,0,0,0,0,0,0,0,0,0,0,0,0,0
0,0,0,0,0,0,0,0,0,0,0,0,0,0,0,0,0,0,0,0,0
0,0,0,0,0,0,0,0,0,0,0,0,0,0,0,0,0,0,0,0,0
0,0,0,0,0,0,0,0,0,0,0,0,0,0,0,0,0,0,0,0,0
0,0,0,0,0,0,0,0,0,0,0,0,0,0,0,0,0,0,0,0,0
endlayer

layer
0,0,0,0,0,0,0,0,0,0,0,0,0,0,0,0,0,0,0,0,0
0,0,0,0,0,0,0,0,0,0,0,0,0,0,0,0,0,0,0,0,0
0,0,0,0,0,0,0,0,0,0,0,0,0,0,0,0,0,0,0,0,0
0,0,0,0,0,0,0,0,0,0,0,0,0,0,0,0,0,0,0,0,0
0,0,0,0,0,0,0,0,0,0,0,0,0,0,0,0,0,0,0,0,0
0,0,0,0,0,0,0,0,0,0,0,0,0,0,0,0,0,0,0,0,0
0,0,0,0,0,0,7,8,0,8,0,8,0,8,7,0,0,0,0,0,0
0,0,0,0,0,0,8,0,0,0,0,0,0,0,8,0,0,0,0,0,0
0,0,0,0,0,0,10,0,0,0,0,0,0,0,0,0,0,0,0,0,0
0,0,0,0,0,0,8,0,0,0,0,0,0,0,8,0,0,0,0,0,0
0,0,0,0,0,0,0,0,0,0,0,0,0,0,0,0,0,0,0,0,0
0,0,0,0,0,0,8,0,0,0,0,0,0,0,8,0,0,0,0,0,0
0,0,0,0,0,0,0,0,0,0,0,0,0,0,10,0,0,0,0,0,0
0,0,0,0,0,0,8,0,0,0,0,0,0,0,8,0,0,0,0,0,0
0,0,0,0,0,0,7,8,0,8,0,8,0,8,7,0,0,0,0,0,0
0,0,0,0,0,0,0,0,0,0,0,0,0,0,0,0,0,0,0,0,0
0,0,0,0,0,0,0,0,0,0,0,0,0,0,0,0,0,0,0,0,0
0,0,0,0,0,0,0,0,0,0,0,0,0,0,0,0,0,0,0,0,0
0,0,0,0,0,0,0,0,0,0,0,0,0,0,0,0,0,0,0,0,0
0,0,0,0,0,0,0,0,0,0,0,0,0,0,0,0,0,0,0,0,0
0,0,0,0,0,0,0,0,0,0,0,0,0,0,0,0,0,0,0,0,0
endlayer

layer
0,0,0,0,0,0,0,0,0,0,0,0,0,0,0,0,0,0,0,0,0
0,0,0,0,0,0,0,0,0,0,0,0,0,0,0,0,0,0,0,0,0
0,0,0,0,0,0,0,0,0,0,0,0,0,0,0,0,0,0,0,0,0
0,0,0,0,0,0,0,0,0,0,0,0,0,0,0,0,0,0,0,0,0
0,0,0,0,0,0,0,0,0,0,0,0,0,0,0,0,0,0,0,0,0
0,0,0,0,0,0,0,0,0,0,0,0,0,0,0,0,0,0,0,0,0
0,0,0,0,0,0,7,8,0,8,10,8,0,0,7,0,0,0,0,0,0
0,0,0,0,0,0,8,0,0,0,0,0,0,0,8,0,0,0,0,0,0
0,0,0,0,0,0,0,0,0,0,0,0,0,0,0,0,0,0,0,0,0
0,0,0,0,0,0,8,0,0,0,0,0,0,0,8,0,0,0,0,0,0
0,0,0,0,0,0,0,0,0,0,0,0,0,0,10,0,0,0,0,0,0
0,0,0,0,0,0,8,0,0,0,0,0,0,0,8,0,0,0,0,0,0
0,0,0,0,0,0,0,0,0,0,0,0,0,0,0,0,0,0,0,0,0
0,0,0,0,0,0,8,0,0,0,0,0,0,0,8,0,0,0,0,0,0
0,0,0,0,0,0,7,8,0,8,0,8,0,8,7,0,0,0,0,0,0
0,0,0,0,0,0,0,0,0,0,0,0,0,0,0,0,0,0,0,0,0
0,0,0,0,0,0,0,0,0,0,0,0,0,0,0,0,0,0,0,0,0
0,0,0,0,0,0,0,0,0,0,0,0,0,0,0,0,0,0,0,0,0
0,0,0,0,0,0,0,0,0,0,0,0,0,0,0,0,0,0,0,0,0
0,0,0,0,0,0,0,0,0,0,0,0,0,0,0,0,0,0,0,0,0
0,0,0,0,0,0,0,0,0,0,0,0,0,0,0,0,0,0,0,0,0
endlayer

layer
0,0,0,0,0,0,0,0,0,0,0,0,0,0,0,0,0,0,0,0,0
0,0,0,0,0,0,0,0,0,0,0,0,0,0,0,0,0,0,0,0,0
0,0,0,0,0,0,0,0,0,0,0,0,0,0,0,0,0,0,0,0,0
0,0,0,0,0,0,0,0,0,0,0,0,0,0,0,0,0,0,0,0,0
0,0,0,0,0,0,0,0,0,0,0,0,0,0,0,0,0,0,0,0,0
0,0,0,0,0,0,0,0,0,0,0,0,0,0,0,0,0,0,0,0,0
0,0,0,0,0,0,7,8,0,8,10,8,10,8,7,0,0,0,0,0,0
0,0,0,0,0,0,8,0,0,0,0,0,0,0,8,0,0,0,0,0,0
0,0,0,0,0,0,10,0,0,0,0,0,0,0,0,0,0,0,0,0,0
0,0,0,0,0,0,8,0,0,0,0,0,0,0,8,0,0,0,0,0,0
0,0,0,0,0,0,10,0,0,0,0,0,0,0,0,0,0,0,0,0,0
0,0,0,0,0,0,8,0,0,0,0,0,0,0,8,0,0,0,0,0,0
0,0,0,0,0,0,0,0,0,0,0,0,0,0,0,0,0,0,0,0,0
0,0,0,0,0,0,8,0,0,0,0,0,0,0,8,0,0,0,0,0,0
0,0,0,0,0,0,7,8,0,8,0,8,10,0,7,0,0,0,0,0,0
0,0,0,0,0,0,0,0,0,0,0,0,0,0,0,0,0,0,0,0,0
0,0,0,0,0,0,0,0,0,0,0,0,0,0,0,0,0,0,0,0,0
0,0,0,0,0,0,0,0,0,0,0,0,0,0,0,0,0,0,0,0,0
0,0,0,0,0,0,0,0,0,0,0,0,0,0,0,0,0,0,0,0,0
0,0,0,0,0,0,0,0,0,0,0,0,0,0,0,0,0,0,0,0,0
0,0,0,0,0,0,0,0,0,0,0,0,0,0,0,0,0,0,0,0,0
endlayer

layer
0,0,0,0,0,0,0,0,0,0,0,0,0,0,0,0,0,0,0,0,0
0,0,0,0,0,0,0,0,0,0,0,0,0,0,0,0,0,0,0,0,0
0,0,0,0,0,0,0,0,0,0,0,0,0,0,0,0,0,0,0,0,0
0,0,0,0,0,0,0,0,0,0,0,0,0,0,0,0,0,0,0,0,0
0,0,0,0,0,0,0,0,0,0,0,0,0,0,0,0,0,0,0,0,0
0,0,0,0,0,0,0,0,0,0,0,0,0,0,0,0,0,0,0,0,0
0,0,0,0,0,0,7,8,0,8,0,8,10,0,7,0,0,0,0,0,0
0,0,0,0,0,0,8,0,0,0,0,0,0,0,8,0,0,0,0,0,0
0,0,0,0,0,0,0,0,0,0,0,0,0,0,10,0,0,0,0,0,0
0,0,0,0,0,0,8,0,0,0,0,0,0,0,8,0,0,0,0,0,0
0,0,0,0,0,0,0,0,0,0,0,0,0,0,10,0,0,0,0,0,0
0,0,0,0,0,0,8,0,0,0,0,0,0,0,8,0,0,0,0,0,0
0,0,0,0,0,0,0,0,0,0,0,0,0,0,0,0,0,0,0,0,0
0,0,0,0,0,0,8,0,0,0,0,0,0,0,8,0,0,0,0,0,0
0,0,0,0,0,0,7,8,0,8,0,8,0,8,7,0,0,0,0,0,0
0,0,0,0,0,0,0,0,0,0,0,0,0,0,0,0,0,0,0,0,0
0,0,0,0,0,0,0,0,0,0,0,0,0,0,0,0,0,0,0,0,0
0,0,0,0,0,0,0,0,0,0,0,0,0,0,0,0,0,0,0,0,0
0,0,0,0,0,0,0,0,0,0,0,0,0,0,0,0,0,0,0,0,0
0,0,0,0,0,0,0,0,0,0,0,0,0,0,0,0,0,0,0,0,0
0,0,0,0,0,0,0,0,0,0,0,0,0,0,0,0,0,0,0,0,0
endlayer

layer
0,0,0,0,0,0,0,0,0,0,0,0,0,0,0,0,0,0,0,0,0
0,0,0,0,0,0,0,0,0,0,0,0,0,0,0,0,0,0,0,0,0
0,0,0,0,0,0,0,0,0,0,0,0,0,0,0,0,0,0,0,0,0
0,0,0,0,0,0,0,0,0,0,0,0,0,0,0,0,0,0,0,0,0
0,0,0,0,0,0,0,0,0,0,0,0,0,0,0,0,0,0,0,0,0
0,0,0,0,0,0,0,0,0,0,0,0,0,0,0,0,0,0,0,0,0
0,0,0,0,0,0,7,8,0,8,0,8,0,8,7,0,0,0,0,0,0
0,0,0,0,0,0,8,0,0,0,0,0,0,0,8,0,0,0,0,0,0
0,0,0,0,0,0,0,0,0,0,0,0,0,0,10,0,0,0,0,0,0
0,0,0,0,0,0,8,0,0,0,0,0,0,0,8,0,0,0,0,0,0
0,0,0,0,0,0,0,0,0,0,0,0,0,0,10,0,0,0,0,0,0
0,0,0,0,0,0,8,0,0,0,0,0,0,0,8,0,0,0,0,0,0
0,0,0,0,0,0,10,0,0,0,0,0,0,0,0,0,0,0,0,0,0
0,0,0,0,0,0,8,0,0,0,0,0,0,0,8,0,0,0,0,0,0
0,0,0,0,0,0,7,8,0,8,0,8,10,8,7,0,0,0,0,0,0
0,0,0,0,0,0,0,0,0,0,0,0,0,0,0,0,0,0,0,0,0
0,0,0,0,0,0,0,0,0,0,0,0,0,0,0,0,0,0,0,0,0
0,0,0,0,0,0,0,0,0,0,0,0,0,0,0,0,0,0,0,0,0
0,0,0,0,0,0,0,0,0,0,0,0,0,0,0,0,0,0,0,0,0
0,0,0,0,0,0,0,0,0,0,0,0,0,0,0,0,0,0,0,0,0
0,0,0,0,0,0,0,0,0,0,0,0,0,0,0,0,0,0,0,0,0
endlayer

layer
0,0,0,0,0,0,0,0,0,0,0,0,0,0,0,0,0,0,0,0,0
0,0,0,0,0,0,0,0,0,0,0,0,0,0,0,0,0,0,0,0,0
0,0,0,0,0,0,0,0,0,0,0,0,0,0,0,0,0,0,0,0,0
0,0,0,0,0,0,0,0,0,0,0,0,0,0,0,0,0,0,0,0,0
0,0,0,0,0,0,0,0,0,0,0,0,0,0,0,0,0,0,0,0,0
0,0,0,0,0,0,0,0,0,0,0,0,0,0,0,0,0,0,0,0,0
0,0,0,0,0,0,7,8,0,8,0,8,10,8,7,0,0,0,0,0,0
0,0,0,0,0,0,8,0,0,0,0,0,0,0,8,0,0,0,0,0,0
0,0,0,0,0,0,10,0,0,0,0,0,0,0,0,0,0,0,0,0,0
0,0,0,0,0,0,8,0,0,0,0,0,0,0,8,0,0,0,0,0,0
0,0,0,0,0,0,0,0,0,0,0,0,0,0,0,0,0,0,0,0,0
0,0,0,0,0,0,8,0,0,0,0,0,0,0,0,0,0,0,0,0,0
0,0,0,0,0,0,0,0,0,0,0,0,0,0,10,0,0,0,0,0,0
0,0,0,0,0,0,8,0,0,0,0,0,0,0,8,0,0,0,0,0,0
0,0,0,0,0,0,7,8,10,8,0,8,10,8,7,0,0,0,0,0,0
0,0,0,0,0,0,0,0,0,0,0,0,0,0,0,0,0,0,0,0,0
0,0,0,0,0,0,0,0,0,0,0,0,0,0,0,0,0,0,0,0,0
0,0,0,0,0,0,0,0,0,0,0,0,0,0,0,0,0,0,0,0,0
0,0,0,0,0,0,0,0,0,0,0,0,0,0,0,0,0,0,0,0,0
0,0,0,0,0,0,0,0,0,0,0,0,0,0,0,0,0,0,0,0,0
0,0,0,0,0,0,0,0,0,0,0,0,0,0,0,0,0,0,0,0,0
endlayer

layer
0,0,0,0,0,0,0,0,0,0,0,0,0,0,0,0,0,0,0,0,0
0,0,0,0,0,0,0,0,0,0,0,0,0,0,0,0,0,0,0,0,0
0,0,0,0,0,0,0,0,0,0,0,0,0,0,0,0,0,0,0,0,0
0,0,0,0,0,0,0,0,0,0,0,0,0,0,0,0,0,0,0,0,0
0,0,0,0,0,0,0,0,0,0,0,0,0,0,0,0,0,0,0,0,0
0,0,0,0,0,0,0,0,0,0,0,0,0,0,0,0,0,0,0,0,0
0,0,0,0,0,0,7,8,0,0,10,8,10,8,7,0,0,0,0,0,0
0,0,0,0,0,0,8,0,0,0,0,0,0,0,8,0,0,0,0,0,0
0,0,0,0,0,0,0,0,0,0,0,0,0,0,0,0,0,0,0,0,0
0,0,0,0,0,0,0,0,0,0,0,0,0,0,8,0,0,0,0,0,0
0,0,0,0,0,0,0,0,0,0,0,0,0,0,0,0,0,0,0,0,0
0,0,0,0,0,0,8,0,0,0,0,0,0,0,8,0,0,0,0,0,0
0,0,0,0,0,0,0,0,0,0,0,0,0,0,0,0,0,0,0,0,0
0,0,0,0,0,0,8,0,0,0,0,0,0,0,8,0,0,0,0,0,0
0,0,0,0,0,0,7,8,0,8,10,8,0,8,7,0,0,0,0,0,0
0,0,0,0,0,0,0,0,0,0,0,0,0,0,0,0,0,0,0,0,0
0,0,0,0,0,0,0,0,0,0,0,0,0,0,0,0,0,0,0,0,0
0,0,0,0,0,0,0,0,0,0,0,0,0,0,0,0,0,0,0,0,0
0,0,0,0,0,0,0,0,0,0,0,0,0,0,0,0,0,0,0,0,0
0,0,0,0,0,0,0,0,0,0,0,0,0,0,0,0,0,0,0,0,0
0,0,0,0,0,0,0,0,0,0,0,0,0,0,0,0,0,0,0,0,0
endlayer

layer
0,0,0,0,0,0,0,0,0,0,0,0,0,0,0,0,0,0,0,0,0
0,0,0,0,0,0,0,0,0,0,0,0,0,0,0,0,0,0,0,0,0
0,0,0,0,0,0,0,0,0,0,0,0,0,0,0,0,0,0,0,0,0
0,0,0,0,0,0,0,0,0,0,0,0,0,0,0,0,0,0,0,0,0
0,0,0,0,0,0,0,0,0,0,0,0,0,0,0,0,0,0,0,0,0
0,0,0,0,0,0,0,0,0,0,0,0,0,0,0,0,0,0,0,0,0
0,0,0,0,0,0,7,7,7,7,7,7,7,7,7,0,0,0,0,0,0
0,0,0,0,0,0,7,12,12,12,12,12,12,12,7,0,0,0,0,0,0
0,0,0,0,0,0,7,12,0,0,0,0,0,12,7,0,0,0,0,0,0
0,0,0,0,0,0,7,12,0,0,0,0,0,12,7,0,0,0,0,0,0
0,0,0,0,0,0,7,12,0,0,0,0,0,12,7,0,0,0,0,0,0
0,0,0,0,0,0,7,12,0,0,0,0,0,12,7,0,0,0,0,0,0
0,0,0,0,0,0,7,12,0,0,0,0,0,12,7,0,0,0,0,0,0
0,0,0,0,0,0,7,12,12,12,12,12,12,12,7,0,0,0,0,0,0
0,0,0,0,0,0,7,7,7,7,7,7,7,7,7,0,0,0,0,0,0
0,0,0,0,0,0,0,0,0,0,0,0,0,0,0,0,0,0,0,0,0
0,0,0,0,0,0,0,0,0,0,0,0,0,0,0,0,0,0,0,0,0
0,0,0,0,0,0,0,0,0,0,0,0,0,0,0,0,0,0,0,0,0
0,0,0,0,0,0,0,0,0,0,0,0,0,0,0,0,0,0,0,0,0
0,0,0,0,0,0,0,0,0,0,0,0,0,0,0,0,0,0,0,0,0
0,0,0,0,0,0,0,0,0,0,0,0,0,0,0,0,0,0,0,0,0
endlayer

layer
0,0,0,0,0,0,0,0,0,0,0,0,0,0,0,0,0,0,0,0,0
0,0,0,0,0,0,0,0,0,0,0,0,0,0,0,0,0,0,0,0,0
0,0,0,0,0,0,0,0,0,0,0,0,0,0,0,0,0,0,0,0,0
0,0,0,0,0,0,0,0,0,0,0,0,0,0,0,0,0,0,0,0,0
0,0,0,0,0,0,0,0,0,0,0,0,0,0,0,0,0,0,0,0,0
0,0,0,0,0,0,0,0,0,0,0,0,0,0,0,0,0,0,0,0,0
0,0,0,0,0,0,0,0,0,0,0,0,0,0,0,0,0,0,0,0,0
0,0,0,0,0,0,0,0,0,0,0,0,0,0,0,0,0,0,0,0,0
0,0,0,0,0,0,0,0,12,12,12,12,12,0,0,0,0,0,0,0,0
0,0,0,0,0,0,0,0,12,0,0,0,12,0,0,0,0,0,0,0,0
0,0,0,0,0,0,0,0,12,0,0,0,12,0,0,0,0,0,0,0,0
0,0,0,0,0,0,0,0,12,0,0,0,12,0,0,0,0,0,0,0,0
0,0,0,0,0,0,0,0,12,12,12,12,12,0,0,0,0,0,0,0,0
0,0,0,0,0,0,0,0,0,0,0,0,0,0,0,0,0,0,0,0,0
0,0,0,0,0,0,0,0,0,0,0,0,0,0,0,0,0,0,0,0,0
0,0,0,0,0,0,0,0,0,0,0,0,0,0,0,0,0,0,0,0,0
0,0,0,0,0,0,0,0,0,0,0,0,0,0,0,0,0,0,0,0,0
0,0,0,0,0,0,0,0,0,0,0,0,0,0,0,0,0,0,0,0,0
0,0,0,0,0,0,0,0,0,0,0,0,0,0,0,0,0,0,0,0,0
0,0,0,0,0,0,0,0,0,0,0,0,0,0,0,0,0,0,0,0,0
0,0,0,0,0,0,0,0,0,0,0,0,0,0,0,0,0,0,0,0,0
endlayer

layer
0,0,0,0,0,0,0,0,0,0,0,0,0,0,0,0,0,0,0,0,0
0,0,0,0,0,0,0,0,0,0,0,0,0,0,0,0,0,0,0,0,0
0,0,0,0,0,0,0,0,0,0,0,0,0,0,0,0,0,0,0,0,0
0,0,0,0,0,0,0,0,0,0,0,0,0,0,0,0,0,0,0,0,0
0,0,0,0,0,0,0,0,0,0,0,0,0,0,0,0,0,0,0,0,0
0,0,0,0,0,0,0,0,0,0,0,0,0,0,0,0,0,0,0,0,0
0,0,0,0,0,0,0,0,0,0,0,0,0,0,0,0,0,0,0,0,0
0,0,0,0,0,0,0,0,0,0,0,0,0,0,0,0,0,0,0,0,0
0,0,0,0,0,0,0,0,0,0,0,0,0,0,0,0,0,0,0,0,0
0,0,0,0,0,0,0,0,0,12,12,12,0,0,0,0,0,0,0,0,0
0,0,0,0,0,0,0,0,0,12,0,12,0,0,0,0,0,0,0,0,0
0,0,0,0,0,0,0,0,0,12,12,12,0,0,0,0,0,0,0,0,0
0,0,0,0,0,0,0,0,0,0,0,0,0,0,0,0,0,0,0,0,0
0,0,0,0,0,0,0,0,0,0,0,0,0,0,0,0,0,0,0,0,0
0,0,0,0,0,0,0,0,0,0,0,0,0,0,0,0,0,0,0,0,0
0,0,0,0,0,0,0,0,0,0,0,0,0,0,0,0,0,0,0,0,0
0,0,0,0,0,0,0,0,0,0,0,0,0,0,0,0,0,0,0,0,0
0,0,0,0,0,0,0,0,0,0,0,0,0,0,0,0,0,0,0,0,0
0,0,0,0,0,0,0,0,0,0,0,0,0,0,0,0,0,0,0,0,0
0,0,0,0,0,0,0,0,0,0,0,0,0,0,0,0,0,0,0,0,0
0,0,0,0,0,0,0,0,0,0,0,0,0,0,0,0,0,0,0,0,0
endlayer

layer
0,0,0,0,0,0,0,0,0,0,0,0,0,0,0,0,0,0,0,0,0
0,0,0,0,0,0,0,0,0,0,0,0,0,0,0,0,0,0,0,0,0
0,0,0,0,0,0,0,0,0,0,0,0,0,0,0,0,0,0,0,0,0
0,0,0,0,0,0,0,0,0,0,0,0,0,0,0,0,0,0,0,0,0
0,0,0,0,0,0,0,0,0,0,0,0,0,0,0,0,0,0,0,0,0
0,0,0,0,0,0,0,0,0,0,0,0,0,0,0,0,0,0,0,0,0
0,0,0,0,0,0,0,0,0,0,0,0,0,0,0,0,0,0,0,0,0
0,0,0,0,0,0,0,0,0,0,0,0,0,0,0,0,0,0,0,0,0
0,0,0,0,0,0,0,0,0,0,0,0,0,0,0,0,0,0,0,0,0
0,0,0,0,0,0,0,0,0,0,0,0,0,0,0,0,0,0,0,0,0
0,0,0,0,0,0,0,0,0,0,12,0,0,0,0,0,0,0,0,0,0
0,0,0,0,0,0,0,0,0,0,0,0,0,0,0,0,0,0,0,0,0
0,0,0,0,0,0,0,0,0,0,0,0,0,0,0,0,0,0,0,0,0
0,0,0,0,0,0,0,0,0,0,0,0,0,0,0,0,0,0,0,0,0
0,0,0,0,0,0,0,0,0,0,0,0,0,0,0,0,0,0,0,0,0
0,0,0,0,0,0,0,0,0,0,0,0,0,0,0,0,0,0,0,0,0
0,0,0,0,0,0,0,0,0,0,0,0,0,0,0,0,0,0,0,0,0
0,0,0,0,0,0,0,0,0,0,0,0,0,0,0,0,0,0,0,0,0
0,0,0,0,0,0,0,0,0,0,0,0,0,0,0,0,0,0,0,0,0
0,0,0,0,0,0,0,0,0,0,0,0,0,0,0,0,0,0,0,0,0
0,0,0,0,0,0,0,0,0,0,0,0,0,0,0,0,0,0,0,0,0
endlayer

layer
0,0,0,0,0,0,0,0,0,0,0,0,0,0,0,0,0,0,0,0,0
0,0,0,0,0,0,0,0,0,0,0,0,0,0,0,0,0,0,0,0,0
0,0,0,0,0,0,0,0,0,0,0,0,0,0,0,0,0,0,0,0,0
0,0,0,0,0,0,0,0,0,0,0,0,0,0,0,0,0,0,0,0,0
0,0,0,0,0,0,0,0,0,0,0,0,0,0,0,0,0,0,0,0,0
0,0,0,0,0,0,0,0,0,0,0,0,0,0,0,0,0,0,0,0,0
0,0,0,0,0,0,0,0,0,0,0,0,0,0,0,0,0,0,0,0,0
0,0,0,0,0,0,0,0,0,0,0,0,0,0,0,0,0,0,0,0,0
0,0,0,0,0,0,0,0,0,0,0,0,0,0,0,0,0,0,0,0,0
0,0,0,0,0,0,0,0,0,0,0,0,0,0,0,0,0,0,0,0,0
0,0,0,0,0,0,0,0,0,0,12,0,0,0,0,0,0,0,0,0,0
0,0,0,0,0,0,0,0,0,0,0,0,0,0,0,0,0,0,0,0,0
0,0,0,0,0,0,0,0,0,0,0,0,0,0,0,0,0,0,0,0,0
0,0,0,0,0,0,0,0,0,0,0,0,0,0,0,0,0,0,0,0,0
0,0,0,0,0,0,0,0,0,0,0,0,0,0,0,0,0,0,0,0,0
0,0,0,0,0,0,0,0,0,0,0,0,0,0,0,0,0,0,0,0,0
0,0,0,0,0,0,0,0,0,0,0,0,0,0,0,0,0,0,0,0,0
0,0,0,0,0,0,0,0,0,0,0,0,0,0,0,0,0,0,0,0,0
0,0,0,0,0,0,0,0,0,0,0,0,0,0,0,0,0,0,0,0,0
0,0,0,0,0,0,0,0,0,0,0,0,0,0,0,0,0,0,0,0,0
0,0,0,0,0,0,0,0,0,0,0,0,0,0,0,0,0,0,0,0,0
endlayer

layer
0,0,0,0,0,0,0,0,0,0,0,0,0,0,0,0,0,0,0,0,0
0,0,0,0,0,0,0,0,0,0,0,0,0,0,0,0,0,0,0,0,0
0,0,0,0,0,0,0,0,0,0,0,0,0,0,0,0,0,0,0,0,0
0,0,0,0,0,0,0,0,0,0,0,0,0,0,0,0,0,0,0,0,0
0,0,0,0,0,0,0,0,0,0,0,0,0,0,0,0,0,0,0,0,0
0,0,0,0,0,0,0,0,0,0,0,0,0,0,0,0,0,0,0,0,0
0,0,0,0,0,0,0,0,0,0,0,0,0,0,0,0,0,0,0,0,0
0,0,0,0,0,0,0,0,0,0,0,0,0,0,0,0,0,0,0,0,0
0,0,0,0,0,0,0,0,0,0,0,0,0,0,0,0,0,0,0,0,0
0,0,0,0,0,0,0,0,0,0,0,0,0,0,0,0,0,0,0,0,0
0,0,0,0,0,0,0,0,0,0,12,0,0,0,0,0,0,0,0,0,0
0,0,0,0,0,0,0,0,0,0,0,0,0,0,0,0,0,0,0,0,0
0,0,0,0,0,0,0,0,0,0,0,0,0,0,0,0,0,0,0,0,0
0,0,0,0,0,0,0,0,0,0,0,0,0,0,0,0,0,0,0,0,0
0,0,0,0,0,0,0,0,0,0,0,0,0,0,0,0,0,0,0,0,0
0,0,0,0,0,0,0,0,0,0,0,0,0,0,0,0,0,0,0,0,0
0,0,0,0,0,0,0,0,0,0,0,0,0,0,0,0,0,0,0,0,0
0,0,0,0,0,0,0,0,0,0,0,0,0,0,0,0,0,0,0,0,0
0,0,0,0,0,0,0,0,0,0,0,0,0,0,0,0,0,0,0,0,0
0,0,0,0,0,0,0,0,0,0,0,0,0,0,0,0,0,0,0,0,0
0,0,0,0,0,0,0,0,0,0,0,0,0,0,0,0,0,0,0,0,0
endlayer

