# Converted from schematic
# THIS TEMPLATE USES DEFAULTS!  Please edit for corrections.
# If you need help, consult template_rules.txt

weight=20
embed_into_distance=1
acceptable_target_blocks=1,2,3,12,13
dimensions=33,21,21
allowable_overhang=0
max_cut_in=2
cut_in_buffer=1
max_leveling=2
leveling_buffer=1
preserve_water=0
preserve_lava=0
preserve_plants=0


rule1=0,100,3134-10
rule2=0,100,250
rule3=0,100,2843-4
rule4=0,100,311
rule5=0,100,2542-0
rule6=0,100,2843-14,2843-14,2843-14,2843-14,2843
rule7=0,100,47,2837-7,2837-5,2837-8,47,2837-7,2837-5,2837-8,311
rule8=0,100,2843-15
rule9=0,100,2291-0
rule10=0,100,2248-0
rule11=0,100,2761-6,2761-6,2761-6,2761-7,2761-7
rule12=0,95,2835-2,2835-2,2835-2,2835-2,2835-2,2835-2,2835-2,2835-1,2835-1,2835-0
rule13=0,50,308,308,308,308,308,308,313,313,314,327
rule14=0,25,3225-3
rule15=0,100,2245
rule16=0,100,140-10
rule17=0,100,2781-4,2781-4,2781-4,2781-4,2781-4,2781-4,2781-4,2781-4,2781-4,2781-8


layer
1,1,1,1,1,1,1,1,1,1,1,1,1,1,1,1,1,1,1,1,1
1,1,1,1,1,1,1,1,1,1,1,1,1,1,1,1,1,1,1,1,1
1,1,2,2,2,2,2,2,2,2,2,2,2,2,2,2,2,2,2,1,1
1,1,2,2,2,2,3,3,3,3,3,3,3,3,3,2,2,2,2,1,1
1,1,2,2,2,3,3,3,3,3,3,3,3,3,3,3,2,2,2,1,1
1,1,2,2,3,3,3,3,3,3,3,3,3,3,3,3,3,2,2,1,1
1,1,2,3,3,3,3,3,3,3,3,3,3,3,3,3,3,3,2,1,1
1,1,2,3,3,3,3,3,3,3,3,3,3,3,3,3,3,3,2,1,1
1,1,2,3,3,3,3,3,3,3,3,3,3,3,3,3,3,3,2,1,1
1,1,2,3,3,3,3,3,3,3,3,3,3,3,3,3,3,3,2,1,1
1,1,2,3,3,3,3,3,3,3,3,3,3,3,3,3,3,3,2,1,1
1,1,2,3,3,3,3,3,3,3,3,3,3,3,3,3,3,3,2,1,1
1,1,2,3,3,3,3,3,3,3,3,3,3,3,3,3,3,3,2,1,1
1,1,2,3,3,3,3,5,3,4,3,3,3,3,3,3,3,3,2,1,1
1,1,2,3,3,3,3,3,3,3,3,3,3,3,3,3,3,3,2,1,1
1,1,2,2,3,3,3,3,3,3,3,3,3,3,3,3,3,2,2,1,1
1,1,2,2,2,3,3,3,3,3,3,3,3,3,3,3,2,2,2,1,1
1,1,2,2,2,2,3,3,3,3,3,3,3,3,3,2,2,2,2,1,1
1,1,2,2,2,2,2,2,2,3,3,3,2,2,2,2,2,2,2,1,1
1,1,1,1,1,1,1,1,1,1,1,1,1,1,1,1,1,1,1,1,1
1,1,1,1,1,1,1,1,1,1,1,1,1,1,1,1,1,1,1,1,1
endlayer

layer
0,0,0,0,0,0,0,0,0,0,0,0,0,0,0,0,0,0,0,0,0
0,0,0,0,0,0,0,0,0,0,0,0,0,0,0,0,0,0,0,0,0
0,0,0,0,0,0,6,6,6,6,6,6,6,6,6,0,0,0,0,0,0
0,0,0,0,0,6,7,13,0,0,8,0,0,13,7,6,0,0,0,0,0
0,0,0,0,6,8,10,9,0,0,8,0,0,9,10,8,6,0,0,0,0
0,0,0,6,10,8,8,8,0,8,8,0,8,8,8,8,10,6,0,0,0
0,0,6,7,9,8,0,0,0,0,0,0,0,0,0,8,9,7,6,0,0
0,0,6,0,0,0,0,0,0,0,0,0,0,0,0,0,0,0,6,0,0
0,0,6,8,8,8,0,0,0,0,0,0,0,0,0,8,8,8,6,0,0
0,0,6,0,0,8,0,0,0,0,0,0,0,0,0,8,0,0,6,0,0
0,0,6,9,0,0,0,0,0,0,0,0,0,0,0,0,0,9,6,0,0
0,0,6,10,7,8,0,0,0,0,0,0,0,0,0,8,7,10,6,0,0
0,0,6,8,8,8,0,0,0,11,0,11,0,0,0,8,8,8,6,0,0
0,0,6,0,0,0,0,0,0,11,10,11,0,0,0,0,0,0,6,0,0
0,0,6,7,9,8,0,0,0,11,11,11,0,0,0,8,9,7,6,0,0
0,0,0,6,10,8,0,0,0,0,0,0,0,0,0,8,10,6,0,0,0
0,0,0,0,6,8,0,0,0,0,0,0,0,0,0,8,6,0,0,0,0
0,0,0,0,0,6,0,0,0,0,0,0,0,0,0,6,0,0,0,0,0
0,0,0,0,0,0,6,6,6,12,0,12,6,6,6,0,0,0,0,0,0
0,0,0,0,0,0,0,0,0,0,0,0,0,0,0,0,0,0,0,0,0
0,0,0,0,0,0,0,0,0,0,0,0,0,0,0,0,0,0,0,0,0
endlayer

layer
0,0,0,0,0,0,0,0,0,0,0,0,0,0,0,0,0,0,0,0,0
0,0,0,0,0,0,0,0,0,0,0,0,0,0,0,0,0,0,0,0,0
0,0,0,0,0,0,6,12,14,12,14,12,14,12,6,0,0,0,0,0,0
0,0,0,0,0,12,7,0,0,0,8,0,0,0,7,12,0,0,0,0,0
0,0,0,0,6,8,0,0,0,0,8,0,0,0,0,8,6,0,0,0,0
0,0,0,12,0,8,8,8,0,8,8,0,8,8,8,8,0,12,0,0,0
0,0,6,7,0,8,0,0,0,0,0,0,0,0,0,8,0,7,6,0,0
0,0,12,0,0,0,0,0,0,0,0,0,0,0,0,0,0,0,12,0,0
0,0,14,8,8,8,0,0,0,0,0,0,0,0,0,8,8,8,14,0,0
0,0,12,0,0,8,0,0,0,0,0,0,0,0,0,8,0,0,12,0,0
0,0,14,0,0,0,0,0,0,0,0,0,0,0,0,0,0,0,14,0,0
0,0,12,0,7,8,0,0,0,0,0,0,0,0,0,8,7,0,12,0,0
0,0,14,8,8,8,0,0,0,0,0,0,0,0,0,8,8,8,14,0,0
0,0,12,0,0,0,0,0,0,0,0,0,0,0,0,0,0,0,12,0,0
0,0,6,7,0,8,0,0,0,0,0,0,0,0,0,8,0,7,6,0,0
0,0,0,12,0,8,0,0,0,0,0,0,0,0,0,8,0,12,0,0,0
0,0,0,0,6,8,0,0,0,0,0,0,0,0,0,8,6,0,0,0,0
0,0,0,0,0,12,0,0,0,0,0,0,0,0,0,12,0,0,0,0,0
0,0,0,0,0,0,6,12,14,12,0,12,14,12,6,0,0,0,0,0,0
0,0,0,0,0,0,0,0,0,0,0,0,0,0,0,0,0,0,0,0,0
0,0,0,0,0,0,0,0,0,0,0,0,0,0,0,0,0,0,0,0,0
endlayer

layer
0,0,0,0,0,0,0,0,0,0,0,0,0,0,0,0,0,0,0,0,0
0,0,0,0,0,0,0,0,0,0,0,0,0,0,0,0,0,0,0,0,0
0,0,0,0,0,0,6,12,14,12,14,12,14,12,6,0,0,0,0,0,0
0,0,0,0,0,12,0,0,0,0,0,0,0,0,0,12,0,0,0,0,0
0,0,0,0,6,0,0,0,0,0,0,0,0,0,0,0,6,0,0,0,0
0,0,0,12,0,0,0,0,0,0,0,0,0,0,0,0,0,12,0,0,0
0,0,6,0,0,0,0,0,0,0,0,0,0,0,0,0,0,0,6,0,0
0,0,12,0,0,0,0,0,0,0,0,0,0,0,0,0,0,0,12,0,0
0,0,14,0,0,0,0,0,0,0,0,0,0,0,0,0,0,0,14,0,0
0,0,12,0,0,0,0,0,0,0,0,0,0,0,0,0,0,0,12,0,0
0,0,14,0,0,0,0,0,0,0,0,0,0,0,0,0,0,0,14,0,0
0,0,12,0,0,0,0,0,0,0,0,0,0,0,0,0,0,0,12,0,0
0,0,14,0,0,0,0,0,0,0,0,0,0,0,0,0,0,0,14,0,0
0,0,12,0,0,0,0,0,0,0,0,0,0,0,0,0,0,0,12,0,0
0,0,6,0,0,0,0,0,0,0,0,0,0,0,0,0,0,0,6,0,0
0,0,0,12,0,0,0,0,0,0,0,0,0,0,0,0,0,12,0,0,0
0,0,0,0,6,0,0,0,0,0,0,0,0,0,0,0,6,0,0,0,0
0,0,0,0,0,12,0,0,0,0,0,0,0,0,0,12,0,0,0,0,0
0,0,0,0,0,0,6,12,14,12,12,12,14,12,6,0,0,0,0,0,0
0,0,0,0,0,0,0,0,0,0,0,0,0,0,0,0,0,0,0,0,0
0,0,0,0,0,0,0,0,0,0,0,0,0,0,0,0,0,0,0,0,0
endlayer

layer
0,0,0,0,0,0,0,0,0,0,0,0,0,0,0,0,0,0,0,0,0
0,0,0,0,0,0,0,0,0,0,0,0,0,0,0,0,0,0,0,0,0
0,0,0,0,0,0,6,12,14,12,14,12,14,12,6,0,0,0,0,0,0
0,0,0,0,0,12,0,0,0,0,0,0,0,0,0,12,0,0,0,0,0
0,0,0,0,6,0,0,0,0,0,0,0,0,0,0,0,6,0,0,0,0
0,0,0,12,0,0,0,0,0,0,0,0,0,0,0,0,0,12,0,0,0
0,0,6,0,0,0,0,0,0,0,0,0,0,0,0,0,0,0,6,0,0
0,0,12,0,0,0,0,0,0,0,0,0,0,0,0,0,0,0,12,0,0
0,0,14,0,0,0,0,0,0,0,0,0,0,0,0,0,0,0,14,0,0
0,0,12,0,0,0,0,0,0,0,0,0,0,0,0,0,0,0,12,0,0
0,0,14,0,0,0,0,0,0,0,0,0,0,0,0,0,0,0,14,0,0
0,0,12,0,0,0,0,0,0,0,0,0,0,0,0,0,0,0,12,0,0
0,0,14,0,0,0,0,0,0,0,0,0,0,0,0,0,0,0,14,0,0
0,0,12,0,0,0,0,0,0,0,0,0,0,0,0,0,0,0,12,0,0
0,0,6,0,0,0,0,0,0,0,0,0,0,0,0,0,0,0,6,0,0
0,0,0,12,0,0,0,0,0,0,0,0,0,0,0,0,0,12,0,0,0
0,0,0,0,6,0,0,0,0,0,0,0,0,0,0,0,6,0,0,0,0
0,0,0,0,0,12,0,0,0,0,0,0,0,0,0,12,0,0,0,0,0
0,0,0,0,0,0,6,12,12,12,12,12,12,12,6,0,0,0,0,0,0
0,0,0,0,0,0,0,0,0,0,0,0,0,0,0,0,0,0,0,0,0
0,0,0,0,0,0,0,0,0,0,0,0,0,0,0,0,0,0,0,0,0
endlayer

layer
0,0,0,0,0,0,0,0,0,0,0,0,0,0,0,0,0,0,0,0,0
0,0,0,0,0,0,0,0,0,0,0,0,0,0,0,0,0,0,0,0,0
0,0,0,0,0,0,6,12,14,12,14,12,14,12,6,0,0,0,0,0,0
0,0,0,0,0,12,0,0,0,0,0,0,0,0,0,12,0,0,0,0,0
0,0,0,0,6,0,0,0,0,0,0,0,0,0,0,0,6,0,0,0,0
0,0,0,12,0,0,0,0,0,0,0,0,0,0,0,0,0,12,0,0,0
0,0,6,0,0,0,0,0,0,0,0,0,0,0,0,0,0,0,6,0,0
0,0,12,0,0,0,0,0,0,0,0,0,0,0,0,0,0,0,12,0,0
0,0,14,0,0,0,0,0,0,0,0,0,0,0,0,0,0,0,14,0,0
0,0,12,0,0,0,0,0,0,0,0,0,0,0,0,0,0,0,12,0,0
0,0,14,0,0,0,0,0,0,0,0,0,0,0,0,0,0,0,14,0,0
0,0,12,0,0,0,0,0,0,0,0,0,0,0,0,0,0,0,12,0,0
0,0,14,0,0,0,0,0,0,0,0,0,0,0,0,0,0,0,14,0,0
0,0,12,0,0,0,0,0,0,0,0,0,0,0,0,0,0,0,12,0,0
0,0,6,0,0,0,0,0,0,0,0,0,0,0,0,0,0,0,6,0,0
0,0,0,12,0,0,0,0,0,0,0,0,0,0,0,0,0,12,0,0,0
0,0,0,0,6,0,0,0,0,0,0,0,0,0,0,0,6,0,0,0,0
0,0,0,0,0,12,0,0,0,0,0,0,0,0,0,12,0,0,0,0,0
0,0,0,0,0,0,6,12,14,12,14,12,14,12,6,0,0,0,0,0,0
0,0,0,0,0,0,0,0,0,0,0,0,0,0,0,0,0,0,0,0,0
0,0,0,0,0,0,0,0,0,0,0,0,0,0,0,0,0,0,0,0,0
endlayer

layer
0,0,0,0,0,0,0,0,0,0,0,0,0,0,0,0,0,0,0,0,0
0,0,0,0,0,0,0,0,0,0,0,0,0,0,0,0,0,0,0,0,0
0,0,0,0,0,0,6,12,14,12,14,12,14,12,6,0,0,0,0,0,0
0,0,0,0,0,12,0,0,0,0,0,0,0,0,0,12,0,0,0,0,0
0,0,0,0,6,0,0,0,0,0,0,0,0,0,0,0,6,0,0,0,0
0,0,0,12,0,0,0,0,0,0,0,0,0,0,0,0,0,12,0,0,0
0,0,6,0,0,0,0,0,0,0,0,0,0,0,0,0,0,0,6,0,0
0,0,12,0,0,0,0,0,0,0,0,0,0,0,0,0,0,0,12,0,0
0,0,14,0,0,0,0,0,0,0,0,0,0,0,0,0,0,0,14,0,0
0,0,12,0,0,0,0,0,0,0,0,0,0,0,0,0,0,0,12,0,0
0,0,14,0,0,0,0,0,0,0,0,0,0,0,0,0,0,0,14,0,0
0,0,12,0,0,0,0,0,0,0,0,0,0,0,0,0,0,0,12,0,0
0,0,14,0,0,0,0,0,0,0,0,0,0,0,0,0,0,0,14,0,0
0,0,12,0,0,0,0,0,0,0,0,0,0,0,0,0,0,0,12,0,0
0,0,6,0,0,0,0,0,0,0,0,0,0,0,0,0,0,0,6,0,0
0,0,0,12,0,0,0,0,0,0,0,0,0,0,0,0,0,12,0,0,0
0,0,0,0,6,0,0,0,0,0,0,0,0,0,0,0,6,0,0,0,0
0,0,0,0,0,12,0,0,0,0,0,0,0,0,0,12,0,0,0,0,0
0,0,0,0,0,0,6,12,14,12,14,12,14,12,6,0,0,0,0,0,0
0,0,0,0,0,0,0,0,0,0,0,0,0,0,0,0,0,0,0,0,0
0,0,0,0,0,0,0,0,0,0,0,0,0,0,0,0,0,0,0,0,0
endlayer

layer
0,0,0,0,0,0,0,0,0,0,0,0,0,0,0,0,0,0,0,0,0
0,0,0,0,0,0,0,0,0,0,0,0,0,0,0,0,0,0,0,0,0
0,0,0,0,0,0,6,6,6,6,6,6,6,6,6,0,0,0,0,0,0
0,0,0,0,0,6,0,0,0,0,0,0,0,0,0,6,0,0,0,0,0
0,0,0,0,6,0,0,0,0,0,0,0,0,0,0,0,6,0,0,0,0
0,0,0,6,0,0,0,0,0,0,0,0,0,0,0,0,0,6,0,0,0
0,0,6,0,0,0,0,0,0,0,0,0,0,0,0,0,0,0,6,0,0
0,0,6,0,0,0,0,0,0,0,0,0,0,0,0,0,0,0,6,0,0
0,0,6,0,0,0,0,0,0,0,0,0,0,0,0,0,0,0,6,0,0
0,0,6,0,0,0,0,0,0,0,0,0,0,0,0,0,0,0,6,0,0
0,0,6,0,0,0,0,0,0,0,0,0,0,0,0,0,0,0,6,0,0
0,0,6,0,0,0,0,0,0,0,0,0,0,0,0,0,0,0,6,0,0
0,0,6,0,0,0,0,0,0,0,0,0,0,0,0,0,0,0,6,0,0
0,0,6,0,0,0,0,0,0,0,0,0,0,0,0,0,0,0,6,0,0
0,0,6,0,0,0,0,0,0,0,0,0,0,0,0,0,0,0,6,0,0
0,0,0,6,0,0,0,0,0,0,0,0,0,0,0,0,0,6,0,0,0
0,0,0,0,6,0,0,0,0,0,0,0,0,0,0,0,6,0,0,0,0
0,0,0,0,0,6,0,0,0,0,0,0,0,0,0,6,0,0,0,0,0
0,0,0,0,0,0,6,6,6,6,6,6,6,6,6,0,0,0,0,0,0
0,0,0,0,0,0,0,0,0,0,0,0,0,0,0,0,0,0,0,0,0
0,0,0,0,0,0,0,0,0,0,0,0,0,0,0,0,0,0,0,0,0
endlayer

layer
0,0,0,0,0,0,0,0,0,0,0,0,0,0,0,0,0,0,0,0,0
0,0,0,0,0,0,0,0,0,0,0,0,0,0,0,0,0,0,0,0,0
0,0,0,0,0,0,0,0,0,0,0,0,0,0,0,0,0,0,0,0,0
0,0,0,0,0,0,6,6,6,6,6,6,6,6,6,0,0,0,0,0,0
0,0,0,0,0,6,3,3,3,3,3,3,3,3,3,6,0,0,0,0,0
0,0,0,0,6,3,3,3,3,3,3,3,3,3,3,3,6,0,0,0,0
0,0,0,6,3,3,3,3,3,3,3,3,3,3,3,3,3,6,0,0,0
0,0,0,6,3,3,3,3,3,3,3,3,3,3,3,3,3,6,0,0,0
0,0,0,6,3,3,3,3,3,3,3,3,3,3,3,3,3,6,0,0,0
0,0,0,6,3,3,3,3,3,3,3,3,3,3,3,3,3,6,0,0,0
0,0,0,6,3,3,3,3,3,3,3,3,3,3,3,3,3,6,0,0,0
0,0,0,6,3,3,3,3,3,3,3,3,3,3,3,3,3,6,0,0,0
0,0,0,6,3,3,3,3,3,3,3,3,3,3,3,3,3,6,0,0,0
0,0,0,6,3,3,3,5,3,3,3,3,3,3,3,3,3,6,0,0,0
0,0,0,6,3,3,3,3,3,3,3,3,3,3,3,3,3,6,0,0,0
0,0,0,0,6,3,3,3,3,3,3,3,3,3,3,3,6,0,0,0,0
0,0,0,0,0,6,3,3,3,3,3,3,3,3,3,6,0,0,0,0,0
0,0,0,0,0,0,6,6,6,6,6,6,6,6,6,0,0,0,0,0,0
0,0,0,0,0,0,0,0,0,0,0,0,0,0,0,0,0,0,0,0,0
0,0,0,0,0,0,0,0,0,0,0,0,0,0,0,0,0,0,0,0,0
0,0,0,0,0,0,0,0,0,0,0,0,0,0,0,0,0,0,0,0,0
endlayer

layer
0,0,0,0,0,0,0,0,0,0,0,0,0,0,0,0,0,0,0,0,0
0,0,0,0,0,0,0,0,0,0,0,0,0,0,0,0,0,0,0,0,0
0,0,0,0,0,0,0,0,0,0,0,0,0,0,0,0,0,0,0,0,0
0,0,0,0,0,0,6,12,14,12,14,12,14,12,6,0,0,0,0,0,0
0,0,0,0,0,12,7,13,8,9,10,8,0,13,7,12,0,0,0,0,0
0,0,0,0,12,10,9,0,8,0,7,8,0,0,9,10,12,0,0,0,0
0,0,0,6,8,8,8,0,8,0,8,8,0,8,8,8,8,6,0,0,0
0,0,0,12,10,7,8,0,0,0,0,0,0,0,0,0,0,12,0,0,0
0,0,0,14,9,0,0,0,8,8,8,8,0,8,8,0,0,14,0,0,0
0,0,0,12,8,8,8,0,8,10,9,8,0,7,8,0,0,12,0,0,0
0,0,0,14,10,7,8,0,8,7,0,8,9,10,8,0,0,14,0,0,0
0,0,0,12,9,0,0,0,8,8,0,8,8,8,8,0,0,12,0,0,0
0,0,0,14,8,8,8,0,0,0,0,0,0,0,0,0,0,14,0,0,0
0,0,0,12,0,0,0,0,0,0,0,0,0,0,0,0,0,12,0,0,0
0,0,0,6,8,8,8,0,8,8,8,0,8,0,8,8,8,6,0,0,0
0,0,0,0,12,10,9,0,8,10,9,0,8,0,9,10,12,0,0,0,0
0,0,0,0,0,12,7,0,8,7,0,0,8,0,7,12,0,0,0,0,0
0,0,0,0,0,0,6,12,14,12,14,12,14,12,6,0,0,0,0,0,0
0,0,0,0,0,0,0,0,0,0,0,0,0,0,0,0,0,0,0,0,0
0,0,0,0,0,0,0,0,0,0,0,0,0,0,0,0,0,0,0,0,0
0,0,0,0,0,0,0,0,0,0,0,0,0,0,0,0,0,0,0,0,0
endlayer

layer
0,0,0,0,0,0,0,0,0,0,0,0,0,0,0,0,0,0,0,0,0
0,0,0,0,0,0,0,0,0,0,0,0,0,0,0,0,0,0,0,0,0
0,0,0,0,0,0,0,0,0,0,0,0,0,0,0,0,0,0,0,0,0
0,0,0,0,0,0,6,12,14,12,14,12,14,12,6,0,0,0,0,0,0
0,0,0,0,0,12,7,0,8,0,0,8,0,0,7,12,0,0,0,0,0
0,0,0,0,12,0,0,0,8,0,7,8,0,0,0,0,12,0,0,0,0
0,0,0,6,8,8,8,0,8,0,8,8,0,8,8,8,8,6,0,0,0
0,0,0,12,0,7,8,0,0,0,0,0,0,0,0,0,0,12,0,0,0
0,0,0,14,0,0,0,0,8,8,8,8,0,8,8,0,0,14,0,0,0
0,0,0,12,8,8,8,0,8,0,0,8,0,7,8,0,0,12,0,0,0
0,0,0,14,0,7,8,0,8,7,0,8,0,0,8,0,0,14,0,0,0
0,0,0,12,0,0,0,0,8,8,0,8,8,8,8,0,0,12,0,0,0
0,0,0,14,8,8,8,0,0,0,0,0,0,0,0,0,0,14,0,0,0
0,0,0,12,0,0,0,0,0,0,0,0,0,0,0,0,0,12,0,0,0
0,0,0,6,8,8,8,0,8,8,8,0,8,0,8,8,8,6,0,0,0
0,0,0,0,12,0,0,0,8,0,0,0,8,0,0,0,12,0,0,0,0
0,0,0,0,0,12,7,0,8,7,0,0,8,0,7,12,0,0,0,0,0
0,0,0,0,0,0,6,12,14,12,14,12,14,12,6,0,0,0,0,0,0
0,0,0,0,0,0,0,0,0,0,0,0,0,0,0,0,0,0,0,0,0
0,0,0,0,0,0,0,0,0,0,0,0,0,0,0,0,0,0,0,0,0
0,0,0,0,0,0,0,0,0,0,0,0,0,0,0,0,0,0,0,0,0
endlayer

layer
0,0,0,0,0,0,0,0,0,0,0,0,0,0,0,0,0,0,0,0,0
0,0,0,0,0,0,0,0,0,0,0,0,0,0,0,0,0,0,0,0,0
0,0,0,0,0,0,0,0,0,0,0,0,0,0,0,0,0,0,0,0,0
0,0,0,0,0,0,6,12,14,12,14,12,14,12,6,0,0,0,0,0,0
0,0,0,0,0,12,0,0,0,0,0,0,0,0,0,12,0,0,0,0,0
0,0,0,0,12,0,0,0,0,0,0,0,0,0,0,0,12,0,0,0,0
0,0,0,6,0,0,0,0,0,0,0,0,0,0,0,0,0,6,0,0,0
0,0,0,12,0,0,0,0,0,0,0,0,0,0,0,0,0,12,0,0,0
0,0,0,14,0,0,0,0,0,0,0,0,0,0,0,0,0,14,0,0,0
0,0,0,12,0,0,0,0,0,0,0,0,0,0,0,0,0,12,0,0,0
0,0,0,14,0,0,0,0,0,0,0,0,0,0,0,0,0,14,0,0,0
0,0,0,12,0,0,0,0,0,0,0,0,0,0,0,0,0,12,0,0,0
0,0,0,14,0,0,0,0,0,0,0,0,0,0,0,0,0,14,0,0,0
0,0,0,12,0,0,0,0,0,0,0,0,0,0,0,0,0,12,0,0,0
0,0,0,6,0,0,0,0,0,0,0,0,0,0,0,0,0,6,0,0,0
0,0,0,0,12,0,0,0,0,0,0,0,0,0,0,0,12,0,0,0,0
0,0,0,0,0,12,0,0,0,0,0,0,0,0,0,12,0,0,0,0,0
0,0,0,0,0,0,6,12,14,12,14,12,14,12,6,0,0,0,0,0,0
0,0,0,0,0,0,0,0,0,0,0,0,0,0,0,0,0,0,0,0,0
0,0,0,0,0,0,0,0,0,0,0,0,0,0,0,0,0,0,0,0,0
0,0,0,0,0,0,0,0,0,0,0,0,0,0,0,0,0,0,0,0,0
endlayer

layer
0,0,0,0,0,0,0,0,0,0,0,0,0,0,0,0,0,0,0,0,0
0,0,0,0,0,0,0,0,0,0,0,0,0,0,0,0,0,0,0,0,0
0,0,0,0,0,0,0,0,0,0,0,0,0,0,0,0,0,0,0,0,0
0,0,0,0,0,0,6,12,14,12,14,12,14,12,6,0,0,0,0,0,0
0,0,0,0,0,12,0,0,0,0,0,0,0,0,0,12,0,0,0,0,0
0,0,0,0,12,0,0,0,0,0,0,0,0,0,0,0,12,0,0,0,0
0,0,0,6,0,0,0,0,0,0,0,0,0,0,0,0,0,6,0,0,0
0,0,0,12,0,0,0,0,0,0,0,0,0,0,0,0,0,12,0,0,0
0,0,0,14,0,0,0,0,0,0,0,0,0,0,0,0,0,14,0,0,0
0,0,0,12,0,0,0,0,0,0,0,0,0,0,0,0,0,12,0,0,0
0,0,0,14,0,0,0,0,0,0,0,0,0,0,0,0,0,14,0,0,0
0,0,0,12,0,0,0,0,0,0,0,0,0,0,0,0,0,12,0,0,0
0,0,0,14,0,0,0,0,0,0,0,0,0,0,0,0,0,14,0,0,0
0,0,0,12,0,0,0,0,0,0,0,0,0,0,0,0,0,12,0,0,0
0,0,0,6,0,0,0,0,0,0,0,0,0,0,0,0,0,6,0,0,0
0,0,0,0,12,0,0,0,0,0,0,0,0,0,0,0,12,0,0,0,0
0,0,0,0,0,12,0,0,0,0,0,0,0,0,0,12,0,0,0,0,0
0,0,0,0,0,0,6,12,14,12,14,12,14,12,6,0,0,0,0,0,0
0,0,0,0,0,0,0,0,0,0,0,0,0,0,0,0,0,0,0,0,0
0,0,0,0,0,0,0,0,0,0,0,0,0,0,0,0,0,0,0,0,0
0,0,0,0,0,0,0,0,0,0,0,0,0,0,0,0,0,0,0,0,0
endlayer

layer
0,0,0,0,0,0,0,0,0,0,0,0,0,0,0,0,0,0,0,0,0
0,0,0,0,0,0,0,0,0,0,0,0,0,0,0,0,0,0,0,0,0
0,0,0,0,0,0,0,0,0,0,0,0,0,0,0,0,0,0,0,0,0
0,0,0,0,0,0,6,12,14,12,14,12,14,12,6,0,0,0,0,0,0
0,0,0,0,0,12,0,0,0,0,0,0,0,0,0,12,0,0,0,0,0
0,0,0,0,12,0,0,0,0,0,0,0,0,0,0,0,12,0,0,0,0
0,0,0,6,0,0,0,0,0,0,0,0,0,0,0,0,0,6,0,0,0
0,0,0,12,0,0,0,0,0,0,0,0,0,0,0,0,0,12,0,0,0
0,0,0,14,0,0,0,0,0,0,0,0,0,0,0,0,0,14,0,0,0
0,0,0,12,0,0,0,0,0,0,0,0,0,0,0,0,0,12,0,0,0
0,0,0,14,0,0,0,0,0,0,0,0,0,0,0,0,0,14,0,0,0
0,0,0,12,0,0,0,0,0,0,0,0,0,0,0,0,0,12,0,0,0
0,0,0,14,0,0,0,0,0,0,0,0,0,0,0,0,0,14,0,0,0
0,0,0,12,0,0,0,0,0,0,0,0,0,0,0,0,0,12,0,0,0
0,0,0,6,0,0,0,0,0,0,0,0,0,0,0,0,0,6,0,0,0
0,0,0,0,12,0,0,0,0,0,0,0,0,0,0,0,12,0,0,0,0
0,0,0,0,0,12,0,0,0,0,0,0,0,0,0,12,0,0,0,0,0
0,0,0,0,0,0,6,12,14,12,14,12,14,12,6,0,0,0,0,0,0
0,0,0,0,0,0,0,0,0,0,0,0,0,0,0,0,0,0,0,0,0
0,0,0,0,0,0,0,0,0,0,0,0,0,0,0,0,0,0,0,0,0
0,0,0,0,0,0,0,0,0,0,0,0,0,0,0,0,0,0,0,0,0
endlayer

layer
0,0,0,0,0,0,0,0,0,0,0,0,0,0,0,0,0,0,0,0,0
0,0,0,0,0,0,0,0,0,0,0,0,0,0,0,0,0,0,0,0,0
0,0,0,0,0,0,0,0,0,0,0,0,0,0,0,0,0,0,0,0,0
0,0,0,0,0,0,6,12,14,12,14,12,14,12,6,0,0,0,0,0,0
0,0,0,0,0,12,0,0,0,0,0,0,0,0,0,12,0,0,0,0,0
0,0,0,0,12,0,0,0,0,0,0,0,0,0,0,0,12,0,0,0,0
0,0,0,6,0,0,0,0,0,0,0,0,0,0,0,0,0,6,0,0,0
0,0,0,12,0,0,0,0,0,0,0,0,0,0,0,0,0,12,0,0,0
0,0,0,14,0,0,0,0,0,0,0,0,0,0,0,0,0,14,0,0,0
0,0,0,12,0,0,0,0,0,0,0,0,0,0,0,0,0,12,0,0,0
0,0,0,14,0,0,0,0,0,0,0,0,0,0,0,0,0,14,0,0,0
0,0,0,12,0,0,0,0,0,0,0,0,0,0,0,0,0,12,0,0,0
0,0,0,14,0,0,0,0,0,0,0,0,0,0,0,0,0,14,0,0,0
0,0,0,12,0,0,0,0,0,0,0,0,0,0,0,0,0,12,0,0,0
0,0,0,6,0,0,0,0,0,0,0,0,0,0,0,0,0,6,0,0,0
0,0,0,0,12,0,0,0,0,0,0,0,0,0,0,0,12,0,0,0,0
0,0,0,0,0,12,0,0,0,0,0,0,0,0,0,12,0,0,0,0,0
0,0,0,0,0,0,6,12,14,12,14,12,14,12,6,0,0,0,0,0,0
0,0,0,0,0,0,0,0,0,0,0,0,0,0,0,0,0,0,0,0,0
0,0,0,0,0,0,0,0,0,0,0,0,0,0,0,0,0,0,0,0,0
0,0,0,0,0,0,0,0,0,0,0,0,0,0,0,0,0,0,0,0,0
endlayer

layer
0,0,0,0,0,0,0,0,0,0,0,0,0,0,0,0,0,0,0,0,0
0,0,0,0,0,0,0,0,0,0,0,0,0,0,0,0,0,0,0,0,0
0,0,0,0,0,0,0,0,0,0,0,0,0,0,0,0,0,0,0,0,0
0,0,0,0,0,0,6,6,6,6,6,6,6,6,6,0,0,0,0,0,0
0,0,0,0,0,6,0,0,0,0,0,0,0,0,0,6,0,0,0,0,0
0,0,0,0,6,0,0,0,0,0,0,0,0,0,0,0,6,0,0,0,0
0,0,0,6,0,0,0,0,0,0,0,0,0,0,0,0,0,6,0,0,0
0,0,0,6,0,0,0,0,0,0,0,0,0,0,0,0,0,6,0,0,0
0,0,0,6,0,0,0,0,0,0,0,0,0,0,0,0,0,6,0,0,0
0,0,0,6,0,0,0,0,0,0,0,0,0,0,0,0,0,6,0,0,0
0,0,0,6,0,0,0,0,0,0,0,0,0,0,0,0,0,6,0,0,0
0,0,0,6,0,0,0,0,0,0,0,0,0,0,0,0,0,6,0,0,0
0,0,0,6,0,0,0,0,0,0,0,0,0,0,0,0,0,6,0,0,0
0,0,0,6,0,0,0,0,0,0,0,0,0,0,0,0,0,6,0,0,0
0,0,0,6,0,0,0,0,0,0,0,0,0,0,0,0,0,6,0,0,0
0,0,0,0,6,0,0,0,0,0,0,0,0,0,0,0,6,0,0,0,0
0,0,0,0,0,6,0,0,0,0,0,0,0,0,0,6,0,0,0,0,0
0,0,0,0,0,0,6,6,6,6,6,6,6,6,6,0,0,0,0,0,0
0,0,0,0,0,0,0,0,0,0,0,0,0,0,0,0,0,0,0,0,0
0,0,0,0,0,0,0,0,0,0,0,0,0,0,0,0,0,0,0,0,0
0,0,0,0,0,0,0,0,0,0,0,0,0,0,0,0,0,0,0,0,0
endlayer

layer
0,0,0,0,0,0,0,0,0,0,0,0,0,0,0,0,0,0,0,0,0
0,0,0,0,0,0,0,0,0,0,0,0,0,0,0,0,0,0,0,0,0
0,0,0,0,0,0,0,0,0,0,0,0,0,0,0,0,0,0,0,0,0
0,0,0,0,0,0,0,0,0,0,0,0,0,0,0,0,0,0,0,0,0
0,0,0,0,0,0,6,6,6,6,6,6,6,6,6,0,0,0,0,0,0
0,0,0,0,0,6,0,0,0,0,0,0,0,0,0,6,0,0,0,0,0
0,0,0,0,6,0,0,0,0,0,0,0,0,0,0,0,6,0,0,0,0
0,0,0,0,6,0,0,0,0,0,0,0,0,0,0,0,6,0,0,0,0
0,0,0,0,6,0,0,0,0,0,0,0,0,0,0,0,6,0,0,0,0
0,0,0,0,6,0,0,0,0,0,0,0,0,0,0,0,6,0,0,0,0
0,0,0,0,6,0,0,0,0,0,0,0,0,0,0,0,6,0,0,0,0
0,0,0,0,6,0,0,0,0,0,0,0,0,0,0,0,6,0,0,0,0
0,0,0,0,6,0,0,0,0,0,0,0,0,0,0,0,6,0,0,0,0
0,0,0,0,6,0,0,0,0,0,0,0,0,0,0,0,6,0,0,0,0
0,0,0,0,6,0,0,0,0,0,0,0,0,0,0,0,6,0,0,0,0
0,0,0,0,0,6,0,0,0,0,0,0,0,0,0,6,0,0,0,0,0
0,0,0,0,0,0,6,6,6,6,6,6,6,6,6,0,0,0,0,0,0
0,0,0,0,0,0,0,0,0,0,0,0,0,0,0,0,0,0,0,0,0
0,0,0,0,0,0,0,0,0,0,0,0,0,0,0,0,0,0,0,0,0
0,0,0,0,0,0,0,0,0,0,0,0,0,0,0,0,0,0,0,0,0
0,0,0,0,0,0,0,0,0,0,0,0,0,0,0,0,0,0,0,0,0
endlayer

layer
0,0,0,0,0,0,0,0,0,0,0,0,0,0,0,0,0,0,0,0,0
0,0,0,0,0,0,0,0,0,0,0,0,0,0,0,0,0,0,0,0,0
0,0,0,0,0,0,0,0,0,0,0,0,0,0,0,0,0,0,0,0,0
0,0,0,0,0,0,0,0,0,0,0,0,0,0,0,0,0,0,0,0,0
0,0,0,0,0,0,0,0,0,0,0,0,0,0,0,0,0,0,0,0,0
0,0,0,0,0,0,6,6,6,6,6,6,6,6,6,0,0,0,0,0,0
0,0,0,0,0,6,3,3,3,3,3,3,3,3,6,6,0,0,0,0,0
0,0,0,0,0,6,3,3,3,3,3,3,3,3,3,6,0,0,0,0,0
0,0,0,0,0,6,3,3,3,3,3,3,3,3,3,6,0,0,0,0,0
0,0,0,0,0,6,3,3,3,3,3,3,3,3,3,6,0,0,0,0,0
0,0,0,0,0,6,3,3,3,3,3,3,3,3,3,6,0,0,0,0,0
0,0,0,0,0,6,3,3,3,3,3,3,3,3,3,6,0,0,0,0,0
0,0,0,0,0,6,3,3,3,3,3,3,3,3,3,6,0,0,0,0,0
0,0,0,0,0,6,3,5,3,3,3,3,3,3,3,6,0,0,0,0,0
0,0,0,0,0,6,6,3,3,3,3,3,3,3,3,6,0,0,0,0,0
0,0,0,0,0,0,6,6,6,6,6,6,6,6,6,0,0,0,0,0,0
0,0,0,0,0,0,0,0,0,0,0,0,0,0,0,0,0,0,0,0,0
0,0,0,0,0,0,0,0,0,0,0,0,0,0,0,0,0,0,0,0,0
0,0,0,0,0,0,0,0,0,0,0,0,0,0,0,0,0,0,0,0,0
0,0,0,0,0,0,0,0,0,0,0,0,0,0,0,0,0,0,0,0,0
0,0,0,0,0,0,0,0,0,0,0,0,0,0,0,0,0,0,0,0,0
endlayer

layer
0,0,0,0,0,0,0,0,0,0,0,0,0,0,0,0,0,0,0,0,0
0,0,0,0,0,0,0,0,0,0,0,0,0,0,0,0,0,0,0,0,0
0,0,0,0,0,0,0,0,0,0,0,0,0,0,0,0,0,0,0,0,0
0,0,0,0,0,0,0,0,0,0,0,0,0,0,0,0,0,0,0,0,0
0,0,0,0,0,0,0,0,0,0,0,0,0,0,0,0,0,0,0,0,0
0,0,0,0,0,0,0,0,0,0,0,0,0,0,0,0,0,0,0,0,0
0,0,0,0,0,0,6,12,14,12,14,12,14,12,6,0,0,0,0,0,0
0,0,0,0,0,0,12,0,0,0,0,0,7,13,12,0,0,0,0,0,0
0,0,0,0,0,0,14,0,0,0,0,0,0,7,14,0,0,0,0,0,0
0,0,0,0,0,0,12,0,0,0,0,15,0,0,12,0,0,0,0,0,0
0,0,0,0,0,0,14,0,0,0,0,15,9,0,14,0,0,0,0,0,0
0,0,0,0,0,0,12,0,0,0,0,15,0,0,12,0,0,0,0,0,0
0,0,0,0,0,0,14,0,0,0,0,0,0,7,14,0,0,0,0,0,0
0,0,0,0,0,0,12,0,0,0,0,0,7,13,12,0,0,0,0,0,0
0,0,0,0,0,0,6,12,14,12,14,12,14,12,6,0,0,0,0,0,0
0,0,0,0,0,0,0,0,0,0,0,0,0,0,0,0,0,0,0,0,0
0,0,0,0,0,0,0,0,0,0,0,0,0,0,0,0,0,0,0,0,0
0,0,0,0,0,0,0,0,0,0,0,0,0,0,0,0,0,0,0,0,0
0,0,0,0,0,0,0,0,0,0,0,0,0,0,0,0,0,0,0,0,0
0,0,0,0,0,0,0,0,0,0,0,0,0,0,0,0,0,0,0,0,0
0,0,0,0,0,0,0,0,0,0,0,0,0,0,0,0,0,0,0,0,0
endlayer

layer
0,0,0,0,0,0,0,0,0,0,0,0,0,0,0,0,0,0,0,0,0
0,0,0,0,0,0,0,0,0,0,0,0,0,0,0,0,0,0,0,0,0
0,0,0,0,0,0,0,0,0,0,0,0,0,0,0,0,0,0,0,0,0
0,0,0,0,0,0,0,0,0,0,0,0,0,0,0,0,0,0,0,0,0
0,0,0,0,0,0,0,0,0,0,0,0,0,0,0,0,0,0,0,0,0
0,0,0,0,0,0,0,0,0,0,0,0,0,0,0,0,0,0,0,0,0
0,0,0,0,0,0,6,12,14,12,14,12,14,12,6,0,0,0,0,0,0
0,0,0,0,0,0,12,0,0,0,0,0,0,7,12,0,0,0,0,0,0
0,0,0,0,0,0,14,0,0,0,0,0,0,0,14,0,0,0,0,0,0
0,0,0,0,0,0,12,0,0,0,0,0,0,0,12,0,0,0,0,0,0
0,0,0,0,0,0,14,0,0,0,0,0,0,0,14,0,0,0,0,0,0
0,0,0,0,0,0,12,0,0,0,0,16,0,0,12,0,0,0,0,0,0
0,0,0,0,0,0,14,0,0,0,0,0,0,0,14,0,0,0,0,0,0
0,0,0,0,0,0,12,0,0,0,0,0,0,7,12,0,0,0,0,0,0
0,0,0,0,0,0,6,12,14,12,14,12,14,12,6,0,0,0,0,0,0
0,0,0,0,0,0,0,0,0,0,0,0,0,0,0,0,0,0,0,0,0
0,0,0,0,0,0,0,0,0,0,0,0,0,0,0,0,0,0,0,0,0
0,0,0,0,0,0,0,0,0,0,0,0,0,0,0,0,0,0,0,0,0
0,0,0,0,0,0,0,0,0,0,0,0,0,0,0,0,0,0,0,0,0
0,0,0,0,0,0,0,0,0,0,0,0,0,0,0,0,0,0,0,0,0
0,0,0,0,0,0,0,0,0,0,0,0,0,0,0,0,0,0,0,0,0
endlayer

layer
0,0,0,0,0,0,0,0,0,0,0,0,0,0,0,0,0,0,0,0,0
0,0,0,0,0,0,0,0,0,0,0,0,0,0,0,0,0,0,0,0,0
0,0,0,0,0,0,0,0,0,0,0,0,0,0,0,0,0,0,0,0,0
0,0,0,0,0,0,0,0,0,0,0,0,0,0,0,0,0,0,0,0,0
0,0,0,0,0,0,0,0,0,0,0,0,0,0,0,0,0,0,0,0,0
0,0,0,0,0,0,0,0,0,0,0,0,0,0,0,0,0,0,0,0,0
0,0,0,0,0,0,6,12,14,12,14,12,14,12,6,0,0,0,0,0,0
0,0,0,0,0,0,12,0,0,0,0,0,0,0,12,0,0,0,0,0,0
0,0,0,0,0,0,14,0,0,0,0,0,0,0,14,0,0,0,0,0,0
0,0,0,0,0,0,12,0,0,0,0,0,0,0,12,0,0,0,0,0,0
0,0,0,0,0,0,14,0,0,0,0,0,0,0,14,0,0,0,0,0,0
0,0,0,0,0,0,12,0,0,0,0,0,0,0,12,0,0,0,0,0,0
0,0,0,0,0,0,14,0,0,0,0,0,0,0,14,0,0,0,0,0,0
0,0,0,0,0,0,12,0,0,0,0,0,0,0,12,0,0,0,0,0,0
0,0,0,0,0,0,6,12,14,12,14,12,14,12,6,0,0,0,0,0,0
0,0,0,0,0,0,0,0,0,0,0,0,0,0,0,0,0,0,0,0,0
0,0,0,0,0,0,0,0,0,0,0,0,0,0,0,0,0,0,0,0,0
0,0,0,0,0,0,0,0,0,0,0,0,0,0,0,0,0,0,0,0,0
0,0,0,0,0,0,0,0,0,0,0,0,0,0,0,0,0,0,0,0,0
0,0,0,0,0,0,0,0,0,0,0,0,0,0,0,0,0,0,0,0,0
0,0,0,0,0,0,0,0,0,0,0,0,0,0,0,0,0,0,0,0,0
endlayer

layer
0,0,0,0,0,0,0,0,0,0,0,0,0,0,0,0,0,0,0,0,0
0,0,0,0,0,0,0,0,0,0,0,0,0,0,0,0,0,0,0,0,0
0,0,0,0,0,0,0,0,0,0,0,0,0,0,0,0,0,0,0,0,0
0,0,0,0,0,0,0,0,0,0,0,0,0,0,0,0,0,0,0,0,0
0,0,0,0,0,0,0,0,0,0,0,0,0,0,0,0,0,0,0,0,0
0,0,0,0,0,0,0,0,0,0,0,0,0,0,0,0,0,0,0,0,0
0,0,0,0,0,0,6,12,14,12,14,12,0,12,6,0,0,0,0,0,0
0,0,0,0,0,0,12,0,0,0,0,0,0,0,12,0,0,0,0,0,0
0,0,0,0,0,0,14,0,0,0,0,0,0,0,14,0,0,0,0,0,0
0,0,0,0,0,0,12,0,0,0,0,0,0,0,12,0,0,0,0,0,0
0,0,0,0,0,0,14,0,0,0,0,0,0,0,14,0,0,0,0,0,0
0,0,0,0,0,0,12,0,0,0,0,0,0,0,12,0,0,0,0,0,0
0,0,0,0,0,0,14,0,0,0,0,0,0,0,14,0,0,0,0,0,0
0,0,0,0,0,0,12,0,0,0,0,0,0,0,12,0,0,0,0,0,0
0,0,0,0,0,0,6,12,0,12,14,12,14,12,6,0,0,0,0,0,0
0,0,0,0,0,0,0,0,0,0,0,0,0,0,0,0,0,0,0,0,0
0,0,0,0,0,0,0,0,0,0,0,0,0,0,0,0,0,0,0,0,0
0,0,0,0,0,0,0,0,0,0,0,0,0,0,0,0,0,0,0,0,0
0,0,0,0,0,0,0,0,0,0,0,0,0,0,0,0,0,0,0,0,0
0,0,0,0,0,0,0,0,0,0,0,0,0,0,0,0,0,0,0,0,0
0,0,0,0,0,0,0,0,0,0,0,0,0,0,0,0,0,0,0,0,0
endlayer

layer
0,0,0,0,0,0,0,0,0,0,0,0,0,0,0,0,0,0,0,0,0
0,0,0,0,0,0,0,0,0,0,0,0,0,0,0,0,0,0,0,0,0
0,0,0,0,0,0,0,0,0,0,0,0,0,0,0,0,0,0,0,0,0
0,0,0,0,0,0,0,0,0,0,0,0,0,0,0,0,0,0,0,0,0
0,0,0,0,0,0,0,0,0,0,0,0,0,0,0,0,0,0,0,0,0
0,0,0,0,0,0,0,0,0,0,0,0,0,0,0,0,0,0,0,0,0
0,0,0,0,0,0,6,12,14,12,14,12,14,12,6,0,0,0,0,0,0
0,0,0,0,0,0,12,0,0,0,0,0,0,0,12,0,0,0,0,0,0
0,0,0,0,0,0,14,0,0,0,0,0,0,0,14,0,0,0,0,0,0
0,0,0,0,0,0,12,0,0,0,0,0,0,0,12,0,0,0,0,0,0
0,0,0,0,0,0,14,0,0,0,0,0,0,0,14,0,0,0,0,0,0
0,0,0,0,0,0,12,0,0,0,0,0,0,0,12,0,0,0,0,0,0
0,0,0,0,0,0,14,0,0,0,0,0,0,0,14,0,0,0,0,0,0
0,0,0,0,0,0,12,0,0,0,0,0,0,0,12,0,0,0,0,0,0
0,0,0,0,0,0,6,12,14,12,14,12,14,12,6,0,0,0,0,0,0
0,0,0,0,0,0,0,0,0,0,0,0,0,0,0,0,0,0,0,0,0
0,0,0,0,0,0,0,0,0,0,0,0,0,0,0,0,0,0,0,0,0
0,0,0,0,0,0,0,0,0,0,0,0,0,0,0,0,0,0,0,0,0
0,0,0,0,0,0,0,0,0,0,0,0,0,0,0,0,0,0,0,0,0
0,0,0,0,0,0,0,0,0,0,0,0,0,0,0,0,0,0,0,0,0
0,0,0,0,0,0,0,0,0,0,0,0,0,0,0,0,0,0,0,0,0
endlayer

layer
0,0,0,0,0,0,0,0,0,0,0,0,0,0,0,0,0,0,0,0,0
0,0,0,0,0,0,0,0,0,0,0,0,0,0,0,0,0,0,0,0,0
0,0,0,0,0,0,0,0,0,0,0,0,0,0,0,0,0,0,0,0,0
0,0,0,0,0,0,0,0,0,0,0,0,0,0,0,0,0,0,0,0,0
0,0,0,0,0,0,0,0,0,0,0,0,0,0,0,0,0,0,0,0,0
0,0,0,0,0,0,0,0,0,0,0,0,0,0,0,0,0,0,0,0,0
0,0,0,0,0,0,6,12,14,12,14,12,14,12,6,0,0,0,0,0,0
0,0,0,0,0,0,12,0,0,0,0,0,0,0,12,0,0,0,0,0,0
0,0,0,0,0,0,14,0,0,0,0,0,0,0,14,0,0,0,0,0,0
0,0,0,0,0,0,12,0,0,0,0,0,0,0,12,0,0,0,0,0,0
0,0,0,0,0,0,14,0,0,0,0,0,0,0,14,0,0,0,0,0,0
0,0,0,0,0,0,12,0,0,0,0,0,0,0,12,0,0,0,0,0,0
0,0,0,0,0,0,14,0,0,0,0,0,0,0,14,0,0,0,0,0,0
0,0,0,0,0,0,12,0,0,0,0,0,0,0,12,0,0,0,0,0,0
0,0,0,0,0,0,6,12,14,12,14,12,14,12,6,0,0,0,0,0,0
0,0,0,0,0,0,0,0,0,0,0,0,0,0,0,0,0,0,0,0,0
0,0,0,0,0,0,0,0,0,0,0,0,0,0,0,0,0,0,0,0,0
0,0,0,0,0,0,0,0,0,0,0,0,0,0,0,0,0,0,0,0,0
0,0,0,0,0,0,0,0,0,0,0,0,0,0,0,0,0,0,0,0,0
0,0,0,0,0,0,0,0,0,0,0,0,0,0,0,0,0,0,0,0,0
0,0,0,0,0,0,0,0,0,0,0,0,0,0,0,0,0,0,0,0,0
endlayer

layer
0,0,0,0,0,0,0,0,0,0,0,0,0,0,0,0,0,0,0,0,0
0,0,0,0,0,0,0,0,0,0,0,0,0,0,0,0,0,0,0,0,0
0,0,0,0,0,0,0,0,0,0,0,0,0,0,0,0,0,0,0,0,0
0,0,0,0,0,0,0,0,0,0,0,0,0,0,0,0,0,0,0,0,0
0,0,0,0,0,0,0,0,0,0,0,0,0,0,0,0,0,0,0,0,0
0,0,0,0,0,0,0,0,0,0,0,0,0,0,0,0,0,0,0,0,0
0,0,0,0,0,0,6,12,14,12,14,12,0,12,6,0,0,0,0,0,0
0,0,0,0,0,0,12,0,0,0,0,0,0,0,12,0,0,0,0,0,0
0,0,0,0,0,0,14,0,0,0,0,0,0,0,14,0,0,0,0,0,0
0,0,0,0,0,0,12,0,0,0,0,0,0,0,12,0,0,0,0,0,0
0,0,0,0,0,0,14,0,0,0,0,0,0,0,14,0,0,0,0,0,0
0,0,0,0,0,0,12,0,0,0,0,0,0,0,12,0,0,0,0,0,0
0,0,0,0,0,0,14,0,0,0,0,0,0,0,14,0,0,0,0,0,0
0,0,0,0,0,0,12,0,0,0,0,0,0,0,12,0,0,0,0,0,0
0,0,0,0,0,0,6,12,0,12,14,12,14,12,6,0,0,0,0,0,0
0,0,0,0,0,0,0,0,0,0,0,0,0,0,0,0,0,0,0,0,0
0,0,0,0,0,0,0,0,0,0,0,0,0,0,0,0,0,0,0,0,0
0,0,0,0,0,0,0,0,0,0,0,0,0,0,0,0,0,0,0,0,0
0,0,0,0,0,0,0,0,0,0,0,0,0,0,0,0,0,0,0,0,0
0,0,0,0,0,0,0,0,0,0,0,0,0,0,0,0,0,0,0,0,0
0,0,0,0,0,0,0,0,0,0,0,0,0,0,0,0,0,0,0,0,0
endlayer

layer
0,0,0,0,0,0,0,0,0,0,0,0,0,0,0,0,0,0,0,0,0
0,0,0,0,0,0,0,0,0,0,0,0,0,0,0,0,0,0,0,0,0
0,0,0,0,0,0,0,0,0,0,0,0,0,0,0,0,0,0,0,0,0
0,0,0,0,0,0,0,0,0,0,0,0,0,0,0,0,0,0,0,0,0
0,0,0,0,0,0,0,0,0,0,0,0,0,0,0,0,0,0,0,0,0
0,0,0,0,0,0,0,0,0,0,0,0,0,0,0,0,0,0,0,0,0
0,0,0,0,0,0,6,12,14,12,14,12,14,12,6,0,0,0,0,0,0
0,0,0,0,0,0,12,0,0,0,0,0,0,0,12,0,0,0,0,0,0
0,0,0,0,0,0,14,0,0,0,0,0,0,0,14,0,0,0,0,0,0
0,0,0,0,0,0,12,0,0,0,0,0,0,0,12,0,0,0,0,0,0
0,0,0,0,0,0,14,0,0,0,0,0,0,0,14,0,0,0,0,0,0
0,0,0,0,0,0,12,0,0,0,0,0,0,0,12,0,0,0,0,0,0
0,0,0,0,0,0,14,0,0,0,0,0,0,0,14,0,0,0,0,0,0
0,0,0,0,0,0,12,0,0,0,0,0,0,0,12,0,0,0,0,0,0
0,0,0,0,0,0,6,12,14,12,14,12,14,12,6,0,0,0,0,0,0
0,0,0,0,0,0,0,0,0,0,0,0,0,0,0,0,0,0,0,0,0
0,0,0,0,0,0,0,0,0,0,0,0,0,0,0,0,0,0,0,0,0
0,0,0,0,0,0,0,0,0,0,0,0,0,0,0,0,0,0,0,0,0
0,0,0,0,0,0,0,0,0,0,0,0,0,0,0,0,0,0,0,0,0
0,0,0,0,0,0,0,0,0,0,0,0,0,0,0,0,0,0,0,0,0
0,0,0,0,0,0,0,0,0,0,0,0,0,0,0,0,0,0,0,0,0
endlayer

layer
0,0,0,0,0,0,0,0,0,0,0,0,0,0,0,0,0,0,0,0,0
0,0,0,0,0,0,0,0,0,0,0,0,0,0,0,0,0,0,0,0,0
0,0,0,0,0,0,0,0,0,0,0,0,0,0,0,0,0,0,0,0,0
0,0,0,0,0,0,0,0,0,0,0,0,0,0,0,0,0,0,0,0,0
0,0,0,0,0,0,0,0,0,0,0,0,0,0,0,0,0,0,0,0,0
0,0,0,0,0,0,0,0,0,0,0,0,0,0,0,0,0,0,0,0,0
0,0,0,0,0,0,6,12,14,12,14,12,14,12,6,0,0,0,0,0,0
0,0,0,0,0,0,12,0,0,0,0,0,0,0,12,0,0,0,0,0,0
0,0,0,0,0,0,14,0,0,0,0,0,0,0,14,0,0,0,0,0,0
0,0,0,0,0,0,12,0,0,0,0,0,0,0,12,0,0,0,0,0,0
0,0,0,0,0,0,14,0,0,0,0,0,0,0,14,0,0,0,0,0,0
0,0,0,0,0,0,12,0,0,0,0,0,0,0,12,0,0,0,0,0,0
0,0,0,0,0,0,14,0,0,0,0,0,0,0,14,0,0,0,0,0,0
0,0,0,0,0,0,12,0,0,0,0,0,0,0,12,0,0,0,0,0,0
0,0,0,0,0,0,6,12,14,12,14,12,14,12,6,0,0,0,0,0,0
0,0,0,0,0,0,0,0,0,0,0,0,0,0,0,0,0,0,0,0,0
0,0,0,0,0,0,0,0,0,0,0,0,0,0,0,0,0,0,0,0,0
0,0,0,0,0,0,0,0,0,0,0,0,0,0,0,0,0,0,0,0,0
0,0,0,0,0,0,0,0,0,0,0,0,0,0,0,0,0,0,0,0,0
0,0,0,0,0,0,0,0,0,0,0,0,0,0,0,0,0,0,0,0,0
0,0,0,0,0,0,0,0,0,0,0,0,0,0,0,0,0,0,0,0,0
endlayer

layer
0,0,0,0,0,0,0,0,0,0,0,0,0,0,0,0,0,0,0,0,0
0,0,0,0,0,0,0,0,0,0,0,0,0,0,0,0,0,0,0,0,0
0,0,0,0,0,0,0,0,0,0,0,0,0,0,0,0,0,0,0,0,0
0,0,0,0,0,0,0,0,0,0,0,0,0,0,0,0,0,0,0,0,0
0,0,0,0,0,0,0,0,0,0,0,0,0,0,0,0,0,0,0,0,0
0,0,0,0,0,0,0,0,0,0,0,0,0,0,0,0,0,0,0,0,0
0,0,0,0,0,0,6,6,6,6,6,6,6,6,6,0,0,0,0,0,0
0,0,0,0,0,0,6,17,17,17,17,17,17,17,6,0,0,0,0,0,0
0,0,0,0,0,0,6,17,0,0,0,0,0,17,6,0,0,0,0,0,0
0,0,0,0,0,0,6,17,0,0,0,0,0,17,6,0,0,0,0,0,0
0,0,0,0,0,0,6,17,0,0,0,0,0,17,6,0,0,0,0,0,0
0,0,0,0,0,0,6,17,0,0,0,0,0,17,6,0,0,0,0,0,0
0,0,0,0,0,0,6,17,0,0,0,0,0,17,6,0,0,0,0,0,0
0,0,0,0,0,0,6,17,17,17,17,17,17,17,6,0,0,0,0,0,0
0,0,0,0,0,0,6,6,6,6,6,6,6,6,6,0,0,0,0,0,0
0,0,0,0,0,0,0,0,0,0,0,0,0,0,0,0,0,0,0,0,0
0,0,0,0,0,0,0,0,0,0,0,0,0,0,0,0,0,0,0,0,0
0,0,0,0,0,0,0,0,0,0,0,0,0,0,0,0,0,0,0,0,0
0,0,0,0,0,0,0,0,0,0,0,0,0,0,0,0,0,0,0,0,0
0,0,0,0,0,0,0,0,0,0,0,0,0,0,0,0,0,0,0,0,0
0,0,0,0,0,0,0,0,0,0,0,0,0,0,0,0,0,0,0,0,0
endlayer

layer
0,0,0,0,0,0,0,0,0,0,0,0,0,0,0,0,0,0,0,0,0
0,0,0,0,0,0,0,0,0,0,0,0,0,0,0,0,0,0,0,0,0
0,0,0,0,0,0,0,0,0,0,0,0,0,0,0,0,0,0,0,0,0
0,0,0,0,0,0,0,0,0,0,0,0,0,0,0,0,0,0,0,0,0
0,0,0,0,0,0,0,0,0,0,0,0,0,0,0,0,0,0,0,0,0
0,0,0,0,0,0,0,0,0,0,0,0,0,0,0,0,0,0,0,0,0
0,0,0,0,0,0,0,0,0,0,0,0,0,0,0,0,0,0,0,0,0
0,0,0,0,0,0,0,0,0,0,0,0,0,0,0,0,0,0,0,0,0
0,0,0,0,0,0,0,0,17,17,17,17,17,0,0,0,0,0,0,0,0
0,0,0,0,0,0,0,0,17,0,0,0,17,0,0,0,0,0,0,0,0
0,0,0,0,0,0,0,0,17,0,0,0,17,0,0,0,0,0,0,0,0
0,0,0,0,0,0,0,0,17,0,0,0,17,0,0,0,0,0,0,0,0
0,0,0,0,0,0,0,0,17,17,17,17,17,0,0,0,0,0,0,0,0
0,0,0,0,0,0,0,0,0,0,0,0,0,0,0,0,0,0,0,0,0
0,0,0,0,0,0,0,0,0,0,0,0,0,0,0,0,0,0,0,0,0
0,0,0,0,0,0,0,0,0,0,0,0,0,0,0,0,0,0,0,0,0
0,0,0,0,0,0,0,0,0,0,0,0,0,0,0,0,0,0,0,0,0
0,0,0,0,0,0,0,0,0,0,0,0,0,0,0,0,0,0,0,0,0
0,0,0,0,0,0,0,0,0,0,0,0,0,0,0,0,0,0,0,0,0
0,0,0,0,0,0,0,0,0,0,0,0,0,0,0,0,0,0,0,0,0
0,0,0,0,0,0,0,0,0,0,0,0,0,0,0,0,0,0,0,0,0
endlayer

layer
0,0,0,0,0,0,0,0,0,0,0,0,0,0,0,0,0,0,0,0,0
0,0,0,0,0,0,0,0,0,0,0,0,0,0,0,0,0,0,0,0,0
0,0,0,0,0,0,0,0,0,0,0,0,0,0,0,0,0,0,0,0,0
0,0,0,0,0,0,0,0,0,0,0,0,0,0,0,0,0,0,0,0,0
0,0,0,0,0,0,0,0,0,0,0,0,0,0,0,0,0,0,0,0,0
0,0,0,0,0,0,0,0,0,0,0,0,0,0,0,0,0,0,0,0,0
0,0,0,0,0,0,0,0,0,0,0,0,0,0,0,0,0,0,0,0,0
0,0,0,0,0,0,0,0,0,0,0,0,0,0,0,0,0,0,0,0,0
0,0,0,0,0,0,0,0,0,0,0,0,0,0,0,0,0,0,0,0,0
0,0,0,0,0,0,0,0,0,17,17,17,0,0,0,0,0,0,0,0,0
0,0,0,0,0,0,0,0,0,17,0,17,0,0,0,0,0,0,0,0,0
0,0,0,0,0,0,0,0,0,17,17,17,0,0,0,0,0,0,0,0,0
0,0,0,0,0,0,0,0,0,0,0,0,0,0,0,0,0,0,0,0,0
0,0,0,0,0,0,0,0,0,0,0,0,0,0,0,0,0,0,0,0,0
0,0,0,0,0,0,0,0,0,0,0,0,0,0,0,0,0,0,0,0,0
0,0,0,0,0,0,0,0,0,0,0,0,0,0,0,0,0,0,0,0,0
0,0,0,0,0,0,0,0,0,0,0,0,0,0,0,0,0,0,0,0,0
0,0,0,0,0,0,0,0,0,0,0,0,0,0,0,0,0,0,0,0,0
0,0,0,0,0,0,0,0,0,0,0,0,0,0,0,0,0,0,0,0,0
0,0,0,0,0,0,0,0,0,0,0,0,0,0,0,0,0,0,0,0,0
0,0,0,0,0,0,0,0,0,0,0,0,0,0,0,0,0,0,0,0,0
endlayer

layer
0,0,0,0,0,0,0,0,0,0,0,0,0,0,0,0,0,0,0,0,0
0,0,0,0,0,0,0,0,0,0,0,0,0,0,0,0,0,0,0,0,0
0,0,0,0,0,0,0,0,0,0,0,0,0,0,0,0,0,0,0,0,0
0,0,0,0,0,0,0,0,0,0,0,0,0,0,0,0,0,0,0,0,0
0,0,0,0,0,0,0,0,0,0,0,0,0,0,0,0,0,0,0,0,0
0,0,0,0,0,0,0,0,0,0,0,0,0,0,0,0,0,0,0,0,0
0,0,0,0,0,0,0,0,0,0,0,0,0,0,0,0,0,0,0,0,0
0,0,0,0,0,0,0,0,0,0,0,0,0,0,0,0,0,0,0,0,0
0,0,0,0,0,0,0,0,0,0,0,0,0,0,0,0,0,0,0,0,0
0,0,0,0,0,0,0,0,0,0,0,0,0,0,0,0,0,0,0,0,0
0,0,0,0,0,0,0,0,0,0,17,0,0,0,0,0,0,0,0,0,0
0,0,0,0,0,0,0,0,0,0,0,0,0,0,0,0,0,0,0,0,0
0,0,0,0,0,0,0,0,0,0,0,0,0,0,0,0,0,0,0,0,0
0,0,0,0,0,0,0,0,0,0,0,0,0,0,0,0,0,0,0,0,0
0,0,0,0,0,0,0,0,0,0,0,0,0,0,0,0,0,0,0,0,0
0,0,0,0,0,0,0,0,0,0,0,0,0,0,0,0,0,0,0,0,0
0,0,0,0,0,0,0,0,0,0,0,0,0,0,0,0,0,0,0,0,0
0,0,0,0,0,0,0,0,0,0,0,0,0,0,0,0,0,0,0,0,0
0,0,0,0,0,0,0,0,0,0,0,0,0,0,0,0,0,0,0,0,0
0,0,0,0,0,0,0,0,0,0,0,0,0,0,0,0,0,0,0,0,0
0,0,0,0,0,0,0,0,0,0,0,0,0,0,0,0,0,0,0,0,0
endlayer

layer
0,0,0,0,0,0,0,0,0,0,0,0,0,0,0,0,0,0,0,0,0
0,0,0,0,0,0,0,0,0,0,0,0,0,0,0,0,0,0,0,0,0
0,0,0,0,0,0,0,0,0,0,0,0,0,0,0,0,0,0,0,0,0
0,0,0,0,0,0,0,0,0,0,0,0,0,0,0,0,0,0,0,0,0
0,0,0,0,0,0,0,0,0,0,0,0,0,0,0,0,0,0,0,0,0
0,0,0,0,0,0,0,0,0,0,0,0,0,0,0,0,0,0,0,0,0
0,0,0,0,0,0,0,0,0,0,0,0,0,0,0,0,0,0,0,0,0
0,0,0,0,0,0,0,0,0,0,0,0,0,0,0,0,0,0,0,0,0
0,0,0,0,0,0,0,0,0,0,0,0,0,0,0,0,0,0,0,0,0
0,0,0,0,0,0,0,0,0,0,0,0,0,0,0,0,0,0,0,0,0
0,0,0,0,0,0,0,0,0,0,17,0,0,0,0,0,0,0,0,0,0
0,0,0,0,0,0,0,0,0,0,0,0,0,0,0,0,0,0,0,0,0
0,0,0,0,0,0,0,0,0,0,0,0,0,0,0,0,0,0,0,0,0
0,0,0,0,0,0,0,0,0,0,0,0,0,0,0,0,0,0,0,0,0
0,0,0,0,0,0,0,0,0,0,0,0,0,0,0,0,0,0,0,0,0
0,0,0,0,0,0,0,0,0,0,0,0,0,0,0,0,0,0,0,0,0
0,0,0,0,0,0,0,0,0,0,0,0,0,0,0,0,0,0,0,0,0
0,0,0,0,0,0,0,0,0,0,0,0,0,0,0,0,0,0,0,0,0
0,0,0,0,0,0,0,0,0,0,0,0,0,0,0,0,0,0,0,0,0
0,0,0,0,0,0,0,0,0,0,0,0,0,0,0,0,0,0,0,0,0
0,0,0,0,0,0,0,0,0,0,0,0,0,0,0,0,0,0,0,0,0
endlayer

layer
0,0,0,0,0,0,0,0,0,0,0,0,0,0,0,0,0,0,0,0,0
0,0,0,0,0,0,0,0,0,0,0,0,0,0,0,0,0,0,0,0,0
0,0,0,0,0,0,0,0,0,0,0,0,0,0,0,0,0,0,0,0,0
0,0,0,0,0,0,0,0,0,0,0,0,0,0,0,0,0,0,0,0,0
0,0,0,0,0,0,0,0,0,0,0,0,0,0,0,0,0,0,0,0,0
0,0,0,0,0,0,0,0,0,0,0,0,0,0,0,0,0,0,0,0,0
0,0,0,0,0,0,0,0,0,0,0,0,0,0,0,0,0,0,0,0,0
0,0,0,0,0,0,0,0,0,0,0,0,0,0,0,0,0,0,0,0,0
0,0,0,0,0,0,0,0,0,0,0,0,0,0,0,0,0,0,0,0,0
0,0,0,0,0,0,0,0,0,0,0,0,0,0,0,0,0,0,0,0,0
0,0,0,0,0,0,0,0,0,0,17,0,0,0,0,0,0,0,0,0,0
0,0,0,0,0,0,0,0,0,0,0,0,0,0,0,0,0,0,0,0,0
0,0,0,0,0,0,0,0,0,0,0,0,0,0,0,0,0,0,0,0,0
0,0,0,0,0,0,0,0,0,0,0,0,0,0,0,0,0,0,0,0,0
0,0,0,0,0,0,0,0,0,0,0,0,0,0,0,0,0,0,0,0,0
0,0,0,0,0,0,0,0,0,0,0,0,0,0,0,0,0,0,0,0,0
0,0,0,0,0,0,0,0,0,0,0,0,0,0,0,0,0,0,0,0,0
0,0,0,0,0,0,0,0,0,0,0,0,0,0,0,0,0,0,0,0,0
0,0,0,0,0,0,0,0,0,0,0,0,0,0,0,0,0,0,0,0,0
0,0,0,0,0,0,0,0,0,0,0,0,0,0,0,0,0,0,0,0,0
0,0,0,0,0,0,0,0,0,0,0,0,0,0,0,0,0,0,0,0,0
endlayer

