weight=3
embed_into_distance=1
dimensions=23,13,13
max_cut_in=2

rule1=0,100,250
rule2=0,75,2843-4
rule3=0,80,2838-6,2838-6,2838-6,2838-6,2838-6,2838-6,2838-1,2838
rule4=0,80,2838-7,2838-7,2838-7,2838-7,2838-5,2838,2838
rule5=0,45,4094-6
rule6=0,75,2838-15


layer
1,1,1,1,1,1,1,1,1,1,1,1,1
1,1,1,2,2,2,2,2,2,2,1,1,1
1,1,2,2,2,2,2,2,2,2,2,1,1
1,2,2,2,2,2,2,2,2,2,2,2,1
1,2,2,2,2,2,2,2,2,2,2,2,1
1,2,2,2,2,2,2,2,2,2,2,2,1
1,2,2,2,2,2,2,2,2,2,2,2,1
1,2,2,2,2,2,2,2,2,2,2,2,1
1,2,2,2,2,2,2,2,2,2,2,2,1
1,2,2,2,2,2,2,2,2,2,2,2,1
1,1,2,2,2,2,2,2,2,2,2,1,1
1,1,1,2,2,2,2,2,2,2,1,1,1
1,1,1,1,1,1,2,1,1,1,1,1,1
endlayer

layer
0,0,0,3,3,3,3,3,3,3,0,0,0
0,0,3,0,0,0,0,0,0,0,3,0,0
0,3,0,0,0,0,0,0,0,0,0,3,0
3,0,0,0,0,0,0,0,0,0,0,0,3
3,0,0,0,0,0,0,0,0,0,0,0,3
3,0,0,0,0,0,0,0,0,0,0,0,3
3,0,0,0,0,0,0,0,0,0,0,0,3
3,0,0,0,0,0,0,0,0,0,0,0,3
3,0,0,0,0,0,0,0,0,0,0,0,3
3,0,0,0,0,0,0,0,0,0,0,0,3
0,3,0,0,0,0,0,0,0,0,0,3,0
0,0,3,0,0,0,0,0,0,0,3,0,0
0,0,0,3,3,3,0,3,3,3,0,0,0
endlayer

layer
0,0,0,5,4,5,4,5,4,3,0,0,0
0,0,5,0,0,0,0,0,0,0,5,0,0
0,5,0,0,0,0,0,0,0,0,0,5,0
3,0,0,0,0,0,0,0,0,0,0,0,3
4,0,0,0,0,0,0,0,0,0,0,0,4
5,0,0,0,0,0,0,0,0,0,0,0,5
4,0,0,0,0,0,0,0,0,0,0,0,4
5,0,0,0,0,0,0,0,0,0,0,0,5
4,0,0,0,0,0,0,0,0,0,0,0,4
3,0,0,0,0,0,0,0,0,0,0,0,3
0,5,0,0,0,0,0,0,0,0,0,5,0
0,0,5,0,0,0,0,0,0,0,5,0,0
0,0,0,3,4,5,0,5,4,3,0,0,0
endlayer

layer
0,0,0,5,4,5,4,5,4,3,0,0,0
0,0,5,0,0,0,0,0,0,0,5,0,0
0,5,0,0,0,0,0,0,0,0,0,5,0
3,0,0,0,0,0,0,0,0,0,0,0,3
4,0,0,0,0,0,0,0,0,0,0,0,4
5,0,0,0,0,0,0,0,0,0,0,0,5
4,0,0,0,0,0,0,0,0,0,0,0,4
5,0,0,0,0,0,0,0,0,0,0,0,5
4,0,0,0,0,0,0,0,0,0,0,0,4
3,0,0,0,0,0,0,0,0,0,0,0,3
0,5,0,0,0,0,0,0,0,0,0,5,0
0,0,5,0,0,0,0,0,0,0,5,0,0
0,0,0,3,4,4,4,4,4,3,0,0,0
endlayer

layer
0,0,0,5,4,5,4,5,4,3,0,0,0
0,0,5,0,0,0,0,0,0,0,5,0,0
0,5,0,0,0,0,0,0,0,0,0,5,0
3,0,0,0,0,0,0,0,0,0,0,0,3
4,0,0,0,0,0,0,0,0,0,0,0,4
5,0,0,0,0,0,0,0,0,0,0,0,5
4,0,0,0,0,0,0,0,0,0,0,0,4
5,0,0,0,0,0,0,0,0,0,0,0,5
4,0,0,0,0,0,0,0,0,0,0,0,4
3,0,0,0,0,0,0,0,0,0,0,0,3
0,5,0,0,0,0,0,0,0,0,0,5,0
0,0,5,0,0,0,0,0,0,0,5,0,0
0,0,0,3,4,5,4,5,4,3,0,0,0
endlayer

layer
0,0,0,5,4,5,4,5,4,3,0,0,0
0,0,5,0,0,0,0,0,0,0,5,0,0
0,5,0,0,0,0,0,0,0,0,0,5,0
3,0,0,0,0,0,0,0,0,0,0,0,3
4,0,0,0,0,0,0,0,0,0,0,0,4
5,0,0,0,0,0,0,0,0,0,0,0,5
4,0,0,0,0,0,0,0,0,0,0,0,4
5,0,0,0,0,0,0,0,0,0,0,0,5
4,0,0,0,0,0,0,0,0,0,0,0,4
3,0,0,0,0,0,0,0,0,0,0,0,3
0,5,0,0,0,0,0,0,0,0,0,5,0
0,0,5,0,0,0,0,0,0,0,5,0,0
0,0,0,3,4,5,4,5,4,3,0,0,0
endlayer

layer
0,0,0,0,0,0,0,0,0,0,0,0,0
0,0,0,3,3,3,3,3,3,3,0,0,0
0,0,3,0,0,0,0,0,0,0,3,0,0
0,3,0,0,0,0,0,0,0,0,0,3,0
0,3,0,0,0,0,0,0,0,0,0,3,0
0,3,0,0,0,0,0,0,0,0,0,3,0
0,3,0,0,0,0,0,0,0,0,0,3,0
0,3,0,0,0,0,0,0,0,0,0,3,0
0,3,0,0,0,0,0,0,0,0,0,3,0
0,3,0,0,0,0,0,0,0,0,0,3,0
0,0,3,0,0,0,0,0,0,0,3,0,0
0,0,0,3,3,3,3,3,3,3,0,0,0
0,0,0,0,0,0,0,0,0,0,0,0,0
endlayer

layer
0,0,0,0,0,0,0,0,0,0,0,0,0
0,0,0,0,0,0,0,0,0,0,0,0,0
0,0,0,3,3,3,3,3,3,3,0,0,0
0,0,3,0,0,0,0,0,0,0,3,0,0
0,0,3,0,0,0,0,0,0,0,3,0,0
0,0,3,0,0,0,0,0,0,0,3,0,0
0,0,3,0,0,0,0,0,0,0,3,0,0
0,0,3,0,0,0,0,0,0,0,3,0,0
0,0,3,0,0,0,0,0,0,0,3,0,0
0,0,3,0,0,0,0,0,0,0,3,0,0
0,0,0,3,3,3,3,3,3,3,0,0,0
0,0,0,0,0,0,0,0,0,0,0,0,0
0,0,0,0,0,0,0,0,0,0,0,0,0
endlayer

layer
0,0,0,0,0,0,0,0,0,0,0,0,0
0,0,0,0,0,0,0,0,0,0,0,0,0
0,0,0,3,4,5,4,5,4,3,0,0,0
0,0,3,0,0,0,0,0,0,0,3,0,0
0,0,4,0,0,0,0,0,0,0,4,0,0
0,0,5,0,0,0,0,0,0,0,5,0,0
0,0,4,0,0,0,0,0,0,0,4,0,0
0,0,5,0,0,0,0,0,0,0,5,0,0
0,0,4,0,0,0,0,0,0,0,4,0,0
0,0,3,0,0,0,0,0,0,0,3,0,0
0,0,0,3,4,5,4,5,4,3,0,0,0
0,0,0,0,0,0,0,0,0,0,0,0,0
0,0,0,0,0,0,0,0,0,0,0,0,0
endlayer

layer
0,0,0,0,0,0,0,0,0,0,0,0,0
0,0,0,0,0,0,0,0,0,0,0,0,0
0,0,0,3,4,5,4,5,4,3,0,0,0
0,0,3,0,0,0,0,0,0,0,3,0,0
0,0,4,0,0,0,0,0,0,0,4,0,0
0,0,5,0,0,0,0,0,0,0,5,0,0
0,0,4,0,0,0,0,0,0,0,4,0,0
0,0,5,0,0,0,0,0,0,0,5,0,0
0,0,4,0,0,0,0,0,0,0,4,0,0
0,0,3,0,0,0,0,0,0,0,3,0,0
0,0,0,3,4,5,4,5,4,3,0,0,0
0,0,0,0,0,0,0,0,0,0,0,0,0
0,0,0,0,0,0,0,0,0,0,0,0,0
endlayer

layer
0,0,0,0,0,0,0,0,0,0,0,0,0
0,0,0,0,0,0,0,0,0,0,0,0,0
0,0,0,3,4,5,4,5,4,3,0,0,0
0,0,3,0,0,0,0,0,0,0,3,0,0
0,0,4,0,0,0,0,0,0,0,4,0,0
0,0,5,0,0,0,0,0,0,0,5,0,0
0,0,4,0,0,0,0,0,0,0,4,0,0
0,0,5,0,0,0,0,0,0,0,5,0,0
0,0,4,0,0,0,0,0,0,0,4,0,0
0,0,3,0,0,0,0,0,0,0,3,0,0
0,0,0,3,4,5,4,5,4,3,0,0,0
0,0,0,0,0,0,0,0,0,0,0,0,0
0,0,0,0,0,0,0,0,0,0,0,0,0
endlayer

layer
0,0,0,0,0,0,0,0,0,0,0,0,0
0,0,0,0,0,0,0,0,0,0,0,0,0
0,0,0,3,4,5,4,5,4,3,0,0,0
0,0,3,0,0,0,0,0,0,0,3,0,0
0,0,4,0,0,0,0,0,0,0,4,0,0
0,0,5,0,0,0,0,0,0,0,5,0,0
0,0,4,0,0,0,0,0,0,0,4,0,0
0,0,5,0,0,0,0,0,0,0,5,0,0
0,0,4,0,0,0,0,0,0,0,4,0,0
0,0,3,0,0,0,0,0,0,0,3,0,0
0,0,0,3,4,5,4,5,4,3,0,0,0
0,0,0,0,0,0,0,0,0,0,0,0,0
0,0,0,0,0,0,0,0,0,0,0,0,0
endlayer

layer
0,0,0,0,0,0,0,0,0,0,0,0,0
0,0,0,0,0,0,0,0,0,0,0,0,0
0,0,0,3,3,3,3,3,3,3,0,0,0
0,0,3,0,0,0,0,0,0,0,3,0,0
0,0,3,0,0,0,0,0,0,0,3,0,0
0,0,3,0,0,0,0,0,0,0,3,0,0
0,0,3,0,0,0,0,0,0,0,3,0,0
0,0,3,0,0,0,0,0,0,0,3,0,0
0,0,3,0,0,0,0,0,0,0,3,0,0
0,0,3,0,0,0,0,0,0,0,3,0,0
0,0,0,3,3,3,3,3,3,3,0,0,0
0,0,0,0,0,0,0,0,0,0,0,0,0
0,0,0,0,0,0,0,0,0,0,0,0,0
endlayer

layer
0,0,0,0,0,0,0,0,0,0,0,0,0
0,0,0,0,0,0,0,0,0,0,0,0,0
0,0,0,6,6,6,6,6,6,6,0,0,0
0,0,6,6,0,0,0,0,0,6,6,0,0
0,0,6,0,0,0,0,0,0,0,6,0,0
0,0,6,0,0,0,0,0,0,0,6,0,0
0,0,6,0,0,0,0,0,0,0,6,0,0
0,0,6,0,0,0,0,0,0,0,6,0,0
0,0,6,0,0,0,0,0,0,0,6,0,0
0,0,6,6,0,0,0,0,0,6,6,0,0
0,0,0,6,6,6,6,6,6,6,0,0,0
0,0,0,0,0,0,0,0,0,0,0,0,0
0,0,0,0,0,0,0,0,0,0,0,0,0
endlayer

layer
0,0,0,0,0,0,0,0,0,0,0,0,0
0,0,0,0,0,0,0,0,0,0,0,0,0
0,0,0,0,0,0,0,0,0,0,0,0,0
0,0,0,0,6,6,6,6,6,0,0,0,0
0,0,0,6,6,0,0,0,6,6,0,0,0
0,0,0,6,0,0,0,0,0,6,0,0,0
0,0,0,6,0,0,0,0,0,6,0,0,0
0,0,0,6,0,0,0,0,0,6,0,0,0
0,0,0,6,6,0,0,0,6,6,0,0,0
0,0,0,0,6,6,6,6,6,0,0,0,0
0,0,0,0,0,0,0,0,0,0,0,0,0
0,0,0,0,0,0,0,0,0,0,0,0,0
0,0,0,0,0,0,0,0,0,0,0,0,0
endlayer

layer
0,0,0,0,0,0,0,0,0,0,0,0,0
0,0,0,0,0,0,0,0,0,0,0,0,0
0,0,0,0,0,0,0,0,0,0,0,0,0
0,0,0,0,0,0,0,0,0,0,0,0,0
0,0,0,0,0,6,6,6,0,0,0,0,0
0,0,0,0,6,6,0,6,6,0,0,0,0
0,0,0,0,6,0,0,0,6,0,0,0,0
0,0,0,0,6,6,0,6,6,0,0,0,0
0,0,0,0,0,6,6,6,0,0,0,0,0
0,0,0,0,0,0,0,0,0,0,0,0,0
0,0,0,0,0,0,0,0,0,0,0,0,0
0,0,0,0,0,0,0,0,0,0,0,0,0
0,0,0,0,0,0,0,0,0,0,0,0,0
endlayer

layer
0,0,0,0,0,0,0,0,0,0,0,0,0
0,0,0,0,0,0,0,0,0,0,0,0,0
0,0,0,0,0,0,0,0,0,0,0,0,0
0,0,0,0,0,0,0,0,0,0,0,0,0
0,0,0,0,0,0,0,0,0,0,0,0,0
0,0,0,0,0,0,6,0,0,0,0,0,0
0,0,0,0,0,6,0,6,0,0,0,0,0
0,0,0,0,0,0,6,0,0,0,0,0,0
0,0,0,0,0,0,0,0,0,0,0,0,0
0,0,0,0,0,0,0,0,0,0,0,0,0
0,0,0,0,0,0,0,0,0,0,0,0,0
0,0,0,0,0,0,0,0,0,0,0,0,0
0,0,0,0,0,0,0,0,0,0,0,0,0
endlayer

layer
0,0,0,0,0,0,0,0,0,0,0,0,0
0,0,0,0,0,0,0,0,0,0,0,0,0
0,0,0,0,0,0,0,0,0,0,0,0,0
0,0,0,0,0,0,0,0,0,0,0,0,0
0,0,0,0,0,0,0,0,0,0,0,0,0
0,0,0,0,0,0,0,0,0,0,0,0,0
0,0,0,0,0,0,6,0,0,0,0,0,0
0,0,0,0,0,0,0,0,0,0,0,0,0
0,0,0,0,0,0,0,0,0,0,0,0,0
0,0,0,0,0,0,0,0,0,0,0,0,0
0,0,0,0,0,0,0,0,0,0,0,0,0
0,0,0,0,0,0,0,0,0,0,0,0,0
0,0,0,0,0,0,0,0,0,0,0,0,0
endlayer

layer
0,0,0,0,0,0,0,0,0,0,0,0,0
0,0,0,0,0,0,0,0,0,0,0,0,0
0,0,0,0,0,0,0,0,0,0,0,0,0
0,0,0,0,0,0,0,0,0,0,0,0,0
0,0,0,0,0,0,0,0,0,0,0,0,0
0,0,0,0,0,0,0,0,0,0,0,0,0
0,0,0,0,0,0,6,0,0,0,0,0,0
0,0,0,0,0,0,0,0,0,0,0,0,0
0,0,0,0,0,0,0,0,0,0,0,0,0
0,0,0,0,0,0,0,0,0,0,0,0,0
0,0,0,0,0,0,0,0,0,0,0,0,0
0,0,0,0,0,0,0,0,0,0,0,0,0
0,0,0,0,0,0,0,0,0,0,0,0,0
endlayer

layer
0,0,0,0,0,0,0,0,0,0,0,0,0
0,0,0,0,0,0,0,0,0,0,0,0,0
0,0,0,0,0,0,0,0,0,0,0,0,0
0,0,0,0,0,0,0,0,0,0,0,0,0
0,0,0,0,0,0,0,0,0,0,0,0,0
0,0,0,0,0,0,0,0,0,0,0,0,0
0,0,0,0,0,0,6,0,0,0,0,0,0
0,0,0,0,0,0,0,0,0,0,0,0,0
0,0,0,0,0,0,0,0,0,0,0,0,0
0,0,0,0,0,0,0,0,0,0,0,0,0
0,0,0,0,0,0,0,0,0,0,0,0,0
0,0,0,0,0,0,0,0,0,0,0,0,0
0,0,0,0,0,0,0,0,0,0,0,0,0
endlayer

layer
0,0,0,0,0,0,0,0,0,0,0,0,0
0,0,0,0,0,0,0,0,0,0,0,0,0
0,0,0,0,0,0,0,0,0,0,0,0,0
0,0,0,0,0,0,0,0,0,0,0,0,0
0,0,0,0,0,0,0,0,0,0,0,0,0
0,0,0,0,0,0,0,0,0,0,0,0,0
0,0,0,0,0,0,6,0,0,0,0,0,0
0,0,0,0,0,0,0,0,0,0,0,0,0
0,0,0,0,0,0,0,0,0,0,0,0,0
0,0,0,0,0,0,0,0,0,0,0,0,0
0,0,0,0,0,0,0,0,0,0,0,0,0
0,0,0,0,0,0,0,0,0,0,0,0,0
0,0,0,0,0,0,0,0,0,0,0,0,0
endlayer

layer
0,0,0,0,0,0,0,0,0,0,0,0,0
0,0,0,0,0,0,0,0,0,0,0,0,0
0,0,0,0,0,0,0,0,0,0,0,0,0
0,0,0,0,0,0,0,0,0,0,0,0,0
0,0,0,0,0,0,0,0,0,0,0,0,0
0,0,0,0,0,0,0,0,0,0,0,0,0
0,0,0,0,0,0,6,0,0,0,0,0,0
0,0,0,0,0,0,0,0,0,0,0,0,0
0,0,0,0,0,0,0,0,0,0,0,0,0
0,0,0,0,0,0,0,0,0,0,0,0,0
0,0,0,0,0,0,0,0,0,0,0,0,0
0,0,0,0,0,0,0,0,0,0,0,0,0
0,0,0,0,0,0,0,0,0,0,0,0,0
endlayer

layer
0,0,0,0,0,0,0,0,0,0,0,0,0
0,0,0,0,0,0,0,0,0,0,0,0,0
0,0,0,0,0,0,0,0,0,0,0,0,0
0,0,0,0,0,0,0,0,0,0,0,0,0
0,0,0,0,0,0,0,0,0,0,0,0,0
0,0,0,0,0,0,0,0,0,0,0,0,0
0,0,0,0,0,0,6,0,0,0,0,0,0
0,0,0,0,0,0,0,0,0,0,0,0,0
0,0,0,0,0,0,0,0,0,0,0,0,0
0,0,0,0,0,0,0,0,0,0,0,0,0
0,0,0,0,0,0,0,0,0,0,0,0,0
0,0,0,0,0,0,0,0,0,0,0,0,0
0,0,0,0,0,0,0,0,0,0,0,0,0
endlayer

