# Converted from schematic
# THIS TEMPLATE USES DEFAULTS!  Please edit for corrections.
# If you need help, consult template_rules.txt

weight=2
embed_into_distance=11
acceptable_target_blocks=1,2,3,12,13,250
dimensions=29,15,15
allowable_overhang=0
max_cut_in=2
cut_in_buffer=1
max_leveling=2
leveling_buffer=1
preserve_water=0
preserve_lava=0
preserve_plants=0


rule1=0,100,3134-10
rule2=0,100,300
rule3=0,100,2843-4
rule4=0,175,311
rule5=0,100,2542-0
rule6=0,100,2843-14,2843-14,2843-14,2843-14,2843
rule7=0,100,47,2837-7,2837-5,2837-8,47,2837-7,2837-5,2837-8,311,250,250
rule8=0,66,308,308,308,308,308,308,313,313,314,327
rule9=0,100,2843-12
rule10=0,100,2291-3
rule11=0,50,2248-3
rule12=0,100,2761-6,2761-6,2761-7,2761-7
rule13=0,95,2835-2,2835-2,2835-2,2835-2,2835-2,2835-2,2835-2,2835-1,2835-1,2835-0
rule14=0,25,3225-3
rule15=0,95,300
rule16=0,100,3134,3134,3134,3134,3134-8,3134-2


layer
1,1,1,1,1,1,1,1,1,1,1,1,1,1,1
1,1,1,1,1,1,1,1,1,1,1,1,1,1,1
1,1,2,2,2,2,2,2,2,2,2,2,2,1,1
1,1,2,3,3,3,3,5,3,3,3,3,2,1,1
1,1,2,3,3,3,3,3,3,3,3,3,2,1,1
1,1,2,3,3,3,3,3,3,3,3,3,2,1,1
1,1,2,3,3,3,3,3,3,3,3,3,2,1,1
1,1,2,3,3,3,3,3,3,3,3,3,2,1,1
1,1,2,3,3,3,3,3,3,3,3,3,2,1,1
1,1,2,3,3,3,3,3,4,3,3,3,2,1,1
1,1,2,3,3,3,3,3,3,3,3,3,2,1,1
1,1,2,3,3,3,3,3,3,3,3,3,2,1,1
1,1,2,2,2,2,2,3,2,2,2,2,2,1,1
1,1,1,1,1,1,1,1,1,1,1,1,1,1,1
1,1,1,1,1,1,1,1,1,1,1,1,1,1,1
endlayer

layer
2,2,2,2,2,2,2,2,2,2,2,2,2,2,2
2,2,2,2,2,2,2,2,2,2,2,2,2,2,2
2,2,6,6,6,6,6,6,6,6,6,6,6,2,2
2,2,6,7,10,9,0,0,0,9,10,7,6,2,2
2,2,6,8,11,9,0,0,0,9,11,8,6,2,2
2,2,6,0,0,0,0,0,0,0,0,0,6,2,2
2,2,6,9,9,9,0,0,0,9,9,9,6,2,2
2,2,6,0,0,0,0,0,0,0,0,0,6,2,2
2,2,6,0,0,0,12,0,12,0,0,0,6,2,2
2,2,6,0,0,0,12,10,12,0,0,0,6,2,2
2,2,6,0,0,0,12,12,12,0,0,0,6,2,2
2,2,6,0,0,0,2,2,2,2,0,0,6,2,2
2,2,6,6,6,6,6,2,6,6,6,6,6,2,2
2,2,2,2,2,2,2,2,2,2,2,2,2,2,2
2,2,2,2,2,2,2,2,2,2,2,2,2,2,2
endlayer

layer
2,2,2,2,2,2,2,2,2,2,2,2,2,2,2
2,2,2,2,2,2,2,2,2,2,2,2,2,2,2
2,2,6,13,14,14,13,14,13,14,14,13,6,2,2
2,2,13,7,0,9,0,0,0,9,0,7,13,2,2
2,2,14,0,0,9,0,0,0,9,0,0,14,2,2
2,2,14,0,0,0,0,0,0,0,0,0,14,2,2
2,2,13,9,9,9,0,0,0,9,9,9,13,2,2
2,2,14,0,0,0,0,0,0,0,0,0,14,2,2
2,2,13,0,0,0,0,0,0,0,0,0,13,2,2
2,2,14,0,0,0,0,0,0,0,0,0,14,2,2
2,2,14,0,0,0,0,2,0,0,0,0,14,2,2
2,2,13,0,0,0,0,2,0,0,0,0,13,2,2
2,2,6,13,14,14,13,2,13,14,14,13,6,2,2
2,2,2,2,2,2,2,2,2,2,2,2,2,2,2
2,2,2,2,2,2,2,2,2,2,2,2,2,2,2
endlayer

layer
2,2,2,2,2,2,2,2,2,2,2,2,2,2,2
2,2,2,2,2,2,2,2,2,2,2,2,2,2,2
2,2,6,13,14,14,13,14,13,14,14,13,6,2,2
2,2,13,0,0,0,0,0,0,0,0,0,13,2,2
2,2,14,0,0,0,0,0,0,0,0,0,14,2,2
2,2,14,0,0,0,0,0,0,0,0,0,14,2,2
2,2,13,0,0,0,0,0,0,0,0,0,13,2,2
2,2,14,0,0,0,0,0,0,0,0,0,14,2,2
2,2,13,0,0,0,0,0,0,0,0,0,13,2,2
2,2,14,0,0,0,0,0,0,0,0,0,14,2,2
2,2,14,0,0,0,0,0,0,0,0,0,14,2,2
2,2,13,0,0,0,0,0,0,0,0,0,13,2,2
2,2,6,13,14,14,13,13,13,14,14,13,6,2,2
2,2,2,2,2,2,2,2,2,2,2,2,2,2,2
2,2,2,2,2,2,2,2,2,2,2,2,2,2,2
endlayer

layer
2,2,2,2,2,2,2,2,2,2,2,2,2,2,2
2,2,2,2,2,2,2,2,2,2,2,2,2,2,2
2,2,6,13,14,14,13,14,13,14,14,13,6,2,2
2,2,13,0,0,0,0,0,0,0,0,0,13,2,2
2,2,14,0,0,0,0,0,0,0,0,0,14,2,2
2,2,14,0,0,0,0,0,0,0,0,0,14,2,2
2,2,13,0,0,0,0,0,0,0,0,0,13,2,2
2,2,14,0,0,0,0,0,0,0,0,0,14,2,2
2,2,13,0,0,0,0,0,0,0,0,0,13,2,2
2,2,14,0,0,0,0,0,0,0,0,0,14,2,2
2,2,14,0,0,0,0,0,0,0,0,0,14,2,2
2,2,13,0,0,0,0,0,0,0,0,0,13,2,2
2,2,6,13,14,14,13,14,13,14,14,13,6,2,2
2,2,2,2,2,2,2,2,2,2,2,2,2,2,2
2,2,2,2,2,2,2,2,2,2,2,2,2,2,2
endlayer

layer
2,2,2,2,2,2,2,2,2,2,2,2,2,2,2
2,2,2,2,2,2,2,2,2,2,2,2,2,2,2
2,2,6,13,14,14,13,14,13,14,14,13,6,2,2
2,2,13,0,0,0,0,0,0,0,0,0,13,2,2
2,2,14,0,0,0,0,0,0,0,0,0,14,2,2
2,2,14,0,0,0,0,0,0,0,0,0,14,2,2
2,2,13,0,0,0,0,0,0,0,0,0,13,2,2
2,2,14,0,0,0,0,0,0,0,0,0,14,2,2
2,2,13,0,0,0,0,0,0,0,0,0,13,2,2
2,2,14,0,0,0,0,0,0,0,0,0,14,2,2
2,2,14,0,0,0,0,0,0,0,0,0,14,2,2
2,2,13,0,0,0,0,0,0,0,0,0,13,2,2
2,2,6,13,14,14,13,14,13,14,14,13,6,2,2
2,2,2,2,2,2,2,2,2,2,2,2,2,2,2
2,2,2,2,2,2,2,2,2,2,2,2,2,2,2
endlayer

layer
2,2,2,2,2,2,2,2,2,2,2,2,2,2,2
2,2,2,2,2,2,2,2,2,2,2,2,2,2,2
2,2,6,13,14,14,13,14,13,14,14,13,6,2,2
2,2,13,0,0,0,0,0,0,0,0,0,13,2,2
2,2,14,0,0,0,0,0,0,0,0,0,14,2,2
2,2,14,0,0,0,0,0,0,0,0,0,14,2,2
2,2,13,0,0,0,0,0,0,0,0,0,13,2,2
2,2,14,0,0,0,0,0,0,0,0,0,14,2,2
2,2,13,0,0,0,0,0,0,0,0,0,13,2,2
2,2,14,0,0,0,0,0,0,0,0,0,14,2,2
2,2,14,0,0,0,0,0,0,0,0,0,14,2,2
2,2,13,0,0,0,0,0,0,0,0,0,13,2,2
2,2,6,13,14,14,13,14,13,14,14,13,6,2,2
2,2,2,2,2,2,2,2,2,2,2,2,2,2,2
2,2,2,2,2,2,2,2,2,2,2,2,2,2,2
endlayer

layer
2,2,2,2,2,2,2,2,2,2,2,2,2,2,2
2,2,2,2,2,2,2,2,2,2,2,2,2,2,2
2,2,6,13,14,14,13,14,13,14,14,13,6,2,2
2,2,13,0,0,0,0,0,0,0,0,0,13,2,2
2,2,14,0,0,0,0,0,0,0,0,0,14,2,2
2,2,14,0,0,0,0,0,0,0,0,0,14,2,2
2,2,13,0,0,0,0,0,0,0,0,0,13,2,2
2,2,14,0,0,0,0,0,0,0,0,0,14,2,2
2,2,13,0,0,0,0,0,0,0,0,0,13,2,2
2,2,14,0,0,0,0,0,0,0,0,0,14,2,2
2,2,14,0,0,0,0,0,0,0,0,0,14,2,2
2,2,13,0,0,0,0,0,0,0,0,0,13,2,2
2,2,6,13,14,14,13,14,13,14,14,13,6,2,2
2,2,2,2,2,2,2,2,2,2,2,2,2,2,2
2,2,2,2,2,2,2,2,2,2,2,2,2,2,2
endlayer

layer
2,2,2,2,2,2,2,2,2,2,2,2,2,2,2
2,2,2,2,2,2,2,2,2,2,2,2,2,2,2
2,2,6,13,14,14,13,14,13,14,14,13,6,2,2
2,2,13,0,0,0,0,0,0,0,0,0,13,2,2
2,2,14,0,0,0,0,0,0,0,0,0,14,2,2
2,2,14,0,0,0,0,0,0,0,0,0,14,2,2
2,2,13,0,0,0,0,0,0,0,0,0,13,2,2
2,2,14,0,0,0,0,0,0,0,0,0,14,2,2
2,2,13,0,0,0,0,0,0,0,0,0,13,2,2
2,2,14,0,0,0,0,0,0,0,0,0,14,2,2
2,2,14,0,0,0,0,0,0,0,0,0,14,2,2
2,2,13,0,0,0,0,0,0,0,0,0,13,2,2
2,2,6,13,14,14,13,14,13,14,14,13,6,2,2
2,2,2,2,2,2,2,2,2,2,2,2,2,2,2
2,2,2,2,2,2,2,2,2,2,2,2,2,2,2
endlayer

layer
2,2,2,2,2,2,2,2,2,2,2,2,2,2,2
2,2,2,2,2,2,2,2,2,2,2,2,2,2,2
2,2,6,6,6,6,6,6,6,6,6,6,6,2,2
2,2,6,3,3,3,3,5,3,3,3,3,6,2,2
2,2,6,3,3,3,3,3,3,3,3,3,6,2,2
2,2,6,3,3,3,3,3,3,3,3,3,6,2,2
2,2,6,3,3,3,3,3,3,3,3,3,6,2,2
2,2,6,3,3,3,3,3,3,3,3,3,6,2,2
2,2,6,3,3,3,3,3,3,3,3,3,6,2,2
2,2,6,3,3,3,3,3,3,3,3,3,6,2,2
2,2,6,3,3,3,3,3,3,3,3,3,6,2,2
2,2,6,3,3,3,3,3,3,3,3,3,6,2,2
2,2,6,6,6,6,6,6,6,6,6,6,6,2,2
2,2,2,2,2,2,2,2,2,2,2,2,2,2,2
2,2,2,2,2,2,2,2,2,2,2,2,2,2,2
endlayer

layer
15,15,15,15,15,15,15,15,15,15,15,15,15,15,15
15,15,15,15,15,15,15,15,15,15,15,15,15,15,15
15,15,6,13,14,14,13,14,13,14,14,13,6,15,15
15,15,13,0,0,0,0,0,0,0,0,0,13,15,15
15,15,14,0,9,9,9,0,9,9,9,0,14,15,15
15,15,14,0,11,7,11,0,11,7,11,0,14,15,15
15,15,13,0,10,7,10,0,10,7,10,0,13,15,15
15,15,14,0,9,8,9,0,9,8,9,0,14,15,15
15,15,13,0,11,7,11,0,11,7,11,0,13,15,15
15,15,14,0,10,7,10,0,10,7,10,0,14,15,15
15,15,14,0,9,9,9,0,9,9,9,0,14,15,15
15,15,13,0,0,0,0,0,0,0,0,0,13,15,15
15,15,6,13,14,14,13,14,13,14,14,13,6,15,15
15,15,15,15,15,15,15,15,15,15,15,15,15,15,15
15,15,15,15,15,15,15,15,15,15,15,15,15,15,15
endlayer

layer
0,0,0,0,0,0,0,0,0,0,0,0,0,0,0
0,0,0,0,0,0,0,0,0,0,0,0,0,0,0
0,0,6,13,14,14,13,14,13,14,14,13,6,0,0
0,0,13,0,0,0,0,0,0,0,0,0,13,0,0
0,0,14,0,9,9,9,0,9,9,9,0,14,0,0
0,0,14,0,0,7,0,0,0,7,0,0,14,0,0
0,0,13,0,0,7,0,0,0,7,0,0,13,0,0
0,0,14,0,9,9,9,0,9,9,9,0,14,0,0
0,0,13,0,0,7,0,0,0,7,0,0,13,0,0
0,0,14,0,0,7,0,0,0,7,0,0,14,0,0
0,0,14,0,9,9,9,0,9,9,9,0,14,0,0
0,0,13,0,0,0,0,0,0,0,0,0,13,0,0
0,0,6,13,14,14,13,14,13,14,14,13,6,0,0
0,0,0,0,0,0,0,0,0,0,0,0,0,0,0
0,0,0,0,0,0,0,0,0,0,0,0,0,0,0
endlayer

layer
0,0,0,0,0,0,0,0,0,0,0,0,0,0,0
0,0,0,0,0,0,0,0,0,0,0,0,0,0,0
0,0,6,13,14,14,13,14,13,14,14,13,6,0,0
0,0,13,0,0,0,0,0,0,0,0,0,13,0,0
0,0,14,0,0,0,0,0,0,0,0,0,14,0,0
0,0,14,0,0,0,0,0,0,0,0,0,14,0,0
0,0,13,0,0,0,0,0,0,0,0,0,13,0,0
0,0,14,0,0,0,0,0,0,0,0,0,14,0,0
0,0,13,0,0,0,0,0,0,0,0,0,13,0,0
0,0,14,0,0,0,0,0,0,0,0,0,14,0,0
0,0,14,0,0,0,0,0,0,0,0,0,14,0,0
0,0,13,0,0,0,0,0,0,0,0,0,13,0,0
0,0,6,13,14,14,13,14,13,14,14,13,6,0,0
0,0,0,0,0,0,0,0,0,0,0,0,0,0,0
0,0,0,0,0,0,0,0,0,0,0,0,0,0,0
endlayer

layer
0,0,0,0,0,0,0,0,0,0,0,0,0,0,0
0,0,0,0,0,0,0,0,0,0,0,0,0,0,0
0,0,6,13,14,14,13,14,13,14,14,13,6,0,0
0,0,13,0,0,0,0,0,0,0,0,0,13,0,0
0,0,14,0,0,0,0,0,0,0,0,0,14,0,0
0,0,14,0,0,0,0,0,0,0,0,0,14,0,0
0,0,13,0,0,0,0,0,0,0,0,0,13,0,0
0,0,14,0,0,0,0,0,0,0,0,0,14,0,0
0,0,13,0,0,0,0,0,0,0,0,0,13,0,0
0,0,14,0,0,0,0,0,0,0,0,0,14,0,0
0,0,14,0,0,0,0,0,0,0,0,0,14,0,0
0,0,13,0,0,0,0,0,0,0,0,0,13,0,0
0,0,6,13,14,14,13,14,13,14,14,13,6,0,0
0,0,0,0,0,0,0,0,0,0,0,0,0,0,0
0,0,0,0,0,0,0,0,0,0,0,0,0,0,0
endlayer

layer
0,0,0,0,0,0,0,0,0,0,0,0,0,0,0
0,0,0,0,0,0,0,0,0,0,0,0,0,0,0
0,0,6,13,14,14,13,14,13,14,14,13,6,0,0
0,0,13,0,0,0,0,0,0,0,0,0,13,0,0
0,0,14,0,0,0,0,0,0,0,0,0,14,0,0
0,0,14,0,0,0,0,0,0,0,0,0,14,0,0
0,0,13,0,0,0,0,0,0,0,0,0,13,0,0
0,0,14,0,0,0,0,0,0,0,0,0,14,0,0
0,0,13,0,0,0,0,0,0,0,0,0,13,0,0
0,0,14,0,0,0,0,0,0,0,0,0,14,0,0
0,0,14,0,0,0,0,0,0,0,0,0,14,0,0
0,0,13,0,0,0,0,0,0,0,0,0,13,0,0
0,0,6,13,14,14,13,14,13,14,14,13,6,0,0
0,0,0,0,0,0,0,0,0,0,0,0,0,0,0
0,0,0,0,0,0,0,0,0,0,0,0,0,0,0
endlayer

layer
0,0,0,0,0,0,0,0,0,0,0,0,0,0,0
0,0,0,0,0,0,0,0,0,0,0,0,0,0,0
0,0,6,13,14,14,13,14,13,14,14,13,6,0,0
0,0,13,0,0,0,0,0,0,0,0,0,13,0,0
0,0,14,0,0,0,0,0,0,0,0,0,14,0,0
0,0,14,0,0,0,0,0,0,0,0,0,14,0,0
0,0,13,0,0,0,0,0,0,0,0,0,13,0,0
0,0,14,0,0,0,0,0,0,0,0,0,14,0,0
0,0,13,0,0,0,0,0,0,0,0,0,13,0,0
0,0,14,0,0,0,0,0,0,0,0,0,14,0,0
0,0,14,0,0,0,0,0,0,0,0,0,14,0,0
0,0,13,0,0,0,0,0,0,0,0,0,13,0,0
0,0,6,13,14,14,13,14,13,14,14,13,6,0,0
0,0,0,0,0,0,0,0,0,0,0,0,0,0,0
0,0,0,0,0,0,0,0,0,0,0,0,0,0,0
endlayer

layer
0,0,0,0,0,0,0,0,0,0,0,0,0,0,0
0,0,0,0,0,0,0,0,0,0,0,0,0,0,0
0,0,6,13,14,14,13,14,13,14,14,13,6,0,0
0,0,13,0,0,0,0,0,0,0,0,0,13,0,0
0,0,14,0,0,0,0,0,0,0,0,0,14,0,0
0,0,14,0,0,0,0,0,0,0,0,0,14,0,0
0,0,13,0,0,0,0,0,0,0,0,0,13,0,0
0,0,14,0,0,0,0,0,0,0,0,0,14,0,0
0,0,13,0,0,0,0,0,0,0,0,0,13,0,0
0,0,14,0,0,0,0,0,0,0,0,0,14,0,0
0,0,14,0,0,0,0,0,0,0,0,0,14,0,0
0,0,13,0,0,0,0,0,0,0,0,0,13,0,0
0,0,6,13,14,14,13,14,13,14,14,13,6,0,0
0,0,0,0,0,0,0,0,0,0,0,0,0,0,0
0,0,0,0,0,0,0,0,0,0,0,0,0,0,0
endlayer

layer
0,0,0,0,0,0,0,0,0,0,0,0,0,0,0
0,0,0,0,0,0,0,0,0,0,0,0,0,0,0
0,0,6,13,14,14,13,14,13,14,14,13,6,0,0
0,0,13,0,0,0,0,0,0,0,0,0,13,0,0
0,0,14,0,0,0,0,0,0,0,0,0,14,0,0
0,0,14,0,0,0,0,0,0,0,0,0,14,0,0
0,0,13,0,0,0,0,0,0,0,0,0,13,0,0
0,0,14,0,0,0,0,0,0,0,0,0,14,0,0
0,0,13,0,0,0,0,0,0,0,0,0,13,0,0
0,0,14,0,0,0,0,0,0,0,0,0,14,0,0
0,0,14,0,0,0,0,0,0,0,0,0,14,0,0
0,0,13,0,0,0,0,0,0,0,0,0,13,0,0
0,0,6,13,14,14,13,14,13,14,14,13,6,0,0
0,0,0,0,0,0,0,0,0,0,0,0,0,0,0
0,0,0,0,0,0,0,0,0,0,0,0,0,0,0
endlayer

layer
0,0,0,0,0,0,0,0,0,0,0,0,0,0,0
0,0,0,0,0,0,0,0,0,0,0,0,0,0,0
0,0,6,6,6,6,6,6,6,6,6,6,6,0,0
0,0,6,3,3,3,3,5,3,3,3,3,6,0,0
0,0,6,3,3,3,3,3,3,3,3,3,6,0,0
0,0,6,3,3,3,3,3,3,3,3,3,6,0,0
0,0,6,3,3,3,3,3,3,3,3,3,6,0,0
0,0,6,3,3,3,3,3,3,3,3,3,6,0,0
0,0,6,3,3,3,3,3,3,3,3,3,6,0,0
0,0,6,3,3,3,3,3,3,3,3,3,6,0,0
0,0,6,3,3,3,3,3,3,3,3,3,6,0,0
0,0,6,3,3,3,3,3,3,3,3,3,6,0,0
0,0,6,6,6,6,6,6,6,6,6,6,6,0,0
0,0,0,0,0,0,0,0,0,0,0,0,0,0,0
0,0,0,0,0,0,0,0,0,0,0,0,0,0,0
endlayer

layer
0,0,0,0,0,0,0,0,0,0,0,0,0,0,0
0,0,0,0,0,0,0,0,0,0,0,0,0,0,0
0,0,6,13,14,14,13,14,13,14,14,13,6,0,0
0,0,13,0,0,0,0,0,0,0,0,0,13,0,0
0,0,14,0,9,9,9,0,9,9,9,0,14,0,0
0,0,14,0,10,7,10,0,10,7,10,0,14,0,0
0,0,13,0,11,7,11,0,11,7,11,0,13,0,0
0,0,14,0,9,8,9,0,9,8,9,0,14,0,0
0,0,13,0,11,7,11,0,11,7,11,0,13,0,0
0,0,14,0,10,7,10,0,10,7,10,0,14,0,0
0,0,14,0,9,9,9,0,9,9,9,0,14,0,0
0,0,13,0,0,0,0,0,0,0,0,0,13,0,0
0,0,6,13,14,14,13,14,13,14,14,13,6,0,0
0,0,0,0,0,0,0,0,0,0,0,0,0,0,0
0,0,0,0,0,0,0,0,0,0,0,0,0,0,0
endlayer

layer
0,0,0,0,0,0,0,0,0,0,0,0,0,0,0
0,0,0,0,0,0,0,0,0,0,0,0,0,0,0
0,0,6,13,14,14,13,14,13,14,14,13,6,0,0
0,0,13,0,0,0,0,0,0,0,0,0,13,0,0
0,0,14,0,9,9,9,0,9,9,9,0,14,0,0
0,0,14,0,0,7,0,0,0,7,0,0,14,0,0
0,0,13,0,0,7,0,0,0,7,0,0,13,0,0
0,0,14,0,9,9,9,0,9,9,9,0,14,0,0
0,0,13,0,0,7,0,0,0,7,0,0,13,0,0
0,0,14,0,0,7,0,0,0,7,0,0,14,0,0
0,0,14,0,9,9,9,0,9,9,9,0,14,0,0
0,0,13,0,0,0,0,0,0,0,0,0,13,0,0
0,0,6,13,14,14,13,14,13,14,14,13,6,0,0
0,0,0,0,0,0,0,0,0,0,0,0,0,0,0
0,0,0,0,0,0,0,0,0,0,0,0,0,0,0
endlayer

layer
0,0,0,0,0,0,0,0,0,0,0,0,0,0,0
0,0,0,0,0,0,0,0,0,0,0,0,0,0,0
0,0,6,13,14,14,13,14,13,14,14,13,6,0,0
0,0,13,0,0,0,0,0,0,0,0,0,13,0,0
0,0,14,0,0,0,0,0,0,0,0,0,14,0,0
0,0,14,0,0,0,0,0,0,0,0,0,14,0,0
0,0,13,0,0,0,0,0,0,0,0,0,13,0,0
0,0,14,0,0,0,0,0,0,0,0,0,14,0,0
0,0,13,0,0,0,0,0,0,0,0,0,13,0,0
0,0,14,0,0,0,0,0,0,0,0,0,14,0,0
0,0,14,0,0,0,0,0,0,0,0,0,14,0,0
0,0,13,0,0,0,0,0,0,0,0,0,13,0,0
0,0,6,13,14,14,13,14,13,14,14,13,6,0,0
0,0,0,0,0,0,0,0,0,0,0,0,0,0,0
0,0,0,0,0,0,0,0,0,0,0,0,0,0,0
endlayer

layer
0,0,0,0,0,0,0,0,0,0,0,0,0,0,0
0,0,0,0,0,0,0,0,0,0,0,0,0,0,0
0,0,6,13,14,14,13,14,13,14,14,13,6,0,0
0,0,13,0,0,0,0,0,0,0,0,0,13,0,0
0,0,14,0,0,0,0,0,0,0,0,0,14,0,0
0,0,14,0,0,0,0,0,0,0,0,0,14,0,0
0,0,13,0,0,0,0,0,0,0,0,0,13,0,0
0,0,14,0,0,0,0,0,0,0,0,0,14,0,0
0,0,13,0,0,0,0,0,0,0,0,0,13,0,0
0,0,14,0,0,0,0,0,0,0,0,0,14,0,0
0,0,14,0,0,0,0,0,0,0,0,0,14,0,0
0,0,13,0,0,0,0,0,0,0,0,0,13,0,0
0,0,6,13,14,14,13,14,13,14,14,13,6,0,0
0,0,0,0,0,0,0,0,0,0,0,0,0,0,0
0,0,0,0,0,0,0,0,0,0,0,0,0,0,0
endlayer

layer
0,0,0,0,0,0,0,0,0,0,0,0,0,0,0
0,0,0,0,0,0,0,0,0,0,0,0,0,0,0
0,0,6,13,14,14,13,14,13,14,14,13,6,0,0
0,0,13,0,0,0,0,0,0,0,0,0,13,0,0
0,0,14,0,0,0,0,0,0,0,0,0,14,0,0
0,0,14,0,0,0,0,0,0,0,0,0,14,0,0
0,0,13,0,0,0,0,0,0,0,0,0,13,0,0
0,0,14,0,0,0,0,0,0,0,0,0,14,0,0
0,0,13,0,0,0,0,0,0,0,0,0,13,0,0
0,0,14,0,0,0,0,0,0,0,0,0,14,0,0
0,0,14,0,0,0,0,0,0,0,0,0,14,0,0
0,0,13,0,0,0,0,0,0,0,0,0,13,0,0
0,0,6,13,14,14,13,14,13,14,14,13,6,0,0
0,0,0,0,0,0,0,0,0,0,0,0,0,0,0
0,0,0,0,0,0,0,0,0,0,0,0,0,0,0
endlayer

layer
0,0,0,0,0,0,0,0,0,0,0,0,0,0,0
0,0,0,0,0,0,0,0,0,0,0,0,0,0,0
0,0,6,13,14,14,13,14,13,14,14,13,6,0,0
0,0,13,0,0,0,0,0,0,0,0,0,13,0,0
0,0,14,0,0,0,0,0,0,0,0,0,14,0,0
0,0,14,0,0,0,0,0,0,0,0,0,14,0,0
0,0,13,0,0,0,0,0,0,0,0,0,13,0,0
0,0,14,0,0,0,0,0,0,0,0,0,14,0,0
0,0,13,0,0,0,0,0,0,0,0,0,13,0,0
0,0,14,0,0,0,0,0,0,0,0,0,14,0,0
0,0,14,0,0,0,0,0,0,0,0,0,14,0,0
0,0,13,0,0,0,0,0,0,0,0,0,13,0,0
0,0,6,13,14,14,13,14,13,14,14,13,6,0,0
0,0,0,0,0,0,0,0,0,0,0,0,0,0,0
0,0,0,0,0,0,0,0,0,0,0,0,0,0,0
endlayer

layer
0,0,0,0,0,0,0,0,0,0,0,0,0,0,0
0,0,0,0,0,0,0,0,0,0,0,0,0,0,0
0,0,6,13,14,14,13,14,13,14,14,13,6,0,0
0,0,13,0,0,0,0,0,0,0,0,0,13,0,0
0,0,14,0,0,0,0,0,0,0,0,0,14,0,0
0,0,14,0,0,0,0,0,0,0,0,0,14,0,0
0,0,13,0,0,0,0,0,0,0,0,0,13,0,0
0,0,14,0,0,0,0,0,0,0,0,0,14,0,0
0,0,13,0,0,0,0,0,0,0,0,0,13,0,0
0,0,14,0,0,0,0,0,0,0,0,0,14,0,0
0,0,14,0,0,0,0,0,0,0,0,0,14,0,0
0,0,13,0,0,0,0,0,0,0,0,0,13,0,0
0,0,6,13,14,14,13,14,13,14,14,13,6,0,0
0,0,0,0,0,0,0,0,0,0,0,0,0,0,0
0,0,0,0,0,0,0,0,0,0,0,0,0,0,0
endlayer

layer
0,0,0,0,0,0,0,0,0,0,0,0,0,0,0
0,0,0,0,0,0,0,0,0,0,0,0,0,0,0
0,0,6,13,14,14,13,14,13,14,14,13,6,0,0
0,0,13,0,0,0,0,0,0,0,0,0,13,0,0
0,0,14,0,0,0,0,0,0,0,0,0,14,0,0
0,0,14,0,0,0,0,0,0,0,0,0,14,0,0
0,0,13,0,0,0,0,0,0,0,0,0,13,0,0
0,0,14,0,0,0,0,0,0,0,0,0,14,0,0
0,0,13,0,0,0,0,0,0,0,0,0,13,0,0
0,0,14,0,0,0,0,0,0,0,0,0,14,0,0
0,0,14,0,0,0,0,0,0,0,0,0,14,0,0
0,0,13,0,0,0,0,0,0,0,0,0,13,0,0
0,0,6,13,14,14,13,14,13,14,14,13,6,0,0
0,0,0,0,0,0,0,0,0,0,0,0,0,0,0
0,0,0,0,0,0,0,0,0,0,0,0,0,0,0
endlayer

layer
0,0,0,0,0,0,0,0,0,0,0,0,0,0,0
0,0,0,0,0,0,0,0,0,0,0,0,0,0,0
0,0,6,13,14,14,13,14,13,14,14,13,6,0,0
0,0,13,0,0,0,0,0,0,0,0,0,13,0,0
0,0,14,0,0,0,0,0,0,0,0,0,14,0,0
0,0,14,0,0,0,0,0,0,0,0,0,14,0,0
0,0,13,0,0,0,0,0,0,0,0,0,13,0,0
0,0,14,0,0,0,0,0,0,0,0,0,14,0,0
0,0,13,0,0,0,0,0,0,0,0,0,13,0,0
0,0,14,0,0,0,0,0,0,0,0,0,14,0,0
0,0,14,0,0,0,0,0,0,0,0,0,14,0,0
0,0,13,0,0,0,0,0,0,0,0,0,13,0,0
0,0,6,13,14,14,13,14,13,14,14,13,6,0,0
0,0,0,0,0,0,0,0,0,0,0,0,0,0,0
0,0,0,0,0,0,0,0,0,0,0,0,0,0,0
endlayer

layer
0,0,0,0,0,0,0,0,0,0,0,0,0,0,0
0,0,0,0,0,0,0,0,0,0,0,0,0,0,0
0,0,6,6,6,6,6,6,6,6,6,6,6,0,0
0,0,6,16,16,16,16,16,16,16,16,16,6,0,0
0,0,6,16,16,16,16,16,16,16,16,16,6,0,0
0,0,6,16,16,16,16,16,16,16,16,16,6,0,0
0,0,6,16,16,16,16,16,16,16,16,16,6,0,0
0,0,6,16,16,16,16,16,16,16,16,16,6,0,0
0,0,6,16,16,16,16,16,16,16,16,16,6,0,0
0,0,6,16,16,16,16,16,16,16,16,16,6,0,0
0,0,6,16,16,16,16,16,16,16,16,16,6,0,0
0,0,6,16,16,16,16,16,16,16,16,16,6,0,0
0,0,6,6,6,6,6,6,6,6,6,6,6,0,0
0,0,0,0,0,0,0,0,0,0,0,0,0,0,0
0,0,0,0,0,0,0,0,0,0,0,0,0,0,0
endlayer

