# Converted from schematic
# THIS TEMPLATE USES DEFAULTS!  Please edit for corrections.
# If you need help, consult template_rules.txt

weight=7
embed_into_distance=11
acceptable_target_blocks=1,2,3,12,13,250
dimensions=29,15,13
allowable_overhang=0
max_cut_in=2
cut_in_buffer=1
max_leveling=2
leveling_buffer=1
preserve_water=0
preserve_lava=0
preserve_plants=0


rule1=0,100,300
rule2=0,100,3134-10
rule3=0,100,308
rule4=0,100,2843-14,2843-14,2843-14,2843-14,2843
rule5=0,100,2843-12
rule6=0,50,311
rule7=0,95,2835-2,2835-2,2835-2,2835-2,2835-2,2835-2,2835-2,2835-1,2835-1,2835-0
rule8=0,25,3225-3
rule9=0,100,2843-4
rule10=0,100,2542
rule11=0,95,300
rule12=0,100,3134,3134,3134,3134,3134-8,3134-2


layer
2,2,2,2,2,2,2,2,2,2,1,1,1
2,2,2,2,2,2,2,2,2,2,2,1,1
2,2,1,1,1,1,1,1,1,1,1,1,1
2,2,1,1,1,1,1,1,1,1,1,1,1
2,2,1,1,1,1,1,1,1,1,1,1,1
2,2,1,1,1,1,1,1,1,1,1,1,1
2,2,1,1,1,1,1,1,1,1,1,1,1
2,2,1,1,1,1,1,1,1,1,1,1,1
2,2,1,1,1,1,1,1,1,1,1,1,1
2,2,1,1,1,1,1,3,1,1,1,1,1
2,2,1,1,1,1,1,1,1,1,1,1,1
2,2,1,1,1,1,1,1,1,1,1,1,1
2,2,1,1,1,1,1,1,1,1,1,1,1
2,2,2,2,2,2,2,2,2,2,2,1,1
2,2,2,2,2,2,2,2,2,2,2,1,1
endlayer

layer
1,1,1,1,1,1,1,1,1,1,1,1,1
1,1,1,1,1,1,1,1,1,1,1,1,1
1,1,4,4,4,4,4,4,4,4,4,1,1
1,1,4,1,1,1,5,1,1,1,1,1,1
1,1,4,0,1,6,5,1,1,1,1,1,1
1,1,4,5,5,1,5,1,1,1,1,1,1
1,1,4,0,0,0,1,1,1,1,1,1,1
1,1,4,0,0,0,0,1,1,1,1,1,1
1,1,4,0,0,0,0,1,1,1,1,1,1
1,1,4,5,5,0,5,1,1,1,1,1,1
1,1,4,0,0,0,5,1,1,1,1,1,1
1,1,4,0,0,0,5,1,1,1,1,1,1
1,1,4,4,4,4,4,4,4,4,4,1,1
1,1,1,1,1,1,1,1,1,1,1,1,1
1,1,1,1,1,1,1,1,1,1,1,1,1
endlayer

layer
1,1,1,1,1,1,1,1,1,1,1,1,1
1,1,1,1,1,1,1,1,1,1,1,1,1
1,1,4,7,1,1,7,1,1,1,1,1,1
1,1,7,1,1,1,5,1,1,1,1,1,1
1,1,1,0,1,1,5,1,1,1,1,1,1
1,1,1,5,5,0,5,1,1,1,1,1,1
1,1,7,0,0,0,0,1,1,1,1,1,1
1,1,1,0,0,0,0,1,1,1,1,1,1
1,1,7,0,0,0,0,0,1,1,1,1,1
1,1,1,5,5,0,5,0,1,1,1,1,1
1,1,1,0,0,0,5,1,1,1,1,1,1
1,1,7,0,0,0,5,1,1,1,1,1,1
1,1,4,7,1,1,7,1,7,1,1,1,1
1,1,1,1,1,1,1,1,1,1,1,1,1
1,1,1,1,1,1,1,1,1,1,1,1,1
endlayer

layer
1,1,1,1,1,1,1,1,1,1,1,1,1
1,1,1,1,1,1,1,1,1,1,1,1,1
1,1,4,7,1,1,7,1,1,1,1,1,1
1,1,7,0,1,1,1,1,1,1,1,1,1
1,1,8,0,0,0,1,1,1,1,1,1,1
1,1,1,0,0,0,1,1,1,1,1,1,1
1,1,7,0,0,0,0,1,1,1,1,1,1
1,1,1,0,0,0,0,0,1,1,1,1,1
1,1,7,0,0,0,0,0,1,1,1,1,1
1,1,1,0,0,0,0,0,1,1,1,1,1
1,1,8,0,0,0,0,0,1,1,1,1,1
1,1,7,0,0,0,0,0,1,1,1,1,1
1,1,4,7,1,8,7,1,7,1,1,1,1
1,1,1,1,1,1,1,1,1,1,1,1,1
1,1,1,1,1,1,1,1,1,1,1,1,1
endlayer

layer
1,1,1,1,1,1,1,1,1,1,1,1,1
1,1,1,1,1,1,1,1,1,1,1,1,1
1,1,4,7,1,1,7,1,1,1,1,1,1
1,1,7,0,0,0,1,1,1,1,1,1,1
1,1,8,0,0,0,1,1,1,1,1,1,1
1,1,8,0,0,0,0,1,1,1,1,1,1
1,1,7,0,0,0,0,0,1,1,1,1,1
1,1,0,0,0,0,0,0,0,1,1,1,1
1,1,7,0,0,0,0,0,1,1,1,1,1
1,1,1,0,0,0,0,0,1,1,1,1,1
1,1,0,0,0,0,0,0,1,1,1,1,1
1,1,7,0,0,0,0,0,1,1,1,1,1
1,1,4,7,1,0,7,0,7,1,1,1,1
1,1,1,1,1,1,1,1,1,1,1,1,1
1,1,1,1,1,1,1,1,1,1,1,1,1
endlayer

layer
1,1,1,1,1,1,1,1,1,1,1,1,1
1,1,1,1,1,1,1,1,1,1,1,1,1
1,1,4,0,0,1,7,1,1,1,1,1,1
1,1,7,0,0,0,1,1,1,1,1,1,1
1,1,0,0,0,0,0,1,1,1,1,1,1
1,1,8,0,0,0,0,0,1,1,1,1,1
1,1,7,0,0,0,0,0,0,1,1,1,1
1,1,0,0,0,0,0,0,0,1,1,1,1
1,1,7,0,0,0,0,0,0,1,1,1,1
1,1,8,0,0,0,0,0,1,1,1,1,1
1,1,0,0,0,0,0,0,1,1,1,1,1
1,1,7,0,0,0,0,0,1,1,1,1,1
1,1,4,7,0,0,7,0,7,1,1,1,1
1,1,1,1,1,1,1,1,1,1,1,1,1
1,1,1,1,1,1,1,1,1,1,1,1,1
endlayer

layer
1,1,1,1,1,1,1,1,1,1,1,1,1
1,1,1,1,1,1,1,1,1,1,1,1,1
1,1,4,7,8,8,7,1,1,1,1,1,1
1,1,7,0,0,0,0,1,1,1,1,1,1
1,1,0,0,0,0,0,0,1,1,1,1,1
1,1,0,0,0,0,0,0,1,1,1,1,1
1,1,7,0,0,0,0,0,0,1,1,1,1
1,1,0,0,0,0,0,0,0,1,1,1,1
1,1,7,0,0,0,0,0,0,1,1,1,1
1,1,0,0,0,0,0,0,1,1,1,1,1
1,1,0,0,0,0,0,0,1,1,1,1,1
1,1,7,0,0,0,0,0,1,1,1,1,1
1,1,4,7,0,8,0,8,7,1,1,1,1
1,1,1,1,1,1,1,1,1,1,1,1,1
1,1,1,1,1,1,1,1,1,1,1,1,1
endlayer

layer
1,1,1,1,1,1,1,1,1,1,1,1,1
1,1,1,1,1,1,1,1,1,1,1,1,1
1,1,4,7,0,0,7,1,1,1,1,1,1
1,1,7,0,0,0,0,0,1,1,1,1,1
1,1,8,0,0,0,0,0,1,1,1,1,1
1,1,0,0,0,0,0,0,0,1,1,1,1
1,1,7,0,0,0,0,0,0,1,1,1,1
1,1,0,0,0,0,0,0,0,1,1,1,1
1,1,7,0,0,0,0,0,0,1,1,1,1
1,1,8,0,0,0,0,0,0,1,1,1,1
1,1,8,0,0,0,0,0,1,1,1,1,1
1,1,7,0,0,0,0,0,0,1,1,1,1
1,1,4,7,8,8,7,0,7,1,1,1,1
1,1,1,1,1,1,1,1,1,1,1,1,1
1,1,1,1,1,1,1,1,1,1,1,1,1
endlayer

layer
1,1,1,1,1,1,1,1,1,1,1,1,1
1,1,1,1,1,1,1,1,1,1,1,1,1
1,1,4,7,0,0,7,1,1,1,1,1,1
1,1,7,0,0,0,0,0,1,1,1,1,1
1,1,0,0,0,0,0,0,0,1,1,1,1
1,1,0,0,0,0,0,0,0,1,1,1,1
1,1,7,0,0,0,0,0,0,1,1,1,1
1,1,0,0,0,0,0,0,0,1,1,1,1
1,1,7,0,0,0,0,0,0,1,1,1,1
1,1,8,0,0,0,0,0,0,1,1,1,1
1,1,0,0,0,0,0,0,0,1,1,1,1
1,1,7,0,0,0,0,0,0,1,1,1,1
1,1,4,0,8,0,7,8,7,1,1,1,1
1,1,1,1,1,1,1,1,1,1,1,1,1
1,1,1,1,1,1,1,1,1,1,1,1,1
endlayer

layer
1,1,1,1,1,1,1,1,1,1,1,1,1
1,1,1,1,1,1,1,1,1,1,1,1,1
1,1,4,4,4,4,4,4,4,1,1,1,1
1,1,4,9,9,9,9,9,9,1,1,1,1
1,1,4,9,9,9,9,9,9,0,0,1,1
1,1,4,9,9,9,9,9,9,0,1,1,1
1,1,4,9,9,9,9,9,9,1,1,1,1
1,1,4,10,9,9,9,9,9,1,1,1,1
1,1,4,9,9,9,9,9,9,1,1,1,1
1,1,4,9,9,9,9,9,9,1,1,1,1
1,1,4,9,9,9,9,9,9,1,1,1,1
1,1,4,9,9,9,9,9,9,1,1,1,1
1,1,4,4,4,4,4,4,7,1,1,1,1
1,1,1,1,1,1,1,1,1,1,1,1,1
1,1,1,1,1,1,1,1,1,1,1,1,1
endlayer

layer
11,11,11,11,11,11,11,11,11,11,11,11,11
11,11,11,11,11,11,11,11,11,11,11,11,11
11,11,4,7,11,8,7,11,7,11,11,11,11
11,11,7,0,0,0,0,0,0,11,11,11,11
11,11,11,11,5,0,0,5,0,0,0,11,11
11,11,11,11,5,0,0,0,0,0,0,11,11
11,11,7,0,5,0,0,5,0,0,11,11,11
11,11,0,0,0,0,0,0,11,0,11,11,11
11,11,7,0,5,0,0,5,0,0,11,11,11
11,11,0,0,5,0,0,0,0,11,11,11,11
11,11,8,0,5,11,0,5,11,11,11,11,11
11,11,7,0,11,11,11,0,11,11,11,11,11
11,11,4,7,11,11,7,11,7,11,11,11,11
11,11,11,11,11,11,11,11,11,11,11,11,11
11,11,11,11,11,11,11,11,11,11,11,11,11
endlayer

layer
0,0,0,0,0,0,0,0,0,0,0,0,0
0,0,0,0,0,0,0,0,0,0,0,0,0
0,0,4,7,0,0,7,8,7,0,0,0,0
0,0,7,0,0,0,0,0,0,0,0,0,0
0,0,0,0,5,0,0,5,0,0,0,0,0
0,0,8,0,5,0,0,5,0,0,0,0,0
0,0,7,0,5,0,0,5,0,0,0,0,0
0,0,0,0,0,0,0,0,0,0,0,0,0
0,0,7,0,5,0,0,5,0,0,0,0,0
0,0,0,0,5,0,0,0,0,0,0,0,0
0,0,8,0,5,0,0,5,0,0,0,0,0
0,0,7,0,0,0,0,0,0,0,0,0,0
0,0,4,7,0,0,7,0,7,0,0,0,0
0,0,0,0,0,0,0,0,0,0,0,0,0
0,0,0,0,0,0,0,0,0,0,0,0,0
endlayer

layer
0,0,0,0,0,0,0,0,0,0,0,0,0
0,0,0,0,0,0,0,0,0,0,0,0,0
0,0,4,7,0,8,7,0,0,0,0,0,0
0,0,7,0,0,0,0,0,0,0,0,0,0
0,0,0,0,0,0,0,0,0,0,0,0,0
0,0,0,0,0,0,0,0,0,0,0,0,0
0,0,7,0,0,0,0,0,0,0,0,0,0
0,0,0,0,0,0,0,0,0,0,0,0,0
0,0,7,0,0,0,0,0,0,0,0,0,0
0,0,0,0,0,0,0,0,0,0,0,0,0
0,0,8,0,0,0,0,0,0,0,0,0,0
0,0,7,0,0,0,0,0,0,0,0,0,0
0,0,4,7,0,0,7,0,7,0,0,0,0
0,0,0,0,0,0,0,0,0,0,0,0,0
0,0,0,0,0,0,0,0,0,0,0,0,0
endlayer

layer
0,0,0,0,0,0,0,0,0,0,0,0,0
0,0,0,0,0,0,0,0,0,0,0,0,0
0,0,4,7,0,8,7,0,0,0,0,0,0
0,0,7,0,0,0,0,0,0,0,0,0,0
0,0,0,0,0,0,0,0,0,0,0,0,0
0,0,0,0,0,0,0,0,0,0,0,0,0
0,0,7,0,0,0,0,0,0,0,0,0,0
0,0,0,0,0,0,0,0,0,0,0,0,0
0,0,7,0,0,0,0,0,0,0,0,0,0
0,0,0,0,0,0,0,0,0,0,0,0,0
0,0,0,0,0,0,0,0,0,0,0,0,0
0,0,7,0,0,0,0,0,0,0,0,0,0
0,0,4,7,0,0,7,0,7,0,0,0,0
0,0,0,0,0,0,0,0,0,0,0,0,0
0,0,0,0,0,0,0,0,0,0,0,0,0
endlayer

layer
0,0,0,0,0,0,0,0,0,0,0,0,0
0,0,0,0,0,0,0,0,0,0,0,0,0
0,0,4,0,0,8,7,8,0,0,0,0,0
0,0,7,0,0,0,0,0,0,0,0,0,0
0,0,0,0,0,0,0,0,0,0,0,0,0
0,0,0,0,0,0,0,0,0,0,0,0,0
0,0,7,0,0,0,0,0,0,0,0,0,0
0,0,0,0,0,0,0,0,0,0,0,0,0
0,0,7,0,0,0,0,0,0,0,0,0,0
0,0,0,0,0,0,0,0,0,0,0,0,0
0,0,0,0,0,0,0,0,0,0,0,0,0
0,0,7,0,0,0,0,0,0,0,0,0,0
0,0,4,7,0,0,7,0,0,0,0,0,0
0,0,0,0,0,0,0,0,0,0,0,0,0
0,0,0,0,0,0,0,0,0,0,0,0,0
endlayer

layer
0,0,0,0,0,0,0,0,0,0,0,0,0
0,0,0,0,0,0,0,0,0,0,0,0,0
0,0,4,7,8,0,7,0,0,0,0,0,0
0,0,7,0,0,0,0,0,0,0,0,0,0
0,0,0,0,0,0,0,0,0,0,0,0,0
0,0,0,0,0,0,0,0,0,0,0,0,0
0,0,7,0,0,0,0,0,0,0,0,0,0
0,0,0,0,0,0,0,0,0,0,0,0,0
0,0,7,0,0,0,0,0,0,0,0,0,0
0,0,0,0,0,0,0,0,0,0,0,0,0
0,0,0,0,0,0,0,0,0,0,0,0,0
0,0,7,0,0,0,0,0,0,0,0,0,0
0,0,4,7,0,0,7,0,0,0,0,0,0
0,0,0,0,0,0,0,0,0,0,0,0,0
0,0,0,0,0,0,0,0,0,0,0,0,0
endlayer

layer
0,0,0,0,0,0,0,0,0,0,0,0,0
0,0,0,0,0,0,0,0,0,0,0,0,0
0,0,4,7,0,0,7,0,0,0,0,0,0
0,0,7,0,0,0,0,0,0,0,0,0,0
0,0,0,0,0,0,0,0,0,0,0,0,0
0,0,0,0,0,0,0,0,0,0,0,0,0
0,0,7,0,0,0,0,0,0,0,0,0,0
0,0,0,0,0,0,0,0,0,0,0,0,0
0,0,7,0,0,0,0,0,0,0,0,0,0
0,0,0,0,0,0,0,0,0,0,0,0,0
0,0,0,0,0,0,0,0,0,0,0,0,0
0,0,7,0,0,0,0,0,0,0,0,0,0
0,0,4,7,8,0,7,0,0,0,0,0,0
0,0,0,0,0,0,0,0,0,0,0,0,0
0,0,0,0,0,0,0,0,0,0,0,0,0
endlayer

layer
0,0,0,0,0,0,0,0,0,0,0,0,0
0,0,0,0,0,0,0,0,0,0,0,0,0
0,0,4,7,0,0,0,8,0,0,0,0,0
0,0,0,0,0,0,0,0,0,0,0,0,0
0,0,0,0,0,0,0,0,0,0,0,0,0
0,0,0,0,0,0,0,0,0,0,0,0,0
0,0,7,0,0,0,0,0,0,0,0,0,0
0,0,0,0,0,0,0,0,0,0,0,0,0
0,0,7,0,0,0,0,0,0,0,0,0,0
0,0,0,0,0,0,0,0,0,0,0,0,0
0,0,0,0,0,0,0,0,0,0,0,0,0
0,0,7,0,0,0,0,0,0,0,0,0,0
0,0,4,7,0,0,7,0,0,0,0,0,0
0,0,0,0,0,0,0,0,0,0,0,0,0
0,0,0,0,0,0,0,0,0,0,0,0,0
endlayer

layer
0,0,0,0,0,0,0,0,0,0,0,0,0
0,0,0,0,0,0,0,0,0,0,0,0,0
0,0,4,4,4,4,4,4,0,0,0,0,0
0,0,4,9,9,9,9,9,0,0,0,0,0
0,0,4,9,9,9,9,9,0,0,0,0,0
0,0,4,9,9,9,9,9,0,0,0,0,0
0,0,4,9,9,9,9,9,0,0,0,0,0
0,0,4,10,9,9,9,9,0,0,0,0,0
0,0,4,9,9,9,9,0,0,0,0,0,0
0,0,4,9,9,9,9,9,0,0,0,0,0
0,0,4,9,9,9,9,9,0,0,0,0,0
0,0,4,9,9,9,9,0,0,0,0,0,0
0,0,4,4,4,4,4,0,0,0,0,0,0
0,0,0,0,0,0,0,0,0,0,0,0,0
0,0,0,0,0,0,0,0,0,0,0,0,0
endlayer

layer
0,0,0,0,0,0,0,0,0,0,0,0,0
0,0,0,0,0,0,0,0,0,0,0,0,0
0,0,4,7,0,0,7,0,0,0,0,0,0
0,0,7,0,0,0,0,0,0,0,0,0,0
0,0,8,0,5,0,0,5,0,0,0,0,0
0,0,8,0,5,0,0,0,0,0,0,0,0
0,0,7,0,5,0,0,0,0,0,0,0,0
0,0,0,0,0,0,0,0,0,0,0,0,0
0,0,7,0,5,0,0,5,0,0,0,0,0
0,0,0,0,5,0,0,0,0,0,0,0,0
0,0,0,0,5,0,0,5,0,0,0,0,0
0,0,7,0,0,0,0,0,0,0,0,0,0
0,0,4,7,0,8,7,0,0,0,0,0,0
0,0,0,0,0,0,0,0,0,0,0,0,0
0,0,0,0,0,0,0,0,0,0,0,0,0
endlayer

layer
0,0,0,0,0,0,0,0,0,0,0,0,0
0,0,0,0,0,0,0,0,0,0,0,0,0
0,0,4,7,0,0,0,0,0,0,0,0,0
0,0,7,0,0,0,0,0,0,0,0,0,0
0,0,0,0,5,0,0,0,0,0,0,0,0
0,0,8,0,5,0,0,0,0,0,0,0,0
0,0,7,0,5,0,0,0,0,0,0,0,0
0,0,8,0,0,0,0,0,0,0,0,0,0
0,0,7,0,5,0,0,0,0,0,0,0,0
0,0,0,0,5,0,0,0,0,0,0,0,0
0,0,0,0,5,0,0,5,0,0,0,0,0
0,0,0,0,0,0,0,0,0,0,0,0,0
0,0,4,7,8,0,0,0,0,0,0,0,0
0,0,0,0,0,0,0,0,0,0,0,0,0
0,0,0,0,0,0,0,0,0,0,0,0,0
endlayer

layer
0,0,0,0,0,0,0,0,0,0,0,0,0
0,0,0,0,0,0,0,0,0,0,0,0,0
0,0,4,7,0,0,0,0,0,0,0,0,0
0,0,7,0,0,0,0,0,0,0,0,0,0
0,0,0,0,0,0,0,0,0,0,0,0,0
0,0,0,0,0,0,0,0,0,0,0,0,0
0,0,7,0,0,0,0,0,0,0,0,0,0
0,0,8,0,0,0,0,0,0,0,0,0,0
0,0,7,0,0,0,0,0,0,0,0,0,0
0,0,0,0,0,0,0,0,0,0,0,0,0
0,0,0,0,0,0,0,0,0,0,0,0,0
0,0,7,0,0,0,0,0,0,0,0,0,0
0,0,4,7,0,8,7,0,0,0,0,0,0
0,0,0,0,0,0,0,0,0,0,0,0,0
0,0,0,0,0,0,0,0,0,0,0,0,0
endlayer

layer
0,0,0,0,0,0,0,0,0,0,0,0,0
0,0,0,0,0,0,0,0,0,0,0,0,0
0,0,4,7,0,0,0,0,0,0,0,0,0
0,0,7,0,0,0,0,0,0,0,0,0,0
0,0,0,0,0,0,0,0,0,0,0,0,0
0,0,0,0,0,0,0,0,0,0,0,0,0
0,0,7,0,0,0,0,0,0,0,0,0,0
0,0,0,0,0,0,0,0,0,0,0,0,0
0,0,7,0,0,0,0,0,0,0,0,0,0
0,0,0,0,0,0,0,0,0,0,0,0,0
0,0,0,0,0,0,0,0,0,0,0,0,0
0,0,7,0,0,0,0,0,0,0,0,0,0
0,0,4,7,8,0,7,0,0,0,0,0,0
0,0,0,0,0,0,0,0,0,0,0,0,0
0,0,0,0,0,0,0,0,0,0,0,0,0
endlayer

layer
0,0,0,0,0,0,0,0,0,0,0,0,0
0,0,0,0,0,0,0,0,0,0,0,0,0
0,0,4,7,0,0,0,0,0,0,0,0,0
0,0,7,0,0,0,0,0,0,0,0,0,0
0,0,0,0,0,0,0,0,0,0,0,0,0
0,0,0,0,0,0,0,0,0,0,0,0,0
0,0,0,0,0,0,0,0,0,0,0,0,0
0,0,0,0,0,0,0,0,0,0,0,0,0
0,0,7,0,0,0,0,0,0,0,0,0,0
0,0,0,0,0,0,0,0,0,0,0,0,0
0,0,8,0,0,0,0,0,0,0,0,0,0
0,0,7,0,0,0,0,0,0,0,0,0,0
0,0,4,7,8,0,7,0,0,0,0,0,0
0,0,0,0,0,0,0,0,0,0,0,0,0
0,0,0,0,0,0,0,0,0,0,0,0,0
endlayer

layer
0,0,0,0,0,0,0,0,0,0,0,0,0
0,0,0,0,0,0,0,0,0,0,0,0,0
0,0,4,7,0,0,0,0,0,0,0,0,0
0,0,7,0,0,0,0,0,0,0,0,0,0
0,0,0,0,0,0,0,0,0,0,0,0,0
0,0,0,0,0,0,0,0,0,0,0,0,0
0,0,7,0,0,0,0,0,0,0,0,0,0
0,0,0,0,0,0,0,0,0,0,0,0,0
0,0,7,0,0,0,0,0,0,0,0,0,0
0,0,0,0,0,0,0,0,0,0,0,0,0
0,0,8,0,0,0,0,0,0,0,0,0,0
0,0,7,0,0,0,0,0,0,0,0,0,0
0,0,4,7,0,0,7,0,0,0,0,0,0
0,0,0,0,0,0,0,0,0,0,0,0,0
0,0,0,0,0,0,0,0,0,0,0,0,0
endlayer

layer
0,0,0,0,0,0,0,0,0,0,0,0,0
0,0,0,0,0,0,0,0,0,0,0,0,0
0,0,4,7,0,0,0,0,0,0,0,0,0
0,0,7,0,0,0,0,0,0,0,0,0,0
0,0,0,0,0,0,0,0,0,0,0,0,0
0,0,0,0,0,0,0,0,0,0,0,0,0
0,0,7,0,0,0,0,0,0,0,0,0,0
0,0,8,0,0,0,0,0,0,0,0,0,0
0,0,7,0,0,0,0,0,0,0,0,0,0
0,0,0,0,0,0,0,0,0,0,0,0,0
0,0,8,0,0,0,0,0,0,0,0,0,0
0,0,7,0,0,0,0,0,0,0,0,0,0
0,0,4,7,0,0,7,0,0,0,0,0,0
0,0,0,0,0,0,0,0,0,0,0,0,0
0,0,0,0,0,0,0,0,0,0,0,0,0
endlayer

layer
0,0,0,0,0,0,0,0,0,0,0,0,0
0,0,0,0,0,0,0,0,0,0,0,0,0
0,0,4,7,0,0,0,0,0,0,0,0,0
0,0,7,0,0,0,0,0,0,0,0,0,0
0,0,0,0,0,0,0,0,0,0,0,0,0
0,0,0,0,0,0,0,0,0,0,0,0,0
0,0,7,0,0,0,0,0,0,0,0,0,0
0,0,0,0,0,0,0,0,0,0,0,0,0
0,0,7,0,0,0,0,0,0,0,0,0,0
0,0,8,0,0,0,0,0,0,0,0,0,0
0,0,0,0,0,0,0,0,0,0,0,0,0
0,0,7,0,0,0,0,0,0,0,0,0,0
0,0,4,7,8,0,7,0,0,0,0,0,0
0,0,0,0,0,0,0,0,0,0,0,0,0
0,0,0,0,0,0,0,0,0,0,0,0,0
endlayer

layer
0,0,0,0,0,0,0,0,0,0,0,0,0
0,0,0,0,0,0,0,0,0,0,0,0,0
0,0,4,7,0,0,0,0,0,0,0,0,0
0,0,7,0,0,0,0,0,0,0,0,0,0
0,0,0,0,0,0,0,0,0,0,0,0,0
0,0,0,0,0,0,0,0,0,0,0,0,0
0,0,7,0,0,0,0,0,0,0,0,0,0
0,0,8,0,0,0,0,0,0,0,0,0,0
0,0,7,0,0,0,0,0,0,0,0,0,0
0,0,0,0,0,0,0,0,0,0,0,0,0
0,0,0,0,0,0,0,0,0,0,0,0,0
0,0,7,0,0,0,0,0,0,0,0,0,0
0,0,4,7,0,0,7,0,0,0,0,0,0
0,0,0,0,0,0,0,0,0,0,0,0,0
0,0,0,0,0,0,0,0,0,0,0,0,0
endlayer

layer
0,0,0,0,0,0,0,0,0,0,0,0,0
0,0,0,0,0,0,0,0,0,0,0,0,0
0,0,4,0,0,0,0,0,0,0,0,0,0
0,0,4,0,0,0,0,0,0,0,0,0,0
0,0,4,12,0,0,0,0,0,0,0,0,0
0,0,4,12,12,0,0,0,0,0,0,0,0
0,0,4,12,0,0,0,0,0,0,0,0,0
0,0,4,12,12,12,12,0,0,0,0,0,0
0,0,4,12,12,12,0,0,0,0,0,0,0
0,0,4,12,12,12,12,12,0,0,0,0,0
0,0,4,12,12,12,12,12,0,0,0,0,0
0,0,4,12,12,12,12,12,0,0,0,0,0
0,0,4,4,4,4,4,4,0,0,0,0,0
0,0,0,0,0,0,0,0,0,0,0,0,0
0,0,0,0,0,0,0,0,0,0,0,0,0
endlayer

