weight=20
embed_into_distance=1
dimensions=29,15,15
max_cut_in=2



rule1=0,100,3134-10
rule2=0,100,250
rule3=0,100,2843-4
rule4=0,100,311
rule5=0,100,2542-0
rule6=0,100,2843-14,2843-14,2843-14,2843-14,2843
rule7=0,100,2761-6,2761-6,2761-6,2761-7,2761-7
rule8=0,100,2248-3
rule9=0,100,2843-15
rule10=0,100,2291-3
rule11=0,50,308,308,308,308,308,308,313,313,314,327
rule12=0,100,47,2837-7,2837-5,2837-8,47,2837-7,2837-5,2837-8,311
rule13=0,95,2835-2,2835-2,2835-2,2835-2,2835-2,2835-2,2835-2,2835-1,2835-1,2835-0
rule14=0,25,3225-3
rule15=0,100,2781-4,2781-4,2781-4,2781-4,2781-8


layer
1,1,1,1,1,1,1,1,1,1,1,1,1,1,1
1,1,1,1,1,1,1,1,1,1,1,1,1,1,1
1,1,2,2,2,2,2,2,2,2,2,2,2,1,1
1,1,2,3,3,3,3,3,3,3,3,3,2,1,1
1,1,2,3,3,3,3,3,3,3,3,3,2,1,1
1,1,2,3,3,3,3,3,3,3,3,3,2,1,1
1,1,2,3,3,3,3,3,3,4,3,3,2,1,1
1,1,2,5,3,3,3,3,3,3,3,3,3,1,1
1,1,2,3,3,3,3,3,3,3,3,3,2,1,1
1,1,2,3,3,3,3,3,3,3,3,3,2,1,1
1,1,2,3,3,3,3,3,3,3,3,3,2,1,1
1,1,2,3,3,3,3,3,3,3,3,3,2,1,1
1,1,2,2,2,2,2,2,2,2,2,2,2,1,1
1,1,1,1,1,1,1,1,1,1,1,1,1,1,1
1,1,1,1,1,1,1,1,1,1,1,1,1,1,1
endlayer

layer
0,0,0,0,0,0,0,0,0,0,0,0,0,0,0
0,0,0,0,0,0,0,0,0,0,0,0,0,0,0
0,0,6,6,6,6,6,6,6,6,6,6,6,0,0
0,0,6,12,11,0,9,0,0,0,0,0,6,0,0
0,0,6,8,10,0,9,0,0,0,0,0,6,0,0
0,0,6,9,9,0,9,0,0,0,0,0,6,0,0
0,0,6,0,0,0,0,0,7,7,7,0,6,0,0
0,0,6,0,0,0,0,0,0,8,7,0,0,0,0
0,0,6,0,0,0,0,0,7,7,7,0,6,0,0
0,0,6,9,9,0,9,0,0,0,0,0,6,0,0
0,0,6,8,10,0,9,0,0,0,0,0,6,0,0
0,0,6,12,11,0,9,0,0,0,0,0,6,0,0
0,0,6,6,6,6,6,6,6,6,6,6,6,0,0
0,0,0,0,0,0,0,0,0,0,0,0,0,0,0
0,0,0,0,0,0,0,0,0,0,0,0,0,0,0
endlayer

layer
0,0,0,0,0,0,0,0,0,0,0,0,0,0,0
0,0,0,0,0,0,0,0,0,0,0,0,0,0,0
0,0,6,13,14,14,13,14,13,14,14,13,6,0,0
0,0,13,12,0,0,9,0,0,0,0,0,13,0,0
0,0,14,0,0,0,9,0,0,0,0,0,14,0,0
0,0,14,9,9,0,9,0,0,0,0,0,14,0,0
0,0,13,0,0,0,0,0,0,0,0,0,13,0,0
0,0,14,0,0,0,0,0,0,0,0,0,0,0,0
0,0,13,0,0,0,0,0,0,0,0,0,13,0,0
0,0,14,9,9,0,9,0,0,0,0,0,14,0,0
0,0,14,0,0,0,9,0,0,0,0,0,14,0,0
0,0,13,12,0,0,9,0,0,0,0,0,13,0,0
0,0,6,13,14,14,13,14,13,14,14,13,6,0,0
0,0,0,0,0,0,0,0,0,0,0,0,0,0,0
0,0,0,0,0,0,0,0,0,0,0,0,0,0,0
endlayer

layer
0,0,0,0,0,0,0,0,0,0,0,0,0,0,0
0,0,0,0,0,0,0,0,0,0,0,0,0,0,0
0,0,6,13,14,14,13,14,13,14,14,13,6,0,0
0,0,13,0,0,0,0,0,0,0,0,0,13,0,0
0,0,14,0,0,0,0,0,0,0,0,0,14,0,0
0,0,14,0,0,0,0,0,0,0,0,0,14,0,0
0,0,13,0,0,0,0,0,0,0,0,0,13,0,0
0,0,14,0,0,0,0,0,0,0,0,0,13,0,0
0,0,13,0,0,0,0,0,0,0,0,0,13,0,0
0,0,14,0,0,0,0,0,0,0,0,0,14,0,0
0,0,14,0,0,0,0,0,0,0,0,0,14,0,0
0,0,13,0,0,0,0,0,0,0,0,0,13,0,0
0,0,6,13,14,14,13,14,13,14,14,13,6,0,0
0,0,0,0,0,0,0,0,0,0,0,0,0,0,0
0,0,0,0,0,0,0,0,0,0,0,0,0,0,0
endlayer

layer
0,0,0,0,0,0,0,0,0,0,0,0,0,0,0
0,0,0,0,0,0,0,0,0,0,0,0,0,0,0
0,0,6,13,14,14,13,14,13,14,14,13,6,0,0
0,0,13,0,0,0,0,0,0,0,0,0,13,0,0
0,0,14,0,0,0,0,0,0,0,0,0,14,0,0
0,0,14,0,0,0,0,0,0,0,0,0,14,0,0
0,0,13,0,0,0,0,0,0,0,0,0,13,0,0
0,0,14,0,0,0,0,0,0,0,0,0,14,0,0
0,0,13,0,0,0,0,0,0,0,0,0,13,0,0
0,0,14,0,0,0,0,0,0,0,0,0,14,0,0
0,0,14,0,0,0,0,0,0,0,0,0,14,0,0
0,0,13,0,0,0,0,0,0,0,0,0,13,0,0
0,0,6,13,14,14,13,14,13,14,14,13,6,0,0
0,0,0,0,0,0,0,0,0,0,0,0,0,0,0
0,0,0,0,0,0,0,0,0,0,0,0,0,0,0
endlayer

layer
0,0,0,0,0,0,0,0,0,0,0,0,0,0,0
0,0,0,0,0,0,0,0,0,0,0,0,0,0,0
0,0,6,13,14,14,13,14,13,14,14,13,6,0,0
0,0,13,0,0,0,0,0,0,0,0,0,13,0,0
0,0,14,0,0,0,0,0,0,0,0,0,14,0,0
0,0,14,0,0,0,0,0,0,0,0,0,14,0,0
0,0,13,0,0,0,0,0,0,0,0,0,13,0,0
0,0,14,0,0,0,0,0,0,0,0,0,14,0,0
0,0,13,0,0,0,0,0,0,0,0,0,13,0,0
0,0,14,0,0,0,0,0,0,0,0,0,14,0,0
0,0,14,0,0,0,0,0,0,0,0,0,14,0,0
0,0,13,0,0,0,0,0,0,0,0,0,13,0,0
0,0,6,13,14,14,13,14,13,14,14,13,6,0,0
0,0,0,0,0,0,0,0,0,0,0,0,0,0,0
0,0,0,0,0,0,0,0,0,0,0,0,0,0,0
endlayer

layer
0,0,0,0,0,0,0,0,0,0,0,0,0,0,0
0,0,0,0,0,0,0,0,0,0,0,0,0,0,0
0,0,6,13,14,14,13,14,13,14,14,13,6,0,0
0,0,13,0,0,0,0,0,0,0,0,0,13,0,0
0,0,14,0,0,0,0,0,0,0,0,0,14,0,0
0,0,14,0,0,0,0,0,0,0,0,0,14,0,0
0,0,13,0,0,0,0,0,0,0,0,0,13,0,0
0,0,14,0,0,0,0,0,0,0,0,0,14,0,0
0,0,13,0,0,0,0,0,0,0,0,0,13,0,0
0,0,14,0,0,0,0,0,0,0,0,0,14,0,0
0,0,14,0,0,0,0,0,0,0,0,0,14,0,0
0,0,13,0,0,0,0,0,0,0,0,0,13,0,0
0,0,6,13,14,14,13,14,13,14,14,13,6,0,0
0,0,0,0,0,0,0,0,0,0,0,0,0,0,0
0,0,0,0,0,0,0,0,0,0,0,0,0,0,0
endlayer

layer
0,0,0,0,0,0,0,0,0,0,0,0,0,0,0
0,0,0,0,0,0,0,0,0,0,0,0,0,0,0
0,0,6,13,14,14,13,14,13,14,14,13,6,0,0
0,0,13,0,0,0,0,0,0,0,0,0,13,0,0
0,0,14,0,0,0,0,0,0,0,0,0,14,0,0
0,0,14,0,0,0,0,0,0,0,0,0,14,0,0
0,0,13,0,0,0,0,0,0,0,0,0,13,0,0
0,0,14,0,0,0,0,0,0,0,0,0,14,0,0
0,0,13,0,0,0,0,0,0,0,0,0,13,0,0
0,0,14,0,0,0,0,0,0,0,0,0,14,0,0
0,0,14,0,0,0,0,0,0,0,0,0,14,0,0
0,0,13,0,0,0,0,0,0,0,0,0,13,0,0
0,0,6,13,14,14,13,14,13,14,14,13,6,0,0
0,0,0,0,0,0,0,0,0,0,0,0,0,0,0
0,0,0,0,0,0,0,0,0,0,0,0,0,0,0
endlayer

layer
0,0,0,0,0,0,0,0,0,0,0,0,0,0,0
0,0,0,0,0,0,0,0,0,0,0,0,0,0,0
0,0,6,13,14,14,13,14,13,14,14,13,6,0,0
0,0,13,0,0,0,0,0,0,0,0,0,13,0,0
0,0,14,0,0,0,0,0,0,0,0,0,14,0,0
0,0,14,0,0,0,0,0,0,0,0,0,14,0,0
0,0,13,0,0,0,0,0,0,0,0,0,13,0,0
0,0,14,0,0,0,0,0,0,0,0,0,14,0,0
0,0,13,0,0,0,0,0,0,0,0,0,13,0,0
0,0,14,0,0,0,0,0,0,0,0,0,14,0,0
0,0,14,0,0,0,0,0,0,0,0,0,14,0,0
0,0,13,0,0,0,0,0,0,0,0,0,13,0,0
0,0,6,13,14,14,13,14,13,14,14,13,6,0,0
0,0,0,0,0,0,0,0,0,0,0,0,0,0,0
0,0,0,0,0,0,0,0,0,0,0,0,0,0,0
endlayer

layer
0,0,0,0,0,0,0,0,0,0,0,0,0,0,0
0,0,0,0,0,0,0,0,0,0,0,0,0,0,0
0,0,6,6,6,6,6,6,6,6,6,6,6,0,0
0,0,6,3,3,3,3,3,3,3,3,3,6,0,0
0,0,6,3,3,3,3,3,3,3,3,3,6,0,0
0,0,6,3,3,3,3,3,3,3,3,3,6,0,0
0,0,6,3,3,3,3,3,3,3,3,3,6,0,0
0,0,6,5,3,3,3,3,3,3,3,3,6,0,0
0,0,6,3,3,3,3,3,3,3,3,3,6,0,0
0,0,6,3,3,3,3,3,3,3,3,3,6,0,0
0,0,6,3,3,3,3,3,3,3,3,3,6,0,0
0,0,6,3,3,3,3,3,3,3,3,3,6,0,0
0,0,6,6,6,6,6,6,6,6,6,6,6,0,0
0,0,0,0,0,0,0,0,0,0,0,0,0,0,0
0,0,0,0,0,0,0,0,0,0,0,0,0,0,0
endlayer

layer
0,0,0,0,0,0,0,0,0,0,0,0,0,0,0
0,0,0,0,0,0,0,0,0,0,0,0,0,0,0
0,0,6,13,14,14,13,14,13,14,14,13,6,0,0
0,0,13,0,0,0,0,0,0,0,0,0,13,0,0
0,0,14,0,9,10,8,9,10,8,9,0,14,0,0
0,0,14,0,9,12,12,11,12,12,9,0,14,0,0
0,0,13,0,9,10,8,9,10,8,9,0,13,0,0
0,0,14,0,0,0,0,0,0,0,0,0,14,0,0
0,0,13,0,9,10,8,9,10,8,9,0,13,0,0
0,0,14,0,9,12,12,11,12,12,9,0,14,0,0
0,0,14,0,9,10,8,9,10,8,9,0,14,0,0
0,0,13,0,0,0,0,0,0,0,0,0,13,0,0
0,0,6,13,14,14,13,14,13,14,14,13,6,0,0
0,0,0,0,0,0,0,0,0,0,0,0,0,0,0
0,0,0,0,0,0,0,0,0,0,0,0,0,0,0
endlayer

layer
0,0,0,0,0,0,0,0,0,0,0,0,0,0,0
0,0,0,0,0,0,0,0,0,0,0,0,0,0,0
0,0,6,13,14,14,13,14,13,14,14,13,6,0,0
0,0,13,0,0,0,0,0,0,0,0,0,13,0,0
0,0,14,0,9,0,0,9,0,0,9,0,14,0,0
0,0,14,0,9,12,12,9,12,12,9,0,14,0,0
0,0,13,0,9,0,0,9,0,0,9,0,13,0,0
0,0,14,0,0,0,0,0,0,0,0,0,14,0,0
0,0,13,0,9,0,0,9,0,0,9,0,13,0,0
0,0,14,0,9,12,12,9,12,12,9,0,14,0,0
0,0,14,0,9,0,0,9,0,0,9,0,14,0,0
0,0,13,0,0,0,0,0,0,0,0,0,13,0,0
0,0,6,13,14,14,13,14,13,14,14,13,6,0,0
0,0,0,0,0,0,0,0,0,0,0,0,0,0,0
0,0,0,0,0,0,0,0,0,0,0,0,0,0,0
endlayer

layer
0,0,0,0,0,0,0,0,0,0,0,0,0,0,0
0,0,0,0,0,0,0,0,0,0,0,0,0,0,0
0,0,6,13,14,14,13,14,13,14,14,13,6,0,0
0,0,13,0,0,0,0,0,0,0,0,0,13,0,0
0,0,14,0,0,0,0,0,0,0,0,0,14,0,0
0,0,14,0,0,0,0,0,0,0,0,0,14,0,0
0,0,13,0,0,0,0,0,0,0,0,0,13,0,0
0,0,14,0,0,0,0,0,0,0,0,0,14,0,0
0,0,13,0,0,0,0,0,0,0,0,0,13,0,0
0,0,14,0,0,0,0,0,0,0,0,0,14,0,0
0,0,14,0,0,0,0,0,0,0,0,0,14,0,0
0,0,13,0,0,0,0,0,0,0,0,0,13,0,0
0,0,6,13,14,14,13,14,13,14,14,13,6,0,0
0,0,0,0,0,0,0,0,0,0,0,0,0,0,0
0,0,0,0,0,0,0,0,0,0,0,0,0,0,0
endlayer

layer
0,0,0,0,0,0,0,0,0,0,0,0,0,0,0
0,0,0,0,0,0,0,0,0,0,0,0,0,0,0
0,0,6,13,14,14,13,14,13,14,14,13,6,0,0
0,0,13,0,0,0,0,0,0,0,0,0,13,0,0
0,0,14,0,0,0,0,0,0,0,0,0,14,0,0
0,0,14,0,0,0,0,0,0,0,0,0,14,0,0
0,0,13,0,0,0,0,0,0,0,0,0,13,0,0
0,0,14,0,0,0,0,0,0,0,0,0,14,0,0
0,0,13,0,0,0,0,0,0,0,0,0,13,0,0
0,0,14,0,0,0,0,0,0,0,0,0,14,0,0
0,0,14,0,0,0,0,0,0,0,0,0,14,0,0
0,0,13,0,0,0,0,0,0,0,0,0,13,0,0
0,0,6,13,14,14,13,14,13,14,14,13,6,0,0
0,0,0,0,0,0,0,0,0,0,0,0,0,0,0
0,0,0,0,0,0,0,0,0,0,0,0,0,0,0
endlayer

layer
0,0,0,0,0,0,0,0,0,0,0,0,0,0,0
0,0,0,0,0,0,0,0,0,0,0,0,0,0,0
0,0,6,13,14,14,13,14,13,14,14,13,6,0,0
0,0,13,0,0,0,0,0,0,0,0,0,13,0,0
0,0,14,0,0,0,0,0,0,0,0,0,14,0,0
0,0,14,0,0,0,0,0,0,0,0,0,14,0,0
0,0,13,0,0,0,0,0,0,0,0,0,13,0,0
0,0,14,0,0,0,0,0,0,0,0,0,14,0,0
0,0,13,0,0,0,0,0,0,0,0,0,13,0,0
0,0,14,0,0,0,0,0,0,0,0,0,14,0,0
0,0,14,0,0,0,0,0,0,0,0,0,14,0,0
0,0,13,0,0,0,0,0,0,0,0,0,13,0,0
0,0,6,13,14,14,13,14,13,14,14,13,6,0,0
0,0,0,0,0,0,0,0,0,0,0,0,0,0,0
0,0,0,0,0,0,0,0,0,0,0,0,0,0,0
endlayer

layer
0,0,0,0,0,0,0,0,0,0,0,0,0,0,0
0,0,0,0,0,0,0,0,0,0,0,0,0,0,0
0,0,6,13,14,14,13,14,13,14,14,13,6,0,0
0,0,13,0,0,0,0,0,0,0,0,0,13,0,0
0,0,14,0,0,0,0,0,0,0,0,0,14,0,0
0,0,14,0,0,0,0,0,0,0,0,0,14,0,0
0,0,13,0,0,0,0,0,0,0,0,0,13,0,0
0,0,14,0,0,0,0,0,0,0,0,0,14,0,0
0,0,13,0,0,0,0,0,0,0,0,0,13,0,0
0,0,14,0,0,0,0,0,0,0,0,0,14,0,0
0,0,14,0,0,0,0,0,0,0,0,0,14,0,0
0,0,13,0,0,0,0,0,0,0,0,0,13,0,0
0,0,6,13,14,14,13,14,13,14,14,13,6,0,0
0,0,0,0,0,0,0,0,0,0,0,0,0,0,0
0,0,0,0,0,0,0,0,0,0,0,0,0,0,0
endlayer

layer
0,0,0,0,0,0,0,0,0,0,0,0,0,0,0
0,0,0,0,0,0,0,0,0,0,0,0,0,0,0
0,0,6,13,14,14,13,14,13,14,14,13,6,0,0
0,0,13,0,0,0,0,0,0,0,0,0,13,0,0
0,0,14,0,0,0,0,0,0,0,0,0,14,0,0
0,0,14,0,0,0,0,0,0,0,0,0,14,0,0
0,0,13,0,0,0,0,0,0,0,0,0,13,0,0
0,0,14,0,0,0,0,0,0,0,0,0,14,0,0
0,0,13,0,0,0,0,0,0,0,0,0,13,0,0
0,0,14,0,0,0,0,0,0,0,0,0,14,0,0
0,0,14,0,0,0,0,0,0,0,0,0,14,0,0
0,0,13,0,0,0,0,0,0,0,0,0,13,0,0
0,0,6,13,14,14,13,14,13,14,14,13,6,0,0
0,0,0,0,0,0,0,0,0,0,0,0,0,0,0
0,0,0,0,0,0,0,0,0,0,0,0,0,0,0
endlayer

layer
0,0,0,0,0,0,0,0,0,0,0,0,0,0,0
0,0,0,0,0,0,0,0,0,0,0,0,0,0,0
0,0,6,13,14,14,13,14,13,14,14,13,6,0,0
0,0,13,0,0,0,0,0,0,0,0,0,13,0,0
0,0,14,0,0,0,0,0,0,0,0,0,14,0,0
0,0,14,0,0,0,0,0,0,0,0,0,14,0,0
0,0,13,0,0,0,0,0,0,0,0,0,13,0,0
0,0,14,0,0,0,0,0,0,0,0,0,14,0,0
0,0,13,0,0,0,0,0,0,0,0,0,13,0,0
0,0,14,0,0,0,0,0,0,0,0,0,14,0,0
0,0,14,0,0,0,0,0,0,0,0,0,14,0,0
0,0,13,0,0,0,0,0,0,0,0,0,13,0,0
0,0,6,13,14,14,13,14,13,14,14,13,6,0,0
0,0,0,0,0,0,0,0,0,0,0,0,0,0,0
0,0,0,0,0,0,0,0,0,0,0,0,0,0,0
endlayer

layer
0,0,0,0,0,0,0,0,0,0,0,0,0,0,0
0,0,0,0,0,0,0,0,0,0,0,0,0,0,0
0,0,6,6,6,6,6,6,6,6,6,6,6,0,0
0,0,6,3,3,3,3,3,3,3,3,3,6,0,0
0,0,6,3,3,3,3,3,3,3,3,3,6,0,0
0,0,6,3,3,3,3,3,3,3,3,3,6,0,0
0,0,6,3,3,3,3,3,3,3,3,3,6,0,0
0,0,6,5,3,3,3,3,3,3,3,3,6,0,0
0,0,6,3,3,3,3,3,3,3,3,3,6,0,0
0,0,6,3,3,3,3,3,3,3,3,3,6,0,0
0,0,6,3,3,3,3,3,3,3,3,3,6,0,0
0,0,6,3,3,3,3,3,3,3,3,3,6,0,0
0,0,6,6,6,6,6,6,6,6,6,6,6,0,0
0,0,0,0,0,0,0,0,0,0,0,0,0,0,0
0,0,0,0,0,0,0,0,0,0,0,0,0,0,0
endlayer

layer
0,0,0,0,0,0,0,0,0,0,0,0,0,0,0
0,0,0,0,0,0,0,0,0,0,0,0,0,0,0
0,0,6,13,14,14,13,14,13,14,14,13,6,0,0
0,0,13,0,0,0,0,0,0,0,0,0,13,0,0
0,0,14,0,9,8,10,9,10,8,9,0,14,0,0
0,0,14,0,9,12,12,11,12,12,9,0,14,0,0
0,0,13,0,9,8,10,9,10,8,9,0,13,0,0
0,0,14,0,0,0,0,0,0,0,0,0,14,0,0
0,0,13,0,9,8,10,9,10,8,9,0,13,0,0
0,0,14,0,9,12,12,11,12,12,9,0,14,0,0
0,0,14,0,9,8,10,9,10,8,9,0,14,0,0
0,0,13,0,0,0,0,0,0,0,0,0,13,0,0
0,0,6,13,14,14,13,14,13,14,14,13,6,0,0
0,0,0,0,0,0,0,0,0,0,0,0,0,0,0
0,0,0,0,0,0,0,0,0,0,0,0,0,0,0
endlayer

layer
0,0,0,0,0,0,0,0,0,0,0,0,0,0,0
0,0,0,0,0,0,0,0,0,0,0,0,0,0,0
0,0,6,13,14,14,13,14,13,14,14,13,6,0,0
0,0,13,0,0,0,0,0,0,0,0,0,13,0,0
0,0,14,0,9,0,0,9,0,0,9,0,14,0,0
0,0,14,0,9,12,12,9,12,12,9,0,14,0,0
0,0,13,0,9,0,0,9,0,0,9,0,13,0,0
0,0,14,0,0,0,0,0,0,0,0,0,14,0,0
0,0,13,0,9,0,0,9,0,0,9,0,13,0,0
0,0,14,0,9,12,12,9,12,12,9,0,14,0,0
0,0,14,0,9,0,0,9,0,0,9,0,14,0,0
0,0,13,0,0,0,0,0,0,0,0,0,13,0,0
0,0,6,13,14,14,13,14,13,14,14,13,6,0,0
0,0,0,0,0,0,0,0,0,0,0,0,0,0,0
0,0,0,0,0,0,0,0,0,0,0,0,0,0,0
endlayer

layer
0,0,0,0,0,0,0,0,0,0,0,0,0,0,0
0,0,0,0,0,0,0,0,0,0,0,0,0,0,0
0,0,6,13,14,14,13,14,13,14,14,13,6,0,0
0,0,13,0,0,0,0,0,0,0,0,0,13,0,0
0,0,14,0,0,0,0,0,0,0,0,0,14,0,0
0,0,14,0,0,0,0,0,0,0,0,0,14,0,0
0,0,13,0,0,0,0,0,0,0,0,0,13,0,0
0,0,14,0,0,0,0,0,0,0,0,0,14,0,0
0,0,13,0,0,0,0,0,0,0,0,0,13,0,0
0,0,14,0,0,0,0,0,0,0,0,0,14,0,0
0,0,14,0,0,0,0,0,0,0,0,0,14,0,0
0,0,13,0,0,0,0,0,0,0,0,0,13,0,0
0,0,6,13,14,14,13,14,13,14,14,13,6,0,0
0,0,0,0,0,0,0,0,0,0,0,0,0,0,0
0,0,0,0,0,0,0,0,0,0,0,0,0,0,0
endlayer

layer
0,0,0,0,0,0,0,0,0,0,0,0,0,0,0
0,0,0,0,0,0,0,0,0,0,0,0,0,0,0
0,0,6,13,14,14,13,14,13,14,14,13,6,0,0
0,0,13,0,0,0,0,0,0,0,0,0,13,0,0
0,0,14,0,0,0,0,0,0,0,0,0,14,0,0
0,0,14,0,0,0,0,0,0,0,0,0,14,0,0
0,0,13,0,0,0,0,0,0,0,0,0,13,0,0
0,0,14,0,0,0,0,0,0,0,0,0,14,0,0
0,0,13,0,0,0,0,0,0,0,0,0,13,0,0
0,0,14,0,0,0,0,0,0,0,0,0,14,0,0
0,0,14,0,0,0,0,0,0,0,0,0,14,0,0
0,0,13,0,0,0,0,0,0,0,0,0,13,0,0
0,0,6,13,14,14,13,14,13,14,14,13,6,0,0
0,0,0,0,0,0,0,0,0,0,0,0,0,0,0
0,0,0,0,0,0,0,0,0,0,0,0,0,0,0
endlayer

layer
0,0,0,0,0,0,0,0,0,0,0,0,0,0,0
0,0,0,0,0,0,0,0,0,0,0,0,0,0,0
0,0,6,13,14,14,13,14,13,14,14,13,6,0,0
0,0,13,0,0,0,0,0,0,0,0,0,13,0,0
0,0,14,0,0,0,0,0,0,0,0,0,14,0,0
0,0,14,0,0,0,0,0,0,0,0,0,14,0,0
0,0,13,0,0,0,0,0,0,0,0,0,13,0,0
0,0,14,0,0,0,0,0,0,0,0,0,14,0,0
0,0,13,0,0,0,0,0,0,0,0,0,13,0,0
0,0,14,0,0,0,0,0,0,0,0,0,14,0,0
0,0,14,0,0,0,0,0,0,0,0,0,14,0,0
0,0,13,0,0,0,0,0,0,0,0,0,13,0,0
0,0,6,13,14,14,13,14,13,14,14,13,6,0,0
0,0,0,0,0,0,0,0,0,0,0,0,0,0,0
0,0,0,0,0,0,0,0,0,0,0,0,0,0,0
endlayer

layer
0,0,0,0,0,0,0,0,0,0,0,0,0,0,0
0,0,0,0,0,0,0,0,0,0,0,0,0,0,0
0,0,6,13,14,14,13,14,13,14,14,13,6,0,0
0,0,13,0,0,0,0,0,0,0,0,0,13,0,0
0,0,14,0,0,0,0,0,0,0,0,0,14,0,0
0,0,14,0,0,0,0,0,0,0,0,0,14,0,0
0,0,13,0,0,0,0,0,0,0,0,0,13,0,0
0,0,14,0,0,0,0,0,0,0,0,0,14,0,0
0,0,13,0,0,0,0,0,0,0,0,0,13,0,0
0,0,14,0,0,0,0,0,0,0,0,0,14,0,0
0,0,14,0,0,0,0,0,0,0,0,0,14,0,0
0,0,13,0,0,0,0,0,0,0,0,0,13,0,0
0,0,6,13,14,14,13,14,13,14,14,13,6,0,0
0,0,0,0,0,0,0,0,0,0,0,0,0,0,0
0,0,0,0,0,0,0,0,0,0,0,0,0,0,0
endlayer

layer
0,0,0,0,0,0,0,0,0,0,0,0,0,0,0
0,0,0,0,0,0,0,0,0,0,0,0,0,0,0
0,0,6,13,14,14,13,14,13,14,14,13,6,0,0
0,0,13,0,0,0,0,0,0,0,0,0,13,0,0
0,0,14,0,0,0,0,0,0,0,0,0,14,0,0
0,0,14,0,0,0,0,0,0,0,0,0,14,0,0
0,0,13,0,0,0,0,0,0,0,0,0,13,0,0
0,0,14,0,0,0,0,0,0,0,0,0,14,0,0
0,0,13,0,0,0,0,0,0,0,0,0,13,0,0
0,0,14,0,0,0,0,0,0,0,0,0,14,0,0
0,0,14,0,0,0,0,0,0,0,0,0,14,0,0
0,0,13,0,0,0,0,0,0,0,0,0,13,0,0
0,0,6,13,14,14,13,14,13,14,14,13,6,0,0
0,0,0,0,0,0,0,0,0,0,0,0,0,0,0
0,0,0,0,0,0,0,0,0,0,0,0,0,0,0
endlayer

layer
0,0,0,0,0,0,0,0,0,0,0,0,0,0,0
0,0,0,0,0,0,0,0,0,0,0,0,0,0,0
0,0,6,13,14,14,13,14,13,14,14,13,6,0,0
0,0,13,0,0,0,0,0,0,0,0,0,13,0,0
0,0,14,0,0,0,0,0,0,0,0,0,14,0,0
0,0,14,0,0,0,0,0,0,0,0,0,14,0,0
0,0,13,0,0,0,0,0,0,0,0,0,13,0,0
0,0,14,0,0,0,0,0,0,0,0,0,14,0,0
0,0,13,0,0,0,0,0,0,0,0,0,13,0,0
0,0,14,0,0,0,0,0,0,0,0,0,14,0,0
0,0,14,0,0,0,0,0,0,0,0,0,14,0,0
0,0,13,0,0,0,0,0,0,0,0,0,13,0,0
0,0,6,13,14,14,13,14,13,14,14,13,6,0,0
0,0,0,0,0,0,0,0,0,0,0,0,0,0,0
0,0,0,0,0,0,0,0,0,0,0,0,0,0,0
endlayer

layer
0,0,0,0,0,0,0,0,0,0,0,0,0,0,0
0,0,0,0,0,0,0,0,0,0,0,0,0,0,0
0,0,6,13,14,14,13,14,13,14,14,13,6,0,0
0,0,13,0,0,0,0,0,0,0,0,0,13,0,0
0,0,14,0,0,0,0,0,0,0,0,0,14,0,0
0,0,14,0,0,0,0,0,0,0,0,0,14,0,0
0,0,13,0,0,0,0,0,0,0,0,0,13,0,0
0,0,14,0,0,0,0,0,0,0,0,0,14,0,0
0,0,13,0,0,0,0,0,0,0,0,0,13,0,0
0,0,14,0,0,0,0,0,0,0,0,0,14,0,0
0,0,14,0,0,0,0,0,0,0,0,0,14,0,0
0,0,13,0,0,0,0,0,0,0,0,0,13,0,0
0,0,6,13,14,14,13,14,13,14,14,13,6,0,0
0,0,0,0,0,0,0,0,0,0,0,0,0,0,0
0,0,0,0,0,0,0,0,0,0,0,0,0,0,0
endlayer

layer
0,0,0,0,0,0,0,0,0,0,0,0,0,0,0
0,0,0,0,0,0,0,0,0,0,0,0,0,0,0
0,0,6,6,6,6,6,6,6,6,6,6,6,0,0
0,0,6,15,15,15,15,15,15,15,15,15,6,0,0
0,0,6,15,15,15,15,15,15,15,15,15,6,0,0
0,0,6,15,15,15,15,15,15,15,15,15,6,0,0
0,0,6,15,15,15,15,15,15,15,15,15,6,0,0
0,0,6,15,15,15,15,15,15,15,15,15,6,0,0
0,0,6,15,15,15,15,15,15,15,15,15,6,0,0
0,0,6,15,15,15,15,15,15,15,15,15,6,0,0
0,0,6,15,15,15,15,15,15,15,15,15,6,0,0
0,0,6,15,15,15,15,15,15,15,15,15,6,0,0
0,0,6,6,6,6,6,6,6,6,6,6,6,0,0
0,0,0,0,0,0,0,0,0,0,0,0,0,0,0
0,0,0,0,0,0,0,0,0,0,0,0,0,0,0
endlayer

