weight=0
embed_into_distance=1
dimensions=16,11,11
max_cut_in=0

rule1=0,100,250
rule2=2,95,2843-4
rule3=0,100,2843-14,2843-14,2843-14,2843-14,2843
rule4=0,100,159-14
rule5=0,95,2835-2,2835-2,2835-2,2835-2,2835-2,2835-2,2835-2,2835-1,2835-1,2835-0
rule6=2,75,3225-3
rule7=0,100,159-12
rule8=0,95,2781-4,2781-4,2781-4,2781-4,2781-8


layer
1,1,1,1,1,1,1,1,1,1,1
1,2,2,2,2,2,2,2,2,2,1
1,2,2,2,2,2,2,2,2,2,1
1,2,2,2,2,2,2,2,2,2,1
1,2,2,2,2,2,2,2,2,2,1
1,2,2,2,2,2,2,2,2,2,1
1,2,2,2,2,2,2,2,2,2,1
1,2,2,2,2,2,2,2,2,2,1
1,2,2,2,2,2,2,2,2,2,1
1,2,2,2,2,2,2,2,2,2,1
1,1,1,1,1,2,1,1,1,1,1
endlayer

layer
3,3,3,3,3,3,3,3,3,3,3
3,0,0,0,0,0,0,0,0,0,3
3,0,0,0,0,0,0,0,0,0,3
3,0,0,0,0,0,0,0,0,0,3
3,0,0,0,0,0,0,0,0,0,3
3,0,0,0,0,4,0,0,0,2,3
3,0,0,0,0,0,0,0,0,0,3
3,0,0,0,0,0,0,0,0,0,3
3,0,0,0,0,0,0,0,0,0,3
3,0,0,0,0,0,0,0,0,0,3
3,3,3,3,3,0,3,3,3,3,3
endlayer

layer
3,5,6,6,5,6,5,6,6,5,3
5,0,0,0,0,0,0,0,0,0,5
6,0,0,0,0,0,0,0,0,0,6
6,0,0,0,0,0,0,0,0,0,6
5,0,0,0,0,0,0,0,0,2,5
6,0,0,0,0,0,0,0,0,0,6
5,0,0,0,0,0,0,0,0,0,5
6,0,0,0,0,0,0,0,0,0,6
6,0,0,0,0,0,0,0,0,0,6
5,0,0,0,0,0,0,0,0,0,5
3,5,6,6,5,0,5,6,6,5,3
endlayer

layer
3,5,6,6,5,6,5,6,6,5,3
5,0,0,0,0,0,0,0,0,0,5
6,0,0,0,0,0,0,0,0,0,6
6,0,0,0,0,0,0,0,0,2,6
5,0,0,0,0,0,0,0,0,0,5
6,0,0,0,0,0,0,0,0,0,6
5,0,0,0,0,0,0,0,0,0,5
6,0,0,0,0,0,0,0,0,0,6
6,0,0,0,0,0,0,0,0,0,6
5,0,0,0,0,0,0,0,0,0,5
3,5,6,6,5,5,5,6,6,5,3
endlayer

layer
3,5,6,6,5,6,5,6,6,5,3
5,0,0,0,0,0,0,0,0,0,5
6,0,0,0,0,0,0,0,0,2,6
6,0,0,0,0,0,0,0,0,0,6
5,0,0,0,0,0,0,0,0,0,5
6,0,0,0,0,0,0,0,0,0,6
5,0,0,0,0,0,0,0,0,0,5
6,0,0,0,0,0,0,0,0,0,6
6,0,0,0,0,0,0,0,0,0,6
5,0,0,0,0,0,0,0,0,0,5
3,5,6,6,5,6,5,6,6,5,3
endlayer

layer
3,5,6,6,5,6,5,6,6,5,3
5,0,0,0,0,0,0,0,0,2,5
6,0,0,0,0,0,0,0,0,0,6
6,0,0,0,0,0,0,0,0,0,6
5,0,0,0,0,0,0,0,0,0,5
6,0,0,0,0,0,0,0,0,0,6
5,0,0,0,0,0,0,0,0,0,5
6,0,0,0,0,0,0,0,0,0,6
6,0,0,0,0,0,0,0,0,0,6
5,0,0,0,0,0,0,0,0,0,5
3,5,6,6,5,6,5,6,6,5,3
endlayer

layer
3,5,6,6,5,6,5,6,6,5,3
5,0,0,0,0,0,0,0,2,0,5
6,0,0,0,0,0,0,0,0,0,6
6,0,0,0,0,0,0,0,0,0,6
5,0,0,0,0,0,0,0,0,0,5
6,0,0,0,0,0,0,0,0,0,6
5,0,0,0,0,0,0,0,0,0,5
6,0,0,0,0,0,0,0,0,0,6
6,0,0,0,0,0,0,0,0,0,6
5,0,0,0,0,0,0,0,0,0,5
3,5,6,6,5,6,5,6,6,5,3
endlayer

layer
3,5,6,6,5,6,5,6,6,5,3
5,0,0,0,0,0,0,2,0,0,5
6,0,0,0,0,0,0,0,0,0,6
6,0,0,0,0,0,0,0,0,0,6
5,0,0,0,0,0,0,0,0,0,5
6,0,0,0,0,0,0,0,0,0,6
5,0,0,0,0,0,0,0,0,0,5
6,0,0,0,0,0,0,0,0,0,6
6,0,0,0,0,0,0,0,0,0,6
5,0,0,0,0,0,0,0,0,0,5
3,5,6,6,5,6,5,6,6,5,3
endlayer

layer
3,5,6,6,5,6,5,6,6,5,3
5,0,0,0,0,0,2,0,0,0,5
6,0,0,0,0,0,0,0,0,0,6
6,0,0,0,0,0,0,0,0,0,6
5,0,0,0,0,0,0,0,0,0,5
6,0,0,0,0,0,0,0,0,0,6
5,0,0,0,0,0,0,0,0,0,5
6,0,0,0,0,0,0,0,0,0,6
6,0,0,0,0,0,0,0,0,0,6
5,0,0,0,0,0,0,0,0,0,5
3,5,6,6,5,6,5,6,6,5,3
endlayer

layer
3,3,3,3,3,3,3,3,3,3,3
3,2,2,2,2,2,0,0,0,0,3
3,2,2,2,2,2,2,2,2,2,3
3,2,2,2,2,2,2,2,2,2,3
3,2,2,2,2,2,2,2,2,2,3
3,2,2,2,2,2,2,2,2,2,3
3,2,2,2,2,2,2,2,2,2,3
3,2,2,2,2,2,2,2,2,2,3
3,2,2,2,2,2,2,2,2,2,3
3,2,2,2,2,2,2,2,2,2,3
3,3,3,3,3,3,3,3,3,3,3
endlayer

layer
3,5,6,6,5,6,5,6,6,5,3
5,0,0,0,0,0,0,0,0,0,5
6,0,0,0,0,0,0,0,0,0,6
6,0,0,0,0,0,0,0,0,0,6
5,0,0,0,0,0,0,0,0,0,5
6,0,0,0,0,4,0,0,0,0,6
5,0,0,0,0,0,0,0,0,0,5
6,0,0,0,0,0,0,0,0,0,6
6,0,0,0,0,0,0,0,0,0,6
5,0,0,0,0,7,0,0,0,0,5
3,5,6,6,5,6,5,6,6,5,3
endlayer

layer
3,5,6,6,5,6,5,6,6,5,3
5,0,0,0,0,0,0,0,0,0,5
6,0,0,0,0,0,0,0,0,0,6
6,0,0,0,0,0,0,0,0,0,6
5,0,0,0,0,0,0,0,0,0,5
6,0,0,0,0,0,0,0,0,0,6
5,0,0,0,0,0,0,0,0,0,5
6,0,0,0,0,0,0,0,0,0,6
6,0,0,0,0,0,0,0,0,0,6
5,0,0,0,0,0,0,0,0,0,5
3,5,6,6,5,6,5,6,6,5,3
endlayer

layer
3,5,6,6,5,6,5,6,6,5,3
5,0,0,0,0,0,0,0,0,0,5
6,0,0,0,0,0,0,0,0,0,6
6,0,0,0,0,0,0,0,0,0,6
5,0,0,0,0,0,0,0,0,0,5
6,0,0,0,0,0,0,0,0,0,6
5,0,0,0,0,0,0,0,0,0,5
6,0,0,0,0,0,0,0,0,0,6
6,0,0,0,0,0,0,0,0,0,6
5,0,0,0,0,0,0,0,0,0,5
3,5,6,6,5,6,5,6,6,5,3
endlayer

layer
3,5,6,6,5,6,5,6,6,5,3
5,0,0,0,0,0,0,0,0,0,5
6,0,0,0,0,0,0,0,0,0,6
6,0,0,0,0,0,0,0,0,0,6
5,0,0,0,0,0,0,0,0,0,5
6,0,0,0,0,0,0,0,0,0,6
5,0,0,0,0,0,0,0,0,0,5
6,0,0,0,0,0,0,0,0,0,6
6,0,0,0,0,0,0,0,0,0,6
5,0,0,0,0,0,0,0,0,0,5
3,5,6,6,5,6,5,6,6,5,3
endlayer

layer
3,5,6,6,5,6,5,6,6,5,3
5,0,0,0,0,0,0,0,0,0,5
6,0,0,0,0,0,0,0,0,0,6
6,0,0,0,0,0,0,0,0,0,6
5,0,0,0,0,0,0,0,0,0,5
6,0,0,0,0,0,0,0,0,0,6
5,0,0,0,0,0,0,0,0,0,5
6,0,0,0,0,0,0,0,0,0,6
6,0,0,0,0,0,0,0,0,0,6
5,0,0,0,0,0,0,0,0,0,5
3,5,6,6,5,6,5,6,6,5,3
endlayer

layer
3,3,3,3,3,3,3,3,3,3,3
3,8,8,8,8,8,8,8,8,8,3
3,8,8,8,8,8,8,8,8,8,3
3,8,8,8,8,8,8,8,8,8,3
3,8,8,8,8,8,8,8,8,8,3
3,8,8,8,8,8,8,8,8,8,3
3,8,8,8,8,8,8,8,8,8,3
3,8,8,8,8,8,8,8,8,8,3
3,8,8,8,8,8,8,8,8,8,3
3,8,8,8,8,8,8,8,8,8,3
3,3,3,3,3,3,3,3,3,3,3
endlayer



