# Converted from schematic
# THIS TEMPLATE USES DEFAULTS!  Please edit for corrections.
# If you need help, consult template_rules.txt

weight=3
embed_into_distance=11
acceptable_target_blocks=1,2,3,12,13,250
dimensions=11,25,19
allowable_overhang=0


rule1=0,100,3134-10
rule2=0,100,300
rule3=0,100,2843-4
rule4=0,100,308,308,308,308,308,308,313,313,314,327
rule5=0,100,2843-14,2843-14,2843-14,2843-14,2843
rule6=0,25,3225-3
rule7=0,100,2843-10
rule8=0,100,2249
rule9=0,100,4094-4
rule10=0,100,2252-2
rule11=0,100,2254-2
rule12=0,100,54,54,54,54,54,54,54,54,54,54,54,54,54,54,54,54,54,311,311,311,311,311,309,310
rule13=0,95,2835-2,2835-2,2835-2,2835-2,2835-2,2835-2,2835-2,2835-1,2835-1,2835-0
rule14=0,100,2255-6
rule15=0,100,3134,3134,3134,3134-8,3134-2
rule16=0,100,113
rule17=0,100,2843-12
rule18=0,100,2838-13
rule19=0,95,300


layer
1,1,1,1,1,1,1,1,1,1,1,1,1,1,1,1,1,1,1
1,1,1,1,1,1,1,1,1,1,1,1,1,1,1,1,1,1,1
1,1,3,3,3,3,3,3,3,3,3,3,3,3,3,2,2,1,1
1,1,3,3,3,3,3,3,3,3,3,3,3,3,3,2,2,1,1
1,1,3,3,3,3,3,3,3,3,3,3,4,3,3,2,2,1,1
1,1,3,3,3,3,3,3,3,3,3,3,3,3,3,2,2,1,1
1,1,3,3,3,3,3,3,3,3,3,3,3,3,3,2,2,1,1
1,1,3,3,3,3,3,3,3,3,3,3,3,3,3,2,2,1,1
1,1,3,3,3,3,3,3,3,3,3,3,3,3,3,2,2,1,1
1,1,3,3,3,3,3,3,3,3,3,3,3,3,3,2,2,1,1
1,1,3,3,3,3,3,3,3,3,3,3,3,3,3,3,3,1,1
1,1,3,3,3,3,4,3,3,3,3,3,3,3,3,3,3,1,1
1,1,3,3,3,3,3,3,3,3,3,3,3,3,3,3,3,1,1
1,1,3,3,3,3,3,3,3,3,3,3,3,3,3,3,3,1,1
1,1,3,3,3,3,3,3,3,3,3,3,3,3,3,3,3,1,1
1,1,3,3,3,3,3,3,3,3,3,3,3,3,3,2,2,1,1
1,1,3,3,3,3,3,3,3,3,3,3,4,3,3,2,2,1,1
1,1,3,3,3,3,3,3,3,3,3,3,3,3,3,2,2,1,1
1,1,3,3,3,3,3,3,3,3,3,3,3,3,3,2,2,1,1
1,1,3,3,3,3,3,3,3,3,3,3,3,3,3,2,2,1,1
1,1,3,3,3,3,3,3,3,3,3,3,3,3,3,2,2,1,1
1,1,3,3,3,3,3,3,3,3,3,3,3,3,3,2,2,1,1
1,1,3,3,3,3,3,3,3,3,3,3,3,3,3,2,2,1,1
1,1,1,1,1,1,1,1,1,1,1,1,1,1,1,1,1,1,1
1,1,1,1,1,1,1,1,1,1,1,1,1,1,1,1,1,1,1
endlayer

layer
2,2,2,2,2,2,2,2,2,2,2,2,2,2,2,2,2,2,2
2,2,2,2,2,2,2,2,2,2,2,2,2,2,2,2,2,2,2
2,2,5,5,5,5,5,5,5,5,5,5,5,5,5,2,2,2,2
2,2,5,0,0,0,0,0,0,0,0,0,0,0,5,2,2,2,2
2,2,5,0,0,8,0,8,0,8,0,0,7,7,5,2,2,2,2
2,2,5,0,0,0,0,0,0,0,0,0,7,7,5,2,2,2,2
2,2,5,0,0,0,0,0,0,0,0,0,7,7,5,2,2,2,2
2,2,5,0,0,8,0,8,0,8,0,0,7,7,5,2,2,2,2
2,2,5,12,0,0,0,0,0,0,0,0,7,7,5,2,2,2,2
2,2,5,0,0,0,0,0,0,0,0,0,0,0,5,2,2,2,2
2,2,5,12,0,0,0,0,0,0,0,0,2,0,5,5,5,2,2
2,2,5,0,0,0,9,9,9,9,0,0,2,2,2,2,6,2,2
2,2,5,12,0,0,0,0,0,9,0,0,2,2,2,2,2,2,2
2,2,5,0,0,0,9,9,9,9,0,0,2,2,2,2,6,2,2
2,2,5,12,0,0,0,0,0,0,0,2,0,0,5,5,5,2,2
2,2,5,0,0,0,0,0,0,0,0,0,0,0,5,2,2,2,2
2,2,5,12,0,0,0,0,0,0,0,0,7,7,5,2,2,2,2
2,2,5,0,0,0,0,0,0,0,0,0,7,7,5,2,2,2,2
2,2,5,0,0,10,0,10,0,10,0,0,7,7,5,2,2,2,2
2,2,5,0,0,0,0,0,0,0,0,0,7,7,5,2,2,2,2
2,2,5,0,0,11,0,11,0,11,0,0,7,7,5,2,2,2,2
2,2,5,0,0,0,0,0,0,0,0,0,0,0,5,2,2,2,2
2,2,5,5,5,5,5,5,5,5,5,5,5,5,5,2,2,2,2
2,2,2,2,2,2,2,2,2,2,2,2,2,2,2,2,2,2,2
2,2,2,2,2,2,2,2,2,2,2,2,2,2,2,2,2,2,2
endlayer

layer
2,2,2,2,2,2,2,2,2,2,2,2,2,2,2,2,2,2,2
2,2,2,2,2,2,2,2,2,2,2,2,2,2,2,2,2,2,2
2,2,5,13,6,6,13,6,6,6,13,6,6,13,5,2,2,2,2
2,2,13,0,0,0,0,0,0,0,0,0,0,0,13,2,2,2,2
2,2,13,0,0,0,0,0,0,0,0,0,0,0,6,2,2,2,2
2,2,13,0,0,0,0,0,0,0,0,0,0,8,6,2,2,2,2
2,2,13,0,0,0,0,0,0,0,0,0,0,0,6,2,2,2,2
2,2,13,0,0,0,0,0,0,0,0,0,0,8,6,2,2,2,2
2,2,13,12,0,0,0,0,0,0,0,0,0,0,6,2,2,2,2
2,2,13,0,0,0,0,0,0,0,0,0,0,0,13,2,2,2,2
2,2,13,12,0,0,0,0,0,0,0,0,0,0,5,13,5,2,2
2,2,13,0,0,0,14,0,0,0,0,0,0,0,0,0,6,2,2
2,2,13,12,0,0,0,0,0,0,0,0,0,0,0,0,2,2,2
2,2,13,0,0,0,14,0,0,0,0,0,0,0,0,0,6,2,2
2,2,13,12,0,0,0,0,0,0,0,0,0,0,5,13,5,2,2
2,2,13,0,0,0,0,0,0,0,0,0,0,0,13,2,2,2,2
2,2,13,12,0,0,0,0,0,0,0,0,0,0,6,2,2,2,2
2,2,13,0,0,0,0,0,0,0,0,0,0,8,6,2,2,2,2
2,2,13,0,0,10,0,10,0,10,0,0,0,0,6,2,2,2,2
2,2,13,0,0,0,0,0,0,0,0,0,0,8,6,2,2,2,2
2,2,13,0,0,11,0,11,0,11,0,0,0,0,6,2,2,2,2
2,2,13,0,0,0,0,0,0,0,0,0,0,0,13,2,2,2,2
2,2,5,13,6,6,13,6,6,6,13,6,6,13,5,2,2,2,2
2,2,2,2,2,2,2,2,2,2,2,2,2,2,2,2,2,2,2
2,2,2,2,2,2,2,2,2,2,2,2,2,2,2,2,2,2,2
endlayer

layer
2,2,2,2,2,2,2,2,2,2,2,2,2,2,2,2,2,2,2
2,2,2,2,2,2,2,2,2,2,2,2,2,2,2,2,2,2,2
2,2,5,13,6,6,13,6,6,6,13,6,6,13,5,2,2,2,2
2,2,13,0,0,0,0,0,0,0,0,0,0,0,13,2,2,2,2
2,2,13,0,0,0,0,0,0,0,0,0,0,0,6,2,2,2,2
2,2,13,0,0,0,0,0,0,0,0,0,0,0,6,2,2,2,2
2,2,13,0,0,0,0,0,0,0,0,0,0,0,6,2,2,2,2
2,2,13,0,0,0,0,0,0,0,0,0,0,0,6,2,2,2,2
2,2,13,12,0,0,0,0,0,0,0,0,0,0,6,2,2,2,2
2,2,13,0,0,0,0,0,0,0,0,0,0,0,13,2,2,2,2
2,2,13,12,0,0,0,0,0,0,0,0,0,0,5,13,5,2,2
2,2,13,0,0,0,0,0,0,0,0,0,0,0,0,0,6,2,2
2,2,13,12,0,0,0,0,0,0,0,0,0,0,0,0,6,2,2
2,2,13,0,0,0,0,0,0,0,0,0,0,0,0,0,6,2,2
2,2,13,12,0,0,0,0,0,0,0,0,0,0,5,13,5,2,2
2,2,13,0,0,0,0,0,0,0,0,0,0,0,13,2,2,2,2
2,2,13,12,0,0,0,0,0,0,0,0,0,0,6,2,2,2,2
2,2,13,0,0,0,0,0,0,0,0,0,0,0,6,2,2,2,2
2,2,13,0,0,10,0,10,0,10,0,0,0,0,6,2,2,2,2
2,2,13,0,0,0,0,0,0,0,0,0,0,0,6,2,2,2,2
2,2,13,0,0,11,0,11,0,11,0,0,0,0,6,2,2,2,2
2,2,13,0,0,0,0,0,0,0,0,0,0,0,13,2,2,2,2
2,2,5,13,6,6,13,6,6,6,13,6,6,13,5,2,2,2,2
2,2,2,2,2,2,2,2,2,2,2,2,2,2,2,2,2,2,2
2,2,2,2,2,2,2,2,2,2,2,2,2,2,2,2,2,2,2
endlayer

layer
2,2,2,2,2,2,2,2,2,2,2,2,2,2,2,2,2,2,2
2,2,2,2,2,2,2,2,2,2,2,2,2,2,2,2,2,2,2
2,2,5,13,6,6,13,6,6,6,13,6,6,13,5,2,2,2,2
2,2,13,0,0,0,0,0,0,0,0,0,0,0,13,2,2,2,2
2,2,13,0,0,0,0,0,0,0,0,0,0,0,6,2,2,2,2
2,2,13,0,0,0,0,0,0,0,0,0,0,0,6,2,2,2,2
2,2,13,0,0,0,0,0,0,0,0,0,0,0,6,2,2,2,2
2,2,13,0,0,0,0,0,0,0,0,0,0,0,6,2,2,2,2
2,2,13,0,0,0,0,0,0,0,0,0,0,0,6,2,2,2,2
2,2,13,0,0,0,0,0,0,0,0,0,0,0,13,2,2,2,2
2,2,13,0,0,0,0,0,0,0,0,0,0,0,5,13,5,2,2
2,2,13,0,0,0,0,0,0,0,0,0,0,0,0,0,6,2,2
2,2,13,0,0,0,0,0,0,0,0,0,0,0,0,0,6,2,2
2,2,13,0,0,0,0,0,0,0,0,0,0,0,0,0,6,2,2
2,2,13,0,0,0,0,0,0,0,0,0,0,0,5,13,5,2,2
2,2,13,0,0,0,0,0,0,0,0,0,0,0,13,2,2,2,2
2,2,13,0,0,0,0,0,0,0,0,0,0,0,6,2,2,2,2
2,2,13,0,0,0,0,0,0,0,0,0,0,0,6,2,2,2,2
2,2,13,0,0,0,0,0,0,0,0,0,0,0,6,2,2,2,2
2,2,13,0,0,0,0,0,0,0,0,0,0,0,6,2,2,2,2
2,2,13,0,0,0,0,0,0,0,0,0,0,0,6,2,2,2,2
2,2,13,0,0,0,0,0,0,0,0,0,0,0,13,2,2,2,2
2,2,5,13,6,6,13,6,6,6,13,6,6,13,5,2,2,2,2
2,2,2,2,2,2,2,2,2,2,2,2,2,2,2,2,2,2,2
2,2,2,2,2,2,2,2,2,2,2,2,2,2,2,2,2,2,2
endlayer

layer
2,2,2,2,2,2,2,2,2,2,2,2,2,2,2,2,2,2,2
2,2,2,2,2,2,2,2,2,2,2,2,2,2,2,2,2,2,2
2,2,5,13,6,6,13,6,6,6,13,6,6,13,5,2,2,2,2
2,2,13,0,0,0,0,0,0,0,0,0,0,0,13,2,2,2,2
2,2,13,0,0,0,0,0,0,0,0,0,0,0,6,2,2,2,2
2,2,13,0,0,0,0,0,0,0,0,0,0,0,6,2,2,2,2
2,2,13,0,0,0,0,0,0,0,0,0,0,0,6,2,2,2,2
2,2,13,0,0,0,0,0,0,0,0,0,0,0,6,2,2,2,2
2,2,13,0,0,0,0,0,0,0,0,0,0,0,6,2,2,2,2
2,2,13,0,0,0,0,0,0,0,0,0,0,0,13,2,2,2,2
2,2,13,0,0,0,0,0,0,0,0,0,0,0,5,13,5,2,2
2,2,13,0,0,0,0,0,0,0,0,0,0,0,0,0,6,2,2
2,2,13,0,0,0,0,0,0,0,0,0,0,0,0,0,6,2,2
2,2,13,0,0,0,0,0,0,0,0,0,0,0,0,0,6,2,2
2,2,13,0,0,0,0,0,0,0,0,0,0,0,5,13,5,2,2
2,2,13,0,0,0,0,0,0,0,0,0,0,0,13,2,2,2,2
2,2,13,0,0,0,0,0,0,0,0,0,0,0,6,2,2,2,2
2,2,13,0,0,0,0,0,0,0,0,0,0,0,6,2,2,2,2
2,2,13,0,0,0,0,0,0,0,0,0,0,0,6,2,2,2,2
2,2,13,0,0,0,0,0,0,0,0,0,0,0,6,2,2,2,2
2,2,13,0,0,0,0,0,0,0,0,0,0,0,6,2,2,2,2
2,2,13,0,0,0,0,0,0,0,0,0,0,0,13,2,2,2,2
2,2,5,13,6,6,13,6,6,6,13,6,6,13,5,2,2,2,2
2,2,2,2,2,2,2,2,2,2,2,2,2,2,2,2,2,2,2
2,2,2,2,2,2,2,2,2,2,2,2,2,2,2,2,2,2,2
endlayer

layer
2,2,2,2,2,2,2,2,2,2,2,2,2,2,2,2,2,2,2
2,2,2,2,2,2,2,2,2,2,2,2,2,2,2,2,2,2,2
2,2,5,5,5,5,5,5,5,5,5,5,5,5,5,2,2,2,2
2,2,5,15,15,15,15,15,15,15,15,15,15,15,5,2,2,2,2
2,2,5,15,15,15,15,15,15,15,15,15,15,15,5,2,2,2,2
2,2,5,15,15,15,15,15,15,15,15,15,15,15,5,2,2,2,2
2,2,5,15,15,15,15,15,15,15,15,15,15,15,5,2,2,2,2
2,2,5,15,15,15,15,15,15,15,15,15,15,15,5,2,2,2,2
2,2,5,15,15,15,15,15,15,15,15,15,15,15,5,2,2,2,2
2,2,5,15,15,15,15,15,15,15,15,15,15,15,5,2,2,2,2
2,2,5,15,15,15,15,15,15,15,15,15,15,15,5,5,5,2,2
2,2,5,15,15,15,15,15,15,15,15,15,15,15,15,15,5,2,2
2,2,5,15,15,15,15,15,15,15,15,15,15,15,15,15,5,2,2
2,2,5,15,15,15,15,15,15,15,15,15,15,15,15,15,5,2,2
2,2,5,15,15,15,15,15,15,15,15,15,15,15,5,5,5,2,2
2,2,5,15,15,15,15,15,15,15,15,15,15,15,5,2,2,2,2
2,2,5,15,15,15,15,15,15,15,15,15,15,15,5,2,2,2,2
2,2,5,15,15,15,15,15,15,15,15,15,15,15,5,2,2,2,2
2,2,5,15,15,15,15,15,15,15,15,15,15,15,5,2,2,2,2
2,2,5,15,15,15,15,15,15,15,15,15,15,15,5,2,2,2,2
2,2,5,15,15,15,15,15,15,15,15,15,15,15,5,2,2,2,2
2,2,5,15,15,15,15,15,15,15,15,15,15,15,5,2,2,2,2
2,2,5,5,5,5,5,5,5,5,5,5,5,5,5,2,2,2,2
2,2,2,2,2,2,2,2,2,2,2,2,2,2,2,2,2,2,2
2,2,2,2,2,2,2,2,2,2,2,2,2,2,2,2,2,2,2
endlayer

layer
2,2,2,2,2,2,2,2,2,2,2,2,2,2,2,2,2,2,2
2,2,2,2,2,2,2,2,2,2,2,2,2,2,2,2,2,2,2
2,2,2,2,2,2,2,2,2,2,2,2,2,2,2,2,2,2,2
2,2,2,2,2,2,2,2,2,2,2,2,2,2,2,2,2,2,2
2,2,2,2,2,2,2,2,2,2,2,2,2,2,2,2,2,2,2
2,2,2,2,2,2,2,2,2,2,2,2,2,2,2,2,2,2,2
2,2,2,2,2,2,2,2,2,2,2,2,2,2,2,2,2,2,2
2,2,2,2,2,2,2,2,2,2,2,2,2,2,2,2,2,2,2
2,2,2,2,2,2,2,2,2,2,2,2,2,2,2,2,2,2,2
2,2,2,2,2,2,2,2,2,2,2,2,2,2,2,2,2,2,2
2,2,2,2,2,2,2,2,2,2,2,2,2,16,2,2,2,2,2
2,2,2,2,2,2,2,2,2,2,2,2,2,2,2,2,2,2,2
2,2,2,2,2,2,2,2,2,2,2,2,2,2,2,2,2,2,2
2,2,2,2,2,2,2,2,2,2,2,2,2,2,2,2,2,2,2
2,2,2,2,2,2,2,2,2,2,2,2,2,16,2,2,2,2,2
2,2,2,2,2,2,2,2,2,2,2,2,2,2,2,2,2,2,2
2,2,2,2,2,2,2,2,2,2,2,2,2,2,2,2,2,2,2
2,2,2,2,2,2,2,2,2,2,2,2,2,2,2,2,2,2,2
2,2,2,2,2,2,2,2,2,2,2,2,2,2,2,2,2,2,2
2,2,2,2,2,2,2,2,2,2,2,2,2,2,2,2,2,2,2
2,2,2,2,2,2,2,2,2,2,2,2,2,2,2,2,2,2,2
2,2,2,2,2,2,2,2,2,2,2,2,2,2,2,2,2,2,2
2,2,2,2,2,2,2,2,2,2,2,2,2,2,2,2,2,2,2
2,2,2,2,2,2,2,2,2,2,2,2,2,2,2,2,2,2,2
2,2,2,2,2,2,2,2,2,2,2,2,2,2,2,2,2,2,2
endlayer

layer
2,2,2,2,2,2,2,2,2,2,2,2,2,2,2,2,2,2,2
2,2,2,2,2,2,2,2,2,2,2,2,2,2,2,2,2,2,2
2,2,2,2,2,2,2,2,2,2,2,2,2,2,2,2,2,2,2
2,2,2,2,2,2,2,2,2,2,2,2,2,2,2,2,2,2,2
2,2,2,2,2,2,2,2,2,2,2,2,2,2,2,2,2,2,2
2,2,2,2,2,2,2,2,2,2,2,2,2,2,2,2,2,2,2
2,2,2,2,2,2,2,2,2,2,2,2,2,2,2,2,2,2,2
2,2,2,2,2,2,2,2,2,2,2,2,2,2,2,2,2,2,2
2,2,2,2,2,2,2,2,2,2,2,2,2,2,2,2,2,2,2
2,2,2,2,2,2,2,2,2,2,2,2,2,2,2,2,2,2,2
2,2,2,2,2,2,2,2,2,2,2,2,2,17,2,2,2,2,2
2,2,2,2,2,2,2,2,2,2,2,2,2,17,2,2,2,2,2
2,2,2,2,2,2,2,2,2,2,2,2,2,17,2,2,2,2,2
2,2,2,2,2,2,2,2,2,2,2,2,2,17,2,2,2,2,2
2,2,2,2,2,2,2,2,2,2,2,2,2,17,2,2,2,2,2
2,2,2,2,2,2,2,2,2,2,2,2,2,2,2,2,2,2,2
2,2,2,2,2,2,2,2,2,2,2,2,2,2,2,2,2,2,2
2,2,2,2,2,2,2,2,2,2,2,2,2,2,2,2,2,2,2
2,2,2,2,2,2,2,2,2,2,2,2,2,2,2,2,2,2,2
2,2,2,2,2,2,2,2,2,2,2,2,2,2,2,2,2,2,2
2,2,2,2,2,2,2,2,2,2,2,2,2,2,2,2,2,2,2
2,2,2,2,2,2,2,2,2,2,2,2,2,2,2,2,2,2,2
2,2,2,2,2,2,2,2,2,2,2,2,2,2,2,2,2,2,2
2,2,2,2,2,2,2,2,2,2,2,2,2,2,2,2,2,2,2
2,2,2,2,2,2,2,2,2,2,2,2,2,2,2,2,2,2,2
endlayer

layer
2,2,2,2,2,2,2,2,2,2,2,2,2,2,2,2,2,2,2
2,2,2,2,2,2,2,2,2,2,2,2,2,2,2,2,2,2,2
2,2,2,2,2,2,2,2,2,2,2,2,2,2,2,2,2,2,2
2,2,2,2,2,2,2,2,2,2,2,2,2,2,2,2,2,2,2
2,2,2,2,2,2,2,2,2,2,2,2,2,2,2,2,2,2,2
2,2,2,2,2,2,2,2,2,2,2,2,2,2,2,2,2,2,2
2,2,2,2,2,2,2,2,2,2,2,2,2,2,2,2,2,2,2
2,2,2,2,2,2,2,2,2,2,2,2,2,2,2,2,2,2,2
2,2,2,2,2,2,2,2,2,2,2,2,2,2,2,2,2,2,2
2,2,2,2,2,2,2,2,2,2,2,2,2,2,2,2,2,2,2
2,2,2,2,2,2,2,2,2,2,2,2,2,17,2,2,2,2,2
2,2,2,2,2,2,2,2,2,2,2,2,2,18,2,2,2,2,2
2,2,2,2,2,2,2,2,2,2,2,2,2,18,2,2,2,2,2
2,2,2,2,2,2,2,2,2,2,2,2,2,18,2,2,2,2,2
2,2,2,2,2,2,2,2,2,2,2,2,2,17,2,2,2,2,2
2,2,2,2,2,2,2,2,2,2,2,2,2,2,2,2,2,2,2
2,2,2,2,2,2,2,2,2,2,2,2,2,2,2,2,2,2,2
2,2,2,2,2,2,2,2,2,2,2,2,2,2,2,2,2,2,2
2,2,2,2,2,2,2,2,2,2,2,2,2,2,2,2,2,2,2
2,2,2,2,2,2,2,2,2,2,2,2,2,2,2,2,2,2,2
2,2,2,2,2,2,2,2,2,2,2,2,2,2,2,2,2,2,2
2,2,2,2,2,2,2,2,2,2,2,2,2,2,2,2,2,2,2
2,2,2,2,2,2,2,2,2,2,2,2,2,2,2,2,2,2,2
2,2,2,2,2,2,2,2,2,2,2,2,2,2,2,2,2,2,2
2,2,2,2,2,2,2,2,2,2,2,2,2,2,2,2,2,2,2
endlayer

layer
19,19,19,19,19,19,19,19,19,19,19,19,19,19,19,19,19,19,19
19,19,19,19,19,19,19,19,19,19,19,19,19,19,19,19,19,19,19
19,19,19,19,19,19,19,19,19,19,19,19,19,19,19,19,19,19,19
19,19,19,19,19,19,19,19,19,19,19,19,19,19,19,19,19,19,19
19,19,19,19,19,19,19,19,19,19,19,19,19,19,19,19,19,19,19
19,19,19,19,19,19,19,19,19,19,19,19,19,19,19,19,19,19,19
19,19,19,19,19,19,19,19,19,19,19,19,19,19,19,19,19,19,19
19,19,19,19,19,19,19,19,19,19,19,19,19,19,19,19,19,19,19
19,19,19,19,19,19,19,19,19,19,19,19,19,19,19,19,19,19,19
19,19,19,19,19,19,19,19,19,19,19,19,19,19,19,19,19,19,19
19,19,19,19,19,19,19,19,19,19,19,19,19,17,19,19,19,19,19
19,19,19,19,19,19,19,19,19,19,19,19,19,17,19,19,19,19,19
19,19,19,19,19,19,19,19,19,19,19,19,19,17,19,19,19,19,19
19,19,19,19,19,19,19,19,19,19,19,19,19,17,19,19,19,19,19
19,19,19,19,19,19,19,19,19,19,19,19,19,17,19,19,19,19,19
19,19,19,19,19,19,19,19,19,19,19,19,19,19,19,19,19,19,19
19,19,19,19,19,19,19,19,19,19,19,19,19,19,19,19,19,19,19
19,19,19,19,19,19,19,19,19,19,19,19,19,19,19,19,19,19,19
19,19,19,19,19,19,19,19,19,19,19,19,19,19,19,19,19,19,19
19,19,19,19,19,19,19,19,19,19,19,19,19,19,19,19,19,19,19
19,19,19,19,19,19,19,19,19,19,19,19,19,19,19,19,19,19,19
19,19,19,19,19,19,19,19,19,19,19,19,19,19,19,19,19,19,19
19,19,19,19,19,19,19,19,19,19,19,19,19,19,19,19,19,19,19
19,19,19,19,19,19,19,19,19,19,19,19,19,19,19,19,19,19,19
19,19,19,19,19,19,19,19,19,19,19,19,19,19,19,19,19,19,19
endlayer

