# Converted from schematic
# THIS TEMPLATE USES DEFAULTS!  Please edit for corrections.
# If you need help, consult template_rules.txt

weight=1
embed_into_distance=23
acceptable_target_blocks=1,2,3,12,13,250
dimensions=26,25,45
allowable_overhang=0
max_cut_in=2
cut_in_buffer=1
max_leveling=2
leveling_buffer=1
preserve_water=0
preserve_lava=0
preserve_plants=0


rule1=0,100,300
rule2=0,75,308,308,308,308,308,308,313,313,314,327
rule3=0,100,2799-4
rule4=0,66,311,311,311
rule5=0,100,2799-7,2798-4,2799-8
rule6=0,100,2799-6
rule7=0,100,2787-1
rule8=0,100,4
rule9=0,100,2843-14,2843-14,2843-14,2843-14,2843
rule10=0,100,66
rule11=0,95,2835-2,2835-2,2835-2,2835-2,2835-2,2835-2,2835-2,2835-1,2835-1,2835-0
rule12=0,100,2843-4
rule13=0,100,2835-12
rule14=0,100,44
rule15=0,100,113
rule16=0,100,3134-10
rule17=0,100,2761-15,2761-15,2761-15,2762-13,2762-13,2762-13,2762-13,2762-13,2762-13,2762-13
rule18=0,100,2010-0
rule19=0,100,250,250,250,250,1476-3
rule20=0,100,2542-0
rule21=0,100,2835-6
rule22=0,100,2835-4
rule23=0,100,2835-5
rule24=0,100,2291-2
rule25=0,100,2245-2
rule26=0,100,2516
rule27=0,100,47,2837-7,2837-5,2837-8,250
rule28=0,75,2844-3
rule29=0,100,2777-10
rule30=0,100,2248
rule31=0,100,2788-9
rule32=0,100,2763-15,2763-15,2764-13,2764-13,2764-13,2764-13,2764-13,2764-13,2764-13
rule33=0,100,2835-7
rule34=0,66,3225-3
rule35=0,100,140-10
rule36=0,50,2245-1
rule37=0,50,2291-1
rule38=0,100,2802-7
rule39=0,95,300
rule40=0,100,4094-10




layer
1,1,1,1,1,1,1,1,1,1,1,1,1,1,1,1,1,1,1,1,1,1,1,1,1,1,1,1,1,1,1,1,1,1,1,1,1,1,1,1,1,1,1,1,1
1,1,1,1,1,1,1,1,1,1,1,1,1,1,2,1,1,1,3,3,3,3,1,1,3,3,3,3,3,3,3,3,1,1,1,1,3,3,3,3,3,3,3,2,1
1,1,1,1,1,1,3,3,4,1,1,1,3,3,3,3,3,1,1,1,1,3,1,1,3,1,1,3,1,1,1,3,1,1,1,1,3,1,1,1,1,1,3,1,1
1,1,1,1,1,1,3,1,1,1,1,1,3,3,3,3,3,1,1,1,1,3,1,4,3,1,1,3,1,1,1,3,1,1,1,1,3,1,1,1,1,1,2,1,1
1,1,1,1,1,1,3,3,3,3,3,3,3,3,3,3,3,3,3,3,3,3,3,3,3,3,3,3,3,3,3,3,3,3,3,3,3,3,3,3,3,1,1,1,1
1,1,2,1,1,1,3,1,1,1,1,1,3,3,3,3,3,1,1,1,3,1,1,1,1,1,3,1,1,3,1,3,1,3,1,1,1,1,1,1,3,3,3,3,1
1,1,3,1,1,1,3,1,1,1,1,1,3,3,3,3,3,1,1,1,1,1,1,1,1,1,3,1,1,3,1,3,3,3,1,3,3,3,2,1,3,1,1,3,1
1,1,3,3,3,3,3,3,3,1,1,1,3,1,1,2,1,1,1,1,1,1,1,1,1,1,3,3,3,3,1,3,1,2,1,3,3,3,1,1,3,1,1,3,1
1,1,1,1,1,1,1,1,1,1,1,1,3,3,3,3,3,1,1,1,1,1,1,1,1,1,1,1,3,1,1,1,1,1,1,1,3,1,1,0,3,3,2,3,1
1,1,1,1,1,1,1,1,1,1,1,1,1,1,1,1,3,1,1,1,1,1,1,1,1,1,1,1,3,1,1,1,1,1,1,1,3,1,1,1,3,3,1,3,1
1,1,1,1,1,1,1,1,1,1,1,1,1,1,1,1,3,1,1,1,1,1,1,1,1,1,1,1,3,1,1,1,1,1,1,1,3,1,1,1,1,3,1,1,1
1,1,1,1,3,3,3,3,3,3,3,3,3,3,3,3,3,1,1,1,1,1,1,1,1,1,1,1,3,3,3,3,3,3,3,3,3,3,3,3,1,3,3,1,1
1,1,1,1,1,1,1,1,1,1,1,3,1,1,1,1,3,1,1,1,1,1,1,1,1,1,1,1,1,1,1,1,1,1,1,1,1,1,1,3,1,1,3,1,1
1,1,1,1,1,1,1,1,1,1,1,3,1,1,1,1,3,1,1,1,0,1,1,1,1,1,1,1,1,2,2,1,1,1,1,1,1,1,1,3,1,1,3,1,1
1,1,1,1,1,1,1,1,1,1,1,3,3,2,3,1,1,1,1,1,1,1,0,1,1,1,1,3,3,3,3,3,3,3,3,3,3,3,3,3,1,1,3,1,1
1,1,1,1,1,1,1,1,1,1,1,3,3,3,3,4,1,1,4,1,1,1,1,1,1,1,1,1,1,3,1,1,1,1,1,1,1,1,1,1,1,1,3,1,1
1,1,1,1,1,1,1,1,1,1,1,1,1,1,1,1,1,1,1,1,1,1,1,1,1,1,1,1,1,3,1,1,1,1,1,1,1,1,1,1,1,1,1,1,1
1,1,1,1,1,1,1,1,1,1,1,1,1,1,1,1,1,1,1,1,1,1,1,1,1,1,1,1,1,1,1,1,1,1,1,1,1,1,1,1,1,1,1,1,1
1,1,1,1,1,1,1,1,1,1,1,1,1,1,1,1,1,1,1,1,1,1,1,1,1,1,1,1,1,1,1,1,1,1,1,1,1,1,1,1,1,1,1,1,1
1,1,1,1,1,1,1,1,1,1,1,1,1,1,1,1,1,1,1,1,1,1,1,1,1,1,1,1,1,1,1,1,1,1,1,1,1,1,1,1,1,1,1,1,1
1,1,1,1,1,1,1,1,1,1,1,1,1,1,1,1,1,1,1,1,1,1,1,1,1,1,1,1,1,1,1,1,1,1,1,1,1,1,1,1,1,1,1,1,1
1,1,1,1,1,1,1,1,1,1,1,1,1,1,1,1,1,1,1,1,1,1,1,1,1,1,1,1,1,1,1,1,1,1,1,1,1,1,1,1,1,1,1,1,1
1,1,1,1,1,1,1,1,1,1,1,1,1,1,1,1,1,1,1,1,1,1,1,1,1,1,1,1,1,1,1,1,1,1,1,1,1,1,1,1,1,1,1,1,1
1,1,1,1,1,1,1,1,1,1,1,1,1,1,1,1,1,1,1,1,1,1,1,1,1,1,1,1,1,1,1,1,1,1,1,1,1,1,1,1,1,1,1,1,1
1,1,1,1,1,1,1,1,1,1,1,1,1,1,1,1,1,1,1,1,1,1,1,1,1,1,1,1,1,1,1,1,1,1,1,1,1,1,1,1,1,1,1,1,1
endlayer

layer
1,1,1,1,1,1,1,1,1,1,1,1,1,1,1,1,1,1,5,5,5,5,1,1,5,5,5,5,5,5,5,5,1,1,1,1,5,5,5,5,5,5,5,1,1
1,1,1,1,1,1,5,5,1,1,1,1,5,5,5,5,5,5,0,0,0,0,5,5,0,0,0,0,0,0,0,0,5,1,1,5,0,0,0,0,0,0,0,5,1
1,1,1,1,1,5,0,0,5,1,1,5,0,0,0,0,0,5,5,5,5,0,5,5,0,5,5,0,5,5,5,0,5,1,1,5,0,5,5,5,5,5,0,5,1
1,1,1,1,1,5,0,5,5,5,5,5,0,0,0,0,0,5,5,5,5,0,5,5,0,5,5,0,5,5,5,0,5,5,5,5,0,5,5,5,5,1,5,1,1
1,1,1,1,1,5,0,0,0,0,0,0,0,0,0,0,0,0,0,0,0,0,0,0,0,5,0,0,5,0,0,0,5,0,0,0,0,0,0,0,0,5,5,5,1
1,1,5,1,1,5,0,5,5,5,5,5,0,0,0,0,0,5,5,5,0,5,5,5,5,5,0,5,5,0,5,0,5,0,5,5,5,5,5,5,0,7,0,0,5
5,5,0,5,5,5,0,5,5,1,1,5,0,0,0,0,0,5,1,5,5,5,1,1,1,5,0,5,5,0,5,0,1,0,5,0,0,0,5,5,0,5,5,0,5
5,5,0,0,0,0,0,0,0,5,1,5,0,5,5,5,5,1,1,5,1,5,1,1,1,5,0,0,0,0,5,0,5,5,5,0,0,0,5,5,0,5,5,0,5
1,1,5,5,5,5,5,5,5,1,1,5,0,0,0,0,0,5,1,5,1,5,1,1,1,1,5,5,0,5,1,5,1,1,1,5,0,5,1,5,0,0,5,0,5
1,1,1,1,1,1,1,1,1,1,1,1,5,5,5,5,0,5,1,5,0,5,1,1,1,1,1,5,0,5,1,1,1,1,1,5,0,5,1,5,0,0,5,4,5
1,0,1,1,5,5,5,5,5,5,5,5,5,5,5,5,0,5,5,5,0,5,5,5,5,5,1,5,0,5,5,5,5,5,5,5,0,5,5,5,5,0,5,2,1
1,3,3,3,0,0,0,0,0,0,0,0,0,0,0,0,0,5,0,0,0,0,0,0,0,0,5,5,0,0,0,0,0,0,0,0,0,0,0,0,5,0,0,5,1
1,3,3,3,5,5,5,5,5,5,5,0,5,5,5,5,0,5,0,5,5,5,5,5,5,0,5,1,5,5,5,5,5,5,5,5,5,5,5,0,5,5,0,5,1
1,3,3,3,1,1,1,1,1,1,5,0,5,5,5,5,0,5,0,4,5,1,5,0,0,0,5,5,5,5,4,5,5,5,5,5,5,5,5,0,5,5,0,5,1
1,3,3,3,1,1,1,1,1,1,5,0,0,5,1,5,5,5,5,5,1,1,5,0,0,0,5,0,0,0,0,0,0,0,0,0,0,0,0,0,5,5,0,5,1
1,3,3,3,1,1,1,1,1,1,5,0,0,5,1,5,1,1,5,1,1,1,1,5,5,5,1,5,5,0,5,5,5,5,5,5,5,5,5,5,1,5,0,5,1
1,1,3,1,1,1,1,1,1,1,1,5,5,1,5,1,5,5,1,1,1,1,1,1,1,1,1,1,5,0,5,1,1,1,1,1,1,1,1,1,1,1,3,1,1
1,1,3,1,1,1,1,1,1,1,1,1,1,1,1,1,1,1,1,1,1,2,1,1,1,1,1,1,1,5,1,1,1,1,1,1,1,1,1,1,1,1,3,1,1
1,6,6,6,6,6,6,6,6,6,6,6,6,6,6,6,6,6,6,6,6,6,6,6,6,6,6,6,6,6,6,6,6,6,6,6,6,6,6,6,6,6,6,6,1
1,6,6,6,6,6,6,6,6,6,6,6,6,6,6,6,6,6,6,6,6,6,6,6,6,6,6,6,6,6,6,6,6,6,6,6,6,6,6,6,6,6,6,6,1
1,6,6,6,6,6,6,6,6,6,6,6,6,6,6,6,6,6,6,6,6,6,6,6,6,6,6,6,6,6,6,6,6,6,6,6,6,6,6,6,6,6,6,6,1
1,1,1,1,1,1,1,1,1,1,1,1,1,1,1,1,1,1,1,1,1,1,1,1,1,1,1,1,1,1,1,1,1,1,1,1,1,1,1,1,1,1,1,1,1
1,1,1,1,1,1,1,1,1,1,1,1,1,1,1,1,1,1,1,1,1,1,1,1,1,1,1,1,1,1,1,1,1,1,1,1,1,1,1,1,1,1,1,1,1
1,1,1,1,1,1,1,1,1,1,1,1,1,1,1,1,1,1,1,1,1,1,1,1,1,1,1,1,1,1,1,1,1,1,1,1,1,1,1,1,1,1,1,1,1
1,1,1,1,1,1,1,1,1,1,1,1,1,1,1,1,1,1,1,1,1,1,1,1,1,1,1,1,1,1,1,1,1,1,1,1,1,1,1,1,1,1,1,1,1
endlayer

layer
1,1,1,1,1,1,1,1,1,1,1,1,1,1,1,1,1,1,5,5,5,5,1,1,5,5,5,5,5,5,5,5,1,1,1,1,5,5,5,5,5,5,5,1,1
1,1,1,1,1,1,5,5,1,1,1,1,5,5,5,5,5,5,0,0,0,0,5,5,0,0,0,0,0,0,0,0,5,1,1,5,0,0,0,0,0,0,0,5,1
1,1,1,1,1,5,0,0,5,1,1,5,0,0,0,0,0,5,5,5,5,0,5,5,0,5,5,0,5,5,5,0,5,1,1,5,0,5,5,5,5,5,0,5,1
1,1,1,1,1,5,0,5,5,5,5,5,0,0,0,0,0,5,5,5,5,0,5,5,0,5,5,0,5,5,5,0,5,5,5,5,0,5,5,5,5,1,5,1,1
1,1,1,1,1,5,0,0,0,0,0,0,0,0,0,0,0,0,0,0,0,0,0,0,0,5,0,0,5,0,0,0,5,0,0,0,0,0,0,0,0,5,5,5,1
1,1,5,1,1,5,0,5,5,5,5,5,0,0,0,0,0,5,5,5,0,5,5,5,5,5,0,5,5,0,5,0,5,0,5,5,5,5,5,5,0,5,0,0,5
5,5,0,5,5,5,0,5,5,1,1,5,0,0,0,0,0,5,1,5,5,5,1,1,1,5,0,5,5,0,5,0,1,0,5,0,0,0,5,5,0,5,5,0,5
5,5,0,0,0,0,0,0,0,5,1,5,0,5,5,5,5,1,1,5,1,5,1,1,1,5,0,0,0,0,5,0,5,5,5,0,0,0,5,5,0,5,5,0,5
1,1,5,5,5,5,5,5,5,1,1,5,0,0,0,0,0,5,1,5,0,5,1,1,1,5,5,5,0,5,1,5,1,1,1,5,0,5,1,5,0,0,5,0,5
1,1,1,1,1,1,1,1,1,1,1,1,5,5,5,5,0,5,1,5,0,5,1,1,1,1,1,5,0,5,1,1,1,1,1,5,0,5,1,5,0,0,5,0,5
5,5,5,5,5,5,5,5,5,5,5,5,5,5,5,5,0,5,5,5,0,5,5,5,5,5,1,5,0,5,5,5,5,5,5,5,0,5,5,5,5,0,5,5,1
5,0,0,0,0,0,0,0,0,0,0,0,0,0,0,0,0,5,0,0,0,0,0,0,0,0,5,5,0,0,0,0,0,0,0,0,0,0,0,0,5,0,0,5,1
5,0,0,0,5,5,5,5,5,5,5,0,5,5,5,5,0,5,0,5,5,5,5,5,5,0,5,1,5,5,5,5,5,5,5,5,5,5,5,0,5,5,0,5,1
5,0,0,0,5,1,1,1,1,1,5,0,5,5,5,5,0,5,0,0,1,1,5,0,0,0,5,5,5,5,5,5,5,5,5,5,5,5,5,0,5,5,0,5,1
5,0,0,0,5,1,1,1,1,1,5,0,0,5,1,5,5,5,5,5,1,1,5,0,0,0,5,0,0,0,0,0,0,0,0,0,0,0,0,0,5,5,0,5,1
5,0,0,0,5,1,1,1,1,1,5,0,0,5,1,5,1,1,5,1,1,1,1,5,5,5,1,5,5,0,5,5,5,5,5,5,5,5,5,5,1,5,0,5,1
5,5,0,5,1,1,1,1,1,1,1,5,5,1,5,1,5,5,1,1,1,1,1,1,1,1,1,1,5,0,5,1,1,1,1,1,1,1,1,1,1,5,0,5,1
1,9,0,5,5,5,5,9,5,5,5,5,5,9,5,5,5,5,11,9,5,5,5,5,5,9,5,5,5,5,5,9,11,5,5,5,5,9,5,5,5,5,0,9,1
8,0,0,0,0,0,0,0,0,0,0,0,0,0,0,0,0,0,0,0,0,0,0,0,0,0,0,0,0,0,0,0,0,0,0,0,0,0,0,0,0,0,0,0,8
8,10,10,10,10,10,10,10,10,10,10,10,10,10,10,10,10,10,10,10,10,10,10,10,10,10,10,10,10,10,10,10,10,10,10,10,10,10,10,10,10,10,10,10,8
8,0,0,0,0,0,0,0,0,0,0,0,0,0,0,0,0,0,0,0,0,0,0,0,0,0,0,0,0,0,0,0,0,0,0,0,0,0,0,0,0,0,0,0,8
1,9,5,5,5,5,5,9,5,5,5,5,5,9,5,5,5,5,11,9,11,11,11,11,11,9,11,11,11,11,11,9,11,5,5,5,5,9,5,5,5,5,5,9,8
1,1,1,1,1,1,1,1,1,1,1,1,1,1,1,1,1,1,1,1,1,1,1,1,1,1,1,1,1,1,1,1,1,1,1,1,1,1,1,1,1,1,1,1,1
1,1,1,1,1,1,1,1,1,1,1,1,1,1,1,1,1,1,1,1,1,1,1,1,1,1,1,1,1,1,1,1,1,1,1,1,1,1,1,1,1,1,1,1,1
1,1,1,1,1,1,1,1,1,1,1,1,1,1,1,1,1,1,1,1,1,1,1,1,1,1,1,1,1,1,1,1,1,1,1,1,1,1,1,1,1,1,1,1,1
endlayer

layer
1,1,1,1,1,1,1,1,1,1,1,1,1,1,1,1,1,1,1,1,1,1,1,1,1,1,1,1,1,1,1,1,1,1,1,1,1,1,1,1,1,1,1,1,1
1,1,1,1,1,1,1,1,1,1,1,1,5,5,5,5,5,1,5,5,5,5,1,1,5,5,5,5,5,5,5,5,1,1,1,1,5,5,5,5,5,5,5,1,1
1,1,1,1,1,1,5,5,1,1,1,5,0,0,0,0,0,5,1,1,1,5,1,1,5,1,1,5,1,1,1,5,1,1,1,1,5,1,1,1,1,1,5,1,1
1,1,1,1,1,1,5,1,1,1,1,5,0,0,0,0,0,5,1,1,1,5,1,1,5,1,1,5,1,1,1,5,1,1,1,1,5,1,1,1,1,1,1,1,1
1,1,1,1,1,1,5,5,5,5,5,5,0,0,0,0,0,5,5,5,5,5,5,5,5,5,5,5,5,5,5,5,5,5,5,5,5,5,5,5,5,1,1,1,1
1,1,1,1,1,1,5,1,1,1,1,5,0,0,0,0,0,5,1,1,5,1,1,1,1,1,5,1,1,5,1,5,5,5,5,5,5,5,5,5,5,5,5,5,1
1,1,5,1,1,1,5,1,1,1,1,5,0,0,0,0,0,5,1,1,1,1,1,1,1,1,5,1,1,5,1,5,1,5,5,0,0,0,5,1,5,1,1,5,1
1,1,5,5,5,5,5,5,5,1,1,1,5,5,5,5,5,1,1,1,1,1,1,1,1,1,5,5,5,5,1,5,1,1,5,0,0,0,5,1,5,1,1,5,1
1,1,1,1,1,1,1,1,1,1,1,1,5,5,5,5,5,1,1,1,5,1,1,0,1,1,1,1,5,1,1,1,1,1,1,5,5,5,1,1,5,5,1,5,1
1,1,1,1,1,1,1,1,1,1,1,1,1,1,12,12,12,12,12,12,12,12,12,12,12,12,12,12,5,12,12,12,1,1,1,1,5,1,1,1,5,5,1,5,1
5,5,5,5,5,1,1,1,1,1,1,1,1,1,12,12,12,12,12,12,12,12,12,12,12,12,12,12,12,12,12,12,1,1,1,1,5,1,1,1,1,5,1,1,1
5,0,0,0,0,5,5,5,5,5,5,5,5,5,12,12,12,12,12,12,12,12,12,12,12,12,12,12,12,12,12,12,5,5,5,5,5,5,5,5,1,5,5,1,1
5,0,0,0,5,1,1,1,1,1,1,5,1,1,1,1,5,1,5,12,12,12,12,12,12,12,12,12,12,12,12,12,1,1,1,1,1,1,1,5,1,1,5,1,1
5,0,0,0,5,1,1,1,1,1,1,5,1,1,1,1,12,12,12,12,12,12,12,12,12,12,12,12,12,12,12,12,1,1,1,1,1,1,1,5,1,1,5,1,1
5,0,0,0,5,1,1,1,1,1,1,5,5,5,1,1,1,1,1,12,12,12,12,12,12,12,12,12,12,12,12,12,5,5,5,5,5,5,5,5,1,5,0,5,1
5,0,0,0,5,1,1,1,1,1,1,5,5,5,1,1,1,1,1,12,12,12,12,12,12,12,12,12,12,12,12,12,1,1,1,1,1,1,1,1,1,5,0,5,1
5,5,0,5,1,1,1,1,1,1,1,1,5,5,1,1,1,1,1,12,12,12,12,12,12,12,12,12,12,12,12,12,1,1,1,1,1,1,1,1,1,5,0,5,1
1,9,0,5,5,5,5,9,5,5,5,5,5,9,5,5,5,5,11,9,12,12,12,12,12,9,12,12,12,12,12,9,11,5,5,5,5,9,5,5,5,5,0,9,1
8,0,0,0,0,0,0,0,0,0,0,0,0,0,0,0,0,0,0,0,0,0,0,0,0,0,0,0,0,0,0,0,0,0,0,0,0,0,0,0,0,0,0,0,8
8,0,0,0,0,0,0,0,0,0,0,0,0,0,0,0,0,0,0,0,0,0,0,0,0,0,0,0,0,0,0,0,0,0,0,0,0,0,0,0,0,0,0,0,8
8,0,0,0,0,0,0,0,0,0,0,0,0,0,0,0,0,0,0,0,0,0,0,0,0,0,0,0,0,0,0,0,0,0,0,0,0,0,0,0,0,0,0,0,8
1,9,5,5,5,5,5,9,5,5,5,5,5,9,5,5,5,5,11,9,11,11,11,11,11,9,11,11,11,11,11,9,11,5,5,5,5,9,5,5,5,5,5,9,8
1,1,1,1,1,1,1,1,1,1,1,1,1,1,1,1,1,1,1,1,1,1,1,1,1,1,1,1,1,1,1,1,1,1,1,1,1,1,1,1,1,1,1,1,1
1,1,1,1,1,1,1,1,1,1,1,1,1,1,1,1,1,1,1,1,1,1,1,1,1,1,1,1,1,1,1,1,1,1,1,1,1,1,1,1,1,1,1,1,1
1,1,1,1,1,1,1,1,1,1,1,1,1,1,1,1,1,1,1,1,1,1,1,1,1,1,1,1,1,1,1,1,1,1,1,1,1,1,1,1,1,1,1,1,1
endlayer

layer
1,1,1,1,1,1,1,1,1,1,1,1,1,1,1,1,1,1,1,1,1,1,1,1,1,1,1,1,1,1,1,1,1,1,1,1,1,1,1,1,1,1,1,1,1
1,1,1,1,1,1,1,1,1,1,1,1,1,1,1,1,1,1,1,1,1,1,1,1,1,1,1,1,1,1,1,1,1,1,1,1,1,1,1,1,1,1,1,1,1
1,1,1,1,1,1,1,1,1,1,1,1,5,5,5,5,5,1,1,1,1,1,1,1,1,1,1,1,1,1,1,1,1,1,1,1,1,1,1,1,1,1,1,1,1
1,1,1,1,1,1,1,1,1,1,1,1,5,5,5,5,5,1,1,1,1,1,1,1,1,1,1,1,1,1,1,1,1,1,1,1,1,1,1,1,1,1,1,1,1
1,1,1,1,1,1,1,1,1,1,1,1,5,5,5,5,5,1,1,1,1,1,1,1,1,1,1,1,1,1,1,1,1,1,1,1,1,1,1,1,1,1,1,1,1
1,1,1,1,1,1,1,1,1,1,1,1,5,5,5,5,5,1,1,1,1,1,1,1,1,1,1,1,1,1,1,1,1,1,1,1,1,1,1,1,1,1,1,1,1
1,1,1,1,1,1,1,1,1,1,1,1,5,5,5,5,5,1,1,1,1,1,1,1,1,1,1,1,1,1,1,1,1,1,1,5,5,5,1,1,1,1,1,1,1
1,1,1,1,1,1,1,1,1,1,1,1,1,1,1,1,1,1,1,1,1,1,1,1,1,1,1,1,1,1,1,1,1,1,1,5,5,5,1,1,1,1,1,1,1
1,1,1,1,1,1,1,1,1,1,1,1,1,1,11,11,11,11,11,9,11,11,11,11,11,9,11,11,11,11,11,9,1,1,1,1,1,1,1,1,1,1,1,1,1
1,1,1,1,1,1,1,1,1,1,1,1,1,16,1,1,0,0,0,0,13,14,14,14,13,0,13,14,14,14,13,0,11,1,1,1,1,1,1,1,1,1,1,1,1
5,5,5,5,1,1,1,1,1,1,1,1,1,16,1,1,0,0,15,0,0,0,0,0,0,0,0,0,0,0,0,0,11,1,1,1,1,1,1,1,1,1,1,1,1
5,0,0,0,5,1,1,1,1,1,1,1,1,16,1,1,0,0,0,0,0,0,0,0,0,0,0,0,0,0,0,0,11,1,1,1,1,1,1,1,1,1,1,1,1
5,0,0,0,5,1,1,1,1,1,1,1,1,1,11,11,11,11,11,0,0,0,0,0,0,0,0,0,0,0,0,0,11,1,1,1,1,1,1,1,1,1,1,1,1
5,0,0,0,5,1,1,1,1,1,1,1,1,1,1,11,0,0,0,0,0,0,0,0,0,0,0,0,0,0,0,0,11,1,1,1,1,1,1,1,1,1,1,1,1
5,0,0,0,5,1,1,1,1,1,1,1,1,1,1,1,11,11,11,0,0,0,0,0,0,0,0,0,0,0,0,0,11,1,1,1,1,1,1,1,1,1,5,1,1
5,0,0,0,5,1,1,1,1,1,1,1,1,1,1,1,1,1,11,0,0,0,0,0,0,0,0,0,0,0,0,0,11,1,1,1,1,1,1,1,1,1,5,1,1
5,5,5,5,1,1,1,1,1,1,1,1,1,1,1,1,1,1,11,0,0,0,0,0,0,0,0,0,0,0,0,0,11,1,1,1,1,1,1,1,1,1,5,1,1
1,9,5,5,5,5,5,9,5,5,5,5,5,9,5,5,5,5,11,9,0,0,0,0,0,9,0,0,0,0,0,9,11,5,5,5,5,9,5,5,5,5,5,9,1
8,0,0,0,0,0,0,0,0,0,0,0,0,0,0,0,0,0,0,0,0,0,0,0,0,0,0,0,0,0,0,0,0,0,0,0,0,0,0,0,0,0,0,0,8
8,0,0,0,0,0,0,0,0,0,0,0,0,0,0,0,0,0,0,0,0,0,0,0,0,0,0,0,0,0,0,0,0,0,0,0,0,0,0,0,0,0,0,0,8
8,0,0,0,0,0,0,0,0,0,0,0,0,0,0,0,0,0,0,0,0,0,0,0,0,0,0,0,0,0,0,0,0,0,0,0,0,0,0,0,0,0,0,0,8
1,9,5,5,5,5,5,9,5,5,5,5,5,9,5,5,5,5,11,9,11,11,11,11,11,9,11,11,11,11,11,9,11,5,5,5,5,9,5,5,5,5,5,9,1
1,1,1,1,1,1,1,1,1,1,1,1,1,1,1,1,1,1,1,1,1,1,1,1,1,1,1,1,1,1,1,1,1,1,1,1,1,1,1,1,1,1,1,1,1
1,1,1,1,1,1,1,1,1,1,1,1,1,1,1,1,1,1,1,1,1,1,1,1,1,1,1,1,1,1,1,1,1,1,1,1,1,1,1,1,1,1,1,1,1
1,1,1,1,1,1,1,1,1,1,1,1,1,1,1,1,1,1,1,1,1,1,1,1,1,1,1,1,1,1,1,1,1,1,1,1,1,1,1,1,1,1,1,1,1
endlayer

layer
1,1,1,1,1,1,1,1,1,1,1,1,1,1,1,1,1,1,1,1,1,1,1,1,1,1,1,1,1,1,1,1,1,1,1,1,1,1,1,1,1,1,1,1,1
1,1,1,1,1,1,1,1,1,1,1,1,1,1,1,1,1,1,1,1,1,1,1,1,1,1,1,1,1,1,1,1,1,1,1,1,1,1,1,1,1,1,1,1,1
1,1,1,1,1,1,1,1,1,1,1,1,1,1,1,1,1,1,1,1,1,1,1,1,1,1,1,1,1,1,1,1,1,1,1,1,1,1,1,1,1,1,1,1,1
1,1,1,1,1,1,1,1,1,1,1,1,1,1,1,1,1,1,1,1,1,1,1,1,1,1,1,1,1,1,1,1,1,1,1,1,1,1,1,1,1,1,1,1,1
1,1,1,1,1,1,1,1,1,1,1,1,1,1,1,1,1,1,1,1,1,1,1,1,1,1,1,1,1,1,1,1,1,1,1,1,1,1,1,1,1,1,1,1,1
1,1,1,1,1,1,1,1,1,1,1,1,1,1,1,1,1,1,1,1,1,1,1,1,1,1,1,1,1,1,1,1,1,1,1,1,1,1,1,1,1,1,1,1,1
1,1,1,1,1,1,1,1,1,1,1,1,1,1,1,1,1,1,1,1,1,1,1,1,1,1,1,1,1,1,1,1,1,1,1,1,1,1,1,1,1,1,1,1,1
1,1,1,1,1,1,1,1,1,1,1,1,1,1,1,1,1,1,1,1,1,1,1,1,1,1,1,1,1,1,1,1,1,1,1,1,1,1,1,1,1,1,1,1,1
1,1,1,1,1,1,1,1,1,1,1,1,1,11,11,11,11,11,11,9,11,11,11,11,11,9,11,11,11,11,11,9,1,1,1,1,1,1,1,1,1,1,1,1,1
1,1,1,1,1,1,1,1,1,1,1,1,16,1,1,0,0,0,0,0,0,0,0,0,0,0,0,0,0,0,0,0,11,1,1,1,1,1,1,1,1,1,1,1,1
1,1,1,1,1,1,1,1,1,1,1,1,16,1,1,0,0,0,15,0,0,0,0,0,0,0,0,0,0,0,0,0,11,1,1,1,1,1,1,1,1,1,1,1,1
5,5,5,5,1,1,1,1,1,1,1,1,16,1,1,0,0,0,0,0,0,0,0,0,0,0,0,0,0,0,0,0,11,1,1,1,1,1,1,1,1,1,1,1,1
5,5,5,5,1,1,1,1,1,1,1,0,1,11,11,11,0,0,11,0,0,0,0,0,0,0,0,0,0,0,0,0,11,1,1,1,1,1,1,1,1,1,1,1,1
5,5,5,5,1,1,1,1,1,1,1,1,1,1,1,11,0,0,0,0,0,0,0,0,0,0,0,0,0,0,0,0,11,1,1,1,1,1,1,1,1,1,1,1,1
5,5,5,5,1,1,1,1,1,1,1,1,1,1,1,1,11,11,11,0,0,0,0,0,0,0,0,0,0,0,0,0,11,1,1,1,1,1,1,1,1,1,1,1,1
5,5,5,5,1,1,1,1,1,1,1,1,1,1,1,1,1,1,11,0,0,0,0,0,0,0,0,0,0,0,0,0,11,1,1,1,1,1,1,1,1,1,1,1,1
1,1,1,1,1,1,1,1,1,1,1,1,1,1,1,1,1,1,11,0,0,0,0,0,0,0,0,0,0,0,0,0,11,1,1,1,1,1,1,1,1,1,1,1,1
1,1,1,1,1,1,1,1,1,1,1,1,1,1,1,1,1,1,1,9,0,0,0,0,0,9,0,0,0,0,0,9,11,1,1,1,1,1,1,1,1,1,1,1,1
1,9,5,5,5,5,5,9,5,5,5,5,5,9,5,5,5,5,11,0,0,0,0,0,0,0,0,0,0,0,0,0,11,5,5,5,5,9,5,5,5,5,5,9,1
8,0,0,0,0,0,0,0,0,0,0,0,0,0,0,0,0,0,0,0,0,0,0,0,0,0,0,0,0,0,0,0,0,0,0,0,0,0,0,0,0,0,0,0,8
1,9,5,5,5,5,5,9,5,5,5,5,5,9,5,5,5,5,11,0,0,0,0,0,0,0,0,0,0,0,0,0,11,5,5,5,5,9,5,5,5,5,5,9,1
1,1,1,1,1,1,1,1,1,1,1,1,1,1,1,1,1,1,1,9,11,11,11,11,11,9,11,11,11,11,11,9,1,1,1,1,1,1,1,1,1,1,1,1,1
1,1,1,1,1,1,1,1,1,1,1,1,1,1,1,1,1,1,1,1,1,1,1,1,1,1,1,1,1,1,1,1,1,1,1,1,1,1,1,1,1,1,1,1,1
1,1,1,1,1,1,1,1,1,1,1,1,1,1,1,1,1,1,1,1,1,1,1,1,1,1,1,1,1,1,1,1,1,1,1,1,1,1,1,1,1,1,1,1,1
1,1,1,1,1,1,1,1,1,1,1,1,1,1,1,1,1,1,1,1,1,1,1,1,1,1,1,1,1,1,1,1,1,1,1,1,1,1,1,1,1,1,1,1,1
endlayer

layer
1,1,1,1,1,1,1,1,1,1,1,1,1,1,1,1,1,1,1,1,1,1,1,1,1,1,1,1,1,1,1,1,1,1,1,1,1,1,1,1,1,1,1,1,1
1,1,1,1,1,1,1,1,1,1,1,1,1,1,1,1,1,1,1,1,1,1,1,1,1,1,1,1,1,1,1,1,1,1,1,1,1,1,1,1,1,1,1,1,1
1,1,1,1,1,1,1,1,1,1,1,1,1,1,1,1,1,1,1,1,1,1,1,1,1,1,1,1,1,1,1,1,1,1,1,1,1,1,1,1,1,1,1,1,1
1,1,1,1,1,1,1,1,1,1,1,1,1,1,1,1,1,1,1,1,1,1,1,1,1,1,1,1,1,1,1,1,1,1,1,1,1,1,1,1,1,1,1,1,1
1,1,1,1,1,1,1,1,1,1,1,1,1,1,1,1,1,1,1,1,1,1,1,1,1,1,1,1,1,1,1,1,1,1,1,1,1,1,1,1,1,1,1,1,1
1,1,1,1,1,1,1,1,1,1,1,1,1,1,1,1,1,1,1,1,1,1,1,1,1,1,1,1,1,1,1,1,1,1,1,1,1,1,1,1,1,1,1,1,1
1,1,1,1,1,1,1,1,1,1,1,1,1,1,1,1,1,1,1,1,1,1,1,1,1,1,1,1,1,1,1,1,1,1,1,1,1,1,1,1,1,1,1,1,1
1,1,1,1,1,1,1,1,1,1,1,1,1,1,1,1,1,1,1,1,1,1,1,1,1,1,1,1,1,1,1,1,1,1,1,1,1,1,1,1,1,1,1,1,1
1,1,1,1,1,1,1,1,1,1,1,1,11,11,11,11,11,11,11,9,11,11,11,11,11,9,11,11,11,11,11,9,1,1,1,1,1,1,1,1,1,1,1,1,1
1,1,1,1,1,1,1,1,1,1,1,16,1,1,0,0,0,0,0,0,0,0,0,0,0,0,0,0,0,0,0,0,11,1,1,1,1,1,1,1,1,1,1,1,1
1,1,1,1,1,1,1,1,1,1,1,16,1,1,0,0,0,0,15,0,0,0,0,0,0,0,0,0,0,0,0,0,11,1,1,1,1,1,1,1,1,1,1,1,1
1,1,1,1,1,1,1,1,1,1,1,16,1,1,0,0,0,0,0,0,0,0,0,0,0,0,0,0,0,0,0,0,11,1,1,1,1,1,1,1,1,1,1,1,1
1,1,1,1,1,1,1,1,1,1,1,0,11,11,11,11,11,11,11,0,0,0,0,0,0,0,0,0,0,0,0,0,11,1,1,1,1,1,1,1,1,1,1,1,1
1,1,1,1,1,1,1,1,1,1,1,1,1,1,1,1,11,11,11,0,0,0,0,0,0,0,0,0,0,0,0,0,11,1,1,1,1,1,1,1,1,1,1,1,1
1,1,1,1,1,1,1,1,1,1,1,1,1,1,1,1,1,1,11,0,0,0,0,0,0,0,0,0,0,0,0,0,11,1,1,1,1,1,1,1,1,1,1,1,1
1,1,1,1,1,1,1,1,1,1,1,1,1,1,1,1,1,1,11,0,0,0,0,0,0,0,0,0,0,0,0,0,11,1,1,1,1,1,1,1,1,1,1,1,1
1,1,1,1,1,1,1,1,1,1,1,1,1,1,1,1,1,1,11,0,0,0,0,0,0,0,0,0,0,0,0,0,11,1,1,1,1,1,1,1,1,1,1,1,1
1,1,1,1,1,1,1,17,1,1,1,1,1,17,1,1,1,1,1,9,0,0,0,0,0,9,0,0,0,0,0,9,11,1,1,1,1,17,1,1,1,1,1,1,1
1,1,1,1,1,1,1,1,1,1,1,1,1,1,1,1,1,1,11,0,0,0,0,0,0,0,0,0,0,0,0,0,11,1,1,1,1,1,1,1,1,1,1,1,1
1,9,5,5,5,5,5,9,5,5,5,5,5,9,5,5,5,5,11,0,0,0,0,0,0,0,0,0,0,0,0,0,11,5,5,5,5,9,5,5,5,5,5,9,1
1,1,1,1,1,1,1,1,1,1,1,1,1,1,1,1,1,1,11,0,0,0,0,0,0,0,0,0,0,0,0,0,11,1,1,1,1,1,1,1,1,1,1,1,1
1,1,1,1,1,1,1,1,1,1,1,1,1,17,1,1,1,1,1,9,11,11,11,11,11,9,11,11,11,11,11,9,1,1,1,1,1,1,1,1,1,1,1,1,1
1,1,1,1,1,1,1,1,1,1,1,1,1,1,1,1,1,1,1,1,1,1,1,1,1,1,1,1,1,1,1,1,1,1,1,1,1,1,1,1,1,1,1,1,1
1,1,1,1,1,1,1,1,1,1,1,1,1,1,1,1,1,1,1,1,1,1,1,1,1,1,1,1,1,1,1,1,1,1,1,1,1,1,1,1,1,1,1,1,1
1,1,1,1,1,1,1,1,1,1,1,1,1,1,1,1,1,1,1,1,1,1,1,1,1,1,1,1,1,1,1,1,1,1,1,1,1,1,1,1,1,1,1,1,1
endlayer

layer
1,1,1,1,1,1,1,1,1,1,1,1,1,1,1,1,1,1,1,1,1,1,1,1,1,1,1,1,1,1,1,1,1,1,1,1,1,1,1,1,1,1,1,1,1
1,1,1,1,1,1,1,1,1,1,1,1,1,1,1,1,1,1,1,1,1,1,1,1,1,1,1,1,1,1,1,1,1,1,1,1,1,1,1,1,1,1,1,1,1
1,1,1,1,1,1,1,1,1,1,1,1,1,1,1,1,1,1,1,1,1,1,1,1,1,1,1,1,1,1,1,1,1,1,1,1,1,1,1,1,1,1,1,1,1
1,1,1,1,1,1,1,1,1,1,1,1,1,1,1,1,1,1,1,1,1,1,1,1,1,1,1,1,1,1,1,1,1,1,1,1,1,1,1,1,1,1,1,1,1
1,1,1,1,1,1,1,1,1,1,1,1,1,1,1,1,1,1,1,1,1,1,1,1,1,1,1,1,1,1,1,1,1,1,1,1,1,1,1,1,1,1,1,1,1
1,1,1,1,1,1,1,1,1,1,1,1,1,1,1,1,1,1,1,1,1,1,1,1,1,1,1,1,1,1,1,1,1,1,1,1,1,1,1,1,1,1,1,1,1
1,1,1,1,1,1,1,1,1,1,1,1,1,1,1,1,1,1,1,1,1,1,1,1,1,1,1,1,1,1,1,1,1,1,1,1,1,1,1,1,1,1,1,1,1
1,1,1,1,1,1,1,1,1,1,1,1,1,1,1,1,1,1,1,1,1,1,1,1,1,1,1,1,1,1,1,1,1,1,1,1,1,1,1,1,1,1,1,1,1
1,1,1,1,1,1,1,1,1,1,1,11,11,11,11,11,11,11,11,9,11,11,11,11,11,9,11,11,11,11,11,9,1,1,1,1,1,1,1,1,1,1,1,1,1
1,1,1,1,1,1,1,1,1,1,16,1,0,0,0,0,0,0,0,9,0,0,0,0,0,9,0,0,0,0,0,9,11,1,1,1,1,1,1,1,1,1,1,1,1
1,1,1,1,1,1,1,1,1,1,16,1,0,0,0,0,0,0,15,0,0,0,0,0,0,0,0,0,0,0,0,0,11,1,1,1,1,1,1,1,1,1,1,1,1
1,1,1,1,1,1,1,1,1,1,16,1,0,0,0,0,0,0,0,0,0,0,0,0,0,0,0,0,0,0,0,0,11,1,1,1,1,1,1,1,1,1,1,1,1
1,1,1,1,1,1,1,1,1,1,1,11,11,11,11,11,11,11,11,0,0,0,0,0,0,0,0,0,0,0,0,0,11,1,1,1,1,1,1,1,1,1,1,1,1
1,1,1,1,1,1,1,1,1,1,1,1,1,1,1,1,1,1,11,0,0,0,0,0,0,0,0,0,0,0,0,0,11,1,1,1,1,1,1,1,1,1,1,1,1
1,1,1,1,1,1,1,1,1,1,1,1,1,1,1,1,1,1,11,0,0,0,0,0,0,0,0,0,0,0,0,0,11,1,1,1,1,1,1,1,1,1,1,1,1
1,1,1,1,1,1,1,1,1,1,1,1,1,1,1,1,1,1,11,0,0,0,0,0,0,0,0,0,0,0,0,0,11,1,1,1,1,1,1,1,1,1,1,1,1
1,1,1,1,1,1,1,1,1,1,1,1,1,1,1,1,1,1,11,9,0,0,0,0,0,9,0,0,0,0,0,9,11,1,1,1,1,1,1,1,1,1,1,1,1
1,1,1,1,1,1,1,1,1,1,1,1,1,1,1,1,1,1,11,9,0,0,0,0,0,9,0,0,0,0,0,9,11,1,1,1,1,1,1,1,1,1,1,1,1
1,1,1,1,1,1,1,1,1,1,1,1,1,1,1,1,1,1,11,9,0,0,0,0,0,9,0,0,0,0,0,9,11,1,1,1,1,1,1,1,1,1,1,1,1
1,1,1,1,1,1,1,1,1,1,1,1,1,1,1,1,1,1,11,0,0,0,0,0,0,0,0,0,0,0,0,0,11,1,1,1,1,1,1,1,1,1,1,1,1
1,1,1,1,1,1,1,1,1,1,1,1,1,1,1,1,1,1,11,9,0,0,0,0,0,9,0,0,0,0,0,9,11,1,1,1,1,1,1,1,1,1,1,1,1
1,1,1,1,1,1,1,1,1,1,1,1,1,1,1,1,1,1,1,9,11,11,11,11,11,9,11,11,11,11,11,9,1,1,1,1,1,1,1,1,1,1,1,1,1
1,1,1,1,1,1,1,1,1,1,1,1,1,1,1,1,1,1,1,1,1,1,1,1,1,1,1,1,1,1,1,1,1,1,1,1,1,1,1,1,1,1,1,1,1
1,1,1,1,1,1,1,1,1,1,1,1,1,1,1,1,1,1,1,1,1,1,1,1,1,1,1,1,1,1,1,1,1,1,1,1,1,1,1,1,1,1,1,1,1
1,1,1,1,1,1,1,1,1,1,1,1,1,1,1,1,1,1,1,1,1,1,1,1,1,1,1,1,1,1,1,1,1,1,1,1,1,1,1,1,1,1,1,1,1
endlayer

layer
1,1,1,1,1,1,1,1,1,1,1,1,1,1,1,1,1,1,1,1,1,1,1,1,1,1,1,1,1,1,1,1,1,1,1,1,1,1,1,1,1,1,1,1,1
1,1,1,1,1,1,1,1,1,1,1,1,1,1,1,1,1,1,1,1,1,1,1,1,1,1,1,1,1,1,1,1,1,1,1,1,1,1,1,1,1,1,1,1,1
1,1,1,1,1,1,1,1,1,1,1,1,1,1,1,1,1,1,1,1,1,1,1,1,1,1,1,1,1,1,1,1,1,1,1,1,1,1,1,1,1,1,1,1,1
1,1,1,1,1,1,1,1,1,1,1,1,1,1,1,1,1,1,1,1,1,1,1,1,1,1,1,1,1,1,1,1,1,1,1,1,1,1,1,1,1,1,1,1,1
1,1,1,1,1,1,1,1,1,1,1,1,1,1,1,1,1,1,1,1,1,1,1,1,1,1,1,1,1,1,1,1,1,1,1,1,1,1,1,1,1,1,1,1,1
1,1,1,1,1,1,1,1,1,1,1,1,1,1,1,1,1,1,1,1,1,1,1,1,1,1,1,1,1,1,1,1,1,1,1,1,1,1,1,1,1,1,1,1,1
1,1,1,1,1,1,1,1,1,1,1,1,1,1,1,1,1,1,1,1,1,1,1,1,1,1,1,1,1,1,1,1,1,1,1,1,1,1,1,1,1,1,1,1,1
1,1,1,1,1,1,1,1,1,1,1,1,1,1,1,1,1,1,1,1,1,1,1,1,1,1,1,1,1,1,1,1,1,1,1,1,1,1,1,1,1,1,1,1,1
1,1,1,1,1,1,1,1,1,1,11,11,11,11,11,11,11,11,11,9,11,11,11,11,11,9,11,11,11,11,11,9,1,1,1,1,1,1,1,1,1,1,1,1,1
1,1,1,1,1,1,1,1,1,16,1,1,0,0,0,0,0,0,0,0,0,0,0,0,0,0,0,0,0,0,0,0,11,1,1,1,1,1,1,1,1,1,1,1,1
1,1,1,1,1,1,1,1,1,16,1,1,0,0,0,0,0,0,15,9,0,0,0,0,0,9,0,0,0,0,0,9,11,1,1,1,1,1,1,1,1,1,1,1,1
1,1,1,1,1,1,1,1,1,16,1,1,0,0,0,0,0,0,0,0,0,0,0,0,0,0,0,0,0,0,0,0,11,1,1,1,1,1,1,1,1,1,1,1,1
1,1,1,1,1,1,1,1,1,1,11,11,11,11,11,11,11,11,11,0,0,0,0,0,0,0,0,0,0,0,0,0,11,1,1,1,1,1,1,1,1,1,1,1,1
1,1,1,1,1,1,1,1,1,1,1,1,1,1,1,1,1,1,11,0,0,0,0,0,0,0,0,0,0,0,0,0,11,1,1,1,1,1,1,1,1,1,1,1,1
1,1,1,1,1,1,1,1,1,1,1,1,1,1,1,1,1,1,11,0,0,0,0,0,0,0,0,0,0,0,0,0,11,1,1,1,1,1,1,1,1,1,1,1,1
1,1,1,1,1,1,1,1,1,1,1,1,1,1,1,1,1,1,11,9,0,0,0,0,0,9,0,0,0,0,0,9,11,1,1,1,1,1,1,1,1,1,1,1,1
1,1,1,1,1,1,1,1,1,1,1,1,1,1,1,1,1,1,11,0,0,0,0,0,0,0,0,0,0,0,0,0,11,1,1,1,1,1,1,1,1,1,1,1,1
1,1,1,1,1,1,1,1,1,1,1,1,1,1,1,1,1,1,11,9,0,0,0,0,0,9,0,0,0,0,0,9,11,1,1,1,1,1,1,1,1,1,1,1,1
1,1,1,1,1,1,1,1,1,1,1,1,1,1,1,1,1,1,11,0,0,0,0,0,0,0,0,0,0,0,0,0,11,1,1,1,1,1,1,1,1,1,1,1,1
1,1,1,1,1,1,1,1,1,1,1,1,1,1,1,1,1,1,11,9,0,0,0,0,0,9,0,0,0,0,0,9,11,1,1,1,1,1,1,1,1,1,1,1,1
1,1,1,1,1,1,1,1,1,1,1,1,1,1,1,1,1,1,11,0,0,0,0,0,0,0,0,0,0,0,0,0,11,1,1,1,1,1,1,1,1,1,1,1,1
1,1,1,1,1,1,1,1,1,1,1,1,1,1,1,1,1,1,1,9,11,11,11,11,11,9,11,11,11,11,11,9,1,1,1,1,1,1,1,1,1,1,1,1,1
1,1,1,1,1,1,1,1,1,1,1,1,1,1,1,1,1,1,1,1,1,1,1,1,1,1,1,1,1,1,1,1,1,1,1,1,1,1,1,1,1,1,1,1,1
1,1,1,1,1,1,1,1,1,1,1,1,1,1,1,1,1,1,1,1,1,1,1,1,1,1,1,1,1,1,1,1,1,1,1,1,1,1,1,1,1,1,1,1,1
1,1,1,1,1,1,1,1,1,1,1,1,1,1,1,1,1,1,1,1,1,1,1,1,1,1,1,1,1,1,1,1,1,1,1,1,1,1,1,1,1,1,1,1,1
endlayer

layer
1,1,1,1,1,1,1,1,1,1,1,1,1,1,1,1,1,1,1,1,1,1,1,1,1,1,1,1,1,1,1,1,1,1,1,1,1,1,1,1,1,1,1,1,1
1,1,1,1,1,1,1,1,1,1,1,1,1,1,1,1,1,1,1,1,1,1,1,1,1,1,1,1,1,1,1,1,1,1,1,1,1,1,1,1,1,1,1,1,1
1,1,1,1,1,1,1,1,1,1,1,1,1,1,1,1,1,1,1,1,1,1,1,1,1,1,1,1,1,1,1,1,1,1,1,1,1,1,1,1,1,1,1,1,1
1,1,1,1,1,1,1,1,1,1,1,1,1,1,1,1,1,1,1,1,1,1,1,1,1,1,1,1,1,1,1,1,1,1,1,1,1,1,1,1,1,1,1,1,1
1,1,1,1,1,1,1,1,1,1,1,1,1,1,1,1,1,1,1,1,1,1,1,1,1,1,1,1,1,1,1,1,1,1,1,1,1,1,1,1,1,1,1,1,1
1,1,1,1,1,1,1,1,1,1,1,1,1,1,1,1,1,1,1,1,1,1,1,1,1,1,1,1,1,1,1,1,1,1,1,1,1,1,1,1,1,1,1,1,1
1,1,1,1,1,1,1,1,1,1,1,1,1,1,1,1,1,1,1,1,1,1,1,1,1,1,1,1,1,1,1,1,1,1,1,1,1,1,1,1,1,1,1,1,1
1,1,1,1,1,1,1,1,1,1,1,1,1,1,1,1,1,1,1,1,1,1,1,1,1,1,1,1,1,1,1,1,1,1,1,1,1,1,1,1,1,1,1,1,1
1,1,1,1,1,1,1,1,1,11,11,11,11,1,1,1,1,1,1,1,1,1,1,1,1,17,1,1,1,1,1,1,1,1,1,1,1,1,1,1,1,1,1,1,1
1,1,1,1,1,1,1,1,16,1,1,1,0,11,11,11,11,11,11,9,11,11,11,11,11,9,11,11,11,11,11,9,1,1,1,1,1,1,1,1,1,1,1,1,1
1,1,1,1,1,1,1,1,16,1,1,1,0,11,11,11,18,11,11,9,11,11,18,11,11,9,11,11,18,11,11,9,1,1,1,1,1,1,1,1,1,1,1,1,1
1,1,1,1,1,1,1,1,16,1,1,1,0,11,11,11,11,11,11,9,11,11,11,11,11,9,11,11,11,11,11,9,1,1,1,1,1,1,1,1,1,1,1,1,1
1,1,1,1,1,1,1,1,1,11,11,11,11,1,1,1,1,1,1,9,11,11,11,11,11,9,11,11,11,11,11,9,1,1,1,1,1,1,1,1,1,1,1,1,1
1,1,1,1,1,1,1,1,1,1,1,1,1,1,1,1,1,1,1,9,11,11,18,11,11,9,11,11,18,11,11,9,1,1,1,1,1,1,1,1,1,1,1,1,1
1,1,1,1,1,1,1,1,1,1,1,1,1,1,1,1,1,1,1,9,11,11,11,11,11,9,11,11,11,11,11,9,1,1,1,1,1,1,1,1,1,1,1,1,1
1,1,1,1,1,1,1,1,1,1,1,1,1,1,1,1,1,1,1,9,11,11,11,11,11,9,11,11,11,11,11,9,1,1,1,1,1,1,1,1,1,1,1,1,1
1,1,1,1,1,1,1,1,1,1,1,1,1,1,1,1,1,1,1,9,11,11,18,11,11,9,11,11,18,11,11,9,1,1,1,1,1,1,1,1,1,1,1,1,1
1,1,1,1,1,1,1,1,1,1,1,1,1,1,1,1,1,1,1,9,11,11,11,11,11,9,11,11,11,11,11,9,1,1,1,1,1,1,1,1,1,1,1,1,1
1,1,1,1,1,1,1,1,1,1,1,1,1,1,1,1,1,1,1,9,11,11,11,11,11,9,11,11,11,11,11,9,1,1,1,1,1,1,1,1,1,1,1,1,1
1,1,1,1,1,1,1,1,1,1,1,1,1,1,1,1,1,1,1,9,11,11,11,11,11,9,11,11,11,11,11,9,1,1,1,1,1,1,1,1,1,1,1,1,1
1,1,1,1,1,1,1,1,1,1,1,1,1,1,1,1,1,1,1,9,11,11,11,11,11,9,11,11,11,11,11,9,1,1,1,1,1,1,1,1,1,1,1,1,1
1,1,1,1,1,1,1,1,1,1,1,1,1,1,1,1,1,1,1,1,1,1,1,1,1,1,1,1,1,1,1,1,1,1,1,1,1,1,1,1,1,1,1,1,1
1,1,1,1,1,1,1,1,1,1,1,1,1,1,1,1,1,1,1,1,1,1,1,1,1,1,1,1,1,1,1,1,1,1,1,1,1,1,1,1,1,1,1,1,1
1,1,1,1,1,1,1,1,1,1,1,1,1,1,1,1,1,1,1,1,1,1,1,1,1,1,1,1,1,1,1,1,1,1,1,1,1,1,1,1,1,1,1,1,1
1,1,1,1,1,1,1,1,1,1,1,1,1,1,1,1,1,1,1,1,1,1,1,1,1,1,1,1,1,1,1,1,1,1,1,1,1,1,1,1,1,1,1,1,1
endlayer

layer
1,1,1,1,1,1,1,1,1,1,1,1,1,1,1,1,1,1,1,1,1,1,1,1,1,1,1,1,1,1,1,1,1,1,1,1,1,1,1,1,1,1,1,1,1
1,1,1,1,1,1,1,1,1,1,1,1,1,1,1,1,1,1,1,1,1,1,1,1,1,1,1,1,1,1,1,1,1,1,1,1,1,1,1,1,1,1,1,1,1
1,1,1,1,1,1,1,1,1,1,1,1,1,1,1,1,1,1,1,1,1,1,1,1,1,1,1,1,1,1,1,1,1,1,1,1,1,1,1,1,1,1,1,1,1
1,1,1,1,1,1,1,1,1,1,1,1,1,1,1,1,1,1,1,1,1,1,1,1,1,1,1,1,1,1,1,1,1,1,1,1,1,1,1,1,1,1,1,1,1
1,1,1,1,1,1,1,1,1,1,1,1,1,1,1,1,1,1,1,1,1,1,1,1,1,1,1,1,1,1,1,1,1,1,1,1,1,1,1,1,1,1,1,1,1
1,1,1,1,1,1,1,1,1,1,1,1,1,1,1,1,1,1,1,1,1,1,1,1,1,1,1,1,1,1,1,1,1,1,1,1,1,1,1,1,1,1,1,1,1
1,1,1,1,1,1,1,1,1,1,1,1,1,1,1,1,1,1,1,1,1,1,1,1,1,1,1,1,1,1,1,1,0,1,1,1,1,1,1,1,1,1,1,1,1
1,1,1,1,1,1,1,1,1,1,1,1,1,1,1,1,1,1,1,1,1,1,1,1,1,1,1,1,1,1,1,1,1,1,1,1,1,1,1,1,1,1,1,1,1
1,1,1,1,1,1,1,1,11,11,11,11,1,1,1,1,1,1,1,1,1,1,1,1,1,1,1,1,1,1,1,1,1,1,1,1,1,1,1,1,1,1,1,1,1
1,1,1,1,1,1,1,16,1,1,1,1,11,1,1,1,1,1,1,1,1,1,1,1,1,1,1,1,1,1,1,1,1,1,1,1,1,1,1,1,1,1,1,1,1
1,1,1,1,1,1,1,16,1,1,1,1,11,1,1,1,1,1,1,1,1,1,1,1,1,1,1,1,1,1,1,1,1,1,1,1,1,1,1,1,1,1,1,1,1
1,1,1,1,1,1,1,16,1,1,1,1,11,1,1,1,1,1,1,1,1,1,1,1,1,1,1,1,1,1,1,1,1,1,1,1,1,1,1,1,1,1,1,1,1
1,1,1,1,1,1,1,1,11,11,11,11,1,1,1,1,1,1,1,1,1,1,1,1,1,1,1,1,1,1,1,1,1,1,1,1,1,1,1,1,1,1,1,1,1
1,1,1,1,1,1,1,1,1,1,1,1,1,1,1,1,1,1,1,1,1,1,1,1,1,1,1,1,1,1,1,1,1,1,1,1,1,1,1,1,1,1,1,1,1
1,1,1,1,1,1,1,1,1,1,1,1,1,1,1,1,1,1,1,1,1,1,1,1,1,1,1,1,1,1,1,1,1,1,1,1,1,1,1,1,1,1,1,1,1
1,1,1,1,1,1,1,1,1,1,1,1,1,1,1,1,1,1,1,1,1,1,1,1,1,1,1,1,1,1,1,1,1,1,1,1,1,1,1,1,1,1,1,1,1
1,1,1,1,1,1,1,1,1,1,1,1,1,1,1,1,1,1,1,1,1,1,1,1,1,1,1,1,1,1,1,1,1,1,1,1,1,1,1,1,1,1,1,1,1
1,1,1,1,1,1,1,1,1,1,1,1,1,1,1,1,1,1,1,1,1,1,1,1,1,1,1,1,1,1,1,1,1,1,1,1,1,1,1,1,1,1,1,1,1
1,1,1,1,1,1,1,1,1,1,1,1,1,1,1,1,1,1,1,1,1,1,1,1,1,1,1,1,1,1,1,1,1,1,1,1,1,1,1,1,1,1,1,1,1
1,1,1,1,1,1,1,1,0,1,1,1,1,1,1,1,1,1,1,1,1,1,1,1,1,1,1,1,1,1,1,1,1,1,1,1,1,1,1,1,1,1,1,1,1
1,1,1,1,1,1,1,1,1,1,1,1,1,1,1,1,1,1,1,1,1,1,1,1,1,1,1,1,1,1,1,1,1,1,1,1,1,1,1,1,1,1,1,1,1
1,1,1,1,1,1,1,1,1,1,1,1,1,1,1,1,1,1,1,1,1,1,1,1,1,1,1,1,1,1,1,1,1,1,1,1,1,1,1,1,1,1,1,1,1
1,1,1,1,1,1,1,1,1,1,1,1,1,1,1,1,1,1,1,1,1,1,1,1,1,1,1,1,1,1,1,1,1,1,1,1,1,1,1,1,1,1,1,1,1
1,1,1,1,1,1,1,1,1,1,1,1,1,1,1,1,1,1,1,1,1,1,1,1,1,1,1,1,1,1,1,1,1,1,1,1,1,1,1,1,1,1,1,1,1
1,1,1,1,1,1,1,1,1,1,1,1,1,1,1,1,1,1,1,1,1,1,1,1,1,1,1,1,1,1,1,1,1,1,1,1,1,1,1,1,1,1,1,1,1
endlayer

layer
1,1,1,1,1,1,1,1,1,1,1,1,1,1,1,1,1,1,1,1,1,1,1,1,1,1,1,1,1,1,1,1,1,1,1,1,1,1,1,1,1,1,1,1,1
1,1,1,1,1,1,1,1,1,1,1,1,1,1,1,1,1,1,1,1,1,1,1,1,1,1,1,1,1,1,1,1,1,1,1,1,1,1,1,1,1,1,1,1,1
1,1,1,1,1,1,1,1,1,1,1,1,1,1,1,1,1,1,1,1,1,1,1,1,1,1,1,1,1,1,1,1,1,1,1,1,1,1,1,1,1,1,1,1,1
1,1,1,1,1,1,1,1,1,1,1,1,1,1,1,1,1,1,1,1,1,1,1,1,0,1,1,1,1,1,1,1,1,1,1,1,1,1,1,1,1,1,1,1,1
1,1,1,1,1,1,1,1,1,1,1,1,1,1,1,1,1,1,1,1,1,1,1,1,1,1,1,1,1,1,1,1,1,1,1,1,1,1,1,1,1,1,1,1,1
1,1,1,1,1,1,1,1,1,1,1,1,1,1,1,1,1,1,1,1,1,1,1,1,1,1,1,1,1,1,1,1,1,1,1,1,1,1,1,1,1,1,1,1,1
1,1,1,1,1,1,1,1,1,1,1,1,1,1,1,1,1,1,1,1,1,1,1,1,1,1,1,1,1,1,1,1,0,1,1,1,1,1,1,1,1,1,1,1,1
1,1,1,1,1,1,1,1,1,1,1,1,1,1,1,1,1,1,1,1,1,1,1,1,1,1,1,1,1,1,1,1,1,1,1,1,1,1,1,1,1,1,1,1,1
1,1,1,1,1,1,1,11,11,11,11,1,1,1,1,1,1,1,1,1,1,1,1,1,1,1,1,1,1,1,1,1,1,1,1,1,1,1,1,1,1,1,1,1,1
1,1,1,1,1,1,16,1,1,1,1,11,1,1,1,1,1,1,1,1,1,1,1,1,1,1,1,1,1,1,1,1,1,1,1,1,1,1,1,1,1,1,1,1,1
1,1,1,1,1,1,16,1,1,1,1,11,1,1,1,1,1,1,1,1,1,1,1,1,1,1,1,1,1,1,1,1,1,1,1,1,1,1,1,1,1,1,1,1,1
1,1,1,1,1,1,16,1,1,1,1,11,1,1,1,1,1,1,1,1,1,1,1,1,1,1,1,1,1,1,1,1,1,1,1,1,1,1,1,1,1,1,1,1,1
1,1,1,1,1,1,1,11,11,11,11,1,1,1,1,1,1,1,1,1,1,1,1,1,1,1,1,1,1,1,1,1,1,1,1,1,1,1,1,1,1,1,1,1,1
1,1,1,1,1,1,1,1,1,1,1,1,1,1,1,1,1,1,1,1,1,1,1,1,1,1,1,1,1,1,1,1,1,1,1,1,1,1,1,1,1,1,1,1,1
1,1,1,1,1,1,1,1,1,1,1,1,1,1,0,1,1,1,1,1,1,1,1,1,1,1,1,1,1,1,1,1,1,1,1,1,1,1,1,1,1,1,1,1,1
1,1,1,1,1,1,1,1,1,1,1,1,1,1,1,1,1,1,1,1,1,1,1,1,1,1,1,1,1,1,1,1,1,1,1,1,1,1,1,1,1,1,1,1,1
1,1,1,1,1,1,17,17,17,1,1,1,1,1,1,1,1,1,1,1,1,1,1,1,1,1,1,1,1,1,1,1,1,1,1,1,1,1,1,1,1,1,1,1,1
1,1,1,1,1,17,17,17,17,17,1,1,1,1,1,1,1,1,1,1,1,1,1,1,1,1,1,1,1,1,1,1,1,1,1,1,1,1,1,1,1,1,1,1,1
1,1,1,1,1,17,17,17,17,17,1,1,1,1,1,1,1,1,1,1,1,1,1,1,1,1,1,1,1,1,1,1,1,1,1,1,1,1,1,1,1,1,1,1,1
1,1,1,1,1,17,17,17,17,17,1,1,1,1,1,1,1,1,1,1,1,1,1,1,1,1,1,1,1,1,1,1,1,1,1,1,1,1,1,1,1,1,1,1,1
1,1,1,1,1,1,17,17,17,1,1,1,1,1,1,1,1,1,1,1,1,1,1,1,1,1,1,1,1,1,1,1,1,1,1,1,1,1,1,1,1,1,1,1,1
1,1,1,1,1,1,1,1,1,1,1,1,1,1,1,1,1,1,1,1,1,1,1,1,1,1,1,1,1,1,1,1,1,1,1,1,1,0,1,1,1,1,1,1,1
1,1,1,1,1,1,1,1,1,1,1,1,1,1,1,1,1,1,1,1,1,1,1,1,1,1,1,1,1,1,1,1,1,1,1,1,1,1,1,1,1,1,1,1,1
1,1,1,1,1,1,1,1,1,1,1,1,1,1,1,1,1,1,1,1,1,1,1,1,1,1,1,1,1,1,1,1,1,1,1,1,1,1,1,1,1,1,1,1,1
1,1,1,1,1,1,1,1,1,1,1,1,1,1,1,1,1,1,1,1,1,1,1,1,1,1,1,1,1,1,1,1,1,1,1,1,1,1,1,1,1,1,1,1,1
endlayer

layer
16,16,16,16,16,16,16,16,16,16,16,16,16,16,16,16,16,16,16,16,16,16,16,16,16,16,16,16,16,16,16,16,16,16,16,16,16,16,16,16,16,16,16,16,16
16,16,16,16,16,16,16,16,16,16,16,16,16,16,16,16,16,16,16,16,16,16,16,16,16,16,16,16,16,16,16,16,16,16,16,16,16,16,16,16,16,16,16,16,16
16,16,1,1,1,1,1,1,1,1,1,1,1,1,1,1,16,1,1,1,9,9,9,9,9,9,9,1,1,1,1,1,1,1,16,1,1,1,1,1,1,1,1,16,16
16,16,1,1,1,1,1,1,1,1,1,1,1,1,1,1,16,1,1,1,9,12,12,12,12,12,9,19,19,19,19,19,19,19,19,19,19,19,19,19,19,19,1,16,16
16,16,1,1,1,1,1,1,1,1,1,1,1,1,1,1,16,1,1,1,9,12,12,2,12,12,9,19,19,19,19,19,19,19,19,19,19,19,19,19,19,19,1,16,16
16,16,1,1,1,1,1,1,1,1,1,1,1,1,1,1,16,1,1,1,9,12,12,12,12,12,9,19,19,19,19,19,19,19,19,19,19,19,19,19,19,19,1,16,16
16,16,1,1,1,1,1,1,1,1,1,1,1,1,1,1,16,1,1,1,9,12,12,12,12,12,9,19,19,19,19,19,19,19,19,19,19,19,19,19,19,19,1,16,16
16,16,1,1,1,1,1,1,1,1,1,1,1,1,1,1,16,1,1,1,9,12,12,12,12,12,9,19,19,19,19,19,19,19,19,19,19,19,19,19,19,19,1,16,16
16,16,1,1,1,1,11,11,11,11,1,1,1,1,1,1,16,1,1,1,9,12,12,12,12,12,9,19,19,19,19,19,19,19,19,19,19,19,19,19,19,19,1,16,16
16,16,16,16,16,16,1,1,1,1,11,1,1,9,9,9,12,9,9,9,12,12,12,12,12,12,20,9,9,9,12,9,9,9,19,19,19,19,19,19,19,19,1,16,16
16,16,16,16,16,16,1,1,1,1,11,1,1,9,12,12,12,12,12,12,12,12,12,12,12,12,12,12,12,12,12,12,12,9,19,19,19,19,19,19,19,19,1,16,16
16,16,16,16,16,16,1,1,1,1,11,1,1,9,12,12,12,12,12,12,12,12,12,12,12,12,12,12,12,12,12,12,12,9,19,19,19,19,19,19,19,19,1,16,16
16,16,1,1,1,1,11,11,11,11,1,1,1,9,12,12,12,12,12,0,12,12,12,12,12,12,12,2,12,12,12,12,12,9,19,19,19,19,19,19,19,19,16,16,16
16,16,1,1,1,1,1,1,1,1,1,1,1,9,12,12,12,12,12,12,12,12,12,12,12,12,12,12,12,12,12,12,12,9,19,19,19,19,19,19,19,19,1,16,16
16,16,1,1,1,1,1,1,1,1,1,1,1,9,12,12,12,12,12,12,12,12,12,12,12,12,12,12,12,12,12,12,12,9,19,19,19,19,19,19,19,19,1,16,16
16,16,1,1,1,1,1,1,1,1,1,1,1,9,9,9,12,9,9,9,12,12,12,12,12,12,12,9,9,9,12,9,9,9,19,19,19,19,19,19,19,19,1,16,16
16,16,1,1,1,1,17,17,17,1,1,1,1,1,1,1,16,1,1,1,9,12,12,4,12,12,9,19,19,19,19,19,19,19,19,19,19,19,19,19,19,19,1,16,16
16,16,1,1,1,17,1,1,1,17,1,1,1,1,1,1,16,1,1,1,9,12,12,12,12,12,9,19,19,19,19,19,19,19,19,19,19,19,19,19,19,19,1,16,16
16,16,1,1,1,17,1,21,1,17,1,1,1,1,1,1,16,1,1,1,9,12,12,12,12,12,9,19,19,19,19,19,19,19,19,19,19,19,19,19,19,19,1,16,16
16,16,1,1,1,17,1,1,1,17,1,1,1,1,1,1,16,1,1,1,9,12,12,12,12,12,9,19,19,19,19,19,19,19,19,19,19,19,19,19,19,19,1,16,16
16,16,1,1,1,1,17,17,17,1,1,1,1,1,1,1,16,1,1,1,9,12,12,12,12,12,9,19,19,19,19,19,19,19,19,19,19,19,19,19,19,19,1,16,16
16,16,1,1,1,1,1,1,1,1,1,1,1,1,1,1,16,1,1,1,9,12,12,12,12,12,9,19,19,19,19,19,19,19,19,19,19,19,19,19,19,19,1,16,16
16,16,1,1,1,1,1,1,1,1,1,1,1,1,1,1,16,1,1,1,9,9,9,9,9,9,9,1,1,1,1,1,1,1,16,1,1,1,1,1,1,1,1,16,16
16,16,16,16,16,16,16,16,16,16,16,16,16,16,16,16,16,16,16,16,16,16,16,16,16,16,16,16,16,16,16,16,16,16,16,16,16,16,16,16,16,16,16,16,16
16,16,16,16,16,16,16,16,16,16,16,16,16,16,16,16,16,16,16,16,16,16,16,16,16,16,16,16,16,16,16,16,16,16,16,16,16,16,16,16,16,16,16,16,16
endlayer

layer
1,1,1,1,1,1,1,1,1,1,1,1,1,1,1,1,1,1,1,1,1,1,1,1,1,1,1,1,1,1,1,1,1,1,1,1,1,1,1,1,1,1,1,1,1
1,1,1,1,1,1,1,1,1,1,1,1,1,1,1,1,1,1,1,1,1,1,1,1,1,1,1,1,1,1,1,1,1,1,1,1,1,1,1,1,1,1,1,1,1
1,1,1,1,1,1,1,31,14,14,31,1,1,1,1,1,1,1,1,1,9,9,9,9,9,9,9,22,23,23,23,23,23,22,1,22,23,23,23,23,23,23,22,1,1
1,1,1,1,1,1,1,31,31,31,31,1,1,1,1,1,1,1,1,1,9,0,0,4,0,0,9,1,1,1,1,1,1,1,1,1,26,1,1,1,1,1,23,1,1
1,1,1,1,1,1,1,1,1,1,1,1,1,1,1,1,1,1,1,1,9,0,27,27,27,0,9,13,1,1,1,1,1,1,1,1,1,1,1,1,24,1,23,1,1
1,1,1,1,1,1,1,1,1,1,1,1,1,1,1,1,1,1,1,1,9,0,0,0,0,0,9,14,1,1,1,1,1,1,1,1,1,1,1,1,25,1,23,1,1
1,1,1,1,1,1,1,1,1,1,1,1,1,1,1,1,1,1,1,1,9,0,0,0,0,0,9,14,1,1,1,1,1,1,1,1,1,1,1,1,24,1,23,1,1
1,1,1,1,1,1,1,1,1,1,1,1,1,1,1,1,1,1,1,1,9,0,0,0,0,0,9,13,1,1,1,1,1,1,1,1,1,1,1,1,1,1,23,1,1
1,1,1,1,1,1,22,23,23,23,22,1,1,1,1,1,1,1,1,1,9,0,29,30,29,29,9,1,1,1,1,1,1,1,1,1,1,1,1,1,24,1,23,1,1
1,1,1,1,1,1,1,1,1,1,23,1,1,9,9,9,1,9,9,9,28,28,28,28,28,28,28,9,9,9,1,9,9,9,1,1,1,1,1,1,25,1,23,1,1
1,1,1,1,1,1,1,1,1,1,23,1,1,9,0,1,1,1,0,0,28,28,28,28,28,28,28,0,0,0,1,1,0,9,1,1,1,1,1,1,24,1,23,1,1
1,1,1,1,1,1,1,1,1,1,23,1,1,9,0,27,27,27,0,0,28,28,28,28,28,28,28,0,0,27,27,27,0,9,1,1,1,1,1,1,1,1,22,1,1
1,1,1,1,1,1,22,23,23,23,22,1,1,9,0,0,0,0,0,11,28,28,28,28,28,28,28,11,0,0,0,0,0,9,1,1,1,1,1,1,1,1,1,1,1
1,1,1,1,1,1,1,1,1,1,1,1,1,9,0,27,27,27,0,0,28,28,28,28,28,28,28,0,0,27,27,27,0,9,1,1,1,1,1,1,1,1,22,1,1
1,1,1,1,1,1,1,1,1,1,1,1,1,9,1,1,1,0,0,0,28,28,28,28,28,28,28,0,0,0,1,0,0,9,1,1,1,1,1,1,1,1,23,1,1
1,1,1,1,1,1,32,32,32,1,1,1,1,9,9,9,1,9,9,9,28,28,28,28,28,28,28,9,9,9,1,9,9,9,1,1,1,1,1,24,25,24,23,1,1
1,1,1,1,1,32,17,17,17,32,1,1,1,1,1,1,1,1,1,1,9,0,0,11,0,0,9,1,1,1,1,1,1,1,1,1,1,1,1,24,25,24,23,1,1
1,1,1,1,32,17,1,1,1,17,32,1,1,1,1,1,1,1,1,1,9,0,0,0,0,0,9,13,1,1,1,1,1,1,1,1,1,1,1,1,1,1,23,1,1
1,1,1,1,32,17,1,33,1,17,32,1,1,1,1,1,1,1,1,1,9,0,27,0,27,0,9,14,1,1,1,1,1,1,1,1,1,1,1,24,25,24,23,1,1
1,1,1,1,32,17,1,1,1,17,32,1,1,1,1,1,1,1,1,1,9,0,27,0,27,0,9,14,1,1,1,1,1,1,1,1,1,1,1,24,25,24,23,1,1
1,1,1,1,1,32,17,17,17,32,1,1,1,1,1,1,1,1,1,1,9,0,27,0,27,0,9,13,1,1,1,1,1,1,1,1,1,1,1,1,1,1,23,1,1
1,1,1,1,1,1,32,32,32,1,1,1,1,1,1,1,1,1,1,1,9,0,0,0,0,0,9,1,1,1,1,1,1,1,1,1,26,1,1,1,1,1,23,1,1
1,1,1,1,1,1,1,1,1,1,1,1,1,1,1,1,1,1,1,1,9,9,9,9,9,9,9,22,23,23,23,23,23,22,1,22,23,23,23,23,23,23,22,1,1
1,1,1,1,1,1,1,1,1,1,1,1,1,1,1,1,1,1,1,1,1,1,1,1,1,1,1,1,1,1,1,1,1,1,1,1,1,1,1,1,1,1,1,1,1
1,1,1,1,1,1,1,1,1,1,1,1,1,1,1,1,1,1,1,1,1,1,1,1,1,1,1,1,1,1,1,1,1,1,1,1,1,1,1,1,1,1,1,1,1
endlayer

layer
1,1,1,1,1,1,1,1,1,1,1,1,1,1,1,1,1,1,1,1,1,1,1,1,1,1,1,1,1,1,1,1,1,1,1,1,1,1,1,1,1,1,1,1,1
1,1,1,1,1,1,1,1,1,1,1,1,1,1,1,1,1,1,1,1,1,1,1,1,1,1,1,1,1,1,1,1,1,1,1,1,1,1,1,1,1,1,1,1,1
1,1,1,1,1,1,1,31,0,0,31,1,1,1,1,1,1,1,1,1,9,34,11,34,11,34,9,1,1,1,1,1,1,1,1,1,1,1,1,1,1,1,1,1,1
1,1,1,1,1,1,1,31,31,31,31,1,1,1,1,1,1,1,1,1,34,0,0,0,0,0,34,1,1,1,1,1,1,1,1,1,1,1,1,1,1,1,1,1,1
1,1,1,1,1,1,1,1,1,1,1,1,1,1,1,1,1,1,1,1,11,0,27,27,27,0,11,1,1,1,1,1,1,1,1,1,1,1,1,1,1,1,1,1,1
1,1,1,1,1,1,1,1,1,1,1,1,1,1,1,1,1,1,1,1,34,0,0,0,0,0,34,1,1,1,1,1,1,1,1,1,1,1,1,1,1,1,1,1,1
1,1,1,1,1,1,1,1,1,1,1,1,1,1,1,1,1,1,1,1,11,0,0,0,0,0,11,1,1,1,1,1,1,1,1,1,1,1,1,1,1,1,1,1,1
1,1,1,1,1,1,1,1,1,1,1,1,1,1,1,1,1,1,1,1,34,0,0,0,0,0,34,1,1,1,1,1,1,1,1,1,1,1,1,1,1,1,1,1,1
1,1,1,1,1,1,1,1,1,1,1,1,1,1,1,1,1,1,1,1,9,0,0,0,0,35,9,1,1,1,1,1,1,1,1,1,1,1,1,1,1,1,1,1,1
1,1,1,1,1,1,1,1,1,1,1,1,1,9,34,11,1,11,34,9,0,0,0,0,0,0,0,9,34,11,0,11,34,9,1,1,1,1,1,1,1,1,1,1,1
1,1,1,1,1,1,1,1,1,1,1,1,1,34,0,0,0,0,0,0,0,0,0,0,0,0,0,0,0,0,0,0,0,34,1,1,1,1,1,1,1,1,1,1,1
1,1,1,1,1,1,1,1,1,1,1,1,1,11,0,27,27,27,0,0,0,0,0,0,0,0,0,0,0,27,27,27,0,11,1,1,1,1,1,1,1,1,1,1,1
1,1,1,1,1,1,1,1,1,1,1,1,1,34,0,0,0,0,0,11,0,0,0,0,0,0,0,11,0,0,0,0,0,34,1,1,1,1,1,1,1,1,1,1,1
1,1,1,1,1,1,1,1,1,1,1,1,1,11,0,27,27,27,0,0,0,0,0,0,0,0,0,0,0,27,27,27,0,11,1,1,1,1,1,1,1,1,1,1,1
1,1,1,1,1,1,1,1,1,1,1,1,1,34,0,0,0,0,0,0,0,0,0,0,0,0,0,0,0,0,0,0,0,34,1,1,1,1,1,1,1,1,1,1,1
1,1,1,1,1,1,1,1,1,1,1,1,1,9,34,11,0,11,34,9,0,0,0,0,0,0,0,9,34,11,1,11,34,9,1,1,1,1,1,1,1,1,1,1,1
1,1,1,1,1,1,1,1,1,1,1,1,1,1,1,1,1,1,1,1,9,0,0,11,0,0,9,1,1,1,1,1,1,1,1,1,1,1,1,1,1,1,1,1,1
1,1,1,1,1,1,1,1,1,1,1,1,1,1,1,1,1,1,1,1,34,0,0,0,0,0,34,1,1,1,1,1,1,1,1,1,1,1,1,1,1,1,1,1,1
1,1,1,1,1,1,1,21,1,1,1,1,1,1,1,1,1,1,1,1,11,0,27,0,27,0,11,1,1,1,1,1,1,1,1,1,1,1,1,1,1,1,1,1,1
1,1,1,1,1,1,1,1,1,1,1,1,1,1,1,1,1,1,1,1,34,0,27,0,27,0,34,1,1,1,1,1,1,1,1,1,1,1,1,1,1,1,1,1,1
1,1,1,1,1,1,1,1,1,1,1,1,1,1,1,1,1,1,1,1,11,0,27,0,27,0,11,1,1,1,1,1,1,1,1,1,1,1,1,1,1,1,1,1,1
1,1,1,1,1,1,1,1,1,1,1,1,1,1,1,1,1,1,1,1,34,0,0,0,0,0,34,1,1,1,1,1,1,1,1,1,1,1,1,1,1,1,1,1,1
1,1,1,1,1,1,1,1,1,1,1,1,1,1,1,1,1,1,1,1,9,34,11,34,11,34,9,1,1,1,1,1,1,1,1,1,1,1,1,1,1,1,1,1,1
1,1,1,1,1,1,1,1,1,1,1,1,1,1,1,1,1,1,1,1,1,1,1,1,1,1,1,1,1,1,1,1,1,1,1,1,1,1,1,1,1,1,1,1,1
1,1,1,1,1,1,1,1,1,1,1,1,1,1,1,1,1,1,1,1,1,1,1,1,1,1,1,1,1,1,1,1,1,1,1,1,1,1,1,1,1,1,1,1,1
endlayer

layer
1,1,1,1,1,1,1,1,1,1,1,1,1,1,1,1,1,1,1,1,1,1,1,1,1,1,1,1,1,1,1,1,1,1,1,1,1,1,1,1,1,1,1,1,1
1,1,1,1,1,1,1,1,1,1,1,1,1,1,1,1,1,1,1,1,1,1,1,1,1,1,1,1,1,1,1,1,1,1,1,1,1,1,1,1,1,1,1,1,1
1,1,1,1,1,1,1,31,0,0,31,1,1,1,1,1,1,1,1,1,9,34,11,34,11,34,9,1,1,1,1,1,1,1,1,1,1,1,1,1,1,1,1,1,1
1,1,1,1,1,1,1,31,31,31,31,1,1,1,1,1,1,1,1,1,34,0,0,0,0,0,34,1,1,1,1,1,1,1,1,1,1,1,1,1,1,1,1,1,1
1,1,1,1,1,1,1,1,1,1,1,1,1,1,1,1,1,1,1,1,11,0,0,0,0,0,11,1,1,1,1,1,1,1,1,1,1,1,1,1,1,1,1,1,1
1,1,1,1,1,1,1,1,1,1,1,1,1,1,1,1,1,1,1,1,34,0,0,0,0,0,34,1,1,1,1,1,1,1,1,1,1,1,1,1,1,1,1,1,1
1,1,1,1,1,1,1,1,1,1,1,1,1,1,1,1,1,1,1,1,11,0,0,0,0,0,11,1,1,1,1,1,1,1,1,1,1,1,1,1,1,1,1,1,1
1,1,1,1,1,1,1,1,1,1,1,1,1,1,1,1,1,1,1,1,34,0,0,0,0,0,34,1,1,1,1,1,1,1,1,1,1,1,1,1,1,1,1,1,1
1,1,1,1,1,1,1,1,1,1,1,1,1,1,1,1,1,1,1,1,9,0,0,0,0,0,9,1,1,1,1,1,1,1,1,1,1,1,1,1,1,1,1,1,1
1,1,1,1,1,1,1,1,1,1,1,1,1,9,34,11,11,11,34,9,0,0,0,0,0,0,0,9,34,11,11,11,34,9,1,1,1,1,1,1,1,1,1,1,1
1,1,1,1,1,1,1,1,1,1,1,1,1,34,0,0,0,0,0,0,0,0,0,0,0,0,0,0,0,0,0,0,0,34,1,1,1,1,1,1,1,1,1,1,1
1,1,1,1,1,1,1,1,1,1,1,1,1,11,0,27,27,27,0,0,0,0,0,0,0,0,0,0,0,27,27,27,0,11,1,1,1,1,1,1,1,1,1,1,1
1,1,1,1,1,1,1,1,1,1,1,1,1,34,0,0,0,0,0,11,0,0,0,0,0,0,0,11,0,0,0,0,0,34,1,1,1,1,1,1,1,1,1,1,1
1,1,1,1,1,1,1,1,1,1,1,1,1,11,0,27,27,27,0,0,0,0,0,0,0,0,0,0,0,27,27,27,0,11,1,1,1,1,1,1,1,1,1,1,1
1,1,1,1,1,1,1,1,1,1,1,1,1,34,0,0,0,0,0,0,0,0,0,0,0,0,0,0,0,0,0,0,0,34,1,1,1,1,1,1,1,1,1,1,1
1,1,1,1,1,1,1,1,1,1,1,1,1,9,34,11,11,11,34,9,0,0,0,0,0,0,0,9,34,11,11,11,34,9,1,1,1,1,1,1,1,1,1,1,1
1,1,1,1,1,1,1,1,1,1,1,1,1,1,1,1,1,1,1,1,9,0,0,11,0,0,9,1,1,1,1,1,1,1,1,1,1,1,1,1,1,1,1,1,1
1,1,1,1,1,1,1,1,1,1,1,1,1,1,1,1,1,1,1,1,34,0,0,0,0,0,34,1,1,1,1,1,1,1,1,1,1,1,1,1,1,1,1,1,1
1,1,1,1,1,1,1,21,1,1,1,1,1,1,1,1,1,1,1,1,11,0,27,0,27,0,11,1,1,1,1,1,1,1,1,1,1,1,1,1,1,1,1,1,1
1,1,1,1,1,1,1,1,1,1,1,1,1,1,1,1,1,1,1,1,34,0,27,0,27,0,34,1,1,1,1,1,1,1,1,1,1,1,1,1,1,1,1,1,1
1,1,1,1,1,1,1,1,1,1,1,1,1,1,1,1,1,1,1,1,11,0,27,0,27,0,11,1,1,1,1,1,1,1,1,1,1,1,1,1,1,1,1,1,1
1,1,1,1,1,1,1,1,1,1,1,1,1,1,1,1,1,1,1,1,34,0,0,0,0,0,34,1,1,1,1,1,1,1,1,1,1,1,1,1,1,1,1,1,1
1,1,1,1,1,1,1,1,1,1,1,1,1,1,1,1,1,1,1,1,9,34,11,34,11,34,9,1,1,1,1,1,1,1,1,1,1,1,1,1,1,1,1,1,1
1,1,1,1,1,1,1,1,1,1,1,1,1,1,1,1,1,1,1,1,1,1,1,1,1,1,1,1,1,1,1,1,1,1,1,1,1,1,1,1,1,1,1,1,1
1,1,1,1,1,1,1,1,1,1,1,1,1,1,1,1,1,1,1,1,1,1,1,1,1,1,1,1,1,1,1,1,1,1,1,1,1,1,1,1,1,1,1,1,1
endlayer

layer
1,1,1,1,1,1,1,1,1,1,1,1,1,1,1,1,1,1,1,1,1,1,1,1,1,1,1,1,1,1,1,1,1,1,1,1,1,1,1,1,1,1,1,1,1
1,1,1,1,1,1,1,1,1,1,1,1,1,1,1,1,1,1,1,1,1,1,1,1,1,1,1,1,1,1,1,1,1,1,1,1,1,1,1,1,1,1,1,1,1
1,1,1,1,1,1,1,31,31,31,31,1,1,1,1,1,1,1,1,1,9,34,11,34,11,34,9,1,1,1,1,1,1,1,1,1,1,1,1,1,1,1,1,1,1
1,1,1,1,1,1,1,31,31,31,31,1,1,1,1,1,1,1,1,1,34,0,0,0,0,0,34,1,1,1,1,1,1,1,1,1,1,1,1,1,1,1,1,1,1
1,1,1,1,1,1,1,1,1,1,1,1,1,1,1,1,1,1,1,1,11,0,0,0,0,0,11,1,1,1,1,1,1,1,1,1,1,1,1,1,1,1,1,1,1
1,1,1,1,1,1,1,1,1,1,1,1,1,1,1,1,1,1,1,1,34,0,0,0,0,0,34,1,1,1,1,1,1,1,1,1,1,1,1,1,1,1,1,1,1
1,1,1,1,1,1,1,1,1,1,1,1,1,1,1,1,1,1,1,1,11,0,0,0,0,0,11,1,1,1,1,1,1,1,1,1,1,1,1,1,1,1,1,1,1
1,1,1,1,1,1,1,1,1,1,1,1,1,1,1,1,1,1,1,1,34,0,0,0,0,0,34,1,1,1,1,1,1,1,1,1,1,1,1,1,1,1,1,1,1
1,1,1,1,1,1,1,1,1,1,1,1,1,1,1,1,1,1,1,1,9,0,0,0,0,0,9,1,1,1,1,1,1,1,1,1,1,1,1,1,1,1,1,1,1
1,1,1,1,1,1,1,1,1,1,1,1,1,9,34,11,34,11,34,9,0,0,0,0,0,0,0,9,34,11,34,11,34,9,1,1,1,1,1,1,1,1,1,1,1
1,1,1,1,1,1,1,1,1,1,1,1,1,34,0,0,0,0,0,0,0,0,0,0,0,0,0,0,0,0,0,0,0,34,1,1,1,1,1,1,1,1,1,1,1
1,1,1,1,1,1,1,1,1,1,1,1,1,11,0,0,0,0,0,0,0,0,0,0,0,0,0,0,0,0,0,0,0,11,1,1,1,1,1,1,1,1,1,1,1
1,1,1,1,1,1,1,1,1,1,1,1,1,34,0,0,0,0,0,11,0,0,0,0,0,0,0,11,0,0,0,0,0,34,1,1,1,1,1,1,1,1,1,1,1
1,1,1,1,1,1,1,1,1,1,1,1,1,11,0,0,0,0,0,0,0,0,0,0,0,0,0,0,0,0,0,0,0,11,1,1,1,1,1,1,1,1,1,1,1
1,1,1,1,1,1,1,1,1,1,1,1,1,34,0,0,0,0,0,0,0,0,0,0,0,0,0,0,0,0,0,0,0,34,1,1,1,1,1,1,1,1,1,1,1
1,1,1,1,1,1,1,1,1,1,1,1,1,9,34,11,34,11,34,9,0,0,0,0,0,0,0,9,34,11,34,11,34,9,1,1,1,1,1,1,1,1,1,1,1
1,1,1,1,1,1,1,1,1,1,1,1,1,1,1,1,1,1,1,1,9,0,0,11,0,0,9,1,1,1,1,1,1,1,1,1,1,1,1,1,1,1,1,1,1
1,1,1,1,1,1,1,1,1,1,1,1,1,1,1,1,1,1,1,1,34,0,0,0,0,0,34,1,1,1,1,1,1,1,1,1,1,1,1,1,1,1,1,1,1
1,1,1,1,1,1,1,33,1,1,1,1,1,1,1,1,1,1,1,1,11,0,0,0,0,0,11,1,1,1,1,1,1,1,1,1,1,1,1,1,1,1,1,1,1
1,1,1,1,1,1,1,1,1,1,1,1,1,1,1,1,1,1,1,1,34,0,0,0,0,0,34,1,1,1,1,1,1,1,1,1,1,1,1,1,1,1,1,1,1
1,1,1,1,1,1,1,1,1,1,1,1,1,1,1,1,1,1,1,1,11,0,0,0,0,0,11,1,1,1,1,1,1,1,1,1,1,1,1,1,1,1,1,1,1
1,1,1,1,1,1,1,1,1,1,1,1,1,1,1,1,1,1,1,1,34,0,0,0,0,0,34,1,1,1,1,1,1,1,1,1,1,1,1,1,1,1,1,1,1
1,1,1,1,1,1,1,1,1,1,1,1,1,1,1,1,1,1,1,1,9,34,11,34,11,34,9,1,1,1,1,1,1,1,1,1,1,1,1,1,1,1,1,1,1
1,1,1,1,1,1,1,1,1,1,1,1,1,1,1,1,1,1,1,1,1,1,1,1,1,1,1,1,1,1,1,1,1,1,1,1,1,1,1,1,1,1,1,1,1
1,1,1,1,1,1,1,1,1,1,1,1,1,1,1,1,1,1,1,1,1,1,1,1,1,1,1,1,1,1,1,1,1,1,1,1,1,1,1,1,1,1,1,1,1
endlayer

layer
1,1,1,1,1,1,1,1,1,1,1,1,1,1,1,1,1,1,1,1,1,1,1,1,1,1,1,1,1,1,1,1,1,1,1,1,1,1,1,1,1,1,1,1,1
1,1,1,1,1,1,1,1,1,1,1,1,1,1,1,1,1,1,1,1,1,1,1,1,1,1,1,1,1,1,1,1,1,1,1,1,1,1,1,1,1,1,1,1,1
1,1,1,1,1,1,1,1,1,1,1,1,1,1,1,1,1,1,1,1,9,34,11,34,11,34,9,1,1,1,1,1,1,1,1,1,1,1,1,1,1,1,1,1,1
1,1,1,1,1,1,1,1,1,1,1,1,1,1,1,1,1,1,1,1,34,0,0,0,0,0,34,1,1,1,1,1,1,1,1,1,1,1,1,1,1,1,1,1,1
1,1,1,1,1,1,1,1,1,1,1,1,1,1,1,1,1,1,1,1,11,0,0,0,0,0,11,1,1,1,1,1,1,1,1,1,1,1,1,1,1,1,1,1,1
1,1,1,1,1,1,1,1,1,1,1,1,1,1,1,1,1,1,1,1,34,0,0,0,0,0,34,1,1,1,1,1,1,1,1,1,1,1,1,1,1,1,1,1,1
1,1,1,1,1,1,1,1,1,1,1,1,1,1,1,1,1,1,1,1,11,0,0,0,0,0,11,1,1,1,1,1,1,1,1,1,1,1,1,1,1,1,1,1,1
1,1,1,1,1,1,1,1,1,1,1,1,1,1,1,1,1,1,1,1,34,0,0,0,0,0,34,1,1,1,1,1,1,1,1,1,1,1,1,1,1,1,1,1,1
1,1,1,1,1,1,1,1,1,1,1,1,1,1,1,1,1,1,1,1,9,0,0,0,0,0,9,1,1,1,1,1,1,1,1,1,1,1,1,1,1,1,1,1,1
1,1,1,1,1,1,1,1,1,1,1,1,1,9,34,11,34,11,34,9,0,0,0,0,0,0,0,9,34,11,34,11,34,9,1,1,1,1,1,1,1,1,1,1,1
1,1,1,1,1,1,1,1,1,1,1,1,1,34,0,0,0,0,0,0,0,0,0,0,0,0,0,0,0,0,0,0,0,34,1,1,1,1,1,1,1,1,1,1,1
1,1,1,1,1,1,1,1,1,1,1,1,1,11,0,0,0,0,0,0,0,0,0,0,0,0,0,0,0,0,0,0,0,11,1,1,1,1,1,1,1,1,1,1,1
1,1,1,1,1,1,1,1,1,1,1,1,1,34,0,0,0,0,0,11,0,0,0,0,0,0,0,11,0,0,0,0,0,34,1,1,1,1,1,1,1,1,1,1,1
1,1,1,1,1,1,1,1,1,1,1,1,1,11,0,0,0,0,0,0,0,0,0,0,0,0,0,0,0,0,0,0,0,11,1,1,1,1,1,1,1,1,1,1,1
1,1,1,1,1,1,1,1,1,1,1,1,1,34,0,0,0,0,0,0,0,0,0,0,0,0,0,0,0,0,0,0,0,34,1,1,1,1,1,1,1,1,1,1,1
1,1,1,1,1,1,1,1,1,1,1,1,1,9,34,11,34,11,34,9,0,0,0,0,0,0,0,9,34,11,34,11,34,9,1,1,1,1,1,1,1,1,1,1,1
1,1,1,1,1,1,1,1,1,1,1,1,1,1,1,1,1,1,1,1,9,0,0,11,0,0,9,1,1,1,1,1,1,1,1,1,1,1,1,1,1,1,1,1,1
1,1,1,1,1,1,1,1,1,1,1,1,1,1,1,1,1,1,1,1,34,0,0,0,0,0,34,1,1,1,1,1,1,1,1,1,1,1,1,1,1,1,1,1,1
1,1,1,1,1,1,1,21,1,1,1,1,1,1,1,1,1,1,1,1,11,0,0,0,0,0,11,1,1,1,1,1,1,1,1,1,1,1,1,1,1,1,1,1,1
1,1,1,1,1,1,1,1,1,1,1,1,1,1,1,1,1,1,1,1,34,0,0,0,0,0,34,1,1,1,1,1,1,1,1,1,1,1,1,1,1,1,1,1,1
1,1,1,1,1,1,1,1,1,1,1,1,1,1,1,1,1,1,1,1,11,0,0,0,0,0,11,1,1,1,1,1,1,1,1,1,1,1,1,1,1,1,1,1,1
1,1,1,1,1,1,1,1,1,1,1,1,1,1,1,1,1,1,1,1,34,0,0,0,0,0,34,1,1,1,1,1,1,1,1,1,1,1,1,1,1,1,1,1,1
1,1,1,1,1,1,1,1,1,1,1,1,1,1,1,1,1,1,1,1,9,34,11,34,11,34,9,1,1,1,1,1,1,1,1,1,1,1,1,1,1,1,1,1,1
1,1,1,1,1,1,1,1,1,1,1,1,1,1,1,1,1,1,1,1,1,1,1,1,1,1,1,1,1,1,1,1,1,1,1,1,1,1,1,1,1,1,1,1,1
1,1,1,1,1,1,1,1,1,1,1,1,1,1,1,1,1,1,1,1,1,1,1,1,1,1,1,1,1,1,1,1,1,1,1,1,1,1,1,1,1,1,1,1,1
endlayer

layer
1,1,1,1,1,1,1,1,1,1,1,1,1,1,1,1,1,1,1,1,1,1,1,1,1,1,1,1,1,1,1,1,1,1,1,1,1,1,1,1,1,1,1,1,1
1,1,1,1,1,1,1,1,1,1,1,1,1,1,1,1,1,1,1,1,1,1,1,1,1,1,1,1,1,1,1,1,1,1,1,1,1,1,1,1,1,1,1,1,1
1,1,1,1,1,1,1,1,1,1,1,1,1,1,1,1,1,1,1,1,9,9,9,9,9,9,9,1,1,1,1,1,1,1,1,1,1,1,1,1,1,1,1,1,1
1,1,1,1,1,1,1,1,1,1,1,1,1,1,1,1,1,1,1,1,9,12,12,12,12,12,9,1,1,1,1,1,1,1,1,1,1,1,1,1,1,1,1,1,1
1,1,1,1,1,1,1,1,1,1,1,1,1,1,1,1,1,1,1,1,9,12,12,12,12,12,9,1,1,1,1,1,1,1,1,1,1,1,1,1,1,1,1,1,1
1,1,1,1,1,1,1,1,1,1,1,1,1,1,1,1,1,1,1,1,9,12,12,12,12,12,9,1,1,1,1,1,1,1,1,1,1,1,1,1,1,1,1,1,1
1,1,1,1,1,1,1,1,1,1,1,1,1,1,1,1,1,1,1,1,9,12,12,12,12,12,9,1,1,1,1,1,1,1,1,1,1,1,1,1,1,1,1,1,1
1,1,1,1,1,1,1,1,1,1,1,1,1,1,1,1,1,1,1,1,9,12,12,12,12,12,9,1,1,1,1,1,1,1,1,1,1,1,1,1,1,1,1,1,1
1,1,1,1,1,1,1,1,1,1,1,1,1,1,1,1,1,1,1,1,9,9,9,9,9,9,9,1,1,1,1,1,1,1,1,1,1,1,1,1,1,1,1,1,1
1,1,1,1,1,1,1,1,1,1,1,1,1,9,9,9,9,9,9,9,12,12,12,12,12,12,20,9,9,9,9,9,9,9,1,1,1,1,1,1,1,1,1,1,1
1,1,1,1,1,1,1,1,1,1,1,1,1,9,12,12,12,12,12,9,12,12,12,12,12,12,12,9,12,12,12,12,12,9,1,1,1,1,1,1,1,1,1,1,1
1,1,1,1,1,1,1,1,1,1,1,1,1,9,12,12,12,12,12,9,12,12,0,0,0,12,12,9,12,12,12,12,12,9,1,1,1,1,1,1,1,1,1,1,1
1,1,1,1,1,1,1,1,1,1,1,1,1,9,12,12,12,12,12,0,12,12,0,0,0,12,12,2,12,12,12,12,12,9,1,1,1,1,1,1,1,1,1,1,1
1,1,1,1,1,1,1,1,1,1,1,1,1,9,12,12,12,12,12,9,12,12,0,0,0,12,12,9,12,12,12,12,12,9,1,1,1,1,1,1,1,1,1,1,1
1,1,1,1,1,1,1,1,1,1,1,1,1,9,12,12,12,12,12,9,12,12,12,12,12,12,12,9,12,12,12,12,12,9,1,1,1,1,1,1,1,1,1,1,1
1,1,1,1,1,1,1,1,1,1,1,1,1,9,9,9,9,9,9,9,12,12,12,12,12,12,12,9,9,9,9,9,9,9,1,1,1,1,1,1,1,1,1,1,1
1,1,1,1,1,1,1,1,1,1,1,1,1,1,1,1,1,1,1,1,9,9,9,4,9,9,9,1,1,1,1,1,1,1,1,1,1,1,1,1,1,1,1,1,1
1,1,1,1,1,1,1,1,1,1,1,1,1,1,1,1,1,1,1,1,9,12,12,12,12,12,9,1,1,1,1,1,1,1,1,1,1,1,1,1,1,1,1,1,1
1,1,1,1,1,1,1,1,1,1,1,1,1,1,1,1,1,1,1,1,9,12,12,12,12,12,9,1,1,1,1,1,1,1,1,1,1,1,1,1,1,1,1,1,1
1,1,1,1,1,1,1,1,1,1,1,1,1,1,1,1,1,1,1,1,9,12,12,12,12,12,9,1,1,1,1,1,1,1,1,1,1,1,1,1,1,1,1,1,1
1,1,1,1,1,1,1,1,1,1,1,1,1,1,1,1,1,1,1,1,9,12,12,12,12,12,9,1,1,1,1,1,1,1,1,1,1,1,1,1,1,1,1,1,1
1,1,1,1,1,1,1,1,1,1,1,1,1,1,1,1,1,1,1,1,9,12,12,12,12,12,9,1,1,1,1,1,1,1,1,1,1,1,1,1,1,1,1,1,1
1,1,1,1,1,1,1,1,1,1,1,1,1,1,1,1,1,1,1,1,9,9,9,9,9,9,9,1,1,1,1,1,1,1,1,1,1,1,1,1,1,1,1,1,1
1,1,1,1,1,1,1,1,1,1,1,1,1,1,1,1,1,1,1,1,1,1,1,1,1,1,1,1,1,1,1,1,1,1,1,1,1,1,1,1,1,1,1,1,1
1,1,1,1,1,1,1,1,1,1,1,1,1,1,1,1,1,1,1,1,1,1,1,1,1,1,1,1,1,1,1,1,1,1,1,1,1,1,1,1,1,1,1,1,1
endlayer

layer
1,1,1,1,1,1,1,1,1,1,1,1,1,1,1,1,1,1,1,1,1,1,1,1,1,1,1,1,1,1,1,1,1,1,1,1,1,1,1,1,1,1,1,1,1
1,1,1,1,1,1,1,1,1,1,1,1,1,1,1,1,1,1,1,1,1,1,1,1,1,1,1,1,1,1,1,1,1,1,1,1,1,1,1,1,1,1,1,1,1
1,1,1,1,1,1,1,1,1,1,1,1,1,1,1,1,1,1,1,1,9,34,11,34,11,34,9,1,1,1,1,1,1,1,1,1,1,1,1,1,1,1,1,1,1
1,1,1,1,1,1,1,1,1,1,1,1,1,1,1,1,1,1,1,1,34,0,0,0,0,0,34,1,1,1,1,1,1,1,1,1,1,1,1,1,1,1,1,1,1
1,1,1,1,1,1,1,1,1,1,1,1,1,1,1,1,1,1,1,1,11,0,27,0,27,0,11,1,1,1,1,1,1,1,1,1,1,1,1,1,1,1,1,1,1
1,1,1,1,1,1,1,1,1,1,1,1,1,1,1,1,1,1,1,1,34,0,27,0,27,0,34,1,1,1,1,1,1,1,1,1,1,1,1,1,1,1,1,1,1
1,1,1,1,1,1,1,1,1,1,1,1,1,1,1,1,1,1,1,1,11,0,27,0,27,0,11,1,1,1,1,1,1,1,1,1,1,1,1,1,1,1,1,1,1
1,1,1,1,1,1,1,1,1,1,1,1,1,1,1,1,1,1,1,1,34,0,0,0,0,0,34,1,1,1,1,1,1,1,1,1,1,1,1,1,1,1,1,1,1
1,1,1,1,1,1,1,1,1,0,1,1,1,1,1,1,1,1,1,1,9,0,0,11,0,0,9,1,1,1,1,1,1,1,1,1,1,1,1,1,1,1,1,1,1
1,1,1,1,1,1,1,1,1,0,1,1,1,9,34,11,34,11,34,9,0,0,0,0,0,0,0,9,34,11,34,11,34,9,1,1,1,1,1,1,1,1,1,1,1
1,1,1,1,1,1,1,1,1,0,1,1,1,34,36,37,36,37,36,0,0,38,38,38,38,38,0,0,36,37,36,37,36,34,1,1,1,1,1,1,1,1,1,1,1
1,1,1,1,1,1,1,1,1,0,1,1,1,11,0,0,0,0,0,0,0,38,0,0,0,38,0,0,0,0,0,0,0,11,1,1,1,1,1,1,1,1,1,1,1
1,1,1,1,1,1,1,1,1,1,1,1,1,34,0,0,0,0,0,11,0,38,0,0,0,38,0,11,0,0,0,0,0,34,1,1,1,1,1,1,1,1,1,1,1
1,1,1,1,1,1,1,1,1,1,1,1,1,11,0,27,27,27,0,0,0,38,0,0,0,38,0,0,0,27,27,27,0,11,1,1,1,1,1,1,1,1,1,1,1
1,1,1,1,1,1,1,1,1,1,1,1,1,34,0,0,0,0,0,0,0,38,38,38,38,38,0,0,0,0,0,0,0,34,1,1,1,1,1,1,1,1,1,1,1
1,1,1,1,1,1,1,1,1,1,1,1,1,9,34,11,34,11,34,9,0,0,0,0,0,0,0,9,34,11,34,11,34,9,1,1,1,1,1,1,1,1,1,1,1
1,1,1,1,1,1,1,1,1,1,1,1,1,1,1,1,1,1,1,1,9,0,0,11,0,0,9,1,1,1,1,1,1,1,1,1,1,1,1,1,1,1,1,1,1
1,1,1,1,1,1,1,1,1,1,1,1,1,1,1,1,1,1,1,1,34,0,0,0,0,0,34,1,1,1,1,1,1,1,1,1,1,1,1,1,1,1,1,1,1
1,1,1,1,1,1,1,1,1,1,1,1,1,1,1,1,1,1,1,1,11,0,27,0,27,0,11,1,1,1,1,1,1,1,1,1,1,1,1,1,1,1,1,1,1
1,1,1,1,1,1,1,1,1,1,1,1,1,1,1,1,1,1,1,1,34,0,27,0,27,0,34,1,1,1,1,1,1,1,1,1,1,1,1,1,1,1,1,1,1
1,1,1,1,1,1,1,1,1,1,1,1,1,1,1,1,1,1,1,1,11,0,27,0,27,0,11,1,1,1,1,1,1,1,1,1,1,1,1,1,1,1,1,1,1
1,1,1,1,1,1,1,1,1,1,1,1,1,1,1,1,1,1,1,1,34,0,0,0,0,0,34,1,1,1,1,1,1,1,1,1,1,1,1,1,1,1,1,1,1
1,1,1,1,1,1,1,1,1,1,1,1,1,1,1,1,1,1,1,1,9,34,11,34,11,34,9,1,1,1,1,1,1,1,1,1,1,1,1,1,1,1,1,1,1
1,1,1,1,1,1,1,1,1,1,1,1,1,1,1,1,1,1,1,1,1,1,1,1,1,1,1,1,1,1,1,1,1,1,1,1,1,1,1,1,1,1,1,1,1
1,1,1,1,1,1,1,1,1,1,1,1,1,1,1,1,1,1,1,1,1,1,1,1,1,1,1,1,1,1,1,1,1,1,1,1,1,1,1,1,1,1,1,1,1
endlayer

layer
1,1,1,1,1,1,1,1,1,1,1,1,1,1,1,1,1,1,1,1,1,1,1,1,1,1,1,1,1,1,1,1,1,1,1,1,1,1,1,1,1,1,1,1,1
1,1,1,1,1,1,1,1,1,1,1,1,1,1,1,1,1,1,1,1,1,1,1,1,1,1,1,1,1,1,1,1,1,1,1,1,1,1,1,1,1,1,1,1,1
1,1,1,1,1,1,1,1,1,1,1,1,1,1,1,1,1,1,1,1,9,34,11,34,11,34,9,1,1,1,1,1,1,1,1,1,1,1,1,1,1,1,1,1,1
1,1,1,1,1,1,1,1,1,1,1,1,1,1,1,1,1,1,1,1,34,0,0,0,0,0,34,1,1,1,1,1,1,1,1,1,1,1,1,1,1,1,1,1,1
1,1,1,1,1,1,1,1,1,1,1,1,1,1,1,1,1,1,1,1,11,0,27,0,27,0,11,1,1,1,1,1,1,1,1,1,1,1,1,1,1,1,1,1,1
1,1,1,1,1,1,1,1,1,1,1,1,1,1,1,1,1,1,1,1,34,0,27,0,27,0,34,1,1,1,1,1,1,1,1,1,1,1,1,1,1,1,1,1,1
1,1,1,1,1,1,1,1,1,1,1,1,1,1,1,1,1,1,1,1,11,0,27,0,27,0,11,1,1,1,1,1,1,1,1,1,1,1,1,1,1,1,1,1,1
1,1,1,1,1,1,1,1,1,1,1,1,1,1,1,1,1,1,1,1,34,0,0,0,0,0,34,1,1,1,1,1,1,1,1,1,1,1,1,1,1,1,1,1,1
1,1,1,1,1,1,1,1,0,0,0,1,1,1,1,1,1,1,1,1,9,0,0,11,0,0,9,1,1,1,1,1,1,1,1,1,1,1,1,1,1,1,1,1,1
1,1,1,1,1,1,1,1,0,0,1,1,1,9,34,11,34,11,34,9,0,0,0,0,0,0,0,9,34,11,34,11,34,9,1,1,1,1,1,1,1,1,1,1,1
1,1,1,1,1,1,1,1,0,0,1,1,1,34,0,0,0,0,0,0,0,0,0,0,0,0,0,0,0,0,0,0,0,34,1,1,1,1,1,1,1,1,1,1,1
1,1,1,1,1,1,1,1,1,0,1,1,1,11,0,0,0,0,0,0,0,0,0,0,0,0,0,0,0,0,0,0,0,11,1,1,1,1,1,1,1,1,1,1,1
1,1,1,1,1,1,1,1,1,1,1,1,1,34,0,0,0,0,0,11,0,0,0,0,0,0,0,11,0,0,0,0,0,34,1,1,1,1,1,1,1,1,1,1,1
1,1,1,1,1,1,1,1,1,1,1,1,1,11,0,27,27,27,0,0,0,0,0,0,0,0,0,0,0,27,27,27,0,11,1,1,1,1,1,1,1,1,1,1,1
1,1,1,1,1,1,1,1,1,1,1,1,1,34,0,0,0,0,0,0,0,0,0,0,0,0,0,0,0,0,0,0,0,34,1,1,1,1,1,1,1,1,1,1,1
1,1,1,1,1,1,1,1,1,1,1,1,1,9,34,11,34,11,34,9,0,0,0,0,0,0,0,9,34,11,34,11,34,9,1,1,1,1,1,1,1,1,1,1,1
1,1,1,1,1,1,1,1,1,1,1,1,1,1,1,1,1,1,1,1,9,0,0,11,0,0,9,1,1,1,1,1,1,1,1,1,1,1,1,1,1,1,1,1,1
1,1,1,1,1,1,1,1,1,1,1,1,1,1,1,1,1,1,1,1,34,0,0,0,0,0,34,1,1,1,1,1,1,1,1,1,1,1,1,1,1,1,1,1,1
1,1,1,1,1,1,1,1,1,1,1,1,1,1,1,1,1,1,1,1,11,0,27,0,27,0,11,1,1,1,1,1,1,1,1,1,1,1,1,1,1,1,1,1,1
1,1,1,1,1,1,1,1,1,1,1,1,1,1,1,1,1,1,1,1,34,0,27,0,27,0,34,1,1,1,1,1,1,1,1,1,1,1,1,1,1,1,1,1,1
1,1,1,1,1,1,1,1,1,1,1,1,1,1,1,1,1,1,1,1,11,0,27,0,27,0,11,1,1,1,1,1,1,1,1,1,1,1,1,1,1,1,1,1,1
1,1,1,1,1,1,1,1,1,1,1,1,1,1,1,1,1,1,1,1,34,0,0,0,0,0,34,1,1,1,1,1,1,1,1,1,1,1,1,1,1,1,1,1,1
1,1,1,1,1,1,1,1,1,1,1,1,1,1,1,1,1,1,1,1,9,34,11,34,11,34,9,1,1,1,1,1,1,1,1,1,1,1,1,1,1,1,1,1,1
1,1,1,1,1,1,1,1,1,1,1,1,1,1,1,1,1,1,1,1,1,1,1,1,1,1,1,1,1,1,1,1,1,1,1,1,1,1,1,1,1,1,1,1,1
1,1,1,1,1,1,1,1,1,1,1,1,1,1,1,1,1,1,1,1,1,1,1,1,1,1,1,1,1,1,1,1,1,1,1,1,1,1,1,1,1,1,1,1,1
endlayer

layer
1,1,1,1,1,1,1,1,1,1,1,1,1,1,1,1,1,1,1,1,1,1,1,1,1,1,1,1,1,1,1,1,1,1,1,1,1,1,1,1,1,1,1,1,1
1,1,1,1,1,1,1,1,1,1,1,1,1,1,1,1,1,1,1,1,1,1,1,1,1,1,1,1,1,1,1,1,1,1,1,1,1,1,1,1,1,1,1,1,1
1,1,1,1,1,1,1,1,1,1,1,1,1,1,1,1,1,1,1,1,9,34,11,34,11,34,9,1,1,1,1,1,1,1,1,1,1,1,1,1,1,1,1,1,1
1,1,1,1,1,1,1,1,1,1,1,1,1,1,1,1,1,1,1,1,34,0,0,0,0,0,34,1,1,1,1,1,1,1,1,1,1,1,1,1,1,1,1,1,1
1,1,1,1,1,1,1,1,1,1,1,1,1,1,1,1,1,1,1,1,11,0,0,0,0,0,11,1,1,1,1,1,1,1,1,1,1,1,1,1,1,1,1,1,1
1,1,1,1,1,1,1,1,1,1,1,1,1,1,1,1,1,1,1,1,34,0,0,0,0,0,34,1,1,1,1,1,1,1,1,1,1,1,1,1,1,1,1,1,1
1,1,1,1,1,1,1,1,1,1,1,1,1,1,1,1,1,1,1,1,11,0,0,0,0,0,11,1,1,1,1,1,1,1,1,1,1,1,1,1,1,1,1,1,1
1,1,1,1,1,1,1,1,0,0,1,1,1,1,1,1,1,1,1,1,34,0,0,0,0,0,34,1,1,1,1,1,1,1,1,1,1,1,1,1,1,1,1,1,1
1,1,1,1,1,1,1,1,0,0,0,1,1,1,1,1,1,1,1,1,9,0,0,11,0,0,9,1,1,1,1,1,1,1,1,1,1,1,1,1,1,1,1,1,1
1,1,1,1,1,1,1,0,0,0,0,1,1,9,34,11,34,11,34,9,0,0,0,0,0,0,0,9,34,11,34,11,34,9,1,1,1,1,1,1,1,1,1,1,1
1,1,1,1,1,1,1,0,0,0,0,1,1,34,0,0,0,0,0,0,0,0,0,0,0,0,0,0,0,0,0,0,0,34,1,1,1,1,1,1,1,1,1,1,1
1,1,1,1,1,1,1,1,1,0,1,1,1,11,0,0,0,0,0,0,0,0,0,0,0,0,0,0,0,0,0,0,0,11,1,1,1,1,1,1,1,1,1,1,1
1,1,1,1,1,1,1,1,1,1,1,1,1,34,0,0,0,0,0,11,0,0,0,0,0,0,0,11,0,0,0,0,0,34,1,1,1,1,1,1,1,1,1,1,1
1,1,1,1,1,1,1,1,1,1,1,1,1,11,0,0,0,0,0,0,0,0,0,0,0,0,0,0,0,0,0,0,0,11,1,1,1,1,1,1,1,1,1,1,1
1,1,1,1,1,1,1,1,1,1,1,1,1,34,0,0,0,0,0,0,0,0,0,0,0,0,0,0,0,0,0,0,0,34,1,1,1,1,1,1,1,1,1,1,1
1,1,1,1,1,1,1,1,1,1,1,1,1,9,34,11,34,11,34,9,0,0,0,0,0,0,0,9,34,11,34,11,34,9,1,1,1,1,1,1,1,1,1,1,1
1,1,1,1,1,1,1,1,1,1,1,1,1,1,1,1,1,1,1,1,9,0,0,11,0,0,9,1,1,1,1,1,1,1,1,1,1,1,1,1,1,1,1,1,1
1,1,1,1,1,1,1,1,1,1,1,1,1,1,1,1,1,1,1,1,34,0,0,0,0,0,34,1,1,1,1,1,1,1,1,1,1,1,1,1,1,1,1,1,1
1,1,1,1,1,1,1,1,1,1,1,1,1,1,1,1,1,1,1,1,11,0,0,0,0,0,11,1,1,1,1,1,1,1,1,1,1,1,1,1,1,1,1,1,1
1,1,1,1,1,1,1,1,1,1,1,1,1,1,1,1,1,1,1,1,34,0,0,0,0,0,34,1,1,1,1,1,1,1,1,1,1,1,1,1,1,1,1,1,1
1,1,1,1,1,1,1,1,1,1,1,1,1,1,1,1,1,1,1,1,11,0,0,0,0,0,11,1,1,1,1,1,1,1,1,1,1,1,1,1,1,1,1,1,1
1,1,1,1,1,1,1,1,1,1,1,1,1,1,1,1,1,1,1,1,34,0,0,0,0,0,34,1,1,1,1,1,1,1,1,1,1,1,1,1,1,1,1,1,1
1,1,1,1,1,1,1,1,1,1,1,1,1,1,1,1,1,1,1,1,9,34,11,34,11,34,9,1,1,1,1,1,1,1,1,1,1,1,1,1,1,1,1,1,1
1,1,1,1,1,1,1,1,1,1,1,1,1,1,1,1,1,1,1,1,1,1,1,1,1,1,1,1,1,1,1,1,1,1,1,1,1,1,1,1,1,1,1,1,1
1,1,1,1,1,1,1,1,1,1,1,1,1,1,1,1,1,1,1,1,1,1,1,1,1,1,1,1,1,1,1,1,1,1,1,1,1,1,1,1,1,1,1,1,1
endlayer

layer
39,39,39,39,39,39,39,39,39,39,39,39,39,39,39,39,39,39,39,39,39,39,39,39,39,39,39,39,39,39,39,39,39,39,39,39,39,39,39,39,39,39,39,39,39
39,39,39,39,39,39,39,39,39,39,39,39,39,39,39,39,39,39,39,39,39,39,39,39,39,39,39,39,39,39,39,39,39,39,39,39,39,39,39,39,39,39,39,39,39
39,39,39,39,39,39,39,39,39,39,39,39,39,39,39,39,39,39,39,39,9,34,11,34,11,34,9,39,39,39,39,39,39,39,39,39,39,39,39,39,39,39,39,39,39
39,39,39,39,39,39,39,39,39,39,39,39,39,39,39,39,39,39,39,39,34,0,0,0,0,0,34,39,39,39,39,39,39,39,39,39,39,39,39,39,39,39,39,39,39
39,39,39,39,39,39,39,39,39,39,39,39,39,39,39,39,39,39,39,39,11,0,0,0,0,0,11,39,39,39,39,39,39,39,39,39,39,39,39,39,39,39,39,39,39
39,39,39,39,39,39,39,39,39,39,39,39,39,39,39,39,39,39,39,39,34,0,0,0,0,0,34,39,39,39,39,39,39,39,39,39,39,39,39,39,39,39,39,39,39
39,39,39,39,39,39,39,39,39,0,39,39,39,39,39,39,39,39,39,39,11,0,0,0,0,0,11,39,39,39,39,39,39,39,39,39,39,39,39,39,39,39,39,39,39
39,39,39,39,39,39,39,0,0,0,0,39,39,39,39,39,39,39,39,39,34,0,0,0,0,0,34,39,39,39,39,39,39,39,39,39,39,39,39,39,39,39,39,39,39
39,39,39,39,39,39,39,0,0,0,0,0,39,39,39,39,39,39,39,39,9,0,0,11,0,0,9,39,39,39,39,39,39,39,39,39,39,39,39,39,39,39,39,39,39
39,39,39,39,39,39,0,0,0,0,0,39,39,9,34,11,34,11,34,9,0,0,0,0,0,0,0,9,34,11,34,11,34,9,39,39,39,39,39,39,39,39,39,39,39
39,39,39,39,39,39,0,0,0,0,0,0,39,34,0,0,0,0,0,0,0,0,0,0,0,0,0,0,0,0,0,0,0,34,39,39,39,39,39,39,39,39,39,39,39
39,39,39,39,39,39,39,39,0,0,0,39,39,11,0,0,0,0,0,0,0,0,0,0,0,0,0,0,0,0,0,0,0,11,39,39,39,39,39,39,39,39,39,39,39
39,39,39,39,39,39,39,39,39,0,39,39,39,34,0,0,0,0,0,11,0,0,0,0,0,0,0,11,0,0,0,0,0,34,39,39,39,39,39,39,39,39,39,39,39
39,39,39,39,39,39,39,39,39,39,39,39,39,11,0,0,0,0,0,0,0,0,0,0,0,0,0,0,0,0,0,0,0,11,39,39,39,39,39,39,39,39,39,39,39
39,39,39,39,39,39,39,39,39,39,39,39,39,34,0,0,0,0,0,0,0,0,0,0,0,0,0,0,0,0,0,0,0,34,39,39,39,39,39,39,39,39,39,39,39
39,39,39,39,39,39,39,39,39,39,39,39,39,9,34,11,34,11,34,9,0,0,0,0,0,0,0,9,34,11,34,11,34,9,39,39,39,39,39,39,39,39,39,39,39
39,39,39,39,39,39,39,39,39,39,39,39,39,39,39,39,39,39,39,39,9,0,0,11,0,0,9,39,39,39,39,39,39,39,39,39,39,39,39,39,39,39,39,39,39
39,39,39,39,39,39,39,39,39,39,39,39,39,39,39,39,39,39,39,39,34,0,0,0,0,0,34,39,39,39,39,39,39,39,39,39,39,39,39,39,39,39,39,39,39
39,39,39,39,39,39,39,39,39,39,39,39,39,39,39,39,39,39,39,39,11,0,0,0,0,0,11,39,39,39,39,39,39,39,39,39,39,39,39,39,39,39,39,39,39
39,39,39,39,39,39,39,39,39,39,39,39,39,39,39,39,39,39,39,39,34,0,0,0,0,0,34,39,39,39,39,39,39,39,39,39,39,39,39,39,39,39,39,39,39
39,39,39,39,39,39,39,39,39,39,39,39,39,39,39,39,39,39,39,39,11,0,0,0,0,0,11,39,39,39,39,39,39,39,39,39,39,39,39,39,39,39,39,39,39
39,39,39,39,39,39,39,39,39,39,39,39,39,39,39,39,39,39,39,39,34,0,0,0,0,0,34,39,39,39,39,39,39,39,39,39,39,39,39,39,39,39,39,39,39
39,39,39,39,39,39,39,39,39,39,39,39,39,39,39,39,39,39,39,39,9,34,11,34,11,34,9,39,39,39,39,39,39,39,39,39,39,39,39,39,39,39,39,39,39
39,39,39,39,39,39,39,39,39,39,39,39,39,39,39,39,39,39,39,39,39,39,39,39,39,39,39,39,39,39,39,39,39,39,39,39,39,39,39,39,39,39,39,39,39
39,39,39,39,39,39,39,39,39,39,39,39,39,39,39,39,39,39,39,39,39,39,39,39,39,39,39,39,39,39,39,39,39,39,39,39,39,39,39,39,39,39,39,39,39
endlayer

layer
0,0,0,0,0,0,0,0,0,0,0,0,0,0,0,0,0,0,0,0,0,0,0,0,0,0,0,0,0,0,0,0,0,0,0,0,0,0,0,0,0,0,0,0,0
0,0,0,0,0,0,0,0,0,0,0,0,0,0,0,0,0,0,0,0,0,0,0,0,0,0,0,0,0,0,0,0,0,0,0,0,0,0,0,0,0,0,0,0,0
0,0,0,0,0,0,0,0,0,0,0,0,0,0,0,0,0,0,0,0,9,9,9,9,9,9,9,0,0,0,0,0,0,0,0,0,0,0,0,0,0,0,0,0,0
0,0,0,0,0,0,0,0,0,0,0,0,0,0,0,0,0,0,0,0,9,11,11,11,11,11,9,0,0,0,0,0,0,0,0,0,0,0,0,0,0,0,0,0,0
0,0,0,0,0,0,0,0,0,0,0,0,0,0,0,0,0,0,0,0,9,11,40,40,40,11,9,0,0,0,0,0,0,0,0,0,0,0,0,0,0,0,0,0,0
0,0,0,0,0,0,0,0,0,0,0,0,0,0,0,0,0,0,0,0,9,11,40,40,40,11,9,0,0,0,0,0,0,0,0,0,0,0,0,0,0,0,0,0,0
0,0,0,0,0,0,0,0,0,0,0,0,0,0,0,0,0,0,0,0,9,11,11,11,11,11,9,0,0,0,0,0,0,0,0,0,0,0,0,0,0,0,0,0,0
0,0,0,0,0,0,0,0,0,0,0,0,0,0,0,0,0,0,0,0,9,9,9,9,9,9,9,0,0,0,0,0,0,0,0,0,0,0,0,0,0,0,0,0,0
0,0,0,0,0,0,0,0,0,0,0,0,0,0,0,0,0,0,0,0,9,0,0,11,0,0,9,0,0,0,0,0,0,0,0,0,0,0,0,0,0,0,0,0,0
0,0,0,0,0,0,0,0,0,0,0,0,0,9,9,9,9,9,9,9,0,0,0,0,0,0,0,9,9,9,9,9,9,9,0,0,0,0,0,0,0,0,0,0,0
0,0,0,0,0,0,0,0,0,0,0,0,0,9,11,11,11,11,9,0,0,0,0,0,0,0,0,0,9,11,11,11,11,9,0,0,0,0,0,0,0,0,0,0,0
0,0,0,0,0,0,0,0,0,0,0,0,0,9,11,40,40,11,9,0,0,0,0,0,0,0,0,0,9,11,40,40,11,9,0,0,0,0,0,0,0,0,0,0,0
0,0,0,0,0,0,0,0,0,0,0,0,0,9,11,40,40,11,9,11,0,0,0,0,0,0,0,11,9,11,40,40,11,9,0,0,0,0,0,0,0,0,0,0,0
0,0,0,0,0,0,0,0,0,0,0,0,0,9,11,40,40,11,9,0,0,0,0,0,0,0,0,0,9,11,40,40,11,9,0,0,0,0,0,0,0,0,0,0,0
0,0,0,0,0,0,0,0,0,0,0,0,0,9,11,11,11,11,9,0,0,0,0,0,0,0,0,0,9,11,11,11,11,9,0,0,0,0,0,0,0,0,0,0,0
0,0,0,0,0,0,0,0,0,0,0,0,0,9,9,9,9,9,9,9,0,0,0,0,0,0,0,9,9,9,9,9,9,9,0,0,0,0,0,0,0,0,0,0,0
0,0,0,0,0,0,0,0,0,0,0,0,0,0,0,0,0,0,0,0,9,0,0,11,0,0,9,0,0,0,0,0,0,0,0,0,0,0,0,0,0,0,0,0,0
0,0,0,0,0,0,0,0,0,0,0,0,0,0,0,0,0,0,0,0,9,9,9,9,9,9,9,0,0,0,0,0,0,0,0,0,0,0,0,0,0,0,0,0,0
0,0,0,0,0,0,0,0,0,0,0,0,0,0,0,0,0,0,0,0,9,11,11,11,11,11,9,0,0,0,0,0,0,0,0,0,0,0,0,0,0,0,0,0,0
0,0,0,0,0,0,0,0,0,0,0,0,0,0,0,0,0,0,0,0,9,11,40,40,40,11,9,0,0,0,0,0,0,0,0,0,0,0,0,0,0,0,0,0,0
0,0,0,0,0,0,0,0,0,0,0,0,0,0,0,0,0,0,0,0,9,11,40,40,40,11,9,0,0,0,0,0,0,0,0,0,0,0,0,0,0,0,0,0,0
0,0,0,0,0,0,0,0,0,0,0,0,0,0,0,0,0,0,0,0,9,11,11,11,11,11,9,0,0,0,0,0,0,0,0,0,0,0,0,0,0,0,0,0,0
0,0,0,0,0,0,0,0,0,0,0,0,0,0,0,0,0,0,0,0,9,9,9,9,9,9,9,0,0,0,0,0,0,0,0,0,0,0,0,0,0,0,0,0,0
0,0,0,0,0,0,0,0,0,0,0,0,0,0,0,0,0,0,0,0,0,0,0,0,0,0,0,0,0,0,0,0,0,0,0,0,0,0,0,0,0,0,0,0,0
0,0,0,0,0,0,0,0,0,0,0,0,0,0,0,0,0,0,0,0,0,0,0,0,0,0,0,0,0,0,0,0,0,0,0,0,0,0,0,0,0,0,0,0,0
endlayer

layer
0,0,0,0,0,0,0,0,0,0,0,0,0,0,0,0,0,0,0,0,0,0,0,0,0,0,0,0,0,0,0,0,0,0,0,0,0,0,0,0,0,0,0,0,0
0,0,0,0,0,0,0,0,0,0,0,0,0,0,0,0,0,0,0,0,0,0,0,0,0,0,0,0,0,0,0,0,0,0,0,0,0,0,0,0,0,0,0,0,0
0,0,0,0,0,0,0,0,0,0,0,0,0,0,0,0,0,0,0,0,0,0,0,0,0,0,0,0,0,0,0,0,0,0,0,0,0,0,0,0,0,0,0,0,0
0,0,0,0,0,0,0,0,0,0,0,0,0,0,0,0,0,0,0,0,0,0,0,0,0,0,0,0,0,0,0,0,0,0,0,0,0,0,0,0,0,0,0,0,0
0,0,0,0,0,0,0,0,0,0,0,0,0,0,0,0,0,0,0,0,0,0,0,0,0,0,0,0,0,0,0,0,0,0,0,0,0,0,0,0,0,0,0,0,0
0,0,0,0,0,0,0,0,0,0,0,0,0,0,0,0,0,0,0,0,0,0,0,0,0,0,0,0,0,0,0,0,0,0,0,0,0,0,0,0,0,0,0,0,0
0,0,0,0,0,0,0,0,0,0,0,0,0,0,0,0,0,0,0,0,0,0,0,0,0,0,0,0,0,0,0,0,0,0,0,0,0,0,0,0,0,0,0,0,0
0,0,0,0,0,0,0,0,0,0,0,0,0,0,0,0,0,0,0,0,0,0,0,0,0,0,0,0,0,0,0,0,0,0,0,0,0,0,0,0,0,0,0,0,0
0,0,0,0,0,0,0,0,0,0,0,0,0,0,0,0,0,0,0,0,9,9,9,9,9,9,9,0,0,0,0,0,0,0,0,0,0,0,0,0,0,0,0,0,0
0,0,0,0,0,0,0,0,0,0,0,0,0,0,0,0,0,0,0,9,0,0,0,0,0,0,0,9,0,0,0,0,0,0,0,0,0,0,0,0,0,0,0,0,0
0,0,0,0,0,0,0,0,0,0,0,0,0,0,0,0,0,0,0,9,0,0,0,0,0,0,0,9,0,0,0,0,0,0,0,0,0,0,0,0,0,0,0,0,0
0,0,0,0,0,0,0,0,0,0,0,0,0,0,0,0,0,0,0,9,0,0,0,0,0,0,0,9,0,0,0,0,0,0,0,0,0,0,0,0,0,0,0,0,0
0,0,0,0,0,0,0,0,0,0,0,0,0,0,0,0,0,0,0,9,0,0,0,0,0,0,0,9,0,0,0,0,0,0,0,0,0,0,0,0,0,0,0,0,0
0,0,0,0,0,0,0,0,0,0,0,0,0,0,0,0,0,0,0,9,0,0,0,0,0,0,0,9,0,0,0,0,0,0,0,0,0,0,0,0,0,0,0,0,0
0,0,0,0,0,0,0,0,0,0,0,0,0,0,0,0,0,0,0,9,0,0,0,0,0,0,0,9,0,0,0,0,0,0,0,0,0,0,0,0,0,0,0,0,0
0,0,0,0,0,0,0,0,0,0,0,0,0,0,0,0,0,0,0,9,0,0,0,0,0,0,0,9,0,0,0,0,0,0,0,0,0,0,0,0,0,0,0,0,0
0,0,0,0,0,0,0,0,0,0,0,0,0,0,0,0,0,0,0,0,9,9,9,9,9,9,9,0,0,0,0,0,0,0,0,0,0,0,0,0,0,0,0,0,0
0,0,0,0,0,0,0,0,0,0,0,0,0,0,0,0,0,0,0,0,0,0,0,0,0,0,0,0,0,0,0,0,0,0,0,0,0,0,0,0,0,0,0,0,0
0,0,0,0,0,0,0,0,0,0,0,0,0,0,0,0,0,0,0,0,0,0,0,0,0,0,0,0,0,0,0,0,0,0,0,0,0,0,0,0,0,0,0,0,0
0,0,0,0,0,0,0,0,0,0,0,0,0,0,0,0,0,0,0,0,0,0,0,0,0,0,0,0,0,0,0,0,0,0,0,0,0,0,0,0,0,0,0,0,0
0,0,0,0,0,0,0,0,0,0,0,0,0,0,0,0,0,0,0,0,0,0,0,0,0,0,0,0,0,0,0,0,0,0,0,0,0,0,0,0,0,0,0,0,0
0,0,0,0,0,0,0,0,0,0,0,0,0,0,0,0,0,0,0,0,0,0,0,0,0,0,0,0,0,0,0,0,0,0,0,0,0,0,0,0,0,0,0,0,0
0,0,0,0,0,0,0,0,0,0,0,0,0,0,0,0,0,0,0,0,0,0,0,0,0,0,0,0,0,0,0,0,0,0,0,0,0,0,0,0,0,0,0,0,0
0,0,0,0,0,0,0,0,0,0,0,0,0,0,0,0,0,0,0,0,0,0,0,0,0,0,0,0,0,0,0,0,0,0,0,0,0,0,0,0,0,0,0,0,0
0,0,0,0,0,0,0,0,0,0,0,0,0,0,0,0,0,0,0,0,0,0,0,0,0,0,0,0,0,0,0,0,0,0,0,0,0,0,0,0,0,0,0,0,0
endlayer

layer
0,0,0,0,0,0,0,0,0,0,0,0,0,0,0,0,0,0,0,0,0,0,0,0,0,0,0,0,0,0,0,0,0,0,0,0,0,0,0,0,0,0,0,0,0
0,0,0,0,0,0,0,0,0,0,0,0,0,0,0,0,0,0,0,0,0,0,0,0,0,0,0,0,0,0,0,0,0,0,0,0,0,0,0,0,0,0,0,0,0
0,0,0,0,0,0,0,0,0,0,0,0,0,0,0,0,0,0,0,0,0,0,0,0,0,0,0,0,0,0,0,0,0,0,0,0,0,0,0,0,0,0,0,0,0
0,0,0,0,0,0,0,0,0,0,0,0,0,0,0,0,0,0,0,0,0,0,0,0,0,0,0,0,0,0,0,0,0,0,0,0,0,0,0,0,0,0,0,0,0
0,0,0,0,0,0,0,0,0,0,0,0,0,0,0,0,0,0,0,0,0,0,0,0,0,0,0,0,0,0,0,0,0,0,0,0,0,0,0,0,0,0,0,0,0
0,0,0,0,0,0,0,0,0,0,0,0,0,0,0,0,0,0,0,0,0,0,0,0,0,0,0,0,0,0,0,0,0,0,0,0,0,0,0,0,0,0,0,0,0
0,0,0,0,0,0,0,0,0,0,0,0,0,0,0,0,0,0,0,0,0,0,0,0,0,0,0,0,0,0,0,0,0,0,0,0,0,0,0,0,0,0,0,0,0
0,0,0,0,0,0,0,0,0,0,0,0,0,0,0,0,0,0,0,0,0,0,0,0,0,0,0,0,0,0,0,0,0,0,0,0,0,0,0,0,0,0,0,0,0
0,0,0,0,0,0,0,0,0,0,0,0,0,0,0,0,0,0,0,0,0,0,0,0,0,0,0,0,0,0,0,0,0,0,0,0,0,0,0,0,0,0,0,0,0
0,0,0,0,0,0,0,0,0,0,0,0,0,0,0,0,0,0,0,0,11,11,11,11,11,11,11,0,0,0,0,0,0,0,0,0,0,0,0,0,0,0,0,0,0
0,0,0,0,0,0,0,0,0,0,0,0,0,0,0,0,0,0,0,0,11,40,40,40,40,40,11,0,0,0,0,0,0,0,0,0,0,0,0,0,0,0,0,0,0
0,0,0,0,0,0,0,0,0,0,0,0,0,0,0,0,0,0,0,0,11,40,40,40,40,40,11,0,0,0,0,0,0,0,0,0,0,0,0,0,0,0,0,0,0
0,0,0,0,0,0,0,0,0,0,0,0,0,0,0,0,0,0,0,0,11,40,40,40,40,40,11,0,0,0,0,0,0,0,0,0,0,0,0,0,0,0,0,0,0
0,0,0,0,0,0,0,0,0,0,0,0,0,0,0,0,0,0,0,0,11,40,40,40,40,40,11,0,0,0,0,0,0,0,0,0,0,0,0,0,0,0,0,0,0
0,0,0,0,0,0,0,0,0,0,0,0,0,0,0,0,0,0,0,0,11,40,40,40,40,40,11,0,0,0,0,0,0,0,0,0,0,0,0,0,0,0,0,0,0
0,0,0,0,0,0,0,0,0,0,0,0,0,0,0,0,0,0,0,0,11,11,11,11,11,11,11,0,0,0,0,0,0,0,0,0,0,0,0,0,0,0,0,0,0
0,0,0,0,0,0,0,0,0,0,0,0,0,0,0,0,0,0,0,0,0,0,0,0,0,0,0,0,0,0,0,0,0,0,0,0,0,0,0,0,0,0,0,0,0
0,0,0,0,0,0,0,0,0,0,0,0,0,0,0,0,0,0,0,0,0,0,0,0,0,0,0,0,0,0,0,0,0,0,0,0,0,0,0,0,0,0,0,0,0
0,0,0,0,0,0,0,0,0,0,0,0,0,0,0,0,0,0,0,0,0,0,0,0,0,0,0,0,0,0,0,0,0,0,0,0,0,0,0,0,0,0,0,0,0
0,0,0,0,0,0,0,0,0,0,0,0,0,0,0,0,0,0,0,0,0,0,0,0,0,0,0,0,0,0,0,0,0,0,0,0,0,0,0,0,0,0,0,0,0
0,0,0,0,0,0,0,0,0,0,0,0,0,0,0,0,0,0,0,0,0,0,0,0,0,0,0,0,0,0,0,0,0,0,0,0,0,0,0,0,0,0,0,0,0
0,0,0,0,0,0,0,0,0,0,0,0,0,0,0,0,0,0,0,0,0,0,0,0,0,0,0,0,0,0,0,0,0,0,0,0,0,0,0,0,0,0,0,0,0
0,0,0,0,0,0,0,0,0,0,0,0,0,0,0,0,0,0,0,0,0,0,0,0,0,0,0,0,0,0,0,0,0,0,0,0,0,0,0,0,0,0,0,0,0
0,0,0,0,0,0,0,0,0,0,0,0,0,0,0,0,0,0,0,0,0,0,0,0,0,0,0,0,0,0,0,0,0,0,0,0,0,0,0,0,0,0,0,0,0
0,0,0,0,0,0,0,0,0,0,0,0,0,0,0,0,0,0,0,0,0,0,0,0,0,0,0,0,0,0,0,0,0,0,0,0,0,0,0,0,0,0,0,0,0
endlayer

