weight=10
embed_into_distance=13
dimensions=26,45,25
max_cut_in=2



rule1=0,100,250
rule2=0,100,1
rule3=0,100,311
rule4=0,100,2799-6
rule5=0,100,2799-7,2798-4,2799-8
rule6=0,50,313
rule7=0,100,327
rule8=0,100,2787-1
rule9=0,100,4
rule10=0,100,2843-14,2843-14,2843-14,2843-14,2843
rule11=0,100,2835-2,2835-2,2835-2,2835-2,2835-2,2835-2,2835-2,2835-1,2835-1,2835-0
rule12=0,100,66-1
rule13=0,100,2843-4
rule14=0,100,3134-10
rule15=0,100,113
rule16=0,100,2835-12
rule17=0,100,44
rule18=0,100,2761-15,2761-15,2761-15,2762-13,2762-13,2762-13,2762-13,2762-13,2762-13,2762-13
rule19=0,100,35-11
rule20=0,100,2010-0
rule21=0,100,250,250,250,250,1476-3
rule22=0,100,2843-4
rule23=0,100,2835-6
rule24=0,100,2542-0
rule25=0,100,2835-5
rule26=0,100,2835-4
rule27=0,100,2516-0
rule28=0,100,2763-15,2763-15,2764-13,2764-13,2764-13,2764-13,2764-13,2764-13,2764-13
rule29=0,100,47,2837-7,2837-5,2837-8
rule30=0,100,2291-2
rule31=0,100,2245-2
rule32=5,100,2844-1,2844-2,2844-3
rule33=0,100,2777-10
rule34=0,100,2248-0
rule35=0,100,35-15
rule36=0,100,3225-3
rule37=0,100,2835-7
rule38=0,100,140-10
rule39=0,100,2802-7
rule40=0,100,2291-1
rule41=0,100,2245-1
rule42=0,100,2788-9


layer
1,1,1,1,1,1,1,1,1,1,1,1,1,1,1,1,1,1,1,1,1,1,1,1,1
1,3,1,1,1,2,2,2,2,2,1,1,1,1,1,1,1,1,1,1,1,1,1,1,1
1,2,2,3,1,2,1,1,3,1,1,2,2,2,2,2,1,1,1,1,1,1,1,1,1
1,2,1,1,1,2,1,1,2,2,2,2,1,1,1,1,1,1,1,1,1,1,1,1,1
1,2,1,1,2,2,2,2,2,2,1,1,1,1,1,1,1,1,1,1,1,1,1,1,1
1,2,1,1,2,1,1,1,1,1,1,2,2,2,2,1,1,1,1,1,1,1,1,1,1
1,2,1,1,2,1,3,1,1,1,1,2,1,1,2,1,1,1,1,1,1,1,1,1,1
1,2,1,1,2,1,2,2,1,1,1,2,1,1,2,1,1,1,1,1,1,1,1,1,1
1,2,2,2,2,1,2,2,2,2,2,2,1,1,2,1,1,1,1,1,1,1,1,1,1
1,1,1,1,2,1,2,2,1,1,1,2,1,1,2,1,1,1,1,1,1,1,1,1,1
1,1,1,1,2,1,1,1,1,1,1,2,1,1,2,1,1,1,1,1,1,1,1,1,1
1,1,1,1,2,2,2,3,1,1,1,2,1,1,2,1,1,1,1,1,1,1,1,1,1
1,1,1,1,2,1,2,1,1,1,1,2,1,1,2,1,1,1,1,1,1,1,1,1,1
1,2,2,2,2,2,2,2,1,1,1,2,1,1,2,1,1,1,1,1,1,1,1,1,1
1,2,1,1,2,1,1,1,1,1,1,2,1,1,2,1,1,1,1,1,1,1,1,1,1
1,2,1,1,2,2,2,2,1,1,1,2,1,3,2,2,2,1,1,1,1,1,1,1,1
1,2,1,1,2,1,1,2,2,2,2,2,1,1,2,1,1,1,1,1,1,1,1,1,1
1,2,2,2,2,1,1,2,1,1,1,1,1,1,2,1,1,1,1,1,1,1,1,1,1
1,2,1,1,2,2,2,2,1,1,1,1,1,1,1,1,1,1,1,1,1,1,1,1,1
1,2,1,1,2,1,1,1,1,1,1,1,1,1,1,1,1,1,1,1,1,1,1,1,1
1,2,2,2,2,1,1,1,1,1,1,1,1,1,1,1,1,1,1,1,1,1,1,1,1
1,1,1,1,2,1,1,1,1,1,1,1,1,1,1,1,1,1,1,1,1,1,1,1,1
1,1,1,1,2,1,1,1,1,1,1,1,1,1,3,1,1,1,1,1,1,1,1,1,1
1,2,2,2,2,1,1,1,1,1,1,1,1,1,1,1,1,1,1,1,1,1,1,1,1
1,2,1,1,2,2,1,1,1,1,1,1,1,3,1,1,1,1,1,1,1,1,1,1,1
1,2,1,1,2,1,1,1,1,1,1,1,1,1,1,1,1,1,1,1,1,1,1,1,1
1,2,1,1,2,1,1,1,1,1,1,1,1,1,1,3,1,1,1,1,1,1,1,1,1
1,1,1,1,2,1,1,1,1,1,1,1,1,1,1,1,1,1,1,1,1,1,1,1,1
1,1,2,2,2,2,2,1,2,2,2,2,2,2,1,1,1,1,1,1,1,1,1,1,1
1,1,2,2,2,2,2,3,2,1,1,2,1,1,1,3,1,1,1,1,1,1,1,1,1
1,3,2,2,2,2,2,1,2,1,1,2,1,1,2,2,1,1,1,1,1,1,1,1,1
1,1,2,2,2,2,2,1,2,1,1,2,1,1,3,2,1,1,1,1,1,1,1,1,1
1,1,2,2,2,2,2,2,2,1,1,2,1,1,2,2,1,1,1,1,1,1,1,1,1
1,1,1,1,2,1,1,1,1,1,1,2,2,2,2,2,1,1,1,1,1,1,1,1,1
1,1,1,1,2,1,1,1,1,1,1,2,1,1,1,1,1,1,1,1,1,1,1,1,1
1,1,1,1,2,1,1,1,1,1,1,2,1,1,1,1,1,1,1,1,1,1,1,1,1
1,1,3,1,2,1,1,2,1,1,1,2,1,1,1,1,1,1,1,1,1,1,1,1,1
1,1,2,1,2,1,1,2,1,1,1,2,1,1,1,1,1,1,1,1,1,1,1,1,1
1,1,2,2,2,2,2,2,1,1,1,2,1,1,1,1,1,1,1,1,1,1,1,1,1
1,1,1,1,1,1,1,2,1,1,1,2,1,1,1,1,1,1,1,1,1,1,1,1,1
1,1,1,1,1,1,1,2,1,1,1,2,1,1,1,1,1,1,1,1,1,1,1,1,1
1,1,1,1,1,1,1,2,1,1,1,1,1,1,1,1,1,1,1,1,1,1,1,1,1
1,1,1,1,1,3,2,2,1,1,1,1,1,1,1,1,1,1,1,1,1,1,1,1,1
1,1,1,1,1,1,1,1,1,1,1,1,1,1,1,1,1,1,1,1,1,1,1,1,1
1,1,1,1,1,1,1,1,1,1,1,1,1,1,1,1,1,1,1,1,1,1,1,1,1
endlayer

layer
1,1,1,1,1,5,5,5,5,5,1,1,1,1,1,1,1,1,1,1,1,1,1,1,1
1,5,5,1,5,0,0,0,0,7,5,5,5,5,5,5,1,1,4,4,4,1,1,1,1
5,0,6,5,5,0,5,5,5,5,5,0,0,0,0,0,2,2,4,4,4,1,1,1,1
5,0,5,1,5,8,5,5,0,0,0,0,5,5,5,5,1,1,4,4,4,1,1,1,1
5,0,5,5,0,0,0,0,0,0,5,5,5,5,5,1,1,1,4,4,4,1,1,1,1
5,0,5,5,0,5,5,5,5,5,5,0,0,0,0,5,1,1,4,4,4,1,1,1,1
5,0,5,5,0,5,5,5,1,1,5,0,5,5,0,5,1,1,4,4,4,1,1,1,1
5,0,5,5,0,5,0,0,5,5,5,0,5,5,0,5,1,1,4,4,4,1,1,1,1
5,0,0,0,0,5,0,0,0,0,0,0,5,5,0,5,1,1,4,4,4,1,1,1,1
1,5,5,5,0,5,0,0,5,5,5,0,5,5,0,5,1,1,4,4,4,1,1,1,1
1,1,1,5,0,5,5,5,1,1,5,0,5,5,0,5,1,1,4,4,4,1,1,1,1
1,1,1,5,0,0,0,5,1,1,5,0,5,5,0,5,1,1,4,4,4,1,1,1,1
1,5,5,5,5,5,0,5,1,1,5,0,5,5,0,5,1,1,4,4,4,1,1,1,1
5,0,0,0,0,0,0,0,5,1,5,0,5,5,0,5,1,1,4,4,4,1,1,1,1
5,0,5,5,0,5,5,5,1,1,5,0,5,6,0,5,5,1,4,4,4,1,1,1,1
5,0,5,5,0,0,0,0,5,5,5,0,5,5,0,0,0,5,4,4,4,1,1,1,1
5,0,5,5,5,5,5,0,0,0,0,0,5,5,0,5,5,1,4,4,4,1,1,1,1
5,0,0,0,0,5,5,0,5,5,5,5,1,5,0,5,1,1,4,4,4,1,1,1,1
5,0,5,5,0,0,0,0,5,1,1,5,5,5,5,1,1,1,4,4,4,1,1,1,1
5,0,5,5,5,5,5,5,1,1,5,0,0,0,0,5,1,1,4,4,4,1,1,1,1
5,0,0,0,0,5,1,1,1,1,5,0,5,0,0,5,1,1,4,4,4,1,1,1,1
1,5,5,5,0,5,1,1,1,1,5,0,5,6,0,5,1,1,4,4,4,1,1,1,1
1,5,5,5,0,5,1,1,1,1,5,0,5,5,5,1,1,1,4,4,4,1,1,1,1
5,0,0,0,0,5,5,5,5,5,5,0,5,1,1,1,1,3,4,4,4,1,1,1,1
5,0,5,5,0,0,5,1,1,0,0,0,5,5,1,1,1,1,4,4,4,1,1,1,1
5,0,5,5,0,5,5,5,5,5,5,0,5,6,5,1,1,1,4,4,4,1,1,1,1
5,0,5,5,0,5,1,1,1,1,5,0,0,0,5,5,1,1,4,4,4,1,1,1,1
1,5,5,5,0,5,5,1,5,5,5,5,5,5,5,1,5,1,4,4,4,1,1,1,1
1,5,0,0,0,0,0,5,0,0,0,0,0,0,5,1,5,1,4,4,4,1,1,1,1
1,5,0,0,0,0,0,5,0,5,5,0,5,5,5,5,1,1,4,4,4,1,1,1,1
1,5,0,0,0,0,0,5,0,5,5,0,5,5,6,1,5,1,4,4,4,1,1,1,1
1,5,0,0,0,0,0,5,0,5,5,0,5,5,5,5,1,1,4,4,4,1,1,1,1
1,5,6,0,0,0,0,0,0,5,5,0,5,5,0,0,5,1,4,4,4,1,1,1,1
1,1,5,5,0,5,5,5,5,1,5,0,0,0,0,0,5,1,4,4,4,1,1,1,1
1,1,1,5,0,5,1,1,1,1,5,0,5,5,5,5,1,1,4,4,4,1,1,1,1
1,1,1,5,0,5,1,5,1,1,5,0,5,1,1,1,1,1,4,4,4,1,1,1,1
1,1,5,5,0,5,5,0,5,1,5,0,5,1,1,1,1,1,4,4,4,1,1,1,1
1,5,0,5,0,5,5,0,5,1,5,0,5,1,1,1,1,1,4,4,4,1,1,1,1
1,5,0,0,0,0,0,0,5,1,5,0,5,1,1,1,1,1,4,4,4,1,1,1,1
1,1,5,5,5,5,5,0,5,1,5,0,5,1,1,1,1,1,4,4,4,1,1,1,1
1,1,1,1,1,1,5,0,5,1,5,0,5,1,1,1,1,1,4,4,4,1,1,1,1
1,1,1,1,1,1,5,0,5,1,1,2,2,2,2,2,1,1,4,4,4,1,1,1,1
1,1,1,1,1,5,0,0,5,1,1,2,2,2,2,2,2,2,4,4,4,1,1,1,1
1,1,1,1,1,1,5,5,1,1,3,2,2,2,2,2,1,1,4,4,4,1,1,1,1
1,1,1,1,1,1,5,5,1,1,1,1,1,1,1,1,1,1,1,1,1,1,1,1,1
endlayer

layer
1,1,1,1,1,5,5,5,5,5,1,1,1,1,1,1,1,1,9,9,9,9,1,1,1
1,5,5,1,5,0,0,0,0,0,5,5,5,5,5,5,5,10,0,12,0,10,1,1,1
5,0,0,5,5,0,5,5,5,5,5,0,0,0,0,0,0,0,0,12,0,5,1,1,1
5,0,5,1,5,5,5,5,0,0,0,0,5,5,5,5,5,5,0,12,0,5,1,1,1
5,0,5,5,0,0,0,0,0,0,5,5,5,5,5,1,1,5,0,12,0,5,1,1,1
5,0,5,5,0,5,5,5,5,5,5,0,0,0,0,5,1,5,0,12,0,5,1,1,1
5,0,5,5,0,5,5,5,1,1,5,0,5,5,0,5,1,5,0,12,0,5,1,1,1
5,0,5,5,0,5,0,0,5,5,5,0,5,5,0,5,1,10,0,12,0,10,1,1,1
5,0,0,0,0,5,0,0,0,0,0,0,5,5,0,5,1,5,0,12,0,5,1,1,1
1,5,5,5,0,5,0,0,5,5,5,0,5,5,0,5,1,5,0,12,0,5,1,1,1
1,1,1,5,0,5,5,5,1,1,5,0,5,5,0,5,1,5,0,12,0,5,1,1,1
1,1,1,5,0,0,0,5,1,1,5,0,5,5,0,5,1,5,0,12,0,5,1,1,1
1,5,5,5,5,5,0,5,1,1,5,0,5,5,0,5,1,11,0,12,0,11,1,1,1
5,0,0,0,0,0,0,0,5,1,5,0,5,5,0,5,1,10,0,12,0,10,1,1,1
5,0,5,5,0,5,5,5,1,1,5,0,5,5,0,5,5,5,0,12,0,11,1,1,1
5,0,5,5,0,0,0,0,5,5,5,0,5,5,0,0,0,5,0,12,0,11,1,1,1
5,0,5,5,5,5,5,0,0,0,0,0,5,5,0,5,5,5,0,12,0,11,1,1,1
5,0,0,0,0,5,5,0,5,5,5,5,1,5,0,5,1,5,0,12,0,11,1,1,1
5,0,5,5,0,0,0,0,5,1,1,5,5,5,5,1,1,5,0,12,0,11,1,1,1
5,0,5,5,5,5,5,5,5,1,5,0,0,0,0,5,1,10,0,12,0,10,1,1,1
5,0,0,0,0,5,1,1,1,1,5,0,5,0,0,5,1,5,0,12,0,11,1,1,1
1,5,5,5,0,5,1,1,1,1,5,0,5,0,0,5,1,5,0,12,0,11,1,1,1
1,5,5,5,0,5,1,1,1,1,5,0,5,5,5,1,1,5,0,12,0,11,1,1,1
5,0,0,0,0,5,5,5,5,5,5,0,5,1,1,1,1,5,0,12,0,11,1,1,1
5,0,5,5,0,0,5,1,0,0,0,0,5,1,1,1,1,5,0,12,0,11,1,1,1
5,0,5,5,0,5,5,5,5,5,5,0,5,0,5,1,1,10,0,12,0,10,1,1,1
5,0,5,5,0,5,1,1,1,1,5,0,0,0,5,5,1,11,0,12,0,11,1,1,1
1,5,5,5,0,5,5,1,5,5,5,5,5,5,5,1,5,5,0,12,0,5,1,1,1
1,5,0,0,0,0,0,5,0,0,0,0,0,0,5,1,5,5,0,12,0,5,1,1,1
1,5,0,0,0,0,0,5,0,5,5,0,5,5,5,5,1,5,0,12,0,5,1,1,1
1,5,0,0,0,0,0,5,0,5,5,0,5,5,1,1,5,5,0,12,0,5,1,1,1
1,5,0,0,0,0,0,5,0,5,5,0,5,5,5,5,1,10,0,12,0,10,1,1,1
1,5,0,0,0,0,0,0,0,5,5,0,5,5,0,0,5,5,0,12,0,5,1,1,1
1,1,5,5,0,5,5,5,5,1,5,0,0,0,0,0,5,5,0,12,0,5,1,1,1
1,1,1,5,0,5,1,1,1,1,5,0,5,5,5,5,1,5,0,12,0,5,1,1,1
1,1,1,5,0,5,1,5,1,1,5,0,5,1,1,1,1,5,0,12,0,5,1,1,1
1,1,5,5,0,5,5,0,5,1,5,0,5,1,1,1,1,5,0,12,0,5,1,1,1
1,5,0,5,0,5,5,0,5,1,5,0,5,1,1,1,1,10,0,12,0,10,1,1,1
1,5,0,0,0,0,0,0,5,1,5,0,5,1,1,1,1,5,0,12,0,5,1,1,1
1,1,5,5,5,5,5,0,5,1,5,0,5,1,1,1,1,5,0,12,0,5,1,1,1
1,1,1,1,1,1,5,0,5,1,5,0,5,5,5,5,1,5,0,12,0,5,1,1,1
1,1,1,1,1,1,5,0,5,1,5,0,0,0,0,0,5,5,0,12,0,5,1,1,1
1,1,1,1,1,5,0,0,5,1,5,0,0,0,0,0,0,0,0,12,0,5,1,1,1
1,1,1,1,1,1,5,5,1,1,5,0,0,0,0,0,5,10,0,12,0,10,1,1,1
1,1,1,1,1,1,5,5,1,1,5,5,5,5,5,5,5,1,9,9,9,1,1,1,1
endlayer

layer
1,1,1,1,1,1,1,1,1,1,1,1,1,1,1,1,1,1,9,9,9,9,1,1,1
1,1,1,1,1,5,5,5,5,5,1,1,1,1,5,5,5,10,0,0,0,10,1,1,1
1,5,5,1,1,5,1,1,1,1,1,5,5,5,0,0,0,0,0,0,0,5,1,1,1
1,5,1,1,1,5,1,1,5,5,5,5,1,1,5,5,5,5,0,0,0,5,1,1,1
1,5,1,1,5,5,5,5,5,5,1,1,1,1,1,1,1,5,0,0,0,5,1,1,1
1,5,1,1,5,5,1,1,1,1,1,5,5,5,5,1,1,5,0,0,0,5,1,1,1
1,5,1,1,5,5,5,5,1,1,1,5,1,1,5,1,1,5,0,0,0,5,1,1,1
1,5,1,1,5,5,0,0,5,1,1,5,1,1,5,1,1,10,0,0,0,10,1,1,1
1,5,5,5,5,5,0,0,5,5,5,5,1,1,5,1,1,5,0,0,0,5,1,1,1
1,1,1,1,5,5,0,0,5,1,1,5,1,1,5,1,1,5,0,0,0,5,1,1,1
1,1,1,1,5,5,5,5,1,1,1,5,1,1,5,1,1,5,0,0,0,5,1,1,1
1,1,1,1,5,5,5,1,1,1,1,5,1,1,5,1,1,5,0,0,0,5,1,1,1
1,1,1,1,5,5,1,1,1,1,1,5,1,1,5,1,1,11,0,0,0,11,1,1,1
1,5,5,5,5,5,5,5,1,13,13,13,13,13,13,13,13,10,0,0,0,10,1,1,1
1,5,1,1,5,1,1,1,1,13,13,13,13,13,13,13,13,13,0,0,0,11,1,1,1
1,5,1,1,5,5,5,5,1,13,13,13,13,13,13,13,13,13,0,0,0,11,1,1,1
1,5,1,1,5,1,1,5,5,5,13,13,13,13,13,13,13,13,0,0,0,11,1,1,1
1,5,5,5,5,1,1,5,1,13,13,13,13,13,13,13,13,13,0,0,0,11,1,1,1
1,5,1,1,5,5,5,5,1,13,13,13,13,13,13,13,13,13,0,0,0,11,1,1,1
1,5,1,1,5,1,1,1,1,13,13,13,13,13,13,13,13,10,0,0,0,10,1,1,1
1,5,5,5,5,1,1,1,1,13,13,13,13,13,13,13,13,13,0,0,0,11,1,1,1
1,1,1,1,5,1,1,1,3,13,13,13,13,13,13,13,13,13,0,0,0,11,1,1,1
1,1,1,1,5,1,1,1,1,13,13,13,13,13,13,13,13,13,0,0,0,11,1,1,1
1,5,5,5,5,1,1,1,1,13,13,13,13,13,13,13,13,13,0,0,0,11,1,1,1
1,5,1,1,5,5,1,1,5,13,13,13,13,13,13,13,13,13,0,0,0,11,1,1,1
1,5,1,1,5,1,1,1,1,13,13,13,13,13,13,13,13,10,0,0,0,10,1,1,1
1,5,1,1,5,1,1,1,1,13,13,13,5,13,1,1,1,11,0,0,0,11,1,1,1
1,1,5,5,5,5,5,1,1,13,13,13,1,13,1,1,1,5,0,0,0,5,1,1,1
1,5,0,0,0,0,0,5,5,13,13,13,5,13,1,1,1,5,0,0,0,5,1,1,1
1,5,0,0,0,0,0,5,5,13,13,13,1,1,1,1,1,5,0,0,0,5,1,1,1
1,5,0,0,0,0,0,5,5,13,13,13,1,1,1,1,1,5,0,0,0,5,1,1,1
1,5,0,0,0,0,0,5,5,1,1,5,1,1,5,5,5,10,0,0,0,10,1,1,1
1,5,0,0,0,0,0,5,5,1,1,5,1,1,5,5,5,5,0,0,0,5,1,1,1
1,1,5,5,5,5,5,1,1,1,1,5,5,5,5,5,1,5,0,0,0,5,1,1,1
1,1,1,1,5,1,1,1,1,1,1,5,1,1,1,1,1,5,0,0,0,5,1,1,1
1,1,1,1,5,1,1,1,1,1,1,5,1,1,1,1,1,5,0,0,0,5,1,1,1
1,1,1,1,5,1,1,5,1,1,1,5,1,1,1,1,1,5,0,0,0,5,1,1,1
1,1,5,1,5,1,1,5,1,1,1,5,1,1,1,1,1,10,0,0,0,10,1,1,1
1,1,5,5,5,5,5,5,1,1,1,5,1,1,1,1,1,5,0,0,0,5,1,1,1
1,1,1,1,1,1,1,5,1,1,1,5,1,1,1,1,1,5,0,0,0,5,1,1,1
1,1,1,1,1,1,1,5,1,1,5,0,5,5,5,5,1,5,0,0,0,5,1,1,1
1,1,1,1,1,1,1,5,1,1,5,0,0,0,0,0,5,5,0,0,0,5,1,1,1
1,1,1,1,1,1,5,5,1,1,5,0,0,0,0,0,0,0,0,0,0,5,1,1,1
1,1,1,1,1,1,1,1,1,1,5,0,0,0,0,0,5,10,0,0,0,10,1,1,1
1,1,1,1,1,1,1,1,1,1,5,5,5,5,5,5,5,1,9,9,9,1,1,1,1
endlayer

layer
1,1,1,1,1,1,1,1,1,1,1,1,1,1,1,1,1,1,9,9,9,1,1,1,1
1,1,1,1,1,1,1,1,1,1,1,1,1,1,1,1,1,10,0,0,0,10,1,1,1
1,1,1,1,1,1,1,1,1,1,1,1,1,1,5,5,5,5,0,0,0,5,1,1,1
1,1,1,1,1,1,1,1,1,1,1,1,1,1,1,1,1,5,0,0,0,5,1,1,1
1,1,1,1,1,1,1,1,1,1,1,1,1,1,1,1,1,5,0,0,0,5,1,1,1
1,1,1,1,1,1,1,1,1,1,1,1,1,1,1,1,1,5,0,0,0,5,1,1,1
1,1,1,1,1,1,1,1,1,1,1,1,1,1,1,1,1,5,0,0,0,5,1,1,1
1,1,1,1,1,1,5,5,1,1,1,1,1,1,1,1,1,10,0,0,0,10,1,1,1
1,1,1,1,1,1,5,5,1,1,1,1,1,1,1,1,1,5,0,0,0,5,1,1,1
1,1,1,1,1,1,5,5,1,1,1,1,1,1,1,1,1,5,0,0,0,5,1,1,1
1,1,1,1,1,1,1,1,1,1,1,1,1,1,1,1,1,5,0,0,0,5,1,1,1
1,1,1,1,1,1,1,1,1,1,1,1,1,1,1,1,1,5,0,0,0,5,1,1,1
1,1,1,1,1,1,1,1,1,11,11,11,11,11,11,11,11,11,0,0,0,11,1,1,1
1,1,1,1,1,1,1,1,10,0,0,0,0,0,0,0,0,10,0,0,0,10,1,1,1
1,1,1,1,1,1,1,1,11,16,0,0,0,0,0,0,0,0,0,0,0,11,1,1,1
1,1,1,1,1,1,1,1,11,17,0,0,0,0,0,0,0,0,0,0,0,11,1,1,1
1,1,1,1,1,1,1,1,11,17,0,0,0,0,0,0,0,0,0,0,0,11,1,1,1
1,1,1,1,1,1,1,1,11,17,0,0,0,0,0,0,0,0,0,0,0,11,1,1,1
1,1,1,1,1,1,1,1,11,16,0,0,0,0,0,0,0,0,0,0,0,11,1,1,1
1,1,1,1,1,1,1,1,10,0,0,0,0,0,0,0,0,10,0,0,0,10,1,1,1
1,1,1,1,1,1,1,1,11,16,0,0,0,0,0,0,0,0,0,0,0,11,1,1,1
1,1,1,1,1,1,1,1,11,17,0,0,0,0,0,0,0,0,0,0,0,11,1,1,1
1,1,1,1,1,1,1,1,11,17,0,0,0,0,0,0,0,0,0,0,0,11,1,1,1
1,1,1,1,1,1,1,1,11,17,0,0,0,0,0,0,0,0,0,0,0,11,1,1,1
1,1,1,1,1,1,1,1,11,16,0,0,0,0,0,0,0,0,0,0,0,11,1,1,1
1,1,1,1,1,1,1,1,10,0,0,0,0,0,0,0,0,10,0,0,0,10,1,1,1
1,1,1,1,1,1,1,1,11,0,15,0,11,0,11,11,11,11,0,0,0,11,1,1,1
1,1,1,1,1,1,1,1,11,0,0,0,11,0,11,1,1,5,0,0,0,5,1,1,1
1,1,5,5,5,5,5,1,11,0,0,0,11,0,11,1,1,5,0,0,0,5,1,1,1
1,1,5,5,5,5,5,1,11,0,0,0,11,11,1,1,1,5,0,0,0,5,1,1,1
1,1,5,5,5,5,5,1,11,0,0,0,11,1,1,1,1,5,0,0,0,5,1,1,1
1,1,5,5,5,5,5,1,1,14,14,14,1,1,1,1,1,10,0,0,0,10,1,1,1
1,1,5,5,5,5,5,1,1,1,1,1,1,1,1,1,1,5,0,0,0,5,1,1,1
1,1,1,1,1,1,1,1,1,1,1,1,0,1,1,1,1,5,0,0,0,5,1,1,1
1,1,1,1,1,1,1,1,1,1,1,1,1,1,1,1,1,5,0,0,0,5,1,1,1
1,1,1,1,1,1,1,1,1,1,1,1,1,1,1,1,1,5,0,0,0,5,1,1,1
1,1,1,1,1,1,1,1,1,1,1,1,1,1,1,1,1,5,0,0,0,5,1,1,1
1,1,1,1,1,1,1,1,1,1,1,1,1,1,1,1,1,10,0,0,0,10,1,1,1
1,1,1,1,1,1,1,1,1,1,1,1,1,1,1,1,1,5,0,0,0,5,1,1,1
1,1,1,1,1,1,1,1,1,1,1,1,1,1,1,1,1,5,0,0,0,5,1,1,1
1,1,1,1,1,1,1,1,1,1,1,5,5,5,5,5,1,5,0,0,0,5,1,1,1
1,1,1,1,1,1,1,1,1,1,5,0,0,0,0,0,5,5,0,0,0,5,1,1,1
1,1,1,1,1,1,1,1,1,1,5,0,0,0,0,0,5,5,0,0,0,5,1,1,1
1,1,1,1,1,1,1,1,1,1,5,0,0,0,0,0,5,10,0,0,0,10,1,1,1
1,1,1,1,1,1,1,1,1,1,5,5,5,5,5,5,5,1,9,9,9,1,1,1,1
endlayer

layer
1,1,1,1,1,1,1,1,1,1,1,1,1,1,1,1,1,1,1,9,1,1,1,1,1
1,1,1,1,1,1,1,1,1,1,1,1,1,1,1,1,1,18,10,0,10,10,1,1,1
1,1,1,1,1,1,1,1,1,1,1,1,1,1,1,1,1,1,5,0,5,1,1,1,1
1,1,1,1,1,1,1,1,1,1,1,1,1,1,1,1,1,1,5,0,5,1,1,1,1
1,1,1,1,1,1,1,1,1,1,1,1,1,1,1,1,1,1,5,0,5,1,1,1,1
1,1,1,1,1,1,1,1,1,1,1,1,1,1,1,1,1,1,5,0,5,1,1,1,1
1,1,1,1,1,1,1,1,1,1,1,1,1,1,1,1,1,1,5,0,5,1,1,1,1
1,1,1,1,1,1,1,1,1,1,1,1,1,1,1,1,1,18,10,0,10,10,1,1,1
1,1,1,1,1,1,1,1,1,1,1,1,1,1,1,1,1,1,5,0,5,1,1,1,1
1,1,1,1,1,1,1,1,1,1,1,1,1,1,1,1,1,1,5,0,5,1,1,1,1
1,1,1,1,1,1,1,1,1,1,1,1,1,1,1,1,1,1,5,0,5,1,1,1,1
1,1,1,1,1,1,1,1,1,1,1,1,1,1,1,1,1,1,5,0,5,1,1,1,1
1,1,1,1,1,1,1,1,1,11,11,11,11,11,11,11,11,11,11,0,11,1,1,1,1
1,1,1,1,1,1,1,1,10,0,0,0,0,0,0,0,0,10,0,0,0,10,1,1,1
1,1,1,1,1,1,1,1,11,0,0,0,0,0,0,0,0,0,0,0,0,11,1,1,1
1,1,1,1,1,1,1,1,11,0,0,0,0,0,0,0,0,0,0,0,0,11,1,1,1
1,1,1,1,1,1,1,1,11,0,0,0,0,0,0,0,0,0,0,0,0,11,1,1,1
1,1,1,1,1,1,1,1,11,0,0,0,0,0,0,0,0,0,0,0,0,11,1,1,1
1,1,1,1,1,1,1,1,11,0,0,0,0,0,0,0,0,0,0,0,0,11,1,1,1
1,1,1,1,1,1,1,1,10,0,0,0,0,0,0,0,0,10,0,0,0,10,1,1,1
1,1,1,1,1,1,1,1,11,0,0,0,0,0,0,0,0,0,0,0,0,11,1,1,1
1,1,1,1,1,1,1,1,11,0,0,0,0,0,0,0,0,0,0,0,0,11,1,1,1
1,1,1,1,1,1,1,1,11,0,0,0,0,0,0,0,0,0,0,0,0,11,1,1,1
1,1,1,1,1,1,1,1,11,0,0,0,0,0,0,0,0,0,0,0,0,11,1,1,1
1,1,1,1,1,1,1,1,11,0,0,0,0,0,0,0,0,0,0,0,0,11,1,1,1
1,1,1,1,1,1,1,1,10,0,0,0,0,0,0,0,0,10,0,0,0,10,1,1,1
1,1,1,1,1,1,1,1,11,0,15,0,11,0,11,11,11,1,11,0,11,1,1,1,1
1,1,1,1,1,1,1,1,11,0,0,0,0,0,11,1,1,1,5,0,5,1,1,1,1
1,1,1,1,1,1,1,1,11,0,0,0,0,0,11,1,1,1,5,0,5,1,1,1,1
1,1,1,1,1,1,1,1,11,0,0,0,11,11,1,1,1,1,5,0,5,1,1,1,1
1,1,1,1,1,1,1,1,11,0,0,0,11,1,1,1,1,1,5,0,5,1,1,1,1
1,1,1,1,1,1,1,1,11,0,0,0,11,1,1,1,1,18,10,0,10,18,1,1,1
1,1,1,1,1,1,1,1,1,14,14,14,1,1,1,1,1,1,5,0,5,1,1,1,1
1,1,1,1,1,1,1,1,1,1,1,1,0,1,1,1,1,1,5,0,5,1,1,1,1
1,1,1,1,1,1,1,1,1,1,1,1,1,1,1,1,1,1,5,0,5,1,1,1,1
1,1,1,1,1,1,1,1,1,1,1,1,1,1,1,1,1,1,5,0,5,1,1,1,1
1,1,1,1,1,1,1,1,1,1,1,1,1,1,1,1,1,1,5,0,5,1,1,1,1
1,1,1,1,1,1,1,1,1,1,1,1,1,1,1,1,1,18,10,0,10,18,1,1,1
1,1,1,1,1,1,1,1,1,1,1,1,1,1,1,1,1,1,5,0,5,1,1,1,1
1,1,1,1,1,1,1,1,1,1,1,1,1,1,1,1,1,1,5,0,5,1,1,1,1
1,1,1,1,1,1,1,1,1,1,1,1,1,1,1,1,1,1,5,0,5,1,1,1,1
1,1,1,1,1,1,1,1,1,1,1,5,5,5,5,5,1,1,5,0,5,1,1,1,1
1,1,1,1,1,1,1,1,1,1,1,5,5,5,5,5,1,1,5,0,5,1,1,1,1
1,1,1,1,1,1,1,1,1,1,1,5,5,5,5,5,1,10,10,0,10,10,1,1,1
1,1,1,1,1,1,1,1,1,1,1,5,5,5,5,5,1,1,1,9,1,1,1,1,1
endlayer

layer
1,1,1,1,1,1,1,1,1,1,1,1,1,1,1,1,1,1,1,1,1,1,1,1,1
1,1,1,1,1,1,1,1,1,1,1,1,1,1,1,1,1,18,18,10,18,10,1,1,1
1,1,1,1,1,1,1,1,1,1,1,1,1,1,1,1,1,1,1,5,1,1,1,1,1
1,1,1,1,1,1,1,1,1,1,1,1,1,1,1,1,1,1,1,5,1,1,1,1,1
1,1,1,1,1,1,1,1,1,1,1,1,1,1,1,1,1,1,1,5,1,1,1,1,1
1,1,1,1,1,1,1,1,1,1,1,1,1,1,1,1,1,1,1,5,1,1,1,1,1
1,1,1,1,1,1,1,1,1,1,1,1,1,1,1,1,1,1,1,5,1,1,1,1,1
1,1,1,1,1,1,1,1,1,1,1,1,1,1,1,1,1,18,18,10,10,0,1,1,1
1,1,1,1,1,1,1,1,1,1,1,1,1,1,1,1,1,1,1,5,1,1,1,1,1
1,1,1,1,1,1,1,1,1,1,1,1,1,1,1,1,1,1,1,5,1,1,1,1,1
1,1,1,1,1,1,1,1,1,1,1,1,1,1,1,1,1,1,1,5,1,1,1,1,1
1,1,1,1,1,1,1,1,1,1,1,1,1,1,1,1,1,1,1,5,1,1,1,1,1
1,1,1,1,1,1,1,1,1,11,11,11,11,11,11,11,11,11,11,11,11,1,1,1,1
1,1,1,1,1,1,1,1,10,0,0,0,0,0,0,0,0,10,0,0,0,10,1,1,1
1,1,1,1,1,1,1,1,11,0,0,0,0,0,0,0,0,0,0,0,0,11,1,1,1
1,1,1,1,1,1,1,1,11,0,0,0,0,0,0,0,0,0,0,0,0,11,1,1,1
1,1,1,1,1,1,1,1,11,0,0,0,0,0,0,0,0,0,0,0,0,11,1,1,1
1,1,1,1,1,1,1,1,11,0,0,0,0,0,0,0,0,0,0,0,0,11,1,1,1
1,1,1,1,1,1,1,1,11,0,0,0,0,0,0,0,0,0,0,0,0,11,1,1,1
1,1,1,1,1,1,1,1,10,0,0,0,0,0,0,0,0,10,0,0,0,10,1,1,1
1,1,1,1,1,1,1,1,11,0,0,0,0,0,0,0,0,0,0,0,0,11,1,1,1
1,1,1,1,1,1,1,1,11,0,0,0,0,0,0,0,0,0,0,0,0,11,1,1,1
1,1,1,1,1,1,1,1,11,0,0,0,0,0,0,0,0,0,0,0,0,11,1,1,1
1,1,1,1,1,1,1,1,11,0,0,0,0,0,0,0,0,0,0,0,0,11,1,1,1
1,1,1,1,1,1,1,1,11,0,0,0,0,0,0,0,0,0,0,0,0,11,1,1,1
1,1,1,1,1,1,1,1,10,0,0,0,0,0,0,0,0,10,0,0,0,10,1,1,1
1,1,1,1,1,1,1,1,11,0,15,0,11,11,11,11,11,1,11,11,11,1,1,1,1
1,1,1,1,1,1,1,1,11,0,0,0,11,11,1,1,1,1,1,5,1,1,1,1,1
1,1,1,1,1,1,1,1,11,0,0,0,11,11,1,1,1,1,1,5,1,1,1,1,1
1,1,1,1,1,1,1,1,11,0,0,0,11,1,1,1,1,1,1,5,1,1,1,1,1
1,1,1,1,1,1,1,1,11,0,0,0,11,1,1,1,1,1,1,5,1,1,1,1,1
1,1,1,1,1,1,1,1,11,0,0,0,11,1,1,1,1,18,18,10,18,18,1,1,1
1,1,1,1,1,1,1,1,11,0,0,0,11,1,1,1,1,1,1,5,1,1,1,1,1
1,1,1,1,1,1,1,1,1,14,14,14,1,1,1,1,1,1,1,5,1,1,1,1,1
1,1,1,1,1,1,1,1,1,1,1,1,1,1,1,1,1,1,1,5,1,1,1,1,1
1,1,1,1,1,1,1,1,1,1,1,1,1,1,1,1,1,1,1,5,1,1,1,1,1
1,1,1,1,1,1,1,1,1,1,1,1,1,1,1,1,1,1,1,5,1,1,1,1,1
1,1,1,1,1,1,1,1,1,1,1,1,1,1,1,1,1,18,18,5,18,18,1,1,1
1,1,1,1,1,1,1,1,1,1,1,1,1,1,1,1,1,1,1,5,1,1,1,1,1
1,1,1,1,1,1,1,1,1,1,1,1,1,1,1,1,1,1,1,5,1,1,1,1,1
1,1,1,1,1,1,1,1,1,1,1,1,1,1,1,1,1,1,1,5,1,1,1,1,1
1,1,1,1,1,1,1,1,1,1,1,1,1,1,1,1,1,1,1,5,1,1,1,1,1
1,1,1,1,1,1,1,1,1,1,1,1,1,1,1,1,1,1,1,5,1,1,1,1,1
1,1,1,1,1,1,1,1,1,1,1,1,1,1,1,1,1,10,10,10,10,10,1,1,1
1,1,1,1,1,1,1,1,1,1,1,1,1,1,1,1,1,1,1,1,1,1,1,1,1
endlayer

layer
1,1,1,1,1,1,1,1,1,1,1,1,1,1,1,1,1,1,1,1,1,1,1,1,1
1,1,1,1,1,1,1,1,1,1,1,1,1,1,1,1,1,1,1,1,1,1,1,1,1
1,1,1,1,1,1,1,1,1,1,1,1,1,1,1,1,1,1,1,1,1,1,1,1,1
1,1,1,1,1,1,1,1,1,1,1,1,1,1,1,1,1,1,1,1,1,1,1,1,1
1,1,1,1,1,1,1,1,1,1,1,1,1,1,1,1,1,1,1,1,1,1,1,1,1
1,1,1,1,1,1,1,1,1,1,1,1,1,1,1,1,1,1,1,1,1,1,1,1,1
1,1,1,1,1,1,1,1,1,1,1,1,1,1,1,1,1,1,1,1,1,1,1,1,1
1,1,1,1,1,1,1,1,1,1,1,1,1,1,1,1,1,1,1,1,1,1,1,1,1
1,1,1,1,1,1,1,1,1,1,1,1,1,1,1,1,1,1,1,1,1,1,1,1,1
1,1,1,1,1,1,1,1,1,1,1,1,1,1,1,1,1,1,1,1,1,1,1,1,1
1,1,1,1,1,1,1,1,1,1,1,1,1,1,1,1,1,1,1,1,1,1,1,1,1
1,1,1,1,1,1,1,1,1,1,1,1,1,1,1,1,1,1,1,1,1,1,1,1,1
1,1,1,1,1,1,1,1,1,11,11,11,11,11,11,11,11,11,11,11,11,1,1,1,1
1,1,1,1,1,1,1,1,10,10,0,0,0,0,0,0,10,10,10,0,10,10,1,1,1
1,1,1,1,1,1,1,1,11,0,0,0,0,0,0,0,0,0,0,0,0,11,1,1,1
1,1,1,1,1,1,1,1,11,0,0,0,0,0,0,0,0,0,0,0,0,11,1,1,1
1,1,1,1,1,1,1,1,11,0,0,0,0,0,0,0,0,0,0,0,0,11,1,1,1
1,1,1,1,1,1,1,1,11,0,0,0,0,0,0,0,0,0,0,0,0,11,1,1,1
1,1,1,1,1,1,1,1,11,0,0,0,0,0,0,0,0,0,0,0,0,11,1,1,1
1,1,1,1,1,1,1,1,10,10,0,0,0,0,0,0,10,10,10,0,10,10,1,1,1
1,1,1,0,1,1,1,1,11,0,0,0,0,0,0,0,0,0,0,0,0,11,1,1,1
1,1,1,1,1,1,1,1,11,0,0,0,0,0,0,0,0,0,0,0,0,11,1,1,1
1,1,1,1,1,1,1,1,11,0,0,0,0,0,0,0,0,0,0,0,0,11,1,1,1
1,1,1,1,1,1,1,1,11,0,0,0,0,0,0,0,0,0,0,0,0,11,1,1,1
1,1,1,1,1,1,1,1,11,0,0,0,0,0,0,0,0,0,0,0,0,11,1,1,1
1,1,1,1,1,1,1,1,10,10,0,0,0,0,0,0,10,10,10,0,10,10,1,1,1
1,1,1,1,1,1,1,1,11,0,15,0,11,11,11,11,11,11,11,11,11,1,1,1,1
1,1,1,1,1,1,1,1,11,0,0,0,11,1,1,1,1,1,1,1,1,1,1,1,1
1,1,1,1,1,1,1,1,11,0,0,0,11,1,1,1,1,1,1,1,1,1,1,1,1
1,1,1,1,1,1,1,1,11,0,0,0,11,1,1,1,1,1,1,1,1,1,1,1,1
1,1,1,1,1,1,1,1,11,0,0,0,11,1,1,1,1,1,1,1,1,1,1,1,1
1,1,1,1,1,1,1,1,11,0,0,0,11,1,1,1,1,1,1,1,1,1,1,1,1
1,1,1,1,1,1,1,1,11,0,0,0,11,1,1,1,1,1,1,1,1,1,1,1,1
1,1,1,1,1,1,1,1,11,0,0,0,11,1,1,1,1,1,1,1,1,1,1,1,1
1,1,1,1,1,1,1,1,1,14,14,14,1,1,1,1,1,1,1,1,1,1,1,1,1
1,1,1,1,1,1,1,1,1,1,1,1,1,1,1,1,1,1,1,1,1,1,1,1,1
1,1,1,1,1,1,1,1,1,1,1,1,1,1,1,1,1,1,1,0,1,1,1,1,1
1,1,1,1,1,1,1,1,1,1,1,1,1,1,1,1,1,1,1,1,1,1,1,1,1
1,1,1,1,1,1,1,1,1,1,1,1,1,1,1,1,1,1,1,1,1,1,1,1,1
1,1,1,1,1,1,1,1,1,1,1,1,1,1,1,1,1,1,1,1,1,1,1,1,1
1,1,1,1,1,1,1,1,1,1,1,1,1,1,1,1,1,1,1,1,1,1,1,1,1
1,1,1,1,1,1,1,1,1,1,1,1,1,1,1,1,1,1,1,1,1,1,1,1,1
1,1,1,1,1,1,1,1,1,1,1,1,1,1,1,1,1,1,1,1,1,1,1,1,1
1,1,1,1,1,1,1,1,1,1,1,1,1,1,1,1,1,1,1,1,1,1,1,1,1
1,1,1,1,1,1,1,1,1,1,1,1,1,1,1,1,1,1,1,1,1,1,1,1,1
endlayer

layer
1,1,1,1,1,1,1,1,1,1,1,1,1,1,1,1,1,1,1,1,1,1,1,1,1
1,1,1,1,1,1,1,1,1,1,1,1,1,1,1,1,1,1,1,1,1,1,1,1,1
1,1,1,1,1,1,1,1,1,1,1,1,1,1,1,1,1,1,1,1,1,1,1,1,1
1,1,1,1,1,1,1,1,1,1,1,1,1,1,1,1,1,1,1,1,1,1,1,1,1
1,1,1,1,1,1,1,1,1,1,1,1,1,1,1,1,1,1,1,1,1,1,1,1,1
1,1,1,1,1,1,1,1,1,1,1,1,1,1,1,1,1,1,1,1,1,1,1,1,1
1,1,1,1,1,1,1,1,1,1,1,1,1,1,1,1,1,1,1,1,1,1,1,1,1
1,1,1,1,1,1,1,1,1,1,1,1,1,1,1,1,1,1,1,1,1,1,1,1,1
1,1,1,1,1,1,1,1,1,1,1,1,1,1,1,1,1,1,1,1,1,1,1,1,1
1,1,1,1,1,1,1,1,1,1,1,1,1,1,1,1,1,1,1,1,1,1,1,1,1
1,1,1,1,1,1,1,1,1,1,1,1,1,1,1,1,1,1,1,1,1,1,1,1,1
1,1,1,1,1,1,1,1,1,1,1,1,1,1,1,1,1,1,1,1,1,1,1,1,1
1,1,1,1,1,1,1,1,1,11,11,11,11,11,11,11,11,11,11,11,11,1,1,1,1
1,1,1,1,1,1,1,1,10,0,10,0,0,0,0,10,0,10,0,10,0,10,1,1,1
1,1,1,1,1,1,1,1,11,0,0,0,0,0,0,0,0,0,0,0,0,11,1,1,1
1,1,1,1,1,1,1,1,11,0,0,0,0,0,0,0,0,0,0,0,0,11,1,1,1
1,1,1,1,1,1,1,1,11,0,0,0,0,0,0,0,0,0,0,0,0,11,1,1,1
1,1,1,1,1,1,1,1,11,0,0,0,0,0,0,0,0,0,0,0,0,11,1,1,1
1,1,1,1,1,1,1,1,11,0,0,0,0,0,0,0,0,0,0,0,0,11,1,1,1
1,1,1,1,1,1,1,1,10,0,10,0,0,0,0,10,0,10,0,10,0,10,1,1,1
1,1,1,1,1,1,1,1,11,0,0,0,0,0,0,0,0,0,0,0,0,11,1,1,1
1,1,1,1,1,1,1,1,11,0,0,0,0,0,0,0,0,0,0,0,0,11,1,1,1
1,1,1,1,1,1,1,1,11,0,0,0,0,0,0,0,0,0,0,0,0,11,1,1,1
1,1,1,1,1,1,1,1,11,0,0,0,0,0,0,0,0,0,0,0,0,11,1,1,1
1,1,1,1,1,1,1,1,11,0,0,0,0,0,0,0,0,0,0,0,0,11,1,1,1
1,1,1,1,1,1,1,1,10,0,10,0,0,0,0,10,0,10,0,10,0,10,1,1,1
1,1,1,1,1,1,1,1,11,0,15,0,11,11,11,11,11,11,11,11,11,1,1,1,1
1,1,1,1,1,1,1,1,11,0,0,0,11,1,1,1,1,1,1,1,1,1,1,1,1
1,1,1,1,1,1,1,1,11,0,0,0,11,1,1,1,1,1,1,1,1,1,1,1,1
1,1,1,1,1,1,1,1,11,0,0,0,11,1,1,1,1,1,1,1,1,1,1,1,1
1,1,1,1,1,1,1,1,11,0,0,0,11,1,1,1,1,1,1,1,1,1,1,1,1
1,1,1,1,1,1,1,1,11,0,0,0,11,1,1,1,1,1,1,1,1,1,1,1,1
1,1,1,1,1,1,1,1,11,0,0,0,11,1,1,1,1,1,1,1,1,1,1,1,1
1,1,1,1,1,1,1,1,11,0,0,0,11,1,1,1,1,1,1,1,1,1,1,1,1
1,1,1,1,1,1,1,1,11,0,0,0,11,1,1,1,1,1,1,1,1,1,1,1,1
1,1,1,1,1,1,1,1,1,14,14,14,1,1,1,1,1,1,1,1,1,1,1,1,1
1,1,1,1,1,1,1,1,1,1,1,1,1,1,1,1,1,1,1,1,1,1,1,1,1
1,1,1,1,1,1,1,1,1,1,1,1,1,1,1,1,1,1,1,1,1,1,1,1,1
1,1,1,1,1,1,1,1,1,1,1,1,1,1,1,1,1,1,1,1,1,1,1,1,1
1,1,1,1,1,1,1,1,1,1,1,1,1,1,1,1,1,1,1,1,1,1,1,1,1
1,1,1,1,1,1,1,1,1,1,1,1,1,1,1,1,1,1,1,1,1,1,1,1,1
1,1,1,1,1,1,1,1,1,1,1,1,1,1,1,1,1,1,1,1,1,1,1,1,1
1,1,1,1,1,1,1,1,1,1,1,1,1,1,1,1,1,1,1,1,1,1,1,1,1
1,1,1,1,1,1,1,1,1,1,1,1,1,1,1,1,1,1,1,1,1,1,1,1,1
1,1,1,1,1,1,1,1,1,1,1,1,1,1,1,1,1,1,1,1,1,1,1,1,1
endlayer

layer
1,1,1,1,1,1,1,1,1,1,1,1,1,1,1,1,1,1,1,1,1,1,1,1,1
1,1,1,1,1,1,1,1,1,1,1,1,1,1,1,1,1,1,1,1,1,1,1,1,1
1,1,1,1,1,1,1,1,1,1,1,1,1,1,1,1,1,1,1,1,1,1,1,1,1
1,1,1,1,1,1,1,1,1,1,1,1,1,1,1,1,1,1,1,1,1,1,1,1,1
1,1,1,1,1,1,1,1,1,1,1,1,1,1,1,1,1,1,1,1,1,1,1,1,1
1,1,1,1,1,1,1,1,1,1,1,1,1,1,1,1,1,1,1,1,1,1,1,1,1
1,1,1,1,1,1,1,1,1,1,1,1,1,1,1,1,1,1,1,1,1,1,1,1,1
1,1,1,1,1,1,1,1,1,1,1,1,1,1,1,1,1,1,1,1,1,1,1,1,1
1,1,1,1,1,1,1,1,1,1,1,1,1,1,1,1,1,1,1,1,1,1,1,1,1
1,1,1,1,1,1,1,1,1,1,1,1,1,1,1,1,1,1,1,1,1,1,1,1,1
1,1,1,1,1,1,1,1,1,1,1,1,1,1,1,1,1,1,1,1,1,1,1,1,1
1,1,1,1,1,1,1,1,1,1,1,1,1,1,1,1,1,1,1,1,1,1,1,1,1
1,1,1,1,1,1,1,1,1,1,1,1,1,1,1,1,1,1,1,1,1,1,1,1,1
1,1,1,1,1,1,1,1,18,10,10,10,10,10,10,10,10,10,10,10,10,18,1,1,1
1,1,1,1,1,1,1,1,1,11,11,11,11,11,11,11,11,11,11,11,11,1,1,1,1
1,1,1,1,1,1,1,1,1,11,11,11,11,11,11,11,11,11,11,11,11,1,1,1,1
1,1,1,1,1,1,1,1,1,11,20,11,11,20,11,11,20,11,11,11,11,1,1,1,1
1,1,1,1,1,1,1,1,1,11,11,11,11,11,11,11,11,11,11,11,11,1,1,1,1
1,1,1,1,1,1,1,1,1,11,11,11,11,11,11,11,11,11,11,11,11,1,1,1,1
1,1,1,1,1,1,1,1,18,10,10,10,10,10,10,10,10,10,10,10,10,18,1,1,1
1,1,1,1,1,1,1,1,1,11,11,11,11,11,11,11,11,11,11,11,11,1,1,1,1
1,1,1,1,1,1,1,1,1,11,11,11,11,11,11,11,11,11,11,11,11,1,1,1,1
1,1,1,1,1,1,1,1,1,11,20,11,11,20,11,11,20,11,11,11,11,1,1,1,1
1,1,1,1,1,1,1,1,1,11,11,11,11,11,11,11,11,11,11,11,11,1,1,1,1
1,1,1,1,1,1,1,1,1,11,11,11,11,11,11,11,11,11,11,11,11,1,1,1,1
1,1,1,1,1,1,1,1,18,10,10,10,10,10,10,10,10,10,10,10,10,1,1,1,1
1,1,1,1,1,1,1,1,1,11,11,11,1,1,1,1,1,1,1,1,1,1,1,1,1
1,1,1,1,1,1,1,1,1,11,11,11,1,1,1,1,1,1,1,1,1,1,1,1,1
1,1,1,1,1,1,1,1,1,11,20,11,1,1,1,1,1,1,1,1,1,1,1,1,1
1,1,1,1,1,1,1,1,1,11,11,11,1,1,1,1,1,1,1,1,1,1,1,1,1
1,1,1,1,1,1,1,1,1,11,11,11,1,1,1,1,1,1,1,1,1,1,1,1,1
1,1,1,1,1,1,1,1,1,11,11,11,1,1,1,1,1,1,1,1,1,1,1,1,1
1,1,1,1,1,1,1,1,11,0,0,0,11,1,1,1,1,1,1,1,1,1,1,1,1
1,1,1,1,1,1,1,1,11,0,0,0,11,1,1,1,1,1,1,1,1,1,1,1,1
1,1,1,1,1,1,1,1,11,0,0,0,11,1,1,1,1,1,1,1,1,1,1,1,1
1,1,1,1,1,1,1,1,11,0,0,0,11,1,1,1,1,1,1,1,1,1,1,1,1
1,1,1,1,1,1,1,1,1,14,14,14,1,1,1,1,1,1,1,1,1,1,1,1,1
1,1,1,1,1,1,1,1,1,1,1,1,1,1,1,1,1,1,1,1,1,1,1,1,1
1,1,1,1,1,1,1,1,1,1,1,1,1,1,1,1,1,1,1,1,1,1,1,1,1
1,1,1,1,1,1,1,1,1,1,1,1,1,1,1,1,1,1,1,1,1,1,1,1,1
1,1,1,1,1,1,1,1,1,1,1,1,1,1,1,1,1,1,1,1,1,1,1,1,1
1,1,1,1,1,1,1,1,1,1,1,1,1,1,1,1,1,1,1,1,1,1,1,1,1
1,1,1,1,1,1,1,1,1,1,1,1,1,1,1,1,1,1,1,1,1,1,1,1,1
1,1,1,1,1,1,1,1,1,1,1,1,1,1,1,1,1,1,1,1,1,1,1,1,1
1,1,1,1,1,1,1,1,1,1,1,1,1,1,1,1,1,1,1,1,1,1,1,1,1
endlayer

layer
1,1,1,1,1,1,1,1,1,1,1,1,1,1,1,1,1,1,1,1,1,1,1,1,1
1,1,1,1,1,1,1,1,1,1,1,1,1,1,1,1,1,1,1,1,1,1,1,1,1
1,1,1,1,1,1,1,1,1,1,1,1,1,1,1,1,1,1,1,1,1,1,1,1,1
1,1,1,1,1,1,1,1,1,1,1,1,1,1,1,1,1,1,1,1,1,1,1,1,1
1,1,1,1,1,1,1,1,1,1,1,1,1,1,1,1,1,1,1,1,1,1,1,1,1
1,1,1,1,1,1,1,1,1,1,1,1,1,1,1,1,1,1,1,1,1,1,1,1,1
1,1,1,1,1,1,1,1,1,1,1,1,1,1,1,1,1,1,1,1,1,1,1,1,1
1,1,1,1,1,1,1,1,1,1,1,1,1,1,1,1,1,1,1,1,1,1,1,1,1
1,1,1,1,1,1,1,1,1,1,1,1,1,1,1,1,1,1,1,1,1,1,1,1,1
1,1,1,1,1,1,1,1,1,1,1,1,1,1,1,1,1,1,1,1,1,1,1,1,1
1,1,1,1,1,1,1,1,1,1,1,1,1,1,1,1,1,1,1,1,1,1,1,1,1
1,1,1,1,1,1,1,1,1,1,1,1,1,1,1,1,1,1,1,1,1,1,1,1,1
1,1,1,1,1,1,1,1,1,1,1,1,1,1,1,1,1,1,1,1,1,1,1,1,1
1,1,1,1,1,1,1,1,1,1,1,1,1,1,1,1,1,1,1,1,1,1,1,1,1
1,1,1,1,1,1,1,1,1,1,1,1,1,1,1,1,1,1,1,1,1,1,1,1,1
1,1,1,1,1,1,1,1,1,1,1,1,1,1,1,1,1,1,1,1,1,1,1,1,1
1,1,1,1,1,1,1,1,1,1,1,1,1,1,1,1,1,1,1,1,1,1,1,1,1
1,1,1,1,1,1,1,1,1,1,1,1,1,1,1,1,1,1,1,1,1,1,1,1,1
1,1,1,1,1,1,1,1,1,1,1,1,1,1,1,1,1,1,1,1,1,1,1,1,1
1,1,1,1,1,1,1,1,1,1,1,1,1,1,1,1,1,1,1,1,1,1,1,1,1
1,1,1,1,1,1,1,1,1,1,1,1,1,1,1,1,1,1,1,1,1,1,1,1,1
1,1,1,1,1,1,1,1,1,1,1,1,1,1,1,1,1,1,1,1,1,1,1,1,1
1,1,1,1,1,1,1,1,1,1,1,1,1,1,1,1,1,1,1,1,1,1,1,1,1
1,1,1,1,1,1,1,1,1,1,1,1,1,1,1,1,1,1,1,1,1,1,1,1,1
1,1,1,1,1,1,1,1,1,1,1,1,1,1,1,1,1,1,1,1,1,1,1,1,1
1,1,1,1,1,1,1,1,1,1,1,1,1,1,1,1,1,1,1,1,1,1,1,1,1
1,1,1,1,1,1,1,1,1,1,1,1,1,1,1,1,1,1,1,1,1,1,1,1,1
1,1,1,1,1,1,1,1,1,1,1,1,1,1,1,1,1,1,1,1,1,1,1,1,1
1,1,1,1,1,1,1,1,1,1,1,1,1,1,1,1,1,1,1,1,1,1,1,1,1
1,1,1,1,1,1,1,1,1,1,1,1,1,1,1,1,1,1,1,1,1,1,1,1,1
1,1,1,1,1,1,1,1,1,1,1,1,1,1,1,1,1,1,1,1,1,1,1,1,1
1,1,1,1,1,1,1,1,1,1,1,1,1,1,1,1,1,1,1,1,1,1,1,1,1
1,1,1,1,1,1,1,1,1,11,11,11,1,1,1,1,1,1,1,1,1,1,1,1,1
1,1,1,1,1,1,1,1,11,0,0,0,11,1,1,1,1,1,1,1,1,1,1,1,1
1,1,1,1,1,1,1,1,11,0,0,0,11,1,1,1,1,1,1,1,1,1,1,1,1
1,1,1,1,1,1,1,1,11,0,0,0,11,1,1,1,1,1,1,1,1,1,1,1,1
1,1,1,1,1,1,1,1,11,0,0,0,11,1,1,1,1,1,1,1,1,1,1,1,1
1,1,1,1,1,1,1,1,1,14,14,14,1,1,1,1,1,1,1,1,1,1,1,1,1
1,1,1,1,1,1,1,1,1,1,1,1,1,1,1,1,1,1,1,1,1,1,1,1,1
1,1,1,1,1,1,1,1,1,1,1,1,1,1,1,1,1,1,1,1,1,1,1,1,1
1,1,1,1,1,1,1,1,1,1,1,1,1,1,1,1,1,1,1,1,1,1,1,1,1
1,1,1,1,1,1,1,1,1,1,1,1,1,1,1,1,1,1,1,1,1,1,1,1,1
1,1,1,1,1,1,1,1,1,1,1,1,1,1,1,1,1,1,1,1,1,1,1,1,1
1,1,1,1,1,1,1,1,1,1,1,1,1,1,1,1,1,1,1,1,1,1,1,1,1
1,1,1,1,1,1,1,1,1,1,1,1,1,1,1,1,1,1,1,1,1,1,1,1,1
endlayer

layer
1,1,1,1,1,1,1,1,1,1,1,1,1,1,1,1,1,1,1,1,1,1,1,1,1
1,1,1,1,1,1,1,1,1,1,1,1,1,1,1,1,1,1,1,1,1,1,1,1,1
1,1,1,1,1,1,1,1,1,1,1,1,1,1,1,1,1,1,1,1,1,1,1,1,1
1,1,1,1,1,1,1,1,1,1,1,1,1,1,1,1,1,1,1,1,1,1,1,1,1
1,1,1,1,1,1,1,1,1,1,1,1,1,1,1,1,1,1,1,1,1,1,1,1,1
1,1,1,1,1,1,1,1,1,1,1,1,1,1,1,1,1,1,1,1,1,1,1,1,1
1,1,1,1,1,1,1,1,1,1,1,1,1,1,1,1,1,1,1,1,1,1,1,1,1
1,1,1,1,1,1,1,1,1,1,1,1,1,1,1,1,1,1,1,1,1,1,1,1,1
1,1,1,1,1,1,1,1,1,1,1,1,1,1,1,1,1,1,1,1,1,1,1,1,1
1,1,1,1,1,1,1,1,1,1,1,1,1,1,1,1,1,1,1,1,1,1,1,1,1
1,1,1,1,1,1,1,1,1,1,1,1,1,1,1,1,1,1,1,1,1,1,1,1,1
1,1,1,1,1,1,1,1,1,1,1,1,1,1,1,1,1,1,1,1,1,1,1,1,1
1,1,1,1,1,1,1,1,1,1,1,1,1,1,1,1,1,1,1,1,1,1,1,1,1
1,1,1,1,1,1,1,1,1,1,1,1,1,1,1,1,1,1,1,1,1,1,1,1,1
1,1,1,1,1,1,1,1,1,1,1,1,1,1,1,1,1,1,1,1,1,1,1,1,1
1,1,1,1,1,1,1,1,1,1,1,1,1,1,1,1,1,1,1,1,1,1,1,1,1
1,1,1,1,1,1,1,1,1,1,1,1,1,1,1,1,1,1,1,1,1,1,1,1,1
1,1,1,1,1,1,1,1,1,1,1,1,1,1,1,1,1,1,1,1,1,1,1,1,1
1,1,1,1,1,1,1,1,1,1,1,1,1,1,1,1,1,1,1,1,1,1,1,1,1
1,1,1,1,1,1,1,1,1,1,1,1,1,1,1,1,1,1,1,1,1,1,1,1,1
1,1,1,1,1,1,1,1,1,1,1,1,1,1,1,1,1,1,1,1,1,1,1,1,1
1,1,1,1,1,1,1,1,1,1,1,1,1,1,1,1,1,1,1,1,1,1,1,1,1
1,1,1,1,1,1,1,1,1,1,1,1,1,1,1,1,1,1,1,1,1,1,1,1,1
1,1,1,1,1,1,1,1,1,1,1,1,1,1,1,1,1,1,1,1,1,1,1,1,1
1,1,1,1,1,1,1,1,1,1,1,1,1,1,1,1,1,1,1,1,1,1,1,1,1
1,1,1,1,1,1,1,1,1,1,1,1,1,1,1,1,1,1,1,1,1,1,1,1,1
1,1,1,1,1,1,1,1,1,1,1,1,1,1,1,1,1,1,1,1,1,1,1,1,1
1,1,1,1,1,1,1,1,1,1,1,1,1,1,1,1,1,1,1,1,1,1,1,1,1
1,1,1,1,1,1,1,1,1,1,1,1,1,1,1,1,1,1,1,1,1,1,1,1,1
1,1,1,1,1,1,1,1,1,1,1,1,1,1,1,1,1,1,1,1,1,1,1,1,1
1,1,1,1,1,1,1,1,1,1,1,1,1,1,1,1,1,1,1,1,1,1,1,1,1
1,1,1,1,1,1,1,1,1,1,1,1,1,1,1,1,1,1,1,1,1,1,1,1,1
1,1,1,1,1,1,1,1,1,1,1,1,1,1,1,1,1,1,1,1,1,1,1,1,1
1,1,1,1,1,1,1,1,1,11,11,11,1,1,1,1,1,1,1,1,1,1,1,1,1
1,1,1,1,1,1,1,1,11,0,0,0,11,1,1,1,1,1,1,1,1,1,1,1,1
1,1,1,1,1,1,1,1,11,0,0,0,11,1,1,1,1,18,18,18,1,1,1,1,1
1,1,1,1,1,1,1,1,11,0,0,0,11,1,1,1,18,18,18,18,18,1,1,1,1
1,1,1,1,1,1,1,1,11,0,0,0,11,1,1,1,18,18,18,18,18,1,1,1,1
1,1,1,1,1,1,1,1,1,14,14,14,1,1,1,1,18,18,18,18,18,1,1,1,1
1,1,1,1,1,1,1,1,1,1,1,1,1,1,1,1,1,18,18,18,1,1,1,1,1
1,1,1,1,1,1,1,1,1,1,1,1,1,1,1,1,1,1,1,1,1,1,1,1,1
1,1,1,1,1,1,1,1,1,1,1,1,1,1,1,1,1,1,1,1,1,1,1,1,1
1,1,1,1,1,1,1,1,1,1,1,1,1,1,1,1,1,1,1,1,1,1,1,1,1
1,1,1,1,1,1,1,1,1,1,1,1,1,1,1,1,1,1,1,1,1,1,1,1,1
1,1,1,1,1,1,1,1,1,1,1,1,1,1,1,1,1,1,1,1,1,1,1,1,1
endlayer

layer
14,14,14,14,14,14,14,14,14,14,14,14,14,14,14,14,14,14,14,14,14,14,14,14,14
14,14,14,14,14,14,14,14,14,14,14,14,14,14,14,14,14,14,14,14,14,14,14,14,14
14,14,1,1,1,1,1,1,1,1,1,1,14,1,1,1,1,1,1,1,1,1,1,14,14
14,14,1,21,21,21,21,21,21,21,21,21,21,21,21,21,21,21,21,21,21,21,1,14,14
14,14,1,21,21,21,21,21,21,21,21,21,21,21,21,21,21,21,21,21,21,21,1,14,14
14,14,1,21,21,21,21,21,21,21,21,21,21,21,21,21,21,21,21,21,21,21,1,14,14
14,14,1,21,21,21,21,21,21,21,21,21,21,21,21,21,21,21,21,21,21,21,1,14,14
14,14,1,21,21,21,21,21,21,21,21,21,21,21,21,21,21,21,21,21,21,21,1,14,14
14,14,1,21,21,21,21,21,21,21,21,21,21,21,21,21,21,21,21,21,21,21,1,14,14
14,14,1,21,21,21,21,21,21,21,21,21,21,21,21,21,21,21,21,21,21,21,1,14,14
14,14,14,21,21,21,21,21,21,21,21,21,21,21,21,21,21,21,21,21,21,21,14,14,14
14,14,1,21,21,21,21,21,21,10,10,10,10,10,10,10,21,21,21,21,21,21,1,14,14
14,14,1,21,21,21,21,21,21,10,22,22,22,22,22,10,21,21,21,21,21,21,1,14,14
14,14,1,21,21,21,21,21,21,10,22,22,22,22,22,10,21,21,21,21,21,21,1,14,14
14,14,1,21,21,21,21,21,21,22,22,22,22,22,22,22,21,21,21,21,21,21,1,14,14
14,14,1,21,21,21,21,21,21,10,22,22,22,22,22,10,21,21,21,21,21,21,1,14,14
14,14,1,21,21,21,21,21,21,10,22,22,22,22,22,10,21,21,21,21,21,21,1,14,14
14,14,1,21,21,21,21,21,21,10,22,22,3,22,22,10,21,21,21,21,21,21,1,14,14
14,14,10,10,10,10,10,10,10,24,22,22,22,22,22,22,10,10,10,10,10,10,10,14,14
14,14,10,22,22,22,22,22,22,22,22,22,22,22,22,22,22,22,22,22,22,22,10,14,14
14,14,10,0,22,22,22,22,22,22,22,22,22,22,22,22,22,22,22,22,22,22,10,14,14
14,14,10,25,3,22,22,22,22,22,22,22,22,22,22,22,3,22,22,22,22,22,10,14,14
14,14,10,22,22,22,22,22,22,22,22,22,22,22,22,22,22,22,22,22,22,22,10,14,14
14,14,10,22,22,22,22,22,22,22,22,22,22,22,22,22,22,22,22,22,22,22,10,14,14
14,14,10,10,10,10,10,10,10,22,22,22,22,22,22,22,10,10,10,10,10,10,10,14,14
14,14,1,1,1,1,1,1,1,10,22,22,3,22,22,10,1,1,1,1,1,1,1,14,14
14,14,1,1,1,1,1,1,1,10,22,22,22,22,22,10,1,1,1,1,1,1,1,14,14
14,14,1,1,1,1,1,1,1,10,22,22,22,22,22,10,1,1,1,1,1,1,1,14,14
14,14,14,14,14,14,14,14,14,22,22,22,22,22,22,22,14,14,14,14,14,14,14,14,14
14,14,1,1,1,1,1,1,1,10,22,22,22,22,22,10,1,1,1,1,1,1,1,14,14
14,14,1,1,1,1,1,1,1,10,22,22,22,22,22,10,1,1,1,1,1,1,1,14,14
14,14,1,1,1,1,1,1,1,10,10,10,10,10,10,10,1,1,1,1,1,1,1,14,14
14,14,1,1,1,1,1,1,1,1,1,1,1,1,1,1,1,1,1,1,1,1,1,14,14
14,14,1,1,1,1,1,1,1,1,1,1,1,1,1,1,1,1,1,1,1,1,1,14,14
14,14,1,1,1,1,1,1,1,11,11,11,1,1,1,1,1,1,1,1,1,1,1,14,14
14,14,1,1,1,1,1,1,11,0,0,0,11,1,1,1,1,18,18,18,1,1,1,14,14
14,14,1,1,1,1,1,1,11,0,0,0,11,1,1,1,18,0,0,0,18,1,1,14,14
14,14,1,1,1,1,1,1,11,0,0,0,11,1,1,1,18,0,23,0,18,1,1,14,14
14,14,1,1,1,1,1,1,11,0,0,0,11,1,1,1,18,0,0,0,18,1,1,14,14
14,14,1,1,1,1,1,1,1,14,14,14,1,1,1,1,1,18,18,18,1,1,1,14,14
14,14,1,1,1,1,1,1,1,14,14,14,1,1,1,1,1,1,1,1,1,1,1,14,14
14,14,1,1,1,1,1,1,1,14,14,14,1,1,1,1,1,1,1,1,1,1,1,14,14
14,14,1,1,1,1,1,1,1,14,14,14,1,1,1,1,1,1,1,1,1,1,1,14,14
14,14,14,14,14,14,14,14,14,14,14,14,14,14,14,14,14,14,14,14,14,14,14,14,14
14,14,14,14,14,14,14,14,14,14,14,14,14,14,14,14,14,14,14,14,14,14,14,14,14
endlayer

layer
0,0,0,0,0,0,0,0,0,0,0,0,0,0,0,0,0,0,0,0,0,0,0,0,0
0,0,0,0,0,0,0,0,0,0,0,0,0,0,0,0,0,0,0,0,0,0,0,0,0
0,0,26,25,25,25,25,25,25,25,25,26,0,26,25,25,25,25,25,25,25,25,26,0,0
0,0,25,0,0,0,0,0,0,0,0,0,0,0,0,30,30,0,30,30,0,0,25,0,0
0,0,25,0,30,31,30,0,30,31,30,0,0,0,0,31,31,0,31,31,0,0,25,0,0
0,0,25,0,0,0,0,0,0,0,0,0,0,0,0,30,30,0,30,30,0,0,25,0,0
0,0,25,0,0,0,0,0,0,0,0,0,0,0,0,0,0,0,0,0,0,0,25,0,0
0,0,25,0,0,0,0,0,0,0,0,0,0,0,0,0,0,0,0,0,0,0,25,0,0
0,0,25,27,0,0,0,0,0,0,0,0,0,0,0,0,0,0,0,0,0,27,25,0,0
0,0,26,0,0,0,0,0,0,0,0,0,0,0,0,0,0,0,0,0,0,0,26,0,0
0,0,0,0,0,0,0,0,0,0,0,0,0,0,0,0,0,0,0,0,0,0,0,0,0
0,0,26,0,0,0,0,0,0,10,10,10,10,10,10,10,0,0,0,0,0,0,26,0,0
0,0,25,0,0,0,0,0,0,10,0,0,0,0,0,10,0,0,0,0,0,0,25,0,0
0,0,25,0,0,0,0,0,0,10,0,29,0,29,0,10,0,0,0,0,0,0,25,0,0
0,0,25,0,0,0,0,0,0,0,0,29,0,29,0,0,0,0,0,0,0,0,25,0,0
0,0,25,0,0,0,0,0,0,10,0,29,0,29,0,10,0,0,0,0,0,0,25,0,0
0,0,25,0,0,0,0,0,0,10,0,0,0,0,0,10,0,0,0,0,0,0,25,0,0
0,0,26,0,16,17,17,16,0,10,0,0,11,0,0,10,0,16,17,17,16,0,26,0,0
0,0,10,10,10,10,10,10,10,32,32,32,32,32,32,32,10,10,10,10,10,10,10,0,0
0,0,10,0,0,0,0,0,33,32,32,32,32,32,32,32,0,0,0,0,0,0,10,0,0
0,0,10,0,29,0,0,0,33,32,32,32,32,32,32,32,0,0,29,29,29,0,10,0,0
0,0,10,6,29,0,0,0,34,32,32,32,32,32,32,32,11,0,0,0,0,0,10,0,0
0,0,10,0,29,0,0,0,33,32,32,32,32,32,32,32,0,0,29,29,29,0,10,0,0
0,0,10,0,0,0,0,0,0,32,32,32,32,32,32,32,0,0,0,0,0,0,10,0,0
0,0,10,10,10,10,10,10,10,32,32,32,32,32,32,32,10,10,10,10,10,10,10,0,0
0,0,0,0,0,0,0,0,0,10,0,0,11,0,0,10,0,0,0,0,0,0,0,0,0
0,0,0,0,0,0,0,0,0,10,0,0,0,0,0,10,0,0,0,0,0,0,0,0,0
0,0,0,0,0,0,0,0,0,10,0,29,0,29,0,10,0,0,0,0,0,0,0,0,0
0,0,0,0,0,0,0,0,0,0,0,29,0,29,0,0,0,0,0,0,0,0,0,0,0
0,0,0,0,0,0,0,0,0,10,0,29,0,29,0,10,0,0,0,0,0,0,0,0,0
0,0,0,0,0,0,0,0,0,10,0,0,0,0,0,10,0,0,0,0,0,0,0,0,0
0,0,0,0,0,0,0,0,0,10,10,10,10,10,10,10,0,0,0,0,0,0,0,0,0
0,0,0,0,0,0,0,0,0,0,0,0,0,0,0,0,0,0,0,0,0,0,0,0,0
0,0,0,0,0,0,0,0,0,0,0,0,0,0,0,0,0,0,0,0,0,0,0,0,0
0,0,35,35,0,0,0,0,26,25,25,25,26,0,0,0,0,28,28,28,0,0,0,0,0
0,0,17,35,0,0,0,0,25,0,0,0,25,0,0,0,28,18,18,18,28,0,0,0,0
0,0,17,35,0,0,0,0,25,0,0,0,25,0,0,28,18,0,0,0,18,28,0,0,0
0,0,35,35,0,0,0,0,25,0,0,0,25,0,0,28,18,0,37,0,18,28,0,0,0
0,0,0,0,0,0,0,0,26,0,0,0,26,0,0,28,18,0,0,0,18,28,0,0,0
0,0,0,0,0,0,0,0,0,0,0,0,0,0,0,0,28,18,18,18,28,0,0,0,0
0,0,0,0,0,0,0,0,0,0,0,0,0,0,0,0,0,28,28,28,0,0,0,0,0
0,0,0,0,0,0,0,0,0,0,0,0,0,0,0,0,0,0,0,0,0,0,0,0,0
0,0,0,0,0,0,0,0,0,0,0,0,0,0,0,0,0,0,0,0,0,0,0,0,0
0,0,0,0,0,0,0,0,0,0,0,0,0,0,0,0,0,0,0,0,0,0,0,0,0
0,0,0,0,0,0,0,0,0,0,0,0,0,0,0,0,0,0,0,0,0,0,0,0,0
endlayer

layer
0,0,0,0,0,0,0,0,0,0,0,0,0,0,0,0,0,0,0,0,0,0,0,0,0
0,0,0,0,0,0,0,0,0,0,0,0,0,0,0,0,0,0,0,0,0,0,0,0,0
0,0,0,0,0,0,0,0,0,0,0,0,0,0,0,0,0,0,0,0,0,0,0,0,0
0,0,0,0,0,0,0,0,0,0,0,0,0,0,0,0,0,0,0,0,0,0,0,0,0
0,0,0,0,0,0,0,0,0,0,0,0,0,0,0,0,0,0,0,0,0,0,0,0,0
0,0,0,0,0,0,0,0,0,0,0,0,0,0,0,0,0,0,0,0,0,0,0,0,0
0,0,0,0,0,0,0,0,0,0,0,0,0,0,0,0,0,0,0,0,0,0,0,0,0
0,0,0,0,0,0,0,0,0,0,0,0,0,0,0,0,0,0,0,0,0,0,0,0,0
0,0,0,0,0,0,0,0,0,0,0,0,0,0,0,0,0,0,0,0,0,0,0,0,0
0,0,0,0,0,0,0,0,0,0,0,0,0,0,0,0,0,0,0,0,0,0,0,0,0
0,0,0,0,0,0,0,0,0,0,0,0,0,0,0,0,0,0,0,0,0,0,0,0,0
0,0,0,0,0,0,0,0,0,10,36,11,36,11,36,10,0,0,0,0,0,0,0,0,0
0,0,0,0,0,0,0,0,0,36,0,0,0,0,0,36,0,0,0,0,0,0,0,0,0
0,0,0,0,0,0,0,0,0,11,0,29,0,29,0,11,0,0,0,0,0,0,0,0,0
0,0,0,0,0,0,0,0,0,0,0,29,0,29,0,0,0,0,0,0,0,0,0,0,0
0,0,0,0,0,0,0,0,0,11,0,29,0,29,0,11,0,0,0,0,0,0,0,0,0
0,0,0,0,0,0,0,0,0,36,0,0,0,0,0,36,0,0,0,0,0,0,0,0,0
0,0,0,0,0,0,0,0,0,10,0,0,11,0,0,10,0,0,0,0,0,0,0,0,0
0,0,10,36,11,36,11,36,10,0,0,0,0,0,0,0,10,36,11,36,11,36,10,0,0
0,0,36,0,0,0,0,0,38,0,0,0,0,0,0,0,0,0,0,0,0,0,36,0,0
0,0,11,0,29,0,0,0,0,0,0,0,0,0,0,0,0,0,29,29,29,0,11,0,0
0,0,36,0,29,0,0,0,0,0,0,0,0,0,0,0,11,0,0,0,0,0,36,0,0
0,0,11,0,29,0,0,0,0,0,0,0,0,0,0,0,0,0,29,29,29,0,11,0,0
0,0,36,0,0,0,0,0,0,0,0,0,0,0,0,0,0,0,0,0,0,0,36,0,0
0,0,10,36,11,36,11,36,10,0,0,0,0,0,0,0,10,36,11,36,11,36,10,0,0
0,0,0,0,0,0,0,0,0,10,0,0,11,0,0,10,0,0,0,0,0,0,0,0,0
0,0,0,0,0,0,0,0,0,36,0,0,0,0,0,36,0,0,0,0,0,0,0,0,0
0,0,0,0,0,0,0,0,0,11,0,29,0,29,0,11,0,0,0,0,0,0,0,0,0
0,0,0,0,0,0,0,0,0,0,0,29,0,29,0,0,0,0,0,0,0,0,0,0,0
0,0,0,0,0,0,0,0,0,11,0,29,0,29,0,11,0,0,0,0,0,0,0,0,0
0,0,0,0,0,0,0,0,0,36,0,0,0,0,0,36,0,0,0,0,0,0,0,0,0
0,0,0,0,0,0,0,0,0,10,36,11,36,11,36,10,0,0,0,0,0,0,0,0,0
0,0,0,0,0,0,0,0,0,0,0,0,0,0,0,0,0,0,0,0,0,0,0,0,0
0,0,0,0,0,0,0,0,0,0,0,0,0,0,0,0,0,0,0,0,0,0,0,0,0
0,0,35,35,0,0,0,0,0,0,0,0,0,0,0,0,0,0,0,0,0,0,0,0,0
0,0,0,35,0,0,0,0,0,0,0,0,0,0,0,0,0,0,0,0,0,0,0,0,0
0,0,0,35,0,0,0,0,0,0,0,0,0,0,0,0,0,0,0,0,0,0,0,0,0
0,0,35,35,0,0,0,0,0,0,0,0,0,0,0,0,0,0,23,0,0,0,0,0,0
0,0,0,0,0,0,0,0,0,0,0,0,0,0,0,0,0,0,0,0,0,0,0,0,0
0,0,0,0,0,0,0,0,0,0,0,0,0,0,0,0,0,0,0,0,0,0,0,0,0
0,0,0,0,0,0,0,0,0,0,0,0,0,0,0,0,0,0,0,0,0,0,0,0,0
0,0,0,0,0,0,0,0,0,0,0,0,0,0,0,0,0,0,0,0,0,0,0,0,0
0,0,0,0,0,0,0,0,0,0,0,0,0,0,0,0,0,0,0,0,0,0,0,0,0
0,0,0,0,0,0,0,0,0,0,0,0,0,0,0,0,0,0,0,0,0,0,0,0,0
0,0,0,0,0,0,0,0,0,0,0,0,0,0,0,0,0,0,0,0,0,0,0,0,0
endlayer

layer
0,0,0,0,0,0,0,0,0,0,0,0,0,0,0,0,0,0,0,0,0,0,0,0,0
0,0,0,0,0,0,0,0,0,0,0,0,0,0,0,0,0,0,0,0,0,0,0,0,0
0,0,0,0,0,0,0,0,0,0,0,0,0,0,0,0,0,0,0,0,0,0,0,0,0
0,0,0,0,0,0,0,0,0,0,0,0,0,0,0,0,0,0,0,0,0,0,0,0,0
0,0,0,0,0,0,0,0,0,0,0,0,0,0,0,0,0,0,0,0,0,0,0,0,0
0,0,0,0,0,0,0,0,0,0,0,0,0,0,0,0,0,0,0,0,0,0,0,0,0
0,0,0,0,0,0,0,0,0,0,0,0,0,0,0,0,0,0,0,0,0,0,0,0,0
0,0,0,0,0,0,0,0,0,0,0,0,0,0,0,0,0,0,0,0,0,0,0,0,0
0,0,0,0,0,0,0,0,0,0,0,0,0,0,0,0,0,0,0,0,0,0,0,0,0
0,0,0,0,0,0,0,0,0,0,0,0,0,0,0,0,0,0,0,0,0,0,0,0,0
0,0,0,0,0,0,0,0,0,0,0,0,0,0,0,0,0,0,0,0,0,0,0,0,0
0,0,0,0,0,0,0,0,0,10,36,11,36,11,36,10,0,0,0,0,0,0,0,0,0
0,0,0,0,0,0,0,0,0,36,0,0,0,0,0,36,0,0,0,0,0,0,0,0,0
0,0,0,0,0,0,0,0,0,11,0,29,0,29,0,11,0,0,0,0,0,0,0,0,0
0,0,0,0,0,0,0,0,0,11,0,29,0,29,0,11,0,0,0,0,0,0,0,0,0
0,0,0,0,0,0,0,0,0,11,0,29,0,29,0,11,0,0,0,0,0,0,0,0,0
0,0,0,0,0,0,0,0,0,36,0,0,0,0,0,36,0,0,0,0,0,0,0,0,0
0,0,0,0,0,0,0,0,0,10,0,0,11,0,0,10,0,0,0,0,0,0,0,0,0
0,0,10,36,11,36,11,36,10,0,0,0,0,0,0,0,10,36,11,36,11,36,10,0,0
0,0,36,0,0,0,0,0,0,0,0,0,0,0,0,0,0,0,0,0,0,0,36,0,0
0,0,11,0,0,0,0,0,0,0,0,0,0,0,0,0,0,0,29,29,29,0,11,0,0
0,0,36,0,0,0,0,0,0,0,0,0,0,0,0,0,11,0,0,0,0,0,36,0,0
0,0,11,0,0,0,0,0,0,0,0,0,0,0,0,0,0,0,29,29,29,0,11,0,0
0,0,36,0,0,0,0,0,0,0,0,0,0,0,0,0,0,0,0,0,0,0,36,0,0
0,0,10,36,11,36,11,36,10,0,0,0,0,0,0,0,10,36,11,36,11,36,10,0,0
0,0,0,0,0,0,0,0,0,10,0,0,11,0,0,10,0,0,0,0,0,0,0,0,0
0,0,0,0,0,0,0,0,0,36,0,0,0,0,0,36,0,0,0,0,0,0,0,0,0
0,0,0,0,0,0,0,0,0,11,0,29,0,29,0,11,0,0,0,0,0,0,0,0,0
0,0,0,0,0,0,0,0,0,11,0,29,0,29,0,11,0,0,0,0,0,0,0,0,0
0,0,0,0,0,0,0,0,0,11,0,29,0,29,0,11,0,0,0,0,0,0,0,0,0
0,0,0,0,0,0,0,0,0,36,0,0,0,0,0,36,0,0,0,0,0,0,0,0,0
0,0,0,0,0,0,0,0,0,10,36,11,36,11,36,10,0,0,0,0,0,0,0,0,0
0,0,0,0,0,0,0,0,0,0,0,0,0,0,0,0,0,0,0,0,0,0,0,0,0
0,0,0,0,0,0,0,0,0,0,0,0,0,0,0,0,0,0,0,0,0,0,0,0,0
0,0,35,35,0,0,0,0,0,0,0,0,0,0,0,0,0,0,0,0,0,0,0,0,0
0,0,0,35,0,0,0,0,0,0,0,0,0,0,0,0,0,0,0,0,0,0,0,0,0
0,0,0,35,0,0,0,0,0,0,0,0,0,0,0,0,0,0,0,0,0,0,0,0,0
0,0,35,35,0,0,0,0,0,0,0,0,0,0,0,0,0,0,23,0,0,0,0,0,0
0,0,0,0,0,0,0,0,0,0,0,0,0,0,0,0,0,0,0,0,0,0,0,0,0
0,0,0,0,0,0,0,0,0,0,0,0,0,0,0,0,0,0,0,0,0,0,0,0,0
0,0,0,0,0,0,0,0,0,0,0,0,0,0,0,0,0,0,0,0,0,0,0,0,0
0,0,0,0,0,0,0,0,0,0,0,0,0,0,0,0,0,0,0,0,0,0,0,0,0
0,0,0,0,0,0,0,0,0,0,0,0,0,0,0,0,0,0,0,0,0,0,0,0,0
0,0,0,0,0,0,0,0,0,0,0,0,0,0,0,0,0,0,0,0,0,0,0,0,0
0,0,0,0,0,0,0,0,0,0,0,0,0,0,0,0,0,0,0,0,0,0,0,0,0
endlayer

layer
0,0,0,0,0,0,0,0,0,0,0,0,0,0,0,0,0,0,0,0,0,0,0,0,0
0,0,0,0,0,0,0,0,0,0,0,0,0,0,0,0,0,0,0,0,0,0,0,0,0
0,0,0,0,0,0,0,0,0,0,0,0,0,0,0,0,0,0,0,0,0,0,0,0,0
0,0,0,0,0,0,0,0,0,0,0,0,0,0,0,0,0,0,0,0,0,0,0,0,0
0,0,0,0,0,0,0,0,0,0,0,0,0,0,0,0,0,0,0,0,0,0,0,0,0
0,0,0,0,0,0,0,0,0,0,0,0,0,0,0,0,0,0,0,0,0,0,0,0,0
0,0,0,0,0,0,0,0,0,0,0,0,0,0,0,0,0,0,0,0,0,0,0,0,0
0,0,0,0,0,0,0,0,0,0,0,0,0,0,0,0,0,0,0,0,0,0,0,0,0
0,0,0,0,0,0,0,0,0,0,0,0,0,0,0,0,0,0,0,0,0,0,0,0,0
0,0,0,0,0,0,0,0,0,0,0,0,0,0,0,0,0,0,0,0,0,0,0,0,0
0,0,0,0,0,0,0,0,0,0,0,0,0,0,0,0,0,0,0,0,0,0,0,0,0
0,0,0,0,0,0,0,0,0,10,36,11,36,11,36,10,0,0,0,0,0,0,0,0,0
0,0,0,0,0,0,0,0,0,36,0,0,0,0,0,36,0,0,0,0,0,0,0,0,0
0,0,0,0,0,0,0,0,0,11,0,0,0,0,0,11,0,0,0,0,0,0,0,0,0
0,0,0,0,0,0,0,0,0,36,0,0,0,0,0,36,0,0,0,0,0,0,0,0,0
0,0,0,0,0,0,0,0,0,11,0,0,0,0,0,11,0,0,0,0,0,0,0,0,0
0,0,0,0,0,0,0,0,0,36,0,0,0,0,0,36,0,0,0,0,0,0,0,0,0
0,0,0,0,0,0,0,0,0,10,0,0,11,0,0,10,0,0,0,0,0,0,0,0,0
0,0,10,36,11,36,11,36,10,0,0,0,0,0,0,0,10,36,11,36,11,36,10,0,0
0,0,36,0,0,0,0,0,0,0,0,0,0,0,0,0,0,0,0,0,0,0,36,0,0
0,0,11,0,0,0,0,0,0,0,0,0,0,0,0,0,0,0,0,0,0,0,11,0,0
0,0,36,0,0,0,0,0,0,0,0,0,0,0,0,0,11,0,0,0,0,0,36,0,0
0,0,11,0,0,0,0,0,0,0,0,0,0,0,0,0,0,0,0,0,0,0,11,0,0
0,0,36,0,0,0,0,0,0,0,0,0,0,0,0,0,0,0,0,0,0,0,36,0,0
0,0,10,36,11,36,11,36,10,0,0,0,0,0,0,0,10,36,11,36,11,36,10,0,0
0,0,0,0,0,0,0,0,0,10,0,0,11,0,0,10,0,0,0,0,0,0,0,0,0
0,0,0,0,0,0,0,0,0,36,0,0,0,0,0,36,0,0,0,0,0,0,0,0,0
0,0,0,0,0,0,0,0,0,11,0,0,0,0,0,11,0,0,0,0,0,0,0,0,0
0,0,0,0,0,0,0,0,0,36,0,0,0,0,0,36,0,0,0,0,0,0,0,0,0
0,0,0,0,0,0,0,0,0,11,0,0,0,0,0,11,0,0,0,0,0,0,0,0,0
0,0,0,0,0,0,0,0,0,36,0,0,0,0,0,36,0,0,0,0,0,0,0,0,0
0,0,0,0,0,0,0,0,0,10,36,11,36,11,36,10,0,0,0,0,0,0,0,0,0
0,0,0,0,0,0,0,0,0,0,0,0,0,0,0,0,0,0,0,0,0,0,0,0,0
0,0,0,0,0,0,0,0,0,0,0,0,0,0,0,0,0,0,0,0,0,0,0,0,0
0,0,35,35,0,0,0,0,0,0,0,0,0,0,0,0,0,0,0,0,0,0,0,0,0
0,0,35,35,0,0,0,0,0,0,0,0,0,0,0,0,0,0,0,0,0,0,0,0,0
0,0,35,35,0,0,0,0,0,0,0,0,0,0,0,0,0,0,0,0,0,0,0,0,0
0,0,35,35,0,0,0,0,0,0,0,0,0,0,0,0,0,0,37,0,0,0,0,0,0
0,0,0,0,0,0,0,0,0,0,0,0,0,0,0,0,0,0,0,0,0,0,0,0,0
0,0,0,0,0,0,0,0,0,0,0,0,0,0,0,0,0,0,0,0,0,0,0,0,0
0,0,0,0,0,0,0,0,0,0,0,0,0,0,0,0,0,0,0,0,0,0,0,0,0
0,0,0,0,0,0,0,0,0,0,0,0,0,0,0,0,0,0,0,0,0,0,0,0,0
0,0,0,0,0,0,0,0,0,0,0,0,0,0,0,0,0,0,0,0,0,0,0,0,0
0,0,0,0,0,0,0,0,0,0,0,0,0,0,0,0,0,0,0,0,0,0,0,0,0
0,0,0,0,0,0,0,0,0,0,0,0,0,0,0,0,0,0,0,0,0,0,0,0,0
endlayer

layer
0,0,0,0,0,0,0,0,0,0,0,0,0,0,0,0,0,0,0,0,0,0,0,0,0
0,0,0,0,0,0,0,0,0,0,0,0,0,0,0,0,0,0,0,0,0,0,0,0,0
0,0,0,0,0,0,0,0,0,0,0,0,0,0,0,0,0,0,0,0,0,0,0,0,0
0,0,0,0,0,0,0,0,0,0,0,0,0,0,0,0,0,0,0,0,0,0,0,0,0
0,0,0,0,0,0,0,0,0,0,0,0,0,0,0,0,0,0,0,0,0,0,0,0,0
0,0,0,0,0,0,0,0,0,0,0,0,0,0,0,0,0,0,0,0,0,0,0,0,0
0,0,0,0,0,0,0,0,0,0,0,0,0,0,0,0,0,0,0,0,0,0,0,0,0
0,0,0,0,0,0,0,0,0,0,0,0,0,0,0,0,0,0,0,0,0,0,0,0,0
0,0,0,0,0,0,0,0,0,0,0,0,0,0,0,0,0,0,0,0,0,0,0,0,0
0,0,0,0,0,0,0,0,0,0,0,0,0,0,0,0,0,0,0,0,0,0,0,0,0
0,0,0,0,0,0,0,0,0,0,0,0,0,0,0,0,0,0,0,0,0,0,0,0,0
0,0,0,0,0,0,0,0,0,10,36,11,36,11,36,10,0,0,0,0,0,0,0,0,0
0,0,0,0,0,0,0,0,0,36,0,0,0,0,0,36,0,0,0,0,0,0,0,0,0
0,0,0,0,0,0,0,0,0,11,0,0,0,0,0,11,0,0,0,0,0,0,0,0,0
0,0,0,0,0,0,0,0,0,36,0,0,0,0,0,36,0,0,0,0,0,0,0,0,0
0,0,0,0,0,0,0,0,0,11,0,0,0,0,0,11,0,0,0,0,0,0,0,0,0
0,0,0,0,0,0,0,0,0,36,0,0,0,0,0,36,0,0,0,0,0,0,0,0,0
0,0,0,0,0,0,0,0,0,10,0,0,11,0,0,10,0,0,0,0,0,0,0,0,0
0,0,10,36,11,36,11,36,10,0,0,0,0,0,0,0,10,36,11,36,11,36,10,0,0
0,0,36,0,0,0,0,0,0,0,0,0,0,0,0,0,0,0,0,0,0,0,36,0,0
0,0,11,0,0,0,0,0,0,0,0,0,0,0,0,0,0,0,0,0,0,0,11,0,0
0,0,36,0,0,0,0,0,0,0,0,0,0,0,0,0,11,0,0,0,0,0,36,0,0
0,0,11,0,0,0,0,0,0,0,0,0,0,0,0,0,0,0,0,0,0,0,11,0,0
0,0,36,0,0,0,0,0,0,0,0,0,0,0,0,0,0,0,0,0,0,0,36,0,0
0,0,10,36,11,36,11,36,10,0,0,0,0,0,0,0,10,36,11,36,11,36,10,0,0
0,0,0,0,0,0,0,0,0,10,0,0,11,0,0,10,0,0,0,0,0,0,0,0,0
0,0,0,0,0,0,0,0,0,36,0,0,0,0,0,36,0,0,0,0,0,0,0,0,0
0,0,0,0,0,0,0,0,0,11,0,0,0,0,0,11,0,0,0,0,0,0,0,0,0
0,0,0,0,0,0,0,0,0,36,0,0,0,0,0,36,0,0,0,0,0,0,0,0,0
0,0,0,0,0,0,0,0,0,11,0,0,0,0,0,11,0,0,0,0,0,0,0,0,0
0,0,0,0,0,0,0,0,0,36,0,0,0,0,0,36,0,0,0,0,0,0,0,0,0
0,0,0,0,0,0,0,0,0,10,36,11,36,11,36,10,0,0,0,0,0,0,0,0,0
0,0,0,0,0,0,0,0,0,0,0,0,0,0,0,0,0,0,0,0,0,0,0,0,0
0,0,0,0,0,0,0,0,0,0,0,0,0,0,0,0,0,0,0,0,0,0,0,0,0
0,0,0,0,0,0,0,0,0,0,0,0,0,0,0,0,0,0,0,0,0,0,0,0,0
0,0,0,0,0,0,0,0,0,0,0,0,0,0,0,0,0,0,0,0,0,0,0,0,0
0,0,0,0,0,0,0,0,0,0,0,0,0,0,0,0,0,0,0,0,0,0,0,0,0
0,0,0,0,0,0,0,0,0,0,0,0,0,0,0,0,0,0,23,0,0,0,0,0,0
0,0,0,0,0,0,0,0,0,0,0,0,0,0,0,0,0,0,0,0,0,0,0,0,0
0,0,0,0,0,0,0,0,0,0,0,0,0,0,0,0,0,0,0,0,0,0,0,0,0
0,0,0,0,0,0,0,0,0,0,0,0,0,0,0,0,0,0,0,0,0,0,0,0,0
0,0,0,0,0,0,0,0,0,0,0,0,0,0,0,0,0,0,0,0,0,0,0,0,0
0,0,0,0,0,0,0,0,0,0,0,0,0,0,0,0,0,0,0,0,0,0,0,0,0
0,0,0,0,0,0,0,0,0,0,0,0,0,0,0,0,0,0,0,0,0,0,0,0,0
0,0,0,0,0,0,0,0,0,0,0,0,0,0,0,0,0,0,0,0,0,0,0,0,0
endlayer

layer
0,0,0,0,0,0,0,0,0,0,0,0,0,0,0,0,0,0,0,0,0,0,0,0,0
0,0,0,0,0,0,0,0,0,0,0,0,0,0,0,0,0,0,0,0,0,0,0,0,0
0,0,0,0,0,0,0,0,0,0,0,0,0,0,0,0,0,0,0,0,0,0,0,0,0
0,0,0,0,0,0,0,0,0,0,0,0,0,0,0,0,0,0,0,0,0,0,0,0,0
0,0,0,0,0,0,0,0,0,0,0,0,0,0,0,0,0,0,0,0,0,0,0,0,0
0,0,0,0,0,0,0,0,0,0,0,0,0,0,0,0,0,0,0,0,0,0,0,0,0
0,0,0,0,0,0,0,0,0,0,0,0,0,0,0,0,0,0,0,0,0,0,0,0,0
0,0,0,0,0,0,0,0,0,0,0,0,0,0,0,0,0,0,0,0,0,0,0,0,0
0,0,0,0,0,0,0,0,0,0,0,0,0,0,0,0,0,0,0,0,0,0,0,0,0
0,0,0,0,0,0,0,0,0,0,0,0,0,0,0,0,0,0,0,0,0,0,0,0,0
0,0,0,0,0,0,0,0,0,0,0,0,0,0,0,0,0,0,0,0,0,0,0,0,0
0,0,0,0,0,0,0,0,0,10,10,10,10,10,10,10,0,0,0,0,0,0,0,0,0
0,0,0,0,0,0,0,0,0,10,22,22,22,22,22,10,0,0,0,0,0,0,0,0,0
0,0,0,0,0,0,0,0,0,10,22,22,22,22,22,10,0,0,0,0,0,0,0,0,0
0,0,0,0,0,0,0,0,0,10,22,22,22,22,22,10,0,0,0,0,0,0,0,0,0
0,0,0,0,0,0,0,0,0,10,22,22,22,22,22,10,0,0,0,0,0,0,0,0,0
0,0,0,0,0,0,0,0,0,10,22,22,22,22,22,10,0,0,0,0,0,0,0,0,0
0,0,0,0,0,0,0,0,0,10,10,10,3,10,10,10,0,0,0,0,0,0,0,0,0
0,0,10,10,10,10,10,10,10,24,22,22,22,22,22,22,10,10,10,10,10,10,10,0,0
0,0,10,22,22,22,22,22,10,22,22,22,22,22,22,22,10,22,22,22,22,22,10,0,0
0,0,10,22,22,22,22,22,10,22,22,0,0,0,22,22,10,22,22,22,22,22,10,0,0
0,0,10,22,22,22,22,22,10,22,22,0,0,0,22,22,3,22,22,22,22,22,10,0,0
0,0,10,22,22,22,22,22,10,22,22,0,0,0,22,22,10,22,22,22,22,22,10,0,0
0,0,10,22,22,22,22,22,10,22,22,22,22,22,22,22,10,22,22,22,22,22,10,0,0
0,0,10,10,10,10,10,10,10,22,22,22,22,22,22,22,10,10,10,10,10,10,10,0,0
0,0,0,0,0,0,0,0,0,10,10,10,3,10,10,10,0,0,0,0,0,0,0,0,0
0,0,0,0,0,0,0,0,0,10,22,22,22,22,22,10,0,0,0,0,0,0,0,0,0
0,0,0,0,0,0,0,0,0,10,22,22,22,22,22,10,0,0,0,0,0,0,0,0,0
0,0,0,0,0,0,0,0,0,10,22,22,22,22,22,10,0,0,0,0,0,0,0,0,0
0,0,0,0,0,0,0,0,0,10,22,22,22,22,22,10,0,0,0,0,0,0,0,0,0
0,0,0,0,0,0,0,0,0,10,22,22,22,22,22,10,0,0,0,0,0,0,0,0,0
0,0,0,0,0,0,0,0,0,10,10,10,10,10,10,10,0,0,0,0,0,0,0,0,0
0,0,0,0,0,0,0,0,0,0,0,0,0,0,0,0,0,0,0,0,0,0,0,0,0
0,0,0,0,0,0,0,0,0,0,0,0,0,0,0,0,0,0,0,0,0,0,0,0,0
0,0,0,0,0,0,0,0,0,0,0,0,0,0,0,0,0,0,0,0,0,0,0,0,0
0,0,0,0,0,0,0,0,0,0,0,0,0,0,0,0,0,0,0,0,0,0,0,0,0
0,0,0,0,0,0,0,0,0,0,0,0,0,0,0,0,0,0,0,0,0,0,0,0,0
0,0,0,0,0,0,0,0,0,0,0,0,0,0,0,0,0,0,0,0,0,0,0,0,0
0,0,0,0,0,0,0,0,0,0,0,0,0,0,0,0,0,0,0,0,0,0,0,0,0
0,0,0,0,0,0,0,0,0,0,0,0,0,0,0,0,0,0,0,0,0,0,0,0,0
0,0,0,0,0,0,0,0,0,0,0,0,0,0,0,0,0,0,0,0,0,0,0,0,0
0,0,0,0,0,0,0,0,0,0,0,0,0,0,0,0,0,0,0,0,0,0,0,0,0
0,0,0,0,0,0,0,0,0,0,0,0,0,0,0,0,0,0,0,0,0,0,0,0,0
0,0,0,0,0,0,0,0,0,0,0,0,0,0,0,0,0,0,0,0,0,0,0,0,0
0,0,0,0,0,0,0,0,0,0,0,0,0,0,0,0,0,0,0,0,0,0,0,0,0
endlayer

layer
0,0,0,0,0,0,0,0,0,0,0,0,0,0,0,0,0,0,0,0,0,0,0,0,0
0,0,0,0,0,0,0,0,0,0,0,0,0,0,0,0,0,0,0,0,0,0,0,0,0
0,0,0,0,0,0,0,0,0,0,0,0,0,0,0,0,0,0,0,0,0,0,0,0,0
0,0,0,0,0,0,0,0,0,0,0,0,0,0,0,0,0,0,0,0,0,0,0,0,0
0,0,0,0,0,0,0,0,0,0,0,0,0,0,0,0,0,0,0,0,0,0,0,0,0
0,0,0,0,0,0,0,0,0,0,0,0,0,0,0,0,0,0,0,0,0,0,0,0,0
0,0,0,0,0,0,0,0,0,0,0,0,0,0,0,0,0,0,0,0,0,0,0,0,0
0,0,0,0,0,0,0,0,0,0,0,0,0,0,0,0,0,0,0,0,0,0,0,0,0
0,0,0,0,0,0,0,0,0,0,0,0,0,0,0,0,0,0,0,0,0,0,0,0,0
0,0,0,0,0,0,0,0,0,0,0,0,0,0,0,0,0,0,0,0,0,0,0,0,0
0,0,0,0,0,0,0,0,0,0,0,0,0,0,0,0,0,0,0,0,0,0,0,0,0
0,0,0,0,0,0,0,0,0,10,36,11,36,11,36,10,0,0,0,0,0,0,0,0,0
0,0,0,0,0,0,0,0,0,36,40,0,0,0,0,36,0,0,0,0,0,0,0,0,0
0,0,0,0,0,0,0,0,0,11,41,0,0,29,0,11,0,0,0,0,0,0,0,0,0
0,0,0,0,0,0,0,0,0,36,40,0,0,29,0,36,0,0,0,0,0,0,0,0,0
0,0,0,0,0,0,0,0,0,11,41,0,0,29,0,11,0,0,0,0,0,0,0,0,0
0,0,0,0,0,0,0,0,0,36,40,0,0,0,0,36,0,0,0,0,0,0,0,0,0
0,0,0,0,0,0,0,0,0,10,0,0,11,0,0,10,0,0,0,0,0,0,0,0,0
0,0,10,36,11,36,11,36,10,0,0,0,0,0,0,0,10,36,11,36,11,36,10,0,0
0,0,36,0,0,0,0,0,0,0,39,39,39,39,39,0,0,0,0,0,0,0,36,0,0
0,0,11,0,29,29,29,0,0,0,39,0,0,0,39,0,0,0,29,29,29,0,11,0,0
0,0,36,0,0,0,0,0,11,0,39,0,0,0,39,0,11,0,0,0,0,0,36,0,0
0,0,11,0,29,29,29,0,0,0,39,0,0,0,39,0,0,0,29,29,29,0,11,0,0
0,0,36,0,0,0,0,0,0,0,39,39,39,39,39,0,0,0,0,0,0,0,36,0,0
0,0,10,36,11,36,11,36,10,0,0,0,0,0,0,0,10,36,11,36,11,36,10,0,0
0,0,0,0,0,0,0,0,0,10,0,0,11,0,0,10,0,0,0,0,0,0,0,0,0
0,0,0,0,0,0,0,0,0,36,40,0,0,0,0,36,0,0,0,0,0,0,0,0,0
0,0,0,0,0,0,0,0,0,11,41,0,0,29,0,11,0,0,0,0,0,0,0,0,0
0,0,0,0,0,0,0,0,0,36,40,0,0,29,0,36,0,0,0,0,0,0,0,0,0
0,0,0,0,0,0,0,0,0,11,41,0,0,29,0,11,0,0,0,0,0,0,0,0,0
0,0,0,0,0,0,0,0,0,36,40,0,0,0,0,36,0,0,0,0,0,0,0,0,0
0,0,0,0,0,0,0,0,0,10,36,11,36,11,36,10,0,0,0,0,0,0,0,0,0
0,0,0,0,0,0,0,0,0,0,0,0,0,0,0,0,0,0,0,0,0,0,0,0,0
0,0,0,0,0,0,0,0,0,0,0,0,0,0,0,0,0,0,0,0,0,0,0,0,0
0,0,0,0,0,0,0,0,0,0,0,0,0,0,0,0,0,0,0,0,0,0,0,0,0
0,0,0,0,0,0,0,0,0,0,0,0,0,0,0,0,0,0,0,0,0,0,0,0,0
0,0,0,0,0,0,0,0,0,0,0,0,0,0,0,0,0,0,0,0,0,0,0,0,0
0,0,0,0,0,0,0,0,0,0,0,0,0,0,0,0,0,0,0,0,0,0,0,0,0
0,0,0,0,0,0,0,0,0,0,0,0,0,0,0,0,0,0,0,0,0,0,0,0,0
0,0,0,0,0,0,0,0,0,0,0,0,0,0,0,0,0,0,0,0,0,0,0,0,0
0,0,0,0,0,0,0,0,0,0,0,0,0,0,0,0,0,0,0,0,0,0,0,0,0
0,0,0,0,0,0,0,0,0,0,0,0,0,0,0,0,0,0,0,0,0,0,0,0,0
0,0,0,0,0,0,0,0,0,0,0,0,0,0,0,0,0,0,0,0,0,0,0,0,0
0,0,0,0,0,0,0,0,0,0,0,0,0,0,0,0,0,0,0,0,0,0,0,0,0
0,0,0,0,0,0,0,0,0,0,0,0,0,0,0,0,0,0,0,0,0,0,0,0,0
endlayer

layer
0,0,0,0,0,0,0,0,0,0,0,0,0,0,0,0,0,0,0,0,0,0,0,0,0
0,0,0,0,0,0,0,0,0,0,0,0,0,0,0,0,0,0,0,0,0,0,0,0,0
0,0,0,0,0,0,0,0,0,0,0,0,0,0,0,0,0,0,0,0,0,0,0,0,0
0,0,0,0,0,0,0,0,0,0,0,0,0,0,0,0,0,0,0,0,0,0,0,0,0
0,0,0,0,0,0,0,0,0,0,0,0,0,0,0,0,0,0,0,0,0,0,0,0,0
0,0,0,0,0,0,0,0,0,0,0,0,0,0,0,0,0,0,0,0,0,0,0,0,0
0,0,0,0,0,0,0,0,0,0,0,0,0,0,0,0,0,0,0,0,0,0,0,0,0
0,0,0,0,0,0,0,0,0,0,0,0,0,0,0,0,0,0,0,0,0,0,0,0,0
0,0,0,0,0,0,0,0,0,0,0,0,0,0,0,0,0,0,0,0,0,0,0,0,0
0,0,0,0,0,0,0,0,0,0,0,0,0,0,0,0,0,0,0,0,0,0,0,0,0
0,0,0,0,0,0,0,0,0,0,0,0,0,0,0,0,0,0,0,0,0,0,0,0,0
0,0,0,0,0,0,0,0,0,10,36,11,36,11,36,10,0,0,0,0,0,0,0,0,0
0,0,0,0,0,0,0,0,0,36,0,0,0,0,0,36,0,0,0,0,0,0,0,0,0
0,0,0,0,0,0,0,0,0,11,0,0,0,29,0,11,0,0,0,0,0,0,0,0,0
0,0,0,0,0,0,0,0,0,36,0,0,0,29,0,36,0,0,0,0,0,0,0,0,0
0,0,0,0,0,0,0,0,0,11,0,0,0,29,0,11,0,0,0,0,0,0,0,0,0
0,0,0,0,0,0,0,0,0,36,0,0,0,0,0,36,0,0,0,0,0,0,0,0,0
0,0,0,0,0,0,0,0,0,10,0,0,11,0,0,10,0,0,0,0,0,0,0,0,0
0,0,10,36,11,36,11,36,10,0,0,0,0,0,0,0,10,36,11,36,11,36,10,0,0
0,0,36,0,0,0,0,0,0,0,0,0,0,0,0,0,0,0,0,0,0,0,36,0,0
0,0,11,0,29,29,29,0,0,0,0,0,0,0,0,0,0,0,29,29,29,0,11,0,0
0,0,36,0,0,0,0,0,11,0,0,0,0,0,0,0,11,0,0,0,0,0,36,0,0
0,0,11,0,29,29,29,0,0,0,0,0,0,0,0,0,0,0,29,29,29,0,11,0,0
0,0,36,0,0,0,0,0,0,0,0,0,0,0,0,0,0,0,0,0,0,0,36,0,0
0,0,10,36,11,36,11,36,10,0,0,0,0,0,0,0,10,36,11,36,11,36,10,0,0
0,0,0,0,0,0,0,0,0,10,0,0,11,0,0,10,0,0,0,0,0,0,0,0,0
0,0,0,0,0,0,0,0,0,36,0,0,0,0,0,36,0,0,0,0,0,0,0,0,0
0,0,0,0,0,0,0,0,0,11,0,0,0,29,0,11,0,0,0,0,0,0,0,0,0
0,0,0,0,0,0,0,0,0,36,0,0,0,29,0,36,0,0,0,0,0,0,0,0,0
0,0,0,0,0,0,0,0,0,11,0,0,0,29,0,11,0,0,0,0,0,0,0,0,0
0,0,0,0,0,0,0,0,0,36,0,0,0,0,0,36,0,0,0,0,0,0,0,0,0
0,0,0,0,0,0,0,0,0,10,36,11,36,11,36,10,0,0,0,0,0,0,0,0,0
0,0,0,0,0,0,0,0,0,0,0,0,0,0,0,0,0,0,0,0,0,0,0,0,0
0,0,0,0,0,0,0,0,0,0,0,0,0,0,0,0,0,0,0,0,0,0,0,0,0
0,0,0,0,0,0,0,0,0,0,0,0,0,0,0,0,0,0,0,0,0,0,0,0,0
0,0,0,0,0,0,0,0,0,0,0,0,0,0,0,0,0,0,0,0,0,0,0,0,0
0,0,0,0,0,0,0,0,0,0,0,0,0,0,0,0,0,0,0,0,0,0,0,0,0
0,0,0,0,0,0,0,0,0,0,0,0,0,0,0,0,0,0,0,0,0,0,0,0,0
0,0,0,0,0,0,0,0,0,0,0,0,0,0,0,0,0,0,0,0,0,0,0,0,0
0,0,0,0,0,0,0,0,0,0,0,0,0,0,0,0,0,0,0,0,0,0,0,0,0
0,0,0,0,0,0,0,0,0,0,0,0,0,0,0,0,0,0,0,0,0,0,0,0,0
0,0,0,0,0,0,0,0,0,0,0,0,0,0,0,0,0,0,0,0,0,0,0,0,0
0,0,0,0,0,0,0,0,0,0,0,0,0,0,0,0,0,0,0,0,0,0,0,0,0
0,0,0,0,0,0,0,0,0,0,0,0,0,0,0,0,0,0,0,0,0,0,0,0,0
0,0,0,0,0,0,0,0,0,0,0,0,0,0,0,0,0,0,0,0,0,0,0,0,0
endlayer

layer
0,0,0,0,0,0,0,0,0,0,0,0,0,0,0,0,0,0,0,0,0,0,0,0,0
0,0,0,0,0,0,0,0,0,0,0,0,0,0,0,0,0,0,0,0,0,0,0,0,0
0,0,0,0,0,0,0,0,0,0,0,0,0,0,0,0,0,0,0,0,0,0,0,0,0
0,0,0,0,0,0,0,0,0,0,0,0,0,0,0,0,0,0,0,0,0,0,0,0,0
0,0,0,0,0,0,0,0,0,0,0,0,0,0,0,0,0,0,0,0,0,0,0,0,0
0,0,0,0,0,0,0,0,0,0,0,0,0,0,0,0,0,0,0,0,0,0,0,0,0
0,0,0,0,0,0,0,0,0,0,0,0,0,0,0,0,0,0,0,0,0,0,0,0,0
0,0,0,0,0,0,0,0,0,0,0,0,0,0,0,0,0,0,0,0,0,0,0,0,0
0,0,0,0,0,0,0,0,0,0,0,0,0,0,0,0,0,0,0,0,0,0,0,0,0
0,0,0,0,0,0,0,0,0,0,0,0,0,0,0,0,0,0,0,0,0,0,0,0,0
0,0,0,0,0,0,0,0,0,0,0,0,0,0,0,0,0,0,0,0,0,0,0,0,0
0,0,0,0,0,0,0,0,0,10,36,11,36,11,36,10,0,0,0,0,0,0,0,0,0
0,0,0,0,0,0,0,0,0,36,0,0,0,0,0,36,0,0,0,0,0,0,0,0,0
0,0,0,0,0,0,0,0,0,11,0,0,0,0,0,11,0,0,0,0,0,0,0,0,0
0,0,0,0,0,0,0,0,0,36,0,0,0,0,0,36,0,0,0,0,0,0,0,0,0
0,0,0,0,0,0,0,0,0,11,0,0,0,0,0,11,0,0,0,0,0,0,0,0,0
0,0,0,0,0,0,0,0,0,36,0,0,0,0,0,36,0,0,0,0,0,0,0,0,0
0,0,0,0,0,0,0,0,0,10,0,0,11,0,0,10,0,0,0,0,0,0,0,0,0
0,0,10,36,11,36,11,36,10,0,0,0,0,0,0,0,10,36,11,36,11,36,10,0,0
0,0,36,0,0,0,0,0,0,0,0,0,0,0,0,0,0,0,0,0,0,0,36,0,0
0,0,11,0,0,0,0,0,0,0,0,0,0,0,0,0,0,0,0,0,0,0,11,0,0
0,0,36,0,0,0,0,0,11,0,0,0,0,0,0,0,11,0,0,0,0,0,36,0,0
0,0,11,0,0,0,0,0,0,0,0,0,0,0,0,0,0,0,0,0,0,0,11,0,0
0,0,36,0,0,0,0,0,0,0,0,0,0,0,0,0,0,0,0,0,0,0,36,0,0
0,0,10,36,11,36,11,36,10,0,0,0,0,0,0,0,10,36,11,36,11,36,10,0,0
0,0,0,0,0,0,0,0,0,10,0,0,11,0,0,10,0,0,0,0,0,0,0,0,0
0,0,0,0,0,0,0,0,0,36,0,0,0,0,0,36,0,0,0,0,0,0,0,0,0
0,0,0,0,0,0,0,0,0,11,0,0,0,0,0,11,0,0,0,0,0,0,0,0,0
0,0,0,0,0,0,0,0,0,36,0,0,0,0,0,36,0,0,0,0,0,0,0,0,0
0,0,0,0,0,0,0,0,0,11,0,0,0,0,0,11,0,0,0,0,0,0,0,0,0
0,0,0,0,0,0,0,0,0,36,0,0,0,0,0,36,0,0,0,0,0,0,0,0,0
0,0,0,0,0,0,0,0,0,10,36,11,36,11,36,10,0,0,0,0,0,0,0,0,0
0,0,0,0,0,0,0,0,0,0,0,0,0,0,0,0,0,0,0,0,0,0,0,0,0
0,0,0,0,0,0,0,0,0,0,0,0,0,0,0,0,0,0,0,0,0,0,0,0,0
0,0,0,0,0,0,0,0,0,0,0,0,0,0,0,0,0,0,0,0,0,0,0,0,0
0,0,0,0,0,0,0,0,0,0,0,0,0,0,0,0,0,0,0,0,0,0,0,0,0
0,0,0,0,0,0,0,0,0,0,0,0,0,0,0,0,0,0,0,0,0,0,0,0,0
0,0,0,0,0,0,0,0,0,0,0,0,0,0,0,0,0,0,0,0,0,0,0,0,0
0,0,0,0,0,0,0,0,0,0,0,0,0,0,0,0,0,0,0,0,0,0,0,0,0
0,0,0,0,0,0,0,0,0,0,0,0,0,0,0,0,0,0,0,0,0,0,0,0,0
0,0,0,0,0,0,0,0,0,0,0,0,0,0,0,0,0,0,0,0,0,0,0,0,0
0,0,0,0,0,0,0,0,0,0,0,0,0,0,0,0,0,0,0,0,0,0,0,0,0
0,0,0,0,0,0,0,0,0,0,0,0,0,0,0,0,0,0,0,0,0,0,0,0,0
0,0,0,0,0,0,0,0,0,0,0,0,0,0,0,0,0,0,0,0,0,0,0,0,0
0,0,0,0,0,0,0,0,0,0,0,0,0,0,0,0,0,0,0,0,0,0,0,0,0
endlayer

layer
0,0,0,0,0,0,0,0,0,0,0,0,0,0,0,0,0,0,0,0,0,0,0,0,0
0,0,0,0,0,0,0,0,0,0,0,0,0,0,0,0,0,0,0,0,0,0,0,0,0
0,0,0,0,0,0,0,0,0,0,0,0,0,0,0,0,0,0,0,0,0,0,0,0,0
0,0,0,0,0,0,0,0,0,0,0,0,0,0,0,0,0,0,0,0,0,0,0,0,0
0,0,0,0,0,0,0,0,0,0,0,0,0,0,0,0,0,0,0,0,0,0,0,0,0
0,0,0,0,0,0,0,0,0,0,0,0,0,0,0,0,0,0,0,0,0,0,0,0,0
0,0,0,0,0,0,0,0,0,0,0,0,0,0,0,0,0,0,0,0,0,0,0,0,0
0,0,0,0,0,0,0,0,0,0,0,0,0,0,0,0,0,0,0,0,0,0,0,0,0
0,0,0,0,0,0,0,0,0,0,0,0,0,0,0,0,0,0,0,0,0,0,0,0,0
0,0,0,0,0,0,0,0,0,0,0,0,0,0,0,0,0,0,0,0,0,0,0,0,0
0,0,0,0,0,0,0,0,0,0,0,0,0,0,0,0,0,0,0,0,0,0,0,0,0
0,0,0,0,0,0,0,0,0,10,36,11,36,11,36,10,0,0,0,0,0,0,0,0,0
0,0,0,0,0,0,0,0,0,36,0,0,0,0,0,36,0,0,0,0,0,0,0,0,0
0,0,0,0,0,0,0,0,0,11,0,0,0,0,0,11,0,0,0,0,0,0,0,0,0
0,0,0,0,0,0,0,0,0,36,0,0,0,0,0,36,0,0,0,0,0,0,0,0,0
0,0,0,0,0,0,0,0,0,11,0,0,0,0,0,11,0,0,0,0,0,0,0,0,0
0,0,0,0,0,0,0,0,0,36,0,0,0,0,0,36,0,0,0,0,0,0,0,0,0
0,0,0,0,0,0,0,0,0,10,0,0,11,0,0,10,0,0,0,0,0,0,0,0,0
0,0,10,36,11,36,11,36,10,0,0,0,0,0,0,0,10,36,11,36,11,36,10,0,0
0,0,36,0,0,0,0,0,0,0,0,0,0,0,0,0,0,0,0,0,0,0,36,0,0
0,0,11,0,0,0,0,0,0,0,0,0,0,0,0,0,0,0,0,0,0,0,11,0,0
0,0,36,0,0,0,0,0,11,0,0,0,0,0,0,0,11,0,0,0,0,0,36,0,0
0,0,11,0,0,0,0,0,0,0,0,0,0,0,0,0,0,0,0,0,0,0,11,0,0
0,0,36,0,0,0,0,0,0,0,0,0,0,0,0,0,0,0,0,0,0,0,36,0,0
0,0,10,36,11,36,11,36,10,0,0,0,0,0,0,0,10,36,11,36,11,36,10,0,0
0,0,0,0,0,0,0,0,0,10,0,0,11,0,0,10,0,0,0,0,0,0,0,0,0
0,0,0,0,0,0,0,0,0,36,0,0,0,0,0,36,0,0,0,0,0,0,0,0,0
0,0,0,0,0,0,0,0,0,11,0,0,0,0,0,11,0,0,0,0,0,0,0,0,0
0,0,0,0,0,0,0,0,0,36,0,0,0,0,0,36,0,0,0,0,0,0,0,0,0
0,0,0,0,0,0,0,0,0,11,0,0,0,0,0,11,0,0,0,0,0,0,0,0,0
0,0,0,0,0,0,0,0,0,36,0,0,0,0,0,36,0,0,0,0,0,0,0,0,0
0,0,0,0,0,0,0,0,0,10,36,11,36,11,36,10,0,0,0,0,0,0,0,0,0
0,0,0,0,0,0,0,0,0,0,0,0,0,0,0,0,0,0,0,0,0,0,0,0,0
0,0,0,0,0,0,0,0,0,0,0,0,0,0,0,0,0,0,0,0,0,0,0,0,0
0,0,0,0,0,0,0,0,0,0,0,0,0,0,0,0,0,0,0,0,0,0,0,0,0
0,0,0,0,0,0,0,0,0,0,0,0,0,0,0,0,0,0,0,0,0,0,0,0,0
0,0,0,0,0,0,0,0,0,0,0,0,0,0,0,0,0,0,0,0,0,0,0,0,0
0,0,0,0,0,0,0,0,0,0,0,0,0,0,0,0,0,0,0,0,0,0,0,0,0
0,0,0,0,0,0,0,0,0,0,0,0,0,0,0,0,0,0,0,0,0,0,0,0,0
0,0,0,0,0,0,0,0,0,0,0,0,0,0,0,0,0,0,0,0,0,0,0,0,0
0,0,0,0,0,0,0,0,0,0,0,0,0,0,0,0,0,0,0,0,0,0,0,0,0
0,0,0,0,0,0,0,0,0,0,0,0,0,0,0,0,0,0,0,0,0,0,0,0,0
0,0,0,0,0,0,0,0,0,0,0,0,0,0,0,0,0,0,0,0,0,0,0,0,0
0,0,0,0,0,0,0,0,0,0,0,0,0,0,0,0,0,0,0,0,0,0,0,0,0
0,0,0,0,0,0,0,0,0,0,0,0,0,0,0,0,0,0,0,0,0,0,0,0,0
endlayer

layer
0,0,0,0,0,0,0,0,0,0,0,0,0,0,0,0,0,0,0,0,0,0,0,0,0
0,0,0,0,0,0,0,0,0,0,0,0,0,0,0,0,0,0,0,0,0,0,0,0,0
0,0,0,0,0,0,0,0,0,0,0,0,0,0,0,0,0,0,0,0,0,0,0,0,0
0,0,0,0,0,0,0,0,0,0,0,0,0,0,0,0,0,0,0,0,0,0,0,0,0
0,0,0,0,0,0,0,0,0,0,0,0,0,0,0,0,0,0,0,0,0,0,0,0,0
0,0,0,0,0,0,0,0,0,0,0,0,0,0,0,0,0,0,0,0,0,0,0,0,0
0,0,0,0,0,0,0,0,0,0,0,0,0,0,0,0,0,0,0,0,0,0,0,0,0
0,0,0,0,0,0,0,0,0,0,0,0,0,0,0,0,0,0,0,0,0,0,0,0,0
0,0,0,0,0,0,0,0,0,0,0,0,0,0,0,0,0,0,0,0,0,0,0,0,0
0,0,0,0,0,0,0,0,0,0,0,0,0,0,0,0,0,0,0,0,0,0,0,0,0
0,0,0,0,0,0,0,0,0,0,0,0,0,0,0,0,0,0,0,0,0,0,0,0,0
0,0,0,0,0,0,0,0,0,10,10,10,10,10,10,10,0,0,0,0,0,0,0,0,0
0,0,0,0,0,0,0,0,0,10,11,11,11,11,11,10,0,0,0,0,0,0,0,0,0
0,0,0,0,0,0,0,0,0,10,11,42,42,42,11,10,0,0,0,0,0,0,0,0,0
0,0,0,0,0,0,0,0,0,10,11,42,42,42,11,10,0,0,0,0,0,0,0,0,0
0,0,0,0,0,0,0,0,0,10,11,11,11,11,11,10,0,0,0,0,0,0,0,0,0
0,0,0,0,0,0,0,0,0,10,10,10,10,10,10,10,0,0,0,0,0,0,0,0,0
0,0,0,0,0,0,0,0,0,10,0,0,11,0,0,10,0,0,0,0,0,0,0,0,0
0,0,10,10,10,10,10,10,10,0,0,0,0,0,0,0,10,10,10,10,10,10,10,0,0
0,0,10,11,11,11,11,10,0,0,0,0,0,0,0,0,0,10,11,11,11,11,10,0,0
0,0,10,11,42,42,11,10,0,0,0,0,0,0,0,0,0,10,11,42,42,11,10,0,0
0,0,10,11,42,42,11,10,11,0,0,0,0,0,0,0,11,10,11,42,42,11,10,0,0
0,0,10,11,42,42,11,10,0,0,0,0,0,0,0,0,0,10,11,42,42,11,10,0,0
0,0,10,11,11,11,11,10,0,0,0,0,0,0,0,0,0,10,11,11,11,11,10,0,0
0,0,10,10,10,10,10,10,10,0,0,0,0,0,0,0,10,10,10,10,10,10,10,0,0
0,0,0,0,0,0,0,0,0,10,0,0,11,0,0,10,0,0,0,0,0,0,0,0,0
0,0,0,0,0,0,0,0,0,10,10,10,10,10,10,10,0,0,0,0,0,0,0,0,0
0,0,0,0,0,0,0,0,0,10,11,11,11,11,11,10,0,0,0,0,0,0,0,0,0
0,0,0,0,0,0,0,0,0,10,11,42,42,42,11,10,0,0,0,0,0,0,0,0,0
0,0,0,0,0,0,0,0,0,10,11,42,42,42,11,10,0,0,0,0,0,0,0,0,0
0,0,0,0,0,0,0,0,0,10,11,11,11,11,11,10,0,0,0,0,0,0,0,0,0
0,0,0,0,0,0,0,0,0,10,10,10,10,10,10,10,0,0,0,0,0,0,0,0,0
0,0,0,0,0,0,0,0,0,0,0,0,0,0,0,0,0,0,0,0,0,0,0,0,0
0,0,0,0,0,0,0,0,0,0,0,0,0,0,0,0,0,0,0,0,0,0,0,0,0
0,0,0,0,0,0,0,0,0,0,0,0,0,0,0,0,0,0,0,0,0,0,0,0,0
0,0,0,0,0,0,0,0,0,0,0,0,0,0,0,0,0,0,0,0,0,0,0,0,0
0,0,0,0,0,0,0,0,0,0,0,0,0,0,0,0,0,0,0,0,0,0,0,0,0
0,0,0,0,0,0,0,0,0,0,0,0,0,0,0,0,0,0,0,0,0,0,0,0,0
0,0,0,0,0,0,0,0,0,0,0,0,0,0,0,0,0,0,0,0,0,0,0,0,0
0,0,0,0,0,0,0,0,0,0,0,0,0,0,0,0,0,0,0,0,0,0,0,0,0
0,0,0,0,0,0,0,0,0,0,0,0,0,0,0,0,0,0,0,0,0,0,0,0,0
0,0,0,0,0,0,0,0,0,0,0,0,0,0,0,0,0,0,0,0,0,0,0,0,0
0,0,0,0,0,0,0,0,0,0,0,0,0,0,0,0,0,0,0,0,0,0,0,0,0
0,0,0,0,0,0,0,0,0,0,0,0,0,0,0,0,0,0,0,0,0,0,0,0,0
0,0,0,0,0,0,0,0,0,0,0,0,0,0,0,0,0,0,0,0,0,0,0,0,0
endlayer

layer
0,0,0,0,0,0,0,0,0,0,0,0,0,0,0,0,0,0,0,0,0,0,0,0,0
0,0,0,0,0,0,0,0,0,0,0,0,0,0,0,0,0,0,0,0,0,0,0,0,0
0,0,0,0,0,0,0,0,0,0,0,0,0,0,0,0,0,0,0,0,0,0,0,0,0
0,0,0,0,0,0,0,0,0,0,0,0,0,0,0,0,0,0,0,0,0,0,0,0,0
0,0,0,0,0,0,0,0,0,0,0,0,0,0,0,0,0,0,0,0,0,0,0,0,0
0,0,0,0,0,0,0,0,0,0,0,0,0,0,0,0,0,0,0,0,0,0,0,0,0
0,0,0,0,0,0,0,0,0,0,0,0,0,0,0,0,0,0,0,0,0,0,0,0,0
0,0,0,0,0,0,0,0,0,0,0,0,0,0,0,0,0,0,0,0,0,0,0,0,0
0,0,0,0,0,0,0,0,0,0,0,0,0,0,0,0,0,0,0,0,0,0,0,0,0
0,0,0,0,0,0,0,0,0,0,0,0,0,0,0,0,0,0,0,0,0,0,0,0,0
0,0,0,0,0,0,0,0,0,0,0,0,0,0,0,0,0,0,0,0,0,0,0,0,0
0,0,0,0,0,0,0,0,0,0,0,0,0,0,0,0,0,0,0,0,0,0,0,0,0
0,0,0,0,0,0,0,0,0,0,0,0,0,0,0,0,0,0,0,0,0,0,0,0,0
0,0,0,0,0,0,0,0,0,0,0,0,0,0,0,0,0,0,0,0,0,0,0,0,0
0,0,0,0,0,0,0,0,0,0,0,0,0,0,0,0,0,0,0,0,0,0,0,0,0
0,0,0,0,0,0,0,0,0,0,0,0,0,0,0,0,0,0,0,0,0,0,0,0,0
0,0,0,0,0,0,0,0,0,0,0,0,0,0,0,0,0,0,0,0,0,0,0,0,0
0,0,0,0,0,0,0,0,0,10,10,10,10,10,10,10,0,0,0,0,0,0,0,0,0
0,0,0,0,0,0,0,0,10,0,0,0,0,0,0,0,10,0,0,0,0,0,0,0,0
0,0,0,0,0,0,0,0,10,0,0,0,0,0,0,0,10,0,0,0,0,0,0,0,0
0,0,0,0,0,0,0,0,10,0,0,0,0,0,0,0,10,0,0,0,0,0,0,0,0
0,0,0,0,0,0,0,0,10,0,0,0,0,0,0,0,10,0,0,0,0,0,0,0,0
0,0,0,0,0,0,0,0,10,0,0,0,0,0,0,0,10,0,0,0,0,0,0,0,0
0,0,0,0,0,0,0,0,10,0,0,0,0,0,0,0,10,0,0,0,0,0,0,0,0
0,0,0,0,0,0,0,0,10,0,0,0,0,0,0,0,10,0,0,0,0,0,0,0,0
0,0,0,0,0,0,0,0,0,10,10,10,10,10,10,10,0,0,0,0,0,0,0,0,0
0,0,0,0,0,0,0,0,0,0,0,0,0,0,0,0,0,0,0,0,0,0,0,0,0
0,0,0,0,0,0,0,0,0,0,0,0,0,0,0,0,0,0,0,0,0,0,0,0,0
0,0,0,0,0,0,0,0,0,0,0,0,0,0,0,0,0,0,0,0,0,0,0,0,0
0,0,0,0,0,0,0,0,0,0,0,0,0,0,0,0,0,0,0,0,0,0,0,0,0
0,0,0,0,0,0,0,0,0,0,0,0,0,0,0,0,0,0,0,0,0,0,0,0,0
0,0,0,0,0,0,0,0,0,0,0,0,0,0,0,0,0,0,0,0,0,0,0,0,0
0,0,0,0,0,0,0,0,0,0,0,0,0,0,0,0,0,0,0,0,0,0,0,0,0
0,0,0,0,0,0,0,0,0,0,0,0,0,0,0,0,0,0,0,0,0,0,0,0,0
0,0,0,0,0,0,0,0,0,0,0,0,0,0,0,0,0,0,0,0,0,0,0,0,0
0,0,0,0,0,0,0,0,0,0,0,0,0,0,0,0,0,0,0,0,0,0,0,0,0
0,0,0,0,0,0,0,0,0,0,0,0,0,0,0,0,0,0,0,0,0,0,0,0,0
0,0,0,0,0,0,0,0,0,0,0,0,0,0,0,0,0,0,0,0,0,0,0,0,0
0,0,0,0,0,0,0,0,0,0,0,0,0,0,0,0,0,0,0,0,0,0,0,0,0
0,0,0,0,0,0,0,0,0,0,0,0,0,0,0,0,0,0,0,0,0,0,0,0,0
0,0,0,0,0,0,0,0,0,0,0,0,0,0,0,0,0,0,0,0,0,0,0,0,0
0,0,0,0,0,0,0,0,0,0,0,0,0,0,0,0,0,0,0,0,0,0,0,0,0
0,0,0,0,0,0,0,0,0,0,0,0,0,0,0,0,0,0,0,0,0,0,0,0,0
0,0,0,0,0,0,0,0,0,0,0,0,0,0,0,0,0,0,0,0,0,0,0,0,0
0,0,0,0,0,0,0,0,0,0,0,0,0,0,0,0,0,0,0,0,0,0,0,0,0
endlayer

layer
0,0,0,0,0,0,0,0,0,0,0,0,0,0,0,0,0,0,0,0,0,0,0,0,0
0,0,0,0,0,0,0,0,0,0,0,0,0,0,0,0,0,0,0,0,0,0,0,0,0
0,0,0,0,0,0,0,0,0,0,0,0,0,0,0,0,0,0,0,0,0,0,0,0,0
0,0,0,0,0,0,0,0,0,0,0,0,0,0,0,0,0,0,0,0,0,0,0,0,0
0,0,0,0,0,0,0,0,0,0,0,0,0,0,0,0,0,0,0,0,0,0,0,0,0
0,0,0,0,0,0,0,0,0,0,0,0,0,0,0,0,0,0,0,0,0,0,0,0,0
0,0,0,0,0,0,0,0,0,0,0,0,0,0,0,0,0,0,0,0,0,0,0,0,0
0,0,0,0,0,0,0,0,0,0,0,0,0,0,0,0,0,0,0,0,0,0,0,0,0
0,0,0,0,0,0,0,0,0,0,0,0,0,0,0,0,0,0,0,0,0,0,0,0,0
0,0,0,0,0,0,0,0,0,0,0,0,0,0,0,0,0,0,0,0,0,0,0,0,0
0,0,0,0,0,0,0,0,0,0,0,0,0,0,0,0,0,0,0,0,0,0,0,0,0
0,0,0,0,0,0,0,0,0,0,0,0,0,0,0,0,0,0,0,0,0,0,0,0,0
0,0,0,0,0,0,0,0,0,0,0,0,0,0,0,0,0,0,0,0,0,0,0,0,0
0,0,0,0,0,0,0,0,0,0,0,0,0,0,0,0,0,0,0,0,0,0,0,0,0
0,0,0,0,0,0,0,0,0,0,0,0,0,0,0,0,0,0,0,0,0,0,0,0,0
0,0,0,0,0,0,0,0,0,0,0,0,0,0,0,0,0,0,0,0,0,0,0,0,0
0,0,0,0,0,0,0,0,0,0,0,0,0,0,0,0,0,0,0,0,0,0,0,0,0
0,0,0,0,0,0,0,0,0,0,0,0,0,0,0,0,0,0,0,0,0,0,0,0,0
0,0,0,0,0,0,0,0,0,11,11,11,11,11,11,11,0,0,0,0,0,0,0,0,0
0,0,0,0,0,0,0,0,0,11,42,42,42,42,42,11,0,0,0,0,0,0,0,0,0
0,0,0,0,0,0,0,0,0,11,42,42,42,42,42,11,0,0,0,0,0,0,0,0,0
0,0,0,0,0,0,0,0,0,11,42,42,42,42,42,11,0,0,0,0,0,0,0,0,0
0,0,0,0,0,0,0,0,0,11,42,42,42,42,42,11,0,0,0,0,0,0,0,0,0
0,0,0,0,0,0,0,0,0,11,42,42,42,42,42,11,0,0,0,0,0,0,0,0,0
0,0,0,0,0,0,0,0,0,11,11,11,11,11,11,11,0,0,0,0,0,0,0,0,0
0,0,0,0,0,0,0,0,0,0,0,0,0,0,0,0,0,0,0,0,0,0,0,0,0
0,0,0,0,0,0,0,0,0,0,0,0,0,0,0,0,0,0,0,0,0,0,0,0,0
0,0,0,0,0,0,0,0,0,0,0,0,0,0,0,0,0,0,0,0,0,0,0,0,0
0,0,0,0,0,0,0,0,0,0,0,0,0,0,0,0,0,0,0,0,0,0,0,0,0
0,0,0,0,0,0,0,0,0,0,0,0,0,0,0,0,0,0,0,0,0,0,0,0,0
0,0,0,0,0,0,0,0,0,0,0,0,0,0,0,0,0,0,0,0,0,0,0,0,0
0,0,0,0,0,0,0,0,0,0,0,0,0,0,0,0,0,0,0,0,0,0,0,0,0
0,0,0,0,0,0,0,0,0,0,0,0,0,0,0,0,0,0,0,0,0,0,0,0,0
0,0,0,0,0,0,0,0,0,0,0,0,0,0,0,0,0,0,0,0,0,0,0,0,0
0,0,0,0,0,0,0,0,0,0,0,0,0,0,0,0,0,0,0,0,0,0,0,0,0
0,0,0,0,0,0,0,0,0,0,0,0,0,0,0,0,0,0,0,0,0,0,0,0,0
0,0,0,0,0,0,0,0,0,0,0,0,0,0,0,0,0,0,0,0,0,0,0,0,0
0,0,0,0,0,0,0,0,0,0,0,0,0,0,0,0,0,0,0,0,0,0,0,0,0
0,0,0,0,0,0,0,0,0,0,0,0,0,0,0,0,0,0,0,0,0,0,0,0,0
0,0,0,0,0,0,0,0,0,0,0,0,0,0,0,0,0,0,0,0,0,0,0,0,0
0,0,0,0,0,0,0,0,0,0,0,0,0,0,0,0,0,0,0,0,0,0,0,0,0
0,0,0,0,0,0,0,0,0,0,0,0,0,0,0,0,0,0,0,0,0,0,0,0,0
0,0,0,0,0,0,0,0,0,0,0,0,0,0,0,0,0,0,0,0,0,0,0,0,0
0,0,0,0,0,0,0,0,0,0,0,0,0,0,0,0,0,0,0,0,0,0,0,0,0
0,0,0,0,0,0,0,0,0,0,0,0,0,0,0,0,0,0,0,0,0,0,0,0,0
endlayer

