# Converted from schematic
# THIS TEMPLATE USES DEFAULTS!  Please edit for corrections.
# If you need help, consult template_rules.txt

weight=2
embed_into_distance=17
acceptable_target_blocks=1,2,3,12,13,250
dimensions=26,45,25
allowable_overhang=0
max_cut_in=2
cut_in_buffer=1
max_leveling=2
leveling_buffer=1
preserve_water=0
preserve_lava=0
preserve_plants=0


rule1=0,100,300
rule2=0,50,308,308,308,308,308,308,313,313,314,327
rule3=0,100,2799-4
rule4=0,50,311,311,311
rule5=0,100,2799-7,2798-4,2799-8
rule6=0,100,2787-1
rule7=0,100,2799-6
rule8=0,100,2843-14,2843-14,2843-14,2843-14,2843
rule9=0,95,2835-2,2835-2,2835-2,2835-2,2835-2,2835-2,2835-2,2835-1,2835-1,2835-0
rule10=0,100,4
rule11=0,100,66-1
rule12=0,100,2843-4
rule13=0,100,3134-10
rule14=0,100,2835-12
rule15=0,100,44
rule16=0,100,113
rule17=0,100,2761-15,2761-15,2761-15,2762-13,2762-13,2762-13,2762-13,2762-13,2762-13,2762-13
rule18=0,100,2010-0
rule19=0,100,250,250,250,250,1476-3
rule20=0,100,2542-0
rule21=0,100,2835-6
rule22=0,100,2788-9
rule23=0,100,2835-4
rule24=0,100,2835-5
rule25=0,100,2516
rule26=0,100,47,2837-7,2837-5,2837-8,250,250
rule27=0,100,2245-2
rule28=0,100,2291-2
rule29=0,100,2777-10
rule30=0,100,2248
rule31=0,100,2844-3
rule32=0,100,2763-15,2763-15,2764-13,2764-13,2764-13,2764-13,2764-13,2764-13,2764-13
rule33=0,100,2835-7
rule34=0,66,3225-3
rule35=0,100,140-10
rule36=0,100,2245-1
rule37=0,100,2291-1
rule38=0,100,2802-7
rule39=0,100,4094-10


layer
1,1,1,1,1,1,1,1,1,1,1,1,1,1,1,1,1,1,1,1,1,1,1,1,1
1,1,1,1,1,1,1,1,1,1,1,1,1,1,1,1,1,1,1,1,1,1,1,1,1
1,1,1,1,1,1,1,1,1,1,1,1,1,1,1,1,1,3,3,2,1,1,1,1,1
1,1,1,1,1,1,1,1,1,1,1,1,1,1,1,1,1,3,1,1,1,1,1,1,1
1,1,1,1,1,1,1,1,1,1,1,1,1,3,1,1,1,3,1,1,1,1,1,1,1
1,1,1,1,1,1,1,1,1,1,1,1,1,3,1,1,1,3,1,1,1,1,1,1,1
1,1,1,1,1,1,1,1,1,1,1,1,1,3,1,1,1,3,3,3,3,3,3,1,1
1,1,1,1,1,1,1,1,1,1,1,1,1,3,1,1,1,3,1,1,3,1,3,1,1
1,1,1,1,1,1,1,1,1,1,1,1,1,3,1,1,1,3,1,1,3,1,4,1,1
1,1,1,1,1,1,1,1,1,1,1,1,1,3,1,1,1,1,1,1,3,1,1,1,1
1,1,1,1,1,1,1,1,1,1,1,1,1,3,1,1,1,1,1,1,3,1,1,1,1
1,1,1,1,1,1,1,1,1,3,3,3,3,3,1,1,1,1,1,1,3,1,1,1,1
1,1,1,1,1,1,1,1,1,3,3,1,1,3,1,1,3,3,3,3,3,3,3,1,1
1,1,1,1,1,1,1,1,1,3,2,1,1,3,1,1,3,1,3,3,3,3,3,1,1
1,1,1,1,1,1,1,1,1,3,3,1,1,3,1,1,3,1,3,3,3,3,3,2,1
1,1,1,1,1,1,1,1,1,4,1,1,1,3,1,1,3,2,3,3,3,3,3,1,1
1,1,1,1,1,1,1,1,1,1,1,3,3,3,3,3,3,1,3,3,3,3,3,1,1
1,1,1,1,1,1,1,1,1,1,1,1,1,1,1,1,1,1,1,1,3,1,1,1,1
1,1,1,1,1,1,1,1,1,4,1,1,1,1,1,1,1,1,1,1,3,1,1,3,1
1,1,1,1,1,1,1,1,1,1,1,1,1,1,1,1,1,1,1,1,3,1,1,3,1
1,1,1,1,1,1,1,1,1,1,1,4,1,1,1,1,1,1,1,3,3,1,1,3,1
1,1,1,1,1,1,1,1,1,1,1,1,1,1,1,1,1,1,1,1,3,3,3,3,1
1,1,1,1,1,1,1,1,1,1,4,1,1,1,1,1,1,1,1,1,3,1,1,1,1
1,1,1,1,1,1,1,1,1,1,1,1,1,1,1,1,1,1,1,1,3,4,1,1,1
1,1,1,1,1,1,1,1,1,1,1,1,1,1,1,1,1,1,1,1,3,3,3,3,1
1,1,1,1,1,1,1,1,1,1,1,1,1,1,1,1,1,1,1,1,3,1,1,3,1
1,1,1,1,1,1,1,1,1,1,1,1,1,1,1,1,1,3,3,3,3,1,1,3,1
1,1,1,1,1,1,1,1,1,1,3,1,1,1,1,1,1,3,1,1,3,3,3,3,1
1,1,1,1,1,1,1,1,1,1,3,1,1,3,3,3,3,3,1,1,3,1,1,3,1
1,1,1,1,1,1,1,1,3,3,3,2,1,3,1,1,1,3,3,3,3,1,1,3,1
1,1,1,1,1,1,1,1,1,1,3,2,1,3,1,1,1,1,1,1,3,1,1,3,1
1,1,1,1,1,1,1,1,1,1,3,1,1,3,1,1,1,3,3,3,3,3,3,3,1
1,1,1,1,1,1,1,1,1,1,3,1,1,3,1,1,1,1,3,1,3,1,1,1,1
1,1,1,1,1,1,1,1,1,1,3,1,1,3,1,1,1,2,3,3,3,1,1,1,1
1,1,1,1,1,1,1,1,1,1,3,1,1,3,1,1,1,1,1,1,3,1,1,1,1
1,1,1,1,1,1,1,1,1,1,3,1,1,3,1,1,1,3,3,1,3,1,1,1,1
1,1,1,1,1,1,1,1,1,1,3,1,1,3,3,3,3,3,3,1,3,3,3,3,1
1,1,1,1,1,1,1,1,1,1,3,1,1,3,1,1,1,3,3,1,3,1,1,3,1
1,1,1,1,1,1,1,1,1,1,3,1,1,3,1,1,1,1,2,1,3,1,1,3,1
1,1,1,1,1,1,1,1,1,1,3,3,3,3,1,1,4,1,1,1,3,1,1,3,1
1,1,1,1,1,1,1,1,1,1,1,1,1,1,1,3,3,3,3,3,3,1,1,3,1
1,1,1,1,1,1,1,1,1,1,1,1,1,3,3,3,3,1,1,3,1,1,1,3,1
1,1,1,1,1,1,1,1,1,3,3,3,3,3,1,1,2,1,1,3,1,2,3,3,1
1,1,1,1,1,1,1,1,1,1,1,1,1,1,1,3,3,3,3,3,1,1,1,2,1
1,1,1,1,1,1,1,1,1,1,1,1,1,1,1,1,1,1,1,1,1,1,1,1,1
endlayer

layer
1,1,1,1,1,1,1,1,1,1,1,1,1,1,1,1,1,5,5,1,1,1,1,1,1
1,1,1,1,7,7,7,1,1,3,3,3,3,3,4,1,1,5,5,1,1,1,1,1,1
1,1,1,1,7,7,7,3,3,3,3,3,3,3,1,1,5,0,0,5,1,1,1,1,1
1,1,1,1,7,7,7,1,1,3,3,3,3,3,1,1,5,0,5,1,1,1,1,1,1
1,1,1,1,7,7,7,1,1,1,1,1,5,0,5,1,5,0,5,1,1,1,1,1,1
1,1,1,1,7,7,7,1,1,1,1,1,5,0,5,1,5,0,5,5,5,5,5,1,1
1,1,1,1,7,7,7,1,1,1,1,1,5,0,5,1,5,0,0,0,0,0,0,5,1
1,1,1,1,7,7,7,1,1,1,1,1,5,0,5,1,5,0,5,5,0,5,0,5,1
1,1,1,1,7,7,7,1,1,1,1,1,5,0,5,1,5,0,5,5,0,5,5,1,1
1,1,1,1,7,7,7,1,1,1,1,1,5,0,5,1,1,5,1,5,0,5,1,1,1
1,1,1,1,7,7,7,1,1,5,5,5,5,0,5,1,1,1,1,5,0,5,1,1,1
1,1,1,1,7,7,7,1,5,0,0,0,0,0,5,1,5,5,5,5,0,5,5,1,1
1,1,1,1,7,7,7,1,5,0,0,5,5,0,5,5,0,0,0,0,0,0,4,5,1
1,1,1,1,7,7,7,1,1,5,5,5,5,0,5,5,0,5,0,0,0,0,0,5,1
1,1,1,1,7,7,7,1,5,1,4,5,5,0,5,5,0,5,0,0,0,0,0,5,1
1,1,1,1,7,7,7,1,1,5,5,5,5,0,5,5,0,5,0,0,0,0,0,5,1
1,1,1,1,7,7,7,1,5,1,5,0,0,0,0,0,0,5,0,0,0,0,0,5,1
1,1,1,1,7,7,7,1,5,1,5,5,5,5,5,5,5,1,5,5,0,5,5,5,1
1,1,1,1,7,7,7,1,1,5,5,0,0,0,5,1,1,1,1,5,0,5,5,0,5
1,1,1,1,7,7,7,1,1,1,5,4,5,0,5,5,5,5,5,5,0,5,5,0,5
1,1,1,1,7,7,7,1,1,1,1,5,5,0,0,0,1,1,5,0,0,5,5,0,5
1,1,1,1,7,7,7,2,1,1,1,1,5,0,5,5,5,5,5,5,0,0,0,0,5
1,1,1,1,7,7,7,1,1,1,5,5,5,0,5,1,1,1,1,5,0,5,5,5,1
1,1,1,1,7,7,7,1,1,5,0,4,5,0,5,1,1,1,1,5,0,5,5,5,1
1,1,1,1,7,7,7,1,1,5,0,0,5,0,5,1,1,1,1,5,0,0,0,0,5
1,1,1,1,7,7,7,1,1,5,0,0,0,0,5,1,1,5,5,5,5,5,5,0,5
1,1,1,1,7,7,7,1,1,1,5,5,5,5,1,1,5,0,0,0,0,5,5,0,5
1,1,1,1,7,7,7,1,1,5,0,5,1,5,5,5,5,0,5,5,0,0,0,0,5
1,1,1,1,7,7,7,1,5,5,0,5,5,0,0,0,0,0,5,5,5,5,5,0,5
1,1,1,1,7,7,7,5,0,0,0,5,5,0,5,5,5,0,0,0,0,5,5,0,5
1,1,1,1,7,7,7,1,5,5,0,4,5,0,5,1,1,5,5,5,0,5,5,0,5
1,1,1,1,7,7,7,1,1,5,0,5,5,0,5,1,5,0,0,0,0,0,0,0,5
1,1,1,1,7,7,7,1,1,5,0,5,5,0,5,1,1,5,1,5,5,5,5,5,1
1,1,1,1,7,7,7,1,1,5,0,5,5,0,5,1,1,5,0,0,0,5,1,1,1
1,1,1,1,7,7,7,1,1,5,0,5,5,0,5,1,1,5,5,5,0,5,1,1,1
1,1,1,1,7,7,7,1,1,5,0,5,5,0,5,5,5,0,0,5,0,5,5,5,1
1,1,1,1,7,7,7,1,1,5,0,5,5,0,0,0,0,0,0,5,0,0,0,0,5
1,1,1,1,7,7,7,1,1,5,0,5,5,0,5,5,5,0,0,5,0,5,5,0,5
1,1,1,1,7,7,7,1,1,5,0,5,5,0,5,1,1,5,5,5,0,5,5,0,5
1,1,1,1,7,7,7,1,1,5,0,0,0,0,5,5,5,5,5,5,0,5,5,0,5
1,1,1,1,7,7,7,1,1,1,5,5,5,5,5,0,0,0,0,0,0,5,5,0,5
1,1,1,1,7,7,7,1,1,5,5,5,5,0,0,0,0,5,5,6,5,1,5,0,5
1,1,1,1,7,7,7,3,3,0,0,0,0,0,5,5,5,5,5,0,5,5,4,0,5
1,1,1,1,7,7,7,1,1,5,5,5,5,5,2,4,0,0,0,0,5,1,5,5,1
1,1,1,1,1,1,1,1,1,1,1,1,1,1,1,5,5,5,5,5,1,1,1,1,1
endlayer

layer
1,1,1,1,10,10,10,1,5,5,5,5,5,5,5,1,1,5,5,1,1,1,1,1,1
1,1,1,8,0,11,0,8,5,0,0,0,0,0,5,1,1,5,5,1,1,1,1,1,1
1,1,1,5,0,11,0,0,0,0,0,0,0,0,5,1,5,0,0,5,1,1,1,1,1
1,1,1,5,0,11,0,5,5,0,0,0,0,0,5,1,5,0,5,1,1,1,1,1,1
1,1,1,5,0,11,0,5,1,5,5,5,5,0,5,1,5,0,5,1,1,1,1,1,1
1,1,1,5,0,11,0,5,1,1,1,1,5,0,5,1,5,0,5,5,5,5,5,1,1
1,1,1,5,0,11,0,5,1,1,1,1,5,0,5,1,5,0,0,0,0,0,0,5,1
1,1,1,8,0,11,0,8,1,1,1,1,5,0,5,1,5,0,5,5,0,5,0,5,1
1,1,1,5,0,11,0,5,1,1,1,1,5,0,5,1,5,0,5,5,0,5,5,1,1
1,1,1,5,0,11,0,5,1,1,1,1,5,0,5,1,1,5,1,5,0,5,1,1,1
1,1,1,5,0,11,0,5,1,5,5,5,5,0,5,1,1,1,1,5,0,5,1,1,1
1,1,1,5,0,11,0,5,5,0,0,0,0,0,5,1,5,5,5,5,0,5,5,1,1
1,1,1,5,0,11,0,5,5,0,0,5,5,0,5,5,0,0,0,0,0,0,0,5,1
1,1,1,8,0,11,0,8,1,5,5,5,5,0,5,5,0,5,0,0,0,0,0,5,1
1,1,1,5,0,11,0,5,5,1,1,5,5,0,5,5,0,5,0,0,0,0,0,5,1
1,1,1,5,0,11,0,5,1,5,5,5,5,0,5,5,0,5,0,0,0,0,0,5,1
1,1,1,5,0,11,0,5,5,1,5,0,0,0,0,0,0,5,0,0,0,0,0,5,1
1,1,1,5,0,11,0,5,5,1,5,5,5,5,5,5,5,1,5,5,0,5,5,5,1
1,1,1,9,0,11,0,9,1,5,5,0,0,0,5,1,1,1,1,5,0,5,5,0,5
1,1,1,8,0,11,0,8,1,1,5,0,5,0,5,5,5,5,5,5,0,5,5,0,5
1,1,1,9,0,11,0,5,1,1,1,1,5,0,0,0,0,1,5,0,0,5,5,0,5
1,1,1,9,0,11,0,5,1,1,1,1,5,0,5,5,5,5,5,5,0,0,0,0,5
1,1,1,9,0,11,0,5,1,1,5,5,5,0,5,1,1,1,1,5,0,5,5,5,1
1,1,1,9,0,11,0,5,1,5,0,0,5,0,5,1,1,1,1,5,0,5,5,5,1
1,1,1,9,0,11,0,5,1,5,0,0,5,0,5,1,1,1,1,5,0,0,0,0,5
1,1,1,8,0,11,0,8,1,5,0,0,0,0,5,1,5,5,5,5,5,5,5,0,5
1,1,1,9,0,11,0,5,1,1,5,5,5,5,1,1,5,0,0,0,0,5,5,0,5
1,1,1,9,0,11,0,5,1,5,0,5,1,5,5,5,5,0,5,5,0,0,0,0,5
1,1,1,9,0,11,0,5,5,5,0,5,5,0,0,0,0,0,5,5,5,5,5,0,5
1,1,1,9,0,11,0,5,0,0,0,5,5,0,5,5,5,0,0,0,0,5,5,0,5
1,1,1,9,0,11,0,5,5,5,0,5,5,0,5,1,1,5,5,5,0,5,5,0,5
1,1,1,8,0,11,0,8,1,5,0,5,5,0,5,1,5,0,0,0,0,0,0,0,5
1,1,1,9,0,11,0,9,1,5,0,5,5,0,5,1,1,5,1,5,5,5,5,5,1
1,1,1,5,0,11,0,5,1,5,0,5,5,0,5,1,1,5,0,0,0,5,1,1,1
1,1,1,5,0,11,0,5,1,5,0,5,5,0,5,1,1,5,5,5,0,5,1,1,1
1,1,1,5,0,11,0,5,1,5,0,5,5,0,5,5,5,0,0,5,0,5,5,5,1
1,1,1,5,0,11,0,5,1,5,0,5,5,0,0,0,0,0,0,5,0,0,0,0,5
1,1,1,8,0,11,0,8,1,5,0,5,5,0,5,5,5,0,0,5,0,5,5,0,5
1,1,1,5,0,11,0,5,1,5,0,5,5,0,5,1,1,5,5,5,0,5,5,0,5
1,1,1,5,0,11,0,5,1,5,0,0,0,0,5,5,5,5,5,5,0,5,5,0,5
1,1,1,5,0,11,0,5,1,1,5,5,5,5,5,0,0,0,0,0,0,5,5,0,5
1,1,1,5,0,11,0,5,5,5,5,5,5,0,0,0,0,5,5,5,5,1,5,0,5
1,1,1,5,0,11,0,0,0,0,0,0,0,0,5,5,5,5,5,0,5,5,0,0,5
1,1,1,8,0,11,0,8,5,5,5,5,5,5,5,0,0,0,0,0,5,1,5,5,1
1,1,1,10,10,10,10,1,1,1,1,1,1,1,1,5,5,5,5,5,1,1,1,1,1
endlayer

layer
1,1,1,1,10,10,10,1,5,5,5,5,5,5,5,1,1,1,1,1,1,1,1,1,1
1,1,1,8,0,0,0,8,5,0,0,0,0,0,5,1,1,1,1,1,1,1,1,1,1
1,1,1,5,0,0,0,0,0,0,0,0,0,0,5,1,1,5,5,1,1,1,1,1,1
1,1,1,5,0,0,0,5,5,0,0,0,0,0,5,1,1,5,1,1,1,1,1,1,1
1,1,1,5,0,0,0,5,1,5,5,5,5,0,5,1,1,5,1,1,1,1,1,1,1
1,1,1,5,0,0,0,5,1,1,1,1,1,5,1,1,1,5,1,1,1,1,1,1,1
1,1,1,5,0,0,0,5,1,1,1,1,1,5,1,1,1,5,5,5,5,5,5,1,1
1,1,1,8,0,0,0,8,1,1,1,1,1,5,1,1,1,5,1,1,5,1,5,1,1
1,1,1,5,0,0,0,5,1,1,1,1,1,5,1,1,1,5,1,1,5,1,1,1,1
1,1,1,5,0,0,0,5,1,1,1,1,1,5,1,1,1,1,1,1,5,1,1,1,1
1,1,1,5,0,0,0,5,1,1,1,1,1,5,1,1,1,1,1,1,5,1,1,1,1
1,1,1,5,0,0,0,5,1,5,5,5,5,5,1,1,1,1,5,5,5,5,5,1,1
1,1,1,5,0,0,0,5,5,5,5,1,1,5,1,1,5,5,0,0,0,0,0,5,1
1,1,1,8,0,0,0,8,5,5,5,1,1,5,1,1,5,5,0,0,0,0,0,5,1
1,1,1,5,0,0,0,5,1,1,1,1,1,12,12,12,5,5,0,0,0,0,0,5,1
1,1,1,5,0,0,0,5,1,1,1,1,1,12,12,12,5,5,0,0,0,0,0,5,1
1,1,1,5,0,0,0,5,1,1,1,12,5,12,12,12,5,5,0,0,0,0,0,5,1
1,1,1,5,0,0,0,5,1,1,1,12,1,12,12,12,1,1,5,5,5,5,5,1,1
1,1,1,9,0,0,0,9,1,1,1,12,5,12,12,12,1,1,1,1,5,1,1,5,1
1,1,1,8,0,0,0,8,12,12,12,12,12,12,12,12,1,1,1,1,5,1,1,5,1
1,1,1,9,0,0,0,12,12,12,12,12,12,12,12,12,5,1,1,5,5,1,1,5,1
1,1,1,9,0,0,0,12,12,12,12,12,12,12,12,12,1,1,1,1,5,5,5,5,1
1,1,1,9,0,0,0,12,12,12,12,12,12,12,12,12,1,1,1,1,5,1,1,1,1
1,1,1,9,0,0,0,12,12,12,12,12,12,12,12,12,4,1,1,1,5,1,1,1,1
1,1,1,9,0,0,0,12,12,12,12,12,12,12,12,12,1,1,1,1,5,5,5,5,1
1,1,1,8,0,0,0,8,12,12,12,12,12,12,12,12,1,1,1,1,5,1,1,5,1
1,1,1,9,0,0,0,12,12,12,12,12,12,12,12,12,1,5,5,5,5,1,1,5,1
1,1,1,9,0,0,0,12,12,12,12,12,12,12,12,12,1,5,1,1,5,5,5,5,1
1,1,1,9,0,0,0,12,12,12,12,12,12,12,12,5,5,5,1,1,5,1,1,5,1
1,1,1,9,0,0,0,12,12,12,12,12,12,12,12,12,1,5,5,5,5,1,1,5,1
1,1,1,9,0,0,0,12,12,12,12,12,12,12,12,12,1,1,1,1,5,1,1,5,1
1,1,1,8,0,0,0,8,12,12,12,12,12,12,12,12,1,5,5,5,5,5,5,5,1
1,1,1,9,0,0,0,9,1,1,5,1,1,5,1,1,1,1,1,5,5,1,1,1,1
1,1,1,5,0,0,0,5,1,1,5,1,1,5,1,1,1,1,5,5,5,1,1,1,1
1,1,1,5,0,0,0,5,1,1,5,1,1,5,1,1,1,5,5,5,5,1,1,1,1
1,1,1,5,0,0,0,5,1,1,5,1,1,5,1,1,5,0,0,5,5,1,1,1,1
1,1,1,5,0,0,0,5,1,1,5,1,1,5,5,5,5,0,0,5,5,5,5,5,1
1,1,1,8,0,0,0,8,1,1,5,1,1,5,1,1,5,0,0,5,5,1,1,5,1
1,1,1,5,0,0,0,5,1,1,5,1,1,5,1,1,1,5,5,5,5,1,1,5,1
1,1,1,5,0,0,0,5,1,1,5,5,5,5,1,1,1,1,1,5,5,1,1,5,1
1,1,1,5,0,0,0,5,1,1,1,1,1,1,1,5,5,5,5,5,5,1,1,5,1
1,1,1,5,0,0,0,5,5,5,5,1,1,5,5,5,5,1,1,5,1,1,1,5,1
1,1,1,5,0,0,0,0,0,0,0,5,5,5,1,1,1,1,1,5,1,1,5,5,1
1,1,1,8,0,0,0,8,5,5,5,1,1,1,1,5,5,5,5,5,1,1,1,1,1
1,1,1,10,10,10,10,1,1,1,1,1,1,1,1,1,1,1,1,1,1,1,1,1,1
endlayer

layer
1,1,1,1,10,10,10,1,5,5,5,5,5,5,5,1,1,1,1,1,1,1,1,1,1
1,1,1,8,0,0,0,8,5,0,0,0,0,0,5,1,1,1,1,1,1,1,1,1,1
1,1,1,5,0,0,0,5,5,0,0,0,0,0,5,1,1,1,1,1,1,1,1,1,1
1,1,1,5,0,0,0,5,5,0,0,0,0,0,5,1,1,1,1,1,1,1,1,1,1
1,1,1,5,0,0,0,5,1,5,5,5,5,5,1,1,1,1,1,1,1,1,1,1,1
1,1,1,5,0,0,0,5,1,1,1,1,1,1,1,1,1,1,1,1,1,1,1,1,1
1,1,1,5,0,0,0,5,1,1,1,1,1,1,1,1,1,1,1,1,1,1,1,1,1
1,1,1,8,0,0,0,8,1,1,1,1,1,1,1,1,1,1,1,1,1,1,1,1,1
1,1,1,5,0,0,0,5,1,1,1,1,1,1,1,1,1,1,1,1,1,1,1,1,1
1,1,1,5,0,0,0,5,1,1,1,1,1,1,1,1,1,1,1,1,1,1,1,1,1
1,1,1,5,0,0,0,5,1,1,1,1,1,1,1,1,1,1,1,1,1,1,1,1,1
1,1,1,5,0,0,0,5,1,1,1,1,1,1,1,1,1,1,1,1,1,1,1,1,1
1,1,1,5,0,0,0,5,1,1,1,1,1,1,1,1,1,1,5,5,5,5,5,1,1
1,1,1,8,0,0,0,8,1,1,1,1,1,13,13,13,1,1,5,5,5,5,5,1,1
1,1,1,5,0,0,0,5,1,1,1,1,9,1,1,1,9,1,5,5,5,5,5,1,1
1,1,1,5,0,0,0,5,1,1,1,9,9,1,1,1,9,1,5,5,5,5,5,1,1
1,1,1,5,0,0,0,5,1,1,9,0,9,0,0,0,9,1,5,5,5,5,5,1,1
1,1,1,5,0,0,0,5,1,1,9,0,9,0,0,0,9,1,1,1,1,1,1,1,1
1,1,1,9,0,0,0,9,9,9,9,0,9,0,16,0,9,1,1,1,1,1,1,1,1
1,1,1,8,0,0,0,8,0,0,0,0,0,0,0,0,8,1,1,1,1,1,1,1,1
1,1,1,9,0,0,0,0,0,0,0,0,0,0,0,14,9,1,1,1,1,1,1,1,1
1,1,1,9,0,0,0,0,0,0,0,0,0,0,0,15,9,1,1,1,1,1,1,1,1
1,1,1,9,0,0,0,0,0,0,0,0,0,0,0,15,9,1,1,1,1,1,1,1,1
1,1,1,9,0,0,0,0,0,0,0,0,0,0,0,15,9,1,1,1,1,1,1,1,1
1,1,1,9,0,0,0,0,0,0,0,0,0,0,0,14,9,1,1,1,1,1,1,1,1
1,1,1,8,0,0,0,8,0,0,0,0,0,0,0,0,8,1,1,1,1,1,1,1,1
1,1,1,9,0,0,0,0,0,0,0,0,0,0,0,14,9,1,1,1,1,1,1,1,1
1,1,1,9,0,0,0,0,0,0,0,0,0,0,0,15,9,1,1,1,1,1,1,1,1
1,1,1,9,0,0,0,0,0,0,0,0,0,0,0,15,9,1,1,1,1,1,1,1,1
1,1,1,9,0,0,0,0,0,0,0,0,0,0,0,15,9,1,1,1,1,1,1,1,1
1,1,1,9,0,0,0,0,0,0,0,0,0,0,0,14,9,1,1,1,1,1,1,1,1
1,1,1,8,0,0,0,8,0,0,0,0,0,0,0,0,8,1,1,1,1,1,1,1,1
1,1,1,9,0,0,0,9,9,9,9,9,9,9,9,9,1,1,1,1,1,1,1,1,1
1,1,1,5,0,0,0,5,1,1,1,1,1,1,1,1,1,1,1,1,1,1,1,1,1
1,1,1,5,0,0,0,5,1,1,1,1,1,1,1,1,1,1,1,1,1,1,1,1,1
1,1,1,5,0,0,0,5,1,1,1,1,1,1,1,1,1,5,5,1,1,1,1,1,1
1,1,1,5,0,0,0,5,1,1,1,1,1,1,1,1,1,5,5,1,1,1,1,1,1
1,1,1,8,0,0,0,8,1,1,1,1,1,1,1,1,1,5,5,1,1,1,1,1,1
1,1,1,5,0,0,0,5,1,1,1,1,1,1,1,1,1,1,1,1,1,1,1,1,1
1,1,1,5,0,0,0,5,1,1,1,1,1,1,1,1,1,1,1,1,1,1,1,1,1
1,1,1,5,0,0,0,5,1,1,1,1,1,1,1,1,1,1,1,1,1,1,1,1,1
1,1,1,5,0,0,0,5,1,1,1,1,1,1,1,1,1,1,1,1,1,1,1,1,1
1,1,1,5,0,0,0,5,5,5,5,1,1,1,1,1,1,1,1,1,1,1,1,1,1
1,1,1,8,0,0,0,8,1,1,1,1,1,1,1,1,1,1,1,1,1,1,1,1,1
1,1,1,1,10,10,10,1,1,1,1,1,1,1,1,1,1,1,1,1,1,1,1,1,1
endlayer

layer
1,1,1,1,1,10,1,1,1,5,5,5,5,5,1,1,1,1,1,1,1,1,1,1,1
1,1,1,1,8,0,8,1,1,5,5,5,5,5,1,1,1,1,1,1,1,1,1,1,1
1,1,1,1,5,0,5,1,1,5,5,5,5,5,1,1,1,1,1,1,1,1,1,1,1
1,1,1,1,5,0,5,1,1,5,5,5,5,5,1,1,1,1,1,1,1,1,1,1,1
1,1,1,1,5,0,5,1,1,1,1,1,1,1,1,1,1,1,1,1,1,1,1,1,1
1,1,1,1,5,0,5,1,1,1,1,1,1,1,1,1,1,1,1,1,1,1,1,1,1
1,1,1,1,5,0,5,1,1,1,1,1,1,1,1,1,1,1,1,1,1,1,1,1,1
1,1,1,1,8,0,8,1,1,1,1,1,1,1,1,1,1,1,1,1,1,1,1,1,1
1,1,1,1,5,0,5,1,1,1,1,1,1,1,1,1,1,1,1,1,1,1,1,1,1
1,1,1,1,5,0,5,1,1,1,1,1,1,1,1,1,1,1,1,1,1,1,1,1,1
1,1,1,1,5,0,5,1,1,1,1,1,1,1,1,1,1,1,1,1,1,1,1,1,1
1,1,1,1,5,0,5,1,1,1,1,1,0,1,1,1,1,1,1,1,1,1,1,1,1
1,1,1,1,5,0,5,1,1,1,1,1,1,13,13,13,1,1,1,1,1,1,1,1,1
1,1,1,1,8,0,8,1,1,1,1,1,9,1,1,1,9,1,1,1,1,1,1,1,1
1,1,1,1,5,0,5,1,1,1,1,1,9,1,1,1,9,1,1,1,1,1,1,1,1
1,1,1,1,5,0,5,1,1,1,1,9,9,0,0,0,9,1,1,1,1,1,1,1,1
1,1,1,1,5,0,5,1,1,1,9,0,0,0,0,0,9,1,1,1,1,1,1,1,1
1,1,1,1,5,0,5,1,1,1,9,0,0,0,0,0,9,1,1,1,1,1,1,1,1
1,1,1,1,9,0,9,1,9,9,9,0,9,0,16,0,9,1,1,1,1,1,1,1,1
1,1,1,8,0,0,0,8,0,0,0,0,0,0,0,0,8,1,1,1,1,1,1,1,1
1,1,1,9,0,0,0,0,0,0,0,0,0,0,0,0,9,1,1,1,1,1,1,1,1
1,1,1,9,0,0,0,0,0,0,0,0,0,0,0,0,9,1,1,1,1,1,1,1,1
1,1,1,9,0,0,0,0,0,0,0,0,0,0,0,0,9,1,1,1,1,1,1,1,1
1,1,1,9,0,0,0,0,0,0,0,0,0,0,0,0,9,1,1,1,1,1,1,1,1
1,1,1,9,0,0,0,0,0,0,0,0,0,0,0,0,9,1,1,1,1,1,1,1,1
1,1,1,8,0,0,0,8,0,0,0,0,0,0,0,0,8,1,1,1,1,1,1,1,1
1,1,1,9,0,0,0,0,0,0,0,0,0,0,0,0,9,1,1,1,1,1,1,1,1
1,1,1,9,0,0,0,0,0,0,0,0,0,0,0,0,9,1,1,1,1,1,1,1,1
1,1,1,9,0,0,0,0,0,0,0,0,0,0,0,0,9,1,1,1,1,1,1,1,1
1,1,1,9,0,0,0,0,0,0,0,0,0,0,0,0,9,1,1,1,1,1,1,1,1
1,1,1,9,0,0,0,0,0,0,0,0,0,0,0,0,9,1,1,1,1,1,1,1,1
1,1,1,8,0,0,0,8,0,0,0,0,0,0,0,0,8,1,1,1,1,1,1,1,1
1,1,1,1,9,0,9,9,9,9,9,9,9,9,9,9,1,1,1,1,1,1,1,1,1
1,1,1,1,5,0,5,1,1,1,1,1,1,1,1,1,1,1,1,1,1,1,1,1,1
1,1,1,1,5,0,5,1,1,1,1,1,1,1,1,1,1,1,1,1,1,1,1,1,1
1,1,1,1,5,0,5,1,1,1,1,1,1,1,1,1,1,1,1,1,1,1,1,1,1
1,1,1,1,5,0,5,1,1,1,1,1,1,1,1,1,1,1,1,1,1,1,1,1,1
1,1,1,1,8,0,8,1,1,1,1,1,1,1,1,1,1,1,1,1,1,1,1,1,1
1,1,1,1,5,0,5,1,1,1,1,1,1,1,1,1,1,1,1,1,1,1,1,1,1
1,1,1,1,5,0,5,1,1,1,1,1,1,1,1,1,1,1,1,1,1,1,1,1,1
1,1,1,1,5,0,5,1,1,1,1,1,1,1,1,1,1,1,1,1,1,1,1,1,1
1,1,1,1,5,0,5,1,1,1,1,1,1,1,1,1,1,1,1,1,1,1,1,1,1
1,1,1,1,5,0,5,1,1,1,1,1,1,1,1,1,1,1,1,1,1,1,1,1,1
1,1,1,1,8,0,8,1,1,1,1,1,1,1,1,1,1,1,1,1,1,1,1,1,1
1,1,1,1,1,10,1,1,1,1,1,1,1,1,1,1,1,1,1,1,1,1,1,1,1
endlayer

layer
1,1,1,1,1,1,1,1,1,1,1,1,1,1,1,1,1,1,1,1,1,1,1,1,1
1,1,1,1,1,8,1,1,1,1,1,1,1,1,1,1,1,1,1,1,1,1,1,1,1
1,1,1,1,1,5,1,1,1,1,1,1,1,1,1,1,1,1,1,1,1,1,1,1,1
1,1,1,1,1,5,1,1,1,1,1,1,1,1,1,1,1,1,1,1,1,1,1,1,1
1,1,1,1,1,5,1,1,1,1,1,1,1,1,1,1,1,1,1,1,1,1,1,1,1
1,1,1,1,1,5,1,1,1,1,1,1,1,1,1,1,1,1,1,1,1,1,1,1,1
1,1,1,1,1,5,1,1,1,1,1,1,1,1,1,1,1,1,1,1,1,1,1,1,1
1,1,1,1,1,8,1,17,1,1,1,1,1,1,1,1,1,1,1,1,1,1,1,1,1
1,1,1,1,1,5,1,1,1,1,1,1,1,1,1,1,1,1,1,1,1,1,1,1,1
1,1,1,1,1,5,1,1,1,1,1,1,1,1,1,1,1,1,1,1,1,1,1,1,1
1,1,1,1,1,5,1,1,1,1,1,1,1,1,1,1,1,1,1,1,1,1,1,1,1
1,1,1,1,1,5,1,1,1,1,1,1,0,13,13,13,1,1,1,1,1,1,1,1,1
1,1,1,1,1,5,1,1,1,1,1,1,9,1,1,1,9,1,1,1,1,1,1,1,1
1,1,1,17,1,8,1,17,1,1,1,1,9,1,1,1,9,1,1,1,1,1,1,1,1
1,1,1,1,1,5,1,1,1,1,1,1,9,0,0,0,9,1,1,1,1,1,1,1,1
1,1,1,1,1,5,1,1,1,1,1,1,9,0,0,0,9,1,1,1,1,1,1,1,1
1,1,1,1,1,5,1,1,1,1,1,9,9,0,0,0,9,1,1,1,1,1,1,1,1
1,1,1,1,1,5,1,1,1,1,1,9,9,0,0,0,9,1,1,1,1,1,1,1,1
1,1,1,1,9,9,9,1,9,9,9,9,9,0,16,0,9,1,1,1,1,1,1,1,1
1,1,1,8,0,0,0,8,0,0,0,0,0,0,0,0,8,1,1,1,1,1,1,1,1
1,1,1,9,0,0,0,0,0,0,0,0,0,0,0,0,9,1,1,1,1,1,1,1,1
1,1,1,9,0,0,0,0,0,0,0,0,0,0,0,0,9,1,1,1,1,1,1,1,1
1,1,1,9,0,0,0,0,0,0,0,0,0,0,0,0,9,1,1,1,1,1,1,1,1
1,1,1,9,0,0,0,0,0,0,0,0,0,0,0,0,9,1,1,1,1,1,1,1,1
1,1,1,9,0,0,0,0,0,0,0,0,0,0,0,0,9,1,1,1,1,1,1,1,1
1,1,1,8,0,0,0,8,0,0,0,0,0,0,0,0,8,1,1,1,1,1,1,1,1
1,1,1,9,0,0,0,0,0,0,0,0,0,0,0,0,9,1,1,1,1,1,1,1,1
1,1,1,9,0,0,0,0,0,0,0,0,0,0,0,0,9,1,1,1,1,1,1,1,1
1,1,1,9,0,0,0,0,0,0,0,0,0,0,0,0,9,1,1,1,1,1,1,1,1
1,1,1,9,0,0,0,0,0,0,0,0,0,0,0,0,9,1,1,1,1,1,1,1,1
1,1,1,9,0,0,0,0,0,0,0,0,0,0,0,0,9,1,1,1,1,1,1,1,1
1,1,1,8,0,0,0,8,0,0,0,0,0,0,0,0,8,1,1,1,1,1,1,1,1
1,1,1,1,9,9,9,9,9,9,9,9,9,9,9,9,1,1,1,1,1,1,1,1,1
1,1,1,1,1,5,1,1,1,1,1,1,1,1,1,1,1,1,1,1,1,1,1,1,1
1,1,1,1,1,5,1,1,1,1,1,1,1,1,1,1,1,1,1,1,1,1,1,1,1
1,1,1,1,1,5,1,1,1,1,1,1,1,1,1,1,1,1,1,1,1,1,1,1,1
1,1,1,1,1,5,1,1,1,1,1,1,1,1,1,1,1,1,1,1,1,1,1,1,1
1,1,1,1,1,8,1,17,1,1,1,1,1,1,1,1,1,1,1,1,1,1,1,1,1
1,1,1,1,1,5,1,1,1,1,1,1,1,1,1,1,1,1,1,1,1,1,1,1,1
1,1,1,1,1,5,1,1,1,1,1,1,1,1,1,1,1,1,1,1,1,1,1,1,1
1,1,1,1,1,5,1,1,1,1,1,1,1,1,1,1,1,1,1,1,1,1,1,1,1
1,1,1,1,1,5,1,1,1,1,1,1,1,1,1,1,1,1,1,1,1,1,1,1,1
1,1,1,1,1,5,1,1,1,1,1,1,1,1,1,1,1,1,1,1,1,1,1,1,1
1,1,1,1,1,8,1,1,1,1,1,1,1,1,1,1,1,1,1,1,1,1,1,1,1
1,1,1,1,1,1,1,1,1,1,1,1,1,1,1,1,1,1,1,1,1,1,1,1,1
endlayer

layer
1,1,1,1,1,1,1,1,1,1,1,1,1,1,1,1,1,1,1,1,1,1,1,1,1
1,1,1,1,1,1,1,1,1,1,1,1,1,1,1,1,1,1,1,1,1,1,1,1,1
1,1,1,1,1,1,1,1,1,1,1,1,1,1,1,1,1,1,1,1,1,1,1,1,1
1,1,1,1,1,1,1,1,1,1,1,1,1,1,1,1,1,1,1,1,1,1,1,1,1
1,1,1,1,1,1,1,1,1,1,1,1,1,1,1,1,1,1,1,1,1,1,1,1,1
1,1,1,1,1,1,1,1,1,1,1,1,1,1,1,1,1,1,1,1,1,1,1,1,1
1,1,1,1,1,1,1,1,1,1,1,1,1,1,1,1,1,1,1,1,1,1,1,1,1
1,1,1,1,1,1,1,1,1,1,1,1,1,1,1,1,1,1,1,1,1,1,1,1,1
1,1,1,1,1,1,1,1,1,1,1,1,1,1,1,1,1,1,1,1,1,1,1,1,1
1,1,1,1,1,1,1,1,1,1,1,1,1,1,1,1,1,1,1,1,1,1,1,1,1
1,1,1,1,1,1,1,1,1,1,1,1,1,13,13,13,1,1,1,1,1,1,1,1,1
1,1,1,1,1,1,1,1,1,1,1,1,9,1,1,1,9,1,1,1,1,1,1,1,1
1,1,1,1,1,1,1,1,1,1,1,1,9,0,0,0,9,1,1,1,1,1,1,1,1
1,1,1,1,1,1,1,1,1,1,1,1,9,0,0,0,9,1,1,1,1,1,1,1,1
1,1,1,1,1,1,1,1,1,1,1,1,9,0,0,0,9,1,1,1,1,1,1,1,1
1,1,1,1,1,1,1,1,1,1,1,1,9,0,0,0,9,1,1,1,1,1,1,1,1
1,1,1,1,1,1,1,1,1,1,1,1,9,0,0,0,9,1,1,1,1,1,1,1,1
1,1,1,1,1,1,1,1,1,1,1,1,9,0,0,0,9,1,1,1,1,1,1,1,1
1,1,1,1,9,9,9,9,9,9,9,9,9,0,16,0,9,1,1,1,1,1,1,1,1
1,1,1,8,8,0,8,8,8,0,0,0,0,0,0,8,8,1,1,1,1,1,1,1,1
1,1,1,9,0,0,0,0,0,0,0,0,0,0,0,0,9,1,1,1,1,1,1,1,1
1,1,1,9,0,0,0,0,0,0,0,0,0,0,0,0,9,1,1,1,1,1,1,1,1
1,1,1,9,0,0,0,0,0,0,0,0,0,0,0,0,9,1,1,1,1,1,1,1,1
1,1,1,9,0,0,0,0,0,0,0,0,0,0,0,0,9,1,1,1,1,1,1,1,1
1,1,1,9,0,0,0,0,0,0,0,0,0,0,0,0,9,1,1,1,1,1,1,1,1
1,1,1,8,8,0,8,8,8,0,0,0,0,0,0,8,8,1,1,1,1,1,1,1,1
1,1,1,9,0,0,0,0,0,0,0,0,0,0,0,0,9,1,1,1,1,1,1,1,1
1,1,1,9,0,0,0,0,0,0,0,0,0,0,0,0,9,1,1,1,1,1,1,1,1
1,1,1,9,0,0,0,0,0,0,0,0,0,0,0,0,9,1,1,1,1,1,1,1,1
1,1,1,9,0,0,0,0,0,0,0,0,0,0,0,0,9,1,1,1,1,1,1,1,1
1,1,1,9,0,0,0,0,0,0,0,0,0,0,0,0,9,1,1,1,1,1,1,1,1
1,1,1,8,8,0,8,8,8,0,0,0,0,0,0,8,8,1,1,1,1,1,1,1,1
1,1,1,1,9,9,9,9,9,9,9,9,9,9,9,9,1,1,1,1,1,1,1,1,1
1,1,1,1,1,1,1,1,1,1,1,1,1,1,1,1,1,1,1,1,1,1,1,1,1
1,1,1,1,1,1,1,1,1,1,1,1,1,1,1,1,1,1,1,1,1,1,1,1,1
1,1,1,1,1,1,1,1,1,1,1,1,1,1,1,1,1,1,1,1,1,1,1,1,1
1,1,1,1,1,1,1,1,1,1,1,1,1,1,1,1,1,1,1,1,1,1,1,1,1
1,1,1,1,1,1,1,1,1,1,1,1,1,1,1,1,1,1,1,1,1,1,1,1,1
1,1,1,1,1,1,1,1,1,1,1,1,1,1,1,1,1,1,1,1,1,1,1,1,1
1,1,1,1,1,1,1,1,1,1,1,1,1,1,1,1,1,1,1,1,1,1,1,1,1
1,1,1,1,1,1,1,1,1,1,1,1,1,1,1,1,1,1,1,1,1,1,1,1,1
1,1,1,1,1,1,1,1,1,1,1,1,1,1,1,1,1,1,1,1,1,1,1,1,1
1,1,1,1,1,1,1,1,1,1,1,1,1,1,1,1,1,1,1,1,1,1,1,1,1
1,1,1,1,1,1,1,1,1,1,1,1,1,1,1,1,1,1,1,1,1,1,1,1,1
1,1,1,1,1,1,1,1,1,1,1,1,1,1,1,1,1,1,1,1,1,1,1,1,1
endlayer

layer
1,1,1,1,1,1,1,1,1,1,1,1,1,1,1,1,1,1,1,1,1,1,1,1,1
1,1,1,1,1,1,1,1,1,1,1,1,1,1,1,1,1,1,1,1,1,1,1,1,1
1,1,1,1,1,1,1,1,1,1,1,1,1,1,1,1,1,1,1,1,1,1,1,1,1
1,1,1,1,1,1,1,1,1,1,1,1,1,1,1,1,1,1,1,1,1,1,1,1,1
1,1,1,1,1,1,1,1,1,1,1,1,1,1,1,1,1,1,1,1,1,1,1,1,1
1,1,1,1,1,1,1,1,1,1,1,1,1,1,1,1,1,1,1,1,1,1,1,1,1
1,1,1,1,1,1,1,1,1,1,1,1,1,1,1,1,1,1,1,1,1,1,1,1,1
1,1,1,1,1,1,1,1,1,1,1,1,1,1,1,1,1,1,1,1,1,1,1,1,1
1,1,1,1,1,1,1,1,1,1,1,1,1,1,1,1,1,1,1,1,1,1,1,1,1
1,1,1,1,1,1,1,1,1,1,1,1,1,13,13,13,1,1,1,1,1,1,1,1,1
1,1,1,1,1,1,1,1,1,1,1,1,9,0,0,0,9,1,1,1,1,1,1,1,1
1,1,1,1,1,1,1,1,1,1,1,1,9,0,0,0,9,1,1,1,1,1,1,1,1
1,1,1,1,1,1,1,1,1,1,1,1,9,0,0,0,9,1,1,1,1,1,1,1,1
1,1,1,1,1,1,1,1,1,1,1,1,9,0,0,0,9,1,1,1,1,1,1,1,1
1,1,1,1,1,1,1,1,1,1,1,1,9,0,0,0,9,1,1,1,1,1,1,1,1
1,1,1,1,1,1,1,1,1,1,1,1,9,0,0,0,9,1,1,1,1,1,1,1,1
1,1,1,1,1,1,1,1,1,1,1,1,9,0,0,0,9,1,1,1,1,1,1,1,1
1,1,1,1,1,1,1,1,1,1,1,1,9,0,0,0,9,1,1,1,1,1,1,1,1
1,1,1,1,9,9,9,9,9,9,9,9,9,0,16,0,9,1,1,1,1,1,1,1,1
1,1,1,8,0,8,0,8,0,8,0,0,0,0,8,0,8,1,1,1,1,1,1,1,1
1,1,1,9,0,0,0,0,0,0,0,0,0,0,0,0,9,1,1,1,1,1,1,1,1
1,1,1,9,0,0,0,0,0,0,0,0,0,0,0,0,9,1,1,1,1,1,1,1,1
1,1,1,9,0,0,0,0,0,0,0,0,0,0,0,0,9,1,1,1,1,1,1,1,1
1,1,1,9,0,0,0,0,0,0,0,0,0,0,0,0,9,1,1,1,1,1,1,1,1
1,1,1,9,0,0,0,0,0,0,0,0,0,0,0,0,9,1,1,1,1,1,1,1,1
1,1,1,8,0,8,0,8,0,8,0,0,0,0,8,0,8,1,1,1,1,1,1,1,1
1,1,1,9,0,0,0,0,0,0,0,0,0,0,0,0,9,1,1,1,1,1,1,1,1
1,1,1,9,0,0,0,0,0,0,0,0,0,0,0,0,9,1,1,1,1,1,1,1,1
1,1,1,9,0,0,0,0,0,0,0,0,0,0,0,0,9,1,1,1,1,1,1,1,1
1,1,1,9,0,0,0,0,0,0,0,0,0,0,0,0,9,1,1,1,1,1,1,1,1
1,1,1,9,0,0,0,0,0,0,0,0,0,0,0,0,9,1,1,1,1,1,1,1,1
1,1,1,8,0,8,0,8,0,8,0,0,0,0,8,0,8,1,1,1,1,1,1,1,1
1,1,1,1,9,9,9,9,9,9,9,9,9,9,9,9,1,1,1,1,1,1,1,1,1
1,1,1,1,1,1,1,1,1,1,1,1,1,1,1,1,1,1,1,1,1,1,1,1,1
1,1,1,1,1,1,1,1,1,1,1,1,1,1,1,1,1,1,1,1,1,1,1,1,1
1,1,1,1,1,1,1,1,1,1,1,1,1,1,1,1,1,1,1,1,1,1,1,1,1
1,1,1,1,1,1,1,1,1,1,1,1,1,1,1,1,1,1,1,1,1,1,1,1,1
1,1,1,1,1,1,1,1,1,1,1,1,1,1,1,1,1,1,1,1,1,1,1,1,1
1,1,1,1,1,1,1,1,1,1,1,1,1,1,1,1,1,1,1,1,1,1,1,1,1
1,1,1,1,1,1,1,1,1,1,1,1,1,1,1,1,1,1,1,1,1,1,1,1,1
1,1,1,1,1,1,1,1,1,1,1,1,1,1,1,1,1,1,1,1,1,1,1,1,1
1,1,1,1,1,1,1,1,1,1,1,1,1,1,1,1,1,1,1,1,1,1,1,1,1
1,1,1,1,1,1,1,1,1,1,1,1,1,1,1,1,1,1,1,1,1,1,1,1,1
1,1,1,1,1,1,1,1,1,1,1,1,1,1,1,1,1,1,1,1,1,1,1,1,1
1,1,1,1,1,1,1,1,1,1,1,1,1,1,1,1,1,1,1,1,1,1,1,1,1
endlayer

layer
1,1,1,1,1,1,1,1,1,1,1,1,1,1,1,1,1,1,1,1,1,1,1,1,1
1,1,1,1,1,1,1,1,1,1,1,1,1,1,1,1,1,1,1,1,1,1,1,1,1
1,1,1,1,1,1,1,1,1,1,1,1,1,1,1,1,1,1,1,1,1,1,1,1,1
1,1,1,1,1,1,1,1,1,1,1,1,1,1,1,1,1,1,1,1,1,1,1,1,1
1,1,1,1,1,1,1,1,1,1,1,1,1,1,1,1,1,1,1,1,1,1,1,1,1
1,1,1,1,1,1,1,1,1,1,1,1,1,1,1,1,1,1,1,1,1,1,1,1,1
1,1,1,1,1,1,1,1,1,1,1,1,1,1,1,1,1,1,1,1,1,1,1,1,1
1,1,1,1,1,1,1,1,1,1,1,1,1,1,1,1,1,1,1,1,1,1,1,1,1
1,1,1,1,1,1,1,1,1,1,1,1,1,13,13,13,1,1,1,1,1,1,1,1,1
1,1,1,1,1,1,1,1,1,1,1,1,9,0,0,0,9,1,1,1,1,1,1,1,1
1,1,1,1,1,1,1,1,1,1,1,1,9,0,0,0,9,1,1,1,1,1,1,1,1
1,1,1,1,1,1,1,1,1,1,1,1,9,0,0,0,9,1,1,1,1,1,1,1,1
1,1,1,1,1,1,1,1,1,1,1,1,9,0,0,0,9,1,1,1,1,1,1,1,1
1,1,1,1,1,1,1,1,1,1,1,1,1,9,9,9,1,1,1,1,1,1,1,1,1
1,1,1,1,1,1,1,1,1,1,1,1,1,9,9,9,1,1,1,1,1,1,1,1,1
1,1,1,1,1,1,1,1,1,1,1,1,1,9,9,9,1,1,1,1,1,1,1,1,1
1,1,1,1,1,1,1,1,1,1,1,1,1,9,18,9,1,1,1,1,1,1,1,1,1
1,1,1,1,1,1,1,1,1,1,1,1,1,9,9,9,1,1,1,1,1,1,1,1,1
1,1,1,1,1,1,1,1,1,1,1,1,1,9,9,9,1,1,1,1,1,1,1,1,1
1,1,1,1,8,8,8,8,8,8,8,8,8,8,8,8,1,1,1,1,1,1,1,1,1
1,1,1,1,9,9,9,9,9,9,9,9,9,9,9,9,1,1,1,1,1,1,1,1,1
1,1,1,1,9,9,9,9,9,9,9,9,9,9,9,9,1,1,1,1,1,1,1,1,1
1,1,1,1,9,9,9,9,18,9,9,18,9,9,18,9,1,1,1,1,1,1,1,1,1
1,1,1,1,9,9,9,9,9,9,9,9,9,9,9,9,1,1,1,1,1,1,1,1,1
1,1,1,1,9,9,9,9,9,9,9,9,9,9,9,9,1,1,1,1,1,1,1,1,1
1,1,1,1,8,8,8,8,8,8,8,8,8,8,8,8,17,1,1,1,1,1,1,1,1
1,1,1,1,9,9,9,9,9,9,9,9,9,9,9,9,1,1,1,1,1,1,1,1,1
1,1,1,1,9,9,9,9,9,9,9,9,9,9,9,9,1,1,1,1,1,1,1,1,1
1,1,1,1,9,9,9,9,18,9,9,18,9,9,18,9,1,1,1,1,1,1,1,1,1
1,1,1,1,9,9,9,9,9,9,9,9,9,9,9,9,1,1,1,1,1,1,1,1,1
1,1,1,1,9,9,9,9,9,9,9,9,9,9,9,9,1,1,1,1,1,1,1,1,1
1,1,1,1,8,8,8,8,8,8,8,8,8,8,8,8,1,1,1,1,1,1,1,1,1
1,1,1,1,1,1,1,1,1,1,1,1,1,1,1,1,1,1,1,1,1,1,1,1,1
1,1,1,1,1,1,1,1,1,1,1,1,1,1,1,1,1,1,1,1,1,1,1,1,1
1,1,1,1,1,1,1,1,1,1,1,1,1,1,1,1,1,1,1,1,1,1,1,1,1
1,1,1,1,1,1,1,1,1,1,1,1,1,1,1,1,1,1,1,1,1,1,1,1,1
1,1,1,1,1,1,1,1,1,1,1,1,1,1,1,1,1,1,1,1,1,1,1,1,1
1,1,1,1,1,1,1,1,1,1,1,1,1,1,1,1,1,1,1,1,1,1,1,1,1
1,1,1,1,1,1,1,1,1,1,1,1,1,1,1,1,1,1,1,1,1,1,1,1,1
1,1,1,1,1,1,1,1,1,1,1,1,1,1,1,1,1,1,1,1,1,1,1,1,1
1,1,1,1,1,1,1,1,1,1,1,1,1,1,1,1,1,1,1,1,1,1,1,1,1
1,1,1,1,1,1,1,1,1,1,1,1,1,1,1,1,1,1,1,1,1,1,1,1,1
1,1,1,1,1,1,1,1,1,1,1,1,1,1,1,1,1,1,1,1,1,1,1,1,1
1,1,1,1,1,1,1,1,1,1,1,1,1,1,1,1,1,1,1,1,1,1,1,1,1
1,1,1,1,1,1,1,1,1,1,1,1,1,1,1,1,1,1,1,1,1,1,1,1,1
endlayer

layer
1,1,1,1,1,1,1,1,1,1,1,1,1,1,1,1,1,1,1,1,1,1,1,1,1
1,1,1,1,1,1,1,1,1,1,1,1,1,1,1,1,1,1,1,1,1,1,1,1,1
1,1,1,1,1,1,1,1,1,1,1,1,1,1,1,1,1,1,1,1,1,1,1,1,1
1,1,1,1,1,1,1,1,1,1,1,1,1,1,1,1,1,1,1,1,1,1,1,1,1
1,1,1,1,1,1,1,1,1,1,1,1,1,1,1,1,1,1,1,1,1,1,1,1,1
1,1,1,1,1,1,1,1,1,1,1,1,1,1,1,1,1,1,1,1,1,1,1,1,1
1,1,1,1,1,1,1,1,1,1,1,1,1,1,1,1,1,1,1,1,1,1,1,1,1
1,1,1,1,1,1,1,1,1,1,1,1,1,13,13,13,1,1,1,1,1,1,1,1,1
1,1,1,1,1,0,1,1,1,1,1,1,9,0,0,0,9,1,1,1,1,1,1,1,1
1,1,1,1,1,1,1,1,1,1,1,1,9,0,0,0,9,1,1,1,1,1,1,1,1
1,1,1,1,1,1,1,1,1,1,1,1,9,0,0,0,9,1,1,1,1,1,1,1,1
1,1,1,1,1,1,1,1,1,1,1,1,9,0,0,0,9,1,1,1,1,1,1,1,1
1,1,1,1,1,1,1,1,1,1,1,1,1,9,9,9,1,1,1,1,1,1,1,1,1
1,1,1,1,1,1,1,1,1,1,1,1,1,1,1,1,1,1,1,1,1,1,1,1,1
1,1,1,1,1,1,1,1,1,1,1,1,1,1,1,1,1,1,1,1,1,1,1,1,1
1,1,1,1,1,1,1,1,1,1,1,1,1,1,1,1,1,1,1,1,1,1,1,1,1
1,1,1,1,1,1,1,1,1,1,1,1,1,1,1,1,1,1,1,1,1,1,1,1,1
1,1,1,1,1,1,1,1,1,1,1,1,1,1,1,1,1,1,1,1,1,1,1,1,1
1,1,1,1,1,1,1,1,1,1,1,1,1,1,1,1,1,1,1,1,1,1,1,1,1
1,1,1,1,1,1,1,1,1,1,1,1,1,1,1,1,1,1,1,1,1,1,1,1,1
1,1,1,1,1,1,1,1,1,1,1,1,1,1,1,1,1,1,1,1,1,1,1,1,1
1,1,1,1,1,1,1,1,1,1,1,1,1,1,1,1,1,1,1,1,1,1,1,1,1
1,1,1,1,1,1,1,1,1,1,1,1,1,1,1,1,1,1,1,1,1,1,1,1,1
1,1,1,1,1,1,1,1,1,1,1,1,1,1,1,1,1,1,1,1,1,1,1,1,1
1,1,1,1,1,1,1,1,1,1,1,1,1,1,1,1,1,1,1,1,1,1,1,1,1
1,1,1,1,1,1,1,1,1,1,1,1,1,1,1,1,1,1,1,1,1,1,1,1,1
1,1,1,1,1,1,1,1,1,1,1,1,1,1,1,1,1,1,1,1,1,1,1,1,1
1,1,1,1,1,1,1,1,1,1,1,1,1,1,1,1,1,1,1,1,1,1,1,1,1
1,1,1,1,1,1,1,1,1,1,1,1,1,1,1,1,1,1,1,1,1,1,1,1,1
1,1,1,1,1,1,1,1,1,1,1,1,1,1,1,1,1,1,1,1,1,1,1,1,1
1,1,1,1,1,1,1,1,1,1,1,1,1,1,1,1,1,1,1,1,1,1,1,1,1
1,1,1,1,1,1,1,1,1,1,1,1,1,1,1,1,1,1,1,1,1,1,1,1,1
1,1,1,1,1,1,1,1,1,1,1,1,1,1,1,1,1,1,0,1,1,1,1,1,1
1,1,1,1,1,1,1,1,1,1,1,1,1,1,1,1,1,1,1,1,1,1,1,1,1
1,1,1,1,1,1,1,1,1,1,1,1,1,1,1,1,1,1,1,1,1,1,1,1,1
1,1,1,1,1,1,1,1,1,1,1,1,1,1,1,1,1,1,1,1,1,1,1,1,1
1,1,1,1,1,1,1,1,1,1,1,1,1,1,1,1,1,1,1,1,1,1,1,1,1
1,1,1,1,1,1,1,1,1,1,1,1,1,1,1,1,1,1,1,1,1,1,1,1,1
1,1,1,1,1,1,1,1,1,1,1,1,1,1,1,1,1,1,1,1,1,1,1,1,1
1,1,1,1,1,1,1,1,1,1,1,1,1,1,1,1,1,1,1,1,1,1,1,1,1
1,1,1,1,1,1,1,1,1,1,1,1,1,1,1,1,1,1,1,1,1,1,1,1,1
1,1,1,1,1,1,1,1,1,1,1,1,1,1,1,1,1,1,1,1,1,1,1,1,1
1,1,1,1,1,1,1,1,1,1,1,1,1,1,1,1,1,1,1,1,1,1,1,1,1
1,1,1,1,1,1,1,1,1,1,1,1,1,1,1,1,1,1,1,1,1,1,1,1,1
1,1,1,1,1,1,1,1,1,1,1,1,1,1,1,1,1,1,1,1,1,1,1,1,1
endlayer

layer
1,1,1,1,1,1,1,1,1,1,1,1,1,1,1,1,1,1,1,1,1,1,1,1,1
1,1,1,1,1,1,1,1,1,1,1,1,1,1,1,1,1,1,1,1,1,1,1,1,1
1,1,1,1,1,1,1,1,1,1,1,1,1,1,1,1,1,1,1,1,1,1,1,1,1
1,1,1,1,1,1,1,1,1,1,1,1,1,1,1,1,1,1,1,1,1,1,1,1,1
1,1,1,1,1,1,1,1,1,1,1,1,1,1,1,1,1,1,1,1,1,1,1,1,1
1,1,1,1,1,17,17,17,1,1,1,1,1,1,1,1,1,1,1,1,1,1,1,1,1
1,1,1,1,17,17,17,17,17,1,1,1,1,13,13,13,1,1,1,1,1,1,1,1,1
1,1,1,1,17,17,17,17,17,1,1,1,9,1,1,1,9,1,1,1,1,1,1,1,1
1,1,1,1,17,17,17,17,17,1,1,1,9,1,1,1,9,1,1,1,1,1,1,1,1
1,1,1,1,1,17,17,17,1,1,1,1,9,1,1,1,9,1,1,1,1,1,1,1,1
1,1,1,1,1,1,1,1,1,1,1,1,9,1,1,1,9,1,1,1,1,1,1,1,1
1,1,1,1,1,1,1,1,1,1,1,1,1,9,9,9,1,1,1,1,1,1,1,1,1
1,1,1,1,1,1,1,1,1,1,1,1,1,1,1,1,1,1,1,1,1,1,1,1,1
1,1,1,1,1,1,1,1,1,1,1,1,1,1,1,1,1,1,1,1,1,1,1,1,1
1,1,1,1,1,1,1,1,1,1,1,1,1,1,1,1,1,1,1,1,1,1,1,1,1
1,1,1,1,1,1,1,1,1,1,1,1,1,1,1,1,1,1,1,1,1,1,1,1,1
1,1,1,1,1,1,1,1,1,1,1,1,1,1,1,1,1,1,1,1,1,1,1,1,1
1,1,1,1,1,1,1,1,1,1,1,1,1,1,1,1,1,1,1,1,1,1,1,1,1
1,1,1,1,1,1,1,1,1,1,1,1,1,1,1,1,1,1,1,1,1,1,1,1,1
1,1,1,1,1,1,1,1,1,1,1,1,1,1,1,1,1,1,1,1,1,1,1,1,1
1,1,1,1,1,1,1,1,1,1,1,1,1,1,1,1,1,1,1,1,1,1,1,1,1
1,1,1,1,1,1,1,1,1,1,1,1,1,1,1,1,1,1,1,1,1,1,1,1,1
1,1,1,1,1,1,1,1,1,1,1,1,1,1,1,1,1,1,1,1,1,1,1,1,1
1,1,1,1,1,1,1,1,1,1,1,1,1,1,1,1,1,1,1,1,1,1,1,1,1
1,1,1,1,1,1,1,1,1,1,1,1,1,1,1,1,1,1,1,1,1,0,1,1,1
1,1,1,1,1,1,1,1,1,1,1,1,1,1,1,1,1,1,1,1,1,1,1,1,1
1,1,1,1,1,1,1,1,1,1,1,1,1,1,1,1,1,1,1,1,1,1,1,1,1
1,1,1,1,1,1,1,1,1,1,1,1,1,1,1,1,1,1,1,1,1,1,1,1,1
1,1,1,1,1,1,1,1,1,1,1,1,1,1,1,1,1,1,1,1,1,1,1,1,1
1,1,1,1,1,1,1,1,1,1,1,1,1,1,1,1,1,1,1,1,1,1,1,1,1
1,1,1,1,1,1,1,1,1,1,1,1,1,1,1,1,1,1,1,1,1,1,1,1,1
1,1,1,1,1,1,1,1,1,1,1,1,1,1,1,1,1,1,1,1,1,1,1,1,1
1,1,1,1,1,1,1,1,1,1,1,1,1,1,1,1,1,1,0,1,1,1,1,1,1
1,1,1,1,1,1,1,1,1,1,1,1,1,1,1,1,1,1,1,1,1,1,1,1,1
1,1,1,1,1,1,1,1,1,1,1,1,1,1,1,1,1,1,1,1,1,1,1,1,1
1,1,1,1,1,1,1,1,1,1,1,1,1,1,1,1,1,1,1,1,1,1,1,1,1
1,1,1,1,1,1,1,1,1,1,1,1,1,1,1,1,1,1,1,1,1,1,1,1,1
1,1,1,0,1,1,1,1,1,1,1,1,1,1,1,1,1,1,1,1,1,1,1,1,1
1,1,1,1,1,1,1,1,1,1,1,1,1,1,1,1,1,1,1,1,1,1,1,1,1
1,1,1,1,1,1,1,1,1,1,1,1,1,1,1,1,1,1,1,1,1,1,1,1,1
1,1,1,1,1,1,1,1,1,1,1,1,1,1,1,1,1,1,1,1,1,1,1,1,1
1,1,1,1,1,1,1,1,1,1,1,1,1,1,1,1,1,1,1,1,1,1,1,1,1
1,1,1,1,1,1,1,1,1,1,1,1,1,1,1,1,1,1,1,1,1,1,1,1,1
1,1,1,1,1,1,1,1,1,1,1,1,1,1,1,1,1,1,1,1,1,1,1,1,1
1,1,1,1,1,1,1,1,1,1,1,1,1,1,1,1,1,1,1,1,1,1,1,1,1
endlayer

layer
13,13,13,13,13,13,13,13,13,13,13,13,13,13,13,13,13,13,13,13,13,13,13,13,13
13,13,13,13,13,13,13,13,13,13,13,13,13,13,13,13,13,13,13,13,13,13,13,13,13
13,13,1,1,1,1,1,1,1,1,1,1,1,13,13,13,1,1,1,1,1,1,1,13,13
13,13,1,1,1,1,1,1,1,1,1,1,1,13,13,13,1,1,1,1,1,1,1,13,13
13,13,1,1,1,1,1,1,1,1,1,1,1,13,13,13,1,1,1,1,1,1,1,13,13
13,13,1,1,1,17,17,17,1,1,1,1,1,13,13,13,1,1,1,1,1,1,1,13,13
13,13,1,1,17,1,1,1,17,1,1,1,9,1,1,1,9,1,1,1,1,1,1,13,13
13,13,1,1,17,1,21,1,17,1,1,1,9,1,1,1,9,1,1,1,1,1,1,13,13
13,13,1,1,17,1,1,1,17,1,1,1,9,1,1,1,9,1,1,1,1,1,1,13,13
13,13,1,1,1,17,17,17,1,1,1,1,9,1,1,1,9,1,1,1,1,1,1,13,13
13,13,1,1,1,1,1,1,1,1,1,1,1,9,9,9,1,1,1,1,1,1,1,13,13
13,13,1,1,1,1,1,1,1,1,1,1,1,1,1,1,1,1,1,1,1,1,1,13,13
13,13,1,1,1,1,1,1,1,1,1,1,1,1,1,1,1,1,1,1,1,1,1,13,13
13,13,1,1,1,1,1,1,1,8,8,8,8,8,8,8,1,1,1,1,1,1,1,13,13
13,13,1,1,1,1,1,1,1,8,12,12,12,12,12,8,1,1,1,1,1,1,1,13,13
13,13,1,1,1,1,1,1,1,8,12,12,12,12,12,8,1,1,1,1,1,1,1,13,13
13,13,13,13,13,13,13,13,13,12,12,12,12,12,12,12,13,13,13,13,13,13,13,13,13
13,13,1,1,1,1,1,1,1,8,12,12,12,12,12,8,1,1,1,1,1,1,1,13,13
13,13,1,1,1,1,1,1,1,8,12,12,12,12,12,8,1,1,1,1,1,1,1,13,13
13,13,1,1,1,1,1,1,1,8,12,12,4,12,12,8,1,1,1,1,1,1,1,13,13
13,13,8,8,8,8,8,8,8,12,12,12,12,12,12,12,8,8,8,8,8,8,8,13,13
13,13,8,12,12,12,12,12,12,12,12,12,12,12,12,12,12,12,12,12,12,12,8,13,13
13,13,8,12,12,12,12,12,12,12,12,12,12,12,12,12,12,12,12,12,12,12,8,13,13
13,13,8,12,12,12,12,12,4,12,12,12,12,12,12,12,12,12,12,12,2,12,8,13,13
13,13,8,12,12,12,12,12,12,12,12,12,12,12,12,12,12,12,12,12,12,12,8,13,13
13,13,8,12,12,12,12,12,12,12,12,12,12,12,12,12,12,12,12,12,12,12,8,13,13
13,13,8,8,8,8,8,8,8,12,12,12,12,12,12,20,8,8,8,8,8,8,8,13,13
13,13,1,19,19,19,19,19,19,8,12,12,2,12,12,8,19,19,19,19,19,19,1,13,13
13,13,1,19,19,19,19,19,19,8,12,12,12,12,12,8,19,19,19,19,19,19,1,13,13
13,13,1,19,19,19,19,19,19,8,12,12,12,12,12,8,19,19,19,19,19,19,1,13,13
13,13,1,19,19,19,19,19,19,12,12,12,12,12,12,12,19,19,19,19,19,19,1,13,13
13,13,1,19,19,19,19,19,19,8,12,12,12,12,12,8,19,19,19,19,19,19,1,13,13
13,13,1,19,19,19,19,19,19,8,12,12,12,12,12,8,19,19,19,19,19,19,1,13,13
13,13,1,19,19,19,19,19,19,8,8,8,8,8,8,8,19,19,19,19,19,19,1,13,13
13,13,13,19,19,19,19,19,19,19,19,19,19,19,19,19,19,19,19,19,19,19,13,13,13
13,13,1,19,19,19,19,19,19,19,19,19,19,19,19,19,19,19,19,19,19,19,1,13,13
13,13,1,19,19,19,19,19,19,19,19,19,19,19,19,19,19,19,19,19,19,19,1,13,13
13,13,1,19,19,19,19,19,19,19,19,19,19,19,19,19,19,19,19,19,19,19,1,13,13
13,13,1,19,19,19,19,19,19,19,19,19,19,19,19,19,19,19,19,19,19,19,1,13,13
13,13,1,19,19,19,19,19,19,19,19,19,19,19,19,19,19,19,19,19,19,19,1,13,13
13,13,1,19,19,19,19,19,19,19,19,19,19,19,19,19,19,19,19,19,19,19,1,13,13
13,13,1,19,19,19,19,19,19,19,19,19,19,19,19,19,19,19,19,19,19,19,1,13,13
13,13,1,1,1,1,1,1,1,1,1,1,13,1,1,1,1,1,1,1,1,1,1,13,13
13,13,13,13,13,13,13,13,13,13,13,13,13,13,13,13,13,13,13,13,13,13,13,13,13
13,13,13,13,13,13,13,13,13,13,13,13,13,13,13,13,13,13,13,13,13,13,13,13,13
endlayer

layer
1,1,1,1,1,1,1,1,1,1,1,1,1,1,1,1,1,1,1,1,1,1,1,1,1
1,1,1,1,1,1,1,1,1,1,1,1,1,1,1,1,1,1,1,1,1,1,1,1,1
1,1,1,1,1,1,1,1,1,1,1,1,1,1,1,1,1,1,1,1,1,1,1,1,1
1,1,1,1,1,1,1,1,1,1,1,1,1,1,1,1,1,1,1,1,1,1,1,1,1
1,1,1,1,1,32,32,32,1,1,1,1,1,1,1,1,1,1,1,1,1,1,1,1,1
1,1,1,1,32,17,17,17,32,1,1,1,1,1,1,1,1,1,1,1,1,1,1,1,1
1,1,1,32,17,1,1,1,17,32,1,1,23,1,1,1,23,1,1,1,1,1,1,1,1
1,1,1,32,17,1,33,1,17,32,1,1,24,1,1,1,24,1,1,1,1,22,22,1,1
1,1,1,32,17,1,1,1,17,32,1,1,24,1,1,1,24,1,1,1,1,22,15,1,1
1,1,1,1,32,17,17,17,32,1,1,1,24,1,1,1,24,1,1,1,1,22,15,1,1
1,1,1,1,1,32,32,32,1,1,1,1,23,24,24,24,23,1,1,1,1,22,22,1,1
1,1,1,1,1,1,1,1,1,1,1,1,1,1,1,1,1,1,1,1,1,1,1,1,1
1,1,1,1,1,1,1,1,1,1,1,1,1,1,1,1,1,1,1,1,1,1,1,1,1
1,1,1,1,1,1,1,1,1,8,8,8,8,8,8,8,1,1,1,1,1,1,1,1,1
1,1,1,1,1,1,1,1,1,8,1,0,0,0,0,8,1,1,1,1,1,1,1,1,1
1,1,1,1,1,1,1,1,1,8,1,26,0,26,1,8,1,1,1,1,1,1,1,1,1
1,1,1,1,1,1,1,1,1,1,1,26,0,26,1,1,1,1,1,1,1,1,1,1,1
1,1,1,1,1,1,1,1,1,8,0,26,0,26,1,8,1,1,1,1,1,1,1,1,1
1,1,1,1,1,1,1,1,1,8,0,0,0,0,0,8,1,1,1,1,1,1,1,1,1
1,1,1,1,1,1,1,1,1,8,0,0,9,0,0,8,1,1,1,1,1,1,1,1,1
1,1,8,8,8,8,8,8,8,31,31,31,31,31,31,31,8,8,8,8,8,8,8,1,1
1,1,8,0,0,0,0,0,0,31,31,31,31,31,31,31,0,0,0,0,0,0,8,1,1
1,1,8,0,26,26,26,0,0,31,31,31,31,31,31,31,29,0,0,0,26,0,8,1,1
1,1,8,0,0,0,0,0,9,31,31,31,31,31,31,31,30,0,0,0,26,4,8,1,1
1,1,8,0,26,26,26,0,0,31,31,31,31,31,31,31,29,0,0,0,26,0,8,1,1
1,1,8,0,0,0,0,0,0,31,31,31,31,31,31,31,29,0,0,0,0,0,8,1,1
1,1,8,8,8,8,8,8,8,31,31,31,31,31,31,31,8,8,8,8,8,8,8,1,1
1,1,23,1,14,15,15,14,1,8,0,0,9,0,0,8,1,14,15,15,14,1,23,1,1
1,1,24,1,1,1,1,1,1,8,0,0,0,0,0,8,1,1,1,1,1,1,24,1,1
1,1,24,1,1,1,1,1,1,8,0,26,0,26,0,8,1,1,1,1,1,1,24,1,1
1,1,24,1,1,1,1,1,1,1,1,26,0,26,1,1,1,1,1,1,1,1,24,1,1
1,1,24,1,1,1,1,1,1,8,0,26,0,26,1,8,1,1,1,1,1,1,24,1,1
1,1,24,1,1,1,1,1,1,8,0,0,0,0,0,8,1,1,1,1,1,1,24,1,1
1,1,23,1,1,1,1,1,1,8,8,8,8,8,8,8,1,1,1,1,1,1,23,1,1
1,1,1,1,1,1,1,1,1,1,1,1,1,1,1,1,1,1,1,1,1,1,1,1,1
1,1,23,1,1,1,1,1,1,1,1,1,1,1,1,1,1,1,1,1,1,1,23,1,1
1,1,24,25,1,1,1,1,1,1,1,1,1,1,1,1,1,1,1,1,1,25,24,1,1
1,1,24,1,1,1,1,1,1,1,1,1,1,1,1,1,1,1,1,1,1,1,24,1,1
1,1,24,1,1,1,1,1,1,1,1,1,1,1,1,1,1,1,1,1,1,1,24,1,1
1,1,24,1,1,27,27,1,27,27,1,1,1,1,1,1,1,1,1,1,1,1,24,1,1
1,1,24,1,1,28,28,1,28,28,1,1,1,1,27,28,27,1,27,28,27,1,24,1,1
1,1,24,1,1,27,27,1,27,27,1,1,1,1,1,1,1,1,1,1,1,1,24,1,1
1,1,23,24,24,24,24,24,24,24,24,23,1,23,24,24,24,24,24,24,24,24,23,1,1
1,1,1,1,1,1,1,1,1,1,1,1,1,1,1,1,1,1,1,1,1,1,1,1,1
1,1,1,1,1,1,1,1,1,1,1,1,1,1,1,1,1,1,1,1,1,1,1,1,1
endlayer

layer
1,1,1,1,1,1,1,1,1,1,1,1,1,1,1,1,1,1,1,1,1,1,1,1,1
1,1,1,1,1,1,1,1,1,1,1,1,1,1,1,1,1,1,1,1,1,1,1,1,1
1,1,1,1,1,1,1,1,1,1,1,1,1,1,1,1,1,1,1,1,1,1,1,1,1
1,1,1,1,1,1,1,1,1,1,1,1,1,1,1,1,1,1,1,1,1,1,1,1,1
1,1,1,1,1,1,1,1,1,1,1,1,1,1,1,1,1,1,1,1,1,1,1,1,1
1,1,1,1,1,1,1,1,1,1,1,1,1,1,1,1,1,1,1,1,1,1,1,1,1
1,1,1,1,1,1,1,1,1,1,1,1,1,1,1,1,1,1,1,1,1,1,1,1,1
1,1,1,1,1,1,21,1,1,1,1,1,1,1,1,1,1,1,1,1,1,22,22,1,1
1,1,1,1,1,1,1,1,1,1,1,1,1,1,1,1,1,1,1,1,1,22,0,1,1
1,1,1,1,1,1,1,1,1,1,1,1,1,1,0,0,1,1,1,1,1,22,0,1,1
1,1,1,1,1,1,1,1,1,1,1,1,1,1,1,1,1,1,1,1,1,22,22,1,1
1,1,1,1,1,1,1,1,1,1,1,1,1,1,1,1,1,1,1,1,1,1,1,1,1
1,1,1,1,1,1,1,1,1,1,1,1,1,1,1,1,1,1,1,1,1,1,1,1,1
1,1,1,1,1,1,1,1,1,8,34,9,34,9,34,8,1,1,1,1,1,1,1,1,1
1,1,1,1,1,1,1,1,1,34,0,0,0,0,0,34,1,1,1,1,1,1,1,1,1
1,1,1,1,1,1,1,1,1,9,0,26,0,26,0,9,1,1,1,1,1,1,1,1,1
1,1,1,1,1,1,1,1,1,0,0,26,0,26,0,1,1,1,1,1,1,1,1,1,1
1,1,1,1,1,1,1,1,1,9,0,26,0,26,0,9,1,1,1,1,1,1,1,1,1
1,1,1,1,1,1,1,1,1,34,0,0,0,0,0,34,1,1,1,1,1,1,1,1,1
1,1,1,1,1,1,1,1,1,8,0,0,9,0,0,8,1,1,1,1,1,1,1,1,1
1,1,8,34,9,34,9,34,8,0,0,0,0,0,0,0,8,34,9,34,9,34,8,1,1
1,1,34,0,0,0,0,0,0,0,0,0,0,0,0,0,0,0,0,0,0,0,34,1,1
1,1,9,0,26,26,26,0,0,0,0,0,0,0,0,0,0,0,0,0,26,0,9,1,1
1,1,34,0,0,0,0,0,9,0,0,0,0,0,0,0,0,0,0,0,26,0,34,1,1
1,1,9,0,26,26,26,0,0,0,0,0,0,0,0,0,0,0,0,0,26,0,9,1,1
1,1,34,0,0,0,0,0,0,0,0,0,0,0,0,0,35,0,0,0,0,0,34,1,1
1,1,8,34,9,34,9,34,8,0,0,0,0,0,0,0,8,34,9,34,9,34,8,1,1
1,1,1,1,1,1,1,1,1,8,0,0,9,0,0,8,1,1,1,1,1,1,1,1,1
1,1,1,1,1,1,1,1,1,34,0,0,0,0,0,34,1,1,1,1,1,1,1,1,1
1,1,1,1,1,1,1,1,1,9,0,26,0,26,0,9,1,1,1,1,1,1,1,1,1
1,1,1,1,1,1,1,1,1,1,0,26,0,26,0,0,1,1,1,1,1,1,1,1,1
1,1,1,1,1,1,1,1,1,9,0,26,0,26,0,9,1,1,1,1,1,1,1,1,1
1,1,1,1,1,1,1,1,1,34,0,0,0,0,0,34,1,1,1,1,1,1,1,1,1
1,1,1,1,1,1,1,1,1,8,34,9,34,9,34,8,1,1,1,1,1,1,1,1,1
1,1,1,1,1,1,1,1,1,1,1,1,1,1,1,1,1,1,1,1,1,1,1,1,1
1,1,1,1,1,1,1,1,1,1,1,1,1,1,1,1,1,1,1,1,1,1,1,1,1
1,1,1,1,1,1,1,1,1,1,1,1,1,1,1,1,1,1,1,1,1,1,1,1,1
1,1,1,1,1,1,1,1,1,1,1,1,1,1,1,1,1,1,1,1,1,1,1,1,1
1,1,1,1,1,1,1,1,1,1,1,1,1,1,1,1,1,1,1,1,1,1,1,1,1
1,1,1,1,1,1,1,1,1,1,1,1,1,1,1,1,1,1,1,1,1,1,1,1,1
1,1,1,1,1,1,1,1,1,1,1,1,1,1,1,1,1,1,1,1,1,1,1,1,1
1,1,1,1,1,1,1,1,1,1,1,1,1,1,1,1,1,1,1,1,1,1,1,1,1
1,1,1,1,1,1,1,1,1,1,1,1,1,1,1,1,1,1,1,1,1,1,1,1,1
1,1,1,1,1,1,1,1,1,1,1,1,1,1,1,1,1,1,1,1,1,1,1,1,1
1,1,1,1,1,1,1,1,1,1,1,1,1,1,1,1,1,1,1,1,1,1,1,1,1
endlayer

layer
1,1,1,1,1,1,1,1,1,1,1,1,1,1,1,1,1,1,1,1,1,1,1,1,1
1,1,1,1,1,1,1,1,1,1,1,1,1,1,1,1,1,1,1,1,1,1,1,1,1
1,1,1,1,1,1,1,1,1,1,1,1,1,1,1,1,1,1,1,1,1,1,1,1,1
1,1,1,1,1,1,1,1,1,1,1,1,1,1,1,1,1,1,1,1,1,1,1,1,1
1,1,1,1,1,1,1,1,1,1,1,1,1,1,1,1,1,1,1,1,1,1,1,1,1
1,1,1,1,1,1,1,1,1,1,1,1,1,1,1,1,1,1,1,1,1,1,1,1,1
1,1,1,1,1,1,1,1,1,1,1,1,1,1,1,1,1,1,1,1,1,1,1,1,1
1,1,1,1,1,1,21,1,1,1,1,1,1,1,1,1,1,1,1,1,1,22,22,1,1
1,1,1,1,1,1,1,1,1,1,1,1,1,0,0,0,1,1,1,1,1,22,0,1,1
1,1,1,1,1,1,1,1,1,1,1,1,1,0,0,0,1,1,1,1,1,22,0,1,1
1,1,1,1,1,1,1,1,1,1,1,1,1,1,0,1,1,1,1,1,1,22,22,1,1
1,1,1,1,1,1,1,1,1,1,1,1,1,1,1,1,1,1,1,1,1,1,1,1,1
1,1,1,1,1,1,1,1,1,1,1,1,1,1,1,1,1,1,1,1,1,1,1,1,1
1,1,1,1,1,1,1,1,1,8,34,9,34,9,34,8,1,1,1,1,1,1,1,1,1
1,1,1,1,1,1,1,1,1,34,0,0,0,0,0,34,1,1,1,1,1,1,1,1,1
1,1,1,1,1,1,1,1,1,9,0,26,0,26,0,9,1,1,1,1,1,1,1,1,1
1,1,1,1,1,1,1,1,1,9,0,26,0,26,0,9,1,1,1,1,1,1,1,1,1
1,1,1,1,1,1,1,1,1,9,0,26,0,26,0,9,1,1,1,1,1,1,1,1,1
1,1,1,1,1,1,1,1,1,34,0,0,0,0,0,34,1,1,1,1,1,1,1,1,1
1,1,1,1,1,1,1,1,1,8,0,0,9,0,0,8,1,1,1,1,1,1,1,1,1
1,1,8,34,9,34,9,34,8,0,0,0,0,0,0,0,8,34,9,34,9,34,8,1,1
1,1,34,0,0,0,0,0,0,0,0,0,0,0,0,0,0,0,0,0,0,0,34,1,1
1,1,9,0,26,26,26,0,0,0,0,0,0,0,0,0,0,0,0,0,0,0,9,1,1
1,1,34,0,0,0,0,0,9,0,0,0,0,0,0,0,0,0,0,0,0,0,34,1,1
1,1,9,0,26,26,26,0,0,0,0,0,0,0,0,0,0,0,0,0,0,0,9,1,1
1,1,34,0,0,0,0,0,0,0,0,0,0,0,0,0,0,0,0,0,0,0,34,1,1
1,1,8,34,9,34,9,34,8,0,0,0,0,0,0,0,8,34,9,34,9,34,8,1,1
1,1,1,1,1,1,1,1,1,8,0,0,9,0,0,8,1,1,1,1,1,1,1,1,1
1,1,1,1,1,1,1,1,1,34,0,0,0,0,0,34,1,1,1,1,1,1,1,1,1
1,1,1,1,1,1,1,1,1,9,0,26,0,26,0,9,1,1,1,1,1,1,1,1,1
1,1,1,1,1,1,1,1,1,9,0,26,0,26,0,9,1,1,1,1,1,1,1,1,1
1,1,1,1,1,1,1,1,1,9,0,26,0,26,0,9,1,1,1,1,1,1,1,1,1
1,1,1,1,1,1,1,1,1,34,0,0,0,0,0,34,1,1,1,1,1,1,1,1,1
1,1,1,1,1,1,1,1,1,8,34,9,34,9,34,8,1,1,1,1,1,1,1,1,1
1,1,1,1,1,1,1,1,1,1,1,1,1,1,1,1,1,1,1,1,1,1,1,1,1
1,1,1,1,1,1,1,1,1,1,1,1,1,1,1,1,1,1,1,1,1,1,1,1,1
1,1,1,1,1,1,1,1,1,1,1,1,1,1,1,1,1,1,1,1,1,1,1,1,1
1,1,1,1,1,1,1,1,1,1,1,1,1,1,1,1,1,1,1,1,1,1,1,1,1
1,1,1,1,1,1,1,1,1,1,1,1,1,1,1,1,1,1,1,1,1,1,1,1,1
1,1,1,1,1,1,1,1,1,1,1,1,1,1,1,1,1,1,1,1,1,1,1,1,1
1,1,1,1,1,1,1,1,1,1,1,1,1,1,1,1,1,1,1,1,1,1,1,1,1
1,1,1,1,1,1,1,1,1,1,1,1,1,1,1,1,1,1,1,1,1,1,1,1,1
1,1,1,1,1,1,1,1,1,1,1,1,1,1,1,1,1,1,1,1,1,1,1,1,1
1,1,1,1,1,1,1,1,1,1,1,1,1,1,1,1,1,1,1,1,1,1,1,1,1
1,1,1,1,1,1,1,1,1,1,1,1,1,1,1,1,1,1,1,1,1,1,1,1,1
endlayer

layer
1,1,1,1,1,1,1,1,1,1,1,1,1,1,1,1,1,1,1,1,1,1,1,1,1
1,1,1,1,1,1,1,1,1,1,1,1,1,1,1,1,1,1,1,1,1,1,1,1,1
1,1,1,1,1,1,1,1,1,1,1,1,1,1,1,1,1,1,1,1,1,1,1,1,1
1,1,1,1,1,1,1,1,1,1,1,1,1,1,1,1,1,1,1,1,1,1,1,1,1
1,1,1,1,1,1,1,1,1,1,1,1,1,1,1,1,1,1,1,1,1,1,1,1,1
1,1,1,1,1,1,1,1,1,1,1,1,1,1,1,1,1,1,1,1,1,1,1,1,1
1,1,1,1,1,1,1,1,1,1,1,1,1,1,1,1,1,1,1,1,1,1,1,1,1
1,1,1,1,1,1,33,1,1,1,1,1,1,0,0,1,1,1,1,1,1,22,22,1,1
1,1,1,1,1,1,1,1,1,1,1,1,0,0,0,0,1,1,1,1,1,22,22,1,1
1,1,1,1,1,1,1,1,1,1,1,1,0,0,0,0,0,1,1,1,1,22,22,1,1
1,1,1,1,1,1,1,1,1,1,1,1,1,0,0,0,1,1,1,1,1,22,22,1,1
1,1,1,1,1,1,1,1,1,1,1,1,1,1,0,1,1,1,1,1,1,1,1,1,1
1,1,1,1,1,1,1,1,1,1,1,1,1,1,1,1,1,1,1,1,1,1,1,1,1
1,1,1,1,1,1,1,1,1,8,34,9,34,9,34,8,1,1,1,1,1,1,1,1,1
1,1,1,1,1,1,1,1,1,34,0,0,0,0,0,34,1,1,1,1,1,1,1,1,1
1,1,1,1,1,1,1,1,1,9,0,0,0,0,0,9,1,1,1,1,1,1,1,1,1
1,1,1,1,1,1,1,1,1,34,0,0,0,0,0,34,1,1,1,1,1,1,1,1,1
1,1,1,1,1,1,1,1,1,9,0,0,0,0,0,9,1,1,1,1,1,1,1,1,1
1,1,1,1,1,1,1,1,1,34,0,0,0,0,0,34,1,1,1,1,1,1,1,1,1
1,1,1,1,1,1,1,1,1,8,0,0,9,0,0,8,1,1,1,1,1,1,1,1,1
1,1,8,34,9,34,9,34,8,0,0,0,0,0,0,0,8,34,9,34,9,34,8,1,1
1,1,34,0,0,0,0,0,0,0,0,0,0,0,0,0,0,0,0,0,0,0,34,1,1
1,1,9,0,0,0,0,0,0,0,0,0,0,0,0,0,0,0,0,0,0,0,9,1,1
1,1,34,0,0,0,0,0,9,0,0,0,0,0,0,0,0,0,0,0,0,0,34,1,1
1,1,9,0,0,0,0,0,0,0,0,0,0,0,0,0,0,0,0,0,0,0,9,1,1
1,1,34,0,0,0,0,0,0,0,0,0,0,0,0,0,0,0,0,0,0,0,34,1,1
1,1,8,34,9,34,9,34,8,0,0,0,0,0,0,0,8,34,9,34,9,34,8,1,1
1,1,1,1,1,1,1,1,1,8,0,0,9,0,0,8,1,1,1,1,1,1,1,1,1
1,1,1,1,1,1,1,1,1,34,0,0,0,0,0,34,1,1,1,1,1,1,1,1,1
1,1,1,1,1,1,1,1,1,9,0,0,0,0,0,9,1,1,1,1,1,1,1,1,1
1,1,1,1,1,1,1,1,1,34,0,0,0,0,0,34,1,1,1,1,1,1,1,1,1
1,1,1,1,1,1,1,1,1,9,0,0,0,0,0,9,1,1,1,1,1,1,1,1,1
1,1,1,1,1,1,1,1,1,34,0,0,0,0,0,34,1,1,1,1,1,1,1,1,1
1,1,1,1,1,1,1,1,1,8,34,9,34,9,34,8,1,1,1,1,1,1,1,1,1
1,1,1,1,1,1,1,1,1,1,1,1,1,1,1,1,1,1,1,1,1,1,1,1,1
1,1,1,1,1,1,1,1,1,1,1,1,1,1,1,1,1,1,1,1,1,1,1,1,1
1,1,1,1,1,1,1,1,1,1,1,1,1,1,1,1,1,1,1,1,1,1,1,1,1
1,1,1,1,1,1,1,1,1,1,1,1,1,1,1,1,1,1,1,1,1,1,1,1,1
1,1,1,1,1,1,1,1,1,1,1,1,1,1,1,1,1,1,1,1,1,1,1,1,1
1,1,1,1,1,1,1,1,1,1,1,1,1,1,1,1,1,1,1,1,1,1,1,1,1
1,1,1,1,1,1,1,1,1,1,1,1,1,1,1,1,1,1,1,1,1,1,1,1,1
1,1,1,1,1,1,1,1,1,1,1,1,1,1,1,1,1,1,1,1,1,1,1,1,1
1,1,1,1,1,1,1,1,1,1,1,1,1,1,1,1,1,1,1,1,1,1,1,1,1
1,1,1,1,1,1,1,1,1,1,1,1,1,1,1,1,1,1,1,1,1,1,1,1,1
1,1,1,1,1,1,1,1,1,1,1,1,1,1,1,1,1,1,1,1,1,1,1,1,1
endlayer

layer
0,0,0,0,0,0,0,0,0,0,0,0,0,0,0,0,0,0,0,0,0,0,0,0,0
0,0,0,0,0,0,0,0,0,0,0,0,0,0,0,0,0,0,0,0,0,0,0,0,0
0,0,0,0,0,0,0,0,0,0,0,0,0,0,0,0,0,0,0,0,0,0,0,0,0
0,0,0,0,0,0,0,0,0,0,0,0,0,0,0,0,0,0,0,0,0,0,0,0,0
0,0,0,0,0,0,0,0,0,0,0,0,0,0,0,0,0,0,0,0,0,0,0,0,0
0,0,0,0,0,0,0,0,0,0,0,0,0,0,0,0,0,0,0,0,0,0,0,0,0
0,0,0,0,0,0,0,0,0,0,0,0,0,0,0,0,0,0,0,0,0,0,0,0,0
0,0,0,0,0,0,21,0,0,0,0,0,0,0,0,0,0,0,0,0,0,0,0,0,0
0,0,0,0,0,0,0,0,0,0,0,0,0,0,0,0,0,0,0,0,0,0,0,0,0
0,0,0,0,0,0,0,0,0,0,0,0,0,0,0,0,0,0,0,0,0,0,0,0,0
0,0,0,0,0,0,0,0,0,0,0,0,0,0,0,0,0,0,0,0,0,0,0,0,0
0,0,0,0,0,0,0,0,0,0,0,0,0,0,0,0,0,0,0,0,0,0,0,0,0
0,0,0,0,0,0,0,0,0,0,0,0,0,0,0,0,0,0,0,0,0,0,0,0,0
0,0,0,0,0,0,0,0,0,8,34,9,34,9,34,8,0,0,0,0,0,0,0,0,0
0,0,0,0,0,0,0,0,0,34,0,0,0,0,0,34,0,0,0,0,0,0,0,0,0
0,0,0,0,0,0,0,0,0,9,0,0,0,0,0,9,0,0,0,0,0,0,0,0,0
0,0,0,0,0,0,0,0,0,34,0,0,0,0,0,34,0,0,0,0,0,0,0,0,0
0,0,0,0,0,0,0,0,0,9,0,0,0,0,0,9,0,0,0,0,0,0,0,0,0
0,0,0,0,0,0,0,0,0,34,0,0,0,0,0,34,0,0,0,0,0,0,0,0,0
0,0,0,0,0,0,0,0,0,8,0,0,9,0,0,8,0,0,0,0,0,0,0,0,0
0,0,8,34,9,34,9,34,8,0,0,0,0,0,0,0,8,34,9,34,9,34,8,0,0
0,0,34,0,0,0,0,0,0,0,0,0,0,0,0,0,0,0,0,0,0,0,34,0,0
0,0,9,0,0,0,0,0,0,0,0,0,0,0,0,0,0,0,0,0,0,0,9,0,0
0,0,34,0,0,0,0,0,9,0,0,0,0,0,0,0,0,0,0,0,0,0,34,0,0
0,0,9,0,0,0,0,0,0,0,0,0,0,0,0,0,0,0,0,0,0,0,9,0,0
0,0,34,0,0,0,0,0,0,0,0,0,0,0,0,0,0,0,0,0,0,0,34,0,0
0,0,8,34,9,34,9,34,8,0,0,0,0,0,0,0,8,34,9,34,9,34,8,0,0
0,0,0,0,0,0,0,0,0,8,0,0,9,0,0,8,0,0,0,0,0,0,0,0,0
0,0,0,0,0,0,0,0,0,34,0,0,0,0,0,34,0,0,0,0,0,0,0,0,0
0,0,0,0,0,0,0,0,0,9,0,0,0,0,0,9,0,0,0,0,0,0,0,0,0
0,0,0,0,0,0,0,0,0,34,0,0,0,0,0,34,0,0,0,0,0,0,0,0,0
0,0,0,0,0,0,0,0,0,9,0,0,0,0,0,9,0,0,0,0,0,0,0,0,0
0,0,0,0,0,0,0,0,0,34,0,0,0,0,0,34,0,0,0,0,0,0,0,0,0
0,0,0,0,0,0,0,0,0,8,34,9,34,9,34,8,0,0,0,0,0,0,0,0,0
0,0,0,0,0,0,0,0,0,0,0,0,0,0,0,0,0,0,0,0,0,0,0,0,0
0,0,0,0,0,0,0,0,0,0,0,0,0,0,0,0,0,0,0,0,0,0,0,0,0
0,0,0,0,0,0,0,0,0,0,0,0,0,0,0,0,0,0,0,0,0,0,0,0,0
0,0,0,0,0,0,0,0,0,0,0,0,0,0,0,0,0,0,0,0,0,0,0,0,0
0,0,0,0,0,0,0,0,0,0,0,0,0,0,0,0,0,0,0,0,0,0,0,0,0
0,0,0,0,0,0,0,0,0,0,0,0,0,0,0,0,0,0,0,0,0,0,0,0,0
0,0,0,0,0,0,0,0,0,0,0,0,0,0,0,0,0,0,0,0,0,0,0,0,0
0,0,0,0,0,0,0,0,0,0,0,0,0,0,0,0,0,0,0,0,0,0,0,0,0
0,0,0,0,0,0,0,0,0,0,0,0,0,0,0,0,0,0,0,0,0,0,0,0,0
0,0,0,0,0,0,0,0,0,0,0,0,0,0,0,0,0,0,0,0,0,0,0,0,0
0,0,0,0,0,0,0,0,0,0,0,0,0,0,0,0,0,0,0,0,0,0,0,0,0
endlayer

layer
0,0,0,0,0,0,0,0,0,0,0,0,0,0,0,0,0,0,0,0,0,0,0,0,0
0,0,0,0,0,0,0,0,0,0,0,0,0,0,0,0,0,0,0,0,0,0,0,0,0
0,0,0,0,0,0,0,0,0,0,0,0,0,0,0,0,0,0,0,0,0,0,0,0,0
0,0,0,0,0,0,0,0,0,0,0,0,0,0,0,0,0,0,0,0,0,0,0,0,0
0,0,0,0,0,0,0,0,0,0,0,0,0,0,0,0,0,0,0,0,0,0,0,0,0
0,0,0,0,0,0,0,0,0,0,0,0,0,0,0,0,0,0,0,0,0,0,0,0,0
0,0,0,0,0,0,0,0,0,0,0,0,0,0,0,0,0,0,0,0,0,0,0,0,0
0,0,0,0,0,0,0,0,0,0,0,0,0,0,0,0,0,0,0,0,0,0,0,0,0
0,0,0,0,0,0,0,0,0,0,0,0,0,0,0,0,0,0,0,0,0,0,0,0,0
0,0,0,0,0,0,0,0,0,0,0,0,0,0,0,0,0,0,0,0,0,0,0,0,0
0,0,0,0,0,0,0,0,0,0,0,0,0,0,0,0,0,0,0,0,0,0,0,0,0
0,0,0,0,0,0,0,0,0,0,0,0,0,0,0,0,0,0,0,0,0,0,0,0,0
0,0,0,0,0,0,0,0,0,0,0,0,0,0,0,0,0,0,0,0,0,0,0,0,0
0,0,0,0,0,0,0,0,0,8,8,8,8,8,8,8,0,0,0,0,0,0,0,0,0
0,0,0,0,0,0,0,0,0,8,12,12,12,12,12,8,0,0,0,0,0,0,0,0,0
0,0,0,0,0,0,0,0,0,8,12,12,12,12,12,8,0,0,0,0,0,0,0,0,0
0,0,0,0,0,0,0,0,0,8,12,12,12,12,12,8,0,0,0,0,0,0,0,0,0
0,0,0,0,0,0,0,0,0,8,12,12,12,12,12,8,0,0,0,0,0,0,0,0,0
0,0,0,0,0,0,0,0,0,8,12,12,12,12,12,8,0,0,0,0,0,0,0,0,0
0,0,0,0,0,0,0,0,0,8,8,8,4,8,8,8,0,0,0,0,0,0,0,0,0
0,0,8,8,8,8,8,8,8,12,12,12,12,12,12,12,8,8,8,8,8,8,8,0,0
0,0,8,12,12,12,12,12,8,12,12,12,12,12,12,12,8,12,12,12,12,12,8,0,0
0,0,8,12,12,12,12,12,8,12,12,0,0,0,12,12,8,12,12,12,12,12,8,0,0
0,0,8,12,12,12,12,12,4,12,12,0,0,0,12,12,8,12,12,12,12,12,8,0,0
0,0,8,12,12,12,12,12,8,12,12,0,0,0,12,12,8,12,12,12,12,12,8,0,0
0,0,8,12,12,12,12,12,8,12,12,12,12,12,12,12,8,12,12,12,12,12,8,0,0
0,0,8,8,8,8,8,8,8,12,12,12,12,12,12,20,8,8,8,8,8,8,8,0,0
0,0,0,0,0,0,0,0,0,8,8,8,2,8,8,8,0,0,0,0,0,0,0,0,0
0,0,0,0,0,0,0,0,0,8,12,12,12,12,12,8,0,0,0,0,0,0,0,0,0
0,0,0,0,0,0,0,0,0,8,12,12,12,12,12,8,0,0,0,0,0,0,0,0,0
0,0,0,0,0,0,0,0,0,8,12,12,12,12,12,8,0,0,0,0,0,0,0,0,0
0,0,0,0,0,0,0,0,0,8,12,12,12,12,12,8,0,0,0,0,0,0,0,0,0
0,0,0,0,0,0,0,0,0,8,12,12,12,12,12,8,0,0,0,0,0,0,0,0,0
0,0,0,0,0,0,0,0,0,8,8,8,8,8,8,8,0,0,0,0,0,0,0,0,0
0,0,0,0,0,0,0,0,0,0,0,0,0,0,0,0,0,0,0,0,0,0,0,0,0
0,0,0,0,0,0,0,0,0,0,0,0,0,0,0,0,0,0,0,0,0,0,0,0,0
0,0,0,0,0,0,0,0,0,0,0,0,0,0,0,0,0,0,0,0,0,0,0,0,0
0,0,0,0,0,0,0,0,0,0,0,0,0,0,0,0,0,0,0,0,0,0,0,0,0
0,0,0,0,0,0,0,0,0,0,0,0,0,0,0,0,0,0,0,0,0,0,0,0,0
0,0,0,0,0,0,0,0,0,0,0,0,0,0,0,0,0,0,0,0,0,0,0,0,0
0,0,0,0,0,0,0,0,0,0,0,0,0,0,0,0,0,0,0,0,0,0,0,0,0
0,0,0,0,0,0,0,0,0,0,0,0,0,0,0,0,0,0,0,0,0,0,0,0,0
0,0,0,0,0,0,0,0,0,0,0,0,0,0,0,0,0,0,0,0,0,0,0,0,0
0,0,0,0,0,0,0,0,0,0,0,0,0,0,0,0,0,0,0,0,0,0,0,0,0
0,0,0,0,0,0,0,0,0,0,0,0,0,0,0,0,0,0,0,0,0,0,0,0,0
endlayer

layer
0,0,0,0,0,0,0,0,0,0,0,0,0,0,0,0,0,0,0,0,0,0,0,0,0
0,0,0,0,0,0,0,0,0,0,0,0,0,0,0,0,0,0,0,0,0,0,0,0,0
0,0,0,0,0,0,0,0,0,0,0,0,0,0,0,0,0,0,0,0,0,0,0,0,0
0,0,0,0,0,0,0,0,0,0,0,0,0,0,0,0,0,0,0,0,0,0,0,0,0
0,0,0,0,0,0,0,0,0,0,0,0,0,0,0,0,0,0,0,0,0,0,0,0,0
0,0,0,0,0,0,0,0,0,0,0,0,0,0,0,0,0,0,0,0,0,0,0,0,0
0,0,0,0,0,0,0,0,0,0,0,0,0,0,0,0,0,0,0,0,0,0,0,0,0
0,0,0,0,0,0,0,0,0,0,0,0,0,0,0,0,0,0,0,0,0,0,0,0,0
0,0,0,0,0,0,0,0,0,0,0,0,0,0,0,0,0,0,0,0,0,0,0,0,0
0,0,0,0,0,0,0,0,0,0,0,0,0,0,0,0,0,0,0,0,0,0,0,0,0
0,0,0,0,0,0,0,0,0,0,0,0,0,0,0,0,0,0,0,0,0,0,0,0,0
0,0,0,0,0,0,0,0,0,0,0,0,0,0,0,0,0,0,0,0,0,0,0,0,0
0,0,0,0,0,0,0,0,0,0,0,0,0,0,0,0,0,0,0,0,0,0,0,0,0
0,0,0,0,0,0,0,0,0,8,34,9,34,9,34,8,0,0,0,0,0,0,0,0,0
0,0,0,0,0,0,0,0,0,34,0,0,0,0,36,34,0,0,0,0,0,0,0,0,0
0,0,0,0,0,0,0,0,0,9,0,26,0,0,37,9,0,0,0,0,0,0,0,0,0
0,0,0,0,0,0,0,0,0,34,0,26,0,0,36,34,0,0,0,0,0,0,0,0,0
0,0,0,0,0,0,0,0,0,9,0,26,0,0,37,9,0,0,0,0,0,0,0,0,0
0,0,0,0,0,0,0,0,0,34,0,0,0,0,36,34,0,0,0,0,0,0,0,0,0
0,0,0,0,0,0,0,0,0,8,0,0,9,0,0,8,0,0,0,0,0,0,0,0,0
0,0,8,34,9,34,9,34,8,0,0,0,0,0,0,0,8,34,9,34,9,34,8,0,0
0,0,34,0,0,0,0,0,0,0,38,38,38,38,38,0,0,0,0,0,0,0,34,0,0
0,0,9,0,26,26,26,0,0,0,38,0,0,0,38,0,0,0,26,26,26,0,9,0,0
0,0,34,0,0,0,0,0,9,0,38,0,0,0,38,0,9,0,0,0,0,0,34,0,0
0,0,9,0,26,26,26,0,0,0,38,0,0,0,38,0,0,0,26,26,26,0,9,0,0
0,0,34,0,0,0,0,0,0,0,38,38,38,38,38,0,0,0,0,0,0,0,34,0,0
0,0,8,34,9,34,9,34,8,0,0,0,0,0,0,0,8,34,9,34,9,34,8,0,0
0,0,0,0,0,0,0,0,0,8,0,0,9,0,0,8,0,0,0,0,0,0,0,0,0
0,0,0,0,0,0,0,0,0,34,0,0,0,0,36,34,0,0,0,0,0,0,0,0,0
0,0,0,0,0,0,0,0,0,9,0,26,0,0,37,9,0,0,0,0,0,0,0,0,0
0,0,0,0,0,0,0,0,0,34,0,26,0,0,36,34,0,0,0,0,0,0,0,0,0
0,0,0,0,0,0,0,0,0,9,0,26,0,0,37,9,0,0,0,0,0,0,0,0,0
0,0,0,0,0,0,0,0,0,34,0,0,0,0,36,34,0,0,0,0,0,0,0,0,0
0,0,0,0,0,0,0,0,0,8,34,9,34,9,34,8,0,0,0,0,0,0,0,0,0
0,0,0,0,0,0,0,0,0,0,0,0,0,0,0,0,0,0,0,0,0,0,0,0,0
0,0,0,0,0,0,0,0,0,0,0,0,0,0,0,0,0,0,0,0,0,0,0,0,0
0,0,0,0,0,0,0,0,0,0,0,0,0,0,0,0,0,0,0,0,0,0,0,0,0
0,0,0,0,0,0,0,0,0,0,0,0,0,0,0,0,0,0,0,0,0,0,0,0,0
0,0,0,0,0,0,0,0,0,0,0,0,0,0,0,0,0,0,0,0,0,0,0,0,0
0,0,0,0,0,0,0,0,0,0,0,0,0,0,0,0,0,0,0,0,0,0,0,0,0
0,0,0,0,0,0,0,0,0,0,0,0,0,0,0,0,0,0,0,0,0,0,0,0,0
0,0,0,0,0,0,0,0,0,0,0,0,0,0,0,0,0,0,0,0,0,0,0,0,0
0,0,0,0,0,0,0,0,0,0,0,0,0,0,0,0,0,0,0,0,0,0,0,0,0
0,0,0,0,0,0,0,0,0,0,0,0,0,0,0,0,0,0,0,0,0,0,0,0,0
0,0,0,0,0,0,0,0,0,0,0,0,0,0,0,0,0,0,0,0,0,0,0,0,0
endlayer

layer
0,0,0,0,0,0,0,0,0,0,0,0,0,0,0,0,0,0,0,0,0,0,0,0,0
0,0,0,0,0,0,0,0,0,0,0,0,0,0,0,0,0,0,0,0,0,0,0,0,0
0,0,0,0,0,0,0,0,0,0,0,0,0,0,0,0,0,0,0,0,0,0,0,0,0
0,0,0,0,0,0,0,0,0,0,0,0,0,0,0,0,0,0,0,0,0,0,0,0,0
0,0,0,0,0,0,0,0,0,0,0,0,0,0,0,0,0,0,0,0,0,0,0,0,0
0,0,0,0,0,0,0,0,0,0,0,0,0,0,0,0,0,0,0,0,0,0,0,0,0
0,0,0,0,0,0,0,0,0,0,0,0,0,0,0,0,0,0,0,0,0,0,0,0,0
0,0,0,0,0,0,0,0,0,0,0,0,0,0,0,0,0,0,0,0,0,0,0,0,0
0,0,0,0,0,0,0,0,0,0,0,0,0,0,0,0,0,0,0,0,0,0,0,0,0
0,0,0,0,0,0,0,0,0,0,0,0,0,0,0,0,0,0,0,0,0,0,0,0,0
0,0,0,0,0,0,0,0,0,0,0,0,0,0,0,0,0,0,0,0,0,0,0,0,0
0,0,0,0,0,0,0,0,0,0,0,0,0,0,0,0,0,0,0,0,0,0,0,0,0
0,0,0,0,0,0,0,0,0,0,0,0,0,0,0,0,0,0,0,0,0,0,0,0,0
0,0,0,0,0,0,0,0,0,8,34,9,34,9,34,8,0,0,0,0,0,0,0,0,0
0,0,0,0,0,0,0,0,0,34,0,0,0,0,0,34,0,0,0,0,0,0,0,0,0
0,0,0,0,0,0,0,0,0,9,0,26,0,0,0,9,0,0,0,0,0,0,0,0,0
0,0,0,0,0,0,0,0,0,34,0,26,0,0,0,34,0,0,0,0,0,0,0,0,0
0,0,0,0,0,0,0,0,0,9,0,26,0,0,0,9,0,0,0,0,0,0,0,0,0
0,0,0,0,0,0,0,0,0,34,0,0,0,0,0,34,0,0,0,0,0,0,0,0,0
0,0,0,0,0,0,0,0,0,8,0,0,9,0,0,8,0,0,0,0,0,0,0,0,0
0,0,8,34,9,34,9,34,8,0,0,0,0,0,0,0,8,34,9,34,9,34,8,0,0
0,0,34,0,0,0,0,0,0,0,0,0,0,0,0,0,0,0,0,0,0,0,34,0,0
0,0,9,0,26,26,26,0,0,0,0,0,0,0,0,0,0,0,26,26,26,0,9,0,0
0,0,34,0,0,0,0,0,9,0,0,0,0,0,0,0,9,0,0,0,0,0,34,0,0
0,0,9,0,26,26,26,0,0,0,0,0,0,0,0,0,0,0,26,26,26,0,9,0,0
0,0,34,0,0,0,0,0,0,0,0,0,0,0,0,0,0,0,0,0,0,0,34,0,0
0,0,8,34,9,34,9,34,8,0,0,0,0,0,0,0,8,34,9,34,9,34,8,0,0
0,0,0,0,0,0,0,0,0,8,0,0,9,0,0,8,0,0,0,0,0,0,0,0,0
0,0,0,0,0,0,0,0,0,34,0,0,0,0,0,34,0,0,0,0,0,0,0,0,0
0,0,0,0,0,0,0,0,0,9,0,26,0,0,0,9,0,0,0,0,0,0,0,0,0
0,0,0,0,0,0,0,0,0,34,0,26,0,0,0,34,0,0,0,0,0,0,0,0,0
0,0,0,0,0,0,0,0,0,9,0,26,0,0,0,9,0,0,0,0,0,0,0,0,0
0,0,0,0,0,0,0,0,0,34,0,0,0,0,0,34,0,0,0,0,0,0,0,0,0
0,0,0,0,0,0,0,0,0,8,34,9,34,9,34,8,0,0,0,0,0,0,0,0,0
0,0,0,0,0,0,0,0,0,0,0,0,0,0,0,0,0,0,0,0,0,0,0,0,0
0,0,0,0,0,0,0,0,0,0,0,0,0,0,0,0,0,0,0,0,0,0,0,0,0
0,0,0,0,0,0,0,0,0,0,0,0,0,0,0,0,0,0,0,0,0,0,0,0,0
0,0,0,0,0,0,0,0,0,0,0,0,0,0,0,0,0,0,0,0,0,0,0,0,0
0,0,0,0,0,0,0,0,0,0,0,0,0,0,0,0,0,0,0,0,0,0,0,0,0
0,0,0,0,0,0,0,0,0,0,0,0,0,0,0,0,0,0,0,0,0,0,0,0,0
0,0,0,0,0,0,0,0,0,0,0,0,0,0,0,0,0,0,0,0,0,0,0,0,0
0,0,0,0,0,0,0,0,0,0,0,0,0,0,0,0,0,0,0,0,0,0,0,0,0
0,0,0,0,0,0,0,0,0,0,0,0,0,0,0,0,0,0,0,0,0,0,0,0,0
0,0,0,0,0,0,0,0,0,0,0,0,0,0,0,0,0,0,0,0,0,0,0,0,0
0,0,0,0,0,0,0,0,0,0,0,0,0,0,0,0,0,0,0,0,0,0,0,0,0
endlayer

layer
0,0,0,0,0,0,0,0,0,0,0,0,0,0,0,0,0,0,0,0,0,0,0,0,0
0,0,0,0,0,0,0,0,0,0,0,0,0,0,0,0,0,0,0,0,0,0,0,0,0
0,0,0,0,0,0,0,0,0,0,0,0,0,0,0,0,0,0,0,0,0,0,0,0,0
0,0,0,0,0,0,0,0,0,0,0,0,0,0,0,0,0,0,0,0,0,0,0,0,0
0,0,0,0,0,0,0,0,0,0,0,0,0,0,0,0,0,0,0,0,0,0,0,0,0
0,0,0,0,0,0,0,0,0,0,0,0,0,0,0,0,0,0,0,0,0,0,0,0,0
0,0,0,0,0,0,0,0,0,0,0,0,0,0,0,0,0,0,0,0,0,0,0,0,0
0,0,0,0,0,0,0,0,0,0,0,0,0,0,0,0,0,0,0,0,0,0,0,0,0
0,0,0,0,0,0,0,0,0,0,0,0,0,0,0,0,0,0,0,0,0,0,0,0,0
0,0,0,0,0,0,0,0,0,0,0,0,0,0,0,0,0,0,0,0,0,0,0,0,0
0,0,0,0,0,0,0,0,0,0,0,0,0,0,0,0,0,0,0,0,0,0,0,0,0
0,0,0,0,0,0,0,0,0,0,0,0,0,0,0,0,0,0,0,0,0,0,0,0,0
0,0,0,0,0,0,0,0,0,0,0,0,0,0,0,0,0,0,0,0,0,0,0,0,0
0,0,0,0,0,0,0,0,0,8,34,9,34,9,34,8,0,0,0,0,0,0,0,0,0
0,0,0,0,0,0,0,0,0,34,0,0,0,0,0,34,0,0,0,0,0,0,0,0,0
0,0,0,0,0,0,0,0,0,9,0,0,0,0,0,9,0,0,0,0,0,0,0,0,0
0,0,0,0,0,0,0,0,0,34,0,0,0,0,0,34,0,0,0,0,0,0,0,0,0
0,0,0,0,0,0,0,0,0,9,0,0,0,0,0,9,0,0,0,0,0,0,0,0,0
0,0,0,0,0,0,0,0,0,34,0,0,0,0,0,34,0,0,0,0,0,0,0,0,0
0,0,0,0,0,0,0,0,0,8,0,0,9,0,0,8,0,0,0,0,0,0,0,0,0
0,0,8,34,9,34,9,34,8,0,0,0,0,0,0,0,8,34,9,34,9,34,8,0,0
0,0,34,0,0,0,0,0,0,0,0,0,0,0,0,0,0,0,0,0,0,0,34,0,0
0,0,9,0,0,0,0,0,0,0,0,0,0,0,0,0,0,0,0,0,0,0,9,0,0
0,0,34,0,0,0,0,0,9,0,0,0,0,0,0,0,9,0,0,0,0,0,34,0,0
0,0,9,0,0,0,0,0,0,0,0,0,0,0,0,0,0,0,0,0,0,0,9,0,0
0,0,34,0,0,0,0,0,0,0,0,0,0,0,0,0,0,0,0,0,0,0,34,0,0
0,0,8,34,9,34,9,34,8,0,0,0,0,0,0,0,8,34,9,34,9,34,8,0,0
0,0,0,0,0,0,0,0,0,8,0,0,9,0,0,8,0,0,0,0,0,0,0,0,0
0,0,0,0,0,0,0,0,0,34,0,0,0,0,0,34,0,0,0,0,0,0,0,0,0
0,0,0,0,0,0,0,0,0,9,0,0,0,0,0,9,0,0,0,0,0,0,0,0,0
0,0,0,0,0,0,0,0,0,34,0,0,0,0,0,34,0,0,0,0,0,0,0,0,0
0,0,0,0,0,0,0,0,0,9,0,0,0,0,0,9,0,0,0,0,0,0,0,0,0
0,0,0,0,0,0,0,0,0,34,0,0,0,0,0,34,0,0,0,0,0,0,0,0,0
0,0,0,0,0,0,0,0,0,8,34,9,34,9,34,8,0,0,0,0,0,0,0,0,0
0,0,0,0,0,0,0,0,0,0,0,0,0,0,0,0,0,0,0,0,0,0,0,0,0
0,0,0,0,0,0,0,0,0,0,0,0,0,0,0,0,0,0,0,0,0,0,0,0,0
0,0,0,0,0,0,0,0,0,0,0,0,0,0,0,0,0,0,0,0,0,0,0,0,0
0,0,0,0,0,0,0,0,0,0,0,0,0,0,0,0,0,0,0,0,0,0,0,0,0
0,0,0,0,0,0,0,0,0,0,0,0,0,0,0,0,0,0,0,0,0,0,0,0,0
0,0,0,0,0,0,0,0,0,0,0,0,0,0,0,0,0,0,0,0,0,0,0,0,0
0,0,0,0,0,0,0,0,0,0,0,0,0,0,0,0,0,0,0,0,0,0,0,0,0
0,0,0,0,0,0,0,0,0,0,0,0,0,0,0,0,0,0,0,0,0,0,0,0,0
0,0,0,0,0,0,0,0,0,0,0,0,0,0,0,0,0,0,0,0,0,0,0,0,0
0,0,0,0,0,0,0,0,0,0,0,0,0,0,0,0,0,0,0,0,0,0,0,0,0
0,0,0,0,0,0,0,0,0,0,0,0,0,0,0,0,0,0,0,0,0,0,0,0,0
endlayer

layer
0,0,0,0,0,0,0,0,0,0,0,0,0,0,0,0,0,0,0,0,0,0,0,0,0
0,0,0,0,0,0,0,0,0,0,0,0,0,0,0,0,0,0,0,0,0,0,0,0,0
0,0,0,0,0,0,0,0,0,0,0,0,0,0,0,0,0,0,0,0,0,0,0,0,0
0,0,0,0,0,0,0,0,0,0,0,0,0,0,0,0,0,0,0,0,0,0,0,0,0
0,0,0,0,0,0,0,0,0,0,0,0,0,0,0,0,0,0,0,0,0,0,0,0,0
0,0,0,0,0,0,0,0,0,0,0,0,0,0,0,0,0,0,0,0,0,0,0,0,0
0,0,0,0,0,0,0,0,0,0,0,0,0,0,0,0,0,0,0,0,0,0,0,0,0
0,0,0,0,0,0,0,0,0,0,0,0,0,0,0,0,0,0,0,0,0,0,0,0,0
0,0,0,0,0,0,0,0,0,0,0,0,0,0,0,0,0,0,0,0,0,0,0,0,0
0,0,0,0,0,0,0,0,0,0,0,0,0,0,0,0,0,0,0,0,0,0,0,0,0
0,0,0,0,0,0,0,0,0,0,0,0,0,0,0,0,0,0,0,0,0,0,0,0,0
0,0,0,0,0,0,0,0,0,0,0,0,0,0,0,0,0,0,0,0,0,0,0,0,0
0,0,0,0,0,0,0,0,0,0,0,0,0,0,0,0,0,0,0,0,0,0,0,0,0
0,0,0,0,0,0,0,0,0,8,34,9,34,9,34,8,0,0,0,0,0,0,0,0,0
0,0,0,0,0,0,0,0,0,34,0,0,0,0,0,34,0,0,0,0,0,0,0,0,0
0,0,0,0,0,0,0,0,0,9,0,0,0,0,0,9,0,0,0,0,0,0,0,0,0
0,0,0,0,0,0,0,0,0,34,0,0,0,0,0,34,0,0,0,0,0,0,0,0,0
0,0,0,0,0,0,0,0,0,9,0,0,0,0,0,9,0,0,0,0,0,0,0,0,0
0,0,0,0,0,0,0,0,0,34,0,0,0,0,0,34,0,0,0,0,0,0,0,0,0
0,0,0,0,0,0,0,0,0,8,0,0,9,0,0,8,0,0,0,0,0,0,0,0,0
0,0,8,34,9,34,9,34,8,0,0,0,0,0,0,0,8,34,9,34,9,34,8,0,0
0,0,34,0,0,0,0,0,0,0,0,0,0,0,0,0,0,0,0,0,0,0,34,0,0
0,0,9,0,0,0,0,0,0,0,0,0,0,0,0,0,0,0,0,0,0,0,9,0,0
0,0,34,0,0,0,0,0,9,0,0,0,0,0,0,0,9,0,0,0,0,0,34,0,0
0,0,9,0,0,0,0,0,0,0,0,0,0,0,0,0,0,0,0,0,0,0,9,0,0
0,0,34,0,0,0,0,0,0,0,0,0,0,0,0,0,0,0,0,0,0,0,34,0,0
0,0,8,34,9,34,9,34,8,0,0,0,0,0,0,0,8,34,9,34,9,34,8,0,0
0,0,0,0,0,0,0,0,0,8,0,0,9,0,0,8,0,0,0,0,0,0,0,0,0
0,0,0,0,0,0,0,0,0,34,0,0,0,0,0,34,0,0,0,0,0,0,0,0,0
0,0,0,0,0,0,0,0,0,9,0,0,0,0,0,9,0,0,0,0,0,0,0,0,0
0,0,0,0,0,0,0,0,0,34,0,0,0,0,0,34,0,0,0,0,0,0,0,0,0
0,0,0,0,0,0,0,0,0,9,0,0,0,0,0,9,0,0,0,0,0,0,0,0,0
0,0,0,0,0,0,0,0,0,34,0,0,0,0,0,34,0,0,0,0,0,0,0,0,0
0,0,0,0,0,0,0,0,0,8,34,9,34,9,34,8,0,0,0,0,0,0,0,0,0
0,0,0,0,0,0,0,0,0,0,0,0,0,0,0,0,0,0,0,0,0,0,0,0,0
0,0,0,0,0,0,0,0,0,0,0,0,0,0,0,0,0,0,0,0,0,0,0,0,0
0,0,0,0,0,0,0,0,0,0,0,0,0,0,0,0,0,0,0,0,0,0,0,0,0
0,0,0,0,0,0,0,0,0,0,0,0,0,0,0,0,0,0,0,0,0,0,0,0,0
0,0,0,0,0,0,0,0,0,0,0,0,0,0,0,0,0,0,0,0,0,0,0,0,0
0,0,0,0,0,0,0,0,0,0,0,0,0,0,0,0,0,0,0,0,0,0,0,0,0
0,0,0,0,0,0,0,0,0,0,0,0,0,0,0,0,0,0,0,0,0,0,0,0,0
0,0,0,0,0,0,0,0,0,0,0,0,0,0,0,0,0,0,0,0,0,0,0,0,0
0,0,0,0,0,0,0,0,0,0,0,0,0,0,0,0,0,0,0,0,0,0,0,0,0
0,0,0,0,0,0,0,0,0,0,0,0,0,0,0,0,0,0,0,0,0,0,0,0,0
0,0,0,0,0,0,0,0,0,0,0,0,0,0,0,0,0,0,0,0,0,0,0,0,0
endlayer

layer
0,0,0,0,0,0,0,0,0,0,0,0,0,0,0,0,0,0,0,0,0,0,0,0,0
0,0,0,0,0,0,0,0,0,0,0,0,0,0,0,0,0,0,0,0,0,0,0,0,0
0,0,0,0,0,0,0,0,0,0,0,0,0,0,0,0,0,0,0,0,0,0,0,0,0
0,0,0,0,0,0,0,0,0,0,0,0,0,0,0,0,0,0,0,0,0,0,0,0,0
0,0,0,0,0,0,0,0,0,0,0,0,0,0,0,0,0,0,0,0,0,0,0,0,0
0,0,0,0,0,0,0,0,0,0,0,0,0,0,0,0,0,0,0,0,0,0,0,0,0
0,0,0,0,0,0,0,0,0,0,0,0,0,0,0,0,0,0,0,0,0,0,0,0,0
0,0,0,0,0,0,0,0,0,0,0,0,0,0,0,0,0,0,0,0,0,0,0,0,0
0,0,0,0,0,0,0,0,0,0,0,0,0,0,0,0,0,0,0,0,0,0,0,0,0
0,0,0,0,0,0,0,0,0,0,0,0,0,0,0,0,0,0,0,0,0,0,0,0,0
0,0,0,0,0,0,0,0,0,0,0,0,0,0,0,0,0,0,0,0,0,0,0,0,0
0,0,0,0,0,0,0,0,0,0,0,0,0,0,0,0,0,0,0,0,0,0,0,0,0
0,0,0,0,0,0,0,0,0,0,0,0,0,0,0,0,0,0,0,0,0,0,0,0,0
0,0,0,0,0,0,0,0,0,8,8,8,8,8,8,8,0,0,0,0,0,0,0,0,0
0,0,0,0,0,0,0,0,0,8,9,9,9,9,9,8,0,0,0,0,0,0,0,0,0
0,0,0,0,0,0,0,0,0,8,9,39,39,39,9,8,0,0,0,0,0,0,0,0,0
0,0,0,0,0,0,0,0,0,8,9,39,39,39,9,8,0,0,0,0,0,0,0,0,0
0,0,0,0,0,0,0,0,0,8,9,9,9,9,9,8,0,0,0,0,0,0,0,0,0
0,0,0,0,0,0,0,0,0,8,8,8,8,8,8,8,0,0,0,0,0,0,0,0,0
0,0,0,0,0,0,0,0,0,8,0,0,9,0,0,8,0,0,0,0,0,0,0,0,0
0,0,8,8,8,8,8,8,8,0,0,0,0,0,0,0,8,8,8,8,8,8,8,0,0
0,0,8,9,9,9,9,8,0,0,0,0,0,0,0,0,0,8,9,9,9,9,8,0,0
0,0,8,9,39,39,9,8,0,0,0,0,0,0,0,0,0,8,9,39,39,9,8,0,0
0,0,8,9,39,39,9,8,9,0,0,0,0,0,0,0,9,8,9,39,39,9,8,0,0
0,0,8,9,39,39,9,8,0,0,0,0,0,0,0,0,0,8,9,39,39,9,8,0,0
0,0,8,9,9,9,9,8,0,0,0,0,0,0,0,0,0,8,9,9,9,9,8,0,0
0,0,8,8,8,8,8,8,8,0,0,0,0,0,0,0,8,8,8,8,8,8,8,0,0
0,0,0,0,0,0,0,0,0,8,0,0,9,0,0,8,0,0,0,0,0,0,0,0,0
0,0,0,0,0,0,0,0,0,8,8,8,8,8,8,8,0,0,0,0,0,0,0,0,0
0,0,0,0,0,0,0,0,0,8,9,9,9,9,9,8,0,0,0,0,0,0,0,0,0
0,0,0,0,0,0,0,0,0,8,9,39,39,39,9,8,0,0,0,0,0,0,0,0,0
0,0,0,0,0,0,0,0,0,8,9,39,39,39,9,8,0,0,0,0,0,0,0,0,0
0,0,0,0,0,0,0,0,0,8,9,9,9,9,9,8,0,0,0,0,0,0,0,0,0
0,0,0,0,0,0,0,0,0,8,8,8,8,8,8,8,0,0,0,0,0,0,0,0,0
0,0,0,0,0,0,0,0,0,0,0,0,0,0,0,0,0,0,0,0,0,0,0,0,0
0,0,0,0,0,0,0,0,0,0,0,0,0,0,0,0,0,0,0,0,0,0,0,0,0
0,0,0,0,0,0,0,0,0,0,0,0,0,0,0,0,0,0,0,0,0,0,0,0,0
0,0,0,0,0,0,0,0,0,0,0,0,0,0,0,0,0,0,0,0,0,0,0,0,0
0,0,0,0,0,0,0,0,0,0,0,0,0,0,0,0,0,0,0,0,0,0,0,0,0
0,0,0,0,0,0,0,0,0,0,0,0,0,0,0,0,0,0,0,0,0,0,0,0,0
0,0,0,0,0,0,0,0,0,0,0,0,0,0,0,0,0,0,0,0,0,0,0,0,0
0,0,0,0,0,0,0,0,0,0,0,0,0,0,0,0,0,0,0,0,0,0,0,0,0
0,0,0,0,0,0,0,0,0,0,0,0,0,0,0,0,0,0,0,0,0,0,0,0,0
0,0,0,0,0,0,0,0,0,0,0,0,0,0,0,0,0,0,0,0,0,0,0,0,0
0,0,0,0,0,0,0,0,0,0,0,0,0,0,0,0,0,0,0,0,0,0,0,0,0
endlayer

layer
0,0,0,0,0,0,0,0,0,0,0,0,0,0,0,0,0,0,0,0,0,0,0,0,0
0,0,0,0,0,0,0,0,0,0,0,0,0,0,0,0,0,0,0,0,0,0,0,0,0
0,0,0,0,0,0,0,0,0,0,0,0,0,0,0,0,0,0,0,0,0,0,0,0,0
0,0,0,0,0,0,0,0,0,0,0,0,0,0,0,0,0,0,0,0,0,0,0,0,0
0,0,0,0,0,0,0,0,0,0,0,0,0,0,0,0,0,0,0,0,0,0,0,0,0
0,0,0,0,0,0,0,0,0,0,0,0,0,0,0,0,0,0,0,0,0,0,0,0,0
0,0,0,0,0,0,0,0,0,0,0,0,0,0,0,0,0,0,0,0,0,0,0,0,0
0,0,0,0,0,0,0,0,0,0,0,0,0,0,0,0,0,0,0,0,0,0,0,0,0
0,0,0,0,0,0,0,0,0,0,0,0,0,0,0,0,0,0,0,0,0,0,0,0,0
0,0,0,0,0,0,0,0,0,0,0,0,0,0,0,0,0,0,0,0,0,0,0,0,0
0,0,0,0,0,0,0,0,0,0,0,0,0,0,0,0,0,0,0,0,0,0,0,0,0
0,0,0,0,0,0,0,0,0,0,0,0,0,0,0,0,0,0,0,0,0,0,0,0,0
0,0,0,0,0,0,0,0,0,0,0,0,0,0,0,0,0,0,0,0,0,0,0,0,0
0,0,0,0,0,0,0,0,0,0,0,0,0,0,0,0,0,0,0,0,0,0,0,0,0
0,0,0,0,0,0,0,0,0,0,0,0,0,0,0,0,0,0,0,0,0,0,0,0,0
0,0,0,0,0,0,0,0,0,0,0,0,0,0,0,0,0,0,0,0,0,0,0,0,0
0,0,0,0,0,0,0,0,0,0,0,0,0,0,0,0,0,0,0,0,0,0,0,0,0
0,0,0,0,0,0,0,0,0,0,0,0,0,0,0,0,0,0,0,0,0,0,0,0,0
0,0,0,0,0,0,0,0,0,0,0,0,0,0,0,0,0,0,0,0,0,0,0,0,0
0,0,0,0,0,0,0,0,0,8,8,8,8,8,8,8,0,0,0,0,0,0,0,0,0
0,0,0,0,0,0,0,0,8,0,0,0,0,0,0,0,8,0,0,0,0,0,0,0,0
0,0,0,0,0,0,0,0,8,0,0,0,0,0,0,0,8,0,0,0,0,0,0,0,0
0,0,0,0,0,0,0,0,8,0,0,0,0,0,0,0,8,0,0,0,0,0,0,0,0
0,0,0,0,0,0,0,0,8,0,0,0,0,0,0,0,8,0,0,0,0,0,0,0,0
0,0,0,0,0,0,0,0,8,0,0,0,0,0,0,0,8,0,0,0,0,0,0,0,0
0,0,0,0,0,0,0,0,8,0,0,0,0,0,0,0,8,0,0,0,0,0,0,0,0
0,0,0,0,0,0,0,0,8,0,0,0,0,0,0,0,8,0,0,0,0,0,0,0,0
0,0,0,0,0,0,0,0,0,8,8,8,8,8,8,8,0,0,0,0,0,0,0,0,0
0,0,0,0,0,0,0,0,0,0,0,0,0,0,0,0,0,0,0,0,0,0,0,0,0
0,0,0,0,0,0,0,0,0,0,0,0,0,0,0,0,0,0,0,0,0,0,0,0,0
0,0,0,0,0,0,0,0,0,0,0,0,0,0,0,0,0,0,0,0,0,0,0,0,0
0,0,0,0,0,0,0,0,0,0,0,0,0,0,0,0,0,0,0,0,0,0,0,0,0
0,0,0,0,0,0,0,0,0,0,0,0,0,0,0,0,0,0,0,0,0,0,0,0,0
0,0,0,0,0,0,0,0,0,0,0,0,0,0,0,0,0,0,0,0,0,0,0,0,0
0,0,0,0,0,0,0,0,0,0,0,0,0,0,0,0,0,0,0,0,0,0,0,0,0
0,0,0,0,0,0,0,0,0,0,0,0,0,0,0,0,0,0,0,0,0,0,0,0,0
0,0,0,0,0,0,0,0,0,0,0,0,0,0,0,0,0,0,0,0,0,0,0,0,0
0,0,0,0,0,0,0,0,0,0,0,0,0,0,0,0,0,0,0,0,0,0,0,0,0
0,0,0,0,0,0,0,0,0,0,0,0,0,0,0,0,0,0,0,0,0,0,0,0,0
0,0,0,0,0,0,0,0,0,0,0,0,0,0,0,0,0,0,0,0,0,0,0,0,0
0,0,0,0,0,0,0,0,0,0,0,0,0,0,0,0,0,0,0,0,0,0,0,0,0
0,0,0,0,0,0,0,0,0,0,0,0,0,0,0,0,0,0,0,0,0,0,0,0,0
0,0,0,0,0,0,0,0,0,0,0,0,0,0,0,0,0,0,0,0,0,0,0,0,0
0,0,0,0,0,0,0,0,0,0,0,0,0,0,0,0,0,0,0,0,0,0,0,0,0
0,0,0,0,0,0,0,0,0,0,0,0,0,0,0,0,0,0,0,0,0,0,0,0,0
endlayer

layer
0,0,0,0,0,0,0,0,0,0,0,0,0,0,0,0,0,0,0,0,0,0,0,0,0
0,0,0,0,0,0,0,0,0,0,0,0,0,0,0,0,0,0,0,0,0,0,0,0,0
0,0,0,0,0,0,0,0,0,0,0,0,0,0,0,0,0,0,0,0,0,0,0,0,0
0,0,0,0,0,0,0,0,0,0,0,0,0,0,0,0,0,0,0,0,0,0,0,0,0
0,0,0,0,0,0,0,0,0,0,0,0,0,0,0,0,0,0,0,0,0,0,0,0,0
0,0,0,0,0,0,0,0,0,0,0,0,0,0,0,0,0,0,0,0,0,0,0,0,0
0,0,0,0,0,0,0,0,0,0,0,0,0,0,0,0,0,0,0,0,0,0,0,0,0
0,0,0,0,0,0,0,0,0,0,0,0,0,0,0,0,0,0,0,0,0,0,0,0,0
0,0,0,0,0,0,0,0,0,0,0,0,0,0,0,0,0,0,0,0,0,0,0,0,0
0,0,0,0,0,0,0,0,0,0,0,0,0,0,0,0,0,0,0,0,0,0,0,0,0
0,0,0,0,0,0,0,0,0,0,0,0,0,0,0,0,0,0,0,0,0,0,0,0,0
0,0,0,0,0,0,0,0,0,0,0,0,0,0,0,0,0,0,0,0,0,0,0,0,0
0,0,0,0,0,0,0,0,0,0,0,0,0,0,0,0,0,0,0,0,0,0,0,0,0
0,0,0,0,0,0,0,0,0,0,0,0,0,0,0,0,0,0,0,0,0,0,0,0,0
0,0,0,0,0,0,0,0,0,0,0,0,0,0,0,0,0,0,0,0,0,0,0,0,0
0,0,0,0,0,0,0,0,0,0,0,0,0,0,0,0,0,0,0,0,0,0,0,0,0
0,0,0,0,0,0,0,0,0,0,0,0,0,0,0,0,0,0,0,0,0,0,0,0,0
0,0,0,0,0,0,0,0,0,0,0,0,0,0,0,0,0,0,0,0,0,0,0,0,0
0,0,0,0,0,0,0,0,0,0,0,0,0,0,0,0,0,0,0,0,0,0,0,0,0
0,0,0,0,0,0,0,0,0,0,0,0,0,0,0,0,0,0,0,0,0,0,0,0,0
0,0,0,0,0,0,0,0,0,9,9,9,9,9,9,9,0,0,0,0,0,0,0,0,0
0,0,0,0,0,0,0,0,0,9,39,39,39,39,39,9,0,0,0,0,0,0,0,0,0
0,0,0,0,0,0,0,0,0,9,39,39,39,39,39,9,0,0,0,0,0,0,0,0,0
0,0,0,0,0,0,0,0,0,9,39,39,39,39,39,9,0,0,0,0,0,0,0,0,0
0,0,0,0,0,0,0,0,0,9,39,39,39,39,39,9,0,0,0,0,0,0,0,0,0
0,0,0,0,0,0,0,0,0,9,39,39,39,39,39,9,0,0,0,0,0,0,0,0,0
0,0,0,0,0,0,0,0,0,9,9,9,9,9,9,9,0,0,0,0,0,0,0,0,0
0,0,0,0,0,0,0,0,0,0,0,0,0,0,0,0,0,0,0,0,0,0,0,0,0
0,0,0,0,0,0,0,0,0,0,0,0,0,0,0,0,0,0,0,0,0,0,0,0,0
0,0,0,0,0,0,0,0,0,0,0,0,0,0,0,0,0,0,0,0,0,0,0,0,0
0,0,0,0,0,0,0,0,0,0,0,0,0,0,0,0,0,0,0,0,0,0,0,0,0
0,0,0,0,0,0,0,0,0,0,0,0,0,0,0,0,0,0,0,0,0,0,0,0,0
0,0,0,0,0,0,0,0,0,0,0,0,0,0,0,0,0,0,0,0,0,0,0,0,0
0,0,0,0,0,0,0,0,0,0,0,0,0,0,0,0,0,0,0,0,0,0,0,0,0
0,0,0,0,0,0,0,0,0,0,0,0,0,0,0,0,0,0,0,0,0,0,0,0,0
0,0,0,0,0,0,0,0,0,0,0,0,0,0,0,0,0,0,0,0,0,0,0,0,0
0,0,0,0,0,0,0,0,0,0,0,0,0,0,0,0,0,0,0,0,0,0,0,0,0
0,0,0,0,0,0,0,0,0,0,0,0,0,0,0,0,0,0,0,0,0,0,0,0,0
0,0,0,0,0,0,0,0,0,0,0,0,0,0,0,0,0,0,0,0,0,0,0,0,0
0,0,0,0,0,0,0,0,0,0,0,0,0,0,0,0,0,0,0,0,0,0,0,0,0
0,0,0,0,0,0,0,0,0,0,0,0,0,0,0,0,0,0,0,0,0,0,0,0,0
0,0,0,0,0,0,0,0,0,0,0,0,0,0,0,0,0,0,0,0,0,0,0,0,0
0,0,0,0,0,0,0,0,0,0,0,0,0,0,0,0,0,0,0,0,0,0,0,0,0
0,0,0,0,0,0,0,0,0,0,0,0,0,0,0,0,0,0,0,0,0,0,0,0,0
0,0,0,0,0,0,0,0,0,0,0,0,0,0,0,0,0,0,0,0,0,0,0,0,0
endlayer

