# Converted from schematic
# THIS TEMPLATE USES DEFAULTS!  Please edit for corrections.
# If you need help, consult template_rules.txt

weight=3
embed_into_distance=5
acceptable_target_blocks=1,2,3,12,13,250
dimensions=19,24,13
allowable_overhang=0
max_cut_in=2
cut_in_buffer=1
max_leveling=2
leveling_buffer=1
preserve_water=0
preserve_lava=0
preserve_plants=0


rule1=0,100,300
rule2=0,100,3134-10
rule3=0,100,2843-13
rule4=0,50,3501,3501,3501,3502,3502,3502,3502,3503,3503,3503,1474-7
rule5=0,100,1477-2
rule6=0,100,2843-14,2843-14,2843-14,2843-14,2843
rule7=0,100,2843
rule8=0,100,308,308,308,308,308,308,313,313,314,327
rule9=0,100,1473-0
rule10=0,95,309
rule11=0,100,3400-7,3504,3505,3506
rule12=0,66,3225-3
rule13=0,100,1477-0
rule14=0,100,3501,3501,3501,3502,3502,3502,3502,3503,3503,3503,1474-1
rule15=0,95,2835-2,2835-2,2835-2,2835-2,2835-2,2835-2,2835-2,2835-1,2835-1,2835-0
rule16=0,95,300
rule17=0,100,3134,3134,3134,3134-8,3134-2
rule18=0,100,2761-4
rule19=0,100,2838-6
rule20=0,100,2843-12
rule21=1,100,3538
rule22=1,85,3400-7,3504,3505,3506
rule23=1,75,3400-7,3504,3505,3506
rule24=1,65,3400-7,3504,3505,3506
rule25=1,50,3400-7,3504,3505,3506
rule26=1,25,3400-7,3504,3505,3506
rule27=1,15,3400-7,3504,3505,3506


layer
1,1,1,1,1,1,1,1,1,1,1,1,1
1,1,1,1,1,1,1,1,1,1,1,1,1
1,1,1,1,1,1,1,1,1,1,1,1,1
1,1,1,1,1,1,1,1,1,1,1,1,1
1,1,1,1,1,1,1,1,1,1,1,1,1
1,1,1,1,1,1,1,1,1,1,1,1,1
1,1,1,1,1,1,1,1,1,1,1,1,1
1,1,1,1,1,1,1,1,1,1,1,1,1
1,1,1,1,1,1,1,1,1,1,1,1,1
1,1,1,1,1,1,1,1,1,1,1,1,1
1,1,1,1,1,1,1,1,1,1,1,1,1
1,1,1,1,1,1,1,1,1,1,1,1,1
1,1,1,1,1,1,1,1,1,1,1,1,1
1,1,1,1,1,1,1,1,1,1,1,1,1
1,1,1,1,1,1,1,1,1,1,1,1,1
1,1,1,1,1,1,1,1,1,1,1,1,1
1,1,1,1,1,1,1,1,1,1,1,1,1
1,1,1,1,1,1,1,1,1,1,1,1,1
1,1,1,1,1,1,1,1,1,1,1,1,1
1,1,1,1,1,1,1,1,1,1,1,1,1
1,1,1,1,1,1,1,1,1,1,1,1,1
1,1,1,1,1,1,1,1,1,1,1,1,1
1,1,1,1,1,1,1,1,1,1,1,1,1
1,1,1,1,1,1,1,1,1,1,1,1,1
endlayer

layer
2,2,2,2,2,2,2,2,2,2,2,2,2
2,2,2,2,2,2,2,2,2,2,2,2,2
2,2,3,3,3,3,3,3,3,3,3,2,2
2,2,3,3,3,3,3,3,3,3,3,2,2
2,2,3,3,5,3,4,4,1,3,3,2,2
2,2,3,3,3,3,4,4,4,3,3,2,2
2,2,3,3,3,3,4,4,4,3,3,2,2
2,2,3,3,3,3,3,3,3,3,3,2,2
2,2,3,3,3,3,3,1,3,3,3,2,2
2,2,3,3,3,3,3,3,3,3,3,2,2
2,2,3,3,3,3,3,3,3,3,3,2,2
2,2,3,3,3,3,3,3,3,3,3,2,2
2,2,3,3,3,3,3,3,3,3,3,2,2
2,2,3,3,3,3,3,3,8,3,3,2,2
2,1,3,3,3,3,3,3,3,3,3,2,2
1,2,3,3,3,3,3,3,3,3,3,2,2
2,1,3,3,3,3,3,3,3,3,3,2,2
1,2,3,3,3,3,3,3,3,3,3,2,2
1,1,3,3,3,3,3,3,3,3,3,2,2
1,2,3,3,3,3,3,3,3,3,3,2,2
1,1,3,1,3,1,3,3,3,3,3,2,2
1,1,1,3,3,3,3,3,3,3,3,2,2
1,1,1,2,1,1,2,2,2,2,2,2,2
2,1,2,2,1,2,2,2,2,2,2,2,2
endlayer

layer
1,1,1,1,1,1,1,1,1,1,1,1,1
1,1,1,1,1,1,1,1,1,1,1,1,1
1,1,6,7,6,6,7,6,6,6,6,1,1
1,1,6,0,0,0,4,4,1,8,7,1,1
1,1,6,0,0,14,0,1,1,4,6,1,1
1,1,6,0,1,0,0,0,0,4,6,1,1
1,1,6,1,0,0,0,0,0,9,6,1,1
1,1,1,1,0,0,4,0,0,10,6,1,1
1,1,1,1,1,0,0,0,0,0,6,1,1
1,1,6,1,0,0,0,0,0,0,6,1,1
1,1,6,1,1,0,0,0,0,0,6,1,1
1,1,6,1,1,0,0,0,0,0,6,1,1
1,1,6,0,0,0,0,11,11,11,6,1,1
1,1,6,0,0,0,13,11,11,11,6,1,1
1,1,6,0,0,0,0,11,11,11,6,1,1
1,0,6,0,0,0,0,11,11,11,6,1,1
1,1,6,0,0,11,0,0,12,11,6,1,1
1,0,6,0,0,11,0,0,0,11,7,1,1
1,1,6,1,1,11,1,0,12,11,6,1,1
1,0,6,1,1,11,11,1,11,11,6,1,1
1,1,6,1,1,1,1,1,1,1,6,1,1
1,1,1,6,7,1,6,6,1,6,6,1,1
1,1,1,1,1,1,1,1,1,1,1,1,1
1,1,1,1,1,1,1,1,1,1,1,1,1
endlayer

layer
1,1,1,1,1,1,1,1,1,1,1,1,1
1,1,1,1,1,1,1,1,1,1,1,1,1
1,1,7,15,12,15,12,15,1,15,6,1,1
1,1,15,0,0,0,0,1,1,1,15,1,1
1,1,12,0,0,0,0,0,0,1,12,1,1
1,1,12,0,0,0,0,0,0,0,12,1,1
1,1,15,0,0,0,0,0,0,0,15,1,1
1,1,1,0,0,0,0,0,0,0,12,1,1
1,1,1,1,0,0,0,0,0,0,12,1,1
1,1,15,0,0,0,0,0,0,0,15,1,1
1,1,12,1,0,0,0,0,0,0,12,1,1
1,1,12,0,0,0,0,0,0,0,12,1,1
1,1,15,0,0,0,0,0,0,0,15,1,1
1,1,7,0,0,0,0,22,0,22,6,1,1
1,1,15,0,0,0,0,22,22,0,15,1,1
1,0,0,0,0,0,0,12,0,12,12,1,1
1,1,15,0,0,12,0,0,0,0,15,1,1
1,0,0,0,0,12,0,0,0,0,12,1,1
1,1,15,0,0,12,0,0,0,0,15,1,1
1,0,12,1,0,0,1,0,0,1,12,1,1
1,1,15,1,1,1,1,1,0,0,15,1,1
1,1,1,15,1,15,12,15,1,15,6,1,1
1,1,1,1,1,1,1,1,1,1,1,1,1
1,1,1,1,1,1,1,1,1,1,1,1,1
endlayer

layer
1,1,1,1,1,1,1,1,1,1,1,1,1
1,1,1,1,1,1,1,1,1,1,1,1,1
1,1,6,15,12,15,12,15,12,15,6,1,1
1,1,15,0,0,0,0,0,0,1,15,1,1
1,1,12,0,0,0,0,0,0,0,12,1,1
1,1,1,0,0,0,0,0,0,0,12,1,1
1,1,15,0,0,0,0,0,0,0,15,1,1
1,1,1,0,0,0,0,0,0,0,12,1,1
1,1,1,0,0,0,0,0,0,0,1,1,1
1,1,15,0,0,0,0,0,0,0,15,1,1
1,1,1,0,0,0,0,0,0,0,1,1,1
1,1,12,0,0,0,0,0,0,0,12,1,1
1,1,15,0,0,0,0,23,0,23,0,1,1
1,1,6,0,0,0,0,0,0,0,7,1,1
1,1,0,0,0,0,0,0,23,0,15,1,1
1,0,12,0,0,0,0,0,0,0,12,1,1
1,1,0,0,0,0,0,0,0,0,15,1,1
1,0,12,0,0,0,0,0,0,0,12,1,1
1,1,15,0,0,0,0,0,0,0,15,1,1
1,0,0,0,0,0,0,0,0,0,1,1,1
1,1,15,1,0,0,0,0,0,0,15,1,1
1,1,1,15,1,15,1,1,0,15,7,1,1
1,1,1,1,1,1,1,1,1,1,1,1,1
1,1,1,1,1,1,1,1,1,1,1,1,1
endlayer

layer
16,16,16,16,16,16,16,16,16,16,16,16,16
16,16,16,16,16,16,16,16,16,16,16,16,16
16,16,7,15,12,15,12,15,12,15,6,16,16
16,16,15,0,0,0,0,0,0,0,15,16,16
16,16,12,0,0,0,0,0,0,0,16,16,16
16,16,12,0,0,0,0,0,0,0,12,16,16
16,16,15,0,0,0,0,0,0,0,15,16,16
16,16,12,0,0,0,0,0,0,0,12,16,16
16,16,0,0,0,0,0,0,0,0,12,16,16
16,16,15,0,0,0,0,0,0,0,15,16,16
16,16,0,0,0,0,0,0,0,0,12,16,16
16,16,16,0,0,0,0,0,0,0,0,0,16
16,16,15,0,0,0,0,0,24,24,15,16,16
16,16,0,0,0,0,0,24,0,24,6,16,16
16,16,0,0,0,0,0,24,0,24,15,16,16
16,0,12,0,0,0,0,0,0,0,12,16,16
16,16,15,0,0,0,0,0,0,0,15,16,16
16,0,0,0,0,0,0,0,0,0,12,16,16
16,16,15,0,0,0,0,0,0,0,15,16,16
16,0,0,0,0,0,0,0,0,0,0,0,16
16,16,0,0,0,0,0,0,0,0,15,16,16
16,16,16,16,0,15,0,0,0,15,7,16,16
16,16,16,16,16,16,16,0,16,16,16,16,16
16,16,16,16,16,16,16,16,16,16,16,16,16
endlayer

layer
0,0,0,0,0,0,0,0,0,0,0,0,0
0,0,0,0,0,0,0,0,0,0,0,0,0
0,0,6,15,12,15,12,15,12,15,6,0,0
0,0,15,0,0,0,0,0,0,0,15,0,0
0,0,12,0,0,0,0,0,0,0,12,0,0
0,0,0,0,0,0,0,0,0,0,12,0,0
0,0,15,0,0,0,0,0,0,0,15,0,0
0,0,0,0,0,0,0,0,0,0,12,0,0
0,0,0,0,0,0,0,0,0,0,12,0,0
0,0,0,0,0,0,0,0,0,0,15,0,0
0,0,0,0,0,0,0,0,0,0,12,0,0
0,0,12,0,0,0,0,0,0,0,0,0,0
0,0,15,0,0,0,0,25,25,25,15,0,0
0,0,6,0,0,0,0,0,0,25,6,0,0
0,0,15,0,0,0,0,25,25,0,0,0,0
0,0,12,0,0,0,0,0,0,0,12,0,0
0,0,0,0,0,0,0,0,0,0,15,0,0
0,0,0,0,0,0,0,0,0,0,0,0,0
0,0,0,0,0,0,0,0,0,0,15,0,0
0,0,0,0,0,0,0,0,0,0,0,0,0
0,0,0,0,0,0,0,0,0,0,15,0,0
0,0,0,0,0,15,0,0,0,15,6,0,0
0,0,0,0,0,0,0,0,0,0,0,0,0
0,0,0,0,0,0,0,0,0,0,0,0,0
endlayer

layer
0,0,0,0,0,0,0,0,0,0,0,0,0
0,0,0,0,0,0,0,0,0,0,0,0,0
0,0,7,15,0,15,12,15,12,15,6,0,0
0,0,15,0,0,0,0,0,0,0,0,0,0
0,0,12,0,0,0,0,0,0,0,0,0,0
0,0,12,0,0,0,0,0,0,0,0,0,0
0,0,15,0,0,0,0,0,0,0,15,0,0
0,0,0,0,0,0,0,0,0,0,0,0,0
0,0,12,0,0,0,0,0,0,0,12,0,0
0,0,0,0,0,0,0,0,0,0,15,0,0
0,0,12,0,0,0,0,0,0,0,12,0,0
0,0,12,0,0,0,0,0,0,0,0,0,0
0,0,15,0,0,0,0,26,26,26,15,0,0
0,0,7,0,0,0,0,0,0,0,6,0,0
0,0,0,0,0,0,0,26,0,26,15,0,0
0,0,0,0,0,0,0,0,0,0,0,0,0
0,0,0,0,0,0,0,0,0,0,15,0,0
0,0,0,0,0,0,0,0,0,0,12,0,0
0,0,0,0,0,0,0,0,0,0,15,0,0
0,0,0,0,0,0,0,0,0,0,0,0,0
0,0,0,0,0,0,0,0,0,0,15,0,0
0,0,0,0,0,0,0,0,0,15,7,0,0
0,0,0,0,0,0,0,0,0,0,0,0,0
0,0,0,0,0,0,0,0,0,0,0,0,0
endlayer

layer
0,0,0,0,0,0,0,0,0,0,0,0,0
0,0,0,0,0,0,0,0,0,0,0,0,0
0,0,6,15,0,15,0,15,12,15,7,0,0
0,0,15,0,0,0,0,0,0,0,15,0,0
0,0,12,0,0,0,0,0,0,0,0,0,0
0,0,0,0,0,0,0,0,0,0,0,0,0
0,0,15,0,0,0,0,0,0,0,15,0,0
0,0,12,0,0,0,0,0,0,0,12,0,0
0,0,12,0,0,0,0,0,0,0,12,0,0
0,0,15,0,0,0,0,0,0,0,15,0,0
0,0,12,0,0,0,0,0,0,0,0,0,0
0,0,12,0,0,0,0,0,0,0,12,0,0
0,0,15,0,0,0,0,27,27,27,15,0,0
0,0,6,0,0,0,0,27,27,27,6,0,0
0,0,15,0,0,0,0,27,27,27,15,0,0
0,0,0,0,0,0,0,0,0,0,0,0,0
0,0,0,0,0,0,0,0,0,0,15,0,0
0,0,0,0,0,0,0,0,0,0,0,0,0
0,0,0,0,0,0,0,0,0,0,15,0,0
0,0,0,0,0,0,0,0,0,0,0,0,0
0,0,0,0,0,0,0,0,0,0,15,0,0
0,0,0,0,0,0,0,0,0,15,6,0,0
0,0,0,0,0,0,0,0,0,0,0,0,0
0,0,0,0,0,0,0,0,0,0,0,0,0
endlayer

layer
0,0,0,0,0,0,0,0,0,0,0,0,0
0,0,0,0,0,0,0,0,0,0,0,0,0
0,0,7,6,6,6,6,7,7,7,6,0,0
0,0,6,17,0,0,17,17,17,17,7,0,0
0,0,6,0,0,0,0,17,17,17,6,0,0
0,0,6,17,0,17,17,17,17,17,6,0,0
0,0,7,17,17,17,17,17,17,17,6,0,0
0,0,6,17,17,17,17,17,17,17,6,0,0
0,0,6,17,17,17,17,17,17,17,6,0,0
0,0,0,17,17,17,17,17,17,17,6,0,0
0,0,6,17,17,17,17,17,17,17,6,0,0
0,0,6,17,17,17,17,17,17,17,7,0,0
0,0,6,17,17,17,17,17,17,17,6,0,0
0,0,6,6,6,6,6,6,6,6,6,0,0
0,0,6,18,18,18,18,18,18,18,6,0,0
0,0,0,18,18,18,18,18,18,18,6,0,0
0,0,0,0,18,18,18,18,18,18,6,0,0
0,0,0,18,18,18,18,18,18,18,6,0,0
0,0,0,0,0,18,18,18,18,18,7,0,0
0,0,0,0,0,0,0,0,18,18,6,0,0
0,0,0,0,0,0,0,0,18,18,6,0,0
0,0,0,0,0,0,0,0,0,6,6,0,0
0,0,0,0,0,0,0,0,0,0,0,0,0
0,0,0,0,0,0,0,0,0,0,0,0,0
endlayer

layer
0,0,0,0,0,0,0,0,0,0,0,0,0
0,0,0,0,0,0,0,0,0,0,0,0,0
0,0,0,0,0,0,0,0,0,0,0,0,0
0,0,0,0,0,0,0,0,0,0,0,0,0
0,0,0,0,0,0,0,20,19,0,0,0,0
0,0,0,0,0,0,0,20,20,0,0,0,0
0,0,0,0,0,0,0,0,0,0,0,0,0
0,0,0,0,0,21,21,0,0,0,0,0,0
0,0,0,0,0,21,21,0,0,0,0,0,0
0,0,0,0,0,0,0,0,0,0,0,0,0
0,0,0,0,20,0,0,0,0,0,0,0,0
0,0,0,0,0,0,0,0,0,0,0,0,0
0,0,0,0,0,0,0,0,0,0,0,0,0
0,0,0,15,0,15,0,0,12,15,7,0,0
0,0,15,0,0,0,0,0,0,0,15,0,0
0,0,0,0,0,0,0,0,0,0,12,0,0
0,0,0,0,0,0,0,0,0,0,15,0,0
0,0,0,0,0,0,0,0,0,0,0,0,0
0,0,0,0,0,0,0,0,0,0,15,0,0
0,0,0,0,0,0,0,0,0,0,0,0,0
0,0,0,0,0,0,0,0,0,0,15,0,0
0,0,0,0,0,0,0,0,0,15,6,0,0
0,0,0,0,0,0,0,0,0,0,0,0,0
0,0,0,0,0,0,0,0,0,0,0,0,0
endlayer

layer
0,0,0,0,0,0,0,0,0,0,0,0,0
0,0,0,0,0,0,0,0,0,0,0,0,0
0,0,0,0,0,0,0,0,0,0,0,0,0
0,0,0,0,0,0,0,0,0,0,0,0,0
0,0,0,0,0,0,0,19,20,0,0,0,0
0,0,0,0,0,0,0,20,20,0,0,0,0
0,0,0,0,0,0,0,0,0,0,0,0,0
0,0,0,0,0,0,0,0,0,0,0,0,0
0,0,0,0,0,0,0,0,0,0,0,0,0
0,0,0,0,0,0,0,0,0,0,0,0,0
0,0,0,0,0,0,0,0,0,0,0,0,0
0,0,0,0,0,0,0,0,0,0,0,0,0
0,0,0,0,0,0,0,0,0,0,0,0,0
0,0,0,15,12,15,12,15,12,15,6,0,0
0,0,15,0,0,0,0,0,0,0,15,0,0
0,0,0,0,0,0,0,0,0,0,12,0,0
0,0,0,0,0,0,0,0,0,0,15,0,0
0,0,0,0,0,0,0,0,0,0,12,0,0
0,0,0,0,0,0,0,0,0,0,15,0,0
0,0,0,0,0,0,0,0,0,0,0,0,0
0,0,0,0,0,0,0,0,0,0,15,0,0
0,0,0,0,0,0,0,0,0,15,6,0,0
0,0,0,0,0,0,0,0,0,0,0,0,0
0,0,0,0,0,0,0,0,0,0,0,0,0
endlayer

layer
0,0,0,0,0,0,0,0,0,0,0,0,0
0,0,0,0,0,0,0,0,0,0,0,0,0
0,0,0,0,0,0,0,0,0,0,0,0,0
0,0,0,0,0,0,0,0,0,0,0,0,0
0,0,0,0,0,0,0,20,20,0,0,0,0
0,0,0,0,0,0,0,19,20,0,0,0,0
0,0,0,0,0,0,0,0,0,0,0,0,0
0,0,0,0,0,0,0,0,0,0,0,0,0
0,0,0,0,0,0,0,0,0,0,0,0,0
0,0,0,0,0,0,0,0,0,0,0,0,0
0,0,0,0,0,0,0,0,0,0,0,0,0
0,0,0,0,0,0,0,0,0,0,0,0,0
0,0,0,0,0,0,0,0,0,0,0,0,0
0,0,6,15,12,15,12,15,12,15,6,0,0
0,0,15,0,0,0,0,0,0,0,0,0,0
0,0,12,0,0,0,0,0,0,0,0,0,0
0,0,0,0,0,0,0,0,0,0,15,0,0
0,0,0,0,0,0,0,0,0,0,12,0,0
0,0,0,0,0,0,0,0,0,0,15,0,0
0,0,0,0,0,0,0,0,0,0,0,0,0
0,0,0,0,0,0,0,0,0,0,0,0,0
0,0,0,0,0,0,0,0,0,15,6,0,0
0,0,0,0,0,0,0,0,0,0,0,0,0
0,0,0,0,0,0,0,0,0,0,0,0,0
endlayer

layer
0,0,0,0,0,0,0,0,0,0,0,0,0
0,0,0,0,0,0,0,0,0,0,0,0,0
0,0,0,0,0,0,0,0,0,0,0,0,0
0,0,0,0,0,0,0,0,0,0,0,0,0
0,0,0,0,0,0,0,20,20,0,0,0,0
0,0,0,0,0,0,0,20,19,0,0,0,0
0,0,0,0,0,0,0,0,0,0,0,0,0
0,0,0,0,0,0,0,0,0,0,0,0,0
0,0,0,0,0,0,0,0,0,0,0,0,0
0,0,0,0,0,0,0,0,0,0,0,0,0
0,0,0,0,0,0,0,0,0,0,0,0,0
0,0,0,0,0,0,0,0,0,0,0,0,0
0,0,0,0,0,0,0,0,0,0,0,0,0
0,0,6,15,0,15,12,15,12,15,6,0,0
0,0,15,0,0,0,0,0,0,0,15,0,0
0,0,12,0,0,0,0,0,0,0,0,0,0
0,0,15,0,0,0,0,0,0,0,15,0,0
0,0,0,0,0,0,0,0,0,0,12,0,0
0,0,0,0,0,0,0,0,0,0,15,0,0
0,0,0,0,0,0,0,0,0,0,0,0,0
0,0,0,0,0,0,0,0,0,0,15,0,0
0,0,0,15,0,15,0,0,0,15,6,0,0
0,0,0,0,0,0,0,0,0,0,0,0,0
0,0,0,0,0,0,0,0,0,0,0,0,0
endlayer

layer
0,0,0,0,0,0,0,0,0,0,0,0,0
0,0,0,0,0,0,0,0,0,0,0,0,0
0,0,0,0,0,0,0,0,0,0,0,0,0
0,0,0,0,0,0,0,0,0,0,0,0,0
0,0,0,0,0,0,0,20,19,0,0,0,0
0,0,0,0,0,0,0,20,20,0,0,0,0
0,0,0,0,0,0,0,0,0,0,0,0,0
0,0,0,0,0,0,0,0,0,0,0,0,0
0,0,0,0,0,0,0,0,0,0,0,0,0
0,0,0,0,0,0,0,0,0,0,0,0,0
0,0,0,0,0,0,0,0,0,0,0,0,0
0,0,0,0,0,0,0,0,0,0,0,0,0
0,0,0,0,0,0,0,0,0,0,0,0,0
0,0,6,0,12,0,12,15,0,15,6,0,0
0,0,15,0,0,0,0,0,0,0,15,0,0
0,0,12,0,0,0,0,0,0,0,12,0,0
0,0,15,0,0,0,0,0,0,0,15,0,0
0,0,0,0,0,0,0,0,0,0,0,0,0
0,0,0,0,0,0,0,0,0,0,15,0,0
0,0,0,0,0,0,0,0,0,0,0,0,0
0,0,0,0,0,0,0,0,0,0,15,0,0
0,0,0,15,0,15,0,0,0,15,6,0,0
0,0,0,0,0,0,0,0,0,0,0,0,0
0,0,0,0,0,0,0,0,0,0,0,0,0
endlayer

layer
0,0,0,0,0,0,0,0,0,0,0,0,0
0,0,0,0,0,0,0,0,0,0,0,0,0
0,0,0,0,0,0,0,0,0,0,0,0,0
0,0,0,0,0,0,0,0,0,0,0,0,0
0,0,0,0,0,0,0,19,20,0,0,0,0
0,0,0,0,0,0,0,20,20,0,0,0,0
0,0,0,0,0,0,0,0,0,0,0,0,0
0,0,0,0,0,0,0,0,0,0,0,0,0
0,0,0,0,0,0,0,0,0,0,0,0,0
0,0,0,0,0,0,0,0,0,0,0,0,0
0,0,0,0,0,0,0,0,0,0,0,0,0
0,0,0,0,0,0,0,0,0,0,0,0,0
0,0,0,0,0,0,0,0,0,0,0,0,0
0,0,6,15,12,15,12,15,0,15,6,0,0
0,0,0,0,0,0,0,0,0,0,15,0,0
0,0,12,0,0,0,0,0,0,0,12,0,0
0,0,15,0,0,0,0,0,0,0,15,0,0
0,0,0,0,0,0,0,0,0,0,0,0,0
0,0,15,0,0,0,0,0,0,0,15,0,0
0,0,0,0,0,0,0,0,0,0,12,0,0
0,0,15,0,0,0,0,0,0,0,15,0,0
0,0,0,15,12,15,0,0,0,15,6,0,0
0,0,0,0,0,0,0,0,0,0,0,0,0
0,0,0,0,0,0,0,0,0,0,0,0,0
endlayer

layer
0,0,0,0,0,0,0,0,0,0,0,0,0
0,0,0,0,0,0,0,0,0,0,0,0,0
0,0,0,0,0,0,0,0,0,0,0,0,0
0,0,0,0,0,0,0,0,0,0,0,0,0
0,0,0,0,0,0,0,20,20,0,0,0,0
0,0,0,0,0,0,0,19,20,0,0,0,0
0,0,0,0,0,0,0,0,0,0,0,0,0
0,0,0,0,0,0,0,0,0,0,0,0,0
0,0,0,0,0,0,0,0,0,0,0,0,0
0,0,0,0,0,0,0,0,0,0,0,0,0
0,0,0,0,0,0,0,0,0,0,0,0,0
0,0,0,0,0,0,0,0,0,0,0,0,0
0,0,0,0,0,0,0,0,0,0,0,0,0
0,0,7,15,12,15,0,15,12,15,6,0,0
0,0,0,0,0,0,0,0,0,0,15,0,0
0,0,12,0,0,0,0,0,0,0,12,0,0
0,0,15,0,0,0,0,0,0,0,15,0,0
0,0,0,0,0,0,0,0,0,0,12,0,0
0,0,15,0,0,0,0,0,0,0,15,0,0
0,0,12,0,0,0,0,0,0,0,0,0,0
0,0,15,0,0,0,0,0,0,0,15,0,0
0,0,6,15,0,15,0,0,0,15,6,0,0
0,0,0,0,0,0,0,0,0,0,0,0,0
0,0,0,0,0,0,0,0,0,0,0,0,0
endlayer

layer
0,0,0,0,0,0,0,0,0,0,0,0,0
0,0,0,0,0,0,0,0,0,0,0,0,0
0,0,0,0,0,0,0,0,0,0,0,0,0
0,0,0,0,0,0,0,0,0,0,0,0,0
0,0,0,0,0,0,0,20,20,0,0,0,0
0,0,0,0,0,0,0,20,19,0,0,0,0
0,0,0,0,0,0,0,0,0,0,0,0,0
0,0,0,0,0,0,0,0,0,0,0,0,0
0,0,0,0,0,0,0,0,0,0,0,0,0
0,0,0,0,0,0,0,0,0,0,0,0,0
0,0,0,0,0,0,0,0,0,0,0,0,0
0,0,0,0,0,0,0,0,0,0,0,0,0
0,0,0,0,0,0,0,0,0,0,0,0,0
0,0,6,6,6,6,6,7,7,6,6,0,0
0,0,6,17,17,17,17,17,17,17,6,0,0
0,0,6,17,17,17,17,17,17,17,6,0,0
0,0,6,17,17,17,17,17,17,17,6,0,0
0,0,7,17,17,17,17,17,17,17,6,0,0
0,0,7,17,0,0,17,17,17,17,7,0,0
0,0,6,17,0,0,0,0,0,17,6,0,0
0,0,6,17,17,0,0,0,0,17,6,0,0
0,0,6,6,6,7,6,6,7,6,6,0,0
0,0,0,0,0,0,0,0,0,0,0,0,0
0,0,0,0,0,0,0,0,0,0,0,0,0
endlayer

layer
0,0,0,0,0,0,0,0,0,0,0,0,0
0,0,0,0,0,0,0,0,0,0,0,0,0
0,0,0,0,0,0,0,0,0,0,0,0,0
0,0,0,0,0,0,0,0,0,0,0,0,0
0,0,0,0,0,0,0,0,0,0,0,0,0
0,0,0,0,0,0,0,0,0,0,0,0,0
0,0,0,0,0,0,0,0,0,0,0,0,0
0,0,0,0,0,0,0,0,0,0,0,0,0
0,0,0,0,0,0,0,0,0,0,0,0,0
0,0,0,0,0,0,0,0,0,0,0,0,0
0,0,0,0,0,0,0,0,0,0,0,0,0
0,0,0,0,0,0,0,0,0,0,0,0,0
0,0,0,0,0,0,0,0,0,0,0,0,0
0,0,0,0,0,0,0,0,0,0,0,0,0
0,0,0,0,0,0,0,0,0,0,0,0,0
0,0,0,0,0,0,0,0,0,0,0,0,0
0,0,0,0,0,0,0,0,0,0,0,0,0
0,0,0,0,0,21,21,0,0,0,0,0,0
0,0,0,0,0,21,21,0,0,0,0,0,0
0,0,0,0,0,0,0,0,0,0,0,0,0
0,0,0,0,0,0,0,0,0,0,0,0,0
0,0,0,0,0,0,0,0,0,0,0,0,0
0,0,0,0,0,0,0,0,0,0,0,0,0
0,0,0,0,0,0,0,0,0,0,0,0,0
endlayer

