weight=5
embed_into_distance=1
dimensions=17,13,24
max_cut_in=0

rule1=0,100,3134-10
rule2=2,100,2761-4
rule3=0,100,1474-7
rule4=0,100,1477-2 
rule5=0,100,2843-14,2843-14,2843-14,2843-14,2843
rule6=0,100,3400-7,3400-7,2838-4,2838-4,2838-4  
rule7=0,100,1477-0 
rule8=0,95,309
rule9=0,100,1473-0 
rule10=0,100,1474-0 
rule11=0,100,1473-1 
rule12=0,100,1474-1 
rule13=0,95,2835-2,2835-2,2835-2,2835-2,2835-2,2835-2,2835-2,2835-1,2835-1,2835-0
rule14=2,66,3225-3
rule15=0,100,3400-1,3400-1,2838-4,2838-4,2838-4  
rule16=0,100,3400-12,3400-12,2838-4,2838-4,2838-4 
rule17=0,100,2005-1 
rule18=0,100,3400-0,2838-4,2838-4,2838-4,2838-4 
rule19=0,100,2781-4,2781-4,2781-4,2781-4,2781-8
rule20=0,100,2524-0 
rule21=0,100,2245-1 
rule22=0,100,2248-1 
rule23=0,100,2291-1 
rule24=0,100,2843-12
rule25=0,100,2838-6
rule26=0,95,308,308,308,308,308,308,313,313,314,327
rule27=0,100,2761-4
rule28=0,100,2542
rule29=0,100,2843-13
rule30=0,100,3400-13,2838-4,2838-4,2838-4,2838-4 

layer
1,1,1,1,1,1,1,1,1,1,1,1,1,1,1,1,1,1,1,1,1,1,1,1
1,1,1,1,1,1,1,1,1,1,1,1,1,1,1,1,1,1,1,1,1,1,1,1
1,1,1,1,1,1,1,1,1,1,1,1,1,1,1,1,1,1,1,1,1,1,1,1
1,1,1,29,29,29,29,29,29,29,29,29,29,29,29,29,29,29,29,29,29,1,1,1
1,1,1,29,3,3,3,29,29,29,29,29,29,29,29,29,29,29,29,29,29,1,1,1
1,1,1,29,3,3,3,29,29,29,29,29,29,29,29,29,29,29,29,29,29,1,1,1
1,1,1,29,3,3,3,29,29,29,29,29,29,29,29,29,29,29,29,29,29,1,1,1
1,1,1,29,29,29,29,29,29,29,29,29,29,29,29,29,29,29,29,29,29,1,1,1
1,1,1,29,4,29,29,29,29,29,29,29,29,29,29,29,29,29,29,29,29,1,1,1
1,1,1,29,29,29,29,29,29,29,29,29,29,29,29,29,29,29,29,29,28,1,1,1
1,1,1,1,1,1,1,29,29,1,1,1,1,1,1,1,1,1,1,1,1,1,1,1
1,1,1,1,1,1,1,1,1,1,1,1,1,1,1,1,1,1,1,1,1,1,1,1
1,1,1,1,1,1,1,1,1,1,1,1,1,1,1,1,1,1,1,1,1,1,1,1
endlayer

layer
0,0,0,0,0,0,0,0,0,0,0,0,0,0,0,0,0,0,0,0,0,0,0,0
0,0,0,0,0,0,0,0,0,0,0,0,0,0,0,0,0,0,0,0,0,0,0,0
0,0,5,5,5,5,5,5,5,5,5,5,5,5,5,5,5,5,5,5,5,5,0,0
0,0,5,26,3,3,9,8,0,0,0,0,6,6,6,6,6,6,6,6,26,5,0,0
0,0,5,3,0,0,0,3,0,0,0,0,6,6,6,6,14,14,14,6,0,5,0,0
0,0,5,3,0,0,0,3,0,0,0,0,6,6,6,6,14,14,14,6,0,5,0,0
0,0,5,3,0,0,0,3,0,0,0,0,0,7,0,6,14,14,14,6,0,5,0,0
0,0,5,0,12,11,10,0,0,0,0,0,0,0,0,6,6,30,6,6,0,5,0,0
0,0,5,0,0,0,0,0,0,0,0,0,0,0,0,0,0,0,0,0,0,5,0,0
0,0,5,0,0,0,0,0,0,0,0,0,0,0,0,0,0,0,0,0,0,5,0,0
0,0,5,5,5,5,5,0,0,5,5,5,5,5,5,5,5,5,5,5,5,5,0,0
0,0,0,0,0,0,0,0,0,0,0,0,0,0,0,0,0,0,0,0,0,0,0,0
0,0,0,0,0,0,0,0,0,0,0,0,0,0,0,0,0,0,0,0,0,0,0,0
endlayer

layer
0,0,0,0,0,0,0,0,0,0,0,0,0,0,0,0,0,0,0,0,0,0,0,0
0,0,0,0,0,0,0,0,0,0,0,0,0,0,0,0,0,0,0,0,0,0,0,0
0,0,5,13,14,14,13,14,14,13,14,14,13,5,13,14,13,14,13,14,13,5,0,0
0,0,13,0,0,0,0,0,0,0,0,0,6,6,6,14,14,14,14,14,0,13,0,0
0,0,14,0,0,0,0,0,0,0,0,0,16,26,6,14,0,0,0,14,0,14,0,0
0,0,13,0,0,0,0,0,0,0,0,0,6,15,6,14,0,0,0,14,0,13,0,0
0,0,14,0,0,0,0,0,0,0,0,0,0,0,0,14,0,0,0,14,0,14,0,0
0,0,13,0,0,0,0,0,0,0,0,0,0,0,0,14,14,14,14,14,0,13,0,0
0,0,14,0,0,0,0,0,0,0,0,0,0,0,0,0,0,0,0,0,0,14,0,0
0,0,13,0,0,0,0,0,0,0,0,0,0,0,0,0,0,0,0,0,0,13,0,0
0,0,5,13,14,14,13,0,0,13,14,14,13,5,13,14,13,14,13,14,13,5,0,0
0,0,0,0,0,0,0,0,0,0,0,0,0,0,0,0,0,0,0,0,0,0,0,0
0,0,0,0,0,0,0,0,0,0,0,0,0,0,0,0,0,0,0,0,0,0,0,0
endlayer

layer
0,0,0,0,0,0,0,0,0,0,0,0,0,0,0,0,0,0,0,0,0,0,0,0
0,0,0,0,0,0,0,0,0,0,0,0,0,0,0,0,0,0,0,0,0,0,0,0
0,0,5,13,14,14,13,14,14,13,14,14,13,5,13,14,13,14,13,14,13,5,0,0
0,0,13,0,0,0,0,0,0,0,0,0,6,0,6,0,0,0,0,0,0,13,0,0
0,0,14,0,0,0,0,0,0,0,0,0,6,0,6,0,0,0,0,0,0,14,0,0
0,0,13,0,0,0,0,0,0,0,0,0,6,18,6,0,0,0,0,0,0,13,0,0
0,0,14,0,0,0,0,0,0,0,0,0,0,0,0,0,0,0,0,0,0,14,0,0
0,0,13,0,0,0,0,0,0,0,0,0,0,0,0,0,0,0,0,0,0,13,0,0
0,0,14,0,0,0,0,0,0,0,0,0,0,0,0,0,0,0,0,0,0,14,0,0
0,0,13,0,0,0,0,0,0,0,0,0,0,0,0,0,0,0,0,0,0,13,0,0
0,0,5,13,14,14,13,0,0,13,14,14,13,5,13,14,13,14,13,14,13,5,0,0
0,0,0,0,0,0,0,0,0,0,0,0,0,0,0,0,0,0,0,0,0,0,0,0
0,0,0,0,0,0,0,0,0,0,0,0,0,0,0,0,0,0,0,0,0,0,0,0
endlayer

layer
0,0,0,0,0,0,0,0,0,0,0,0,0,0,0,0,0,0,0,0,0,0,0,0
0,0,0,0,0,0,0,0,0,0,0,0,0,0,0,0,0,0,0,0,0,0,0,0
0,0,5,13,14,14,13,14,14,13,14,14,13,5,13,14,13,14,13,14,13,5,0,0
0,0,13,0,0,0,0,0,0,0,0,0,6,6,6,0,0,0,0,0,0,13,0,0
0,0,14,0,0,0,0,0,0,0,0,0,6,0,6,0,0,0,0,0,0,14,0,0
0,0,13,0,0,0,0,0,0,0,0,0,6,6,6,0,0,0,0,0,0,13,0,0
0,0,14,0,0,0,0,0,0,0,0,0,0,0,0,0,0,0,0,0,0,14,0,0
0,0,13,0,0,0,0,0,0,0,0,0,0,0,0,0,0,0,0,0,0,13,0,0
0,0,14,0,0,0,0,0,0,0,0,0,0,0,0,0,0,0,0,0,0,14,0,0
0,0,13,0,0,0,0,0,0,0,0,0,0,0,0,0,0,0,0,0,0,13,0,0
0,0,5,13,14,14,13,14,14,13,14,14,13,5,13,14,13,14,13,14,13,5,0,0
0,0,0,0,0,0,0,0,0,0,0,0,0,0,0,0,0,0,0,0,0,0,0,0
0,0,0,0,0,0,0,0,0,0,0,0,0,0,0,0,0,0,0,0,0,0,0,0
endlayer

layer
0,0,0,0,0,0,0,0,0,0,0,0,0,0,0,0,0,0,0,0,0,0,0,0
0,0,0,0,0,0,0,0,0,0,0,0,0,0,0,0,0,0,0,0,0,0,0,0
0,0,5,13,14,14,13,14,14,13,14,14,13,5,13,14,13,14,13,14,13,5,0,0
0,0,13,0,0,0,0,0,0,0,0,0,6,6,6,0,0,0,0,0,0,13,0,0
0,0,14,0,0,0,0,0,0,0,0,0,6,0,6,0,0,0,0,0,0,14,0,0
0,0,13,0,0,0,0,0,0,0,0,0,6,6,6,0,0,0,0,0,0,13,0,0
0,0,14,0,0,0,0,0,0,0,0,0,0,0,0,0,0,0,0,0,0,14,0,0
0,0,13,0,0,0,0,0,0,0,0,0,0,0,0,0,0,0,0,0,0,13,0,0
0,0,14,0,0,0,0,0,0,0,0,0,0,0,0,0,0,0,0,0,0,14,0,0
0,0,13,0,0,0,0,0,0,0,0,0,0,0,0,0,0,0,0,0,0,13,0,0
0,0,5,13,14,14,13,14,14,13,14,14,13,5,13,14,13,14,13,14,13,5,0,0
0,0,0,0,0,0,0,0,0,0,0,0,0,0,0,0,0,0,0,0,0,0,0,0
0,0,0,0,0,0,0,0,0,0,0,0,0,0,0,0,0,0,0,0,0,0,0,0
endlayer

layer
0,0,0,0,0,0,0,0,0,0,0,0,0,0,0,0,0,0,0,0,0,0,0,0
0,0,0,0,0,0,0,0,0,0,0,0,0,0,0,0,0,0,0,0,0,0,0,0
0,0,5,13,14,14,13,14,14,13,14,14,13,5,13,14,13,14,13,14,13,5,0,0
0,0,13,0,0,0,0,0,0,0,0,0,6,6,6,0,0,0,0,0,0,13,0,0
0,0,14,0,0,0,0,0,0,0,0,0,6,0,6,0,0,0,0,0,0,14,0,0
0,0,13,0,0,0,0,0,0,0,0,0,6,6,6,0,0,0,0,0,0,13,0,0
0,0,14,0,0,0,0,0,0,0,0,0,0,0,0,0,0,0,0,0,0,14,0,0
0,0,13,0,0,0,0,0,0,0,0,0,0,0,0,0,0,0,0,0,0,13,0,0
0,0,14,0,0,0,0,0,0,0,0,0,0,0,0,0,0,0,0,0,0,14,0,0
0,0,13,0,0,0,0,0,0,0,0,0,0,0,0,0,0,0,0,0,0,13,0,0
0,0,5,13,14,14,13,14,14,13,14,14,13,5,13,14,13,14,13,14,13,5,0,0
0,0,0,0,0,0,0,0,0,0,0,0,0,0,0,0,0,0,0,0,0,0,0,0
0,0,0,0,0,0,0,0,0,0,0,0,0,0,0,0,0,0,0,0,0,0,0,0
endlayer

layer
0,0,0,0,0,0,0,0,0,0,0,0,0,0,0,0,0,0,0,0,0,0,0,0
0,0,0,0,0,0,0,0,0,0,0,0,0,0,0,0,0,0,0,0,0,0,0,0
0,0,5,13,14,14,13,14,14,13,14,14,13,5,13,14,13,14,13,14,13,5,0,0
0,0,13,0,0,0,0,0,0,0,0,0,6,6,6,0,0,0,0,0,0,13,0,0
0,0,14,0,0,0,0,0,0,0,0,0,6,6,6,0,0,0,0,0,0,14,0,0
0,0,13,0,0,0,0,0,0,0,0,0,6,6,6,0,0,0,0,0,0,13,0,0
0,0,14,0,0,0,0,0,0,0,0,0,0,0,0,0,0,0,0,0,0,14,0,0
0,0,13,0,0,0,0,0,0,0,0,0,0,0,0,0,0,0,0,0,0,13,0,0
0,0,14,0,0,0,0,0,0,0,0,0,0,0,0,0,0,0,0,0,0,14,0,0
0,0,13,0,0,0,0,0,0,0,0,0,0,0,0,0,0,0,0,0,0,13,0,0
0,0,5,13,14,14,13,14,14,13,14,14,13,5,13,14,13,14,13,14,13,5,0,0
0,0,0,0,0,0,0,0,0,0,0,0,0,0,0,0,0,0,0,0,0,0,0,0
0,0,0,0,0,0,0,0,0,0,0,0,0,0,0,0,0,0,0,0,0,0,0,0
endlayer

layer
0,0,0,0,0,0,0,0,0,0,0,0,0,0,0,0,0,0,0,0,0,0,0,0
0,0,0,0,0,0,0,0,0,0,0,0,0,0,0,0,0,0,0,0,0,0,0,0
0,0,5,5,5,5,5,5,5,5,5,5,5,5,5,5,5,5,5,5,5,5,0,0
0,0,5,19,19,19,19,19,19,19,19,19,19,5,27,27,27,27,27,27,27,5,0,0
0,0,5,19,19,19,19,19,19,19,19,19,19,5,27,2,2,2,2,2,27,5,0,0
0,0,5,19,19,19,19,19,19,19,19,19,19,5,27,2,2,2,2,2,27,5,0,0
0,0,5,19,19,19,19,19,19,19,19,19,19,5,27,2,2,2,2,2,27,5,0,0
0,0,5,19,19,19,19,19,19,19,19,19,19,5,27,2,2,2,2,2,27,5,0,0
0,0,5,19,19,19,19,19,19,19,19,19,19,5,27,2,2,2,2,2,27,5,0,0
0,0,5,19,19,19,19,19,19,19,19,19,19,5,27,27,27,27,27,27,28,5,0,0
0,0,5,5,5,5,5,5,5,5,5,5,5,5,5,5,5,5,5,5,5,5,0,0
0,0,0,0,0,0,0,0,0,0,0,0,0,0,0,0,0,0,0,0,0,0,0,0
0,0,0,0,0,0,0,0,0,0,0,0,0,0,0,0,0,0,0,0,0,0,0,0
endlayer

layer
0,0,0,0,0,0,0,0,0,0,0,0,0,0,0,0,0,0,0,0,0,0,0,0
0,0,0,0,0,0,0,0,0,0,0,0,0,0,0,0,0,0,0,0,0,0,0,0
0,0,0,0,0,0,0,0,0,0,0,0,0,5,13,14,13,14,13,14,13,5,0,0
0,0,0,0,0,0,0,0,0,0,0,0,0,13,0,0,20,0,0,0,8,13,0,0
0,0,0,0,25,24,0,0,0,0,0,0,0,14,0,0,0,0,0,0,0,14,0,0
0,0,0,0,24,24,0,0,0,0,0,0,0,13,0,0,21,0,0,0,0,13,0,0
0,0,0,0,0,0,0,0,0,0,0,0,0,14,0,23,22,0,0,0,0,14,0,0
0,0,0,0,0,0,0,0,0,0,0,0,0,13,0,0,21,26,0,0,0,13,0,0
0,0,0,0,0,0,0,0,0,0,24,0,0,14,0,0,0,0,0,0,0,14,0,0
0,0,0,0,0,0,0,0,0,0,0,0,0,13,0,0,0,0,0,0,0,13,0,0
0,0,0,0,0,0,0,0,0,0,0,0,0,5,13,14,13,14,13,14,13,5,0,0
0,0,0,0,0,0,0,0,0,0,0,0,0,0,0,0,0,0,0,0,0,0,0,0
0,0,0,0,0,0,0,0,0,0,0,0,0,0,0,0,0,0,0,0,0,0,0,0
endlayer

layer
0,0,0,0,0,0,0,0,0,0,0,0,0,0,0,0,0,0,0,0,0,0,0,0
0,0,0,0,0,0,0,0,0,0,0,0,0,0,0,0,0,0,0,0,0,0,0,0
0,0,0,0,0,0,0,0,0,0,0,0,0,5,13,14,13,14,13,14,13,5,0,0
0,0,0,0,0,0,0,0,0,0,0,0,0,13,0,0,20,0,0,0,0,13,0,0
0,0,0,0,24,24,0,0,0,0,0,0,0,14,0,0,0,0,0,0,0,14,0,0
0,0,0,0,25,24,0,0,0,0,0,0,0,13,0,0,0,0,0,0,0,13,0,0
0,0,0,0,0,0,0,0,0,0,0,0,0,14,0,0,0,0,0,0,0,14,0,0
0,0,0,0,0,0,0,0,0,0,0,0,0,13,0,0,0,0,0,0,0,13,0,0
0,0,0,0,0,0,0,0,0,0,24,0,0,14,0,0,0,0,0,0,0,14,0,0
0,0,0,0,0,0,0,0,0,0,0,0,0,13,0,0,0,0,0,0,0,13,0,0
0,0,0,0,0,0,0,0,0,0,0,0,0,5,13,14,13,14,13,14,13,5,0,0
0,0,0,0,0,0,0,0,0,0,0,0,0,0,0,0,0,0,0,0,0,0,0,0
0,0,0,0,0,0,0,0,0,0,0,0,0,0,0,0,0,0,0,0,0,0,0,0
endlayer

layer
0,0,0,0,0,0,0,0,0,0,0,0,0,0,0,0,0,0,0,0,0,0,0,0
0,0,0,0,0,0,0,0,0,0,0,0,0,0,0,0,0,0,0,0,0,0,0,0
0,0,0,0,0,0,0,0,0,0,0,0,0,5,13,14,13,14,13,14,13,5,0,0
0,0,0,0,0,0,0,0,0,0,0,0,0,13,0,0,0,0,0,0,0,13,0,0
0,0,0,0,24,24,0,0,0,0,0,0,0,14,0,0,0,0,0,0,0,14,0,0
0,0,0,0,24,25,0,0,0,0,0,0,0,13,0,0,0,0,0,0,0,13,0,0
0,0,0,0,0,0,0,0,0,0,0,0,0,14,0,0,0,0,0,0,0,14,0,0
0,0,0,0,0,0,0,0,0,0,0,0,0,13,0,0,0,0,0,0,0,13,0,0
0,0,0,0,0,0,0,0,0,0,24,0,0,14,0,0,0,0,0,0,0,14,0,0
0,0,0,0,0,0,0,0,0,0,0,0,0,13,0,0,0,0,0,0,0,13,0,0
0,0,0,0,0,0,0,0,0,0,0,0,0,5,13,14,13,14,13,14,13,5,0,0
0,0,0,0,0,0,0,0,0,0,0,0,0,0,0,0,0,0,0,0,0,0,0,0
0,0,0,0,0,0,0,0,0,0,0,0,0,0,0,0,0,0,0,0,0,0,0,0
endlayer

layer
0,0,0,0,0,0,0,0,0,0,0,0,0,0,0,0,0,0,0,0,0,0,0,0
0,0,0,0,0,0,0,0,0,0,0,0,0,0,0,0,0,0,0,0,0,0,0,0
0,0,0,0,0,0,0,0,0,0,0,0,0,5,13,14,13,14,13,14,13,5,0,0
0,0,0,0,0,0,0,0,0,0,0,0,0,13,0,0,0,0,0,0,0,13,0,0
0,0,0,0,24,25,0,0,0,0,0,0,0,14,0,0,0,0,0,0,0,14,0,0
0,0,0,0,24,24,0,0,0,0,0,0,0,13,0,0,0,0,0,0,0,13,0,0
0,0,0,0,0,0,0,0,0,0,0,0,0,14,0,0,0,0,0,0,0,14,0,0
0,0,0,0,0,0,0,0,0,0,0,0,0,13,0,0,0,0,0,0,0,13,0,0
0,0,0,0,0,0,0,0,0,0,25,0,0,14,0,0,0,0,0,0,0,14,0,0
0,0,0,0,0,0,0,0,0,0,0,0,0,13,0,0,0,0,0,0,0,13,0,0
0,0,0,0,0,0,0,0,0,0,0,0,0,5,13,14,13,14,13,14,13,5,0,0
0,0,0,0,0,0,0,0,0,0,0,0,0,0,0,0,0,0,0,0,0,0,0,0
0,0,0,0,0,0,0,0,0,0,0,0,0,0,0,0,0,0,0,0,0,0,0,0
endlayer

layer
0,0,0,0,0,0,0,0,0,0,0,0,0,0,0,0,0,0,0,0,0,0,0,0
0,0,0,0,0,0,0,0,0,0,0,0,0,0,0,0,0,0,0,0,0,0,0,0
0,0,0,0,0,0,0,0,0,0,0,0,0,5,13,14,13,14,13,14,13,5,0,0
0,0,0,0,0,0,0,0,0,0,0,0,0,13,0,0,0,0,0,0,0,13,0,0
0,0,0,0,25,24,0,0,0,0,0,0,0,14,0,0,0,0,0,0,0,14,0,0
0,0,0,0,24,24,0,0,0,0,0,0,0,13,0,0,0,0,0,0,0,13,0,0
0,0,0,0,0,0,0,0,0,0,0,0,0,14,0,0,0,0,0,0,0,14,0,0
0,0,0,0,0,0,0,0,0,0,0,0,0,13,0,0,0,0,0,0,0,13,0,0
0,0,0,0,0,0,0,0,0,0,24,0,0,14,0,0,0,0,0,0,0,14,0,0
0,0,0,0,0,0,0,0,0,0,0,0,0,13,0,0,0,0,0,0,0,13,0,0
0,0,0,0,0,0,0,0,0,0,0,0,0,5,13,14,13,14,13,14,13,5,0,0
0,0,0,0,0,0,0,0,0,0,0,0,0,0,0,0,0,0,0,0,0,0,0,0
0,0,0,0,0,0,0,0,0,0,0,0,0,0,0,0,0,0,0,0,0,0,0,0
endlayer

layer
0,0,0,0,0,0,0,0,0,0,0,0,0,0,0,0,0,0,0,0,0,0,0,0
0,0,0,0,0,0,0,0,0,0,0,0,0,0,0,0,0,0,0,0,0,0,0,0
0,0,0,0,0,0,0,0,0,0,0,0,0,5,13,14,13,14,13,14,13,5,0,0
0,0,0,0,0,0,0,0,0,0,0,0,0,13,0,0,0,0,0,0,0,13,0,0
0,0,0,0,24,24,0,0,0,0,0,0,0,14,0,0,0,0,0,0,0,14,0,0
0,0,0,0,25,24,0,0,0,0,0,0,0,13,0,0,0,0,0,0,0,13,0,0
0,0,0,0,0,0,0,0,0,0,0,0,0,14,0,0,0,0,0,0,0,14,0,0
0,0,0,0,0,0,0,0,0,0,0,0,0,13,0,0,0,0,0,0,0,13,0,0
0,0,0,0,0,0,0,0,0,0,24,0,0,14,0,0,0,0,0,0,0,14,0,0
0,0,0,0,0,0,0,0,0,0,0,0,0,13,0,0,0,0,0,0,0,13,0,0
0,0,0,0,0,0,0,0,0,0,0,0,0,5,13,14,13,14,13,14,13,5,0,0
0,0,0,0,0,0,0,0,0,0,0,0,0,0,0,0,0,0,0,0,0,0,0,0
0,0,0,0,0,0,0,0,0,0,0,0,0,0,0,0,0,0,0,0,0,0,0,0
endlayer

layer
0,0,0,0,0,0,0,0,0,0,0,0,0,0,0,0,0,0,0,0,0,0,0,0
0,0,0,0,0,0,0,0,0,0,0,0,0,0,0,0,0,0,0,0,0,0,0,0
0,0,0,0,0,0,0,0,0,0,0,0,0,5,13,14,13,14,13,14,13,5,0,0
0,0,0,0,0,0,0,0,0,0,0,0,0,13,0,0,0,0,0,0,0,13,0,0
0,0,0,0,24,24,0,0,0,0,0,0,0,14,0,0,0,0,0,0,0,14,0,0
0,0,0,0,24,25,0,0,0,0,0,0,0,13,0,0,0,0,0,0,0,13,0,0
0,0,0,0,0,0,0,0,0,0,0,0,0,14,0,0,0,0,0,0,0,14,0,0
0,0,0,0,0,0,0,0,0,0,0,0,0,13,0,0,0,0,0,0,0,13,0,0
0,0,0,0,0,0,0,0,0,0,0,0,0,14,0,0,0,0,0,0,0,14,0,0
0,0,0,0,0,0,0,0,0,0,0,0,0,13,0,0,0,0,0,0,0,13,0,0
0,0,0,0,0,0,0,0,0,0,0,0,0,5,13,14,13,14,13,14,13,5,0,0
0,0,0,0,0,0,0,0,0,0,0,0,0,0,0,0,0,0,0,0,0,0,0,0
0,0,0,0,0,0,0,0,0,0,0,0,0,0,0,0,0,0,0,0,0,0,0,0
endlayer

layer
0,0,0,0,0,0,0,0,0,0,0,0,0,0,0,0,0,0,0,0,0,0,0,0
0,0,0,0,0,0,0,0,0,0,0,0,0,0,0,0,0,0,0,0,0,0,0,0
0,0,0,0,0,0,0,0,0,0,0,0,0,5,5,5,5,5,5,5,5,5,0,0
0,0,0,0,0,0,0,0,0,0,0,0,0,5,19,19,19,19,19,19,19,5,0,0
0,0,0,0,24,25,0,0,0,0,0,0,0,5,19,19,19,19,19,19,19,5,0,0
0,0,0,0,24,24,0,0,0,0,0,0,0,5,19,19,19,19,19,19,19,5,0,0
0,0,0,0,0,0,0,0,0,0,0,0,0,5,19,19,19,19,19,19,19,5,0,0
0,0,0,0,0,0,0,0,0,0,0,0,0,5,19,19,19,19,19,19,19,5,0,0
0,0,0,0,0,0,0,0,0,0,0,0,0,5,19,19,19,19,19,19,19,5,0,0
0,0,0,0,0,0,0,0,0,0,0,0,0,5,19,19,19,19,19,19,19,5,0,0
0,0,0,0,0,0,0,0,0,0,0,0,0,5,5,5,5,5,5,5,5,5,0,0
0,0,0,0,0,0,0,0,0,0,0,0,0,0,0,0,0,0,0,0,0,0,0,0
0,0,0,0,0,0,0,0,0,0,0,0,0,0,0,0,0,0,0,0,0,0,0,0
endlayer



