# Converted from schematic
# THIS TEMPLATE USES DEFAULTS!  Please edit for corrections.
# If you need help, consult template_rules.txt

weight=3
embed_into_distance=10
acceptable_target_blocks=1,2,3,12,13,250
dimensions=18,13,24
allowable_overhang=0
max_cut_in=2
cut_in_buffer=1
max_leveling=2
leveling_buffer=1
preserve_water=0
preserve_lava=0
preserve_plants=0


rule1=0,100,3134-10
rule2=0,100,2843-13
rule3=0,100,2542
rule4=0,50,3501,3501,3501,3502,3502,3502,3502,3503,3503,3503,1474-7
rule5=0,100,1477-2
rule6=0,100,300
rule7=0,100,2843-14,2843-14,2843-14,2843-14,2843
rule8=0,100,308,308,308,308,308,308,313,313,314,327
rule9=0,100,3400-7,3504,3505,3506
rule10=0,66,3225-3
rule11=0,100,1477-0
rule12=0,100,309,309,311
rule13=0,100,3501,3501,3501,3502,3502,3502,3502,3503,3503,3503,1473-0
rule14=0,100,3501,3501,3501,3502,3502,3502,3502,3503,3503,3503,1474-0 
rule15=0,100,3501,3501,3501,3502,3502,3502,3502,3503,3503,3503,1473-1
rule16=0,100,3501,3501,3501,3502,3502,3502,3502,3503,3503,3503,1474-1
rule17=0,95,2835-2,2835-2,2835-2,2835-2,2835-2,2835-2,2835-2,2835-1,2835-1,2835-0
rule18=0,100,3400-1,3400-1,3504,3505,3506
rule19=0,100,3400-12,3400-12,3504,3505,3506
rule20=0,100,3400-0,3504,3505,3506
rule21=0,95,300
rule22=0,100,2761-4
rule23=0,100,3134,3134,3134,3134-8,3134-2
rule24=0,100,2245-1 
rule25=0,100,2248-1 
rule26=0,100,2291-1
rule27=0,100,2843-12
rule28=0,100,2838-6
rule29=1,100,3538
rule30=1,85,3400-7,3504,3505,3506
rule31=1,75,3400-7,3504,3505,3506
rule32=1,65,3400-7,3504,3505,3506
rule33=1,50,3400-7,3504,3505,3506
rule34=1,25,3400-7,3504,3505,3506
rule35=1,15,3400-7,3504,3505,3506


layer
1,1,1,1,1,1,1,1,1,1,1,1,1,1,1,1,1,1,1,1,1,1,1,1
1,1,1,1,1,1,1,1,1,1,1,1,1,1,1,1,1,1,1,1,1,1,1,1
1,1,1,1,1,1,1,1,1,1,1,1,1,1,1,1,1,1,1,1,1,1,1,1
1,1,1,2,2,2,2,2,2,2,2,2,2,2,2,2,2,2,2,2,2,1,1,1
1,1,1,2,4,4,4,2,2,2,2,2,2,8,2,2,2,2,2,2,2,1,1,1
1,1,1,2,4,4,4,2,2,2,2,2,2,2,2,2,2,2,2,2,2,1,1,1
1,1,1,2,4,4,4,2,2,2,2,2,2,2,2,2,2,2,2,2,2,1,1,1
1,1,1,2,2,2,2,2,2,2,2,2,2,2,2,2,2,2,2,2,2,1,1,1
1,1,1,2,5,2,2,2,2,2,2,2,2,2,2,2,2,2,2,2,2,1,1,1
1,1,1,2,2,2,2,2,2,2,2,2,2,2,2,2,2,2,2,2,3,1,1,1
1,1,1,1,1,1,1,2,2,1,1,1,1,1,1,1,1,1,1,1,1,1,1,1
1,1,1,1,1,1,1,1,1,1,1,1,1,1,1,1,1,1,1,1,1,1,1,1
1,1,1,1,1,1,1,1,1,1,1,1,1,1,1,1,1,1,1,1,1,1,1,1
endlayer


layer
6,6,6,6,6,6,6,6,6,6,6,6,6,6,6,6,6,6,6,6,6,6,6,6
6,6,6,6,6,6,6,6,6,6,6,6,6,6,6,6,6,6,6,6,6,6,6,6
6,6,7,7,7,7,7,7,7,7,7,7,7,7,7,7,7,7,7,7,7,7,6,6
6,6,7,8,4,4,13,12,0,0,0,0,9,9,9,9,9,9,9,9,8,7,6,6
6,6,7,4,0,0,0,4,0,0,0,0,9,9,9,9,10,10,10,9,0,7,6,6
6,6,7,4,0,0,0,4,0,0,0,0,9,9,9,9,10,10,10,9,0,7,6,6
6,6,7,4,0,0,0,4,0,0,0,0,0,11,0,9,10,10,10,9,0,7,6,6
6,6,7,0,16,15,14,0,0,0,0,0,0,0,0,9,9,9,9,9,0,7,6,6
6,6,7,0,0,0,6,6,6,0,0,0,0,0,0,0,0,0,0,0,0,7,6,6
6,6,7,0,0,0,6,6,6,6,0,0,0,0,0,0,0,0,0,0,0,7,6,6
6,6,7,7,7,7,7,6,6,7,7,7,7,7,7,7,7,7,7,7,7,7,6,6
6,6,6,6,6,6,6,6,6,6,6,6,6,6,6,6,6,6,6,6,6,6,6,6
6,6,6,6,6,6,6,6,6,6,6,6,6,6,6,6,6,6,6,6,6,6,6,6
endlayer

layer
6,6,6,6,6,6,6,6,6,6,6,6,6,6,6,6,6,6,6,6,6,6,6,6
6,6,6,6,6,6,6,6,6,6,6,6,6,6,6,6,6,6,6,6,6,6,6,6
6,6,7,17,10,10,17,10,10,17,10,10,17,7,17,10,17,10,17,10,17,7,6,6
6,6,17,0,0,0,0,0,0,0,0,0,30,30,30,10,10,10,10,10,0,17,6,6
6,6,10,0,0,0,0,0,0,0,0,0,19,0,30,10,0,0,0,10,0,10,6,6
6,6,17,0,0,0,0,0,0,0,0,0,30,18,30,10,0,0,0,10,0,17,6,6
6,6,10,0,0,0,0,0,0,0,0,0,0,0,0,10,0,0,0,10,0,10,6,6
6,6,17,0,0,0,0,0,0,0,0,0,0,0,0,10,10,10,10,10,0,17,6,6
6,6,10,0,0,0,0,0,0,0,0,0,0,0,0,0,0,0,0,0,0,10,6,6
6,6,17,0,0,0,6,6,0,0,0,0,0,0,0,0,0,0,0,0,0,17,6,6
6,6,7,17,10,10,17,6,6,17,10,10,17,7,17,10,17,10,17,10,17,7,6,6
6,6,6,6,6,6,6,6,6,6,6,6,6,6,6,6,6,6,6,6,6,6,6,6
6,6,6,6,6,6,6,6,6,6,6,6,6,6,6,6,6,6,6,6,6,6,6,6
endlayer

layer
6,6,6,6,6,6,6,6,6,6,6,6,6,6,6,6,6,6,6,6,6,6,6,6
6,6,6,6,6,6,6,6,6,6,6,6,6,6,6,6,6,6,6,6,6,6,6,6
6,6,7,17,10,10,17,10,10,17,10,10,17,7,17,10,17,10,17,10,17,7,6,6
6,6,17,0,0,0,0,0,0,0,0,0,31,31,31,0,0,0,0,0,0,17,6,6
6,6,10,0,0,0,0,0,0,0,0,0,31,0,31,0,0,0,0,0,0,10,6,6
6,6,17,0,0,0,0,0,0,0,0,0,31,20,31,0,0,0,0,0,0,17,6,6
6,6,10,0,0,0,0,0,0,0,0,0,0,0,0,0,0,0,0,0,0,10,6,6
6,6,17,0,0,0,0,0,0,0,0,0,0,0,0,0,0,0,0,0,0,17,6,6
6,6,10,0,0,0,0,0,0,0,0,0,0,0,0,0,0,0,0,0,0,10,6,6
6,6,17,0,0,0,0,0,0,0,0,0,0,0,0,0,0,0,0,0,0,17,6,6
6,6,7,17,10,10,17,6,6,17,10,10,17,7,17,10,17,10,17,10,17,7,6,6
6,6,6,6,6,6,6,6,6,6,6,6,6,6,6,6,6,6,6,6,6,6,6,6
6,6,6,6,6,6,6,6,6,6,6,6,6,6,6,6,6,6,6,6,6,6,6,6
endlayer

layer
6,6,6,6,6,6,6,6,6,6,6,6,6,6,6,6,6,6,6,6,6,6,6,6
6,6,6,6,6,6,6,6,6,6,6,6,6,6,6,6,6,6,6,6,6,6,6,6
6,6,7,17,10,10,17,10,10,17,10,10,17,7,17,10,17,10,17,10,17,7,6,6
6,6,17,0,0,0,0,0,0,0,0,0,32,32,32,0,0,0,0,0,0,17,6,6
6,6,10,0,0,0,0,0,0,0,0,0,32,0,32,0,0,0,0,0,0,10,6,6
6,6,17,0,0,0,0,0,0,0,0,0,32,32,32,0,0,0,0,0,0,17,6,6
6,6,10,0,0,0,0,0,0,0,0,0,0,0,0,0,0,0,0,0,0,10,6,6
6,6,17,0,0,0,0,0,0,0,0,0,0,0,0,0,0,0,0,0,0,17,6,6
6,6,10,0,0,0,0,0,0,0,0,0,0,0,0,0,0,0,0,0,0,10,6,6
6,6,17,0,0,0,0,0,0,0,0,0,0,0,0,0,0,0,0,0,0,17,6,6
6,6,7,17,10,10,17,10,10,17,10,10,17,7,17,10,17,10,17,10,17,7,6,6
6,6,6,6,6,6,6,6,6,6,6,6,6,6,6,6,6,6,6,6,6,6,6,6
6,6,6,6,6,6,6,6,6,6,6,6,6,6,6,6,6,6,6,6,6,6,6,6
endlayer

layer
6,6,6,6,6,6,6,6,6,6,6,6,6,6,6,6,6,6,6,6,6,6,6,6
6,6,6,6,6,6,6,6,6,6,6,6,6,6,6,6,6,6,6,6,6,6,6,6
6,6,7,17,10,10,17,10,10,17,10,10,17,7,17,10,17,10,17,10,17,7,6,6
6,6,17,0,0,0,0,0,0,0,0,0,33,33,33,0,0,0,0,0,0,17,6,6
6,6,10,0,0,0,0,0,0,0,0,0,33,0,33,0,0,0,0,0,0,10,6,6
6,6,17,0,0,0,0,0,0,0,0,0,33,33,33,0,0,0,0,0,0,17,6,6
6,6,10,0,0,0,0,0,0,0,0,0,0,0,0,0,0,0,0,0,0,10,6,6
6,6,17,0,0,0,0,0,0,0,0,0,0,0,0,0,0,0,0,0,0,17,6,6
6,6,10,0,0,0,0,0,0,0,0,0,0,0,0,0,0,0,0,0,0,10,6,6
6,6,17,0,0,0,0,0,0,0,0,0,0,0,0,0,0,0,0,0,0,17,6,6
6,6,7,17,10,10,17,10,10,17,10,10,17,7,17,10,17,10,17,10,17,7,6,6
6,6,6,6,6,6,6,6,6,6,6,6,6,6,6,6,6,6,6,6,6,6,6,6
6,6,6,6,6,6,6,6,6,6,6,6,6,6,6,6,6,6,6,6,6,6,6,6
endlayer

layer
6,6,6,6,6,6,6,6,6,6,6,6,6,6,6,6,6,6,6,6,6,6,6,6
6,6,6,6,6,6,6,6,6,6,6,6,6,6,6,6,6,6,6,6,6,6,6,6
6,6,7,17,10,10,17,10,10,17,10,10,17,7,17,10,17,10,17,10,17,7,6,6
6,6,17,0,0,0,0,0,0,0,0,0,34,34,34,0,0,0,0,0,0,17,6,6
6,6,10,0,0,0,0,0,0,0,0,0,34,0,34,0,0,0,0,0,0,10,6,6
6,6,17,0,0,0,0,0,0,0,0,0,34,34,34,0,0,0,0,0,0,17,6,6
6,6,10,0,0,0,0,0,0,0,0,0,0,0,0,0,0,0,0,0,0,10,6,6
6,6,17,0,0,0,0,0,0,0,0,0,0,0,0,0,0,0,0,0,0,17,6,6
6,6,10,0,0,0,0,0,0,0,0,0,0,0,0,0,0,0,0,0,0,10,6,6
6,6,17,0,0,0,0,0,0,0,0,0,0,0,0,0,0,0,0,0,0,17,6,6
6,6,7,17,10,10,17,10,10,17,10,10,17,7,17,10,17,10,17,10,17,7,6,6
6,6,6,6,6,6,6,6,6,6,6,6,6,6,6,6,6,6,6,6,6,6,6,6
6,6,6,6,6,6,6,6,6,6,6,6,6,6,6,6,6,6,6,6,6,6,6,6
endlayer

layer
6,6,6,6,6,6,6,6,6,6,6,6,6,6,6,6,6,6,6,6,6,6,6,6
6,6,6,6,6,6,6,6,6,6,6,6,6,6,6,6,6,6,6,6,6,6,6,6
6,6,7,17,10,10,17,10,10,17,10,10,17,7,17,10,17,10,17,10,17,7,6,6
6,6,17,0,0,0,0,0,0,0,0,0,35,35,35,0,0,0,0,0,0,17,6,6
6,6,10,0,0,0,0,0,0,0,0,0,35,35,35,0,0,0,0,0,0,10,6,6
6,6,17,0,0,0,0,0,0,0,0,0,35,35,35,0,0,0,0,0,0,17,6,6
6,6,10,0,0,0,0,0,0,0,0,0,0,0,0,0,0,0,0,0,0,10,6,6
6,6,17,0,0,0,0,0,0,0,0,0,0,0,0,0,0,0,0,0,0,17,6,6
6,6,10,0,0,0,0,0,0,0,0,0,0,0,0,0,0,0,0,0,0,10,6,6
6,6,17,0,0,0,0,0,0,0,0,0,0,0,0,0,0,0,0,0,0,17,6,6
6,6,7,17,10,10,17,10,10,17,10,10,17,7,17,10,17,10,17,10,17,7,6,6
6,6,6,6,6,6,6,6,6,6,6,6,6,6,6,6,6,6,6,6,6,6,6,6
6,6,6,6,6,6,6,6,6,6,6,6,6,6,6,6,6,6,6,6,6,6,6,6
endlayer

layer
6,6,6,6,6,6,6,6,6,6,6,6,6,6,6,6,6,6,6,6,6,6,6,6
6,6,6,6,6,6,6,6,6,6,6,6,6,6,6,6,6,6,6,6,6,6,6,6
6,6,7,7,7,7,7,7,7,7,7,7,7,7,7,7,7,7,7,7,7,7,6,6
6,6,7,23,23,23,23,23,23,23,23,23,23,7,22,22,22,22,22,22,22,7,6,6
6,6,7,23,23,23,23,23,23,23,23,23,23,7,22,22,22,22,22,22,22,7,6,6
6,6,7,23,23,23,23,23,23,23,23,23,23,7,22,22,22,22,22,22,22,7,6,6
6,6,7,23,23,23,23,23,23,23,23,23,23,7,22,22,22,22,22,22,22,7,6,6
6,6,7,23,23,23,23,23,23,23,23,23,23,7,22,22,22,22,22,22,22,7,6,6
6,6,7,23,23,23,23,23,23,23,23,23,23,7,22,22,22,22,22,22,22,7,6,6
6,6,7,23,23,23,23,23,23,23,23,23,23,7,22,22,22,22,22,22,3,7,6,6
6,6,7,7,7,7,7,7,7,7,7,7,7,7,7,7,7,7,7,7,7,7,6,6
6,6,6,6,6,6,6,6,6,6,6,6,6,6,6,6,6,6,6,6,6,6,6,6
6,6,6,6,6,6,6,6,6,6,6,6,6,6,6,6,6,6,6,6,6,6,6,6
endlayer

layer
21,21,21,21,21,21,21,21,21,21,21,21,21,21,21,21,21,21,21,21,21,21,21,21
21,21,21,21,21,21,21,21,21,21,21,21,21,21,21,21,21,21,21,21,21,21,21,21
21,21,21,21,21,21,21,21,21,21,21,21,21,7,17,10,17,10,17,10,17,7,21,21
21,21,21,21,21,21,21,21,21,21,21,21,21,17,0,0,0,0,0,0,12,17,21,21
21,21,21,21,28,27,21,21,21,21,21,21,21,10,0,0,0,0,0,0,0,10,21,21
21,21,21,21,27,27,21,21,21,21,21,21,21,17,0,0,24,0,0,0,0,17,21,21
21,21,21,21,21,21,29,29,21,21,21,21,21,10,0,26,25,0,0,0,0,10,21,21
21,21,21,21,21,21,29,29,21,21,21,21,21,17,0,0,24,8,0,0,0,17,21,21
21,21,21,21,21,21,21,21,21,21,27,21,21,10,0,0,0,0,0,0,0,10,21,21
21,21,21,21,21,21,21,21,21,21,21,21,21,17,0,0,0,0,0,0,0,17,21,21
21,21,21,21,21,21,21,21,21,21,21,21,21,7,17,10,17,10,17,10,17,7,21,21
21,21,21,21,21,21,21,21,21,21,21,21,21,21,21,21,21,21,21,21,21,21,21,21
21,21,21,21,21,21,21,21,21,21,21,21,21,21,21,21,21,21,21,21,21,21,21,21
endlayer

layer
0,0,0,0,0,0,0,0,0,0,0,0,0,0,0,0,0,0,0,0,0,0,0,0
0,0,0,0,0,0,0,0,0,0,0,0,0,0,0,0,0,0,0,0,0,0,0,0
0,0,0,0,0,0,0,0,0,0,0,0,0,7,17,10,17,10,17,10,17,7,0,0
0,0,0,0,0,0,0,0,0,0,0,0,0,17,0,0,0,0,0,0,0,17,0,0
0,0,0,0,27,27,0,0,0,0,0,0,0,10,0,0,0,0,0,0,0,10,0,0
0,0,0,0,28,27,0,0,0,0,0,0,0,17,0,0,0,0,0,0,0,17,0,0
0,0,0,0,0,0,0,0,0,0,0,0,0,10,0,0,0,0,0,0,0,10,0,0
0,0,0,0,0,0,0,0,0,0,0,0,0,17,0,0,0,0,0,0,0,17,0,0
0,0,0,0,0,0,0,0,0,0,27,0,0,10,0,0,0,0,0,0,0,10,0,0
0,0,0,0,0,0,0,0,0,0,0,0,0,17,0,0,0,0,0,0,0,17,0,0
0,0,0,0,0,0,0,0,0,0,0,0,0,7,17,10,17,10,17,10,17,7,0,0
0,0,0,0,0,0,0,0,0,0,0,0,0,0,0,0,0,0,0,0,0,0,0,0
0,0,0,0,0,0,0,0,0,0,0,0,0,0,0,0,0,0,0,0,0,0,0,0
endlayer

layer
0,0,0,0,0,0,0,0,0,0,0,0,0,0,0,0,0,0,0,0,0,0,0,0
0,0,0,0,0,0,0,0,0,0,0,0,0,0,0,0,0,0,0,0,0,0,0,0
0,0,0,0,0,0,0,0,0,0,0,0,0,7,17,10,17,10,17,10,17,7,0,0
0,0,0,0,0,0,0,0,0,0,0,0,0,17,0,0,0,0,0,0,0,17,0,0
0,0,0,0,27,27,0,0,0,0,0,0,0,10,0,0,0,0,0,0,0,10,0,0
0,0,0,0,27,28,0,0,0,0,0,0,0,17,0,0,0,0,0,0,0,17,0,0
0,0,0,0,0,0,0,0,0,0,0,0,0,10,0,0,0,0,0,0,0,10,0,0
0,0,0,0,0,0,0,0,0,0,0,0,0,17,0,0,0,0,0,0,0,17,0,0
0,0,0,0,0,0,0,0,0,0,27,0,0,10,0,0,0,0,0,0,0,10,0,0
0,0,0,0,0,0,0,0,0,0,0,0,0,17,0,0,0,0,0,0,0,17,0,0
0,0,0,0,0,0,0,0,0,0,0,0,0,7,17,10,17,10,17,10,17,7,0,0
0,0,0,0,0,0,0,0,0,0,0,0,0,0,0,0,0,0,0,0,0,0,0,0
0,0,0,0,0,0,0,0,0,0,0,0,0,0,0,0,0,0,0,0,0,0,0,0
endlayer

layer
0,0,0,0,0,0,0,0,0,0,0,0,0,0,0,0,0,0,0,0,0,0,0,0
0,0,0,0,0,0,0,0,0,0,0,0,0,0,0,0,0,0,0,0,0,0,0,0
0,0,0,0,0,0,0,0,0,0,0,0,0,7,17,10,17,10,17,10,17,7,0,0
0,0,0,0,0,0,0,0,0,0,0,0,0,17,0,0,0,0,0,0,0,17,0,0
0,0,0,0,27,28,0,0,0,0,0,0,0,10,0,0,0,0,0,0,0,10,0,0
0,0,0,0,27,27,0,0,0,0,0,0,0,17,0,0,0,0,0,0,0,17,0,0
0,0,0,0,0,0,0,0,0,0,0,0,0,10,0,0,0,0,0,0,0,10,0,0
0,0,0,0,0,0,0,0,0,0,0,0,0,17,0,0,0,0,0,0,0,17,0,0
0,0,0,0,0,0,0,0,0,0,28,0,0,10,0,0,0,0,0,0,0,10,0,0
0,0,0,0,0,0,0,0,0,0,0,0,0,17,0,0,0,0,0,0,0,17,0,0
0,0,0,0,0,0,0,0,0,0,0,0,0,7,17,10,17,10,17,10,17,7,0,0
0,0,0,0,0,0,0,0,0,0,0,0,0,0,0,0,0,0,0,0,0,0,0,0
0,0,0,0,0,0,0,0,0,0,0,0,0,0,0,0,0,0,0,0,0,0,0,0
endlayer

layer
0,0,0,0,0,0,0,0,0,0,0,0,0,0,0,0,0,0,0,0,0,0,0,0
0,0,0,0,0,0,0,0,0,0,0,0,0,0,0,0,0,0,0,0,0,0,0,0
0,0,0,0,0,0,0,0,0,0,0,0,0,7,17,10,17,10,17,10,17,7,0,0
0,0,0,0,0,0,0,0,0,0,0,0,0,17,0,0,0,0,0,0,0,17,0,0
0,0,0,0,28,27,0,0,0,0,0,0,0,10,0,0,0,0,0,0,0,10,0,0
0,0,0,0,27,27,0,0,0,0,0,0,0,17,0,0,0,0,0,0,0,17,0,0
0,0,0,0,0,0,0,0,0,0,0,0,0,10,0,0,0,0,0,0,0,10,0,0
0,0,0,0,0,0,0,0,0,0,0,0,0,17,0,0,0,0,0,0,0,17,0,0
0,0,0,0,0,0,0,0,0,0,27,0,0,10,0,0,0,0,0,0,0,10,0,0
0,0,0,0,0,0,0,0,0,0,0,0,0,17,0,0,0,0,0,0,0,17,0,0
0,0,0,0,0,0,0,0,0,0,0,0,0,7,17,10,17,10,17,10,17,7,0,0
0,0,0,0,0,0,0,0,0,0,0,0,0,0,0,0,0,0,0,0,0,0,0,0
0,0,0,0,0,0,0,0,0,0,0,0,0,0,0,0,0,0,0,0,0,0,0,0
endlayer

layer
0,0,0,0,0,0,0,0,0,0,0,0,0,0,0,0,0,0,0,0,0,0,0,0
0,0,0,0,0,0,0,0,0,0,0,0,0,0,0,0,0,0,0,0,0,0,0,0
0,0,0,0,0,0,0,0,0,0,0,0,0,7,17,10,17,10,17,10,17,7,0,0
0,0,0,0,0,0,0,0,0,0,0,0,0,17,0,0,0,0,0,0,0,17,0,0
0,0,0,0,27,27,0,0,0,0,0,0,0,10,0,0,0,0,0,0,0,10,0,0
0,0,0,0,28,27,0,0,0,0,0,0,0,17,0,0,0,0,0,0,0,17,0,0
0,0,0,0,0,0,0,0,0,0,0,0,0,10,0,0,0,0,0,0,0,10,0,0
0,0,0,0,0,0,0,0,0,0,0,0,0,17,0,0,0,0,0,0,0,17,0,0
0,0,0,0,0,0,0,0,0,0,27,0,0,10,0,0,0,0,0,0,0,10,0,0
0,0,0,0,0,0,0,0,0,0,0,0,0,17,0,0,0,0,0,0,0,17,0,0
0,0,0,0,0,0,0,0,0,0,0,0,0,7,17,10,17,10,17,10,17,7,0,0
0,0,0,0,0,0,0,0,0,0,0,0,0,0,0,0,0,0,0,0,0,0,0,0
0,0,0,0,0,0,0,0,0,0,0,0,0,0,0,0,0,0,0,0,0,0,0,0
endlayer

layer
0,0,0,0,0,0,0,0,0,0,0,0,0,0,0,0,0,0,0,0,0,0,0,0
0,0,0,0,0,0,0,0,0,0,0,0,0,0,0,0,0,0,0,0,0,0,0,0
0,0,0,0,0,0,0,0,0,0,0,0,0,7,17,10,17,10,17,10,17,7,0,0
0,0,0,0,0,0,0,0,0,0,0,0,0,17,0,0,0,0,0,0,0,17,0,0
0,0,0,0,27,27,0,0,0,0,0,0,0,10,0,0,0,0,0,0,0,10,0,0
0,0,0,0,27,28,0,0,0,0,0,0,0,17,0,0,0,0,0,0,0,17,0,0
0,0,0,0,0,0,0,0,0,0,0,0,0,10,0,0,0,0,0,0,0,10,0,0
0,0,0,0,0,0,0,0,0,0,0,0,0,17,0,0,0,0,0,0,0,17,0,0
0,0,0,0,0,0,0,0,0,0,0,0,0,10,0,0,0,0,0,0,0,10,0,0
0,0,0,0,0,0,0,0,0,0,0,0,0,17,0,0,0,0,0,0,0,17,0,0
0,0,0,0,0,0,0,0,0,0,0,0,0,7,17,10,17,10,17,10,17,7,0,0
0,0,0,0,0,0,0,0,0,0,0,0,0,0,0,0,0,0,0,0,0,0,0,0
0,0,0,0,0,0,0,0,0,0,0,0,0,0,0,0,0,0,0,0,0,0,0,0
endlayer

layer
0,0,0,0,0,0,0,0,0,0,0,0,0,0,0,0,0,0,0,0,0,0,0,0
0,0,0,0,0,0,0,0,0,0,0,0,0,0,0,0,0,0,0,0,0,0,0,0
0,0,0,0,0,0,0,0,0,0,0,0,0,7,7,7,7,7,7,7,7,7,0,0
0,0,0,0,0,0,0,0,0,0,0,0,0,7,23,23,23,23,23,23,23,7,0,0
0,0,0,0,27,28,0,0,0,0,0,0,0,7,23,23,23,23,23,23,23,7,0,0
0,0,0,0,27,27,0,0,0,0,0,0,0,7,23,23,23,23,23,23,23,7,0,0
0,0,0,0,0,0,0,0,0,0,0,0,0,7,23,23,23,23,23,23,23,7,0,0
0,0,0,0,0,0,0,0,0,0,0,0,0,7,23,23,23,23,23,23,23,7,0,0
0,0,0,0,0,0,0,0,0,0,0,0,0,7,23,23,23,23,23,23,23,7,0,0
0,0,0,0,0,0,0,0,0,0,0,0,0,7,23,23,23,23,23,23,23,7,0,0
0,0,0,0,0,0,0,0,0,0,0,0,0,7,7,7,7,7,7,7,7,7,0,0
0,0,0,0,0,0,0,0,0,0,0,0,0,0,0,0,0,0,0,0,0,0,0,0
0,0,0,0,0,0,0,0,0,0,0,0,0,0,0,0,0,0,0,0,0,0,0,0
endlayer

layer
0,0,0,0,0,0,0,0,0,0,0,0,0,0,0,0,0,0,0,0,0,0,0,0
0,0,0,0,0,0,0,0,0,0,0,0,0,0,0,0,0,0,0,0,0,0,0,0
0,0,0,0,0,0,0,0,0,0,0,0,0,0,0,0,0,0,0,0,0,0,0,0
0,0,0,0,0,0,0,0,0,0,0,0,0,0,0,0,0,0,0,0,0,0,0,0
0,0,0,0,0,0,0,0,0,0,0,0,0,0,0,0,0,0,0,0,0,0,0,0
0,0,0,0,0,0,0,0,0,0,0,0,0,0,0,0,0,29,29,0,0,0,0,0
0,0,0,0,0,0,0,0,0,0,0,0,0,0,0,0,0,29,29,0,0,0,0,0
0,0,0,0,0,0,0,0,0,0,0,0,0,0,0,0,0,0,0,0,0,0,0,0
0,0,0,0,0,0,0,0,0,0,0,0,0,0,0,0,0,0,0,0,0,0,0,0
0,0,0,0,0,0,0,0,0,0,0,0,0,0,0,0,0,0,0,0,0,0,0,0
0,0,0,0,0,0,0,0,0,0,0,0,0,0,0,0,0,0,0,0,0,0,0,0
0,0,0,0,0,0,0,0,0,0,0,0,0,0,0,0,0,0,0,0,0,0,0,0
0,0,0,0,0,0,0,0,0,0,0,0,0,0,0,0,0,0,0,0,0,0,0,0
endlayer
