# Converted from schematic
# THIS TEMPLATE USES DEFAULTS!  Please edit for corrections.
# If you need help, consult template_rules.txt

weight=10
embed_into_distance=5
acceptable_target_blocks=1,2,3,12,13,250
dimensions=11,15,21
allowable_overhang=0
max_cut_in=2
cut_in_buffer=1
max_leveling=2
leveling_buffer=1
preserve_water=0
preserve_lava=0
preserve_plants=0


rule1=0,100,3134-2
rule2=0,100,2843-4
rule3=0,100,308,308,308,308,308,308,313,313,314,327
rule4=0,100,2838-15
rule5=0,100,2838
rule6=0,100,113
rule7=0,100,2843-14,2843-14,2843-14,2843-14,2843
rule8=0,100,2788-9
rule9=0,100,2252
rule10=0,100,54,54,54,54,54,54,54,54,54,54,54,54,54,54,54,54,54,54,54,311,311,311,311,311,309,310
rule11=0,100,96-11
rule12=0,100,4094-10
rule13=0,100,4094
rule14=0,100,2838-14
rule15=0,100,3225-3
rule16=0,95,2835-2,2835-2,2835-2,2835-2,2835-2,2835-2,2835-2,2835-1,2835-1,2835-0
rule17=0,10,0
rule18=0,100,3134,3134,3134,3134-8,3134-2
rule19=0,100,2843-13
rule20=0,100,2010
rule21=0,100,2843-12
rule22=0,100,2838-12
rule23=0,99,300


layer
1,1,1,1,1,1,1,1,1,1,1,1,1,1,1,1,1,1,1,1,1
1,1,1,1,1,1,1,1,1,1,1,1,1,1,1,1,1,1,1,1,1
1,1,1,1,1,1,1,1,1,1,1,1,1,1,1,1,1,1,1,1,1
1,1,1,2,2,2,2,2,2,2,2,1,1,1,1,1,1,1,1,1,1
1,1,1,3,2,2,2,2,2,2,2,1,1,1,1,1,1,1,1,1,1
1,1,1,4,2,2,2,2,2,2,2,1,1,1,1,1,1,1,1,1,1
1,1,1,4,2,2,2,2,2,2,2,1,1,1,1,1,1,1,1,1,1
1,1,1,4,2,2,2,2,2,2,2,1,1,1,1,1,1,1,1,1,1
1,1,1,4,2,2,2,2,2,2,2,1,1,1,1,1,1,1,1,1,1
1,1,1,4,2,2,2,2,2,2,2,1,1,1,1,1,1,1,1,1,1
1,1,1,3,2,2,2,2,2,2,2,1,1,1,1,1,1,1,1,1,1
1,1,1,2,2,2,2,2,2,2,2,1,1,1,1,1,1,1,1,1,1
1,1,1,1,1,1,1,1,1,1,1,1,1,1,1,1,1,1,1,1,1
1,1,1,1,1,1,1,1,1,1,1,1,1,1,1,1,1,1,1,1,1
1,1,1,1,1,1,1,1,1,1,1,1,1,1,1,1,1,1,1,1,1
endlayer

layer
23,23,23,23,23,23,23,23,23,23,23,23,23,23,23,23,23,23,5,23,23
23,23,23,23,23,23,23,23,23,23,23,23,23,23,23,23,23,23,23,23,23
23,23,23,23,23,23,23,23,23,23,23,23,23,23,23,23,23,23,23,23,23
23,7,7,7,7,7,7,7,7,7,7,23,23,23,23,23,23,23,23,23,23
23,7,4,4,0,0,11,0,0,0,7,23,23,23,23,6,23,23,23,23,23
23,7,4,12,0,0,8,8,8,8,7,23,23,23,23,4,23,23,23,23,23
23,7,4,13,0,0,0,0,0,23,7,23,23,23,23,23,23,23,23,23,23
23,7,4,4,0,0,0,0,23,23,23,23,23,23,23,23,23,23,23,23,23
23,7,4,12,0,0,9,0,9,23,7,23,23,23,23,23,23,23,23,23,23
23,7,4,13,0,0,0,0,0,23,7,23,23,23,23,4,23,23,23,23,23
23,7,4,4,0,0,10,0,10,0,7,23,23,23,23,6,23,23,23,23,23
23,7,7,7,7,7,7,7,7,7,7,23,23,23,23,23,23,23,23,23,23
23,23,23,23,23,23,23,23,23,23,23,23,23,23,23,23,23,23,23,23,23
23,23,23,23,23,23,23,23,23,23,23,23,23,23,23,23,23,23,23,23,23
23,23,23,23,23,23,23,23,23,23,23,23,23,23,23,23,23,23,23,23,23
endlayer

layer
23,23,23,23,23,23,23,23,23,23,23,23,23,23,23,23,23,23,6,23,23
23,23,23,23,23,23,23,23,23,23,23,23,23,23,23,23,23,23,23,23,23
23,23,23,23,23,23,23,23,23,23,23,23,23,23,23,23,23,23,23,23,23
23,7,16,16,16,16,16,16,16,16,7,23,23,23,23,23,23,23,23,23,23
23,16,4,4,0,0,0,0,0,0,15,23,23,23,23,6,23,23,23,23,23
23,16,4,12,0,0,0,0,0,0,15,23,23,23,23,14,23,23,23,23,23
23,16,4,13,0,0,0,0,0,0,15,23,23,23,23,23,23,23,23,23,23
23,16,10,4,0,0,0,0,0,0,0,23,23,23,23,23,23,23,23,23,23
23,16,4,12,0,0,9,0,9,0,15,23,23,23,23,23,23,23,23,23,23
23,16,4,13,0,0,0,0,0,0,15,23,23,23,23,14,23,23,23,23,23
23,16,4,4,0,0,0,0,0,0,15,23,23,23,23,6,23,23,23,23,23
23,7,16,16,16,16,16,16,16,16,7,23,23,23,23,23,23,23,23,23,23
23,23,23,23,23,23,23,23,23,23,23,23,23,23,23,23,23,23,23,23,23
23,23,23,23,23,23,23,23,23,23,23,23,23,23,23,23,23,23,23,23,23
23,23,23,23,23,23,23,23,23,23,23,23,23,23,23,23,23,23,23,23,23
endlayer

layer
23,23,23,23,23,23,23,23,23,23,23,23,23,23,23,23,23,23,6,23,23
23,23,23,23,23,23,23,23,23,23,23,23,23,23,23,23,23,23,23,23,23
23,23,23,23,23,23,23,23,23,23,23,23,23,23,23,23,23,23,23,23,23
23,7,16,16,16,16,16,16,16,16,7,23,23,23,23,23,23,23,23,23,23
23,16,4,4,0,0,0,0,0,0,15,23,23,23,23,6,23,23,23,23,23
23,16,4,4,0,0,0,0,0,0,15,23,23,23,23,23,23,23,23,23,23
23,16,4,4,0,0,0,0,0,0,15,23,23,23,23,23,23,23,23,23,23
23,16,4,4,0,0,0,0,0,0,16,23,23,23,23,23,23,23,23,23,23
23,16,4,4,0,0,0,0,0,0,15,23,23,23,23,23,23,23,23,23,23
23,16,4,4,0,0,0,0,0,0,15,23,23,23,23,23,23,23,23,23,23
23,16,4,4,0,0,0,0,0,0,15,23,23,23,23,6,23,23,23,23,23
23,7,16,16,16,16,16,16,16,16,7,23,23,23,23,23,23,23,23,23,23
23,23,23,23,23,23,23,23,23,23,23,23,23,23,23,23,23,23,23,23,23
23,23,23,23,23,23,23,23,23,23,23,23,23,23,23,23,23,23,23,23,23
23,23,23,23,23,23,23,23,23,23,23,23,23,23,23,23,23,23,23,23,23
endlayer

layer
23,23,23,23,23,23,23,23,23,23,23,23,23,23,23,23,23,23,6,23,23
23,23,23,23,23,23,23,23,23,23,23,23,23,23,23,23,23,23,23,23,23
23,23,23,23,23,23,23,23,23,23,23,23,23,23,23,23,23,23,23,23,23
23,7,16,16,16,16,16,16,16,16,7,23,23,23,23,23,23,23,23,23,23
23,16,16,16,0,0,0,0,0,0,15,23,23,23,23,6,23,23,23,23,23
23,16,16,16,0,17,0,0,17,0,15,23,23,23,23,23,23,23,23,23,23
23,16,16,16,0,0,0,0,0,0,15,23,23,23,23,23,23,23,23,23,23
23,16,16,16,0,0,0,0,0,0,16,23,23,23,23,23,23,23,23,23,23
23,16,16,16,0,0,0,0,0,0,15,23,23,23,23,23,23,23,23,23,23
23,16,16,16,0,17,0,0,17,0,15,23,23,23,23,23,23,23,23,23,23
23,16,16,16,0,0,0,0,0,0,15,23,23,23,23,6,23,23,23,23,23
23,7,16,16,16,16,16,16,16,16,7,23,23,23,23,23,23,23,23,23,23
23,23,23,23,23,23,23,23,23,23,23,23,23,23,23,23,23,23,23,23,23
23,23,23,23,23,23,23,23,23,23,23,23,23,23,23,23,23,23,23,23,23
23,23,23,23,23,23,23,23,23,23,23,23,23,23,23,23,23,23,23,23,23
endlayer

layer
0,0,0,0,0,0,0,0,0,0,0,0,0,0,0,0,0,0,6,0,0
0,0,0,0,0,0,0,0,0,0,0,0,0,0,0,0,0,0,0,0,0
0,0,0,0,0,0,0,0,0,0,0,0,0,0,0,0,0,0,0,0,0
0,7,7,7,7,7,7,7,7,7,7,0,0,0,0,0,0,0,0,0,0
0,7,18,18,18,18,18,18,18,18,7,0,0,0,0,6,0,0,0,0,0
0,7,18,18,18,18,18,18,18,18,7,0,0,0,0,0,0,0,0,0,0
0,7,18,18,18,18,18,18,18,18,7,0,0,0,0,0,0,0,0,0,0
0,7,18,18,18,18,18,18,18,18,7,0,0,0,0,0,0,0,0,0,0
0,7,18,18,18,18,18,18,18,18,7,0,0,0,0,0,0,0,0,0,0
0,7,18,18,18,18,18,18,18,18,7,0,0,0,0,0,0,0,0,0,0
0,7,18,18,18,18,18,18,18,18,7,0,0,0,0,6,0,0,0,0,0
0,7,7,7,7,7,7,7,7,7,7,0,0,0,0,0,0,0,0,0,0
0,0,0,0,0,0,0,0,0,0,0,0,0,0,0,0,0,0,0,0,0
0,0,0,0,0,0,0,0,0,0,0,0,0,0,0,0,0,0,0,0,0
0,0,0,0,0,0,0,0,0,0,0,0,0,0,0,0,0,0,0,0,0
endlayer

layer
0,0,0,0,0,0,0,0,0,0,0,0,0,0,0,0,0,0,6,0,0
0,0,0,0,0,0,0,0,0,0,0,0,0,0,0,0,0,0,0,0,0
0,0,0,0,0,0,0,0,0,0,0,0,0,0,0,0,0,0,0,0,0
0,0,0,0,0,0,0,0,0,0,0,0,0,0,0,0,0,0,0,0,0
0,0,0,0,0,0,0,0,0,0,0,0,0,19,19,19,19,19,0,0,0
0,0,0,0,0,0,0,0,0,0,0,0,0,19,20,19,20,19,0,0,0
0,0,0,0,0,0,0,0,0,0,0,0,0,19,19,19,19,19,0,0,0
0,0,0,0,0,0,0,0,0,0,0,0,0,19,19,19,19,19,0,0,0
0,0,0,0,0,0,0,0,0,0,0,0,0,19,19,19,19,19,0,0,0
0,0,0,0,0,0,0,0,0,0,0,0,0,19,20,19,20,19,0,0,0
0,0,0,0,0,0,0,0,0,0,0,0,0,19,19,19,19,19,0,0,0
0,0,0,0,0,0,0,0,0,0,0,0,0,0,0,0,0,0,0,0,0
0,0,0,0,0,0,0,0,0,0,0,0,0,0,0,0,0,0,0,0,0
0,0,0,0,0,0,0,0,0,0,0,0,0,0,0,0,0,0,0,0,0
0,0,0,0,0,0,0,0,0,0,0,0,0,0,0,0,0,0,0,0,0
endlayer

layer
0,0,0,0,0,0,0,0,0,0,0,0,0,0,0,0,0,0,6,0,0
0,0,0,0,0,0,0,0,0,0,0,0,0,0,0,0,0,0,0,0,0
0,0,0,0,0,0,0,0,0,0,0,0,0,0,0,0,0,0,0,0,0
0,0,0,0,0,0,0,0,0,0,0,0,0,0,0,0,0,0,0,0,0
0,0,0,0,0,0,0,0,0,0,0,0,0,0,0,0,0,0,0,0,0
0,0,0,0,0,0,0,0,0,0,0,0,0,0,0,0,0,0,0,0,0
0,0,0,0,0,0,0,0,0,0,0,0,0,0,0,0,0,0,0,0,0
0,0,0,0,0,0,0,0,0,0,0,0,0,0,0,0,0,0,0,0,0
0,0,0,0,0,0,0,0,0,0,0,0,0,0,0,0,0,0,0,0,0
0,0,0,0,0,0,0,0,0,0,0,0,0,0,0,0,0,0,0,0,0
0,0,0,0,0,0,0,0,0,0,0,0,0,0,0,0,0,0,0,0,0
0,0,0,0,0,0,0,0,0,0,0,0,0,0,0,0,0,0,0,0,0
0,0,0,0,0,0,0,0,0,0,0,0,0,0,0,0,0,0,0,0,0
0,0,0,0,0,0,0,0,0,0,0,0,0,0,0,0,0,0,0,0,0
0,0,0,0,0,0,0,0,0,0,0,0,0,0,0,0,0,0,0,0,0
endlayer

layer
0,0,0,0,0,0,0,0,0,0,0,0,0,0,0,0,0,21,21,21,0
0,0,0,0,0,0,0,0,0,0,0,0,0,0,0,0,0,0,0,0,0
0,0,0,0,0,0,0,0,0,0,0,0,0,0,0,0,0,0,0,0,0
0,0,0,0,0,0,0,0,0,0,0,0,0,0,0,0,0,0,0,0,0
0,0,0,0,0,0,0,0,0,0,0,0,0,0,0,0,0,0,0,0,0
0,0,0,0,0,0,0,0,0,0,0,0,0,0,0,0,0,0,0,0,0
0,0,0,0,0,0,0,0,0,0,0,0,0,0,0,0,0,0,0,0,0
0,0,0,0,0,0,0,0,0,0,0,0,0,0,0,0,0,0,0,0,0
0,0,0,0,0,0,0,0,0,0,0,0,0,0,0,0,0,0,0,0,0
0,0,0,0,0,0,0,0,0,0,0,0,0,0,0,0,0,0,0,0,0
0,0,0,0,0,0,0,0,0,0,0,0,0,0,0,0,0,0,0,0,0
0,0,0,0,0,0,0,0,0,0,0,0,0,0,0,0,0,0,0,0,0
0,0,0,0,0,0,0,0,0,0,0,0,0,0,0,0,0,0,0,0,0
0,0,0,0,0,0,0,0,0,0,0,0,0,0,0,0,0,0,0,0,0
0,0,0,0,0,0,0,0,0,0,0,0,0,0,0,0,0,0,0,0,0
endlayer

layer
0,0,0,0,0,0,0,0,0,0,0,0,0,0,0,0,21,22,22,22,21
0,0,0,0,0,0,0,0,0,0,0,0,0,0,0,0,0,0,0,0,0
0,0,0,0,0,0,0,0,0,0,0,0,0,0,0,0,0,0,0,0,0
0,0,0,0,0,0,0,0,0,0,0,0,0,0,0,0,0,0,0,0,0
0,0,0,0,0,0,0,0,0,0,0,0,0,0,0,0,0,0,0,0,0
0,0,0,0,0,0,0,0,0,0,0,0,0,0,0,0,0,0,0,0,0
0,0,0,0,0,0,0,0,0,0,0,0,0,0,0,0,0,0,0,0,0
0,0,0,0,0,0,0,0,0,0,0,0,0,0,0,0,0,0,0,0,0
0,0,0,0,0,0,0,0,0,0,0,0,0,0,0,0,0,0,0,0,0
0,0,0,0,0,0,0,0,0,0,0,0,0,0,0,0,0,0,0,0,0
0,0,0,0,0,0,0,0,0,0,0,0,0,0,0,0,0,0,0,0,0
0,0,0,0,0,0,0,0,0,0,0,0,0,0,0,0,0,0,0,0,0
0,0,0,0,0,0,0,0,0,0,0,0,0,0,0,0,0,0,0,0,0
0,0,0,0,0,0,0,0,0,0,0,0,0,0,0,0,0,0,0,0,0
0,0,0,0,0,0,0,0,0,0,0,0,0,0,0,0,0,0,0,0,0
endlayer

layer
0,0,0,0,0,0,0,0,0,0,0,0,0,0,0,0,0,21,21,21,0
0,0,0,0,0,0,0,0,0,0,0,0,0,0,0,0,0,0,0,0,0
0,0,0,0,0,0,0,0,0,0,0,0,0,0,0,0,0,0,0,0,0
0,0,0,0,0,0,0,0,0,0,0,0,0,0,0,0,0,0,0,0,0
0,0,0,0,0,0,0,0,0,0,0,0,0,0,0,0,0,0,0,0,0
0,0,0,0,0,0,0,0,0,0,0,0,0,0,0,0,0,0,0,0,0
0,0,0,0,0,0,0,0,0,0,0,0,0,0,0,0,0,0,0,0,0
0,0,0,0,0,0,0,0,0,0,0,0,0,0,0,0,0,0,0,0,0
0,0,0,0,0,0,0,0,0,0,0,0,0,0,0,0,0,0,0,0,0
0,0,0,0,0,0,0,0,0,0,0,0,0,0,0,0,0,0,0,0,0
0,0,0,0,0,0,0,0,0,0,0,0,0,0,0,0,0,0,0,0,0
0,0,0,0,0,0,0,0,0,0,0,0,0,0,0,0,0,0,0,0,0
0,0,0,0,0,0,0,0,0,0,0,0,0,0,0,0,0,0,0,0,0
0,0,0,0,0,0,0,0,0,0,0,0,0,0,0,0,0,0,0,0,0
0,0,0,0,0,0,0,0,0,0,0,0,0,0,0,0,0,0,0,0,0
endlayer

