# Converted from schematic
# THIS TEMPLATE USES DEFAULTS!  Please edit for corrections.
# If you need help, consult template_rules.txt

weight=20
embed_into_distance=5
acceptable_target_blocks=1,2,3,12,13,250
dimensions=9,9,10
allowable_overhang=0
max_cut_in=2
cut_in_buffer=1
max_leveling=2
leveling_buffer=1
preserve_water=0
preserve_lava=0
preserve_plants=0


rule1=0,100,2843-4
rule2=0,100,2542
rule3=0,100,308,308,308,308,308,308,313,313,314,327
rule4=0,100,2843-14,2843-14,2843-14,2843-14,2843
rule5=0,95,2835-2,2835-2,2835-2,2835-2,2835-2,2835-2,2835-2,2835-1,2835-1,2835-0
rule6=0,100,350
rule7=0,100,2291-1
rule8=0,100,2245-1,2245-1,2245-1,2245-1,2245-1,2245-1,2245-1,2245-1,311
rule9=0,100,2761-2
rule10=0,100,2763-4
rule11=0,25,3225-3
rule12=0,100,2013-1,2013-2,2013-3,2013-4,2013-5,2013-6,2013-7,2013-8,2013-9,2013-10,2013-11,2013-12,2013-13,2013-14,2013-15
rule13=0,100,2013
rule14=0,100,2802-3
rule15=0,100,3134,3134,3134,3134-8,3134-2
rule16=0,65,2242
rule17=0,65,140-10



layer
1,1,1,1,1,1,1,1,1,1
1,1,1,1,1,1,1,1,1,1
1,1,1,1,1,1,1,2,1,1
1,1,1,1,1,1,1,1,1,1
1,1,1,1,1,1,1,1,1,1
1,1,1,1,1,1,1,1,1,1
1,1,1,1,1,1,1,1,1,1
1,1,1,1,1,1,1,1,1,1
1,1,1,1,3,1,1,1,1,1
endlayer

layer
4,5,5,5,4,5,5,5,5,4
5,6,0,0,0,0,0,0,0,5
6,6,6,0,0,0,0,0,0,5
5,6,0,0,0,0,0,0,0,5
4,9,0,0,0,0,0,0,6,5
5,10,0,0,0,0,0,0,0,5
5,10,0,0,0,7,8,8,7,5
5,9,0,0,0,7,8,8,7,5
4,5,5,5,4,5,5,5,5,4
endlayer

layer
4,5,11,5,4,5,11,11,5,4
5,0,0,0,0,0,0,0,0,5
6,6,0,0,0,0,0,0,0,11
5,0,0,0,0,0,0,0,0,5
4,0,0,0,0,0,0,0,0,11
5,0,0,0,0,0,0,0,0,5
11,0,0,0,0,0,0,0,0,11
5,0,0,0,0,0,0,17,0,5
4,5,11,5,4,5,11,11,5,4
endlayer

layer
4,5,11,5,4,5,11,11,5,4
5,0,0,0,0,0,0,0,0,5
5,0,0,0,0,0,0,0,0,11
5,0,0,0,0,0,0,0,0,5
4,0,0,0,0,0,0,0,0,11
5,0,0,0,0,0,0,0,0,5
11,0,0,0,0,0,0,0,0,11
5,0,0,0,0,0,0,0,0,5
4,5,11,5,4,5,11,11,5,4
endlayer

layer
4,4,4,4,4,4,4,4,4,4
4,1,1,1,1,1,1,1,1,4
4,1,1,1,1,1,1,2,1,4
4,1,1,1,1,1,1,1,1,4
4,1,1,1,1,1,1,1,1,4
4,1,1,1,1,1,1,1,1,4
4,1,1,1,1,1,1,1,1,4
4,1,1,1,1,1,1,1,1,4
4,4,4,4,4,4,4,4,4,4
endlayer

layer
0,0,0,0,0,0,0,0,0,0
0,4,5,5,5,5,5,5,4,0
0,5,15,0,0,0,0,0,5,0
0,5,0,0,0,0,0,0,5,0
0,4,0,5,4,0,0,0,5,0
14,0,0,0,5,0,12,0,5,0
14,0,0,0,5,8,13,8,5,0
14,0,0,0,4,5,5,5,4,0
14,14,14,14,0,0,0,0,0,0
endlayer

layer
0,0,0,0,0,0,0,0,0,0
0,4,5,11,5,5,11,5,4,0
0,11,0,0,0,0,0,0,5,0
0,11,0,0,0,0,0,0,11,0
0,4,0,5,4,0,0,0,5,0
0,0,0,0,5,0,0,0,11,0
0,0,0,0,5,17,0,16,5,0
0,0,0,0,4,5,11,5,4,0
0,0,0,0,0,0,0,0,0,0
endlayer

layer
0,0,0,0,0,0,0,0,0,0
0,4,5,11,5,5,11,5,4,0
0,11,0,0,0,0,0,0,5,0
0,11,0,0,0,0,0,0,11,0
0,4,5,5,4,0,0,0,5,0
0,0,0,0,5,0,0,0,11,0
0,0,0,0,5,0,0,0,5,0
0,0,0,0,4,5,11,5,4,0
0,0,0,0,0,0,0,0,0,0
endlayer

layer
0,0,0,0,0,0,0,0,0,0
0,4,4,4,4,4,4,4,4,0
0,4,15,15,15,15,15,15,4,0
0,4,15,15,15,15,15,15,4,0
0,4,4,4,4,15,15,15,4,0
0,0,0,0,4,15,15,15,4,0
0,0,0,0,4,15,15,15,4,0
0,0,0,0,4,4,4,4,4,0
0,0,0,0,0,0,0,0,0,0
endlayer

