# Converted from schematic
# THIS TEMPLATE USES DEFAULTS!  Please edit for corrections.
# If you need help, consult template_rules.txt

weight=40
embed_into_distance=8
acceptable_target_blocks=1,2,3,12,13,250
dimensions=20,32,38
allowable_overhang=0
max_cut_in=2
cut_in_buffer=1
max_leveling=2
leveling_buffer=1
preserve_water=0
preserve_lava=0
preserve_plants=0


rule1=0,100,250
rule2=0,100,2843-4
rule3=0,100,2504-15
rule4=0,100,2291-3
rule5=0,100,3230-1
rule6=0,100,2765-12
rule7=0,100,1476-3
rule8=0,100,2514
rule9=0,100,2761
rule10=0,100,3134-10
rule11=0,100,308,308,308,308,308,308,313,313,314,327
rule12=0,100,2542
rule13=0,100,2843-14,2843-14,2843-14,2843-14,2843
rule14=0,100,2788-9
rule15=0,100,2245-3
rule16=0,100,2291
rule17=0,100,2245
rule18=0,100,2838-15
rule19=0,100,2787-15
rule20=0,100,744
rule21=0,100,2761-5
rule22=0,100,96-11
rule23=0,100,2762-9
rule24=0,100,2761-4
rule25=0,100,2761-10
rule26=0,100,3192
rule27=0,100,25
rule28=0,100,2249-2
rule29=0,100,2843-10
rule30=0,100,54,54,54,54,54,54,54,54,54,54,54,54,54,54,54,54,54,54,54,311,311,311,311,311,309,310
rule31=0,100,4094-4
rule32=0,25,3225-3
rule33=0,100,2250-2
rule34=0,100,2254-2
rule35=0,95,2835-2,2835-2,2835-2,2835-2,2835-2,2835-2,2835-2,2835-1,2835-1,2835-0
rule36=0,100,2838-14
rule37=0,100,2787-11
rule38=0,100,2762-10
rule39=0,100,2249-6
rule40=0,100,2249-3
rule41=0,100,2255-6
rule42=0,100,154
rule43=0,100,2249-7
rule44=0,100,2843-12
rule45=0,100,113
rule46=0,100,23-3
rule47=0,100,3133-11
rule48=0,100,902-3
rule49=0,100,3134,3134,3134,3134,3134,3134,3134,3134,3134,3134-8,3134-2
rule50=0,100,2838-13
rule51=0,100,311
rule52=0,100,125-9
rule53=0,100,126-9
rule54=0,100,2013-1,2013-2,2013-3,2013-4,2013-5,2013-6,2013-7,2013-8,2013-9,2013-10,2013-11,2013-12,2013-13,2013-14,2013-15
rule55=0,100,2013
rule56=0,100,140-10
rule57=0,100,3134,3134,3134,3134,3134,3134,3134,3134,3134,3134-2
rule58=0,99,300


layer
1,1,1,1,1,1,1,1,1,1,1,1,1,1,1,1,1,1,1,1,1,1,1,1,1,1,1,1,1,1,1,1,1,1,1,1,1,1
1,1,1,1,1,1,1,1,1,1,1,1,1,1,1,1,1,1,1,1,1,1,1,1,1,1,1,1,1,1,1,1,1,1,1,1,1,1
1,1,1,1,1,1,1,1,1,1,1,1,1,1,1,1,1,1,1,1,1,1,1,1,1,1,1,1,1,1,1,1,1,1,1,1,1,1
1,1,1,1,1,1,1,1,1,1,1,2,2,2,1,1,1,1,1,1,1,1,1,1,1,1,1,1,1,1,1,1,1,1,1,1,1,1
1,1,1,1,1,1,1,1,1,1,1,2,2,2,1,1,1,1,1,1,1,1,1,1,1,1,1,1,1,1,1,1,1,1,1,1,1,1
1,1,1,1,1,1,1,1,1,1,2,2,2,2,1,1,1,1,1,1,1,1,1,1,1,1,1,1,1,1,1,1,1,1,1,1,1,1
1,1,1,1,1,1,1,1,1,1,2,2,2,2,1,1,1,1,1,1,1,1,1,1,1,1,1,1,1,1,1,1,1,1,1,1,1,1
1,1,1,1,1,1,1,1,1,1,2,2,2,2,1,1,1,1,1,1,1,1,1,1,1,1,1,1,1,1,1,1,1,1,1,1,1,1
1,1,1,1,1,1,1,1,1,1,2,2,2,2,1,1,1,1,1,1,1,1,1,1,1,1,1,1,1,1,1,1,1,1,1,1,1,1
1,1,1,1,1,1,1,1,1,1,2,2,2,2,1,1,1,1,1,1,1,1,1,1,1,1,1,1,1,1,1,1,1,1,1,1,1,1
1,1,1,1,1,1,1,1,1,1,2,2,2,2,1,1,1,1,1,1,1,1,1,1,1,1,1,1,1,1,1,1,1,1,1,1,1,1
1,1,1,1,1,1,1,1,1,1,2,2,2,2,1,1,1,1,1,1,1,1,1,1,1,1,1,1,1,1,1,1,1,1,1,1,1,1
1,1,1,1,1,1,1,1,1,1,2,2,2,2,1,1,1,1,1,1,1,1,1,1,1,1,1,1,1,1,1,1,1,1,1,1,1,1
1,1,1,1,1,1,1,1,1,1,1,2,2,2,1,1,1,1,1,1,1,1,1,1,1,1,1,1,1,1,1,1,1,1,1,1,1,1
1,1,1,1,1,1,1,1,1,1,1,2,2,2,1,1,1,1,1,1,1,1,1,1,1,1,1,1,1,1,1,1,1,1,1,1,1,1
1,1,1,1,1,1,1,1,1,1,1,2,2,2,1,1,1,1,1,1,1,1,1,1,1,1,1,1,1,1,1,1,1,1,1,1,1,1
1,1,1,1,1,1,1,1,1,1,1,1,1,1,1,1,1,1,1,1,1,1,1,1,1,1,1,1,1,1,1,1,1,1,1,1,1,1
1,1,1,1,1,1,1,1,1,1,1,1,1,1,1,1,1,1,1,1,1,1,1,1,1,1,1,1,1,1,1,1,1,1,1,1,1,1
1,1,1,1,1,1,1,1,1,1,1,1,1,1,1,1,1,1,1,1,1,1,1,1,1,1,1,1,1,1,1,1,1,1,1,1,1,1
1,1,1,1,1,1,1,1,1,1,1,1,1,1,1,1,1,1,1,1,1,1,1,1,1,1,1,1,1,1,1,1,1,1,1,1,1,1
1,1,1,1,1,1,1,1,1,1,1,1,1,1,1,1,1,1,1,1,1,1,1,1,1,1,1,1,1,1,1,1,1,1,1,1,1,1
1,1,1,1,1,1,1,1,1,1,1,1,1,1,1,1,1,1,1,1,1,1,1,1,1,1,1,1,1,1,1,1,1,1,1,1,1,1
1,1,1,1,1,1,1,1,1,1,1,1,1,1,1,1,1,1,1,1,1,1,1,1,1,1,1,1,1,1,1,1,1,1,1,1,1,1
1,1,1,1,1,1,1,1,1,1,1,1,1,1,1,1,1,1,1,1,1,1,1,1,1,1,1,1,1,1,1,1,1,1,1,1,1,1
1,1,1,1,1,1,1,1,1,1,1,1,1,1,1,1,1,1,1,1,1,1,1,1,1,1,1,1,1,1,1,1,1,1,1,1,1,1
1,1,1,1,1,1,1,1,1,1,1,1,1,1,1,1,1,1,1,1,1,1,1,1,1,1,1,1,1,1,1,1,1,1,1,1,1,1
1,1,1,1,1,1,1,1,1,1,1,1,1,1,1,1,1,1,1,1,1,1,1,1,1,1,1,1,1,1,1,1,1,1,1,1,1,1
1,1,1,1,1,1,1,1,1,1,1,1,1,1,1,1,1,1,1,1,1,1,1,1,1,1,1,1,1,1,1,1,1,1,1,1,1,1
1,1,1,1,1,1,1,1,1,1,1,1,1,1,1,1,1,1,1,1,1,1,1,1,1,1,1,1,1,1,1,1,1,1,1,1,1,1
1,1,1,1,1,1,1,1,1,1,1,1,1,1,1,1,1,1,1,1,1,1,1,1,1,1,1,1,1,1,1,1,1,1,1,1,1,1
1,1,1,1,1,1,1,1,1,1,1,1,1,1,1,1,1,1,1,1,1,1,1,1,1,1,1,1,1,1,1,1,1,1,1,1,1,1
1,1,1,1,1,1,1,1,1,1,1,1,1,1,1,1,1,1,1,1,1,1,1,1,1,1,1,1,1,1,1,1,1,1,1,1,1,1
endlayer

layer
1,1,1,1,1,1,1,1,1,1,1,1,1,1,1,1,1,1,1,1,1,1,1,1,1,1,1,1,1,1,1,1,1,1,1,1,1,1
1,1,1,1,1,1,1,1,1,1,1,1,1,1,1,1,1,1,1,1,1,1,1,1,1,1,1,1,1,1,1,1,1,1,1,1,1,1
1,1,1,1,1,1,1,1,1,1,3,3,3,3,2,2,2,1,1,1,1,1,1,1,1,1,1,1,1,1,1,1,1,1,1,1,1,1
1,1,1,1,1,1,1,1,1,1,3,3,3,3,2,2,2,1,1,1,1,1,1,1,1,1,1,1,1,1,1,1,1,1,1,1,1,1
1,1,1,1,7,7,7,7,7,7,6,0,0,4,2,2,2,1,1,1,1,1,1,1,1,1,1,1,1,1,1,1,1,1,1,1,1,1
1,1,1,1,7,7,7,7,7,7,7,0,0,4,2,2,2,1,1,1,1,1,1,1,1,1,1,1,1,1,1,1,1,1,1,1,1,1
1,1,1,1,7,7,7,7,7,7,7,0,0,4,2,2,2,1,1,1,1,1,1,1,1,1,1,1,1,1,1,1,1,1,1,1,1,1
1,1,1,1,7,7,7,7,7,7,7,0,0,4,2,2,2,1,1,1,1,1,1,1,1,1,1,1,1,1,1,1,1,1,1,1,1,1
1,1,1,1,7,7,7,7,7,7,7,0,0,5,2,2,2,1,1,1,1,1,1,1,1,1,1,1,1,1,1,1,1,1,1,1,1,1
1,1,1,1,7,7,7,7,7,7,7,0,0,5,2,2,2,1,1,1,1,1,1,1,1,1,1,1,1,1,1,1,1,1,1,1,1,1
1,1,1,1,7,7,7,7,7,7,7,0,0,4,2,2,2,1,1,1,1,1,1,1,1,1,1,1,1,1,1,1,1,1,1,1,1,1
1,1,1,1,7,7,7,7,7,7,7,0,0,4,2,2,2,1,1,1,1,1,1,1,1,1,1,1,1,1,1,1,1,1,1,1,1,1
1,1,1,1,7,7,7,7,7,7,7,0,0,4,2,2,2,1,1,1,1,1,1,1,1,1,1,1,1,1,1,1,1,1,1,1,1,1
1,1,1,1,7,7,7,7,7,7,6,0,0,4,2,2,2,1,1,1,1,1,1,1,1,1,1,1,1,1,1,1,1,1,1,1,1,1
1,1,1,1,1,1,1,1,1,3,3,3,3,3,2,2,2,1,1,1,1,1,1,1,1,1,1,1,1,1,1,1,1,1,1,1,1,1
1,1,1,1,1,1,1,1,1,1,3,3,3,3,2,2,2,1,1,1,1,1,1,1,1,1,1,1,1,1,1,1,1,1,1,1,1,1
1,1,1,1,1,1,1,1,1,1,1,1,1,1,1,1,1,1,1,1,1,1,1,1,1,1,1,1,1,1,1,1,1,1,1,1,1,1
1,1,1,1,1,1,1,1,1,1,1,1,1,1,1,1,1,1,1,1,1,1,1,1,1,1,1,1,1,1,1,1,1,1,1,1,1,1
1,1,1,1,1,1,1,1,1,1,1,1,1,1,1,1,1,1,1,1,1,1,1,1,1,1,1,1,1,1,1,1,1,1,1,1,1,1
1,1,1,1,1,1,1,1,1,1,1,1,1,1,1,1,1,1,1,1,1,1,1,1,1,1,1,1,1,1,1,1,1,1,1,1,1,1
1,1,1,1,1,1,1,1,1,1,1,1,1,1,1,1,1,1,1,1,1,1,1,1,1,1,1,1,1,1,1,1,1,1,1,1,1,1
1,1,1,1,1,1,1,1,1,1,1,1,1,1,1,1,1,1,1,1,1,1,1,1,1,1,1,1,1,1,1,1,1,1,1,1,1,1
1,1,1,1,1,1,1,1,1,1,1,1,1,1,1,1,1,1,1,1,1,1,1,1,1,1,1,1,1,1,1,1,1,1,1,1,1,1
1,1,1,1,1,1,1,1,1,1,1,1,1,1,1,1,1,1,1,1,1,1,1,1,1,1,1,1,1,1,1,1,1,1,1,1,1,1
1,1,1,1,1,1,1,1,1,1,1,1,1,1,1,1,1,1,1,1,1,1,1,1,1,1,1,1,1,1,1,1,1,1,1,1,1,1
1,1,1,1,1,1,1,1,1,1,1,1,1,1,1,1,1,1,1,1,1,1,1,1,1,1,1,1,1,1,1,1,1,1,1,1,1,1
1,1,1,1,1,1,1,1,1,1,1,1,1,1,1,1,1,1,1,1,1,1,1,1,1,1,1,1,1,1,1,1,1,1,1,1,1,1
1,1,1,1,1,1,1,1,1,1,1,1,1,1,1,1,1,1,1,1,1,1,1,1,1,1,1,1,1,1,1,1,1,1,1,1,1,1
1,1,1,1,1,1,1,1,1,1,1,1,1,1,1,1,1,1,1,1,1,1,1,1,1,1,1,1,1,1,1,1,1,1,1,1,1,1
1,1,1,1,1,1,1,1,1,1,1,1,1,1,1,1,1,1,1,1,1,1,1,1,1,1,1,1,1,1,1,1,1,1,1,1,1,1
1,1,1,1,1,1,1,1,1,1,1,1,1,1,1,1,1,1,1,1,1,1,1,1,1,1,1,1,1,1,1,1,1,1,1,1,1,1
1,1,1,1,1,1,1,1,1,1,1,1,1,1,1,1,1,1,1,1,1,1,1,1,1,1,1,1,1,1,1,1,1,1,1,1,1,1
endlayer

layer
1,1,1,1,1,1,1,1,1,1,1,1,1,1,1,1,1,1,1,1,1,1,1,1,1,1,1,1,1,1,1,1,1,1,1,1,1,1
1,1,1,1,1,1,1,1,1,1,1,1,1,1,1,1,1,1,1,1,1,1,1,1,1,1,1,1,1,1,1,1,1,1,1,1,1,1
1,1,1,3,3,3,3,3,3,3,3,3,3,3,3,3,3,2,2,2,1,1,1,1,1,1,1,1,1,1,1,1,1,1,1,1,1,1
1,1,1,3,3,3,3,3,3,3,3,3,3,3,3,3,3,2,2,2,1,1,1,1,1,1,1,1,1,1,1,1,1,1,1,1,1,1
1,1,1,9,0,8,0,0,0,0,6,0,0,0,0,0,4,2,2,2,1,1,1,1,1,1,1,1,1,1,1,1,1,1,1,1,1,1
1,1,1,9,0,8,0,0,0,0,8,0,0,0,0,0,4,2,2,2,1,1,1,1,1,1,1,1,1,1,1,1,1,1,1,1,1,1
1,1,1,9,0,8,0,0,0,0,0,0,0,0,0,0,4,2,2,2,1,1,1,1,1,1,1,1,1,1,1,1,1,1,1,1,1,1
1,1,1,9,0,8,0,0,0,0,0,0,0,0,0,0,4,2,2,2,1,1,1,1,1,1,1,1,1,1,1,1,1,1,1,1,1,1
1,1,1,9,0,8,0,0,0,0,0,0,0,0,0,0,5,2,2,2,1,1,1,1,1,1,1,1,1,1,1,1,1,1,1,1,1,1
1,1,1,9,0,8,0,0,0,0,0,0,0,0,0,0,5,2,2,2,1,1,1,1,1,1,1,1,1,1,1,1,1,1,1,1,1,1
1,1,1,9,0,8,0,0,0,0,0,0,0,0,0,0,4,2,2,2,1,1,1,1,1,1,1,1,1,1,1,1,1,1,1,1,1,1
1,1,1,9,0,8,0,0,0,0,0,0,0,0,0,0,4,2,2,2,1,1,1,1,1,1,1,1,1,1,1,1,1,1,1,1,1,1
1,1,1,9,0,8,0,0,0,0,8,0,0,0,0,0,4,2,2,2,1,1,1,1,1,1,1,1,1,1,1,1,1,1,1,1,1,1
1,1,1,9,0,8,0,0,0,0,6,0,0,0,0,0,4,2,2,2,1,1,1,1,1,1,1,1,1,1,1,1,1,1,1,1,1,1
1,1,1,3,3,3,3,3,3,3,3,3,3,3,3,3,3,2,2,2,1,1,1,1,1,1,1,1,1,1,1,1,1,1,1,1,1,1
1,1,1,3,3,3,3,3,3,3,3,3,3,3,3,3,3,1,1,1,1,1,1,1,1,1,1,1,1,1,1,1,1,1,1,1,1,1
1,1,1,1,1,1,1,1,1,1,1,1,1,1,1,1,1,1,1,1,1,1,1,1,1,1,1,1,1,1,1,1,1,1,1,1,1,1
1,1,1,1,1,1,1,1,1,1,1,1,1,1,1,1,1,1,1,1,1,1,1,1,1,1,1,1,1,1,1,1,1,1,1,1,1,1
1,1,1,1,1,1,1,1,1,1,1,1,1,1,1,1,1,1,1,1,1,1,1,1,1,1,1,1,1,1,1,1,1,1,1,1,1,1
1,1,1,1,1,1,1,1,1,1,1,1,1,1,1,1,1,1,1,1,1,1,1,1,1,1,1,1,1,1,1,1,1,1,1,1,1,1
1,1,1,1,1,1,1,1,1,1,1,1,1,1,1,1,1,1,1,1,1,1,1,1,1,1,1,1,1,1,1,1,1,1,1,1,1,1
1,1,1,1,1,1,1,1,1,1,1,1,1,1,1,1,1,1,1,1,1,1,1,1,1,1,1,1,1,1,1,1,1,1,1,1,1,1
1,1,1,1,1,1,1,1,1,1,1,1,1,1,1,1,1,1,1,1,1,1,1,1,1,1,1,1,1,1,1,1,1,1,1,1,1,1
1,1,1,1,1,1,1,1,1,1,1,1,1,1,1,1,1,1,1,1,1,1,1,1,1,1,1,1,1,1,1,1,1,1,1,1,1,1
1,1,1,1,1,1,1,1,1,1,1,1,1,1,1,1,1,1,1,1,1,1,1,1,1,1,1,1,1,1,1,1,1,1,1,1,1,1
1,1,1,1,1,1,1,1,1,1,1,1,1,1,1,1,1,1,1,1,1,1,1,1,1,1,1,1,1,1,1,1,1,1,1,1,1,1
1,1,1,1,1,1,1,1,1,1,1,1,1,1,1,1,1,1,1,1,1,1,1,1,1,1,1,1,1,1,1,1,1,1,1,1,1,1
1,1,1,1,1,1,1,1,1,1,1,1,1,1,1,1,1,1,1,1,1,1,1,1,1,1,1,1,1,1,1,1,1,1,1,1,1,1
1,1,1,1,1,1,1,1,1,1,1,1,1,1,1,1,1,1,1,1,1,1,1,1,1,1,1,1,1,1,1,1,1,1,1,1,1,1
1,1,1,1,1,1,1,1,1,1,1,1,1,1,1,1,1,1,1,1,1,1,1,1,1,1,1,1,1,1,1,1,1,1,1,1,1,1
1,1,1,1,1,1,1,1,1,1,1,1,1,1,1,1,1,1,1,1,1,1,1,1,1,1,1,1,1,1,1,1,1,1,1,1,1,1
1,1,1,1,1,1,1,1,1,1,1,1,1,1,1,1,1,1,1,1,1,1,1,1,1,1,1,1,1,1,1,1,1,1,1,1,1,1
endlayer

layer
10,10,10,10,10,10,10,10,10,10,10,10,10,10,10,10,10,10,10,10,10,10,10,10,10,10,10,10,10,10,10,10,10,10,10,10,10,10
10,10,10,10,10,10,10,10,10,10,10,10,10,10,10,10,10,10,10,10,10,10,10,10,10,10,10,10,10,10,10,10,10,10,10,10,10,10
10,10,2,2,2,2,2,2,2,2,2,3,3,3,3,3,3,3,3,3,2,2,2,2,2,2,2,2,2,2,2,2,2,2,2,2,10,10
10,10,2,3,3,3,3,3,3,3,3,3,3,3,3,3,3,3,3,3,2,2,2,2,2,2,2,1,2,2,2,2,2,2,2,2,10,10
10,10,2,9,0,8,0,0,0,0,6,0,0,0,0,0,0,0,0,4,2,2,2,2,2,2,2,1,2,2,2,2,2,2,2,2,10,10
10,10,2,9,0,8,0,0,0,0,8,0,0,0,0,0,0,0,0,4,2,2,2,2,2,2,2,1,2,2,2,2,2,2,2,2,10,10
10,10,2,9,0,8,0,0,0,0,0,0,0,0,0,0,0,0,0,4,2,2,2,2,2,2,2,11,2,2,2,2,2,2,2,2,10,10
10,10,2,9,0,8,0,0,0,0,0,0,0,0,0,0,0,0,0,4,2,2,2,2,2,2,2,1,2,2,2,2,2,2,2,2,10,10
10,10,2,9,0,8,0,0,0,0,0,0,0,0,0,0,0,0,0,5,2,2,2,2,2,2,2,1,2,2,2,2,2,2,2,2,10,10
10,10,2,9,0,8,0,0,0,0,0,0,0,0,0,0,0,0,0,5,2,2,2,2,2,2,2,1,2,2,2,2,2,2,2,2,10,10
10,10,2,9,0,8,0,0,0,0,0,0,0,0,0,0,0,0,0,4,2,2,2,2,2,2,2,1,2,2,2,2,2,2,2,2,10,10
10,10,2,9,0,8,0,0,0,0,0,0,0,0,0,0,0,0,0,4,2,2,2,2,2,2,2,1,2,2,2,2,2,2,2,2,10,10
10,10,2,9,0,8,0,0,0,0,8,0,0,0,0,0,0,0,0,4,2,2,2,2,2,2,2,2,2,2,2,2,2,2,2,2,10,10
10,10,2,9,0,8,0,0,0,0,6,0,0,0,0,0,0,0,0,4,2,2,2,2,2,2,2,2,2,2,2,2,2,2,2,2,10,10
10,10,2,3,3,3,3,3,3,3,3,3,3,3,3,3,3,3,3,3,2,2,2,2,2,2,2,2,2,2,2,2,2,2,2,2,10,10
10,10,2,3,3,3,3,3,3,3,3,3,3,3,3,3,3,3,3,3,2,2,2,2,2,1,1,1,1,1,1,1,1,1,1,1,10,10
10,10,2,2,2,2,2,2,2,2,2,2,2,2,2,2,2,2,2,2,2,2,2,2,2,2,2,2,2,2,2,2,2,1,1,1,10,10
10,10,2,2,2,2,2,2,2,2,2,2,2,2,2,2,2,2,2,2,2,2,2,1,2,2,2,2,2,2,2,2,2,2,1,1,10,10
10,10,2,2,2,2,2,2,2,2,2,2,2,2,2,2,2,2,2,2,2,2,2,1,2,2,12,2,2,2,2,2,2,2,2,1,10,10
10,10,2,2,2,2,2,2,2,2,2,2,2,2,2,2,2,2,2,2,2,2,2,1,2,2,2,2,2,2,2,2,2,2,2,1,10,10
10,10,2,2,2,2,2,2,2,2,2,2,2,2,2,2,2,2,2,2,2,2,2,1,2,2,2,2,2,2,2,2,2,2,2,1,10,10
10,10,2,2,2,2,2,2,2,2,2,2,2,2,2,2,2,2,2,2,2,2,2,1,2,2,2,2,2,2,2,2,2,2,2,1,10,10
10,10,2,2,2,2,2,2,2,2,2,2,2,2,2,2,2,2,2,2,2,2,2,1,2,2,2,2,2,2,2,2,2,2,2,1,10,10
10,10,2,2,2,2,2,2,2,2,2,2,2,2,2,2,2,2,2,2,2,2,2,1,2,2,2,2,2,2,2,2,2,2,2,1,10,10
10,10,2,2,2,2,2,2,2,2,2,2,2,2,2,2,2,2,2,2,2,2,2,1,2,2,2,2,2,2,2,2,2,2,2,1,10,10
10,10,2,2,2,2,2,2,2,2,2,2,2,2,2,2,2,2,2,2,2,2,2,10,1,2,2,2,2,2,2,2,2,2,1,10,10,10
10,10,2,2,2,2,2,2,2,2,2,2,2,2,2,2,2,2,2,2,2,2,2,10,10,1,2,2,2,2,2,2,2,1,10,10,10,10
10,10,2,2,2,2,2,2,2,2,2,2,2,2,2,2,2,2,2,2,2,2,2,10,10,10,1,1,1,2,1,1,1,10,10,10,10,10
10,10,10,10,10,10,10,10,10,10,2,2,2,2,2,10,10,10,10,10,10,10,10,10,10,10,10,10,10,10,10,10,10,10,10,10,10,10
10,10,10,10,10,10,10,10,10,10,2,2,2,2,2,10,10,10,10,10,10,10,10,10,10,10,10,10,10,10,10,10,10,10,10,10,10,10
1,1,1,1,1,1,1,1,10,10,10,10,10,10,10,10,10,1,1,1,1,1,1,1,1,1,1,1,1,1,1,1,1,1,1,1,1,1
1,1,1,1,1,1,1,1,10,10,10,10,10,10,10,10,10,1,1,1,1,1,1,1,1,1,1,1,1,1,1,1,1,1,1,1,1,1
endlayer

layer
58,58,58,58,58,58,58,58,58,58,58,58,58,58,58,58,58,58,58,58,58,58,58,58,58,58,58,58,58,58,58,58,58,58,58,58,58,58
58,58,58,58,58,58,58,58,58,58,58,58,58,58,58,58,58,58,58,58,58,58,58,58,58,58,58,58,58,58,58,58,58,58,58,58,58,58
58,58,13,13,13,13,13,13,13,13,13,13,13,13,13,13,13,13,13,13,13,13,13,13,13,13,13,13,13,13,13,13,13,13,13,13,58,58
58,58,13,3,3,3,3,3,3,3,3,3,3,3,3,3,3,3,3,3,3,3,3,13,24,0,0,21,0,0,16,0,16,16,0,13,58,58
58,58,13,9,0,8,0,0,0,0,6,0,0,0,0,0,0,0,0,0,0,4,3,13,25,0,0,21,16,0,17,0,17,17,0,13,58,58
58,58,13,9,0,8,0,0,0,0,8,0,0,0,0,0,0,0,0,0,0,4,3,13,24,0,0,21,16,0,16,0,16,16,0,13,58,58
58,58,13,9,0,8,0,0,0,0,0,0,0,0,0,0,0,0,0,0,0,4,3,13,26,0,0,21,16,0,0,0,0,0,0,13,58,58
58,58,13,9,0,8,0,0,0,0,0,0,0,0,0,0,0,0,0,0,0,0,3,13,26,0,0,21,16,0,16,0,16,16,0,13,58,58
58,58,13,9,0,8,0,0,0,0,0,0,0,0,0,0,0,0,0,0,0,0,3,13,27,0,0,21,16,0,17,0,17,17,0,13,58,58
58,58,13,9,0,8,0,0,0,0,0,0,0,0,0,0,0,0,0,0,0,0,3,13,18,0,0,21,16,0,16,0,16,16,0,13,58,58
58,58,13,9,0,8,0,0,0,0,0,0,0,0,0,0,0,0,0,0,3,8,3,13,18,0,0,21,16,0,0,0,0,0,0,13,58,58
58,58,13,9,0,8,0,0,0,0,0,0,0,0,0,0,0,0,0,0,3,0,3,13,18,0,0,21,0,0,0,0,58,58,58,13,58,58
58,58,13,9,0,8,0,0,0,0,8,0,0,0,0,0,0,0,0,0,3,0,3,13,0,0,0,0,0,0,0,0,0,58,58,58,58,58
58,58,13,9,0,8,0,0,0,0,6,0,0,0,0,0,0,0,0,0,3,0,0,13,0,0,0,0,0,0,0,0,0,58,58,13,58,58
58,58,13,3,3,3,3,3,3,3,3,3,3,3,3,3,3,3,3,3,3,0,0,0,13,13,13,13,13,13,13,13,13,13,13,13,58,58
58,58,13,13,13,13,13,13,13,13,13,13,13,13,13,13,13,13,13,13,13,13,0,0,0,13,13,13,13,13,13,13,13,58,58,58,58,58
58,58,13,0,0,0,0,0,30,0,30,0,30,0,30,0,30,0,0,0,0,0,13,0,0,0,0,22,0,18,20,18,18,13,58,58,58,58
58,58,13,0,0,0,0,0,0,0,0,0,0,0,0,0,0,0,0,0,0,0,13,13,0,0,0,14,0,0,0,0,0,0,13,58,58,58
58,58,13,0,34,0,33,0,0,0,0,0,0,0,0,0,0,28,0,0,28,0,13,13,0,0,0,14,14,14,14,14,14,14,14,13,58,58
58,58,13,0,0,0,0,0,0,0,0,31,0,31,0,0,0,0,0,0,0,0,13,13,0,0,0,0,0,0,0,0,0,0,0,13,58,58
58,58,13,0,34,0,33,0,0,0,0,31,0,31,0,0,0,28,0,0,28,0,13,13,0,0,0,0,0,0,0,0,0,0,4,13,58,58
58,58,13,0,0,0,0,0,0,0,0,31,0,31,0,0,0,0,0,0,0,0,13,13,4,0,0,0,0,0,0,0,0,0,15,13,58,58
58,58,13,0,34,0,33,0,0,0,0,31,31,31,0,0,0,28,0,0,28,0,13,13,4,0,0,0,0,0,0,0,0,0,4,13,58,58
58,58,13,0,0,0,0,0,0,0,0,0,0,0,0,0,0,0,0,0,0,0,13,13,4,0,0,0,0,0,0,0,0,0,0,13,58,58
58,58,13,0,0,0,0,0,0,0,0,0,0,0,0,0,0,0,0,0,0,0,13,13,0,0,0,0,0,0,0,0,0,0,0,13,58,58
58,58,13,0,29,29,29,29,29,0,0,0,0,0,0,0,29,29,29,29,29,0,13,58,13,0,0,0,0,0,58,0,0,0,13,58,58,58
58,58,13,0,29,29,29,29,29,0,0,0,0,0,0,0,29,29,29,29,29,0,13,58,58,13,23,0,58,58,58,0,19,13,58,58,58,58
58,58,13,13,13,13,13,13,13,13,13,0,58,0,13,13,13,13,13,13,13,13,13,58,58,58,13,13,13,58,13,13,13,58,58,58,58,58
58,58,58,58,58,58,58,58,58,58,13,50,58,58,13,58,58,58,58,58,58,58,58,58,58,58,58,58,58,58,58,58,58,58,58,58,58,58
58,58,58,58,58,58,58,58,58,58,13,32,58,32,13,58,58,58,58,58,58,58,58,58,58,58,58,58,58,58,58,58,58,58,58,58,58,58
58,58,58,58,58,58,58,58,58,58,58,58,58,58,58,58,58,58,58,58,58,58,58,58,58,58,58,58,58,58,58,58,58,58,58,58,58,58
58,58,58,58,58,58,58,58,58,58,58,58,58,58,58,58,58,58,58,58,58,58,58,58,58,58,58,58,58,58,58,58,58,58,58,58,58,58
endlayer

layer
58,58,58,58,58,58,58,58,58,58,58,58,58,58,58,58,58,58,58,58,58,58,58,58,58,58,58,58,58,58,58,58,58,58,58,58,58,58
58,58,58,58,58,58,58,58,58,58,58,58,58,58,58,58,58,58,58,58,58,58,58,58,58,58,58,58,58,58,58,58,58,58,58,58,58,58
58,58,13,35,35,35,35,35,35,35,35,35,35,35,35,35,35,35,35,35,35,35,35,13,35,32,32,35,32,32,32,35,32,32,35,13,58,58
58,58,35,3,3,3,3,3,3,3,3,3,3,3,3,3,3,3,3,3,3,3,3,35,24,0,0,0,0,0,0,0,0,0,0,35,58,58
58,58,35,9,0,8,0,0,0,0,6,0,0,0,0,0,0,0,0,0,0,0,3,35,25,0,0,0,0,0,0,0,0,0,0,32,58,58
58,58,35,9,0,8,0,0,0,0,8,0,0,0,0,0,0,0,0,0,0,0,3,35,24,0,0,0,0,0,0,0,0,0,0,32,58,58
58,58,35,9,0,8,0,0,0,0,0,0,0,0,0,0,0,0,0,0,0,0,3,35,0,0,0,0,0,0,0,0,0,0,0,32,58,58
58,58,35,9,0,8,0,0,0,0,0,0,0,0,0,0,0,0,0,0,0,0,3,35,0,0,0,0,0,0,0,0,0,0,0,35,58,58
58,58,35,9,0,8,0,0,0,0,0,0,0,0,0,0,0,0,0,0,0,0,3,35,0,0,0,0,0,0,0,0,0,0,0,32,58,58
58,58,35,9,0,8,0,0,0,0,0,0,0,0,0,0,0,0,0,0,0,0,3,35,0,0,0,0,0,0,0,0,0,0,0,32,58,58
58,58,35,9,0,8,0,0,0,0,0,0,0,0,0,0,0,0,0,0,3,8,3,35,0,0,0,0,0,0,0,0,0,0,0,32,58,58
58,58,35,9,0,8,0,0,0,0,0,0,0,0,0,0,0,0,0,0,3,0,3,35,36,0,0,0,0,0,0,0,0,0,58,35,58,58
58,58,35,9,0,8,0,0,0,0,8,0,0,0,0,0,0,0,0,0,3,0,3,35,0,0,0,0,0,0,0,0,0,58,58,58,58,58
58,58,35,9,0,8,0,0,0,0,6,0,0,0,0,0,0,0,0,0,3,0,0,35,0,0,0,0,0,0,0,0,0,0,58,35,58,58
58,58,35,3,3,3,3,3,3,3,3,3,3,3,3,3,3,3,3,3,3,0,0,0,35,35,35,35,35,35,35,35,35,32,35,13,58,58
58,58,13,35,35,35,35,35,35,35,35,35,35,35,35,35,35,35,35,35,35,35,0,0,0,35,35,35,35,35,35,35,13,58,58,58,58,58
58,58,35,0,0,0,0,0,30,0,30,0,30,0,30,0,30,0,0,0,0,0,35,0,0,0,0,0,0,0,31,0,36,32,58,58,58,58
58,58,32,0,0,0,0,0,0,0,0,0,0,0,0,0,0,0,0,0,0,0,35,35,0,0,0,0,0,0,0,0,0,0,32,58,58,58
58,58,32,0,34,0,33,0,0,0,0,0,0,0,0,0,0,39,0,0,39,0,35,35,0,0,0,0,0,0,0,0,0,0,0,13,58,58
58,58,35,0,0,0,0,0,0,0,0,41,0,41,0,0,0,0,0,0,0,0,35,35,0,0,0,0,0,0,0,0,0,0,0,35,58,58
58,58,32,0,34,0,33,0,0,0,0,0,0,0,0,0,0,39,0,0,39,0,32,35,0,0,0,0,0,0,0,0,0,0,0,32,58,58
58,58,32,0,0,0,0,0,0,0,0,0,0,0,0,0,0,0,0,0,0,0,32,35,0,0,0,0,0,0,0,0,0,0,0,35,58,58
58,58,32,0,34,0,33,0,0,0,0,0,0,0,0,0,0,39,0,0,39,0,32,35,0,0,0,0,0,0,0,0,0,0,0,32,58,58
58,58,35,0,0,0,0,0,0,0,0,0,0,0,0,0,0,0,0,0,0,0,35,35,0,0,0,0,0,0,0,0,0,0,0,35,58,58
58,58,32,0,0,0,0,0,0,0,0,0,0,0,0,0,0,0,0,0,0,0,32,13,0,0,0,0,0,0,0,0,0,0,0,13,58,58
58,58,32,0,0,0,0,0,0,0,0,0,0,0,0,0,0,0,0,0,0,0,32,58,32,0,0,0,0,0,0,0,0,0,32,58,58,58
58,58,35,0,0,40,0,40,0,0,0,0,0,0,0,0,0,40,0,40,0,0,35,58,58,32,38,0,0,58,0,0,37,32,58,58,58,58
58,58,13,35,32,32,32,32,32,35,13,0,0,0,13,35,32,32,32,32,32,35,13,58,58,58,13,32,35,58,35,32,13,58,58,58,58,58
58,58,58,58,58,58,58,58,58,58,35,0,58,0,35,58,58,58,58,58,58,58,58,58,58,58,58,58,58,58,58,58,58,58,58,58,58,58
58,58,58,58,58,58,58,58,58,58,13,32,58,32,13,58,58,58,58,58,58,58,58,58,58,58,58,58,58,58,58,58,58,58,58,58,58,58
58,58,58,58,58,58,58,58,58,58,58,58,58,58,58,58,58,58,58,58,58,58,58,58,58,58,58,58,58,58,58,58,58,58,58,58,58,58
58,58,58,58,58,58,58,58,58,58,58,58,58,58,58,58,58,58,58,58,58,58,58,58,58,58,58,58,58,58,58,58,58,58,58,58,58,58
endlayer

layer
58,58,58,58,58,58,58,58,58,58,58,58,58,58,58,58,58,58,58,58,58,58,58,58,58,58,58,58,58,58,58,58,58,58,58,58,58,58
58,58,58,58,58,58,58,58,58,58,58,58,58,58,58,58,58,58,58,58,58,58,58,58,58,58,58,58,58,58,58,58,58,58,58,58,58,58
58,58,13,35,35,35,35,35,35,35,35,35,35,35,35,35,35,35,35,35,35,35,35,13,35,32,32,35,32,32,32,35,32,32,35,13,58,58
58,58,35,3,3,3,3,3,3,3,3,3,3,3,3,3,3,3,3,3,3,3,3,35,0,0,0,0,0,0,0,0,0,0,0,35,58,58
58,58,35,9,0,8,0,0,0,0,6,0,0,0,0,0,0,0,0,0,0,0,3,35,0,0,0,0,0,0,0,0,0,0,0,32,58,58
58,58,35,9,0,8,0,0,0,0,8,0,0,0,0,0,0,0,0,0,0,0,3,35,0,0,0,0,0,0,0,0,0,0,0,32,58,58
58,58,35,9,0,8,0,0,0,0,0,0,0,0,0,0,0,0,0,0,0,0,3,35,0,0,0,0,0,0,0,0,0,0,0,32,58,58
58,58,35,9,0,8,0,0,0,0,0,0,0,0,0,0,0,0,0,0,3,3,3,35,0,0,0,0,0,0,0,0,0,0,0,35,58,58
58,58,35,9,0,8,0,0,0,0,0,0,0,0,0,0,0,0,0,0,3,3,3,35,0,0,0,0,0,0,0,0,0,0,0,32,58,58
58,58,35,9,0,8,0,0,0,0,0,0,0,0,0,0,0,0,0,0,3,3,3,35,0,0,0,0,0,0,0,0,0,0,0,32,58,58
58,58,35,9,0,8,0,0,0,0,0,0,0,0,0,0,0,0,0,0,3,3,3,35,0,0,0,0,0,0,0,0,0,0,0,32,58,58
58,58,35,9,0,8,0,0,0,0,0,0,0,0,0,0,0,0,0,0,3,3,3,35,0,0,0,0,0,0,0,0,0,0,0,35,58,58
58,58,35,9,0,8,0,0,0,0,8,0,0,0,0,0,0,0,0,0,3,3,3,35,0,0,0,0,0,0,0,0,0,0,0,35,58,58
58,58,35,9,0,8,0,0,0,0,6,0,0,0,0,0,0,0,0,0,3,3,3,35,0,0,0,0,0,0,0,0,0,0,0,35,58,58
58,58,35,3,3,3,3,3,3,3,3,3,3,3,3,3,3,3,3,3,3,3,3,13,35,35,35,35,35,35,35,35,35,32,35,13,58,58
58,58,13,35,35,35,35,35,35,35,35,35,35,35,35,35,35,35,35,35,35,35,13,13,35,35,35,35,35,35,35,35,13,58,58,58,58,58
58,58,35,0,0,0,0,0,30,0,30,0,30,0,30,0,30,0,0,0,0,0,35,35,0,0,0,0,0,0,42,0,0,32,58,58,58,58
58,58,32,0,0,0,0,0,0,0,0,0,0,0,0,0,0,0,0,0,0,0,35,35,0,0,0,0,0,0,0,0,0,0,32,58,58,58
58,58,32,0,34,0,33,0,0,0,0,0,0,0,0,0,0,0,0,0,0,0,35,35,0,0,0,0,0,0,0,0,0,0,0,13,58,58
58,58,35,0,0,0,0,0,0,0,0,0,0,0,0,0,0,0,0,0,0,0,35,35,0,0,0,0,0,0,0,0,0,0,0,35,58,58
58,58,32,0,34,0,33,0,0,0,0,0,0,0,0,0,0,0,0,0,0,0,32,35,0,0,0,0,0,0,0,0,0,0,0,32,58,58
58,58,32,0,0,0,0,0,0,0,0,0,0,0,0,0,0,0,0,0,0,0,32,35,0,0,0,0,0,0,0,0,0,0,0,35,58,58
58,58,32,0,34,0,33,0,0,0,0,0,0,0,0,0,0,0,0,0,0,0,32,35,0,0,0,0,0,0,0,0,0,0,0,32,58,58
58,58,35,0,0,0,0,0,0,0,0,0,0,0,0,0,0,0,0,0,0,0,35,35,0,0,0,0,0,0,0,0,0,0,0,35,58,58
58,58,32,0,0,0,0,0,0,0,0,0,0,0,0,0,0,0,0,0,0,0,32,13,0,0,0,0,0,0,0,0,0,0,0,13,58,58
58,58,32,0,0,0,0,0,0,0,0,0,0,0,0,0,0,0,0,0,0,0,32,58,32,0,0,0,0,0,0,0,0,0,32,58,58,58
58,58,35,0,0,43,0,43,0,0,0,0,0,0,0,0,0,43,0,43,0,0,35,58,58,32,0,0,0,0,0,0,0,32,58,58,58,58
58,58,13,35,32,32,32,32,32,35,13,0,0,0,13,35,32,32,32,32,32,35,13,58,58,58,13,32,35,35,35,32,13,58,58,58,58,58
58,58,58,58,58,58,58,58,58,58,35,0,0,0,35,58,58,58,58,58,58,58,58,58,58,58,58,58,58,58,58,58,58,58,58,58,58,58
58,58,58,58,58,58,58,58,58,58,13,32,32,32,13,58,58,58,58,58,58,58,58,58,58,58,58,58,58,58,58,58,58,58,58,58,58,58
58,58,58,58,58,58,58,58,58,58,58,58,58,58,58,58,58,58,58,58,58,58,58,58,58,58,58,58,58,58,58,58,58,58,58,58,58,58
58,58,58,58,58,58,58,58,58,58,58,58,58,58,58,58,58,58,58,58,58,58,58,58,58,58,58,58,58,58,58,58,58,58,58,58,58,58
endlayer

layer
58,58,58,58,58,58,58,58,58,58,58,58,58,58,58,58,58,58,58,58,58,58,58,58,58,58,58,58,58,58,58,58,58,58,58,58,58,58
58,58,58,58,58,58,58,58,58,58,58,58,58,58,58,58,58,58,58,58,58,58,58,58,58,58,58,58,58,58,58,58,58,58,58,58,58,58
58,58,13,35,35,35,35,35,35,35,35,35,35,35,35,35,35,35,35,35,35,35,35,13,35,32,32,35,32,32,32,35,32,32,35,13,58,58
58,58,35,3,3,3,3,3,3,3,3,3,3,3,3,3,3,3,3,3,3,3,3,35,0,0,0,0,0,0,0,0,0,0,0,35,58,58
58,58,35,9,0,8,0,0,0,0,6,0,0,0,0,0,0,0,0,0,0,0,3,35,0,0,0,0,0,0,0,0,0,0,0,32,58,58
58,58,35,9,0,8,0,0,0,0,8,0,0,0,0,0,0,0,0,0,0,0,3,35,0,0,0,0,0,0,0,0,0,0,0,32,58,58
58,58,35,9,0,8,0,0,0,0,0,0,0,0,0,0,0,0,0,0,0,0,3,35,0,0,0,0,0,0,0,0,0,0,0,32,58,58
58,58,35,9,0,8,0,0,0,0,0,0,0,0,0,0,0,0,0,0,3,3,3,35,0,0,0,0,0,0,0,0,0,0,0,35,58,58
58,58,35,9,0,8,0,0,0,0,0,0,0,0,0,0,0,0,0,0,48,46,3,35,0,0,0,0,0,0,0,0,0,0,0,32,58,58
58,58,35,9,0,8,0,0,0,0,0,0,0,0,0,0,0,0,0,0,48,47,3,35,0,0,0,0,0,0,0,0,0,0,0,32,58,58
58,58,35,9,0,8,0,0,0,0,0,0,0,0,0,0,0,0,0,0,3,3,3,35,0,0,0,0,0,0,0,0,0,0,0,32,58,58
58,58,35,9,0,8,0,0,0,0,0,0,0,0,0,0,0,0,0,0,3,0,3,35,0,0,0,0,0,0,0,0,0,0,0,35,58,58
58,58,35,9,0,8,0,0,0,0,8,0,0,0,0,0,0,0,0,0,3,0,3,35,0,0,0,0,0,0,0,0,0,0,0,35,45,44
58,58,35,9,0,8,0,0,0,0,6,0,0,0,0,0,0,0,0,0,3,0,3,35,0,0,0,0,0,0,0,0,0,0,0,35,58,58
58,58,35,3,3,3,3,3,3,3,3,3,3,3,3,3,3,3,3,3,3,3,3,13,35,35,35,35,35,35,35,35,35,32,35,13,58,58
58,58,13,35,35,35,35,35,35,35,35,35,35,35,35,35,35,35,35,35,35,35,13,13,35,35,35,35,35,35,35,35,13,58,58,58,58,58
58,58,35,0,0,0,0,0,0,0,0,0,0,0,0,0,0,0,0,0,0,0,35,35,0,0,0,0,0,0,0,0,0,32,58,58,58,58
58,58,32,0,0,0,0,0,0,0,0,0,0,0,0,0,0,0,0,0,0,0,35,35,0,0,0,0,0,0,0,0,0,0,32,58,58,58
58,58,32,0,0,0,0,0,0,0,0,0,0,0,0,0,0,0,0,0,0,0,35,35,0,0,0,0,0,0,0,0,0,0,0,13,58,58
58,58,35,0,0,0,0,0,0,0,0,0,0,0,0,0,0,0,0,0,0,0,35,35,0,0,0,0,0,0,0,0,0,0,0,35,58,58
58,58,32,0,0,0,0,0,0,0,0,0,0,0,0,0,0,0,0,0,0,0,32,35,0,0,0,0,0,0,0,0,0,0,0,32,58,58
58,58,32,0,0,0,0,0,0,0,0,0,0,0,0,0,0,0,0,0,0,0,32,35,0,0,0,0,0,0,0,0,0,0,0,35,58,58
58,58,32,0,0,0,0,0,0,0,0,0,0,0,0,0,0,0,0,0,0,0,32,35,0,0,0,0,0,0,0,0,0,0,0,32,58,58
58,58,35,0,0,0,0,0,0,0,0,0,0,0,0,0,0,0,0,0,0,0,35,35,0,0,0,0,0,0,0,0,0,0,0,35,58,58
58,58,32,0,0,0,0,0,0,0,0,0,0,0,0,0,0,0,0,0,0,0,32,13,0,0,0,0,0,0,0,0,0,0,0,13,58,58
58,58,32,0,0,0,0,0,0,0,0,0,0,0,0,0,0,0,0,0,0,0,32,58,32,0,0,0,0,0,0,0,0,0,32,58,58,58
58,58,35,0,0,0,0,0,0,0,0,0,0,0,0,0,0,0,0,0,0,0,35,58,58,32,0,0,0,0,0,0,0,32,58,58,58,58
58,58,13,35,32,32,32,32,32,35,13,0,0,0,13,35,32,32,32,32,32,35,13,58,58,58,13,32,35,32,35,32,13,58,58,58,58,58
58,58,58,58,58,58,58,58,58,58,35,0,0,0,35,58,58,58,58,58,58,58,58,58,58,58,58,58,58,58,58,58,58,58,58,58,58,58
58,58,58,58,58,58,58,58,58,58,13,32,32,32,13,58,58,58,58,58,58,58,58,58,58,58,58,58,58,58,58,58,58,58,58,58,58,58
58,58,58,58,58,58,58,58,58,58,58,58,58,58,58,58,58,58,58,58,58,58,58,58,58,58,58,58,58,58,58,58,58,58,58,58,58,58
58,58,58,58,58,58,58,58,58,58,58,58,58,58,58,58,58,58,58,58,58,58,58,58,58,58,58,58,58,58,58,58,58,58,58,58,58,58
endlayer

layer
0,0,0,0,0,0,0,0,0,0,0,0,0,0,0,0,0,0,0,0,0,0,0,0,0,0,0,0,0,0,0,0,0,0,0,0,0,0
0,0,0,0,0,0,0,0,0,0,0,0,0,0,0,0,0,0,0,0,0,0,0,0,0,0,0,0,0,0,0,0,0,0,0,0,0,0
0,0,13,35,35,35,35,35,35,35,35,35,35,35,35,35,35,35,35,35,35,35,35,13,35,32,32,35,32,32,32,35,32,32,35,13,0,0
0,0,35,3,3,3,3,3,3,3,3,3,3,3,3,3,3,3,3,3,3,3,3,35,0,0,0,0,0,0,0,0,0,0,0,35,0,0
0,0,35,9,0,8,0,0,0,0,6,0,0,0,0,0,0,0,0,0,0,0,3,35,0,0,0,0,0,0,0,0,0,0,0,32,0,0
0,0,35,9,0,8,0,0,0,0,8,0,0,0,0,0,0,0,0,0,0,0,3,35,0,0,0,0,0,0,0,0,0,0,0,32,0,0
0,0,35,9,0,8,0,0,0,0,0,0,0,0,0,0,0,0,0,0,0,0,3,35,0,0,0,0,0,0,0,0,0,0,0,32,0,0
0,0,35,9,0,8,0,0,0,0,0,0,0,0,0,0,0,0,0,0,3,3,3,35,0,0,0,0,0,0,0,0,0,0,0,35,0,0
0,0,35,9,0,8,0,0,0,0,0,0,0,0,0,0,0,0,0,0,3,3,3,35,0,0,0,0,0,0,0,0,0,0,0,32,0,0
0,0,35,9,0,8,0,0,0,0,0,0,0,0,0,0,0,0,0,0,3,3,3,35,0,0,0,0,0,0,0,0,0,0,0,32,0,0
0,0,35,9,0,8,0,0,0,0,0,0,0,0,0,0,0,0,0,0,3,3,3,35,0,0,0,0,0,0,0,0,0,0,0,32,0,0
0,0,35,9,0,8,0,0,0,0,0,0,0,0,0,0,0,0,0,0,3,0,3,35,0,0,0,0,0,0,0,0,0,0,0,35,0,0
0,0,35,9,0,8,0,0,0,0,8,0,0,0,0,0,0,0,0,0,3,0,3,35,0,0,0,0,0,0,0,0,0,0,0,35,0,44
0,0,35,9,0,8,0,0,0,0,6,0,0,0,0,0,0,0,0,0,3,0,3,35,0,0,0,0,0,0,0,0,0,0,0,35,0,0
0,0,35,3,3,3,3,3,3,3,3,3,3,3,3,3,3,3,3,3,3,3,3,13,35,35,35,35,35,35,35,35,35,32,35,13,0,0
0,0,13,35,35,35,35,35,35,35,35,35,35,35,35,35,35,35,35,35,35,35,13,13,35,35,35,35,35,35,35,35,13,0,0,0,0,0
0,0,35,0,0,0,0,0,0,0,0,0,0,0,0,0,0,0,0,0,0,0,35,35,0,0,0,0,0,0,0,0,0,32,0,0,0,0
0,0,32,0,0,0,0,0,0,0,0,0,0,0,0,0,0,0,0,0,0,0,35,35,0,0,0,0,0,0,0,0,0,0,32,0,0,0
0,0,32,0,0,0,0,0,0,0,0,0,0,0,0,0,0,0,0,0,0,0,35,35,0,0,0,0,0,0,0,0,0,0,0,13,0,0
0,0,35,0,0,0,0,0,0,0,0,0,0,0,0,0,0,0,0,0,0,0,35,35,0,0,0,0,0,0,0,0,0,0,0,35,0,0
0,0,32,0,0,0,0,0,0,0,0,0,0,0,0,0,0,0,0,0,0,0,32,35,0,0,0,0,0,0,0,0,0,0,0,32,0,0
0,0,32,0,0,0,0,0,0,0,0,0,0,0,0,0,0,0,0,0,0,0,32,35,0,0,0,0,0,0,0,0,0,0,0,35,0,0
0,0,32,0,0,0,0,0,0,0,0,0,0,0,0,0,0,0,0,0,0,0,32,35,0,0,0,0,0,0,0,0,0,0,0,32,0,0
0,0,35,0,0,0,0,0,0,0,0,0,0,0,0,0,0,0,0,0,0,0,35,35,0,0,0,0,0,0,0,0,0,0,0,35,0,0
0,0,32,0,0,0,0,0,0,0,0,0,0,0,0,0,0,0,0,0,0,0,32,13,0,0,0,0,0,0,0,0,0,0,0,13,0,0
0,0,32,0,0,0,0,0,0,0,0,0,0,0,0,0,0,0,0,0,0,0,32,0,32,0,0,0,0,0,0,0,0,0,32,0,0,0
0,0,35,0,0,0,0,0,0,0,0,0,0,0,0,0,0,0,0,0,0,0,35,0,0,32,0,0,0,0,0,0,0,32,0,0,0,0
0,0,13,35,32,32,32,32,32,35,13,0,0,0,13,35,32,32,32,32,32,35,13,0,0,0,13,32,35,35,35,32,13,0,0,0,0,0
0,0,0,0,0,0,0,0,0,0,35,0,0,0,35,0,0,0,0,0,0,0,0,0,0,0,0,0,0,0,0,0,0,0,0,0,0,0
0,0,0,0,0,0,0,0,0,0,13,32,32,32,13,0,0,0,0,0,0,0,0,0,0,0,0,0,0,44,0,0,0,0,0,0,0,0
0,0,0,0,0,0,0,0,0,0,0,0,0,0,0,0,0,0,0,0,0,0,0,0,0,0,0,0,0,44,0,0,0,0,0,0,0,0
0,0,0,0,0,0,0,0,0,0,0,0,0,0,0,0,0,0,0,0,0,0,0,0,0,0,0,0,0,44,0,0,0,0,0,0,0,0
endlayer

layer
0,0,0,0,0,0,0,0,0,0,0,0,0,0,0,0,0,0,0,0,0,0,0,0,0,0,0,0,0,0,0,0,0,0,0,0,0,0
0,0,0,0,0,0,0,0,0,0,0,0,0,0,0,0,0,0,0,0,0,0,0,0,0,0,0,0,0,0,0,0,0,0,0,0,0,0
0,0,13,13,13,13,13,13,13,13,13,13,13,13,13,13,13,13,13,13,13,13,13,13,13,13,13,13,13,13,13,13,13,13,13,13,0,0
0,0,13,57,57,57,57,57,57,57,57,57,57,57,57,57,57,57,57,57,57,57,13,13,49,49,49,49,49,49,49,49,49,49,49,13,0,0
0,0,13,57,57,57,57,57,57,57,57,57,57,57,57,57,57,57,57,57,57,57,13,13,49,49,49,49,49,49,49,49,49,49,49,13,0,0
0,0,13,57,57,57,57,57,57,57,57,57,57,57,57,57,57,57,57,57,57,57,13,13,49,49,49,49,49,49,49,49,49,49,49,13,0,0
0,0,13,57,57,57,57,57,57,57,57,57,57,57,57,57,57,57,57,57,57,57,13,13,49,49,49,49,49,49,49,49,49,49,49,13,0,0
0,0,13,57,57,57,57,57,57,57,57,57,57,57,57,57,57,57,57,57,57,57,13,13,49,49,49,49,49,49,49,49,49,49,49,13,0,0
0,0,13,57,57,57,57,57,57,57,57,57,57,57,57,57,57,57,57,57,57,57,13,13,49,49,49,49,49,49,49,49,49,49,49,13,0,0
0,0,13,57,57,57,57,57,57,57,57,57,57,57,57,57,57,57,57,57,57,57,13,13,49,49,49,49,49,49,49,49,49,49,49,13,0,0
0,0,13,57,57,57,57,57,57,57,57,57,57,57,57,57,57,57,57,57,57,57,13,13,49,49,49,49,49,49,49,49,49,49,49,13,0,0
0,0,13,57,57,57,57,57,57,57,57,57,57,57,57,57,57,57,57,57,57,57,13,13,49,49,49,49,49,49,49,49,49,49,49,13,0,0
0,0,13,57,57,57,57,57,57,57,57,57,57,57,57,57,57,57,57,57,57,57,13,13,49,49,49,49,49,49,49,49,49,49,49,13,0,44
0,0,13,57,57,57,57,57,57,57,57,57,57,57,57,57,57,57,57,57,57,57,13,13,49,49,49,49,49,49,49,49,49,49,49,13,0,0
0,0,13,13,13,13,13,13,13,13,13,13,13,13,13,13,13,13,13,13,13,13,13,13,13,13,13,13,13,13,13,13,13,13,13,13,0,0
0,0,13,13,13,13,13,13,13,13,13,13,13,13,13,13,13,13,13,13,13,13,13,13,13,13,13,13,13,13,13,13,13,0,0,0,0,0
0,0,13,49,49,49,49,49,49,49,49,49,49,49,49,49,49,49,49,49,49,49,13,13,0,0,0,0,0,0,0,0,0,13,0,0,0,0
0,0,13,49,49,49,49,49,49,49,49,49,49,49,49,49,49,49,49,49,49,49,13,13,0,0,0,0,0,0,0,0,0,0,13,0,0,0
0,0,13,49,49,49,49,49,49,49,49,49,49,49,49,49,49,49,49,49,49,49,13,13,0,0,0,0,0,0,0,0,0,0,0,13,0,0
0,0,13,49,49,49,49,49,49,49,49,49,49,49,49,49,49,49,49,49,49,49,13,13,0,0,0,0,0,0,0,0,0,0,0,13,0,0
0,0,13,49,49,49,49,49,49,49,49,49,49,49,49,49,49,49,49,49,49,49,13,13,0,0,0,0,0,0,0,0,0,0,0,13,0,0
0,0,13,49,49,49,49,49,49,49,49,49,49,49,49,49,49,49,49,49,49,49,13,13,0,0,0,0,0,0,0,0,0,0,0,13,0,0
0,0,13,49,49,49,49,49,49,49,49,49,49,49,49,49,49,49,49,49,49,49,13,13,0,0,0,0,0,0,0,0,0,0,0,13,0,0
0,0,13,49,49,49,49,49,49,49,49,49,49,49,49,49,49,49,49,49,49,49,13,13,0,0,0,0,0,0,0,0,0,0,0,13,0,0
0,0,13,49,49,49,49,49,49,49,49,49,49,49,49,49,49,49,49,49,49,49,13,13,0,0,0,0,0,0,0,0,0,0,0,13,0,0
0,0,13,49,49,49,49,49,49,49,49,49,49,49,49,49,49,49,49,49,49,49,13,0,13,0,0,0,0,0,0,0,0,0,13,0,0,0
0,0,13,49,49,49,49,49,49,49,49,49,49,49,49,49,49,49,49,49,49,49,13,0,0,13,0,0,0,0,0,0,0,13,0,0,0,0
0,0,13,13,13,13,13,13,13,13,13,49,49,49,13,13,13,13,13,13,13,13,13,0,0,0,13,13,13,13,13,13,13,0,0,0,0,0
0,0,0,0,0,0,0,0,0,0,13,49,49,49,13,0,0,0,0,0,0,0,0,0,0,0,0,0,0,45,0,0,0,0,0,0,0,0
0,0,0,0,0,0,0,0,0,0,13,13,13,13,13,0,0,0,0,0,0,0,0,0,0,0,0,0,0,44,0,0,0,0,0,0,0,0
0,0,0,0,0,0,0,0,0,0,0,0,0,0,0,0,0,0,0,0,0,0,0,0,0,0,0,0,0,50,0,0,0,0,0,0,0,0
0,0,0,0,0,0,0,0,0,0,0,0,0,0,0,0,0,0,0,0,0,0,0,0,0,0,0,0,0,44,0,0,0,0,0,0,0,0
endlayer

layer
0,0,0,0,0,0,0,0,0,0,0,0,0,0,0,0,0,0,0,0,0,0,0,0,0,0,0,0,0,0,0,0,0,0,0,0,0,0
0,0,0,0,0,0,0,0,0,0,0,0,0,0,0,0,0,0,0,0,0,0,0,0,0,0,0,0,0,0,0,0,0,0,0,0,0,0
0,0,0,0,0,0,0,0,0,0,0,0,0,0,0,0,0,0,0,0,0,0,0,0,0,0,0,0,0,0,0,0,0,0,0,0,0,0
0,0,0,0,0,0,0,0,0,0,0,0,0,0,0,0,0,0,0,0,0,0,0,0,0,0,0,0,0,0,0,0,0,0,0,0,0,0
0,0,0,0,0,0,0,0,0,0,0,0,0,0,0,0,0,0,0,0,0,0,0,0,0,0,0,0,0,0,0,0,0,0,0,0,0,0
0,0,0,0,0,0,0,0,0,0,0,0,0,0,0,0,0,0,0,0,0,0,0,0,0,0,0,0,0,0,0,0,0,0,0,0,0,0
0,0,0,0,0,0,0,0,0,0,0,0,0,0,0,0,0,0,0,0,0,0,0,0,0,0,0,0,0,0,0,0,0,0,0,0,0,0
0,0,0,0,0,0,0,0,0,0,0,0,0,0,0,0,0,0,0,0,0,0,0,0,0,0,0,0,0,0,0,0,0,0,0,0,0,0
0,0,0,0,0,0,0,0,0,0,0,0,0,0,0,0,0,0,0,0,0,0,0,0,0,0,0,0,0,0,0,0,0,0,0,0,0,0
0,0,0,0,0,0,0,0,0,0,0,0,0,0,0,0,0,0,0,0,0,0,0,0,0,0,0,0,0,0,0,0,0,0,0,0,0,0
0,0,0,0,0,0,0,0,0,0,0,0,0,0,0,0,0,0,0,0,0,0,0,0,0,0,0,0,0,0,0,0,0,0,0,0,0,0
0,0,0,0,0,0,0,0,0,0,0,0,0,0,0,0,0,0,0,0,0,0,0,0,0,0,0,0,0,0,0,0,0,0,0,0,0,0
0,0,0,0,0,0,0,0,0,0,0,0,0,0,0,0,0,0,0,0,0,0,0,0,0,0,0,0,0,0,0,0,0,0,0,0,0,0
0,0,0,0,0,0,0,0,0,0,0,0,0,0,0,0,0,0,0,0,0,0,0,0,0,0,0,0,0,0,0,0,0,0,0,0,0,0
0,0,0,0,0,0,0,0,0,0,0,0,0,0,0,0,0,0,0,0,0,0,0,0,0,0,0,0,0,0,0,0,0,0,0,0,0,0
0,0,0,0,0,0,0,0,0,0,0,0,0,0,0,0,0,0,0,0,0,0,0,0,0,0,0,0,0,0,0,0,0,0,0,0,0,0
0,0,0,0,0,0,0,0,0,0,0,0,0,0,0,0,0,0,0,0,0,0,0,0,35,35,35,35,35,35,35,35,35,0,0,0,0,0
0,0,0,0,0,0,0,0,0,0,0,0,0,0,0,0,0,0,0,0,0,0,0,0,35,35,2,2,2,2,2,2,2,35,0,0,0,0
0,0,0,0,0,0,0,0,0,0,0,0,0,0,0,0,0,0,0,0,0,0,0,0,35,2,12,2,2,2,2,2,2,2,35,0,0,0
0,0,0,0,0,0,0,0,0,0,0,0,0,0,0,0,0,0,0,0,0,0,0,0,35,2,2,2,2,2,2,2,2,2,35,0,0,0
0,0,0,0,0,0,0,0,0,0,0,0,0,0,0,0,0,0,0,0,0,0,0,0,35,2,2,2,2,2,2,2,2,2,35,0,0,0
0,0,0,0,0,0,0,0,0,0,0,0,0,0,0,0,0,0,0,0,0,0,0,0,35,2,2,2,2,2,2,2,2,2,35,0,0,0
0,0,0,0,0,0,0,0,0,0,0,0,0,0,0,0,0,0,0,0,0,0,0,0,35,2,2,2,2,2,2,2,2,2,35,0,0,0
0,0,0,0,0,0,0,0,0,0,0,0,0,0,0,0,0,0,0,0,0,0,0,0,35,2,2,2,2,2,2,2,2,2,35,0,0,0
0,0,0,0,0,0,0,0,0,0,0,0,0,0,0,0,0,0,0,0,0,0,0,0,35,2,2,2,2,2,2,2,2,2,35,0,0,0
0,0,0,0,0,0,0,0,0,0,0,0,0,0,0,0,0,0,0,0,0,0,0,0,0,35,2,2,2,2,2,2,2,35,0,0,0,0
0,0,0,0,0,0,0,0,0,0,45,0,0,0,45,0,0,0,0,0,0,0,0,0,0,0,35,35,35,35,35,35,35,0,0,0,0,0
0,0,0,0,0,0,0,0,0,0,0,0,0,0,0,0,0,0,0,0,0,0,0,0,0,0,0,0,0,0,0,0,0,0,0,0,0,0
0,0,0,0,0,0,0,0,0,0,0,0,0,0,0,0,0,0,0,0,0,0,0,0,0,0,0,0,0,0,0,0,0,0,0,0,0,0
0,0,0,0,0,0,0,0,0,0,0,0,0,0,0,0,0,0,0,0,0,0,0,0,0,0,0,0,0,44,0,0,0,0,0,0,0,0
0,0,0,0,0,0,0,0,0,0,0,0,0,0,0,0,0,0,0,0,0,0,0,0,0,0,0,0,0,50,0,0,0,0,0,0,0,0
0,0,0,0,0,0,0,0,0,0,0,0,0,0,0,0,0,0,0,0,0,0,0,0,0,0,0,0,0,44,0,0,0,0,0,0,0,0
endlayer

layer
0,0,0,0,0,0,0,0,0,0,0,0,0,0,0,0,0,0,0,0,0,0,0,0,0,0,0,0,0,0,0,0,0,0,0,0,0,0
0,0,0,0,0,0,0,0,0,0,0,0,0,0,0,0,0,0,0,0,0,0,0,0,0,0,0,0,0,0,0,0,0,0,0,0,0,0
0,0,0,0,0,0,0,0,0,0,0,0,0,0,0,0,0,0,0,0,0,0,0,0,0,0,0,0,0,0,0,0,0,0,0,0,0,0
0,0,0,0,0,0,0,0,0,0,0,0,0,0,0,0,0,0,0,0,0,0,0,0,0,0,0,0,0,0,0,0,0,0,0,0,0,0
0,0,0,0,0,0,0,0,0,0,0,0,0,0,0,0,0,0,0,0,0,0,0,0,0,0,0,0,0,0,0,0,0,0,0,0,0,0
0,0,0,0,0,0,0,0,0,0,0,0,0,0,0,0,0,0,0,0,0,0,0,0,0,0,0,0,0,0,0,0,0,0,0,0,0,0
0,0,0,0,0,0,0,0,0,0,0,0,0,0,0,0,0,0,0,0,0,0,0,0,0,0,0,0,0,0,0,0,0,0,0,0,0,0
0,0,0,0,0,0,0,0,0,0,0,0,0,0,0,0,0,0,0,0,0,0,0,0,0,0,0,0,0,0,0,0,0,0,0,0,0,0
0,0,0,0,0,0,0,0,0,0,0,0,0,0,0,0,0,0,0,0,0,0,0,0,0,0,0,0,0,0,0,0,0,0,0,0,0,0
0,0,0,0,0,0,0,0,0,0,0,0,0,0,0,0,0,0,0,0,0,0,0,0,0,0,0,0,0,0,0,0,0,0,0,0,0,0
0,0,0,0,0,0,0,0,0,0,0,0,0,0,0,0,0,0,0,0,0,0,0,0,0,0,0,0,0,0,0,0,0,0,0,0,0,0
0,0,0,0,0,0,0,0,0,0,0,0,0,0,0,0,0,0,0,0,0,0,0,0,0,0,0,0,0,0,0,0,0,0,0,0,0,0
0,0,0,0,0,0,0,0,0,0,0,0,0,0,0,0,0,0,0,0,0,0,0,0,0,0,0,0,0,0,0,0,0,0,0,0,0,0
0,0,0,0,0,0,0,0,0,0,0,0,0,0,0,0,0,0,0,0,0,0,0,0,0,0,0,0,0,0,0,0,0,0,0,0,0,0
0,0,0,0,0,0,0,0,0,0,0,0,0,0,0,0,0,0,0,0,0,0,0,0,0,0,0,0,0,0,0,0,0,0,0,0,0,0
0,0,0,0,0,0,0,0,0,0,0,0,0,0,0,0,0,0,0,0,0,0,0,0,0,0,0,0,0,0,0,0,0,0,0,0,0,0
0,0,0,0,0,0,0,0,0,0,0,0,0,0,0,0,0,0,0,0,0,0,0,0,0,0,0,0,0,0,0,0,0,0,0,0,0,0
0,0,0,0,0,0,0,0,0,0,0,0,0,0,0,0,0,0,0,0,0,0,0,0,0,0,13,13,13,13,13,13,13,0,0,0,0,0
0,0,0,0,0,0,0,0,0,0,0,0,0,0,0,0,0,0,0,0,0,0,0,0,0,13,0,0,52,53,52,0,4,13,0,0,0,0
0,0,0,0,0,0,0,0,0,0,0,0,0,0,0,0,0,0,0,0,0,0,0,0,0,13,0,0,0,0,0,0,15,13,0,0,0,0
0,0,0,0,0,0,0,0,0,0,0,0,0,0,0,0,0,0,0,0,0,0,0,0,0,13,0,0,0,0,0,0,4,13,0,0,0,0
0,0,0,0,0,0,0,0,0,0,0,0,0,0,0,0,0,0,0,0,0,0,0,0,0,13,0,0,0,0,0,0,0,13,0,0,0,0
0,0,0,0,0,0,0,0,0,0,0,0,0,0,0,0,0,0,0,0,0,0,0,0,0,13,0,0,0,0,0,0,0,13,0,0,0,0
0,0,0,0,0,0,0,0,0,0,0,0,0,0,0,0,0,0,0,0,0,0,0,0,0,13,0,0,0,54,0,0,0,13,0,0,0,0
0,0,0,0,0,0,0,0,0,0,0,0,0,0,0,0,0,0,0,0,0,0,0,0,0,13,11,0,15,55,15,0,51,13,0,0,0,0
0,0,0,0,0,0,0,0,0,0,0,0,0,0,0,0,0,0,0,0,0,0,0,0,0,0,13,13,13,13,13,13,13,0,0,0,0,0
0,0,0,0,0,0,0,0,0,0,44,44,44,44,44,0,0,0,0,0,0,0,0,0,0,0,0,0,0,0,0,0,0,0,0,0,0,0
0,0,0,0,0,0,0,0,0,0,0,0,0,0,0,0,0,0,0,0,0,0,0,0,0,0,0,0,0,0,0,0,0,0,0,0,0,0
0,0,0,0,0,0,0,0,0,0,0,0,0,0,0,0,0,0,0,0,0,0,0,0,0,0,0,0,0,0,0,0,0,0,0,0,0,0
0,0,0,0,0,0,0,0,0,0,0,0,0,0,0,0,0,0,0,0,0,0,0,0,0,0,0,0,0,44,0,0,0,0,0,0,0,0
0,0,0,0,0,0,0,0,0,0,0,0,0,0,0,0,0,0,0,0,0,0,0,0,0,0,0,0,0,50,0,0,0,0,0,0,0,0
0,0,0,0,0,0,0,0,0,0,0,0,0,0,0,0,0,0,0,0,0,0,0,0,0,0,0,0,0,44,0,0,0,0,0,0,0,0
endlayer

layer
0,0,0,0,0,0,0,0,0,0,0,0,0,0,0,0,0,0,0,0,0,0,0,0,0,0,0,0,0,0,0,0,0,0,0,0,0,0
0,0,0,0,0,0,0,0,0,0,0,0,0,0,0,0,0,0,0,0,0,0,0,0,0,0,0,0,0,0,0,0,0,0,0,0,0,0
0,0,0,0,0,0,0,0,0,0,0,0,0,0,0,0,0,0,0,0,0,0,0,0,0,0,0,0,0,0,0,0,0,0,0,0,0,0
0,0,0,0,0,0,0,0,0,0,0,0,0,0,0,0,0,0,0,0,0,0,0,0,0,0,0,0,0,0,0,0,0,0,0,0,0,0
0,0,0,0,0,0,0,0,0,0,0,0,0,0,0,0,0,0,0,0,0,0,0,0,0,0,0,0,0,0,0,0,0,0,0,0,0,0
0,0,0,0,0,0,0,0,0,0,0,0,0,0,0,0,0,0,0,0,0,0,0,0,0,0,0,0,0,0,0,0,0,0,0,0,0,0
0,0,0,0,0,0,0,0,0,0,0,0,0,0,0,0,0,0,0,0,0,0,0,0,0,0,0,0,0,0,0,0,0,0,0,0,0,0
0,0,0,0,0,0,0,0,0,0,0,0,0,0,0,0,0,0,0,0,0,0,0,0,0,0,0,0,0,0,0,0,0,0,0,0,0,0
0,0,0,0,0,0,0,0,0,0,0,0,0,0,0,0,0,0,0,0,0,0,0,0,0,0,0,0,0,0,0,0,0,0,0,0,0,0
0,0,0,0,0,0,0,0,0,0,0,0,0,0,0,0,0,0,0,0,0,0,0,0,0,0,0,0,0,0,0,0,0,0,0,0,0,0
0,0,0,0,0,0,0,0,0,0,0,0,0,0,0,0,0,0,0,0,0,0,0,0,0,0,0,0,0,0,0,0,0,0,0,0,0,0
0,0,0,0,0,0,0,0,0,0,0,0,0,0,0,0,0,0,0,0,0,0,0,0,0,0,0,0,0,0,0,0,0,0,0,0,0,0
0,0,0,0,0,0,0,0,0,0,0,0,0,0,0,0,0,0,0,0,0,0,0,0,0,0,0,0,0,0,0,0,0,0,0,0,0,0
0,0,0,0,0,0,0,0,0,0,0,0,0,0,0,0,0,0,0,0,0,0,0,0,0,0,0,0,0,0,0,0,0,0,0,0,0,0
0,0,0,0,0,0,0,0,0,0,0,0,0,0,0,0,0,0,0,0,0,0,0,0,0,0,0,0,0,0,0,0,0,0,0,0,0,0
0,0,0,0,0,0,0,0,0,0,0,0,0,0,0,0,0,0,0,0,0,0,0,0,0,0,0,0,0,0,0,0,0,0,0,0,0,0
0,0,0,0,0,0,0,0,0,0,0,0,0,0,0,0,0,0,0,0,0,0,0,0,0,0,0,0,0,0,0,0,0,0,0,0,0,0
0,0,0,0,0,0,0,0,0,0,0,0,0,0,0,0,0,0,0,0,0,0,0,0,0,0,13,35,32,35,32,35,13,0,0,0,0,0
0,0,0,0,0,0,0,0,0,0,0,0,0,0,0,0,0,0,0,0,0,0,0,0,0,13,0,0,0,56,0,0,0,13,0,0,0,0
0,0,0,0,0,0,0,0,0,0,0,0,0,0,0,0,0,0,0,0,0,0,0,0,0,35,0,0,0,0,0,0,0,35,0,0,0,0
0,0,0,0,0,0,0,0,0,0,0,0,0,0,0,0,0,0,0,0,0,0,0,0,0,32,0,0,0,0,0,0,0,32,0,0,0,0
0,0,0,0,0,0,0,0,0,0,0,0,0,0,0,0,0,0,0,0,0,0,0,0,0,35,0,0,0,0,0,0,0,35,0,0,0,0
0,0,0,0,0,0,0,0,0,0,0,0,0,0,0,0,0,0,0,0,0,0,0,0,0,32,0,0,0,0,0,0,0,32,0,0,0,0
0,0,0,0,0,0,0,0,0,0,0,0,0,0,0,0,0,0,0,0,0,0,0,0,0,35,0,0,0,0,0,0,0,35,0,0,0,0
0,0,0,0,0,0,0,0,0,0,0,0,0,0,0,0,0,0,0,0,0,0,0,0,0,13,0,0,0,0,0,0,0,13,0,0,0,0
0,0,0,0,0,0,0,0,0,0,0,0,0,0,0,0,0,0,0,0,0,0,0,0,0,0,13,35,32,35,32,35,13,0,0,0,0,0
0,0,0,0,0,0,0,0,0,0,44,50,50,50,44,0,0,0,0,0,0,0,0,0,0,0,0,0,0,0,0,0,0,0,0,0,0,0
0,0,0,0,0,0,0,0,0,0,0,0,0,0,0,0,0,0,0,0,0,0,0,0,0,0,0,0,0,0,0,0,0,0,0,0,0,0
0,0,0,0,0,0,0,0,0,0,0,0,0,0,0,0,0,0,0,0,0,0,0,0,0,0,0,0,0,0,0,0,0,0,0,0,0,0
0,0,0,0,0,0,0,0,0,0,0,0,0,0,0,0,0,0,0,0,0,0,0,0,0,0,0,0,0,44,0,0,0,0,0,0,0,0
0,0,0,0,0,0,0,0,0,0,0,0,0,0,0,0,0,0,0,0,0,0,0,0,0,0,0,0,0,50,0,0,0,0,0,0,0,0
0,0,0,0,0,0,0,0,0,0,0,0,0,0,0,0,0,0,0,0,0,0,0,0,0,0,0,0,0,44,0,0,0,0,0,0,0,0
endlayer

layer
0,0,0,0,0,0,0,0,0,0,0,0,0,0,0,0,0,0,0,0,0,0,0,0,0,0,0,0,0,0,0,0,0,0,0,0,0,0
0,0,0,0,0,0,0,0,0,0,0,0,0,0,0,0,0,0,0,0,0,0,0,0,0,0,0,0,0,0,0,0,0,0,0,0,0,0
0,0,0,0,0,0,0,0,0,0,0,0,0,0,0,0,0,0,0,0,0,0,0,0,0,0,0,0,0,0,0,0,0,0,0,0,0,0
0,0,0,0,0,0,0,0,0,0,0,0,0,0,0,0,0,0,0,0,0,0,0,0,0,0,0,0,0,0,0,0,0,0,0,0,0,0
0,0,0,0,0,0,0,0,0,0,0,0,0,0,0,0,0,0,0,0,0,0,0,0,0,0,0,0,0,0,0,0,0,0,0,0,0,0
0,0,0,0,0,0,0,0,0,0,0,0,0,0,0,0,0,0,0,0,0,0,0,0,0,0,0,0,0,0,0,0,0,0,0,0,0,0
0,0,0,0,0,0,0,0,0,0,0,0,0,0,0,0,0,0,0,0,0,0,0,0,0,0,0,0,0,0,0,0,0,0,0,0,0,0
0,0,0,0,0,0,0,0,0,0,0,0,0,0,0,0,0,0,0,0,0,0,0,0,0,0,0,0,0,0,0,0,0,0,0,0,0,0
0,0,0,0,0,0,0,0,0,0,0,0,0,0,0,0,0,0,0,0,0,0,0,0,0,0,0,0,0,0,0,0,0,0,0,0,0,0
0,0,0,0,0,0,0,0,0,0,0,0,0,0,0,0,0,0,0,0,0,0,0,0,0,0,0,0,0,0,0,0,0,0,0,0,0,0
0,0,0,0,0,0,0,0,0,0,0,0,0,0,0,0,0,0,0,0,0,0,0,0,0,0,0,0,0,0,0,0,0,0,0,0,0,0
0,0,0,0,0,0,0,0,0,0,0,0,0,0,0,0,0,0,0,0,0,0,0,0,0,0,0,0,0,0,0,0,0,0,0,0,0,0
0,0,0,0,0,0,0,0,0,0,0,0,0,0,0,0,0,0,0,0,0,0,0,0,0,0,0,0,0,0,0,0,0,0,0,0,0,0
0,0,0,0,0,0,0,0,0,0,0,0,0,0,0,0,0,0,0,0,0,0,0,0,0,0,0,0,0,0,0,0,0,0,0,0,0,0
0,0,0,0,0,0,0,0,0,0,0,0,0,0,0,0,0,0,0,0,0,0,0,0,0,0,0,0,0,0,0,0,0,0,0,0,0,0
0,0,0,0,0,0,0,0,0,0,0,0,0,0,0,0,0,0,0,0,0,0,0,0,0,0,0,0,0,0,0,0,0,0,0,0,0,0
0,0,0,0,0,0,0,0,0,0,0,0,0,0,0,0,0,0,0,0,0,0,0,0,0,0,0,0,0,0,0,0,0,0,0,0,0,0
0,0,0,0,0,0,0,0,0,0,0,0,0,0,0,0,0,0,0,0,0,0,0,0,0,0,13,35,32,35,32,35,13,0,0,0,0,0
0,0,0,0,0,0,0,0,0,0,0,0,0,0,0,0,0,0,0,0,0,0,0,0,0,13,0,0,0,0,0,0,0,13,0,0,0,0
0,0,0,0,0,0,0,0,0,0,0,0,0,0,0,0,0,0,0,0,0,0,0,0,0,35,0,0,0,0,0,0,0,35,0,0,0,0
0,0,0,0,0,0,0,0,0,0,0,0,0,0,0,0,0,0,0,0,0,0,0,0,0,32,0,0,0,0,0,0,0,32,0,0,0,0
0,0,0,0,0,0,0,0,0,0,0,0,0,0,0,0,0,0,0,0,0,0,0,0,0,35,0,0,0,0,0,0,0,35,0,0,0,0
0,0,0,0,0,0,0,0,0,0,0,0,0,0,0,0,0,0,0,0,0,0,0,0,0,32,0,0,0,0,0,0,0,32,0,0,0,0
0,0,0,0,0,0,0,0,0,0,0,0,0,0,0,0,0,0,0,0,0,0,0,0,0,35,0,0,0,0,0,0,0,35,0,0,0,0
0,0,0,0,0,0,0,0,0,0,0,0,0,0,0,0,0,0,0,0,0,0,0,0,0,13,0,0,0,0,0,0,0,13,0,0,0,0
0,0,0,0,0,0,0,0,0,0,0,0,0,0,0,0,0,0,0,0,0,0,0,0,0,0,13,35,32,35,32,35,13,0,0,0,0,0
0,0,0,0,0,0,0,0,0,0,44,44,44,44,44,0,0,0,0,0,0,0,0,0,0,0,0,0,0,45,0,0,0,0,0,0,0,0
0,0,0,0,0,0,0,0,0,0,0,0,0,0,0,0,0,0,0,0,0,0,0,0,0,0,0,0,0,45,0,0,0,0,0,0,0,0
0,0,0,0,0,0,0,0,0,0,0,0,0,0,0,0,0,0,0,0,0,0,0,0,0,0,0,0,0,45,0,0,0,0,0,0,0,0
0,0,0,0,0,0,0,0,0,0,0,0,0,0,0,0,0,0,0,0,0,0,0,0,0,0,0,0,0,44,0,0,0,0,0,0,0,0
0,0,0,0,0,0,0,0,0,0,0,0,0,0,0,0,0,0,0,0,0,0,0,0,0,0,0,0,0,50,0,0,0,0,0,0,0,0
0,0,0,0,0,0,0,0,0,0,0,0,0,0,0,0,0,0,0,0,0,0,0,0,0,0,0,0,0,44,0,0,0,0,0,0,0,0
endlayer

layer
0,0,0,0,0,0,0,0,0,0,0,0,0,0,0,0,0,0,0,0,0,0,0,0,0,0,0,0,0,0,0,0,0,0,0,0,0,0
0,0,0,0,0,0,0,0,0,0,0,0,0,0,0,0,0,0,0,0,0,0,0,0,0,0,0,0,0,0,0,0,0,0,0,0,0,0
0,0,0,0,0,0,0,0,0,0,0,0,0,0,0,0,0,0,0,0,0,0,0,0,0,0,0,0,0,0,0,0,0,0,0,0,0,0
0,0,0,0,0,0,0,0,0,0,0,0,0,0,0,0,0,0,0,0,0,0,0,0,0,0,0,0,0,0,0,0,0,0,0,0,0,0
0,0,0,0,0,0,0,0,0,0,0,0,0,0,0,0,0,0,0,0,0,0,0,0,0,0,0,0,0,0,0,0,0,0,0,0,0,0
0,0,0,0,0,0,0,0,0,0,0,0,0,0,0,0,0,0,0,0,0,0,0,0,0,0,0,0,0,0,0,0,0,0,0,0,0,0
0,0,0,0,0,0,0,0,0,0,0,0,0,0,0,0,0,0,0,0,0,0,0,0,0,0,0,0,0,0,0,0,0,0,0,0,0,0
0,0,0,0,0,0,0,0,0,0,0,0,0,0,0,0,0,0,0,0,0,0,0,0,0,0,0,0,0,0,0,0,0,0,0,0,0,0
0,0,0,0,0,0,0,0,0,0,0,0,0,0,0,0,0,0,0,0,0,0,0,0,0,0,0,0,0,0,0,0,0,0,0,0,0,0
0,0,0,0,0,0,0,0,0,0,0,0,0,0,0,0,0,0,0,0,0,0,0,0,0,0,0,0,0,0,0,0,0,0,0,0,0,0
0,0,0,0,0,0,0,0,0,0,0,0,0,0,0,0,0,0,0,0,0,0,0,0,0,0,0,0,0,0,0,0,0,0,0,0,0,0
0,0,0,0,0,0,0,0,0,0,0,0,0,0,0,0,0,0,0,0,0,0,0,0,0,0,0,0,0,0,0,0,0,0,0,0,0,0
0,0,0,0,0,0,0,0,0,0,0,0,0,0,0,0,0,0,0,0,0,0,0,0,0,0,0,0,0,0,0,0,0,0,0,0,0,0
0,0,0,0,0,0,0,0,0,0,0,0,0,0,0,0,0,0,0,0,0,0,0,0,0,0,0,0,0,0,0,0,0,0,0,0,0,0
0,0,0,0,0,0,0,0,0,0,0,0,0,0,0,0,0,0,0,0,0,0,0,0,0,0,0,0,0,0,0,0,0,0,0,0,0,0
0,0,0,0,0,0,0,0,0,0,0,0,0,0,0,0,0,0,0,0,0,0,0,0,0,0,0,0,0,0,0,0,0,0,0,0,0,0
0,0,0,0,0,0,0,0,0,0,0,0,0,0,0,0,0,0,0,0,0,0,0,0,0,0,0,0,0,0,0,0,0,0,0,0,0,0
0,0,0,0,0,0,0,0,0,0,0,0,0,0,0,0,0,0,0,0,0,0,0,0,0,0,13,35,32,35,32,35,13,0,0,0,0,0
0,0,0,0,0,0,0,0,0,0,0,0,0,0,0,0,0,0,0,0,0,0,0,0,0,13,0,0,0,0,0,0,0,13,0,0,0,0
0,0,0,0,0,0,0,0,0,0,0,0,0,0,0,0,0,0,0,0,0,0,0,0,0,35,0,0,0,0,0,0,0,35,0,0,0,0
0,0,0,0,0,0,0,0,0,0,0,0,0,0,0,0,0,0,0,0,0,0,0,0,0,32,0,0,0,0,0,0,0,32,0,0,0,0
0,0,0,0,0,0,0,0,0,0,0,0,0,0,0,0,0,0,0,0,0,0,0,0,0,35,0,0,0,0,0,0,0,35,0,0,0,0
0,0,0,0,0,0,0,0,0,0,0,0,0,0,0,0,0,0,0,0,0,0,0,0,0,32,0,0,0,0,0,0,0,32,0,0,0,0
0,0,0,0,0,0,0,0,0,0,0,0,0,0,0,0,0,0,0,0,0,0,0,0,0,35,0,0,0,0,0,0,0,35,0,0,0,0
0,0,0,0,0,0,0,0,0,0,0,0,0,0,0,0,0,0,0,0,0,0,0,0,0,13,0,0,0,0,0,0,0,13,0,0,0,0
0,0,0,0,0,0,0,0,0,0,0,0,0,0,0,0,0,0,0,0,0,0,0,0,0,0,13,35,32,35,32,35,13,0,0,0,0,0
0,0,0,0,0,0,0,0,0,0,0,0,0,0,0,0,0,0,0,0,0,0,0,0,0,0,0,0,0,0,0,0,0,0,0,0,0,0
0,0,0,0,0,0,0,0,0,0,0,0,0,0,0,0,0,0,0,0,0,0,0,0,0,0,0,0,0,0,0,0,0,0,0,0,0,0
0,0,0,0,0,0,0,0,0,0,0,0,0,0,0,0,0,0,0,0,0,0,0,0,0,0,0,0,0,0,0,0,0,0,0,0,0,0
0,0,0,0,0,0,0,0,0,0,0,0,0,0,0,0,0,0,0,0,0,0,0,0,0,0,0,0,0,44,0,0,0,0,0,0,0,0
0,0,0,0,0,0,0,0,0,0,0,0,0,0,0,0,0,0,0,0,0,0,0,0,0,0,0,0,0,44,0,0,0,0,0,0,0,0
0,0,0,0,0,0,0,0,0,0,0,0,0,0,0,0,0,0,0,0,0,0,0,0,0,0,0,0,0,44,0,0,0,0,0,0,0,0
endlayer

layer
0,0,0,0,0,0,0,0,0,0,0,0,0,0,0,0,0,0,0,0,0,0,0,0,0,0,0,0,0,0,0,0,0,0,0,0,0,0
0,0,0,0,0,0,0,0,0,0,0,0,0,0,0,0,0,0,0,0,0,0,0,0,0,0,0,0,0,0,0,0,0,0,0,0,0,0
0,0,0,0,0,0,0,0,0,0,0,0,0,0,0,0,0,0,0,0,0,0,0,0,0,0,0,0,0,0,0,0,0,0,0,0,0,0
0,0,0,0,0,0,0,0,0,0,0,0,0,0,0,0,0,0,0,0,0,0,0,0,0,0,0,0,0,0,0,0,0,0,0,0,0,0
0,0,0,0,0,0,0,0,0,0,0,0,0,0,0,0,0,0,0,0,0,0,0,0,0,0,0,0,0,0,0,0,0,0,0,0,0,0
0,0,0,0,0,0,0,0,0,0,0,0,0,0,0,0,0,0,0,0,0,0,0,0,0,0,0,0,0,0,0,0,0,0,0,0,0,0
0,0,0,0,0,0,0,0,0,0,0,0,0,0,0,0,0,0,0,0,0,0,0,0,0,0,0,0,0,0,0,0,0,0,0,0,0,0
0,0,0,0,0,0,0,0,0,0,0,0,0,0,0,0,0,0,0,0,0,0,0,0,0,0,0,0,0,0,0,0,0,0,0,0,0,0
0,0,0,0,0,0,0,0,0,0,0,0,0,0,0,0,0,0,0,0,0,0,0,0,0,0,0,0,0,0,0,0,0,0,0,0,0,0
0,0,0,0,0,0,0,0,0,0,0,0,0,0,0,0,0,0,0,0,0,0,0,0,0,0,0,0,0,0,0,0,0,0,0,0,0,0
0,0,0,0,0,0,0,0,0,0,0,0,0,0,0,0,0,0,0,0,0,0,0,0,0,0,0,0,0,0,0,0,0,0,0,0,0,0
0,0,0,0,0,0,0,0,0,0,0,0,0,0,0,0,0,0,0,0,0,0,0,0,0,0,0,0,0,0,0,0,0,0,0,0,0,0
0,0,0,0,0,0,0,0,0,0,0,0,0,0,0,0,0,0,0,0,0,0,0,0,0,0,0,0,0,0,0,0,0,0,0,0,0,0
0,0,0,0,0,0,0,0,0,0,0,0,0,0,0,0,0,0,0,0,0,0,0,0,0,0,0,0,0,0,0,0,0,0,0,0,0,0
0,0,0,0,0,0,0,0,0,0,0,0,0,0,0,0,0,0,0,0,0,0,0,0,0,0,0,0,0,0,0,0,0,0,0,0,0,0
0,0,0,0,0,0,0,0,0,0,0,0,0,0,0,0,0,0,0,0,0,0,0,0,0,0,0,0,0,0,0,0,0,0,0,0,0,0
0,0,0,0,0,0,0,0,0,0,0,0,0,0,0,0,0,0,0,0,0,0,0,0,0,0,0,0,0,0,0,0,0,0,0,0,0,0
0,0,0,0,0,0,0,0,0,0,0,0,0,0,0,0,0,0,0,0,0,0,0,0,0,0,13,13,13,13,13,13,13,0,0,0,0,0
0,0,0,0,0,0,0,0,0,0,0,0,0,0,0,0,0,0,0,0,0,0,0,0,0,13,49,49,49,49,49,49,49,13,0,0,0,0
0,0,0,0,0,0,0,0,0,0,0,0,0,0,0,0,0,0,0,0,0,0,0,0,0,13,49,49,0,0,0,49,49,13,0,0,0,0
0,0,0,0,0,0,0,0,0,0,0,0,0,0,0,0,0,0,0,0,0,0,0,0,0,13,49,0,0,0,0,0,49,13,0,0,0,0
0,0,0,0,0,0,0,0,0,0,0,0,0,0,0,0,0,0,0,0,0,0,0,0,0,13,49,0,0,7,0,0,49,13,0,0,0,0
0,0,0,0,0,0,0,0,0,0,0,0,0,0,0,0,0,0,0,0,0,0,0,0,0,13,49,0,0,0,0,0,49,13,0,0,0,0
0,0,0,0,0,0,0,0,0,0,0,0,0,0,0,0,0,0,0,0,0,0,0,0,0,13,49,49,0,0,0,0,49,13,0,0,0,0
0,0,0,0,0,0,0,0,0,0,0,0,0,0,0,0,0,0,0,0,0,0,0,0,0,13,49,49,49,49,49,49,49,13,0,0,0,0
0,0,0,0,0,0,0,0,0,0,0,0,0,0,0,0,0,0,0,0,0,0,0,0,0,0,13,13,13,13,13,13,13,0,0,0,0,0
0,0,0,0,0,0,0,0,0,0,0,0,0,0,0,0,0,0,0,0,0,0,0,0,0,0,0,0,0,0,0,0,0,0,0,0,0,0
0,0,0,0,0,0,0,0,0,0,0,0,0,0,0,0,0,0,0,0,0,0,0,0,0,0,0,0,0,0,0,0,0,0,0,0,0,0
0,0,0,0,0,0,0,0,0,0,0,0,0,0,0,0,0,0,0,0,0,0,0,0,0,0,0,0,0,0,0,0,0,0,0,0,0,0
0,0,0,0,0,0,0,0,0,0,0,0,0,0,0,0,0,0,0,0,0,0,0,0,0,0,0,0,0,0,0,0,0,0,0,0,0,0
0,0,0,0,0,0,0,0,0,0,0,0,0,0,0,0,0,0,0,0,0,0,0,0,0,0,0,0,0,0,0,0,0,0,0,0,0,0
0,0,0,0,0,0,0,0,0,0,0,0,0,0,0,0,0,0,0,0,0,0,0,0,0,0,0,0,0,0,0,0,0,0,0,0,0,0
endlayer

layer
0,0,0,0,0,0,0,0,0,0,0,0,0,0,0,0,0,0,0,0,0,0,0,0,0,0,0,0,0,0,0,0,0,0,0,0,0,0
0,0,0,0,0,0,0,0,0,0,0,0,0,0,0,0,0,0,0,0,0,0,0,0,0,0,0,0,0,0,0,0,0,0,0,0,0,0
0,0,0,0,0,0,0,0,0,0,0,0,0,0,0,0,0,0,0,0,0,0,0,0,0,0,0,0,0,0,0,0,0,0,0,0,0,0
0,0,0,0,0,0,0,0,0,0,0,0,0,0,0,0,0,0,0,0,0,0,0,0,0,0,0,0,0,0,0,0,0,0,0,0,0,0
0,0,0,0,0,0,0,0,0,0,0,0,0,0,0,0,0,0,0,0,0,0,0,0,0,0,0,0,0,0,0,0,0,0,0,0,0,0
0,0,0,0,0,0,0,0,0,0,0,0,0,0,0,0,0,0,0,0,0,0,0,0,0,0,0,0,0,0,0,0,0,0,0,0,0,0
0,0,0,0,0,0,0,0,0,0,0,0,0,0,0,0,0,0,0,0,0,0,0,0,0,0,0,0,0,0,0,0,0,0,0,0,0,0
0,0,0,0,0,0,0,0,0,0,0,0,0,0,0,0,0,0,0,0,0,0,0,0,0,0,0,0,0,0,0,0,0,0,0,0,0,0
0,0,0,0,0,0,0,0,0,0,0,0,0,0,0,0,0,0,0,0,0,0,0,0,0,0,0,0,0,0,0,0,0,0,0,0,0,0
0,0,0,0,0,0,0,0,0,0,0,0,0,0,0,0,0,0,0,0,0,0,0,0,0,0,0,0,0,0,0,0,0,0,0,0,0,0
0,0,0,0,0,0,0,0,0,0,0,0,0,0,0,0,0,0,0,0,0,0,0,0,0,0,0,0,0,0,0,0,0,0,0,0,0,0
0,0,0,0,0,0,0,0,0,0,0,0,0,0,0,0,0,0,0,0,0,0,0,0,0,0,0,0,0,0,0,0,0,0,0,0,0,0
0,0,0,0,0,0,0,0,0,0,0,0,0,0,0,0,0,0,0,0,0,0,0,0,0,0,0,0,0,0,0,0,0,0,0,0,0,0
0,0,0,0,0,0,0,0,0,0,0,0,0,0,0,0,0,0,0,0,0,0,0,0,0,0,0,0,0,0,0,0,0,0,0,0,0,0
0,0,0,0,0,0,0,0,0,0,0,0,0,0,0,0,0,0,0,0,0,0,0,0,0,0,0,0,0,0,0,0,0,0,0,0,0,0
0,0,0,0,0,0,0,0,0,0,0,0,0,0,0,0,0,0,0,0,0,0,0,0,0,0,0,0,0,0,0,0,0,0,0,0,0,0
0,0,0,0,0,0,0,0,0,0,0,0,0,0,0,0,0,0,0,0,0,0,0,0,0,0,0,0,0,0,0,0,0,0,0,0,0,0
0,0,0,0,0,0,0,0,0,0,0,0,0,0,0,0,0,0,0,0,0,0,0,0,0,0,0,0,0,0,0,0,0,0,0,0,0,0
0,0,0,0,0,0,0,0,0,0,0,0,0,0,0,0,0,0,0,0,0,0,0,0,0,0,0,0,0,0,0,0,0,0,0,0,0,0
0,0,0,0,0,0,0,0,0,0,0,0,0,0,0,0,0,0,0,0,0,0,0,0,0,0,0,49,49,49,49,49,0,0,0,0,0,0
0,0,0,0,0,0,0,0,0,0,0,0,0,0,0,0,0,0,0,0,0,0,0,0,0,0,0,49,0,0,0,49,0,0,0,0,0,0
0,0,0,0,0,0,0,0,0,0,0,0,0,0,0,0,0,0,0,0,0,0,0,0,0,0,0,49,0,45,0,49,0,0,0,0,0,0
0,0,0,0,0,0,0,0,0,0,0,0,0,0,0,0,0,0,0,0,0,0,0,0,0,0,0,49,0,0,0,49,0,0,0,0,0,0
0,0,0,0,0,0,0,0,0,0,0,0,0,0,0,0,0,0,0,0,0,0,0,0,0,0,0,49,49,49,49,49,0,0,0,0,0,0
0,0,0,0,0,0,0,0,0,0,0,0,0,0,0,0,0,0,0,0,0,0,0,0,0,0,0,0,0,0,0,0,0,0,0,0,0,0
0,0,0,0,0,0,0,0,0,0,0,0,0,0,0,0,0,0,0,0,0,0,0,0,0,0,0,0,0,0,0,0,0,0,0,0,0,0
0,0,0,0,0,0,0,0,0,0,0,0,0,0,0,0,0,0,0,0,0,0,0,0,0,0,0,0,0,0,0,0,0,0,0,0,0,0
0,0,0,0,0,0,0,0,0,0,0,0,0,0,0,0,0,0,0,0,0,0,0,0,0,0,0,0,0,0,0,0,0,0,0,0,0,0
0,0,0,0,0,0,0,0,0,0,0,0,0,0,0,0,0,0,0,0,0,0,0,0,0,0,0,0,0,0,0,0,0,0,0,0,0,0
0,0,0,0,0,0,0,0,0,0,0,0,0,0,0,0,0,0,0,0,0,0,0,0,0,0,0,0,0,0,0,0,0,0,0,0,0,0
0,0,0,0,0,0,0,0,0,0,0,0,0,0,0,0,0,0,0,0,0,0,0,0,0,0,0,0,0,0,0,0,0,0,0,0,0,0
0,0,0,0,0,0,0,0,0,0,0,0,0,0,0,0,0,0,0,0,0,0,0,0,0,0,0,0,0,0,0,0,0,0,0,0,0,0
endlayer

layer
0,0,0,0,0,0,0,0,0,0,0,0,0,0,0,0,0,0,0,0,0,0,0,0,0,0,0,0,0,0,0,0,0,0,0,0,0,0
0,0,0,0,0,0,0,0,0,0,0,0,0,0,0,0,0,0,0,0,0,0,0,0,0,0,0,0,0,0,0,0,0,0,0,0,0,0
0,0,0,0,0,0,0,0,0,0,0,0,0,0,0,0,0,0,0,0,0,0,0,0,0,0,0,0,0,0,0,0,0,0,0,0,0,0
0,0,0,0,0,0,0,0,0,0,0,0,0,0,0,0,0,0,0,0,0,0,0,0,0,0,0,0,0,0,0,0,0,0,0,0,0,0
0,0,0,0,0,0,0,0,0,0,0,0,0,0,0,0,0,0,0,0,0,0,0,0,0,0,0,0,0,0,0,0,0,0,0,0,0,0
0,0,0,0,0,0,0,0,0,0,0,0,0,0,0,0,0,0,0,0,0,0,0,0,0,0,0,0,0,0,0,0,0,0,0,0,0,0
0,0,0,0,0,0,0,0,0,0,0,0,0,0,0,0,0,0,0,0,0,0,0,0,0,0,0,0,0,0,0,0,0,0,0,0,0,0
0,0,0,0,0,0,0,0,0,0,0,0,0,0,0,0,0,0,0,0,0,0,0,0,0,0,0,0,0,0,0,0,0,0,0,0,0,0
0,0,0,0,0,0,0,0,0,0,0,0,0,0,0,0,0,0,0,0,0,0,0,0,0,0,0,0,0,0,0,0,0,0,0,0,0,0
0,0,0,0,0,0,0,0,0,0,0,0,0,0,0,0,0,0,0,0,0,0,0,0,0,0,0,0,0,0,0,0,0,0,0,0,0,0
0,0,0,0,0,0,0,0,0,0,0,0,0,0,0,0,0,0,0,0,0,0,0,0,0,0,0,0,0,0,0,0,0,0,0,0,0,0
0,0,0,0,0,0,0,0,0,0,0,0,0,0,0,0,0,0,0,0,0,0,0,0,0,0,0,0,0,0,0,0,0,0,0,0,0,0
0,0,0,0,0,0,0,0,0,0,0,0,0,0,0,0,0,0,0,0,0,0,0,0,0,0,0,0,0,0,0,0,0,0,0,0,0,0
0,0,0,0,0,0,0,0,0,0,0,0,0,0,0,0,0,0,0,0,0,0,0,0,0,0,0,0,0,0,0,0,0,0,0,0,0,0
0,0,0,0,0,0,0,0,0,0,0,0,0,0,0,0,0,0,0,0,0,0,0,0,0,0,0,0,0,0,0,0,0,0,0,0,0,0
0,0,0,0,0,0,0,0,0,0,0,0,0,0,0,0,0,0,0,0,0,0,0,0,0,0,0,0,0,0,0,0,0,0,0,0,0,0
0,0,0,0,0,0,0,0,0,0,0,0,0,0,0,0,0,0,0,0,0,0,0,0,0,0,0,0,0,0,0,0,0,0,0,0,0,0
0,0,0,0,0,0,0,0,0,0,0,0,0,0,0,0,0,0,0,0,0,0,0,0,0,0,0,0,0,0,0,0,0,0,0,0,0,0
0,0,0,0,0,0,0,0,0,0,0,0,0,0,0,0,0,0,0,0,0,0,0,0,0,0,0,0,0,0,0,0,0,0,0,0,0,0
0,0,0,0,0,0,0,0,0,0,0,0,0,0,0,0,0,0,0,0,0,0,0,0,0,0,0,0,0,0,0,0,0,0,0,0,0,0
0,0,0,0,0,0,0,0,0,0,0,0,0,0,0,0,0,0,0,0,0,0,0,0,0,0,0,0,49,49,49,0,0,0,0,0,0,0
0,0,0,0,0,0,0,0,0,0,0,0,0,0,0,0,0,0,0,0,0,0,0,0,0,0,0,0,49,45,49,0,0,0,0,0,0,0
0,0,0,0,0,0,0,0,0,0,0,0,0,0,0,0,0,0,0,0,0,0,0,0,0,0,0,0,49,49,49,0,0,0,0,0,0,0
0,0,0,0,0,0,0,0,0,0,0,0,0,0,0,0,0,0,0,0,0,0,0,0,0,0,0,0,0,0,0,0,0,0,0,0,0,0
0,0,0,0,0,0,0,0,0,0,0,0,0,0,0,0,0,0,0,0,0,0,0,0,0,0,0,0,0,0,0,0,0,0,0,0,0,0
0,0,0,0,0,0,0,0,0,0,0,0,0,0,0,0,0,0,0,0,0,0,0,0,0,0,0,0,0,0,0,0,0,0,0,0,0,0
0,0,0,0,0,0,0,0,0,0,0,0,0,0,0,0,0,0,0,0,0,0,0,0,0,0,0,0,0,0,0,0,0,0,0,0,0,0
0,0,0,0,0,0,0,0,0,0,0,0,0,0,0,0,0,0,0,0,0,0,0,0,0,0,0,0,0,0,0,0,0,0,0,0,0,0
0,0,0,0,0,0,0,0,0,0,0,0,0,0,0,0,0,0,0,0,0,0,0,0,0,0,0,0,0,0,0,0,0,0,0,0,0,0
0,0,0,0,0,0,0,0,0,0,0,0,0,0,0,0,0,0,0,0,0,0,0,0,0,0,0,0,0,0,0,0,0,0,0,0,0,0
0,0,0,0,0,0,0,0,0,0,0,0,0,0,0,0,0,0,0,0,0,0,0,0,0,0,0,0,0,0,0,0,0,0,0,0,0,0
0,0,0,0,0,0,0,0,0,0,0,0,0,0,0,0,0,0,0,0,0,0,0,0,0,0,0,0,0,0,0,0,0,0,0,0,0,0
endlayer

layer
0,0,0,0,0,0,0,0,0,0,0,0,0,0,0,0,0,0,0,0,0,0,0,0,0,0,0,0,0,0,0,0,0,0,0,0,0,0
0,0,0,0,0,0,0,0,0,0,0,0,0,0,0,0,0,0,0,0,0,0,0,0,0,0,0,0,0,0,0,0,0,0,0,0,0,0
0,0,0,0,0,0,0,0,0,0,0,0,0,0,0,0,0,0,0,0,0,0,0,0,0,0,0,0,0,0,0,0,0,0,0,0,0,0
0,0,0,0,0,0,0,0,0,0,0,0,0,0,0,0,0,0,0,0,0,0,0,0,0,0,0,0,0,0,0,0,0,0,0,0,0,0
0,0,0,0,0,0,0,0,0,0,0,0,0,0,0,0,0,0,0,0,0,0,0,0,0,0,0,0,0,0,0,0,0,0,0,0,0,0
0,0,0,0,0,0,0,0,0,0,0,0,0,0,0,0,0,0,0,0,0,0,0,0,0,0,0,0,0,0,0,0,0,0,0,0,0,0
0,0,0,0,0,0,0,0,0,0,0,0,0,0,0,0,0,0,0,0,0,0,0,0,0,0,0,0,0,0,0,0,0,0,0,0,0,0
0,0,0,0,0,0,0,0,0,0,0,0,0,0,0,0,0,0,0,0,0,0,0,0,0,0,0,0,0,0,0,0,0,0,0,0,0,0
0,0,0,0,0,0,0,0,0,0,0,0,0,0,0,0,0,0,0,0,0,0,0,0,0,0,0,0,0,0,0,0,0,0,0,0,0,0
0,0,0,0,0,0,0,0,0,0,0,0,0,0,0,0,0,0,0,0,0,0,0,0,0,0,0,0,0,0,0,0,0,0,0,0,0,0
0,0,0,0,0,0,0,0,0,0,0,0,0,0,0,0,0,0,0,0,0,0,0,0,0,0,0,0,0,0,0,0,0,0,0,0,0,0
0,0,0,0,0,0,0,0,0,0,0,0,0,0,0,0,0,0,0,0,0,0,0,0,0,0,0,0,0,0,0,0,0,0,0,0,0,0
0,0,0,0,0,0,0,0,0,0,0,0,0,0,0,0,0,0,0,0,0,0,0,0,0,0,0,0,0,0,0,0,0,0,0,0,0,0
0,0,0,0,0,0,0,0,0,0,0,0,0,0,0,0,0,0,0,0,0,0,0,0,0,0,0,0,0,0,0,0,0,0,0,0,0,0
0,0,0,0,0,0,0,0,0,0,0,0,0,0,0,0,0,0,0,0,0,0,0,0,0,0,0,0,0,0,0,0,0,0,0,0,0,0
0,0,0,0,0,0,0,0,0,0,0,0,0,0,0,0,0,0,0,0,0,0,0,0,0,0,0,0,0,0,0,0,0,0,0,0,0,0
0,0,0,0,0,0,0,0,0,0,0,0,0,0,0,0,0,0,0,0,0,0,0,0,0,0,0,0,0,0,0,0,0,0,0,0,0,0
0,0,0,0,0,0,0,0,0,0,0,0,0,0,0,0,0,0,0,0,0,0,0,0,0,0,0,0,0,0,0,0,0,0,0,0,0,0
0,0,0,0,0,0,0,0,0,0,0,0,0,0,0,0,0,0,0,0,0,0,0,0,0,0,0,0,0,0,0,0,0,0,0,0,0,0
0,0,0,0,0,0,0,0,0,0,0,0,0,0,0,0,0,0,0,0,0,0,0,0,0,0,0,0,0,0,0,0,0,0,0,0,0,0
0,0,0,0,0,0,0,0,0,0,0,0,0,0,0,0,0,0,0,0,0,0,0,0,0,0,0,0,0,0,0,0,0,0,0,0,0,0
0,0,0,0,0,0,0,0,0,0,0,0,0,0,0,0,0,0,0,0,0,0,0,0,0,0,0,0,0,49,0,0,0,0,0,0,0,0
0,0,0,0,0,0,0,0,0,0,0,0,0,0,0,0,0,0,0,0,0,0,0,0,0,0,0,0,0,0,0,0,0,0,0,0,0,0
0,0,0,0,0,0,0,0,0,0,0,0,0,0,0,0,0,0,0,0,0,0,0,0,0,0,0,0,0,0,0,0,0,0,0,0,0,0
0,0,0,0,0,0,0,0,0,0,0,0,0,0,0,0,0,0,0,0,0,0,0,0,0,0,0,0,0,0,0,0,0,0,0,0,0,0
0,0,0,0,0,0,0,0,0,0,0,0,0,0,0,0,0,0,0,0,0,0,0,0,0,0,0,0,0,0,0,0,0,0,0,0,0,0
0,0,0,0,0,0,0,0,0,0,0,0,0,0,0,0,0,0,0,0,0,0,0,0,0,0,0,0,0,0,0,0,0,0,0,0,0,0
0,0,0,0,0,0,0,0,0,0,0,0,0,0,0,0,0,0,0,0,0,0,0,0,0,0,0,0,0,0,0,0,0,0,0,0,0,0
0,0,0,0,0,0,0,0,0,0,0,0,0,0,0,0,0,0,0,0,0,0,0,0,0,0,0,0,0,0,0,0,0,0,0,0,0,0
0,0,0,0,0,0,0,0,0,0,0,0,0,0,0,0,0,0,0,0,0,0,0,0,0,0,0,0,0,0,0,0,0,0,0,0,0,0
0,0,0,0,0,0,0,0,0,0,0,0,0,0,0,0,0,0,0,0,0,0,0,0,0,0,0,0,0,0,0,0,0,0,0,0,0,0
0,0,0,0,0,0,0,0,0,0,0,0,0,0,0,0,0,0,0,0,0,0,0,0,0,0,0,0,0,0,0,0,0,0,0,0,0,0
endlayer

layer
0,0,0,0,0,0,0,0,0,0,0,0,0,0,0,0,0,0,0,0,0,0,0,0,0,0,0,0,0,0,0,0,0,0,0,0,0,0
0,0,0,0,0,0,0,0,0,0,0,0,0,0,0,0,0,0,0,0,0,0,0,0,0,0,0,0,0,0,0,0,0,0,0,0,0,0
0,0,0,0,0,0,0,0,0,0,0,0,0,0,0,0,0,0,0,0,0,0,0,0,0,0,0,0,0,0,0,0,0,0,0,0,0,0
0,0,0,0,0,0,0,0,0,0,0,0,0,0,0,0,0,0,0,0,0,0,0,0,0,0,0,0,0,0,0,0,0,0,0,0,0,0
0,0,0,0,0,0,0,0,0,0,0,0,0,0,0,0,0,0,0,0,0,0,0,0,0,0,0,0,0,0,0,0,0,0,0,0,0,0
0,0,0,0,0,0,0,0,0,0,0,0,0,0,0,0,0,0,0,0,0,0,0,0,0,0,0,0,0,0,0,0,0,0,0,0,0,0
0,0,0,0,0,0,0,0,0,0,0,0,0,0,0,0,0,0,0,0,0,0,0,0,0,0,0,0,0,0,0,0,0,0,0,0,0,0
0,0,0,0,0,0,0,0,0,0,0,0,0,0,0,0,0,0,0,0,0,0,0,0,0,0,0,0,0,0,0,0,0,0,0,0,0,0
0,0,0,0,0,0,0,0,0,0,0,0,0,0,0,0,0,0,0,0,0,0,0,0,0,0,0,0,0,0,0,0,0,0,0,0,0,0
0,0,0,0,0,0,0,0,0,0,0,0,0,0,0,0,0,0,0,0,0,0,0,0,0,0,0,0,0,0,0,0,0,0,0,0,0,0
0,0,0,0,0,0,0,0,0,0,0,0,0,0,0,0,0,0,0,0,0,0,0,0,0,0,0,0,0,0,0,0,0,0,0,0,0,0
0,0,0,0,0,0,0,0,0,0,0,0,0,0,0,0,0,0,0,0,0,0,0,0,0,0,0,0,0,0,0,0,0,0,0,0,0,0
0,0,0,0,0,0,0,0,0,0,0,0,0,0,0,0,0,0,0,0,0,0,0,0,0,0,0,0,0,0,0,0,0,0,0,0,0,0
0,0,0,0,0,0,0,0,0,0,0,0,0,0,0,0,0,0,0,0,0,0,0,0,0,0,0,0,0,0,0,0,0,0,0,0,0,0
0,0,0,0,0,0,0,0,0,0,0,0,0,0,0,0,0,0,0,0,0,0,0,0,0,0,0,0,0,0,0,0,0,0,0,0,0,0
0,0,0,0,0,0,0,0,0,0,0,0,0,0,0,0,0,0,0,0,0,0,0,0,0,0,0,0,0,0,0,0,0,0,0,0,0,0
0,0,0,0,0,0,0,0,0,0,0,0,0,0,0,0,0,0,0,0,0,0,0,0,0,0,0,0,0,0,0,0,0,0,0,0,0,0
0,0,0,0,0,0,0,0,0,0,0,0,0,0,0,0,0,0,0,0,0,0,0,0,0,0,0,0,0,0,0,0,0,0,0,0,0,0
0,0,0,0,0,0,0,0,0,0,0,0,0,0,0,0,0,0,0,0,0,0,0,0,0,0,0,0,0,0,0,0,0,0,0,0,0,0
0,0,0,0,0,0,0,0,0,0,0,0,0,0,0,0,0,0,0,0,0,0,0,0,0,0,0,0,0,0,0,0,0,0,0,0,0,0
0,0,0,0,0,0,0,0,0,0,0,0,0,0,0,0,0,0,0,0,0,0,0,0,0,0,0,0,0,0,0,0,0,0,0,0,0,0
0,0,0,0,0,0,0,0,0,0,0,0,0,0,0,0,0,0,0,0,0,0,0,0,0,0,0,0,0,49,0,0,0,0,0,0,0,0
0,0,0,0,0,0,0,0,0,0,0,0,0,0,0,0,0,0,0,0,0,0,0,0,0,0,0,0,0,0,0,0,0,0,0,0,0,0
0,0,0,0,0,0,0,0,0,0,0,0,0,0,0,0,0,0,0,0,0,0,0,0,0,0,0,0,0,0,0,0,0,0,0,0,0,0
0,0,0,0,0,0,0,0,0,0,0,0,0,0,0,0,0,0,0,0,0,0,0,0,0,0,0,0,0,0,0,0,0,0,0,0,0,0
0,0,0,0,0,0,0,0,0,0,0,0,0,0,0,0,0,0,0,0,0,0,0,0,0,0,0,0,0,0,0,0,0,0,0,0,0,0
0,0,0,0,0,0,0,0,0,0,0,0,0,0,0,0,0,0,0,0,0,0,0,0,0,0,0,0,0,0,0,0,0,0,0,0,0,0
0,0,0,0,0,0,0,0,0,0,0,0,0,0,0,0,0,0,0,0,0,0,0,0,0,0,0,0,0,0,0,0,0,0,0,0,0,0
0,0,0,0,0,0,0,0,0,0,0,0,0,0,0,0,0,0,0,0,0,0,0,0,0,0,0,0,0,0,0,0,0,0,0,0,0,0
0,0,0,0,0,0,0,0,0,0,0,0,0,0,0,0,0,0,0,0,0,0,0,0,0,0,0,0,0,0,0,0,0,0,0,0,0,0
0,0,0,0,0,0,0,0,0,0,0,0,0,0,0,0,0,0,0,0,0,0,0,0,0,0,0,0,0,0,0,0,0,0,0,0,0,0
0,0,0,0,0,0,0,0,0,0,0,0,0,0,0,0,0,0,0,0,0,0,0,0,0,0,0,0,0,0,0,0,0,0,0,0,0,0
endlayer

