# Converted from schematic
# THIS TEMPLATE USES DEFAULTS!  Please edit for corrections.
# If you need help, consult template_rules.txt

weight=20
embed_into_distance=5
acceptable_target_blocks=1,2,3,12,13,250
dimensions=12,20,18
allowable_overhang=0
max_cut_in=2
cut_in_buffer=1
max_leveling=2
leveling_buffer=1
preserve_water=0
preserve_lava=0
preserve_plants=0


rule1=0,100,3134-10
rule2=0,100,2843-4
rule3=0,100,2542
rule4=0,100,2843-4
rule5=0,100,2843-8
rule6=0,100,2802-7
rule7=0,100,2843-14,2843-14,2843-14,2843-14,2843
rule8=0,50,308,308,308,308,308,308,313,313,314,327
rule9=0,100,2013-1,2013-2,2013-3,2013-4,2013-5,2013-6,2013-7,2013-8,2013-9,2013-10,2013-11,2013-12,2013-13,2013-14,2013-15
rule10=0,100,2245,2245,2245,311
rule11=0,100,2013
rule12=0,100,113
rule13=0,95,2835-2,2835-2,2835-2,2835-2,2835-2,2835-2,2835-2,2835-1,2835-1,2835-0
rule14=0,25,3225-3
rule15=0,100,0
rule16=0,25,2244
rule17=0,95,2835-2,2835-2,2835-2,2835-2,2835-2,2835-2,2835-2,2835-1,2835-1,2835-0
rule18=0,100,3134,3134,3134,3134-8,3134-2
rule19=0,99,300


layer
1,1,1,1,1,1,1,1,1,1,1,1,1,1,1,1,1,1
1,1,1,1,1,1,1,1,1,1,1,1,1,1,1,1,1,1
1,1,2,2,2,2,2,2,2,2,2,2,2,2,2,2,1,1
1,1,2,2,2,2,2,2,2,2,2,2,2,2,2,2,1,1
1,1,2,2,2,2,2,2,2,3,2,2,2,2,2,2,1,1
1,1,2,2,2,2,2,2,2,2,2,2,2,2,2,2,1,1
1,1,2,2,2,2,2,2,2,2,2,2,2,2,2,2,1,1
1,1,2,2,2,2,2,2,4,2,2,2,2,2,2,2,1,1
1,1,2,2,2,2,2,2,4,2,2,2,2,2,2,2,1,1
1,1,2,2,2,2,2,2,2,2,2,2,2,2,2,2,1,1
1,1,2,2,2,2,2,2,2,2,2,2,2,2,2,2,1,1
1,1,2,2,2,2,2,2,2,2,2,2,2,2,2,2,1,1
1,1,2,2,2,2,2,2,2,2,2,2,2,2,2,2,1,1
1,1,2,2,2,2,2,2,2,2,2,2,2,2,2,2,1,1
1,1,2,2,2,2,2,2,2,2,2,2,2,2,2,2,1,1
1,1,2,2,2,2,2,2,3,2,2,2,2,2,2,2,1,1
1,1,2,2,2,2,2,2,2,2,2,2,2,2,2,2,1,1
1,1,2,2,2,2,2,2,2,2,2,2,2,2,2,2,1,1
1,1,1,1,1,1,1,1,1,1,1,1,1,1,1,1,1,1
1,1,1,1,1,1,1,1,1,1,1,1,1,1,1,1,1,1
endlayer

layer
19,19,19,19,19,19,19,19,19,19,19,19,19,19,19,19,19,19
19,19,19,19,19,19,19,19,19,19,19,19,19,19,19,19,19,19
19,19,5,6,6,6,6,6,5,19,5,6,6,6,6,5,19,19
19,19,6,0,0,0,0,0,0,0,0,0,0,0,0,6,19,19
19,19,6,0,0,0,0,0,0,0,0,0,0,0,0,6,19,19
19,19,7,7,0,7,7,7,7,7,7,7,7,0,7,7,19,19
19,19,7,0,0,0,0,10,7,7,10,0,0,0,0,7,19,19
19,19,7,0,0,0,9,11,7,7,11,9,0,0,0,7,19,19
19,19,7,8,0,0,0,10,7,7,10,0,0,0,8,7,19,19
19,19,7,7,7,7,7,7,7,7,7,7,7,7,7,7,19,19
19,19,7,7,7,7,7,7,7,7,7,7,7,7,7,7,19,19
19,19,7,8,0,0,0,10,7,7,10,0,0,0,8,7,19,19
19,19,7,0,0,0,9,11,7,7,11,9,0,0,0,7,19,19
19,19,7,0,0,0,0,10,7,7,10,0,0,0,0,7,19,19
19,19,7,7,0,7,7,7,7,7,7,7,7,0,7,7,19,19
19,19,6,0,0,0,0,0,0,0,0,0,0,0,0,6,19,19
19,19,6,0,0,0,0,0,0,0,0,0,0,0,0,6,19,19
19,19,5,6,6,6,6,5,19,5,6,6,6,6,6,5,19,19
19,19,19,19,19,19,19,19,19,19,19,19,19,19,19,19,19,19
19,19,19,19,19,19,19,19,19,19,19,19,19,19,19,19,19,19
endlayer

layer
19,19,19,19,19,19,19,19,19,19,19,19,19,19,19,19,19,19
19,19,19,19,19,19,19,19,19,19,19,19,19,19,19,19,19,19
19,19,12,19,19,19,19,19,12,19,12,19,19,19,19,12,19,19
19,19,19,19,19,19,19,19,19,19,19,19,19,19,19,19,19,19
19,19,19,19,19,19,19,19,19,19,19,19,19,19,19,19,19,19
19,19,7,13,19,13,14,13,7,7,13,14,13,19,13,7,19,19
19,19,13,0,0,0,0,0,13,13,16,19,19,19,19,13,19,19
19,19,14,0,0,0,0,0,13,13,0,0,0,0,0,14,19,19
19,19,13,0,0,0,0,16,13,13,0,0,0,0,0,13,19,19
19,19,7,13,13,13,13,13,7,7,13,13,13,13,13,7,19,19
19,19,7,13,13,13,13,13,7,7,13,13,13,13,13,7,19,19
19,19,13,0,0,0,0,0,13,13,16,0,0,0,0,13,19,19
19,19,14,0,0,0,0,0,13,13,0,0,0,0,0,14,19,19
19,19,13,0,0,0,0,16,13,13,0,0,0,0,15,13,19,19
19,19,7,13,19,13,14,13,7,7,13,14,13,19,13,7,19,19
19,19,19,19,19,19,19,19,19,19,19,19,19,19,19,19,19,19
19,19,19,19,19,19,19,19,19,19,19,19,19,19,19,19,19,19
19,19,12,19,19,19,19,12,19,12,19,19,19,19,19,12,19,19
19,19,19,19,19,19,19,19,19,19,19,19,19,19,19,19,19,19
19,19,19,19,19,19,19,19,19,19,19,19,19,19,19,19,19,19
endlayer

layer
19,19,19,19,19,19,19,19,19,19,19,19,19,19,19,19,19,19
19,19,19,19,19,19,19,19,19,19,19,19,19,19,19,19,19,19
19,19,12,19,19,19,19,19,12,19,12,19,19,19,19,12,19,19
19,19,19,19,19,19,19,19,19,19,19,19,19,19,19,19,19,19
0,0,0,0,0,0,0,0,0,0,0,0,0,0,0,0,0,0
19,19,7,13,13,13,14,13,7,7,13,14,13,13,13,7,19,19
19,19,13,0,0,0,0,0,13,13,0,0,0,0,0,13,19,19
19,19,14,0,0,0,0,0,13,13,0,0,0,0,0,14,19,19
19,19,13,0,0,0,0,0,13,13,0,0,0,0,0,13,19,19
19,0,7,13,13,13,13,13,7,7,13,13,13,13,13,7,19,19
19,19,7,13,13,13,13,13,7,7,13,13,13,13,13,7,19,19
19,19,13,0,0,0,0,0,13,13,0,0,0,0,0,13,19,19
19,19,14,0,0,0,0,0,13,13,0,0,0,0,0,14,19,19
19,19,13,0,0,0,0,0,13,13,0,0,0,0,0,13,19,19
19,19,7,13,13,13,14,13,7,7,13,14,13,13,13,7,19,19
0,0,0,0,0,0,0,0,0,0,0,0,0,0,0,0,0,0
19,19,19,19,19,19,19,19,19,19,19,19,19,19,19,19,19,19
19,19,12,19,19,19,19,12,19,12,19,19,19,19,19,12,19,19
19,19,19,19,19,19,19,19,19,19,19,19,19,19,19,19,19,19
19,19,19,19,19,19,19,19,19,19,19,19,19,19,19,19,19,19
endlayer

layer
19,19,19,19,19,19,19,19,19,19,19,19,19,19,19,19,19,19
19,19,19,19,19,19,19,19,19,19,19,19,19,19,19,19,19,19
19,19,12,19,19,19,19,19,12,19,12,19,19,19,19,12,19,19
0,0,0,0,0,0,0,0,0,0,0,0,0,0,0,0,0,0
0,0,0,0,0,0,0,0,0,0,0,0,0,0,0,0,0,0
19,19,7,13,13,13,14,13,7,7,13,14,13,13,13,7,19,19
19,19,13,0,0,0,0,0,13,13,0,0,0,0,0,13,19,19
19,19,14,0,0,0,0,0,13,13,0,0,0,0,0,14,19,19
19,19,13,0,0,0,0,0,13,13,0,0,0,0,0,13,19,19
19,19,7,13,13,13,13,13,7,7,13,13,13,13,13,7,19,19
19,19,7,13,13,13,13,13,7,7,13,13,13,13,13,7,19,19
19,19,13,0,0,0,0,0,13,13,0,0,0,0,0,13,19,19
19,19,14,0,0,0,0,0,13,13,0,0,0,0,0,14,19,19
19,19,13,0,0,0,0,0,13,13,0,0,0,0,0,13,19,19
19,19,7,13,13,13,14,13,7,7,13,14,13,13,13,7,19,19
0,0,0,0,0,0,0,0,0,0,0,0,0,0,0,0,0,0
0,0,0,0,0,0,0,0,0,0,0,0,0,0,0,0,0,0
19,19,12,19,19,19,19,12,19,12,19,19,19,19,19,12,19,19
19,19,19,19,19,19,19,19,19,19,19,19,19,19,19,19,19,19
19,19,19,19,19,19,19,19,19,19,19,19,19,19,19,19,19,19
endlayer

layer
0,0,0,0,0,0,0,0,0,0,0,0,0,0,0,0,0,0
0,0,0,0,0,0,0,0,0,0,0,0,0,0,0,0,0,0
0,0,5,0,0,0,0,0,5,0,5,0,0,0,0,5,0,0
0,0,0,0,0,0,0,0,0,0,0,0,0,0,0,0,0,0
0,0,0,0,0,0,0,0,0,0,0,0,0,0,0,0,0,0
0,0,7,13,13,13,14,13,7,7,13,14,13,13,13,7,0,0
0,0,13,0,0,0,0,0,13,13,0,0,0,0,0,13,0,0
0,0,14,0,0,0,0,0,13,13,0,0,0,0,0,14,0,0
0,0,13,0,0,0,0,0,13,13,0,0,0,0,0,13,0,0
0,0,7,13,13,13,13,13,7,7,13,13,13,13,13,7,0,0
0,0,7,13,13,13,13,13,7,7,13,13,13,13,13,7,0,0
0,0,13,0,0,0,0,0,13,13,0,0,0,0,0,13,0,0
0,0,14,0,0,0,0,0,13,13,0,0,0,0,0,14,0,0
0,0,13,0,0,0,0,0,13,13,0,0,0,0,0,13,0,0
0,0,7,13,13,13,14,13,7,7,13,14,13,13,13,7,0,0
0,0,0,0,0,0,0,0,0,0,0,0,0,0,0,0,0,0
0,0,0,0,0,0,0,0,0,0,0,0,0,0,0,0,0,0
0,0,5,0,0,0,0,5,0,5,0,0,0,0,0,5,0,0
0,0,0,0,0,0,0,0,0,0,0,0,0,0,0,0,0,0
0,0,0,0,0,0,0,0,0,0,0,0,0,0,0,0,0,0
endlayer

layer
0,0,0,0,0,0,0,0,0,0,0,0,0,0,0,0,0,0
0,0,0,0,0,0,0,0,0,0,0,0,0,0,0,0,0,0
0,0,2,2,2,2,2,2,2,2,2,2,2,2,2,2,0,0
0,0,2,2,2,2,2,2,2,2,2,2,2,2,2,2,0,0
0,0,2,2,2,2,2,2,2,3,2,2,2,2,2,2,0,0
0,0,7,2,2,2,2,2,2,2,2,2,2,2,2,7,0,0
0,0,7,2,2,2,2,2,2,2,2,2,2,2,2,7,0,0
0,0,7,2,2,2,2,2,2,2,2,2,2,2,2,7,0,0
0,0,7,2,2,2,2,2,2,2,2,2,2,2,2,7,0,0
0,0,7,2,2,2,2,2,2,2,2,2,2,2,2,7,0,0
0,0,7,2,2,2,2,2,2,2,2,2,2,2,2,7,0,0
0,0,7,2,2,2,2,2,2,2,2,2,2,2,2,7,0,0
0,0,7,2,2,2,2,2,2,2,2,2,2,2,2,7,0,0
0,0,7,2,2,2,2,2,2,2,2,2,2,2,2,7,0,0
0,0,7,2,2,2,2,2,2,2,2,2,2,2,2,7,0,0
0,0,2,2,2,2,2,2,3,2,2,2,2,2,2,2,0,0
0,0,2,2,2,2,2,2,2,2,2,2,2,2,2,2,0,0
0,0,2,2,2,2,2,2,2,2,2,2,2,2,2,2,0,0
0,0,0,0,0,0,0,0,0,0,0,0,0,0,0,0,0,0
0,0,0,0,0,0,0,0,0,0,0,0,0,0,0,0,0,0
endlayer

layer
0,0,0,0,0,0,0,0,0,0,0,0,0,0,0,0,0,0
0,0,0,0,0,0,0,0,0,0,0,0,0,0,0,0,0,0
0,0,5,6,6,6,6,6,6,6,6,6,6,6,6,5,0,0
0,0,6,0,0,0,0,0,0,0,0,0,0,0,0,6,0,0
0,0,6,0,0,0,0,0,0,0,0,0,0,0,0,6,0,0
0,0,7,13,0,13,14,13,7,7,13,14,13,0,13,7,0,0
0,0,13,0,0,0,0,10,13,13,10,0,0,0,0,13,0,0
0,0,14,0,0,0,9,11,13,13,11,9,0,0,0,14,0,0
0,0,13,8,0,0,0,10,13,13,10,0,0,0,8,13,0,0
0,0,7,13,13,13,13,13,7,7,13,13,13,13,13,7,0,0
0,0,7,13,13,13,13,13,7,7,17,13,13,13,13,7,0,0
0,0,13,8,0,0,0,10,13,13,10,0,0,0,8,13,0,0
0,0,14,0,0,0,9,11,13,13,11,9,0,0,0,14,0,0
0,0,13,0,0,0,0,10,13,13,10,0,0,0,0,13,0,0
0,0,7,13,0,13,14,13,7,7,13,14,13,0,13,7,0,0
0,0,6,0,0,0,0,0,0,0,0,0,0,0,0,6,0,0
0,0,6,0,0,0,0,0,0,0,0,0,0,0,0,6,0,0
0,0,5,6,6,6,6,6,6,6,6,6,6,6,6,5,0,0
0,0,0,0,0,0,0,0,0,0,0,0,0,0,0,0,0,0
0,0,0,0,0,0,0,0,0,0,0,0,0,0,0,0,0,0
endlayer

layer
0,0,0,0,0,0,0,0,0,0,0,0,0,0,0,0,0,0
0,0,0,0,0,0,0,0,0,0,0,0,0,0,0,0,0,0
0,0,0,0,0,0,0,0,0,0,0,0,0,0,0,0,0,0
0,0,0,0,0,0,0,0,0,0,0,0,0,0,0,0,0,0
0,0,0,0,0,0,0,0,0,0,0,0,0,0,0,0,0,0
0,0,7,13,0,13,14,13,7,7,13,14,13,0,13,7,0,0
0,0,13,0,0,0,0,0,13,13,0,0,0,0,0,13,0,0
0,0,14,0,0,0,0,0,13,13,0,0,0,0,0,14,0,0
0,0,13,0,0,0,0,16,13,13,16,0,0,0,0,13,0,0
0,0,7,13,13,13,13,13,7,7,13,13,13,13,13,7,0,0
0,0,7,13,13,13,13,13,7,7,17,13,13,13,17,7,0,0
0,0,13,0,0,0,0,16,13,13,0,0,0,0,0,13,0,0
0,0,14,0,0,0,0,0,13,13,0,0,0,0,0,14,0,0
0,0,13,0,0,0,0,0,13,13,16,0,0,0,0,13,0,0
0,0,7,13,0,13,14,13,7,7,13,14,13,0,13,7,0,0
0,0,0,0,0,0,0,0,0,0,0,0,0,0,0,0,0,0
0,0,0,0,0,0,0,0,0,0,0,0,0,0,0,0,0,0
0,0,0,0,0,0,0,0,0,0,0,0,0,0,0,0,0,0
0,0,0,0,0,0,0,0,0,0,0,0,0,0,0,0,0,0
0,0,0,0,0,0,0,0,0,0,0,0,0,0,0,0,0,0
endlayer

layer
0,0,0,0,0,0,0,0,0,0,0,0,0,0,0,0,0,0
0,0,0,0,0,0,0,0,0,0,0,0,0,0,0,0,0,0
0,0,0,0,0,0,0,0,0,0,0,0,0,0,0,0,0,0
0,0,0,0,0,0,0,0,0,0,0,0,0,0,0,0,0,0
0,0,0,0,0,0,0,0,0,0,0,0,0,0,0,0,0,0
0,0,7,13,13,13,14,13,7,7,13,14,13,13,13,7,0,0
0,0,13,0,0,0,0,0,13,13,0,0,0,0,0,13,0,0
0,0,14,0,0,0,0,0,13,13,0,0,0,0,0,14,0,0
0,0,13,0,0,0,0,0,13,13,0,0,0,0,0,13,0,0
0,0,7,13,13,13,13,13,7,7,13,13,13,13,13,7,0,0
0,0,7,13,13,13,13,13,7,7,17,13,13,13,13,7,0,0
0,0,13,0,0,0,0,0,13,13,0,0,0,0,0,13,0,0
0,0,14,0,0,0,0,0,13,13,0,0,0,0,0,14,0,0
0,0,13,0,0,0,0,0,13,13,0,0,0,0,0,13,0,0
0,0,7,13,13,13,14,13,7,7,13,14,13,13,13,7,0,0
0,0,0,0,0,0,0,0,0,0,0,0,0,0,0,0,0,0
0,0,0,0,0,0,0,0,0,0,0,0,0,0,0,0,0,0
0,0,0,0,0,0,0,0,0,0,0,0,0,0,0,0,0,0
0,0,0,0,0,0,0,0,0,0,0,0,0,0,0,0,0,0
0,0,0,0,0,0,0,0,0,0,0,0,0,0,0,0,0,0
endlayer

layer
0,0,0,0,0,0,0,0,0,0,0,0,0,0,0,0,0,0
0,0,0,0,0,0,0,0,0,0,0,0,0,0,0,0,0,0
0,0,0,0,0,0,0,0,0,0,0,0,0,0,0,0,0,0
0,0,0,0,0,0,0,0,0,0,0,0,0,0,0,0,0,0
0,0,0,0,0,0,0,0,0,0,0,0,0,0,0,0,0,0
0,0,7,13,13,13,14,13,7,7,13,14,13,13,13,7,0,0
0,0,13,0,0,0,0,0,13,13,0,0,0,0,0,13,0,0
0,0,14,0,0,0,0,0,13,13,0,0,0,0,0,14,0,0
0,0,13,0,0,0,0,0,13,13,0,0,0,0,0,13,0,0
0,0,7,13,13,13,13,13,7,7,13,13,13,13,13,7,0,0
0,0,7,13,13,13,13,13,7,7,17,13,13,13,13,7,0,0
0,0,13,0,0,0,0,0,13,13,0,0,0,0,0,13,0,0
0,0,14,0,0,0,0,0,13,13,0,0,0,0,0,14,0,0
0,0,13,0,0,0,0,0,13,13,0,0,0,0,0,13,0,0
0,0,7,13,13,13,14,13,7,7,13,14,13,13,13,7,0,0
0,0,0,0,0,0,0,0,0,0,0,0,0,0,0,0,0,0
0,0,0,0,0,0,0,0,0,0,0,0,0,0,0,0,0,0
0,0,0,0,0,0,0,0,0,0,0,0,0,0,0,0,0,0
0,0,0,0,0,0,0,0,0,0,0,0,0,0,0,0,0,0
0,0,0,0,0,0,0,0,0,0,0,0,0,0,0,0,0,0
endlayer

layer
0,0,0,0,0,0,0,0,0,0,0,0,0,0,0,0,0,0
0,0,0,0,0,0,0,0,0,0,0,0,0,0,0,0,0,0
0,0,0,0,0,0,0,0,0,0,0,0,0,0,0,0,0,0
0,0,0,0,0,0,0,0,0,0,0,0,0,0,0,0,0,0
0,0,0,0,0,0,0,0,0,0,0,0,0,0,0,0,0,0
0,0,7,7,7,7,7,7,7,7,7,7,7,7,7,7,0,0
0,0,7,18,18,18,18,18,18,18,18,18,18,18,18,7,0,0
0,0,7,18,18,18,18,18,18,18,18,18,18,18,18,7,0,0
0,0,7,18,18,18,18,18,18,18,18,18,18,18,18,7,0,0
0,0,7,7,7,7,7,7,7,7,7,7,7,7,7,7,0,0
0,0,7,7,7,7,7,7,7,7,7,7,7,7,7,7,0,0
0,0,7,18,18,18,18,18,18,18,18,18,18,18,18,7,0,0
0,0,7,18,18,18,18,18,18,18,18,18,18,18,18,7,0,0
0,0,7,18,18,18,18,18,18,18,18,18,18,18,18,7,0,0
0,0,7,7,7,7,7,7,7,7,7,7,7,7,7,7,0,0
0,0,0,0,0,0,0,0,0,0,0,0,0,0,0,0,0,0
0,0,0,0,0,0,0,0,0,0,0,0,0,0,0,0,0,0
0,0,0,0,0,0,0,0,0,0,0,0,0,0,0,0,0,0
0,0,0,0,0,0,0,0,0,0,0,0,0,0,0,0,0,0
0,0,0,0,0,0,0,0,0,0,0,0,0,0,0,0,0,0
endlayer

