# Converted from schematic
# THIS TEMPLATE USES DEFAULTS!  Please edit for corrections.
# If you need help, consult template_rules.txt

weight=12
embed_into_distance=11
acceptable_target_blocks=1,2,3,12,13
dimensions=11,16,25
allowable_overhang=0
max_cut_in=2
cut_in_buffer=1
max_leveling=2
leveling_buffer=1
preserve_water=0
preserve_lava=0
preserve_plants=0


rule1=0,100,3134-10
rule2=0,100,2843-4
rule3=0,100,300
rule4=0,100,2843-14,2843-14,2843-14,2843-14,2843
rule5=0,95,3541,3544,3544
rule6=0,100,2843-6
rule7=0,100,3537
rule8=0,100,3535
rule9=0,100,3536
rule10=0,100,311,311,3532
rule11=0,100,3531
rule12=0,100,3525
rule13=0,100,3526
rule14=0,100,3532
rule15=0,100,308,308,308,308,308,308,313,313,314,327
rule16=0,95,3539,3543,3543
rule17=0,100,3521
rule18=0,100,311,311,308,308,3531
rule19=0,95,3540,3542,3542
rule20=0,100,123
rule21=0,100,3134,3134,3134,3134-8,3134-2
rule22=0,65,2788-7
rule23=0,95,300
rule24=1,100,3538


layer
1,1,1,1,1,1,1,1,1,1,1,1,1,1,1,1,1,1,1,1,1,1,1,1,1
1,1,1,1,1,1,1,1,1,1,1,1,1,1,1,1,1,1,1,1,1,1,1,1,1
1,1,2,2,2,2,2,2,2,2,2,2,2,2,2,2,2,2,2,2,2,2,2,1,1
1,1,2,2,2,2,2,2,2,2,2,2,2,2,2,2,2,2,2,2,2,2,2,1,1
1,1,2,2,2,2,2,2,2,2,2,2,2,2,2,2,2,2,2,2,2,2,2,1,1
1,1,2,2,2,2,2,2,2,2,2,2,2,2,2,2,2,2,2,2,2,2,2,1,1
1,1,2,2,2,2,2,2,2,2,2,2,2,2,2,2,2,2,2,2,2,2,2,1,1
1,1,2,2,2,2,2,2,2,2,2,2,2,2,2,2,2,2,2,2,2,2,2,1,1
1,1,2,2,2,2,2,2,2,2,2,2,2,2,2,2,2,2,2,2,2,2,2,1,1
1,1,2,2,2,2,2,2,2,2,2,2,2,2,2,2,2,2,2,2,2,2,2,1,1
1,1,2,2,2,2,2,2,2,2,2,2,2,2,2,2,2,2,2,2,2,2,2,1,1
1,1,2,2,2,2,2,2,2,2,2,2,2,2,2,2,2,2,2,2,2,2,2,1,1
1,1,2,2,2,2,2,2,2,2,2,2,2,2,2,2,2,2,2,2,2,2,2,1,1
1,1,2,2,2,2,2,2,2,2,2,2,2,2,2,2,2,2,2,2,2,2,2,1,1
1,1,1,1,1,1,1,1,1,1,1,1,1,1,1,1,1,1,1,1,1,1,1,1,1
1,1,1,1,1,1,1,1,1,1,1,1,1,1,1,1,1,1,1,1,1,1,1,1,1
endlayer

layer
3,3,3,3,3,3,3,3,3,3,3,3,3,3,3,3,3,3,3,3,3,3,3,3,3
3,3,3,3,3,3,3,3,3,3,3,3,3,3,3,3,3,3,3,3,3,3,3,3,3
3,3,4,5,5,5,5,4,6,3,3,6,4,5,5,5,5,4,5,5,5,5,4,3,3
3,3,5,14,14,12,12,12,3,3,3,3,0,14,14,12,12,13,13,13,13,10,5,3,3
3,3,5,0,0,12,12,0,3,3,3,3,0,0,0,0,0,0,0,0,11,11,5,3,3
3,3,6,0,0,0,0,0,0,3,3,0,0,0,0,0,0,0,0,11,0,11,6,3,3
3,3,9,0,0,0,0,0,0,13,13,13,0,0,0,0,0,0,0,0,0,0,7,3,3
3,3,8,0,0,0,0,0,0,13,13,13,0,0,0,0,0,0,0,0,0,0,8,3,3
3,3,8,0,0,0,0,0,0,13,13,13,0,0,14,14,14,0,0,0,0,0,8,3,3
3,3,7,0,0,0,0,0,0,0,0,0,0,0,14,15,14,0,0,0,0,0,9,3,3
3,3,6,0,0,0,0,0,0,0,0,0,0,0,14,14,14,0,0,0,0,0,6,3,3
3,3,5,13,13,13,13,13,13,11,0,0,0,11,0,0,0,11,11,11,11,11,5,3,3
3,3,5,15,13,13,13,13,13,11,11,14,11,10,11,0,12,12,12,12,12,12,5,3,3
3,3,4,5,5,5,5,4,5,5,5,5,4,5,5,5,5,4,5,5,5,5,4,3,3
3,3,3,3,3,3,3,3,3,3,3,3,3,3,3,3,3,3,3,3,3,3,3,3,3
3,3,3,3,3,3,3,3,3,3,3,3,3,3,3,3,3,3,3,3,3,3,3,3,3
endlayer

layer
3,3,3,3,3,3,3,3,3,3,3,3,3,3,3,3,3,3,3,3,3,3,3,3,3
3,3,3,3,3,3,3,3,3,3,3,3,3,3,3,3,3,3,3,3,3,3,3,3,3
3,3,4,16,16,16,16,4,6,3,3,6,4,16,16,16,16,4,16,16,16,16,4,3,3
3,3,16,11,12,12,12,0,0,3,3,0,0,14,14,17,17,17,0,13,13,13,16,3,3
3,3,16,0,0,0,0,0,0,0,3,0,0,0,0,0,0,0,0,0,0,11,16,3,3
3,3,6,0,0,0,0,0,0,0,0,0,0,0,0,0,0,0,0,0,0,0,6,3,3
3,3,9,0,0,0,0,0,0,0,13,0,0,0,0,0,0,0,0,0,0,0,7,3,3
3,3,8,0,0,0,0,0,0,13,18,13,0,0,0,0,0,0,0,0,0,0,8,3,3
3,3,8,0,0,0,0,0,0,0,13,0,0,0,0,0,0,0,0,0,0,0,8,3,3
3,3,7,0,0,0,0,0,0,0,0,0,0,0,0,14,0,0,0,0,0,0,9,3,3
3,3,6,0,0,0,0,0,0,0,0,0,0,0,0,0,0,0,0,0,0,0,6,3,3
3,3,16,0,0,0,0,0,0,0,0,0,0,0,0,0,0,11,11,11,11,11,16,3,3
3,3,16,13,13,13,13,13,13,0,0,0,14,14,0,0,12,12,12,12,12,12,16,3,3
3,3,4,16,16,16,16,4,16,16,16,16,4,16,16,16,16,4,16,16,16,16,4,3,3
3,3,3,3,3,3,3,3,3,3,3,3,3,3,3,3,3,3,3,3,3,3,3,3,3
3,3,3,3,3,3,3,3,3,3,3,3,3,3,3,3,3,3,3,3,3,3,3,3,3
endlayer

layer
3,3,3,3,3,3,3,3,3,3,3,3,3,3,3,3,3,3,3,3,3,3,3,3,3
3,3,3,3,3,3,3,3,3,3,3,3,3,3,3,3,3,3,3,3,3,3,3,3,3
3,3,4,16,16,16,16,4,6,6,6,6,4,16,16,16,16,4,16,16,16,16,4,3,3
3,3,16,0,0,0,0,0,0,0,0,0,0,14,14,17,0,0,0,0,13,13,16,3,3
3,3,16,0,0,0,0,0,0,0,0,0,0,0,0,0,0,0,0,0,0,0,16,3,3
3,3,6,0,0,0,0,0,0,0,0,0,0,0,0,0,0,0,0,0,0,0,6,3,3
3,3,9,0,0,0,0,0,0,0,0,0,0,0,0,0,0,0,0,0,0,0,7,3,3
3,3,8,0,0,0,0,0,0,0,13,0,0,0,0,0,0,0,0,0,0,0,8,3,3
3,3,8,0,0,0,0,0,0,0,0,0,0,0,0,0,0,0,0,0,0,0,8,3,3
3,3,7,0,0,0,0,0,0,0,0,0,0,0,0,0,0,0,0,0,0,0,9,3,3
3,3,6,0,0,0,0,0,0,0,0,0,0,0,0,0,0,0,0,0,0,0,6,3,3
3,3,16,0,0,0,0,0,0,0,0,0,0,0,0,0,0,11,11,11,11,11,16,3,3
3,3,16,14,14,14,0,0,0,0,0,0,0,0,0,0,12,12,12,12,12,12,16,3,3
3,3,4,16,16,16,16,4,16,16,16,16,4,16,16,16,16,4,16,16,16,16,4,3,3
3,3,3,3,3,3,3,3,3,3,3,3,3,3,3,3,3,3,3,3,3,3,3,3,3
3,3,3,3,3,3,3,3,3,3,3,3,3,3,3,3,3,3,3,3,3,3,3,3,3
endlayer

layer
3,3,3,3,3,3,3,3,3,3,3,3,3,3,3,3,3,3,3,3,3,3,3,3,3
3,3,3,3,3,3,3,3,3,3,3,3,3,3,3,3,3,3,3,3,3,3,3,3,3
3,3,4,16,16,16,16,4,5,5,5,5,4,16,16,16,16,4,16,16,16,16,4,3,3
3,3,16,0,0,0,0,0,0,0,0,0,0,0,14,17,0,0,0,0,0,0,16,3,3
3,3,16,0,0,0,0,0,0,0,0,0,0,0,0,0,0,0,0,0,0,0,16,3,3
3,3,6,0,0,0,0,0,0,0,0,0,0,0,0,0,0,0,0,0,0,0,6,3,3
3,3,9,0,0,0,0,0,0,0,0,0,0,0,0,0,0,0,0,0,0,0,7,3,3
3,3,8,0,0,0,0,0,0,0,0,0,0,0,0,0,0,0,0,0,0,0,8,3,3
3,3,8,0,0,0,0,0,0,0,0,0,0,0,0,0,0,0,0,0,0,0,8,3,3
3,3,7,0,0,0,0,0,0,0,0,0,0,0,0,0,0,0,0,0,0,0,9,3,3
3,3,6,0,0,0,0,0,0,0,0,0,0,0,0,0,0,0,0,0,0,0,6,3,3
3,3,16,0,0,0,0,0,0,0,0,0,0,0,0,0,0,0,0,0,0,0,16,3,3
3,3,16,0,0,0,0,0,0,0,0,0,0,0,0,0,12,12,12,12,12,12,16,3,3
3,3,4,16,16,16,16,4,16,16,16,16,4,16,16,16,16,4,16,16,16,16,4,3,3
3,3,3,3,3,3,3,3,3,3,3,3,3,3,3,3,3,3,3,3,3,3,3,3,3
3,3,3,3,3,3,3,3,3,3,3,3,3,3,3,3,3,3,3,3,3,3,3,3,3
endlayer

layer
3,3,3,3,3,3,3,3,3,3,3,3,3,3,3,3,3,3,3,3,3,3,3,3,3
3,3,3,3,3,3,3,3,3,3,3,3,3,3,3,3,3,3,3,3,3,3,3,3,3
3,3,4,16,16,16,16,4,16,16,16,16,4,16,16,16,16,4,16,16,16,16,4,3,3
3,3,16,0,0,0,0,0,0,0,0,0,0,0,0,0,0,0,0,0,0,0,16,3,3
3,3,16,0,0,0,0,0,0,0,0,0,0,0,0,0,0,0,0,0,0,0,16,3,3
3,3,6,0,0,0,0,0,0,0,0,0,0,0,0,0,0,0,0,0,0,0,6,3,3
3,3,6,0,0,0,0,0,0,0,0,0,0,0,0,0,0,0,0,0,0,0,6,3,3
3,3,6,0,0,0,0,0,0,0,0,0,0,0,0,0,0,0,0,0,0,0,6,3,3
3,3,6,0,0,0,0,0,0,0,0,0,0,0,0,0,0,0,0,0,0,0,6,3,3
3,3,6,0,0,0,0,0,0,0,0,0,0,0,0,0,0,0,0,0,0,0,6,3,3
3,3,6,0,0,0,0,0,0,0,0,0,0,0,0,0,0,0,0,0,0,0,6,3,3
3,3,16,0,0,0,0,0,0,0,0,0,0,0,0,0,0,0,0,0,0,0,16,3,3
3,3,16,0,0,0,0,0,0,0,0,0,0,0,0,0,12,12,12,12,12,12,16,3,3
3,3,4,16,16,16,16,4,16,16,16,16,4,16,16,16,16,4,16,16,16,16,4,3,3
3,3,3,3,3,3,3,3,3,3,3,3,3,3,3,3,3,3,3,3,3,3,3,3,3
3,3,3,3,3,3,3,3,3,3,3,3,3,3,3,3,3,3,3,3,3,3,3,3,3
endlayer

layer
3,3,3,3,3,3,3,3,3,3,3,3,3,3,3,3,3,3,3,3,3,3,3,3,3
3,3,3,3,3,3,3,3,3,3,3,3,3,3,3,3,3,3,3,3,3,3,3,3,3
3,3,4,16,16,16,16,4,16,16,16,16,4,16,16,16,16,4,16,16,16,16,4,3,3
3,3,16,0,0,0,0,0,0,0,0,0,0,0,0,0,0,0,0,0,0,0,16,3,3
3,3,16,0,0,0,0,0,0,0,0,0,0,0,0,0,0,0,0,0,0,0,16,3,3
3,3,5,0,0,0,0,0,0,0,0,0,0,0,0,0,0,0,0,0,0,0,5,3,3
3,3,5,0,0,0,0,0,0,0,0,0,0,0,0,0,0,0,0,0,0,0,5,3,3
3,3,5,0,0,0,0,0,0,0,0,0,0,0,0,0,0,0,0,0,0,0,5,3,3
3,3,5,0,0,0,0,0,0,0,0,0,0,0,0,0,0,0,0,0,0,0,5,3,3
3,3,5,0,0,0,0,0,0,0,0,0,0,0,0,0,0,0,0,0,0,0,5,3,3
3,3,5,0,0,0,0,0,0,0,0,0,0,0,0,0,0,0,0,0,0,0,5,3,3
3,3,16,0,0,0,0,0,0,0,0,0,0,0,0,0,0,0,0,0,0,0,16,3,3
3,3,16,0,0,0,0,0,0,0,0,0,0,0,0,0,12,12,12,12,12,12,16,3,3
3,3,4,16,16,16,16,4,16,16,16,16,4,16,16,16,16,4,16,16,16,16,4,3,3
3,3,3,3,3,3,3,3,3,3,3,3,3,3,3,3,3,3,3,3,3,3,3,3,3
3,3,3,3,3,3,3,3,3,3,3,3,3,3,3,3,3,3,3,3,3,3,3,3,3
endlayer

layer
3,3,3,3,3,3,3,3,3,3,3,3,3,3,3,3,3,3,3,3,3,3,3,3,3
3,3,3,3,3,3,3,3,3,3,3,3,3,3,3,3,3,3,3,3,3,3,3,3,3
3,3,4,16,16,16,16,4,16,16,16,16,4,16,16,16,16,4,16,16,16,16,4,3,3
3,3,16,0,0,0,0,4,0,0,0,0,4,0,0,0,0,4,0,0,0,0,16,3,3
3,3,16,0,0,0,0,0,0,0,0,0,0,0,0,0,0,0,0,0,0,0,16,3,3
3,3,16,0,0,0,0,0,0,0,0,0,0,0,0,0,0,0,0,0,0,0,16,3,3
3,3,16,0,0,0,0,0,0,0,0,0,0,0,0,0,0,0,0,0,0,0,16,3,3
3,3,16,0,0,0,0,0,0,0,0,0,0,0,0,0,0,0,0,0,0,0,16,3,3
3,3,16,0,0,0,0,0,0,0,0,0,0,0,0,0,0,0,0,0,0,0,16,3,3
3,3,16,0,0,0,0,0,0,0,0,0,0,0,0,0,0,0,0,0,0,0,16,3,3
3,3,16,0,0,0,0,0,0,0,0,0,0,0,0,0,0,0,0,0,0,0,16,3,3
3,3,16,0,0,0,0,0,0,0,0,0,0,0,0,0,0,0,0,0,0,0,16,3,3
3,3,16,0,0,0,0,4,0,0,0,0,4,0,0,0,0,4,0,0,0,0,16,3,3
3,3,4,16,16,16,16,4,16,16,16,16,4,16,16,16,16,4,16,16,16,16,4,3,3
3,3,3,3,3,3,3,3,3,3,3,3,3,3,3,3,3,3,3,3,3,3,3,3,3
3,3,3,3,3,3,3,3,3,3,3,3,3,3,3,3,3,3,3,3,3,3,3,3,3
endlayer

layer
3,3,3,3,3,3,3,3,3,3,3,3,3,3,3,3,3,3,3,3,3,3,3,3,3
3,3,3,3,3,3,3,3,3,3,3,3,3,3,3,3,3,3,3,3,3,3,3,3,3
3,3,4,19,19,19,19,4,19,19,19,19,4,19,19,19,19,4,19,19,19,19,4,3,3
3,3,19,0,0,0,0,20,0,0,0,0,20,0,0,0,0,20,0,0,0,0,19,3,3
3,3,19,0,0,0,0,4,0,0,0,0,4,0,0,0,0,4,0,0,0,0,19,3,3
3,3,19,0,0,0,0,0,0,0,0,0,0,0,0,0,0,0,0,0,0,0,19,3,3
3,3,19,0,0,0,0,0,0,0,0,0,0,0,0,0,0,0,0,0,0,0,19,3,3
3,3,19,0,0,0,0,0,0,0,0,0,0,0,0,0,0,0,0,0,0,0,19,3,3
3,3,19,0,0,0,0,0,0,0,0,0,0,0,0,0,0,0,0,0,0,0,19,3,3
3,3,19,0,0,0,0,0,0,0,0,0,0,0,0,0,0,0,0,0,0,0,19,3,3
3,3,19,0,0,0,0,0,0,0,0,0,0,0,0,0,0,0,0,0,0,0,19,3,3
3,3,19,0,0,0,0,4,0,0,0,0,4,0,0,0,0,4,0,0,0,0,19,3,3
3,3,19,0,0,0,0,20,0,0,0,0,20,0,0,0,0,20,0,0,0,0,19,3,3
3,3,4,19,19,19,19,4,19,19,19,19,4,19,19,19,19,4,19,19,19,19,4,3,3
3,3,3,3,3,3,3,3,3,3,3,3,3,3,3,3,3,3,3,3,3,3,3,3,3
3,3,3,3,3,3,3,3,3,3,3,3,3,3,3,3,3,3,3,3,3,3,3,3,3
endlayer

layer
3,3,3,3,3,3,3,3,3,3,3,3,3,3,3,3,3,3,3,3,3,3,3,3,3
3,3,3,3,3,3,3,3,3,3,3,3,3,3,3,3,3,3,3,3,3,3,3,3,3
3,3,4,4,4,4,4,4,4,4,4,4,4,4,4,4,4,4,4,4,4,4,4,3,3
3,3,4,21,21,21,21,4,21,21,21,21,4,21,21,21,21,4,21,21,21,21,4,3,3
3,3,4,21,22,22,21,4,21,22,22,21,4,21,22,22,21,4,21,22,22,21,4,3,3
3,3,4,21,22,22,21,4,21,22,22,21,4,21,22,22,21,4,21,22,22,21,4,3,3
3,3,4,21,21,21,21,4,21,21,21,21,4,21,21,21,21,4,21,21,21,21,4,3,3
3,3,4,21,21,21,21,4,21,21,21,21,4,21,21,21,21,4,21,21,21,21,4,3,3
3,3,4,21,21,21,21,4,21,21,21,21,4,21,21,21,21,4,21,21,21,21,4,3,3
3,3,4,21,21,21,21,4,21,21,21,21,4,21,21,21,21,4,21,21,21,21,4,3,3
3,3,4,21,22,22,21,4,21,22,22,21,4,21,22,22,21,4,21,22,22,21,4,3,3
3,3,4,21,22,22,21,4,21,22,22,21,4,21,22,22,21,4,21,22,22,21,4,3,3
3,3,4,21,21,21,21,4,21,21,21,21,4,21,21,21,21,4,21,21,21,21,4,3,3
3,3,4,4,4,4,4,4,4,4,4,4,4,4,4,4,4,4,4,4,4,4,4,3,3
3,3,3,3,3,3,3,3,3,3,3,3,3,3,3,3,3,3,3,3,3,3,3,3,3
3,3,3,3,3,3,3,3,3,3,3,3,3,3,3,3,3,3,3,3,3,3,3,3,3
endlayer

layer
23,23,23,23,23,23,23,23,23,23,23,23,23,23,23,23,23,23,23,23,23,23,23,23,23
23,23,23,23,23,23,23,23,23,23,23,23,23,23,23,23,23,23,23,23,23,23,23,23,23
23,23,23,23,23,23,23,23,23,23,23,23,23,23,23,23,23,23,23,23,23,23,23,23,23
23,23,23,23,23,23,23,23,23,23,23,23,23,23,23,23,23,23,23,23,23,23,23,23,23
23,23,23,23,23,23,23,23,23,23,23,23,23,23,23,23,23,23,23,23,23,23,23,23,23
23,23,23,23,23,23,23,23,23,23,23,23,23,23,23,23,23,23,23,23,23,23,23,23,23
23,23,23,23,23,23,23,23,23,23,23,23,23,23,23,23,23,23,23,23,23,23,23,23,23
23,23,23,23,23,23,23,23,23,23,23,24,24,24,23,23,23,23,23,23,23,23,23,23,23
23,23,23,23,23,23,23,23,23,23,23,24,24,24,23,23,23,23,23,23,23,23,23,23,23
23,23,23,23,23,23,23,23,23,23,23,23,23,23,23,23,23,23,23,23,23,23,23,23,23
23,23,23,23,23,23,23,23,23,23,23,23,23,23,23,23,23,23,23,23,23,23,23,23,23
23,23,23,23,23,23,23,23,23,23,23,23,23,23,23,23,23,23,23,23,23,23,23,23,23
23,23,23,23,23,23,23,23,23,23,23,23,23,23,23,23,23,23,23,23,23,23,23,23,23
23,23,23,23,23,23,23,23,23,23,23,23,23,23,23,23,23,23,23,23,23,23,23,23,23
23,23,23,23,23,23,23,23,23,23,23,23,23,23,23,23,23,23,23,23,23,23,23,23,23
23,23,23,23,23,23,23,23,23,23,23,23,23,23,23,23,23,23,23,23,23,23,23,23,23
endlayer

