biomesToSpawnIn=kelp forest,ocean,ocean oil field,oceanic abyss,coral reef,desert
weight=1
embed_into_distance=49
acceptable_target_blocks=1,2,3,12,13,250
dimensions=51,10,42
allowable_overhang=0
max_cut_in=0
cut_in_buffer=0
max_leveling=0
leveling_buffer=0
preserve_water=0
preserve_lava=0
preserve_plants=0


rule1=0,100,250
rule2=0,100,2818-10,2818-10,2818-10,2819-2,2819-2,2816-2,0
rule3=0,100,2762-5,2762-5,2762-5,2762-5,2762-6,2762-6,2762-7,2762,0,0
rule4=0,100,2818-11,2818-11,2818-11,2819-3,2819-32816-3,0
rule5=0,100,2818-8,2818-8,2818-8,2819-8,2819-8,2816-1,0
rule6=0,100,159-15
rule7=0,100,65-2
rule8=0,100,159-14


layer
1,1,1,1,1,1,1,3,0,3,0,0,0,0,3,0,1,1,1,1,1,1,1,1,1,0,3,0,0,0,0,3,0,3,1,1,1,1,1,1,1,1
1,4,3,1,3,0,3,0,3,0,3,0,3,3,3,0,0,1,1,1,1,1,1,1,0,0,0,3,3,0,3,0,3,0,3,0,3,1,3,2,1,1
1,3,3,3,0,3,0,0,3,0,3,3,3,3,3,0,0,0,0,0,1,0,0,0,0,0,0,3,3,3,3,0,3,0,0,3,0,3,3,3,1,1
4,3,0,3,0,0,0,0,0,3,3,3,3,3,3,0,0,0,0,0,1,0,0,0,0,0,0,3,3,3,3,3,0,0,0,0,0,3,0,3,2,1
3,0,0,3,0,3,0,3,0,3,0,0,3,3,3,0,3,0,0,0,1,0,0,0,3,0,3,3,3,0,3,3,0,3,0,3,0,3,0,0,3,1
3,0,0,3,0,3,0,3,0,3,0,0,3,3,3,0,3,0,0,0,1,0,0,0,3,0,3,3,3,0,3,3,0,3,0,3,0,3,0,0,3,1
4,3,0,3,0,0,0,0,0,3,3,3,3,3,3,0,0,0,0,0,1,0,0,0,0,0,0,3,3,3,3,3,0,0,0,0,0,3,0,3,2,1
1,3,3,3,0,3,0,0,3,0,3,3,3,3,3,0,0,0,0,1,1,0,0,0,0,0,0,3,3,3,3,0,3,0,0,3,0,3,3,3,1,1
1,4,3,1,3,0,3,0,3,0,3,3,3,3,3,0,0,1,0,1,1,0,0,1,0,0,0,3,3,0,3,0,3,0,3,0,3,1,3,2,1,1
1,1,1,1,1,1,1,3,0,3,0,3,3,3,3,1,1,1,1,1,1,1,1,1,1,0,3,0,0,0,0,3,0,3,1,1,1,1,1,1,1,1
endlayer

layer
1,1,1,1,1,1,1,3,3,0,0,3,3,3,3,0,1,1,1,1,1,1,1,1,1,0,3,3,3,3,0,0,3,3,1,1,1,1,1,1,1,1
1,1,5,1,0,3,3,3,3,0,3,0,3,0,0,0,3,1,1,1,1,1,1,1,3,0,0,0,3,0,3,0,3,3,3,3,0,1,5,1,1,1
1,3,3,3,0,3,3,0,3,0,0,3,0,0,0,0,0,0,0,0,1,0,0,0,0,0,0,0,0,3,0,0,3,0,3,3,0,3,3,3,1,1
1,3,0,3,0,3,0,3,0,3,0,0,0,0,0,0,0,0,0,0,1,0,0,0,0,0,0,3,2,0,0,3,0,3,0,3,0,3,0,3,1,1
3,3,3,3,0,3,0,3,0,3,0,3,0,0,3,0,3,0,0,0,1,0,0,0,3,0,3,3,0,3,0,3,0,3,0,3,0,3,3,3,3,1
3,3,3,3,0,3,0,3,0,3,0,3,0,0,3,0,3,0,0,0,1,0,0,0,3,0,3,0,0,3,0,3,0,3,0,3,0,3,3,3,3,1
1,3,0,3,0,3,0,3,0,3,0,0,0,0,0,0,0,0,0,0,1,0,0,0,0,0,0,0,0,0,0,3,0,3,0,3,0,3,0,3,1,1
1,3,3,3,0,3,3,0,3,0,0,3,0,0,0,0,0,0,0,0,1,0,0,0,0,0,0,0,0,3,0,0,3,0,3,3,0,3,3,3,1,1
1,1,5,1,0,3,3,3,3,0,3,3,3,3,0,0,3,1,0,1,1,0,0,1,3,0,0,0,3,0,3,0,3,3,3,3,0,1,5,1,1,1
1,1,1,1,1,1,1,3,3,0,0,3,0,3,3,1,1,1,1,1,1,1,1,1,1,0,3,3,3,3,0,0,3,3,1,1,1,1,1,1,1,1
endlayer

layer
1,1,1,1,1,1,1,5,4,3,0,3,3,3,3,3,1,1,1,1,1,1,1,1,1,3,3,3,3,3,0,3,2,5,1,1,1,1,1,1,1,1
1,1,1,1,0,4,3,3,3,0,3,0,3,0,0,0,3,1,1,1,1,1,1,1,3,0,3,0,3,0,3,0,3,3,3,2,0,1,1,1,1,1
1,3,0,3,0,3,3,3,3,0,0,3,0,0,0,3,0,0,0,0,1,0,0,0,0,3,3,0,0,3,0,0,3,3,3,3,0,3,0,3,1,1
1,0,3,2,0,0,0,3,0,0,0,0,0,0,0,0,0,0,0,0,1,0,0,0,0,0,3,2,0,0,0,0,0,3,0,0,0,4,3,0,1,1
3,0,4,3,0,3,0,3,0,3,0,3,3,0,3,0,3,0,0,0,1,0,0,0,3,0,3,3,0,3,0,3,0,3,0,3,0,3,2,0,3,1
3,0,4,3,0,3,0,3,0,3,0,3,0,0,3,0,3,0,0,0,1,0,0,0,3,0,3,0,0,3,0,3,0,3,0,3,0,3,2,0,3,1
1,0,3,2,0,0,0,3,0,0,0,0,0,0,0,0,0,0,0,0,1,0,0,0,0,0,0,0,0,0,0,0,0,3,0,0,0,4,3,0,1,1
1,3,0,3,0,3,3,3,3,0,0,3,0,0,0,3,0,0,0,0,1,0,0,0,0,3,3,0,0,3,0,0,3,3,3,3,0,3,0,3,1,1
1,1,1,1,0,4,3,3,3,0,3,3,0,3,0,0,3,1,0,0,1,0,0,1,3,0,3,0,3,0,3,0,3,3,3,2,0,1,1,1,1,1
1,1,1,1,1,1,1,5,4,3,0,3,3,3,3,3,1,1,1,1,1,1,1,1,1,3,3,3,3,3,0,3,2,5,1,1,1,1,1,1,1,1
endlayer

layer
1,1,1,1,1,1,1,1,1,3,0,3,3,3,3,1,1,1,1,1,1,1,1,1,1,1,3,3,3,3,0,3,1,1,1,1,1,1,1,1,1,1
1,1,1,1,0,0,3,2,1,0,3,0,3,0,3,0,3,1,1,1,1,1,1,1,3,0,3,0,3,0,3,0,1,4,3,0,0,1,1,1,1,1
1,4,3,3,0,3,0,3,3,0,3,3,0,3,3,3,0,0,0,0,1,0,0,0,0,3,3,3,0,3,3,0,3,3,0,3,0,3,3,2,1,1
1,3,3,0,0,0,0,0,0,3,0,3,0,3,3,0,0,0,0,0,1,0,0,0,0,0,0,0,0,0,0,3,0,0,0,0,0,0,3,3,1,1
4,3,0,3,0,3,0,3,0,3,0,3,0,3,3,0,3,0,0,0,1,0,0,0,3,0,5,3,3,3,0,3,0,3,0,3,0,3,0,3,2,1
4,3,0,3,0,3,0,3,0,3,0,3,0,3,3,0,3,0,0,0,1,0,0,0,3,0,3,3,3,3,0,3,0,3,0,3,0,3,0,3,2,1
1,3,3,0,0,0,0,0,0,3,0,3,0,3,3,0,0,0,0,0,1,0,0,0,0,0,3,3,0,3,0,3,0,0,0,0,0,0,3,3,1,1
1,4,3,3,0,3,0,3,3,0,3,3,0,3,3,3,0,0,0,0,1,0,0,0,0,3,3,3,0,3,3,0,3,3,0,3,0,3,3,2,1,1
1,1,1,1,0,0,3,2,1,0,3,3,3,3,3,0,3,1,0,0,1,0,0,1,3,0,3,0,3,0,3,0,1,4,3,0,0,1,1,1,1,1
1,1,1,1,1,1,1,1,1,3,0,3,3,3,3,1,1,1,1,1,1,1,1,1,1,1,3,3,3,3,0,3,1,1,1,1,1,1,1,1,1,1
endlayer

layer
1,1,1,1,1,1,1,1,1,4,3,3,3,0,3,1,1,1,1,1,1,1,1,1,1,1,3,0,3,3,3,2,1,1,1,1,1,1,1,1,1,1
1,1,1,1,0,0,5,1,1,3,3,0,3,0,0,3,2,1,1,1,1,1,1,1,4,3,0,0,3,0,3,3,1,1,5,0,0,1,1,1,1,1
1,1,3,3,0,3,3,3,0,0,3,3,3,3,3,3,3,3,0,0,1,0,0,0,3,3,3,3,3,3,3,0,0,3,3,3,0,3,3,1,1,1
1,4,3,0,0,0,3,0,0,3,0,3,3,3,3,3,3,3,0,0,1,0,0,0,3,3,0,0,0,3,0,3,0,0,3,0,0,0,3,2,1,1
1,3,0,3,0,3,3,3,0,3,0,3,3,3,3,3,3,3,0,0,1,0,0,0,3,3,0,3,3,3,3,3,0,3,3,3,0,3,0,3,1,1
1,3,0,3,0,3,3,3,0,3,0,3,3,3,3,3,3,3,0,0,1,0,0,0,3,3,5,3,3,3,3,3,0,3,3,3,0,3,0,3,1,1
1,4,3,0,0,0,3,0,0,3,0,3,3,3,3,3,3,3,0,0,1,0,0,0,3,3,3,3,3,3,0,3,0,0,3,0,0,0,3,2,1,1
1,1,3,3,0,3,3,3,0,0,3,3,3,3,3,3,3,3,0,0,1,0,0,0,3,3,3,3,3,3,3,0,0,3,3,3,0,3,3,1,1,1
1,1,1,1,0,0,5,1,1,3,3,3,3,3,0,3,2,1,0,0,1,0,0,1,4,3,0,0,3,0,3,3,1,1,5,0,0,1,1,1,1,1
1,1,1,1,1,1,1,1,1,4,3,3,3,3,3,1,1,1,1,1,1,1,1,1,1,1,3,0,3,3,3,2,1,1,1,1,1,1,1,1,1,1
endlayer

layer
1,1,1,1,1,1,1,1,1,1,3,3,2,0,3,1,1,1,1,1,1,1,1,1,1,1,3,0,4,3,3,1,1,1,1,1,1,1,1,1,1,1
1,1,1,1,3,0,1,1,1,0,0,0,3,3,3,2,0,1,1,1,1,1,1,1,0,4,3,3,3,0,0,0,1,1,1,0,3,1,1,1,1,1
1,1,3,3,3,3,3,1,3,0,3,0,0,0,0,3,0,0,0,0,1,0,0,0,0,3,0,0,0,0,3,0,3,1,3,3,3,3,3,1,1,1
1,1,3,0,0,0,3,0,0,0,0,3,0,0,0,0,0,0,0,0,1,0,0,0,0,0,0,0,0,3,0,0,0,0,3,0,0,0,3,1,1,1
1,3,3,3,0,3,3,2,0,3,0,0,0,0,0,0,0,0,0,0,1,0,0,0,0,0,0,6,0,0,0,3,0,4,3,3,0,3,3,3,1,1
1,3,3,3,0,3,3,2,0,3,0,0,0,0,0,0,0,0,0,0,1,0,0,0,0,0,0,0,0,0,0,3,0,4,3,3,0,3,3,3,1,1
1,1,3,0,0,0,3,0,0,0,0,3,0,0,0,0,0,0,0,0,1,0,0,0,3,7,0,0,0,3,0,0,0,0,3,0,0,0,3,1,1,1
1,1,3,3,3,3,3,1,3,0,3,0,0,0,0,3,0,0,0,0,1,0,0,0,0,3,0,0,0,0,3,0,3,1,3,3,3,3,3,1,1,1
1,1,1,1,3,0,1,1,1,0,0,3,3,3,3,2,0,1,0,0,1,0,0,1,0,4,3,3,3,0,0,0,1,1,1,0,3,1,1,1,1,1
1,1,1,1,1,1,1,1,1,1,3,3,0,3,3,1,1,1,1,1,1,1,1,1,1,1,3,0,4,3,3,1,1,1,1,1,1,1,1,1,1,1
endlayer

layer
1,1,1,1,1,1,1,1,1,1,3,0,0,3,2,1,1,1,1,1,1,1,1,1,1,1,4,3,0,0,3,1,1,1,1,1,1,1,1,1,1,1
1,1,1,1,3,3,1,1,1,3,0,3,3,3,3,0,0,1,1,1,1,1,1,1,0,0,3,3,3,3,0,3,1,1,1,3,3,1,1,1,1,1
1,1,3,3,3,3,0,1,3,0,3,0,0,0,0,3,0,0,0,0,1,0,0,0,0,3,0,0,0,0,3,0,3,1,0,3,3,3,3,1,1,1
1,1,3,0,0,0,3,0,0,3,0,3,0,0,0,0,0,0,0,0,1,0,0,0,0,0,0,0,0,3,0,3,0,0,3,0,0,0,3,1,1,1
1,3,3,0,0,3,2,0,0,4,3,0,0,0,0,0,0,0,0,0,1,0,0,0,0,0,0,0,0,0,0,2,0,0,4,3,0,0,3,3,1,1
1,3,3,0,0,3,2,0,0,4,3,0,0,0,0,0,0,0,0,0,1,0,0,0,0,0,0,0,0,0,0,2,0,0,4,3,0,0,3,3,1,1
1,1,3,0,0,0,3,0,0,3,0,3,0,0,0,0,0,0,0,0,1,0,0,0,3,7,0,0,0,3,0,3,0,0,3,0,0,0,3,1,1,1
1,1,3,3,3,3,0,1,3,0,3,0,0,0,0,3,0,0,0,0,1,0,0,0,0,3,0,0,0,0,3,0,3,1,0,3,3,3,3,1,1,1
1,1,1,1,3,3,1,1,1,3,0,3,0,3,3,0,0,1,0,0,1,0,0,1,0,0,3,3,3,3,0,3,1,1,1,3,3,1,1,1,1,1
1,1,1,1,1,1,1,1,1,1,3,3,3,3,2,1,1,1,1,1,1,1,1,1,1,1,4,3,0,0,3,1,1,1,1,1,1,1,1,1,1,1
endlayer

layer
1,1,1,1,1,1,1,1,1,1,4,3,0,3,1,1,1,1,1,1,1,1,1,1,1,1,1,3,0,3,2,1,1,1,1,1,1,1,1,1,1,1
1,1,1,1,5,5,1,1,1,1,3,3,3,3,0,0,0,1,1,1,1,1,1,1,0,0,0,3,3,3,3,1,1,1,1,5,5,1,1,1,1,1
1,1,4,3,3,3,3,1,3,0,3,0,0,0,0,3,0,0,0,0,1,0,0,0,0,3,0,0,0,0,3,0,3,1,3,3,3,3,2,1,1,1
1,1,3,3,3,3,3,0,3,3,3,3,0,3,0,3,0,0,0,0,1,0,0,0,0,3,0,3,0,3,3,3,3,0,3,3,3,3,3,1,1,1
1,4,3,3,0,3,0,0,3,0,5,0,0,0,0,3,3,0,0,0,1,0,0,0,3,3,0,0,0,0,5,0,3,0,0,3,0,3,3,2,1,1
1,4,3,3,0,3,0,0,3,0,5,0,0,0,0,3,3,0,0,0,1,0,0,0,3,3,0,0,0,0,5,0,3,0,0,3,0,3,3,2,1,1
1,1,3,3,3,3,3,0,3,3,3,3,0,3,0,3,0,0,0,0,1,0,0,0,3,7,0,3,0,3,3,3,3,0,3,3,3,3,3,1,1,1
1,1,4,3,3,3,3,1,3,0,3,0,0,0,0,3,0,0,0,0,1,0,0,0,0,3,0,0,0,0,3,0,3,1,3,3,3,3,2,1,1,1
1,1,1,1,5,5,1,1,1,1,3,3,3,3,0,0,0,1,0,0,1,0,0,1,0,0,0,3,3,3,3,1,1,1,1,5,5,1,1,1,1,1
1,1,1,1,1,1,1,1,1,1,4,3,3,3,1,1,1,1,1,1,1,1,1,1,1,1,1,3,0,3,2,1,1,1,1,1,1,1,1,1,1,1
endlayer

layer
1,1,1,1,1,1,1,1,1,1,1,4,3,2,1,1,1,1,1,1,1,1,1,1,1,1,1,4,3,2,1,1,1,1,1,1,1,1,1,1,1,1
1,1,1,1,1,1,1,1,1,1,4,3,3,3,0,0,0,1,1,1,1,1,1,1,0,0,0,3,3,3,2,1,1,1,1,1,1,1,1,1,1,1
1,1,1,4,3,3,2,1,3,0,3,3,0,0,0,3,0,0,0,0,1,0,0,0,0,3,0,0,0,3,3,0,3,1,4,3,3,2,1,1,1,1
1,1,4,3,3,3,3,0,4,3,3,3,3,0,3,3,0,0,0,0,1,0,0,0,0,3,3,0,3,3,3,3,2,0,3,3,3,3,2,1,1,1
1,1,3,3,0,5,0,0,4,3,0,0,3,0,0,3,3,0,0,0,1,0,0,0,3,3,0,0,3,0,0,3,2,0,0,5,0,3,3,1,1,1
1,1,3,3,0,5,0,0,4,3,0,0,3,0,3,3,3,0,0,0,1,0,0,0,3,3,0,0,3,0,0,3,2,0,0,5,0,3,3,1,1,1
1,1,4,3,3,3,3,0,4,3,3,3,3,0,3,3,0,0,0,0,1,0,0,0,3,7,3,0,3,3,3,3,2,0,3,3,3,3,2,1,1,1
1,1,1,4,3,3,2,1,3,0,3,3,0,0,0,3,0,0,0,0,1,0,0,0,0,3,0,0,0,3,3,0,3,1,4,3,3,2,1,1,1,1
1,1,1,1,1,1,1,1,1,1,4,3,3,3,0,0,0,1,0,0,1,0,0,1,0,0,0,3,3,3,2,1,1,1,1,1,1,1,1,1,1,1
1,1,1,1,1,1,1,1,1,1,1,4,3,2,1,1,1,1,1,1,1,1,1,1,1,1,1,4,3,2,1,1,1,1,1,1,1,1,1,1,1,1
endlayer

layer
1,1,1,1,1,1,1,1,1,1,1,1,5,1,1,1,1,1,1,1,1,1,1,1,1,1,1,1,5,1,1,1,1,1,1,1,1,1,1,1,1,1
1,1,1,1,1,1,1,1,1,1,0,3,3,3,0,0,0,1,1,1,1,1,1,1,0,0,0,3,3,3,0,1,1,1,1,1,1,1,1,1,1,1
1,1,1,1,3,3,1,1,3,0,0,3,0,0,3,3,3,0,0,0,1,0,0,0,0,3,3,0,0,3,0,0,3,1,1,3,3,1,1,1,1,1
1,1,1,3,0,0,3,0,0,3,0,3,3,3,3,3,3,0,0,0,1,0,0,0,3,3,3,3,3,3,0,3,0,0,3,0,0,3,1,1,1,1
1,1,3,0,0,0,0,0,0,4,3,0,3,3,3,3,3,3,0,0,1,0,0,0,3,3,3,3,8,3,3,2,0,0,0,0,0,0,3,1,1,1
1,1,3,0,0,0,0,0,0,4,3,0,3,3,8,3,3,3,0,0,1,0,0,0,3,3,3,3,3,3,3,2,0,0,0,0,0,0,3,1,1,1
1,1,1,3,0,0,3,0,0,3,0,3,3,3,3,3,3,0,0,0,1,0,0,0,3,7,3,3,3,3,0,3,0,0,3,0,0,3,1,1,1,1
1,1,1,1,3,3,1,1,3,0,0,3,0,0,3,3,3,0,0,0,1,0,0,0,0,3,3,0,0,3,0,0,3,1,1,3,3,1,1,1,1,1
1,1,1,1,1,1,1,1,1,1,0,3,3,3,0,0,0,1,0,0,1,0,0,1,0,0,0,3,3,3,0,1,1,1,1,1,1,1,1,1,1,1
1,1,1,1,1,1,1,1,1,1,1,1,5,1,1,1,1,1,1,1,1,1,1,1,1,1,1,1,5,1,1,1,1,1,1,1,1,1,1,1,1,1
endlayer

layer
1,1,1,1,1,1,1,1,1,1,1,1,1,1,1,1,1,1,1,1,1,1,1,1,1,1,1,1,1,1,1,1,1,1,1,1,1,1,1,1,1,1
1,1,1,1,1,1,1,1,1,1,0,3,0,0,0,0,0,1,1,1,1,1,1,1,0,0,0,0,0,3,0,1,1,1,1,1,1,1,1,1,1,1
1,1,1,1,5,5,1,1,4,3,0,0,3,3,0,0,0,0,0,0,1,0,0,0,0,0,0,3,3,0,0,3,2,1,1,5,5,1,1,1,1,1
1,1,1,3,3,3,3,0,3,3,3,3,6,0,0,0,0,0,3,0,1,0,0,0,0,0,0,0,0,3,3,3,3,0,3,3,3,3,1,1,1,1
1,1,4,3,0,0,3,0,3,0,0,0,0,3,0,0,0,4,3,0,1,0,0,0,0,0,0,3,0,0,0,0,3,0,3,0,0,3,2,1,1,1
1,1,4,3,0,0,3,0,3,0,0,0,0,3,0,0,0,0,0,0,1,0,0,0,0,0,0,3,0,0,0,0,3,0,3,0,0,3,2,1,1,1
1,1,1,3,3,3,3,0,3,3,3,3,0,0,0,0,0,0,0,0,1,0,0,0,0,0,0,0,0,3,3,3,3,0,3,3,3,3,1,1,1,1
1,1,1,1,5,5,1,1,4,3,0,0,3,3,0,0,0,0,0,0,1,0,0,0,0,0,0,3,3,0,0,3,2,1,1,5,5,1,1,1,1,1
1,1,1,1,1,1,1,1,1,1,0,3,0,0,0,0,0,1,0,0,1,0,0,1,0,0,0,0,0,3,0,1,1,1,1,1,1,1,1,1,1,1
1,1,1,1,1,1,1,1,1,1,1,1,1,1,1,1,1,1,1,1,1,1,1,1,1,1,1,1,1,1,1,1,1,1,1,1,1,1,1,1,1,1
endlayer

layer
1,1,1,1,1,1,1,1,1,1,1,1,1,1,1,1,1,1,1,1,1,1,1,1,1,1,1,1,1,1,1,1,1,1,1,1,1,1,1,1,1,1
1,1,1,1,1,1,1,1,1,1,0,0,3,3,0,0,0,1,1,1,1,1,1,1,0,0,0,3,3,0,0,1,1,1,1,1,1,1,1,1,1,1
1,1,1,1,1,1,1,1,0,4,3,0,3,3,0,0,0,0,0,0,1,0,0,0,0,0,0,3,3,0,3,2,0,1,1,1,1,1,1,1,1,1
1,1,1,4,3,3,2,0,4,3,3,3,0,0,0,0,0,0,3,3,1,0,0,0,0,0,0,0,0,3,3,3,2,0,4,3,3,2,1,1,1,1
1,1,1,3,3,3,3,0,3,3,3,0,0,3,0,0,0,0,4,3,1,0,0,0,0,0,0,3,0,0,3,3,3,0,3,3,3,3,1,1,1,1
1,1,1,3,3,3,3,0,3,3,3,0,0,3,0,0,0,0,0,0,1,0,0,0,0,0,0,3,0,0,3,3,3,0,3,3,3,3,1,1,1,1
1,1,1,4,3,3,2,0,4,3,3,3,0,0,0,0,0,0,0,0,1,0,0,0,0,0,0,0,0,3,3,3,2,0,4,3,3,2,1,1,1,1
1,1,1,1,1,1,1,1,0,4,3,0,3,3,0,0,0,0,0,0,1,0,0,0,0,0,0,3,3,0,3,2,0,1,1,1,1,1,1,1,1,1
1,1,1,1,1,1,1,1,1,1,0,0,3,3,0,0,0,1,0,0,1,0,0,1,0,0,0,3,3,0,0,1,1,1,1,1,1,1,1,1,1,1
1,1,1,1,1,1,1,1,1,1,1,1,1,1,1,1,1,1,1,1,1,1,1,1,1,1,1,1,1,1,1,1,1,1,1,1,1,1,1,1,1,1
endlayer

layer
1,1,1,1,1,1,1,1,1,1,1,1,1,1,1,1,1,1,1,1,1,1,1,1,1,1,1,1,1,1,1,1,1,1,1,1,1,1,1,1,1,1
1,1,1,1,1,1,1,1,1,1,0,0,4,3,0,0,0,1,1,1,1,1,1,1,0,0,0,3,2,0,0,1,1,1,1,1,1,1,1,1,1,1
1,1,1,1,1,1,1,1,0,0,4,3,3,0,0,0,0,0,3,3,1,0,0,0,0,0,0,3,3,3,2,0,0,1,1,1,1,1,1,1,1,1
1,1,1,1,3,0,0,3,0,4,3,3,0,3,0,0,0,0,3,5,1,0,0,0,0,0,0,3,0,3,3,2,0,3,0,0,3,1,1,1,1,1
1,1,1,4,3,3,0,0,0,3,3,0,3,3,0,0,0,0,0,0,1,0,0,0,0,0,0,3,3,0,3,3,0,0,0,3,3,2,1,1,1,1
1,1,1,4,3,3,0,0,0,3,3,0,3,3,0,0,0,0,0,0,1,0,0,0,0,0,0,3,3,0,3,3,0,0,0,3,3,2,1,1,1,1
1,1,1,1,3,0,0,3,0,4,3,3,0,3,0,0,0,0,0,0,1,0,0,0,0,0,0,3,0,3,3,2,0,3,0,0,3,1,1,1,1,1
1,1,1,1,1,1,1,1,0,0,4,3,3,0,0,0,0,0,0,0,1,0,0,0,0,0,0,3,3,3,2,0,0,1,1,1,1,1,1,1,1,1
1,1,1,1,1,1,1,1,1,1,0,0,4,3,0,0,0,1,0,0,1,0,0,1,0,0,0,3,2,0,0,1,1,1,1,1,1,1,1,1,1,1
1,1,1,1,1,1,1,1,1,1,1,1,1,1,1,1,1,1,1,1,1,1,1,1,1,1,1,1,1,1,1,1,1,1,1,1,1,1,1,1,1,1
endlayer

layer
1,1,1,1,1,1,1,1,1,1,1,1,1,1,1,1,1,1,1,1,1,1,1,1,1,1,1,1,1,1,1,1,1,1,1,1,1,1,1,1,1,1
1,1,1,1,1,1,1,1,1,1,3,3,0,3,0,0,0,1,1,1,1,1,1,1,0,0,0,3,0,3,3,1,1,1,1,1,1,1,1,1,1,1
1,1,1,1,1,1,1,1,0,3,0,3,3,0,0,0,0,3,2,1,1,0,0,0,0,0,0,0,3,3,0,3,0,1,1,1,1,1,1,1,1,1
1,1,1,1,4,3,3,5,3,0,3,3,0,0,0,0,0,3,3,0,1,0,0,0,0,0,0,0,0,3,3,0,3,5,3,3,2,1,1,1,1,1
1,1,1,1,3,3,0,3,0,3,3,0,3,3,0,0,0,0,0,0,1,0,0,0,0,0,0,3,3,0,3,3,0,3,0,3,3,1,1,1,1,1
1,1,1,1,3,3,0,3,0,3,3,0,3,3,0,0,0,0,0,0,1,0,0,0,0,0,0,3,3,0,3,3,0,3,0,3,3,1,1,1,1,1
1,1,1,1,4,3,3,5,3,0,3,3,0,0,0,0,0,0,0,0,1,0,0,0,0,0,0,0,0,3,3,0,3,5,3,3,2,1,1,1,1,1
1,1,1,1,1,1,1,1,0,3,0,3,3,0,0,0,0,0,0,0,1,0,0,0,0,0,0,0,3,3,0,3,0,1,1,1,1,1,1,1,1,1
1,1,1,1,1,1,1,1,1,1,3,3,0,3,0,0,0,1,0,0,1,0,0,1,0,0,0,3,0,3,3,1,1,1,1,1,1,1,1,1,1,1
1,1,1,1,1,1,1,1,1,1,1,1,1,1,1,1,1,1,1,1,1,1,1,1,1,1,1,1,1,1,1,1,1,1,1,1,1,1,1,1,1,1
endlayer

layer
1,1,1,1,1,1,1,1,1,1,1,1,1,1,1,1,1,1,1,1,1,1,1,1,1,1,1,1,1,1,1,1,1,1,1,1,1,1,1,1,1,1
1,1,1,1,1,1,1,1,1,1,1,3,0,3,0,0,0,1,1,1,1,1,1,1,0,0,0,3,0,3,1,1,1,1,1,1,1,1,1,1,1,1
1,1,1,1,1,1,1,1,0,3,0,3,3,0,0,0,3,0,0,1,1,0,0,0,3,0,0,0,3,3,0,3,0,1,1,1,1,1,1,1,1,1
1,1,1,1,1,3,0,0,0,0,3,3,0,0,0,0,0,5,3,0,1,0,0,0,0,0,0,0,0,3,3,0,0,0,0,3,1,1,1,1,1,1
1,1,1,1,4,3,0,3,0,3,3,0,0,3,0,0,0,3,3,0,1,0,0,0,0,0,0,3,0,0,3,3,0,3,0,3,2,1,1,1,1,1
1,1,1,1,4,3,0,3,0,3,3,0,0,3,0,0,0,0,0,0,1,0,0,0,0,0,0,3,0,0,3,3,0,3,0,3,2,1,1,1,1,1
1,1,1,1,1,3,0,0,0,0,3,3,0,0,0,0,0,0,0,0,1,0,0,0,0,0,0,0,0,3,3,0,0,0,0,3,1,1,1,1,1,1
1,1,1,1,1,1,1,1,0,3,0,3,3,0,0,0,3,0,0,0,1,0,0,0,3,0,0,0,3,3,0,3,0,1,1,1,1,1,1,1,1,1
1,1,1,1,1,1,1,1,1,1,1,3,0,3,0,0,0,1,0,0,1,0,0,1,0,0,0,3,0,3,1,1,1,1,1,1,1,1,1,1,1,1
1,1,1,1,1,1,1,1,1,1,1,1,1,1,1,1,1,1,1,1,1,1,1,1,1,1,1,1,1,1,1,1,1,1,1,1,1,1,1,1,1,1
endlayer

layer
1,1,1,1,1,1,1,1,1,1,1,1,1,1,1,1,1,1,1,1,1,1,1,1,1,1,1,1,1,1,1,1,1,1,1,1,1,1,1,1,1,1
1,1,1,1,1,1,1,1,1,1,1,4,3,2,0,3,0,1,1,1,1,1,1,1,0,3,0,4,3,2,1,1,1,1,1,1,1,1,1,1,1,1
1,1,1,1,1,1,1,1,0,3,0,3,3,3,0,0,0,0,0,1,1,0,0,0,0,0,0,3,3,3,0,3,0,1,1,1,1,1,1,1,1,1
1,1,1,1,1,4,3,0,3,0,3,3,0,3,0,3,0,0,3,0,1,0,0,3,0,3,0,3,0,3,3,0,3,0,3,2,1,1,1,1,1,1
1,1,1,1,1,3,3,3,0,3,3,0,0,3,0,0,0,0,4,3,1,0,0,0,0,0,0,3,0,0,3,3,0,3,3,3,1,1,1,1,1,1
1,1,1,1,1,3,3,3,0,3,3,0,0,3,0,0,0,0,0,0,1,3,0,0,0,0,0,3,0,0,3,3,0,3,3,3,1,1,1,1,1,1
1,1,1,1,1,4,3,0,3,0,3,3,0,3,0,3,0,3,3,0,1,3,0,3,0,3,0,3,0,3,3,0,3,0,3,2,1,1,1,1,1,1
1,1,1,1,1,1,1,1,0,3,0,3,3,3,0,0,0,0,0,0,1,0,0,0,0,0,0,3,3,3,0,3,0,1,1,1,1,1,1,1,1,1
1,1,1,1,1,1,1,1,1,1,1,4,3,2,0,3,0,1,0,0,1,0,0,1,0,3,0,4,3,2,1,1,1,1,1,1,1,1,1,1,1,1
1,1,1,1,1,1,1,1,1,1,1,1,1,1,1,1,1,1,1,1,1,1,1,1,1,1,1,1,1,1,1,1,1,1,1,1,1,1,1,1,1,1
endlayer

layer
1,1,1,1,1,1,1,1,1,1,1,1,1,1,1,1,1,1,1,1,1,1,1,1,1,1,1,1,1,1,1,1,1,1,1,1,1,1,1,1,1,1
1,1,1,1,1,1,1,1,1,1,1,1,3,0,0,3,0,1,1,1,1,1,1,1,0,3,0,0,3,1,1,1,1,1,1,1,1,1,1,1,1,1
1,1,1,1,1,1,1,1,3,1,3,3,3,0,3,3,0,0,3,1,1,0,3,0,0,3,0,0,3,3,3,1,3,1,1,1,1,1,1,1,1,1
1,1,1,1,1,1,3,0,0,0,3,3,0,3,3,3,3,0,3,3,1,3,3,3,3,3,0,3,0,3,3,0,0,0,3,1,1,1,1,1,1,1
1,1,1,1,1,4,3,3,0,3,3,0,0,3,3,0,3,0,0,4,3,3,3,0,3,0,3,3,0,0,3,3,0,3,3,2,1,1,1,1,1,1
1,1,1,1,1,4,3,3,0,3,3,0,0,3,3,0,3,0,3,3,3,8,3,0,3,0,3,3,0,0,3,3,0,3,3,2,1,1,1,1,1,1
1,1,1,1,1,1,3,0,0,0,3,3,0,3,3,3,3,3,8,3,1,8,3,3,3,3,0,3,0,3,3,0,0,0,3,1,1,1,1,1,1,1
1,1,1,1,1,1,1,1,3,1,3,3,3,0,3,3,0,0,3,0,1,0,3,0,0,3,0,0,3,3,3,1,3,1,1,1,1,1,1,1,1,1
1,1,1,1,1,1,1,1,1,1,1,1,3,0,0,3,0,1,0,0,1,0,0,1,0,3,0,0,3,1,1,1,1,1,1,1,1,1,1,1,1,1
1,1,1,1,1,1,1,1,1,1,1,1,1,1,1,1,1,1,1,1,1,1,1,1,1,1,1,1,1,1,1,1,1,1,1,1,1,1,1,1,1,1
endlayer

layer
1,1,1,1,1,1,1,1,1,1,1,1,1,1,1,1,1,1,1,1,1,1,1,1,1,1,1,1,1,1,1,1,1,1,1,1,1,1,1,1,1,1
1,1,1,1,1,1,1,1,1,1,1,1,3,3,0,3,3,1,1,1,1,1,1,1,3,3,0,3,3,1,1,1,1,1,1,1,1,1,1,1,1,1
1,1,1,1,1,1,1,1,5,1,3,3,3,3,0,3,0,3,0,1,1,0,0,3,0,3,0,3,3,3,3,1,5,1,1,1,1,1,1,1,1,1
1,1,1,1,1,1,4,3,3,3,3,3,0,0,0,3,3,0,0,0,1,0,0,0,3,3,0,0,0,3,3,3,3,3,2,1,1,1,1,1,1,1
1,1,1,1,1,1,3,3,0,5,5,0,0,0,3,0,3,0,0,0,1,0,0,3,3,0,3,0,0,0,5,5,0,3,3,1,1,1,1,1,1,1
1,1,1,1,1,1,3,3,0,5,5,0,0,0,3,0,3,3,0,0,1,0,0,3,3,0,3,0,0,0,5,5,0,3,3,1,1,1,1,1,1,1
1,1,1,1,1,1,4,3,3,3,3,3,0,0,0,3,3,0,0,0,1,0,0,6,3,3,0,0,0,3,3,3,3,3,2,1,1,1,1,1,1,1
1,1,1,1,1,1,1,1,5,1,3,3,3,3,0,3,0,3,0,0,1,0,0,3,0,3,0,3,3,3,3,1,5,1,1,1,1,1,1,1,1,1
1,1,1,1,1,1,1,1,1,1,1,1,3,3,0,3,3,1,0,0,1,0,0,1,3,3,0,3,3,1,1,1,1,1,1,1,1,1,1,1,1,1
1,1,1,1,1,1,1,1,1,1,1,1,1,1,1,1,1,1,1,1,1,1,1,1,1,1,1,1,1,1,1,1,1,1,1,1,1,1,1,1,1,1
endlayer

layer
1,1,1,1,1,1,1,1,1,1,1,1,1,1,1,1,1,1,1,1,1,1,1,1,1,1,1,1,1,1,1,1,1,1,1,1,1,1,1,1,1,1
1,1,1,1,1,1,1,1,1,1,1,1,5,4,3,3,1,1,1,1,1,1,1,1,1,3,3,2,5,1,1,1,1,1,1,1,1,1,1,1,1,1
1,1,1,1,1,1,1,1,1,1,4,3,3,3,0,3,0,3,0,1,1,0,0,3,0,3,0,3,3,3,2,1,1,1,1,1,1,1,1,1,1,1
1,1,1,1,1,1,1,3,0,3,3,0,0,0,0,3,3,0,0,0,1,0,0,0,3,3,0,0,0,0,3,3,0,3,1,1,1,1,1,1,1,1
1,1,1,1,1,1,0,3,0,0,0,0,0,0,3,0,3,3,0,0,1,0,0,3,3,0,3,0,0,0,0,0,0,3,0,1,1,1,1,1,1,1
1,1,1,1,1,1,0,3,0,0,0,0,0,0,3,0,3,3,0,0,1,0,0,3,3,0,3,0,0,0,0,0,0,3,0,1,1,1,1,1,1,1
1,1,1,1,1,1,1,3,0,3,3,0,0,0,0,3,3,0,0,0,1,0,0,0,3,3,0,0,0,0,3,3,0,3,1,1,1,1,1,1,1,1
1,1,1,1,1,1,1,1,1,1,4,3,3,3,0,3,0,3,0,0,1,0,0,3,0,3,0,3,3,3,2,1,1,1,1,1,1,1,1,1,1,1
1,1,1,1,1,1,1,1,1,1,1,1,5,4,3,3,1,1,0,0,1,0,0,1,1,3,3,2,5,1,1,1,1,1,1,1,1,1,1,1,1,1
1,1,1,1,1,1,1,1,1,1,1,1,1,1,1,1,1,1,1,1,1,1,1,1,1,1,1,1,1,1,1,1,1,1,1,1,1,1,1,1,1,1
endlayer

layer
1,1,1,1,1,1,1,1,1,1,1,1,1,1,1,1,1,1,1,1,1,1,1,1,1,1,1,1,1,1,1,1,1,1,1,1,1,1,1,1,1,1
1,1,1,1,1,1,1,1,1,1,1,1,1,1,5,5,1,1,1,1,1,1,1,1,1,5,5,1,1,1,1,1,1,1,1,1,1,1,1,1,1,1
1,1,1,1,1,1,1,1,1,1,1,5,4,3,3,3,3,3,0,1,1,0,0,3,3,3,3,3,2,5,1,1,1,1,1,1,1,1,1,1,1,1
1,1,1,1,1,1,1,0,0,0,3,3,3,0,0,3,3,0,3,3,1,3,3,0,3,3,0,0,3,3,3,0,0,0,1,1,1,1,1,1,1,1
1,1,1,1,1,1,3,3,3,0,3,0,0,3,3,0,3,3,0,0,1,3,0,3,3,0,0,3,0,0,3,0,3,3,3,1,1,1,1,1,1,1
1,1,1,1,1,1,3,3,3,0,3,0,0,3,3,0,3,3,0,3,1,3,0,3,3,0,0,3,0,0,3,0,3,3,3,1,1,1,1,1,1,1
1,1,1,1,1,1,1,0,0,0,3,3,3,0,0,3,3,0,3,3,1,3,3,0,3,3,0,0,3,3,3,0,0,0,1,1,1,1,1,1,1,1
1,1,1,1,1,1,1,1,1,1,1,5,4,3,3,3,3,3,0,0,1,0,0,3,3,3,3,3,2,5,1,1,1,1,1,1,1,1,1,1,1,1
1,1,1,1,1,1,1,1,1,1,1,1,1,1,5,5,1,1,0,0,1,0,0,1,1,5,5,1,1,1,1,1,1,1,1,1,1,1,1,1,1,1
1,1,1,1,1,1,1,1,1,1,1,1,1,1,1,1,1,1,1,1,1,1,1,1,1,1,1,1,1,1,1,1,1,1,1,1,1,1,1,1,1,1
endlayer

layer
1,1,1,1,1,1,1,1,1,1,1,1,1,1,1,1,1,1,1,1,1,1,1,1,1,1,1,1,1,1,1,1,1,1,1,1,1,1,1,1,1,1
1,1,1,1,1,1,1,1,1,1,1,1,1,1,1,1,1,1,1,1,1,1,1,1,1,1,1,1,1,1,1,1,1,1,1,1,1,1,1,1,1,1
1,1,1,1,1,1,1,1,1,1,1,1,1,3,2,0,3,0,0,1,1,0,0,1,3,0,4,3,1,1,1,1,1,1,1,1,1,1,1,1,1,1
1,1,1,1,1,1,1,3,3,0,3,0,0,0,3,3,0,0,0,3,1,3,0,0,0,3,3,0,0,0,3,0,3,3,1,1,1,1,1,1,1,1
1,1,1,1,1,1,4,3,3,0,3,0,3,3,0,0,0,3,0,3,1,3,0,3,0,0,0,3,3,0,3,0,3,3,2,1,1,1,1,1,1,1
1,1,1,1,1,1,4,3,3,0,3,0,3,3,0,0,0,3,0,3,1,3,0,3,0,0,0,3,3,0,3,0,3,3,2,1,1,1,1,1,1,1
1,1,1,1,1,1,1,3,3,0,3,0,0,0,3,3,0,0,0,3,1,3,0,0,0,3,3,0,0,0,3,0,3,3,1,1,1,1,1,1,1,1
1,1,1,1,1,1,1,1,1,1,1,1,1,3,2,0,3,0,0,0,1,0,0,0,3,0,4,3,1,1,1,1,1,1,1,1,1,1,1,1,1,1
1,1,1,1,1,1,1,1,1,1,1,1,1,1,1,1,1,1,0,0,1,0,0,1,1,1,1,1,1,1,1,1,1,1,1,1,1,1,1,1,1,1
1,1,1,1,1,1,1,1,1,1,1,1,1,1,1,1,1,1,1,1,1,1,1,1,1,1,1,1,1,1,1,1,1,1,1,1,1,1,1,1,1,1
endlayer

layer
1,1,1,1,1,1,1,1,1,1,1,1,1,1,1,1,1,1,1,1,1,1,1,1,1,1,1,1,1,1,1,1,1,1,1,1,1,1,1,1,1,1
1,1,1,1,1,1,1,1,1,1,1,1,1,1,1,1,1,1,1,1,1,1,1,1,1,1,1,1,1,1,1,1,1,1,1,1,1,1,1,1,1,1
1,1,1,1,1,1,1,1,1,1,1,1,1,3,0,3,3,0,0,1,1,0,0,1,3,3,0,3,1,1,1,1,1,1,1,1,1,1,1,1,1,1
1,1,1,1,1,1,1,4,3,0,3,0,3,0,3,3,0,0,3,0,1,0,3,0,0,3,3,0,3,0,3,0,3,2,1,1,1,1,1,1,1,1
1,1,1,1,1,1,1,3,3,0,3,0,3,3,0,3,0,3,3,3,1,3,3,3,0,3,0,3,3,0,3,0,3,3,1,1,1,1,1,1,1,1
1,1,1,1,1,1,1,3,3,0,3,0,3,3,0,3,0,3,3,3,1,3,3,3,0,3,0,3,3,0,3,0,3,3,1,1,1,1,1,1,1,1
1,1,1,1,1,1,1,4,3,0,3,0,3,0,3,3,0,0,3,0,1,0,3,0,0,3,3,0,3,0,3,0,3,2,1,1,1,1,1,1,1,1
1,1,1,1,1,1,1,1,1,1,1,1,1,3,0,3,3,0,0,0,1,0,0,0,3,3,0,3,1,1,1,1,1,1,1,1,1,1,1,1,1,1
1,1,1,1,1,1,1,1,1,1,1,1,1,1,1,1,1,1,0,0,1,0,0,1,1,1,1,1,1,1,1,1,1,1,1,1,1,1,1,1,1,1
1,1,1,1,1,1,1,1,1,1,1,1,1,1,1,1,1,1,1,1,1,1,1,1,1,1,1,1,1,1,1,1,1,1,1,1,1,1,1,1,1,1
endlayer

layer
1,1,1,1,1,1,1,1,1,1,1,1,1,1,1,1,1,1,1,1,1,1,1,1,1,1,1,1,1,1,1,1,1,1,1,1,1,1,1,1,1,1
1,1,1,1,1,1,1,1,1,1,1,1,1,1,1,1,1,1,1,1,1,1,1,1,1,1,1,1,1,1,1,1,1,1,1,1,1,1,1,1,1,1
1,1,1,1,1,1,1,1,1,1,1,1,1,1,3,3,2,0,0,1,1,0,0,0,4,3,3,1,1,1,1,1,1,1,1,1,1,1,1,1,1,1
1,1,1,1,1,1,1,1,3,0,3,0,3,0,3,3,3,0,3,0,1,0,3,0,3,3,3,0,3,0,3,0,3,1,1,1,1,1,1,1,1,1
1,1,1,1,1,1,1,4,3,0,3,0,3,3,0,0,0,3,3,0,1,0,3,3,0,0,0,3,3,0,3,0,3,2,1,1,1,1,1,1,1,1
1,1,1,1,1,1,1,4,3,0,3,0,3,3,0,0,0,3,3,0,1,0,3,3,0,0,0,3,3,0,3,0,3,2,1,1,1,1,1,1,1,1
1,1,1,1,1,1,1,1,3,0,3,0,3,0,3,3,3,0,3,0,1,0,3,0,3,3,3,0,3,0,3,0,3,1,1,1,1,1,1,1,1,1
1,1,1,1,1,1,1,1,1,1,1,1,1,1,3,3,2,0,0,0,1,0,0,0,4,3,3,1,1,1,1,1,1,1,1,1,1,1,1,1,1,1
1,1,1,1,1,1,1,1,1,1,1,1,1,1,1,1,1,1,0,0,1,0,0,1,1,1,1,1,1,1,1,1,1,1,1,1,1,1,1,1,1,1
1,1,1,1,1,1,1,1,1,1,1,1,1,1,1,1,1,1,1,1,1,1,1,1,1,1,1,1,1,1,1,1,1,1,1,1,1,1,1,1,1,1
endlayer

layer
1,1,1,1,1,1,1,1,1,1,1,1,1,1,1,1,1,1,1,1,1,1,1,1,1,1,1,1,1,1,1,1,1,1,1,1,1,1,1,1,1,1
1,1,1,1,1,1,1,1,1,1,1,1,1,1,1,1,1,1,1,1,1,1,1,1,1,1,1,1,1,1,1,1,1,1,1,1,1,1,1,1,1,1
1,1,1,1,1,1,1,1,1,1,1,1,1,1,5,5,1,0,0,1,1,0,0,0,1,5,5,1,1,1,1,1,1,1,1,1,1,1,1,1,1,1
1,1,1,1,1,1,1,1,4,3,2,0,4,3,3,3,3,0,3,0,1,0,3,0,3,3,3,3,2,0,4,3,2,1,1,1,1,1,1,1,1,1
1,1,1,1,1,1,1,1,3,3,3,0,3,3,0,3,3,3,0,0,1,0,0,3,3,3,0,3,3,0,3,3,3,1,1,1,1,1,1,1,1,1
1,1,1,1,1,1,1,1,3,3,3,0,3,3,0,3,3,3,3,3,1,0,0,3,3,3,0,3,3,0,3,3,3,1,1,1,1,1,1,1,1,1
1,1,1,1,1,1,1,1,4,3,2,0,4,3,3,3,3,0,3,0,1,0,3,0,3,3,3,3,2,0,4,3,2,1,1,1,1,1,1,1,1,1
1,1,1,1,1,1,1,1,1,1,1,1,1,1,5,5,1,0,0,0,1,0,0,0,1,5,5,1,1,1,1,1,1,1,1,1,1,1,1,1,1,1
1,1,1,1,1,1,1,1,1,1,1,1,1,1,1,1,1,1,0,0,1,0,0,1,1,1,1,1,1,1,1,1,1,1,1,1,1,1,1,1,1,1
1,1,1,1,1,1,1,1,1,1,1,1,1,1,1,1,1,1,1,1,1,1,1,1,1,1,1,1,1,1,1,1,1,1,1,1,1,1,1,1,1,1
endlayer

layer
1,1,1,1,1,1,1,1,1,1,1,1,1,1,1,1,1,1,1,1,1,1,1,1,1,1,1,1,1,1,1,1,1,1,1,1,1,1,1,1,1,1
1,1,1,1,1,1,1,1,1,1,1,1,1,1,1,1,1,1,1,1,1,1,1,1,1,1,1,1,1,1,1,1,1,1,1,1,1,1,1,1,1,1
1,1,1,1,1,1,1,1,1,1,1,1,1,1,1,1,1,0,3,1,1,0,3,0,1,1,1,1,1,1,1,1,1,1,1,1,1,1,1,1,1,1
1,1,1,1,1,1,1,1,1,3,0,0,0,3,3,3,0,3,3,3,1,0,3,3,0,3,3,3,0,0,0,3,1,1,1,1,1,1,1,1,1,1
1,1,1,1,1,1,1,1,0,3,0,0,0,3,3,8,3,3,3,3,1,0,3,3,3,3,3,3,0,0,0,3,0,1,1,1,1,1,1,1,1,1
1,1,1,1,1,1,1,1,0,3,0,0,0,3,3,3,3,3,8,8,1,0,3,3,3,3,3,3,0,0,0,3,0,1,1,1,1,1,1,1,1,1
1,1,1,1,1,1,1,1,1,3,0,0,0,3,3,3,0,3,3,3,1,0,3,3,0,8,3,3,0,0,0,3,1,1,1,1,1,1,1,1,1,1
1,1,1,1,1,1,1,1,1,1,1,1,1,1,1,1,1,0,3,0,1,0,3,0,1,1,1,1,1,1,1,1,1,1,1,1,1,1,1,1,1,1
1,1,1,1,1,1,1,1,1,1,1,1,1,1,1,1,1,1,0,0,1,0,0,1,1,1,1,1,1,1,1,1,1,1,1,1,1,1,1,1,1,1
1,1,1,1,1,1,1,1,1,1,1,1,1,1,1,1,1,1,1,1,1,1,1,1,1,1,1,1,1,1,1,1,1,1,1,1,1,1,1,1,1,1
endlayer

layer
1,1,1,1,1,1,1,1,1,1,1,1,1,1,1,1,1,1,1,1,1,1,1,1,1,1,1,1,1,1,1,1,1,1,1,1,1,1,1,1,1,1
1,1,1,1,1,1,1,1,1,1,1,1,1,1,1,1,1,1,1,1,1,1,1,1,1,1,1,1,1,1,1,1,1,1,1,1,1,1,1,1,1,1
1,1,1,1,1,1,1,1,1,1,1,1,1,1,1,1,1,3,3,0,1,0,3,3,1,1,1,1,1,1,1,1,1,1,1,1,1,1,1,1,1,1
1,1,1,1,1,1,1,1,1,0,0,0,0,0,0,0,3,0,0,1,1,0,0,0,3,0,0,0,0,0,0,0,1,1,1,1,1,1,1,1,1,1
1,1,1,1,1,1,1,1,3,3,3,0,3,3,0,0,0,3,0,1,1,0,0,3,0,0,0,3,3,0,3,3,3,1,1,1,1,1,1,1,1,1
1,1,1,1,1,1,1,1,3,3,3,0,3,3,0,0,0,3,0,1,1,0,6,3,0,0,0,3,3,0,3,3,3,1,1,1,1,1,1,1,1,1
1,1,1,1,1,1,1,1,1,0,0,0,0,0,0,0,3,0,0,1,1,0,0,0,3,0,0,0,0,0,0,0,1,1,1,1,1,1,1,1,1,1
1,1,1,1,1,1,1,1,1,1,1,1,1,1,1,1,1,3,3,0,1,0,3,3,1,1,1,1,1,1,1,1,1,1,1,1,1,1,1,1,1,1
1,1,1,1,1,1,1,1,1,1,1,1,1,1,1,1,1,1,0,0,1,0,0,1,1,1,1,1,1,1,1,1,1,1,1,1,1,1,1,1,1,1
1,1,1,1,1,1,1,1,1,1,1,1,1,1,1,1,1,1,1,1,1,1,1,1,1,1,1,1,1,1,1,1,1,1,1,1,1,1,1,1,1,1
endlayer

layer
1,1,1,1,1,1,1,1,1,1,1,1,1,1,1,1,1,1,1,1,1,1,1,1,1,1,1,1,1,1,1,1,1,1,1,1,1,1,1,1,1,1
1,1,1,1,1,1,1,1,1,1,1,1,1,1,1,1,1,1,1,1,1,1,1,1,1,1,1,1,1,1,1,1,1,1,1,1,1,1,1,1,1,1
1,1,1,1,1,1,1,1,1,1,1,1,1,1,1,1,1,3,3,0,1,0,3,3,1,1,1,1,1,1,1,1,1,1,1,1,1,1,1,1,1,1
1,1,1,1,1,1,1,1,1,3,3,0,3,3,0,0,3,0,0,1,1,0,0,0,3,0,0,3,3,0,3,3,1,1,1,1,1,1,1,1,1,1
1,1,1,1,1,1,1,1,4,3,3,0,3,3,0,0,0,3,0,1,1,0,0,3,0,0,0,3,3,0,3,3,2,1,1,1,1,1,1,1,1,1
1,1,1,1,1,1,1,1,4,3,3,0,3,3,0,0,0,3,0,1,1,0,0,3,0,0,0,3,3,0,3,3,2,1,1,1,1,1,1,1,1,1
1,1,1,1,1,1,1,1,1,3,3,0,3,3,0,0,3,0,0,1,1,0,0,0,3,0,0,3,3,0,3,3,1,1,1,1,1,1,1,1,1,1
1,1,1,1,1,1,1,1,1,1,1,1,1,1,1,1,1,3,3,0,1,0,3,3,1,1,1,1,1,1,1,1,1,1,1,1,1,1,1,1,1,1
1,1,1,1,1,1,1,1,1,1,1,1,1,1,1,1,1,1,0,0,1,0,0,1,1,1,1,1,1,1,1,1,1,1,1,1,1,1,1,1,1,1
1,1,1,1,1,1,1,1,1,1,1,1,1,1,1,1,1,1,1,1,1,1,1,1,1,1,1,1,1,1,1,1,1,1,1,1,1,1,1,1,1,1
endlayer

layer
1,1,1,1,1,1,1,1,1,1,1,1,1,1,1,1,1,1,1,1,1,1,1,1,1,1,1,1,1,1,1,1,1,1,1,1,1,1,1,1,1,1
1,1,1,1,1,1,1,1,1,1,1,1,1,1,1,1,1,1,1,1,1,1,1,1,1,1,1,1,1,1,1,1,1,1,1,1,1,1,1,1,1,1
1,1,1,1,1,1,1,1,1,1,1,1,1,1,1,1,1,3,3,0,1,0,3,3,1,1,1,1,1,1,1,1,1,1,1,1,1,1,1,1,1,1
1,1,1,1,1,1,1,1,1,4,3,0,3,2,0,0,3,0,0,1,1,0,0,0,3,0,0,4,3,0,3,2,1,1,1,1,1,1,1,1,1,1
1,1,1,1,1,1,1,1,1,3,3,0,3,3,0,0,3,3,3,1,1,0,3,3,3,0,0,3,3,0,3,3,1,1,1,1,1,1,1,1,1,1
1,1,1,1,1,1,1,1,1,3,3,0,3,3,0,0,3,3,3,1,1,0,3,3,3,0,0,3,3,0,3,3,1,1,1,1,1,1,1,1,1,1
1,1,1,1,1,1,1,1,1,4,3,0,3,2,0,0,3,0,0,0,1,0,0,0,3,0,0,4,3,0,3,2,1,1,1,1,1,1,1,1,1,1
1,1,1,1,1,1,1,1,1,1,1,1,1,1,1,1,1,3,3,0,1,0,3,3,1,1,1,1,1,1,1,1,1,1,1,1,1,1,1,1,1,1
1,1,1,1,1,1,1,1,1,1,1,1,1,1,1,1,1,1,0,0,1,0,0,1,1,1,1,1,1,1,1,1,1,1,1,1,1,1,1,1,1,1
1,1,1,1,1,1,1,1,1,1,1,1,1,1,1,1,1,1,1,1,1,1,1,1,1,1,1,1,1,1,1,1,1,1,1,1,1,1,1,1,1,1
endlayer

layer
1,1,1,1,1,1,1,1,1,1,1,1,1,1,1,1,1,1,1,1,1,1,1,1,1,1,1,1,1,1,1,1,1,1,1,1,1,1,1,1,1,1
1,1,1,1,1,1,1,1,1,1,1,1,1,1,1,1,1,1,1,1,1,1,1,1,1,1,1,1,1,1,1,1,1,1,1,1,1,1,1,1,1,1
1,1,1,1,1,1,1,1,1,1,1,1,1,1,1,1,1,3,3,0,1,0,3,3,1,1,1,1,1,1,1,1,1,1,1,1,1,1,1,1,1,1
1,1,1,1,1,1,1,1,1,1,3,0,3,0,0,0,0,0,3,1,1,0,3,0,0,0,0,0,3,0,3,1,1,1,1,1,1,1,1,1,1,1
1,1,1,1,1,1,1,1,1,4,3,0,3,2,0,3,3,3,0,1,1,0,0,3,3,3,0,4,3,0,3,2,1,1,1,1,1,1,1,1,1,1
1,1,1,1,1,1,1,1,1,4,3,0,3,2,0,3,3,3,0,1,1,0,0,3,3,3,0,4,3,0,3,2,1,1,1,1,1,1,1,1,1,1
1,1,1,1,1,1,1,1,1,1,3,0,3,0,0,0,0,0,3,0,1,0,3,0,0,0,0,0,3,0,3,1,1,1,1,1,1,1,1,1,1,1
1,1,1,1,1,1,1,1,1,1,1,1,1,1,1,1,1,3,3,0,1,0,3,3,1,1,1,1,1,1,1,1,1,1,1,1,1,1,1,1,1,1
1,1,1,1,1,1,1,1,1,1,1,1,1,1,1,1,1,1,0,0,1,0,0,1,1,1,1,1,1,1,1,1,1,1,1,1,1,1,1,1,1,1
1,1,1,1,1,1,1,1,1,1,1,1,1,1,1,1,1,1,1,1,1,1,1,1,1,1,1,1,1,1,1,1,1,1,1,1,1,1,1,1,1,1
endlayer

layer
1,1,1,1,1,1,1,1,1,1,1,1,1,1,1,1,1,1,1,1,1,1,1,1,1,1,1,1,1,1,1,1,1,1,1,1,1,1,1,1,1,1
1,1,1,1,1,1,1,1,1,1,1,1,1,1,1,1,1,1,1,1,1,1,1,1,1,1,1,1,1,1,1,1,1,1,1,1,1,1,1,1,1,1
1,1,1,1,1,1,1,1,1,1,1,1,1,1,1,1,1,3,3,0,1,0,3,3,1,1,1,1,1,1,1,1,1,1,1,1,1,1,1,1,1,1
1,1,1,1,1,1,1,1,1,1,4,3,2,0,0,0,3,0,0,1,1,0,0,0,3,0,0,0,4,3,2,1,1,1,1,1,1,1,1,1,1,1
1,1,1,1,1,1,1,1,1,1,3,3,3,0,0,0,3,3,0,1,1,0,0,3,3,0,0,0,3,3,3,1,1,1,1,1,1,1,1,1,1,1
1,1,1,1,1,1,1,1,1,1,3,3,3,0,0,0,3,3,0,1,1,0,0,3,3,0,0,0,3,3,3,1,1,1,1,1,1,1,1,1,1,1
1,1,1,1,1,1,1,1,1,1,4,3,2,0,0,0,3,0,0,0,1,0,0,0,3,0,0,0,4,3,2,1,1,1,1,1,1,1,1,1,1,1
1,1,1,1,1,1,1,1,1,1,1,1,1,1,1,1,1,3,3,0,1,0,3,3,1,1,1,1,1,1,1,1,1,1,1,1,1,1,1,1,1,1
1,1,1,1,1,1,1,1,1,1,1,1,1,1,1,1,1,1,0,0,1,0,0,1,1,1,1,1,1,1,1,1,1,1,1,1,1,1,1,1,1,1
1,1,1,1,1,1,1,1,1,1,1,1,1,1,1,1,1,1,1,1,1,1,1,1,1,1,1,1,1,1,1,1,1,1,1,1,1,1,1,1,1,1
endlayer

layer
1,1,1,1,1,1,1,1,1,1,1,1,1,1,1,1,1,1,1,1,1,1,1,1,1,1,1,1,1,1,1,1,1,1,1,1,1,1,1,1,1,1
1,1,1,1,1,1,1,1,1,1,1,1,1,1,1,1,1,1,1,1,1,1,1,1,1,1,1,1,1,1,1,1,1,1,1,1,1,1,1,1,1,1
1,1,1,1,1,1,1,1,1,1,1,1,1,1,1,1,1,3,3,0,1,0,3,3,1,1,1,1,1,1,1,1,1,1,1,1,1,1,1,1,1,1
1,1,1,1,1,1,1,1,1,1,1,3,0,0,0,0,3,0,0,1,1,0,0,0,3,0,0,0,0,3,1,1,1,1,1,1,1,1,1,1,1,1
1,1,1,1,1,1,1,1,1,1,4,3,0,0,0,0,0,3,3,1,1,0,3,3,0,0,0,0,0,3,2,1,1,1,1,1,1,1,1,1,1,1
1,1,1,1,1,1,1,1,1,1,4,3,0,0,0,0,0,3,3,1,1,0,3,3,0,0,0,0,0,3,2,1,1,1,1,1,1,1,1,1,1,1
1,1,1,1,1,1,1,1,1,1,1,3,0,0,0,0,3,0,0,0,1,0,0,0,3,0,0,0,0,3,1,1,1,1,1,1,1,1,1,1,1,1
1,1,1,1,1,1,1,1,1,1,1,1,1,1,1,1,1,3,3,0,1,0,3,3,1,1,1,1,1,1,1,1,1,1,1,1,1,1,1,1,1,1
1,1,1,1,1,1,1,1,1,1,1,1,1,1,1,1,1,1,0,0,1,0,0,1,1,1,1,1,1,1,1,1,1,1,1,1,1,1,1,1,1,1
1,1,1,1,1,1,1,1,1,1,1,1,1,1,1,1,1,1,1,1,1,1,1,1,1,1,1,1,1,1,1,1,1,1,1,1,1,1,1,1,1,1
endlayer

layer
1,1,1,1,1,1,1,1,1,1,1,1,1,1,1,1,1,1,1,1,1,1,1,1,1,1,1,1,1,1,1,1,1,1,1,1,1,1,1,1,1,1
1,1,1,1,1,1,1,1,1,1,1,1,1,1,1,1,1,1,1,1,1,1,1,1,1,1,1,1,1,1,1,1,1,1,1,1,1,1,1,1,1,1
1,1,1,1,1,1,1,1,1,1,1,1,1,1,1,1,1,3,3,0,1,0,3,3,1,1,1,1,1,1,1,1,1,1,1,1,1,1,1,1,1,1
1,1,1,1,1,1,1,1,1,1,1,4,3,0,0,0,0,0,3,1,1,0,3,0,0,0,0,0,3,2,1,1,1,1,1,1,1,1,1,1,1,1
1,1,1,1,1,1,1,1,1,1,1,3,3,3,3,0,3,3,0,1,1,0,0,3,3,0,3,3,3,3,1,1,1,1,1,1,1,1,1,1,1,1
1,1,1,1,1,1,1,1,1,1,1,3,3,3,3,0,3,3,0,0,1,0,0,3,3,0,3,3,3,3,1,1,1,1,1,1,1,1,1,1,1,1
1,1,1,1,1,1,1,1,1,1,1,4,3,0,0,0,0,0,3,0,1,0,3,0,0,0,0,0,3,2,1,1,1,1,1,1,1,1,1,1,1,1
1,1,1,1,1,1,1,1,1,1,1,1,1,1,1,1,1,3,3,0,1,0,3,3,1,1,1,1,1,1,1,1,1,1,1,1,1,1,1,1,1,1
1,1,1,1,1,1,1,1,1,1,1,1,1,1,1,1,1,1,0,0,1,0,0,1,1,1,1,1,1,1,1,1,1,1,1,1,1,1,1,1,1,1
1,1,1,1,1,1,1,1,1,1,1,1,1,1,1,1,1,1,1,1,1,1,1,1,1,1,1,1,1,1,1,1,1,1,1,1,1,1,1,1,1,1
endlayer

layer
1,1,1,1,1,1,1,1,1,1,1,1,1,1,1,1,1,1,1,1,1,1,1,1,1,1,1,1,1,1,1,1,1,1,1,1,1,1,1,1,1,1
1,1,1,1,1,1,1,1,1,1,1,1,1,1,1,1,1,1,1,1,1,1,1,1,1,1,1,1,1,1,1,1,1,1,1,1,1,1,1,1,1,1
1,1,1,1,1,1,1,1,1,1,1,1,1,1,1,1,1,3,3,0,1,0,3,3,1,1,1,1,1,1,1,1,1,1,1,1,1,1,1,1,1,1
1,1,1,1,1,1,1,1,1,1,1,1,3,0,0,0,0,0,3,1,1,0,3,0,0,0,0,0,3,1,1,1,1,1,1,1,1,1,1,1,1,1
1,1,1,1,1,1,1,1,1,1,1,3,0,0,3,0,3,0,0,1,1,0,0,0,3,0,3,0,0,3,1,1,1,1,1,1,1,1,1,1,1,1
1,1,1,1,1,1,1,1,1,1,1,3,0,0,3,0,3,0,0,0,1,0,0,0,3,0,3,0,0,3,1,1,1,1,1,1,1,1,1,1,1,1
1,1,1,1,1,1,1,1,1,1,1,1,3,0,0,0,0,0,3,0,1,0,3,0,0,0,0,0,3,1,1,1,1,1,1,1,1,1,1,1,1,1
1,1,1,1,1,1,1,1,1,1,1,1,1,1,1,1,1,3,3,0,1,0,3,3,1,1,1,1,1,1,1,1,1,1,1,1,1,1,1,1,1,1
1,1,1,1,1,1,1,1,1,1,1,1,1,1,1,1,1,1,0,0,1,0,0,1,1,1,1,1,1,1,1,1,1,1,1,1,1,1,1,1,1,1
1,1,1,1,1,1,1,1,1,1,1,1,1,1,1,1,1,1,1,1,1,1,1,1,1,1,1,1,1,1,1,1,1,1,1,1,1,1,1,1,1,1
endlayer

layer
1,1,1,1,1,1,1,1,1,1,1,1,1,1,1,1,1,1,1,1,1,1,1,1,1,1,1,1,1,1,1,1,1,1,1,1,1,1,1,1,1,1
1,1,1,1,1,1,1,1,1,1,1,1,1,1,1,1,1,1,1,1,1,1,1,1,1,1,1,1,1,1,1,1,1,1,1,1,1,1,1,1,1,1
1,1,1,1,1,1,1,1,1,1,1,1,1,1,1,1,1,4,3,0,1,0,3,2,1,1,1,1,1,1,1,1,1,1,1,1,1,1,1,1,1,1
1,1,1,1,1,1,1,1,1,1,1,1,3,3,0,0,0,3,3,1,1,0,3,3,0,0,0,3,3,1,1,1,1,1,1,1,1,1,1,1,1,1
1,1,1,1,1,1,1,1,1,1,1,4,3,0,3,0,3,0,0,1,1,0,0,0,3,0,3,0,3,2,1,1,1,1,1,1,1,1,1,1,1,1
1,1,1,1,1,1,1,1,1,1,1,4,3,0,3,0,3,0,0,0,1,0,0,0,3,0,3,0,3,2,1,1,1,1,1,1,1,1,1,1,1,1
1,1,1,1,1,1,1,1,1,1,1,1,3,3,0,0,0,3,3,0,1,0,3,3,0,0,0,3,3,1,1,1,1,1,1,1,1,1,1,1,1,1
1,1,1,1,1,1,1,1,1,1,1,1,1,1,1,1,1,4,3,0,1,0,3,2,1,1,1,1,1,1,1,1,1,1,1,1,1,1,1,1,1,1
1,1,1,1,1,1,1,1,1,1,1,1,1,1,1,1,1,1,0,0,1,0,0,1,1,1,1,1,1,1,1,1,1,1,1,1,1,1,1,1,1,1
1,1,1,1,1,1,1,1,1,1,1,1,1,1,1,1,1,1,1,1,1,1,1,1,1,1,1,1,1,1,1,1,1,1,1,1,1,1,1,1,1,1
endlayer

layer
1,1,1,1,1,1,1,1,1,1,1,1,1,1,1,1,1,1,1,1,1,1,1,1,1,1,1,1,1,1,1,1,1,1,1,1,1,1,1,1,1,1
1,1,1,1,1,1,1,1,1,1,1,1,1,1,1,1,1,1,1,1,1,1,1,1,1,1,1,1,1,1,1,1,1,1,1,1,1,1,1,1,1,1
1,1,1,1,1,1,1,1,1,1,1,1,1,1,1,1,1,0,3,3,1,3,3,1,1,1,1,1,1,1,1,1,1,1,1,1,1,1,1,1,1,1
1,1,1,1,1,1,1,1,1,1,1,1,4,3,3,0,3,3,3,3,1,3,3,3,3,0,3,3,2,1,1,1,1,1,1,1,1,1,1,1,1,1
1,1,1,1,1,1,1,1,1,1,1,1,3,3,3,0,3,3,0,1,1,0,0,3,3,0,3,3,3,1,1,1,1,1,1,1,1,1,1,1,1,1
1,1,1,1,1,1,1,1,1,1,1,1,3,3,3,0,3,3,0,0,1,0,0,3,3,0,3,3,3,1,1,1,1,1,1,1,1,1,1,1,1,1
1,1,1,1,1,1,1,1,1,1,1,1,4,3,3,0,3,3,3,3,1,3,3,3,3,0,3,3,2,1,1,1,1,1,1,1,1,1,1,1,1,1
1,1,1,1,1,1,1,1,1,1,1,1,1,1,1,1,1,0,3,3,1,3,3,0,1,1,1,1,1,1,1,1,1,1,1,1,1,1,1,1,1,1
1,1,1,1,1,1,1,1,1,1,1,1,1,1,1,1,1,1,0,0,1,0,0,1,1,1,1,1,1,1,1,1,1,1,1,1,1,1,1,1,1,1
1,1,1,1,1,1,1,1,1,1,1,1,1,1,1,1,1,1,1,1,1,1,1,1,1,1,1,1,1,1,1,1,1,1,1,1,1,1,1,1,1,1
endlayer

layer
1,1,1,1,1,1,1,1,1,1,1,1,1,1,1,1,1,1,1,1,1,1,1,1,1,1,1,1,1,1,1,1,1,1,1,1,1,1,1,1,1,1
1,1,1,1,1,1,1,1,1,1,1,1,1,1,1,1,1,1,1,1,1,1,1,1,1,1,1,1,1,1,1,1,1,1,1,1,1,1,1,1,1,1
1,1,1,1,1,1,1,1,1,1,1,1,1,1,1,1,1,0,3,3,1,3,3,1,1,1,1,1,1,1,1,1,1,1,1,1,1,1,1,1,1,1
1,1,1,1,1,1,1,1,1,1,1,1,1,3,0,0,0,3,3,1,1,0,3,3,0,0,0,3,1,1,1,1,1,1,1,1,1,1,1,1,1,1
1,1,1,1,1,1,1,1,1,1,1,1,4,3,3,0,3,3,0,0,1,0,0,3,3,0,3,3,2,1,1,1,1,1,1,1,1,1,1,1,1,1
1,1,1,1,1,1,1,1,1,1,1,1,4,3,3,0,3,3,0,0,1,0,0,3,3,0,3,3,2,1,1,1,1,1,1,1,1,1,1,1,1,1
1,1,1,1,1,1,1,1,1,1,1,1,1,3,0,0,0,3,3,0,1,0,3,3,0,0,0,3,1,1,1,1,1,1,1,1,1,1,1,1,1,1
1,1,1,1,1,1,1,1,1,1,1,1,1,1,1,1,1,0,3,3,1,3,3,0,1,1,1,1,1,1,1,1,1,1,1,1,1,1,1,1,1,1
1,1,1,1,1,1,1,1,1,1,1,1,1,1,1,1,1,1,3,3,1,3,3,1,1,1,1,1,1,1,1,1,1,1,1,1,1,1,1,1,1,1
1,1,1,1,1,1,1,1,1,1,1,1,1,1,1,1,1,1,1,1,1,1,1,1,1,1,1,1,1,1,1,1,1,1,1,1,1,1,1,1,1,1
endlayer

layer
1,1,1,1,1,1,1,1,1,1,1,1,1,1,1,1,1,1,1,1,1,1,1,1,1,1,1,1,1,1,1,1,1,1,1,1,1,1,1,1,1,1
1,1,1,1,1,1,1,1,1,1,1,1,1,1,1,1,1,1,1,1,1,1,1,1,1,1,1,1,1,1,1,1,1,1,1,1,1,1,1,1,1,1
1,1,1,1,1,1,1,1,1,1,1,1,1,1,1,1,1,0,3,3,1,3,3,1,1,1,1,1,1,1,1,1,1,1,1,1,1,1,1,1,1,1
1,1,1,1,1,1,1,1,1,1,1,1,1,4,3,3,0,3,3,3,1,3,3,3,0,3,3,2,1,1,1,1,1,1,1,1,1,1,1,1,1,1
1,1,1,1,1,1,1,1,1,1,1,1,1,3,3,0,3,3,0,0,1,0,0,3,3,0,3,3,1,1,1,1,1,1,1,1,1,1,1,1,1,1
1,1,1,1,1,1,1,1,1,1,1,1,1,3,3,0,3,3,0,0,1,0,0,3,3,0,3,3,1,1,1,1,1,1,1,1,1,1,1,1,1,1
1,1,1,1,1,1,1,1,1,1,1,1,1,4,3,3,0,3,3,3,1,3,3,3,0,3,3,2,1,1,1,1,1,1,1,1,1,1,1,1,1,1
1,1,1,1,1,1,1,1,1,1,1,1,1,1,1,1,1,0,3,3,1,3,3,0,1,1,1,1,1,1,1,1,1,1,1,1,1,1,1,1,1,1
1,1,1,1,1,1,1,1,1,1,1,1,1,1,1,1,1,1,3,2,1,4,3,1,1,1,1,1,1,1,1,1,1,1,1,1,1,1,1,1,1,1
1,1,1,1,1,1,1,1,1,1,1,1,1,1,1,1,1,1,1,1,1,1,1,1,1,1,1,1,1,1,1,1,1,1,1,1,1,1,1,1,1,1
endlayer

layer
1,1,1,1,1,1,1,1,1,1,1,1,1,1,1,1,1,1,1,1,1,1,1,1,1,1,1,1,1,1,1,1,1,1,1,1,1,1,1,1,1,1
1,1,1,1,1,1,1,1,1,1,1,1,1,1,1,1,1,1,1,1,1,1,1,1,1,1,1,1,1,1,1,1,1,1,1,1,1,1,1,1,1,1
1,1,1,1,1,1,1,1,1,1,1,1,1,1,1,1,1,3,3,3,1,3,3,3,1,1,1,1,1,1,1,1,1,1,1,1,1,1,1,1,1,1
1,1,1,1,1,1,1,1,1,1,1,1,1,1,3,0,0,3,3,0,1,0,3,3,0,0,3,1,1,1,1,1,1,1,1,1,1,1,1,1,1,1
1,1,1,1,1,1,1,1,1,1,1,1,1,4,3,0,3,3,0,0,1,0,0,3,3,0,3,2,1,1,1,1,1,1,1,1,1,1,1,1,1,1
1,1,1,1,1,1,1,1,1,1,1,1,1,4,3,0,3,3,0,0,1,0,0,3,3,0,3,2,1,1,1,1,1,1,1,1,1,1,1,1,1,1
1,1,1,1,1,1,1,1,1,1,1,1,1,1,3,0,0,3,3,0,1,0,3,3,0,0,3,1,1,1,1,1,1,1,1,1,1,1,1,1,1,1
1,1,1,1,1,1,1,1,1,1,1,1,1,1,1,1,1,3,3,3,1,3,3,3,1,1,1,1,1,1,1,1,1,1,1,1,1,1,1,1,1,1
1,1,1,1,1,1,1,1,1,1,1,1,1,1,1,1,1,1,5,1,1,1,5,1,1,1,1,1,1,1,1,1,1,1,1,1,1,1,1,1,1,1
1,1,1,1,1,1,1,1,1,1,1,1,1,1,1,1,1,1,1,1,1,1,1,1,1,1,1,1,1,1,1,1,1,1,1,1,1,1,1,1,1,1
endlayer

layer
1,1,1,1,1,1,1,1,1,1,1,1,1,1,1,1,1,1,1,1,1,1,1,1,1,1,1,1,1,1,1,1,1,1,1,1,1,1,1,1,1,1
1,1,1,1,1,1,1,1,1,1,1,1,1,1,1,1,1,1,1,1,1,1,1,1,1,1,1,1,1,1,1,1,1,1,1,1,1,1,1,1,1,1
1,1,1,1,1,1,1,1,1,1,1,1,1,1,1,1,1,3,0,3,1,3,0,3,1,1,1,1,1,1,1,1,1,1,1,1,1,1,1,1,1,1
1,1,1,1,1,1,1,1,1,1,1,1,1,1,4,3,0,0,3,0,1,0,3,0,0,3,2,1,1,1,1,1,1,1,1,1,1,1,1,1,1,1
1,1,1,1,1,1,1,1,1,1,1,1,1,1,3,3,3,0,0,0,1,0,0,0,3,3,3,1,1,1,1,1,1,1,1,1,1,1,1,1,1,1
1,1,1,1,1,1,1,1,1,1,1,1,1,1,3,3,3,0,0,0,1,0,0,0,3,3,3,1,1,1,1,1,1,1,1,1,1,1,1,1,1,1
1,1,1,1,1,1,1,1,1,1,1,1,1,1,4,3,0,0,3,0,1,0,3,0,0,3,2,1,1,1,1,1,1,1,1,1,1,1,1,1,1,1
1,1,1,1,1,1,1,1,1,1,1,1,1,1,1,1,1,3,0,3,1,3,0,3,1,1,1,1,1,1,1,1,1,1,1,1,1,1,1,1,1,1
1,1,1,1,1,1,1,1,1,1,1,1,1,1,1,1,1,1,1,1,1,1,1,1,1,1,1,1,1,1,1,1,1,1,1,1,1,1,1,1,1,1
1,1,1,1,1,1,1,1,1,1,1,1,1,1,1,1,1,1,1,1,1,1,1,1,1,1,1,1,1,1,1,1,1,1,1,1,1,1,1,1,1,1
endlayer

layer
1,1,1,1,1,1,1,1,1,1,1,1,1,1,1,1,1,1,1,1,1,1,1,1,1,1,1,1,1,1,1,1,1,1,1,1,1,1,1,1,1,1
1,1,1,1,1,1,1,1,1,1,1,1,1,1,1,1,1,1,1,1,1,1,1,1,1,1,1,1,1,1,1,1,1,1,1,1,1,1,1,1,1,1
1,1,1,1,1,1,1,1,1,1,1,1,1,1,1,1,1,3,3,2,1,4,3,3,1,1,1,1,1,1,1,1,1,1,1,1,1,1,1,1,1,1
1,1,1,1,1,1,1,1,1,1,1,1,1,1,1,3,0,0,3,3,1,3,3,0,0,3,1,1,1,1,1,1,1,1,1,1,1,1,1,1,1,1
1,1,1,1,1,1,1,1,1,1,1,1,1,1,4,3,3,0,3,0,1,0,3,0,3,3,2,1,1,1,1,1,1,1,1,1,1,1,1,1,1,1
1,1,1,1,1,1,1,1,1,1,1,1,1,1,4,3,3,0,3,0,1,0,3,0,3,3,2,1,1,1,1,1,1,1,1,1,1,1,1,1,1,1
1,1,1,1,1,1,1,1,1,1,1,1,1,1,1,3,0,0,3,3,1,3,3,0,0,3,1,1,1,1,1,1,1,1,1,1,1,1,1,1,1,1
1,1,1,1,1,1,1,1,1,1,1,1,1,1,1,1,1,3,3,2,1,4,3,3,1,1,1,1,1,1,1,1,1,1,1,1,1,1,1,1,1,1
1,1,1,1,1,1,1,1,1,1,1,1,1,1,1,1,1,1,1,1,1,1,1,1,1,1,1,1,1,1,1,1,1,1,1,1,1,1,1,1,1,1
1,1,1,1,1,1,1,1,1,1,1,1,1,1,1,1,1,1,1,1,1,1,1,1,1,1,1,1,1,1,1,1,1,1,1,1,1,1,1,1,1,1
endlayer

layer
1,1,1,1,1,1,1,1,1,1,1,1,1,1,1,1,1,1,1,1,1,1,1,1,1,1,1,1,1,1,1,1,1,1,1,1,1,1,1,1,1,1
1,1,1,1,1,1,1,1,1,1,1,1,1,1,1,1,1,1,1,1,1,1,1,1,1,1,1,1,1,1,1,1,1,1,1,1,1,1,1,1,1,1
1,1,1,1,1,1,1,1,1,1,1,1,1,1,1,1,1,5,5,1,1,1,5,5,1,1,1,1,1,1,1,1,1,1,1,1,1,1,1,1,1,1
1,1,1,1,1,1,1,1,1,1,1,1,1,1,1,4,3,3,3,3,1,3,3,3,3,2,1,1,1,1,1,1,1,1,1,1,1,1,1,1,1,1
1,1,1,1,1,1,1,1,1,1,1,1,1,1,1,3,3,0,0,0,1,0,0,0,3,3,1,1,1,1,1,1,1,1,1,1,1,1,1,1,1,1
1,1,1,1,1,1,1,1,1,1,1,1,1,1,1,3,3,0,0,0,1,0,0,0,3,3,1,1,1,1,1,1,1,1,1,1,1,1,1,1,1,1
1,1,1,1,1,1,1,1,1,1,1,1,1,1,1,4,3,3,3,3,1,3,3,3,3,2,1,1,1,1,1,1,1,1,1,1,1,1,1,1,1,1
1,1,1,1,1,1,1,1,1,1,1,1,1,1,1,1,1,5,5,1,1,1,5,5,1,1,1,1,1,1,1,1,1,1,1,1,1,1,1,1,1,1
1,1,1,1,1,1,1,1,1,1,1,1,1,1,1,1,1,1,1,1,1,1,1,1,1,1,1,1,1,1,1,1,1,1,1,1,1,1,1,1,1,1
1,1,1,1,1,1,1,1,1,1,1,1,1,1,1,1,1,1,1,1,1,1,1,1,1,1,1,1,1,1,1,1,1,1,1,1,1,1,1,1,1,1
endlayer

layer
1,1,1,1,1,1,1,1,1,1,1,1,1,1,1,1,1,1,1,1,1,1,1,1,1,1,1,1,1,1,1,1,1,1,1,1,1,1,1,1,1,1
1,1,1,1,1,1,1,1,1,1,1,1,1,1,1,1,1,1,1,1,1,1,1,1,1,1,1,1,1,1,1,1,1,1,1,1,1,1,1,1,1,1
1,1,1,1,1,1,1,1,1,1,1,1,1,1,1,1,1,1,1,1,1,1,1,1,1,1,1,1,1,1,1,1,1,1,1,1,1,1,1,1,1,1
1,1,1,1,1,1,1,1,1,1,1,1,1,1,1,1,3,0,3,3,1,3,3,0,3,1,1,1,1,1,1,1,1,1,1,1,1,1,1,1,1,1
1,1,1,1,1,1,1,1,1,1,1,1,1,1,1,1,3,0,0,3,1,3,0,0,3,0,1,1,1,1,1,1,1,1,1,1,1,1,1,1,1,1
1,1,1,1,1,1,1,1,1,1,1,1,1,1,1,1,3,0,0,3,1,3,0,0,3,0,1,1,1,1,1,1,1,1,1,1,1,1,1,1,1,1
1,1,1,1,1,1,1,1,1,1,1,1,1,1,1,1,3,0,3,3,1,3,3,0,3,1,1,1,1,1,1,1,1,1,1,1,1,1,1,1,1,1
1,1,1,1,1,1,1,1,1,1,1,1,1,1,1,1,1,1,1,1,1,1,1,1,1,1,1,1,1,1,1,1,1,1,1,1,1,1,1,1,1,1
1,1,1,1,1,1,1,1,1,1,1,1,1,1,1,1,1,1,1,1,1,1,1,1,1,1,1,1,1,1,1,1,1,1,1,1,1,1,1,1,1,1
1,1,1,1,1,1,1,1,1,1,1,1,1,1,1,1,1,1,1,1,1,1,1,1,1,1,1,1,1,1,1,1,1,1,1,1,1,1,1,1,1,1
endlayer

layer
1,1,1,1,1,1,1,1,1,1,1,1,1,1,1,1,1,1,1,1,1,1,1,1,1,1,1,1,1,1,1,1,1,1,1,1,1,1,1,1,1,1
1,1,1,1,1,1,1,1,1,1,1,1,1,1,1,1,1,1,1,1,1,1,1,1,1,1,1,1,1,1,1,1,1,1,1,1,1,1,1,1,1,1
1,1,1,1,1,1,1,1,1,1,1,1,1,1,1,1,1,1,1,1,1,1,1,1,1,1,1,1,1,1,1,1,1,1,1,1,1,1,1,1,1,1
1,1,1,1,1,1,1,1,1,1,1,1,1,1,1,1,0,0,0,3,1,3,0,0,1,1,1,1,1,1,1,1,1,1,1,1,1,1,1,1,1,1
1,1,1,1,1,1,1,1,1,1,1,1,1,1,1,3,3,3,0,3,1,3,0,3,3,3,1,1,1,1,1,1,1,1,1,1,1,1,1,1,1,1
1,1,1,1,1,1,1,1,1,1,1,1,1,1,1,3,3,3,0,3,1,3,0,3,3,3,1,1,1,1,1,1,1,1,1,1,1,1,1,1,1,1
1,1,1,1,1,1,1,1,1,1,1,1,1,1,1,1,0,0,0,3,1,3,0,0,0,1,1,1,1,1,1,1,1,1,1,1,1,1,1,1,1,1
1,1,1,1,1,1,1,1,1,1,1,1,1,1,1,1,1,1,1,1,1,1,1,1,1,1,1,1,1,1,1,1,1,1,1,1,1,1,1,1,1,1
1,1,1,1,1,1,1,1,1,1,1,1,1,1,1,1,1,1,1,1,1,1,1,1,1,1,1,1,1,1,1,1,1,1,1,1,1,1,1,1,1,1
1,1,1,1,1,1,1,1,1,1,1,1,1,1,1,1,1,1,1,1,1,1,1,1,1,1,1,1,1,1,1,1,1,1,1,1,1,1,1,1,1,1
endlayer

layer
1,1,1,1,1,1,1,1,1,1,1,1,1,1,1,1,1,1,1,1,1,1,1,1,1,1,1,1,1,1,1,1,1,1,1,1,1,1,1,1,1,1
1,1,1,1,1,1,1,1,1,1,1,1,1,1,1,1,1,1,1,1,1,1,1,1,1,1,1,1,1,1,1,1,1,1,1,1,1,1,1,1,1,1
1,1,1,1,1,1,1,1,1,1,1,1,1,1,1,1,1,1,1,1,1,1,1,1,1,1,1,1,1,1,1,1,1,1,1,1,1,1,1,1,1,1
1,1,1,1,1,1,1,1,1,1,1,1,1,1,1,1,3,3,0,3,1,3,0,3,3,1,1,1,1,1,1,1,1,1,1,1,1,1,1,1,1,1
1,1,1,1,1,1,1,1,1,1,1,1,1,1,1,4,3,3,0,3,1,3,0,3,3,2,1,1,1,1,1,1,1,1,1,1,1,1,1,1,1,1
1,1,1,1,1,1,1,1,1,1,1,1,1,1,1,4,3,3,0,3,1,3,0,3,3,2,1,1,1,1,1,1,1,1,1,1,1,1,1,1,1,1
1,1,1,1,1,1,1,1,1,1,1,1,1,1,1,1,3,3,0,3,1,3,0,3,3,1,1,1,1,1,1,1,1,1,1,1,1,1,1,1,1,1
1,1,1,1,1,1,1,1,1,1,1,1,1,1,1,1,1,1,1,1,1,1,1,1,1,1,1,1,1,1,1,1,1,1,1,1,1,1,1,1,1,1
1,1,1,1,1,1,1,1,1,1,1,1,1,1,1,1,1,1,1,1,1,1,1,1,1,1,1,1,1,1,1,1,1,1,1,1,1,1,1,1,1,1
1,1,1,1,1,1,1,1,1,1,1,1,1,1,1,1,1,1,1,1,1,1,1,1,1,1,1,1,1,1,1,1,1,1,1,1,1,1,1,1,1,1
endlayer

layer
1,1,1,1,1,1,1,1,1,1,1,1,1,1,1,1,1,1,1,1,1,1,1,1,1,1,1,1,1,1,1,1,1,1,1,1,1,1,1,1,1,1
1,1,1,1,1,1,1,1,1,1,1,1,1,1,1,1,1,1,1,1,1,1,1,1,1,1,1,1,1,1,1,1,1,1,1,1,1,1,1,1,1,1
1,1,1,1,1,1,1,1,1,1,1,1,1,1,1,1,1,1,1,1,1,1,1,1,1,1,1,1,1,1,1,1,1,1,1,1,1,1,1,1,1,1
1,1,1,1,1,1,1,1,1,1,1,1,1,1,1,1,4,3,0,3,1,3,0,3,2,1,1,1,1,1,1,1,1,1,1,1,1,1,1,1,1,1
1,1,1,1,1,1,1,1,1,1,1,1,1,1,1,1,3,3,0,3,1,3,0,3,3,1,1,1,1,1,1,1,1,1,1,1,1,1,1,1,1,1
1,1,1,1,1,1,1,1,1,1,1,1,1,1,1,1,3,3,0,3,1,3,0,3,3,1,1,1,1,1,1,1,1,1,1,1,1,1,1,1,1,1
1,1,1,1,1,1,1,1,1,1,1,1,1,1,1,1,4,3,0,3,1,3,0,3,2,1,1,1,1,1,1,1,1,1,1,1,1,1,1,1,1,1
1,1,1,1,1,1,1,1,1,1,1,1,1,1,1,1,1,1,1,1,1,1,1,1,1,1,1,1,1,1,1,1,1,1,1,1,1,1,1,1,1,1
1,1,1,1,1,1,1,1,1,1,1,1,1,1,1,1,1,1,1,1,1,1,1,1,1,1,1,1,1,1,1,1,1,1,1,1,1,1,1,1,1,1
1,1,1,1,1,1,1,1,1,1,1,1,1,1,1,1,1,1,1,1,1,1,1,1,1,1,1,1,1,1,1,1,1,1,1,1,1,1,1,1,1,1
endlayer

layer
1,1,1,1,1,1,1,1,1,1,1,1,1,1,1,1,1,1,1,1,1,1,1,1,1,1,1,1,1,1,1,1,1,1,1,1,1,1,1,1,1,1
1,1,1,1,1,1,1,1,1,1,1,1,1,1,1,1,1,1,1,1,1,1,1,1,1,1,1,1,1,1,1,1,1,1,1,1,1,1,1,1,1,1
1,1,1,1,1,1,1,1,1,1,1,1,1,1,1,1,1,1,1,1,1,1,1,1,1,1,1,1,1,1,1,1,1,1,1,1,1,1,1,1,1,1
1,1,1,1,1,1,1,1,1,1,1,1,1,1,1,1,1,3,0,3,1,3,0,3,1,1,1,1,1,1,1,1,1,1,1,1,1,1,1,1,1,1
1,1,1,1,1,1,1,1,1,1,1,1,1,1,1,1,4,3,0,3,1,3,0,3,2,1,1,1,1,1,1,1,1,1,1,1,1,1,1,1,1,1
1,1,1,1,1,1,1,1,1,1,1,1,1,1,1,1,4,3,0,3,1,3,0,3,2,1,1,1,1,1,1,1,1,1,1,1,1,1,1,1,1,1
1,1,1,1,1,1,1,1,1,1,1,1,1,1,1,1,1,3,0,3,1,3,0,3,1,1,1,1,1,1,1,1,1,1,1,1,1,1,1,1,1,1
1,1,1,1,1,1,1,1,1,1,1,1,1,1,1,1,1,1,1,1,1,1,1,1,1,1,1,1,1,1,1,1,1,1,1,1,1,1,1,1,1,1
1,1,1,1,1,1,1,1,1,1,1,1,1,1,1,1,1,1,1,1,1,1,1,1,1,1,1,1,1,1,1,1,1,1,1,1,1,1,1,1,1,1
1,1,1,1,1,1,1,1,1,1,1,1,1,1,1,1,1,1,1,1,1,1,1,1,1,1,1,1,1,1,1,1,1,1,1,1,1,1,1,1,1,1
endlayer

layer
1,1,1,1,1,1,1,1,1,1,1,1,1,1,1,1,1,1,1,1,1,1,1,1,1,1,1,1,1,1,1,1,1,1,1,1,1,1,1,1,1,1
1,1,1,1,1,1,1,1,1,1,1,1,1,1,1,1,1,1,1,1,1,1,1,1,1,1,1,1,1,1,1,1,1,1,1,1,1,1,1,1,1,1
1,1,1,1,1,1,1,1,1,1,1,1,1,1,1,1,1,1,1,1,1,1,1,1,1,1,1,1,1,1,1,1,1,1,1,1,1,1,1,1,1,1
1,1,1,1,1,1,1,1,1,1,1,1,1,1,1,1,1,4,3,2,1,4,3,2,1,1,1,1,1,1,1,1,1,1,1,1,1,1,1,1,1,1
1,1,1,1,1,1,1,1,1,1,1,1,1,1,1,1,1,3,3,3,1,3,3,3,1,1,1,1,1,1,1,1,1,1,1,1,1,1,1,1,1,1
1,1,1,1,1,1,1,1,1,1,1,1,1,1,1,1,1,3,3,3,1,3,3,3,1,1,1,1,1,1,1,1,1,1,1,1,1,1,1,1,1,1
1,1,1,1,1,1,1,1,1,1,1,1,1,1,1,1,1,4,3,2,1,4,3,2,1,1,1,1,1,1,1,1,1,1,1,1,1,1,1,1,1,1
1,1,1,1,1,1,1,1,1,1,1,1,1,1,1,1,1,1,1,1,1,1,1,1,1,1,1,1,1,1,1,1,1,1,1,1,1,1,1,1,1,1
1,1,1,1,1,1,1,1,1,1,1,1,1,1,1,1,1,1,1,1,1,1,1,1,1,1,1,1,1,1,1,1,1,1,1,1,1,1,1,1,1,1
1,1,1,1,1,1,1,1,1,1,1,1,1,1,1,1,1,1,1,1,1,1,1,1,1,1,1,1,1,1,1,1,1,1,1,1,1,1,1,1,1,1
endlayer

layer
1,1,1,1,1,1,1,1,1,1,1,1,1,1,1,1,1,1,1,1,1,1,1,1,1,1,1,1,1,1,1,1,1,1,1,1,1,1,1,1,1,1
1,1,1,1,1,1,1,1,1,1,1,1,1,1,1,1,1,1,1,1,1,1,1,1,1,1,1,1,1,1,1,1,1,1,1,1,1,1,1,1,1,1
1,1,1,1,1,1,1,1,1,1,1,1,1,1,1,1,1,1,1,1,1,1,1,1,1,1,1,1,1,1,1,1,1,1,1,1,1,1,1,1,1,1
1,1,1,1,1,1,1,1,1,1,1,1,1,1,1,1,1,1,3,1,1,1,3,1,1,1,1,1,1,1,1,1,1,1,1,1,1,1,1,1,1,1
1,1,1,1,1,1,1,1,1,1,1,1,1,1,1,1,1,1,3,1,1,1,3,1,1,1,1,1,1,1,1,1,1,1,1,1,1,1,1,1,1,1
1,1,1,1,1,1,1,1,1,1,1,1,1,1,1,1,1,1,3,1,1,1,3,1,1,1,1,1,1,1,1,1,1,1,1,1,1,1,1,1,1,1
1,1,1,1,1,1,1,1,1,1,1,1,1,1,1,1,1,1,3,1,1,1,3,1,1,1,1,1,1,1,1,1,1,1,1,1,1,1,1,1,1,1
1,1,1,1,1,1,1,1,1,1,1,1,1,1,1,1,1,1,1,1,1,1,1,1,1,1,1,1,1,1,1,1,1,1,1,1,1,1,1,1,1,1
1,1,1,1,1,1,1,1,1,1,1,1,1,1,1,1,1,1,1,1,1,1,1,1,1,1,1,1,1,1,1,1,1,1,1,1,1,1,1,1,1,1
1,1,1,1,1,1,1,1,1,1,1,1,1,1,1,1,1,1,1,1,1,1,1,1,1,1,1,1,1,1,1,1,1,1,1,1,1,1,1,1,1,1
endlayer

layer
1,1,1,1,1,1,1,1,1,1,1,1,1,1,1,1,1,1,1,1,1,1,1,1,1,1,1,1,1,1,1,1,1,1,1,1,1,1,1,1,1,1
1,1,1,1,1,1,1,1,1,1,1,1,1,1,1,1,1,1,1,1,1,1,1,1,1,1,1,1,1,1,1,1,1,1,1,1,1,1,1,1,1,1
1,1,1,1,1,1,1,1,1,1,1,1,1,1,1,1,1,1,1,1,1,1,1,1,1,1,1,1,1,1,1,1,1,1,1,1,1,1,1,1,1,1
1,1,1,1,1,1,1,1,1,1,1,1,1,1,1,1,1,1,1,1,1,1,1,1,1,1,1,1,1,1,1,1,1,1,1,1,1,1,1,1,1,1
1,1,1,1,1,1,1,1,1,1,1,1,1,1,1,1,1,3,3,3,1,3,3,3,1,1,1,1,1,1,1,1,1,1,1,1,1,1,1,1,1,1
1,1,1,1,1,1,1,1,1,1,1,1,1,1,1,1,1,3,3,3,1,3,3,3,1,1,1,1,1,1,1,1,1,1,1,1,1,1,1,1,1,1
1,1,1,1,1,1,1,1,1,1,1,1,1,1,1,1,1,1,1,1,1,1,0,1,1,1,1,1,1,1,1,1,1,1,1,1,1,1,1,1,1,1
1,1,1,1,1,1,1,1,1,1,1,1,1,1,1,1,1,1,1,1,1,1,1,1,1,1,1,1,1,1,1,1,1,1,1,1,1,1,1,1,1,1
1,1,1,1,1,1,1,1,1,1,1,1,1,1,1,1,1,1,1,1,1,1,1,1,1,1,1,1,1,1,1,1,1,1,1,1,1,1,1,1,1,1
1,1,1,1,1,1,1,1,1,1,1,1,1,1,1,1,1,1,1,1,1,1,1,1,1,1,1,1,1,1,1,1,1,1,1,1,1,1,1,1,1,1
endlayer

layer
0,0,0,0,0,0,0,0,0,0,0,0,0,0,0,0,0,0,0,0,0,0,0,0,0,0,0,0,0,0,0,0,0,0,0,1,1,0,0,0,0,0
0,0,0,0,0,0,0,0,0,0,0,0,0,0,0,0,0,0,0,0,0,0,0,0,0,0,0,0,0,0,0,1,1,1,1,1,1,1,0,0,0,0
0,0,0,0,0,0,0,0,0,0,0,0,0,0,0,0,0,0,0,0,0,0,0,0,0,0,0,0,1,1,1,1,1,1,1,1,1,1,0,0,0,0
0,0,0,0,0,0,0,0,0,0,0,0,0,0,0,0,0,0,3,3,0,3,3,0,0,1,1,1,1,1,1,1,1,1,1,1,1,1,0,0,0,0
0,0,0,0,0,0,0,0,0,0,0,0,0,0,0,0,0,4,3,3,0,3,3,2,0,0,0,1,1,1,1,1,1,1,1,1,1,1,0,0,0,0
0,0,0,0,0,0,0,0,0,0,0,0,0,0,0,0,0,4,3,3,0,3,3,2,0,0,0,1,1,1,1,1,1,1,1,1,1,1,0,0,0,0
0,0,0,0,0,0,0,0,0,0,0,0,0,0,0,0,0,0,3,3,0,3,3,0,0,0,0,0,1,1,1,1,1,1,1,1,1,0,0,0,0,0
0,0,0,0,0,0,0,0,0,0,0,0,0,0,0,0,0,0,0,0,0,0,0,0,0,0,0,0,0,1,1,1,1,1,1,1,1,0,0,0,0,0
0,0,0,0,0,0,0,0,0,0,0,0,0,0,0,0,0,0,0,0,0,0,0,0,0,0,0,0,1,1,1,1,1,1,1,1,0,0,0,0,0,0
0,0,0,0,0,0,0,0,0,0,0,0,0,0,0,0,0,0,0,0,0,0,0,0,0,0,0,0,0,0,0,0,0,0,0,0,0,0,0,0,0,0
endlayer

layer
0,0,0,0,0,0,0,0,0,0,0,0,0,0,0,0,0,0,0,0,0,0,0,0,0,0,0,0,0,0,0,0,0,0,0,0,0,0,0,0,0,0
0,0,0,0,0,0,0,0,0,0,0,0,0,0,0,0,0,0,0,0,0,0,0,0,0,0,0,0,0,0,0,0,0,0,0,0,0,0,0,0,0,0
0,0,0,0,0,0,0,0,0,0,0,0,0,0,0,0,0,0,0,0,0,0,0,0,0,0,0,0,0,0,0,0,0,0,0,0,0,0,0,0,0,0
0,0,0,0,0,0,0,0,0,0,0,0,0,0,0,0,0,0,4,3,0,3,2,0,0,0,0,0,0,0,1,1,1,1,1,1,1,0,0,0,0,0
0,0,0,0,0,0,0,0,0,0,0,0,0,0,0,0,0,0,3,3,0,3,3,0,0,0,0,0,0,0,0,1,1,1,1,1,0,0,0,0,0,0
0,0,0,0,0,0,0,0,0,0,0,0,0,0,0,0,0,0,3,3,0,3,3,0,0,0,0,0,0,0,0,1,1,1,1,0,0,0,0,0,0,0
0,0,0,0,0,0,0,0,0,0,0,0,0,0,0,0,0,0,4,3,0,3,2,0,0,0,0,0,0,0,0,1,1,1,1,0,0,0,0,0,0,0
0,0,0,0,0,0,0,0,0,0,0,0,0,0,0,0,0,0,0,0,0,0,0,0,0,0,0,0,0,0,0,1,1,1,0,0,0,0,0,0,0,0
0,0,0,0,0,0,0,0,0,0,0,0,0,0,0,0,0,0,0,0,0,0,0,0,0,0,0,0,0,0,0,0,1,0,0,0,0,0,0,0,0,0
0,0,0,0,0,0,0,0,0,0,0,0,0,0,0,0,0,0,0,0,0,0,0,0,0,0,0,0,0,0,0,0,0,0,0,0,0,0,0,0,0,0
endlayer

