biomesToSpawnIn=kelp forest,ocean,ocean oil field,oceanic abyss,coral reef,desert
weight=1
embed_into_distance=23
acceptable_target_blocks=1,2,3,12,13,250
dimensions=28,12,12
allowable_overhang=0
max_cut_in=0
cut_in_buffer=0
max_leveling=0
leveling_buffer=0
preserve_water=0
preserve_lava=0
preserve_plants=0


rule1=0,100,250
rule2=0,100,2780-1,2780-2,2780-3,2780-4,2780-5,2780-6,2780-7,2780-8,2780-9,2780-10,2780-11,2780-12,2780-13,2780-14,2780-15,2789-3,2789-3,2789-3,2789-3,2789-3,2789-3,2789-8,2789-8,0,0
rule3=0,100,159-15
rule4=0,100,159-14
rule5=0,100,128-2,128-2,128-2,128-2,0
rule6=0,100,128,128,128,128,0
rule7=0,100,128-1,128-1,128-1,128-1,0
rule8=0,100,128-3,128-3,128-3,128-3,0


layer
1,1,1,1,1,1,1,1,1,1,1,1
1,0,0,0,0,0,0,0,0,0,0,1
1,0,0,0,0,0,0,0,0,0,0,1
1,0,0,0,0,0,0,0,0,0,0,1
1,0,0,0,0,0,0,0,0,0,0,1
1,0,0,0,0,0,0,0,0,0,0,1
1,0,0,0,0,0,0,0,0,0,0,1
1,0,0,0,0,0,0,0,0,0,0,1
1,0,0,0,0,0,0,0,0,0,0,1
1,0,0,0,0,0,0,0,0,0,0,1
1,0,0,0,0,0,0,0,0,0,0,1
1,1,1,1,1,1,1,1,1,1,1,1
endlayer

layer
1,1,1,1,1,1,1,1,1,1,1,1
1,0,0,0,0,0,0,0,0,0,0,1
1,0,0,0,0,0,0,0,0,0,0,1
1,0,0,0,0,0,0,0,0,0,0,1
1,0,0,0,0,0,0,0,0,0,0,1
1,0,0,0,0,0,0,0,0,0,0,1
1,0,0,0,0,0,0,0,0,0,0,1
1,0,0,0,0,0,0,0,0,0,0,1
1,0,0,0,0,0,0,0,0,0,0,1
1,0,0,0,0,0,0,0,0,0,0,1
1,0,0,0,0,0,0,0,0,0,0,1
1,1,1,1,1,1,1,1,1,1,1,1
endlayer

layer
1,1,1,1,1,1,1,1,1,1,1,1
1,0,0,0,0,0,0,0,0,0,0,1
1,0,0,0,0,0,0,0,0,0,0,1
1,0,0,0,0,0,0,0,0,0,0,1
1,0,0,0,0,0,0,0,0,0,0,1
1,0,0,0,0,0,0,0,0,0,0,1
1,0,0,0,0,0,0,0,0,0,0,1
1,0,0,0,0,0,0,0,0,0,0,1
1,0,0,0,0,0,0,0,0,0,0,1
1,0,0,0,0,0,0,0,0,0,0,1
1,0,0,0,0,0,0,0,0,0,0,1
1,1,1,1,1,1,1,1,1,1,1,1
endlayer

layer
1,1,1,1,1,1,1,1,1,1,1,1
1,0,0,0,0,0,0,0,0,0,0,1
1,0,0,0,0,0,0,0,0,0,0,1
1,0,0,0,0,0,0,0,0,0,0,1
1,0,0,0,0,0,0,0,0,0,0,1
1,0,0,0,0,0,0,0,0,0,0,1
1,0,0,0,0,0,0,0,0,0,0,1
1,0,0,0,0,0,0,0,0,0,0,1
1,0,0,0,0,0,0,0,0,0,0,1
1,0,0,0,0,0,0,0,0,0,0,1
1,0,0,0,0,0,0,0,0,0,0,1
1,1,1,1,1,1,1,1,1,1,1,1
endlayer

layer
1,1,1,1,1,1,1,1,1,1,1,1
1,0,0,0,0,0,0,0,0,0,0,1
1,0,0,0,0,0,0,0,0,0,0,1
1,0,0,0,0,0,0,0,0,0,0,1
1,0,0,0,0,0,0,0,0,0,0,1
1,0,0,0,0,0,0,0,0,0,0,1
1,0,0,0,0,0,0,0,0,0,0,1
1,0,0,0,0,0,0,0,0,0,0,1
1,0,0,0,0,0,0,0,0,0,0,1
1,0,0,0,0,0,0,0,0,0,0,1
1,0,0,0,0,0,0,0,0,0,0,1
1,1,1,1,1,1,1,1,1,1,1,1
endlayer

layer
1,1,1,1,1,1,1,1,1,1,1,1
1,0,2,2,2,2,2,2,2,2,0,1
1,2,2,2,2,2,2,2,2,2,2,1
1,2,2,2,2,2,2,2,2,2,2,1
1,2,2,2,2,2,2,2,2,2,2,1
1,2,2,2,2,2,2,2,2,2,2,1
1,2,2,2,2,3,2,2,2,2,2,1
1,2,2,2,2,2,2,2,2,2,2,1
1,2,2,2,2,2,2,2,2,2,2,1
1,2,2,2,2,2,2,2,2,2,2,1
1,0,2,2,2,2,2,2,2,2,2,1
1,1,1,1,1,1,1,1,1,1,1,1
endlayer

layer
1,1,1,1,1,1,1,1,1,1,1,1
1,0,2,2,0,0,0,0,2,2,0,1
1,2,4,0,0,0,0,0,0,0,2,1
1,2,0,0,0,0,0,0,0,0,2,1
1,0,0,0,0,0,0,0,0,0,0,1
1,0,0,0,0,0,0,0,0,0,0,1
1,0,0,0,0,0,0,0,0,0,0,1
1,0,0,0,0,0,0,0,0,0,0,1
1,2,0,0,0,0,0,0,0,0,2,1
1,2,0,0,0,0,0,0,0,0,2,1
1,0,2,2,0,0,0,0,2,2,0,1
1,1,1,1,1,1,1,1,1,1,1,1
endlayer

layer
1,1,1,1,1,1,1,1,1,1,1,1
1,2,0,6,0,0,0,0,6,0,2,1
1,0,2,2,2,0,0,2,2,2,0,1
1,8,2,0,0,0,0,0,0,2,5,1
1,0,2,0,0,0,0,0,0,2,0,1
1,0,0,0,0,0,0,0,0,0,0,1
1,0,0,0,0,0,0,0,0,0,0,1
1,0,2,0,0,0,0,0,0,2,0,1
1,8,2,0,0,0,0,0,0,2,5,1
1,0,2,2,2,0,0,2,2,2,0,1
1,2,0,7,0,0,0,0,7,0,2,1
1,1,1,1,1,1,1,1,1,1,1,1
endlayer

layer
1,1,1,1,1,1,1,1,1,1,1,1
1,0,2,0,0,0,0,0,0,2,0,1
1,2,2,2,2,0,0,2,2,2,2,1
1,0,2,2,0,0,0,0,2,2,0,1
1,0,2,0,2,0,0,2,0,2,0,1
1,0,0,0,0,0,0,0,0,0,0,1
1,0,0,0,0,0,0,0,0,0,0,1
1,0,2,0,2,0,0,2,0,2,0,1
1,0,2,2,0,0,0,0,2,2,0,1
1,2,2,2,2,0,0,2,2,2,2,1
1,0,2,0,0,0,0,0,0,2,0,1
1,1,1,1,1,1,1,1,1,1,1,1
endlayer

layer
1,1,1,1,1,1,1,1,1,1,1,1
1,2,0,0,0,0,0,0,0,0,2,1
1,0,2,2,0,0,0,0,2,2,0,1
1,0,2,2,2,0,0,2,2,2,0,1
1,0,0,2,0,0,0,0,2,0,0,1
1,0,0,0,0,0,0,0,0,0,0,1
1,0,0,0,0,0,0,0,0,0,0,1
1,0,0,2,0,0,0,0,2,0,0,1
1,0,2,2,2,0,0,2,2,2,0,1
1,0,2,2,2,0,0,0,2,2,0,1
1,2,0,0,0,0,0,0,0,0,2,1
1,1,1,1,1,1,1,1,1,1,1,1
endlayer

layer
1,1,1,1,1,1,1,1,1,1,1,1
1,8,2,2,0,0,0,0,2,2,5,1
1,2,2,0,2,0,0,2,0,2,2,1
1,2,0,2,2,0,0,2,2,0,2,1
1,0,2,2,0,2,2,0,2,2,0,1
1,0,0,2,2,0,0,2,0,0,0,1
1,0,0,2,2,0,0,2,0,0,0,1
1,0,2,2,0,2,2,0,2,2,0,1
1,2,0,2,2,0,0,2,2,0,2,1
1,2,2,0,0,0,0,2,0,2,2,1
1,8,2,2,0,0,0,0,2,2,5,1
1,1,1,1,1,1,1,1,1,1,1,1
endlayer

layer
1,1,2,2,2,1,1,1,1,1,1,1
1,1,2,2,2,0,0,0,2,5,1,1
1,8,2,2,2,0,0,0,2,2,5,1
1,2,2,2,2,2,2,0,0,2,2,1
1,0,2,2,2,2,2,0,0,0,0,1
1,0,2,2,2,0,0,2,2,0,0,1
1,0,2,2,2,0,0,2,2,0,0,1
1,0,0,0,0,2,2,0,0,0,0,1
1,2,2,0,0,2,2,0,0,2,2,1
1,8,2,2,0,0,0,0,2,2,5,1
1,1,8,2,0,0,0,0,2,5,1,1
1,1,1,1,1,1,1,1,1,1,1,1
endlayer

layer
1,1,2,2,2,1,1,1,1,1,1,1
1,1,2,2,2,0,0,2,5,1,1,1
1,1,2,2,2,0,2,2,2,2,1,1
1,8,2,2,2,2,2,2,2,2,5,1
1,2,2,2,2,2,2,2,2,2,2,1
1,0,2,2,2,3,2,2,2,2,0,1
1,0,2,2,2,2,2,2,2,2,0,1
1,2,2,2,2,2,2,2,2,2,2,1
1,8,2,2,2,2,2,2,2,2,5,1
1,1,2,2,2,0,2,2,2,2,1,1
1,1,1,8,2,0,0,2,5,1,1,1
1,1,1,1,1,1,1,1,1,1,1,1
endlayer

layer
1,1,2,2,2,1,1,1,1,1,1,1
1,1,2,2,2,0,0,2,1,1,1,1
1,1,2,2,2,0,0,0,2,0,1,1
1,1,2,0,0,0,0,0,0,2,1,1
1,2,0,0,0,0,0,0,0,0,2,1
1,0,0,0,0,0,0,0,0,0,0,1
1,0,0,0,0,0,0,0,0,0,0,1
1,2,0,0,0,0,0,0,0,0,2,1
1,1,2,0,0,0,0,0,0,2,1,1
1,1,0,2,0,0,0,0,2,1,1,1
1,1,1,1,2,0,0,2,1,1,1,1
1,1,1,1,1,1,1,1,1,1,1,1
endlayer

layer
1,1,2,2,2,2,2,1,1,1,1,1
1,1,2,2,2,2,2,1,1,1,1,1
1,1,2,2,2,0,0,0,2,0,1,1
1,1,2,0,0,0,0,0,0,2,1,1
1,0,0,0,0,0,0,0,0,0,0,1
2,2,0,0,0,0,0,0,0,0,2,2
2,2,0,0,0,0,0,0,0,0,2,2
1,0,0,0,0,0,0,0,0,0,1,1
1,1,2,0,0,0,0,0,0,2,1,1
1,1,0,2,0,0,0,0,2,1,1,1
1,1,1,1,0,2,2,0,1,1,1,1
1,1,1,1,1,2,2,1,1,1,1,1
endlayer

layer
1,1,2,2,2,6,6,1,1,1,1,1
1,1,2,2,2,2,2,2,1,1,1,1
1,1,2,2,2,2,2,0,2,0,1,1
1,1,2,0,0,2,2,0,0,2,1,1
1,2,0,0,2,2,2,2,0,0,2,1
8,2,2,2,2,0,0,2,2,2,2,5
8,2,2,2,2,0,0,2,2,2,2,5
1,2,0,0,2,2,2,2,0,0,2,1
1,1,2,0,0,2,2,0,0,2,1,1
1,1,0,2,0,2,2,0,2,1,1,1
1,1,1,1,2,2,2,2,1,1,1,1
1,1,1,1,1,7,7,1,1,1,1,1
endlayer

layer
1,1,1,1,1,1,1,1,1,1,1,1
1,1,1,1,6,6,6,6,1,1,1,1
1,1,0,2,2,2,2,2,2,0,1,1
1,1,2,0,0,2,2,0,0,2,1,1
1,8,2,0,2,0,0,2,0,2,5,1
1,8,2,2,0,0,0,0,2,2,5,1
1,8,2,2,0,0,0,0,2,2,5,1
1,8,2,0,2,0,0,2,0,2,5,1
1,1,2,0,0,2,2,0,0,2,1,1
1,1,0,2,2,2,2,2,2,1,1,1
1,1,1,1,7,7,7,7,1,1,1,1
1,1,1,1,1,1,1,1,1,1,1,1
endlayer

layer
1,1,1,1,1,1,1,1,1,1,1,1
1,1,1,1,1,1,1,1,1,1,1,1
1,1,2,0,8,2,2,5,0,2,1,1
1,1,0,2,2,0,0,2,2,0,1,1
1,1,8,2,0,0,0,0,2,5,1,1
1,1,2,0,0,0,0,0,0,2,1,1
1,1,2,0,0,0,0,0,0,2,1,1
1,1,8,2,0,0,0,0,2,5,1,1
1,1,0,2,2,0,0,2,2,0,1,1
1,1,2,0,8,2,2,5,1,2,1,1
1,1,1,1,1,0,0,1,1,1,1,1
1,1,1,1,1,1,1,1,1,1,1,1
endlayer

layer
1,1,1,1,1,1,1,1,1,1,1,1
1,1,1,1,1,2,2,1,1,1,1,1
1,1,8,2,0,3,0,0,2,5,1,1
1,1,2,2,2,0,0,2,2,2,1,1
1,1,0,2,2,0,0,2,2,0,1,1
1,2,0,0,0,0,0,0,0,0,2,1
1,2,0,0,0,0,0,0,0,0,2,1
1,1,0,2,2,0,0,2,2,0,1,1
1,1,2,2,2,0,0,2,2,2,1,1
1,1,8,2,0,0,0,1,2,5,1,1
1,1,1,1,1,2,2,1,1,1,1,1
1,1,1,1,1,1,1,1,1,1,1,1
endlayer

layer
1,1,1,1,1,1,1,1,1,1,1,1
1,1,1,1,1,6,6,1,1,1,1,1
1,1,1,8,2,2,2,2,5,1,1,1
1,1,8,2,2,0,0,2,2,5,1,1
1,1,2,2,0,0,0,0,2,2,1,1
1,8,2,0,0,0,0,0,0,2,5,1
1,8,2,0,0,0,0,0,0,2,5,1
1,1,2,2,0,0,0,0,2,2,1,1
1,1,8,2,2,0,0,2,2,5,1,1
1,1,1,8,2,2,2,2,5,1,1,1
1,1,1,1,1,7,7,1,1,1,1,1
1,1,1,1,1,1,1,1,1,1,1,1
endlayer

layer
1,1,1,1,1,1,1,1,1,1,1,1
1,1,1,1,1,1,1,1,1,1,1,1
1,1,1,1,8,2,2,5,1,1,1,1
1,1,1,2,2,0,0,2,2,1,1,1
1,1,8,2,0,2,2,0,2,5,1,1
1,1,2,0,2,0,0,2,0,2,1,1
1,1,2,0,2,0,0,2,0,2,1,1
1,1,8,2,0,2,2,0,2,5,1,1
1,1,1,2,2,0,0,2,2,1,1,1
1,1,1,1,8,2,2,5,1,1,1,1
1,1,1,1,1,1,1,1,1,1,1,1
1,1,1,1,1,1,1,1,1,1,1,1
endlayer

layer
1,1,1,1,1,1,1,1,1,1,1,1
1,1,1,1,1,1,1,1,1,1,1,1
1,1,1,1,1,2,2,1,1,1,1,1
1,1,1,2,2,2,2,2,2,1,1,1
1,1,1,2,0,2,2,0,2,1,1,1
1,1,2,2,2,0,0,2,2,2,1,1
1,1,2,2,2,0,0,2,2,2,1,1
1,1,1,2,0,2,2,0,2,1,1,1
1,1,1,2,2,2,2,2,2,1,1,1
1,1,1,1,1,2,2,1,1,1,1,1
1,1,1,1,1,1,1,1,1,1,1,1
1,1,1,1,1,1,1,1,1,1,1,1
endlayer

layer
1,1,1,1,1,1,1,1,1,1,1,1
1,1,1,1,1,1,1,1,1,1,1,1
1,1,1,1,1,2,2,1,1,1,1,1
1,1,1,2,2,2,2,2,2,1,1,1
1,1,1,2,0,0,0,0,2,1,1,1
1,1,2,2,0,0,0,0,2,2,1,1
1,1,2,2,0,0,0,0,2,2,1,1
1,1,1,2,0,4,0,0,2,1,1,1
1,1,1,2,2,2,2,2,2,1,1,1
1,1,1,1,1,2,2,1,1,1,1,1
1,1,1,1,1,1,1,1,1,1,1,1
1,1,1,1,1,1,1,1,1,1,1,1
endlayer

layer
0,0,0,0,0,0,0,0,0,0,0,0
0,0,0,0,0,0,0,0,0,0,1,0
0,0,1,1,0,6,6,0,0,1,0,0
0,1,1,8,2,2,2,2,5,0,0,0
1,1,1,2,2,2,2,2,2,0,0,0
0,1,8,2,2,0,0,2,2,5,0,0
0,0,8,2,2,0,0,2,2,5,0,0
0,0,0,2,2,2,2,2,2,1,0,0
0,0,0,8,2,2,2,2,5,1,1,0
0,0,0,0,1,7,7,0,1,0,0,0
0,0,0,0,0,0,0,0,0,0,0,0
0,0,0,0,0,0,0,0,0,0,0,0
endlayer

layer
0,0,0,0,0,0,0,0,0,0,0,0
0,0,0,0,0,0,0,0,0,0,0,0
0,0,0,0,0,0,0,0,0,0,0,0
0,0,0,1,8,2,2,5,0,0,0,0
0,1,1,8,2,2,2,2,5,0,0,0
0,0,1,2,2,0,0,2,2,0,0,0
0,0,0,2,2,0,0,2,2,0,0,0
0,0,0,8,2,2,2,2,5,0,0,0
0,0,0,0,8,2,2,5,1,0,0,0
0,0,0,0,0,0,0,0,0,0,0,0
0,0,0,0,0,0,0,0,0,0,0,0
0,0,0,0,0,0,0,0,0,0,0,0
endlayer

layer
0,0,0,0,0,0,0,0,0,0,0,0
0,0,0,0,0,0,0,0,0,0,0,0
0,0,0,0,0,0,0,0,0,0,0,0
0,0,0,0,0,2,2,0,0,0,0,0
0,0,0,1,2,0,0,2,0,0,0,0
0,0,0,2,0,0,0,0,2,0,0,0
0,0,0,2,4,0,0,0,2,0,0,0
0,0,0,0,2,0,0,2,0,0,0,0
0,0,0,0,0,2,2,0,0,0,0,0
0,0,0,0,0,0,0,0,0,0,0,0
0,0,0,0,0,0,0,0,0,0,0,0
0,0,0,0,0,0,0,0,0,0,0,0
endlayer

layer
0,0,0,0,0,0,0,0,0,0,0,0
0,0,0,0,0,0,0,0,0,0,0,0
0,0,0,0,0,0,0,0,0,0,0,0
0,0,0,0,0,6,6,0,0,0,0,0
0,0,0,0,2,2,2,2,0,0,0,0
0,0,0,8,2,0,0,2,5,0,0,0
0,0,0,8,2,0,0,2,5,0,0,0
0,0,0,0,2,2,2,2,0,0,0,0
0,0,0,0,0,7,7,0,0,0,0,0
0,0,0,0,0,0,0,0,0,0,0,0
0,0,0,0,0,0,0,0,0,0,0,0
0,0,0,0,0,0,0,0,0,0,0,0
endlayer

layer
0,0,0,0,0,0,0,0,0,0,0,0
0,0,0,0,0,0,0,0,0,0,0,0
0,0,0,0,0,0,0,0,0,0,0,0
0,0,0,0,0,0,0,0,0,0,0,0
0,0,0,0,8,2,2,5,0,0,0,0
0,0,0,0,2,2,2,2,0,0,0,0
0,0,0,0,2,2,2,2,0,0,0,0
0,0,0,0,8,2,2,5,0,0,0,0
0,0,0,0,0,0,0,0,0,0,0,0
0,0,0,0,0,0,0,0,0,0,0,0
0,0,0,0,0,0,0,0,0,0,0,0
0,0,0,0,0,0,0,0,0,0,0,0
endlayer

