biomesToSpawnIn=kelp forest,ocean,ocean oil field,oceanic abyss,coral reef,desert
weight=1
embed_into_distance=1
acceptable_target_blocks=1,2,3,12,13,250
dimensions=32,13,13
allowable_overhang=0
max_cut_in=2
cut_in_buffer=1
max_leveling=2
leveling_buffer=1
preserve_water=0
preserve_lava=0
preserve_plants=0


rule1=0,100,2762-5,2762-5,2762-5,2762-5,2762-6,2762-6,2762-7,2762,0,0
rule2=0,100,159-14
rule3=0,100,159-15


layer
0,1,1,1,1,1,1,0,1,1,1,0,0
0,0,1,1,1,1,1,1,1,1,1,1,1
0,1,1,1,1,1,1,1,1,1,1,1,1
0,1,1,1,1,1,1,1,1,1,1,1,0
1,1,1,1,1,1,1,1,1,1,1,1,1
1,1,1,1,1,1,1,1,1,1,1,1,0
1,1,1,1,1,1,1,1,1,1,1,1,1
1,1,1,1,1,1,1,1,1,1,1,1,0
1,1,1,1,1,1,1,1,1,1,1,1,1
1,1,1,1,1,1,1,1,1,1,1,1,0
1,1,1,1,1,1,1,1,1,1,1,1,1
0,1,1,1,1,1,1,1,1,1,1,1,1
0,1,1,1,1,0,1,0,1,1,1,1,0
endlayer

layer
0,1,1,1,1,1,1,0,1,0,0,0,0
0,0,1,1,1,1,1,1,1,1,1,0,1
0,1,1,1,1,1,1,1,1,1,1,1,1
0,1,1,1,1,1,1,1,1,1,1,1,0
1,1,1,1,1,1,1,1,1,1,1,1,1
1,1,1,1,1,1,1,1,1,1,1,1,0
1,1,1,1,1,1,1,1,1,1,1,1,1
1,1,1,1,1,1,1,1,1,1,1,1,0
0,1,1,1,1,1,1,1,1,1,1,1,1
0,1,1,1,1,1,1,1,1,1,1,1,0
0,1,1,1,1,1,1,1,1,1,1,1,0
0,1,1,1,1,1,1,1,1,1,1,0,1
0,1,0,1,1,0,0,0,1,1,1,1,0
endlayer

layer
0,1,1,1,0,1,0,0,1,0,0,0,0
0,0,1,1,1,1,1,1,1,1,1,0,1
0,1,1,1,1,1,1,1,1,1,1,1,1
0,1,1,1,1,1,1,1,1,1,1,1,0
0,1,1,1,1,1,1,1,1,1,1,1,1
0,1,1,1,1,1,1,1,1,1,1,1,0
0,1,1,1,1,1,1,1,1,1,1,1,1
1,1,1,1,1,1,1,1,1,1,1,1,0
0,1,1,1,1,1,1,1,1,1,1,1,1
0,1,1,1,1,1,1,1,1,1,1,1,0
0,1,1,1,1,1,1,1,1,1,1,1,0
0,1,1,1,1,1,1,1,1,1,1,0,1
0,0,0,0,1,0,0,0,1,1,0,1,0
endlayer

layer
0,1,0,1,0,1,0,0,1,0,0,0,0
0,0,1,1,1,1,1,1,1,1,1,0,1
0,1,1,1,1,1,1,1,1,1,1,1,1
0,1,1,1,1,1,1,1,1,1,1,1,0
0,1,1,1,1,1,1,1,1,1,1,1,1
0,1,1,1,1,1,1,1,1,1,1,1,0
0,1,1,1,1,1,1,1,1,1,1,1,0
0,1,1,1,1,1,1,1,1,1,1,1,0
0,1,1,1,1,1,1,1,1,1,1,1,1
0,1,1,1,1,1,1,1,1,1,1,1,0
0,1,1,1,1,1,1,1,1,1,1,1,0
0,1,1,1,1,1,1,1,1,1,1,0,1
0,0,0,0,1,0,0,0,1,1,0,1,0
endlayer

layer
0,1,0,1,0,1,0,0,1,0,0,0,0
0,0,1,0,0,1,1,1,1,1,1,0,1
0,1,0,1,1,1,1,1,1,1,1,1,1
0,1,1,1,1,1,1,1,1,1,1,1,0
0,1,1,1,1,1,1,1,1,1,1,1,1
0,0,1,1,1,1,1,1,1,1,1,1,0
0,1,1,1,1,1,1,1,1,1,1,1,0
0,0,1,1,1,1,1,1,1,1,1,1,0
0,1,1,1,1,1,1,1,1,1,1,1,1
0,1,1,1,1,1,1,1,1,1,1,1,0
0,1,1,1,1,1,1,1,1,1,1,0,0
0,1,1,1,0,1,1,1,1,1,1,0,1
0,0,0,0,1,0,0,0,1,1,0,1,0
endlayer

layer
0,0,0,0,0,0,0,0,0,0,0,0,0
0,0,1,0,0,1,1,1,1,0,0,0,0
0,1,0,1,1,1,1,1,1,1,1,1,0
0,1,1,1,1,1,1,1,1,1,1,1,0
0,0,1,1,1,1,1,1,1,1,1,1,0
0,0,1,1,1,1,1,1,1,1,1,1,0
0,1,1,1,1,1,1,1,1,1,1,1,0
0,0,1,1,1,1,1,1,1,1,1,1,0
0,1,1,1,1,1,1,1,1,1,1,1,0
0,1,1,1,1,1,1,1,1,1,1,0,0
0,0,0,1,1,1,1,1,1,1,1,0,0
0,0,1,1,0,1,1,0,1,0,0,0,0
0,0,0,0,0,0,0,0,0,0,0,0,0
endlayer

layer
0,0,0,0,0,0,0,0,0,0,0,0,0
0,0,0,0,0,1,1,0,0,0,0,0,0
0,1,0,1,1,1,1,1,1,1,1,1,0
0,1,1,1,1,1,1,1,1,1,1,1,0
0,0,1,1,1,1,1,1,1,1,1,0,0
0,0,1,1,1,1,1,1,1,1,1,0,0
0,1,1,1,1,1,1,1,1,1,1,0,0
0,0,1,1,1,1,1,1,1,1,1,1,0
0,1,1,1,1,1,1,1,1,1,1,1,0
0,1,1,1,1,1,1,1,1,0,1,0,0
0,0,0,1,1,1,1,1,1,1,1,0,0
0,0,1,1,0,1,0,0,1,0,0,0,0
0,0,0,0,0,0,0,0,0,0,0,0,0
endlayer

layer
0,0,0,0,0,0,0,0,0,0,0,0,0
0,0,0,0,0,0,0,0,0,0,0,0,0
0,1,0,1,1,1,1,1,1,1,1,1,0
0,1,1,1,1,1,1,1,1,1,1,1,0
0,0,1,1,1,1,1,1,1,1,1,0,0
0,0,1,1,1,1,1,1,1,1,1,0,0
0,0,1,1,1,1,1,1,1,1,1,0,0
0,0,1,1,1,1,1,1,1,1,1,1,0
0,0,1,1,1,1,1,1,1,1,1,1,0
0,1,1,1,1,1,1,1,1,1,1,0,0
0,0,0,1,1,1,1,1,1,1,1,0,0
0,0,1,1,0,1,0,0,0,0,0,0,0
0,0,0,0,0,0,0,0,0,0,0,0,0
endlayer

layer
0,0,0,0,0,0,0,0,0,0,0,0,0
0,0,0,0,0,0,0,0,0,0,0,0,0
0,0,0,1,1,1,1,1,1,1,1,1,0
0,1,1,1,1,1,1,1,1,1,1,1,0
0,0,1,1,1,1,1,1,1,1,1,0,0
0,0,1,1,1,1,1,1,1,1,1,0,0
0,0,1,1,1,1,1,1,1,1,1,0,0
0,0,1,1,1,1,1,1,1,1,1,1,0
0,0,1,1,1,1,1,1,1,1,1,1,0
0,1,1,1,1,1,1,1,1,1,1,0,0
0,0,0,1,1,1,1,1,1,1,1,0,0
0,0,1,1,0,1,0,0,0,0,0,0,0
0,0,0,0,0,0,0,0,0,0,0,0,0
endlayer

layer
0,0,0,0,0,0,0,0,0,0,0,0,0
0,0,0,0,0,0,0,0,0,0,0,0,0
0,0,0,0,1,1,1,1,1,1,1,1,0
0,1,0,1,1,1,1,1,1,1,1,0,0
0,0,1,1,1,1,1,1,1,1,0,0,0
0,0,0,1,1,1,1,1,1,1,1,0,0
0,0,1,1,1,1,1,1,1,1,1,0,0
0,0,1,1,1,1,1,1,1,1,1,0,0
0,0,1,1,1,1,1,1,1,1,1,1,0
0,1,1,1,1,1,1,1,1,1,1,0,0
0,0,0,1,1,1,1,1,1,1,1,0,0
0,0,1,1,0,1,0,0,0,0,0,0,0
0,0,0,0,0,0,0,0,0,0,0,0,0
endlayer

layer
0,0,0,0,0,0,0,0,0,0,0,0,0
0,0,0,0,0,0,0,0,0,0,0,0,0
0,0,0,0,1,0,1,1,1,1,0,0,0
0,0,0,1,1,1,1,1,1,1,1,0,0
0,0,0,1,1,1,1,1,1,1,0,0,0
0,0,0,1,1,1,1,1,1,1,1,0,0
0,0,1,1,1,1,1,1,1,1,0,0,0
0,0,0,1,1,1,1,1,1,1,1,0,0
0,0,0,1,1,1,1,1,1,1,1,0,0
0,0,1,1,1,1,1,1,1,1,0,0,0
0,0,0,0,0,0,1,0,1,0,0,0,0
0,0,0,0,0,0,0,0,0,0,0,0,0
0,0,0,0,0,0,0,0,0,0,0,0,0
endlayer

layer
0,0,0,0,0,0,0,0,0,0,0,0,0
0,0,0,0,0,0,0,0,0,0,0,0,0
0,0,0,0,1,0,0,0,1,1,0,0,0
0,0,0,0,1,1,1,1,1,1,1,0,0
0,0,0,1,1,1,1,1,1,1,0,0,0
0,0,0,1,1,1,1,1,1,1,1,0,0
0,0,0,1,1,1,1,1,1,1,0,0,0
0,0,0,1,1,1,1,1,1,1,1,0,0
0,0,0,1,1,1,1,1,1,1,1,0,0
0,0,1,0,1,1,1,1,1,1,0,0,0
0,0,0,0,0,0,1,0,1,0,0,0,0
0,0,0,0,0,0,0,0,0,0,0,0,0
0,0,0,0,0,0,0,0,0,0,0,0,0
endlayer

layer
0,0,0,0,0,0,0,0,0,0,0,0,0
0,0,0,0,0,0,0,0,0,0,0,0,0
0,0,0,0,1,0,0,0,1,0,0,0,0
0,0,0,0,1,1,1,1,1,1,1,0,0
0,0,0,1,1,1,1,1,1,1,0,0,0
0,0,0,1,1,1,1,1,1,1,1,0,0
0,0,0,1,1,1,1,1,1,1,0,0,0
0,0,0,1,1,1,1,1,1,1,0,0,0
0,0,0,1,1,1,1,1,1,1,1,0,0
0,0,1,0,1,1,1,1,1,0,0,0,0
0,0,0,0,0,0,1,0,1,0,0,0,0
0,0,0,0,0,0,0,0,0,0,0,0,0
0,0,0,0,0,0,0,0,0,0,0,0,0
endlayer

layer
0,0,0,0,0,0,0,0,0,0,0,0,0
0,0,0,0,0,0,0,0,0,0,0,0,0
0,0,0,0,1,0,0,0,0,0,0,0,0
0,0,0,0,1,1,1,1,1,1,1,0,0
0,0,0,1,1,1,1,1,1,1,0,0,0
0,0,0,1,1,1,1,1,1,1,0,0,0
0,0,0,1,1,1,1,1,1,1,0,0,0
0,0,0,1,1,1,1,1,1,1,0,0,0
0,0,0,1,1,1,1,1,1,1,1,0,0
0,0,0,0,1,1,1,1,1,0,0,0,0
0,0,0,0,0,0,1,0,1,0,0,0,0
0,0,0,0,0,0,0,0,0,0,0,0,0
0,0,0,0,0,0,0,0,0,0,0,0,0
endlayer

layer
0,0,0,0,0,0,0,0,0,0,0,0,0
0,0,0,0,0,0,0,0,0,0,0,0,0
0,0,0,0,1,0,0,0,0,0,0,0,0
0,0,0,0,0,1,1,0,0,1,1,0,0
0,0,0,1,0,1,1,1,0,1,0,0,0
0,0,0,1,1,1,1,1,1,0,0,0,0
0,0,0,0,1,1,1,1,1,0,0,0,0
0,0,0,1,1,1,1,1,1,0,0,0,0
0,0,0,1,1,1,1,1,1,0,0,0,0
0,0,0,0,1,0,1,1,1,0,0,0,0
0,0,0,0,0,0,0,0,1,0,0,0,0
0,0,0,0,0,0,0,0,0,0,0,0,0
0,0,0,0,0,0,0,0,0,0,0,0,0
endlayer

layer
0,0,0,0,0,0,0,0,0,0,0,0,0
0,0,0,0,0,0,0,0,0,0,0,0,0
0,0,0,0,0,0,0,0,0,0,0,0,0
0,0,0,0,0,0,1,0,0,0,0,0,0
0,0,0,1,0,1,1,1,0,1,0,0,0
0,0,0,1,1,1,1,1,1,0,0,0,0
0,0,0,0,1,1,1,1,1,0,0,0,0
0,0,0,1,1,1,1,1,1,0,0,0,0
0,0,0,1,1,1,1,1,1,0,0,0,0
0,0,0,0,1,0,0,1,1,0,0,0,0
0,0,0,0,0,0,0,0,0,0,0,0,0
0,0,0,0,0,0,0,0,0,0,0,0,0
0,0,0,0,0,0,0,0,0,0,0,0,0
endlayer

layer
0,0,0,0,0,0,0,0,0,0,0,0,0
0,0,0,0,0,0,0,0,0,0,0,0,0
0,0,0,0,0,0,0,0,0,0,0,0,0
0,0,0,0,0,0,1,0,0,0,0,0,0
0,0,0,1,0,1,1,1,0,0,0,0,0
0,0,0,0,1,1,1,1,1,0,0,0,0
0,0,0,0,1,1,1,1,1,0,0,0,0
0,0,0,1,1,1,1,1,1,0,0,0,0
0,0,0,1,1,1,1,1,1,0,0,0,0
0,0,0,0,1,0,0,0,0,0,0,0,0
0,0,0,0,0,0,0,0,0,0,0,0,0
0,0,0,0,0,0,0,0,0,0,0,0,0
0,0,0,0,0,0,0,0,0,0,0,0,0
endlayer

layer
0,0,0,0,0,0,0,0,0,0,0,0,0
0,0,0,0,0,0,0,0,0,0,0,0,0
0,0,0,0,0,0,0,0,0,0,0,0,0
0,0,0,0,0,0,0,0,0,0,0,0,0
0,0,0,1,0,1,1,1,0,0,0,0,0
0,0,0,0,1,0,1,1,1,0,0,0,0
0,0,0,0,1,1,2,0,1,0,0,0,0
0,0,0,1,1,1,1,1,1,0,0,0,0
0,0,0,1,1,1,1,1,1,0,0,0,0
0,0,0,0,1,0,0,0,0,0,0,0,0
0,0,0,0,0,0,0,0,0,0,0,0,0
0,0,0,0,0,0,0,0,0,0,0,0,0
0,0,0,0,0,0,0,0,0,0,0,0,0
endlayer

layer
0,0,0,0,0,0,0,0,0,0,0,0,0
0,0,0,0,0,0,0,0,0,0,0,0,0
0,0,0,0,0,0,0,0,0,0,0,0,0
0,0,0,0,0,0,0,0,0,0,0,0,0
0,0,0,1,0,1,1,1,0,0,0,0,0
0,0,0,0,1,1,1,1,1,0,0,0,0
0,0,0,0,1,1,0,0,1,0,0,0,0
0,0,0,0,1,1,1,3,1,0,0,0,0
0,0,0,1,1,1,1,1,1,0,0,0,0
0,0,0,0,1,0,0,0,0,0,0,0,0
0,0,0,0,0,0,0,0,0,0,0,0,0
0,0,0,0,0,0,0,0,0,0,0,0,0
0,0,0,0,0,0,0,0,0,0,0,0,0
endlayer

layer
0,0,0,0,0,0,0,0,0,0,0,0,0
0,0,0,0,0,0,0,0,0,0,0,0,0
0,0,0,0,0,0,0,0,0,0,0,0,0
0,0,0,0,0,0,0,0,0,0,0,0,0
0,0,0,1,0,1,1,1,0,0,0,0,0
0,0,0,0,1,1,1,1,1,0,0,0,0
0,0,0,0,1,1,0,0,1,0,0,0,0
0,0,0,0,0,1,1,0,1,0,0,0,0
0,0,0,1,1,1,1,1,0,0,0,0,0
0,0,0,0,1,0,0,0,0,0,0,0,0
0,0,0,0,0,0,0,0,0,0,0,0,0
0,0,0,0,0,0,0,0,0,0,0,0,0
0,0,0,0,0,0,0,0,0,0,0,0,0
endlayer

layer
0,0,0,0,0,0,0,0,0,0,0,0,0
0,0,0,0,0,0,0,0,0,0,0,0,0
0,0,0,0,0,0,0,0,0,0,0,0,0
0,0,0,0,0,0,0,0,0,0,0,0,0
0,0,0,0,0,0,1,1,0,0,0,0,0
0,0,0,0,1,0,1,1,1,0,0,0,0
0,0,0,0,1,1,0,1,1,0,0,0,0
0,0,0,0,0,1,1,0,1,0,0,0,0
0,0,0,0,0,0,1,1,0,0,0,0,0
0,0,0,0,0,0,0,0,0,0,0,0,0
0,0,0,0,0,0,0,0,0,0,0,0,0
0,0,0,0,0,0,0,0,0,0,0,0,0
0,0,0,0,0,0,0,0,0,0,0,0,0
endlayer

layer
0,0,0,0,0,0,0,0,0,0,0,0,0
0,0,0,0,0,0,0,0,0,0,0,0,0
0,0,0,0,0,0,0,0,0,0,0,0,0
0,0,0,0,0,0,0,0,0,0,0,0,0
0,0,0,0,0,0,1,1,0,0,0,0,0
0,0,0,0,1,0,1,1,1,0,0,0,0
0,0,0,0,1,1,1,1,1,0,0,0,0
0,0,0,0,0,1,1,0,1,0,0,0,0
0,0,0,0,0,0,1,1,0,0,0,0,0
0,0,0,0,0,0,0,0,0,0,0,0,0
0,0,0,0,0,0,0,0,0,0,0,0,0
0,0,0,0,0,0,0,0,0,0,0,0,0
0,0,0,0,0,0,0,0,0,0,0,0,0
endlayer

layer
0,0,0,0,0,0,0,0,0,0,0,0,0
0,0,0,0,0,0,0,0,0,0,0,0,0
0,0,0,0,0,0,0,0,0,0,0,0,0
0,0,0,0,0,0,0,0,0,0,0,0,0
0,0,0,0,0,0,1,1,0,0,0,0,0
0,0,0,0,0,0,1,1,0,0,0,0,0
0,0,0,0,1,1,1,1,0,0,0,0,0
0,0,0,0,0,0,1,0,1,0,0,0,0
0,0,0,0,0,0,0,1,0,0,0,0,0
0,0,0,0,0,0,0,0,0,0,0,0,0
0,0,0,0,0,0,0,0,0,0,0,0,0
0,0,0,0,0,0,0,0,0,0,0,0,0
0,0,0,0,0,0,0,0,0,0,0,0,0
endlayer

layer
0,0,0,0,0,0,0,0,0,0,0,0,0
0,0,0,0,0,0,0,0,0,0,0,0,0
0,0,0,0,0,0,0,0,0,0,0,0,0
0,0,0,0,0,0,0,0,0,0,0,0,0
0,0,0,0,0,0,1,1,0,0,0,0,0
0,0,0,0,0,0,1,1,0,0,0,0,0
0,0,0,0,0,1,1,1,0,0,0,0,0
0,0,0,0,0,0,1,0,1,0,0,0,0
0,0,0,0,0,0,0,1,0,0,0,0,0
0,0,0,0,0,0,0,0,0,0,0,0,0
0,0,0,0,0,0,0,0,0,0,0,0,0
0,0,0,0,0,0,0,0,0,0,0,0,0
0,0,0,0,0,0,0,0,0,0,0,0,0
endlayer

layer
0,0,0,0,0,0,0,0,0,0,0,0,0
0,0,0,0,0,0,0,0,0,0,0,0,0
0,0,0,0,0,0,0,0,0,0,0,0,0
0,0,0,0,0,0,0,0,0,0,0,0,0
0,0,0,0,0,0,1,1,0,0,0,0,0
0,0,0,0,0,0,1,1,0,0,0,0,0
0,0,0,0,0,1,1,1,0,0,0,0,0
0,0,0,0,0,1,1,1,1,0,0,0,0
0,0,0,0,0,0,0,1,0,0,0,0,0
0,0,0,0,0,0,0,0,0,0,0,0,0
0,0,0,0,0,0,0,0,0,0,0,0,0
0,0,0,0,0,0,0,0,0,0,0,0,0
0,0,0,0,0,0,0,0,0,0,0,0,0
endlayer

layer
0,0,0,0,0,0,0,0,0,0,0,0,0
0,0,0,0,0,0,0,0,0,0,0,0,0
0,0,0,0,0,0,0,0,0,0,0,0,0
0,0,0,0,0,0,0,0,0,0,0,0,0
0,0,0,0,0,0,0,0,0,0,0,0,0
0,0,0,0,0,0,1,1,0,0,0,0,0
0,0,0,0,0,1,1,1,0,0,0,0,0
0,0,0,0,0,1,1,1,0,0,0,0,0
0,0,0,0,0,0,0,0,0,0,0,0,0
0,0,0,0,0,0,0,0,0,0,0,0,0
0,0,0,0,0,0,0,0,0,0,0,0,0
0,0,0,0,0,0,0,0,0,0,0,0,0
0,0,0,0,0,0,0,0,0,0,0,0,0
endlayer

layer
0,0,0,0,0,0,0,0,0,0,0,0,0
0,0,0,0,0,0,0,0,0,0,0,0,0
0,0,0,0,0,0,0,0,0,0,0,0,0
0,0,0,0,0,0,0,0,0,0,0,0,0
0,0,0,0,0,0,0,0,0,0,0,0,0
0,0,0,0,0,0,0,0,0,0,0,0,0
0,0,0,0,0,0,1,1,0,0,0,0,0
0,0,0,0,0,1,0,0,0,0,0,0,0
0,0,0,0,0,0,0,0,0,0,0,0,0
0,0,0,0,0,0,0,0,0,0,0,0,0
0,0,0,0,0,0,0,0,0,0,0,0,0
0,0,0,0,0,0,0,0,0,0,0,0,0
0,0,0,0,0,0,0,0,0,0,0,0,0
endlayer

layer
0,0,0,0,0,0,0,0,0,0,0,0,0
0,0,0,0,0,0,0,0,0,0,0,0,0
0,0,0,0,0,0,0,0,0,0,0,0,0
0,0,0,0,0,0,0,0,0,0,0,0,0
0,0,0,0,0,0,0,0,0,0,0,0,0
0,0,0,0,0,0,0,0,0,0,0,0,0
0,0,0,0,0,0,1,1,0,0,0,0,0
0,0,0,0,0,1,0,0,0,0,0,0,0
0,0,0,0,0,0,0,0,0,0,0,0,0
0,0,0,0,0,0,0,0,0,0,0,0,0
0,0,0,0,0,0,0,0,0,0,0,0,0
0,0,0,0,0,0,0,0,0,0,0,0,0
0,0,0,0,0,0,0,0,0,0,0,0,0
endlayer

layer
0,0,0,0,0,0,0,0,0,0,0,0,0
0,0,0,0,0,0,0,0,0,0,0,0,0
0,0,0,0,0,0,0,0,0,0,0,0,0
0,0,0,0,0,0,0,0,0,0,0,0,0
0,0,0,0,0,0,0,0,0,0,0,0,0
0,0,0,0,0,0,0,0,0,0,0,0,0
0,0,0,0,0,0,1,1,0,0,0,0,0
0,0,0,0,0,1,0,0,0,0,0,0,0
0,0,0,0,0,0,0,0,0,0,0,0,0
0,0,0,0,0,0,0,0,0,0,0,0,0
0,0,0,0,0,0,0,0,0,0,0,0,0
0,0,0,0,0,0,0,0,0,0,0,0,0
0,0,0,0,0,0,0,0,0,0,0,0,0
endlayer

layer
0,0,0,0,0,0,0,0,0,0,0,0,0
0,0,0,0,0,0,0,0,0,0,0,0,0
0,0,0,0,0,0,0,0,0,0,0,0,0
0,0,0,0,0,0,0,0,0,0,0,0,0
0,0,0,0,0,0,0,0,0,0,0,0,0
0,0,0,0,0,0,0,0,0,0,0,0,0
0,0,0,0,0,0,1,0,0,0,0,0,0
0,0,0,0,0,0,0,0,0,0,0,0,0
0,0,0,0,0,0,0,0,0,0,0,0,0
0,0,0,0,0,0,0,0,0,0,0,0,0
0,0,0,0,0,0,0,0,0,0,0,0,0
0,0,0,0,0,0,0,0,0,0,0,0,0
0,0,0,0,0,0,0,0,0,0,0,0,0
endlayer

layer
0,0,0,0,0,0,0,0,0,0,0,0,0
0,0,0,0,0,0,0,0,0,0,0,0,0
0,0,0,0,0,0,0,0,0,0,0,0,0
0,0,0,0,0,0,0,0,0,0,0,0,0
0,0,0,0,0,0,0,0,0,0,0,0,0
0,0,0,0,0,0,0,0,0,0,0,0,0
0,0,0,0,0,0,1,0,0,0,0,0,0
0,0,0,0,0,0,0,0,0,0,0,0,0
0,0,0,0,0,0,0,0,0,0,0,0,0
0,0,0,0,0,0,0,0,0,0,0,0,0
0,0,0,0,0,0,0,0,0,0,0,0,0
0,0,0,0,0,0,0,0,0,0,0,0,0
0,0,0,0,0,0,0,0,0,0,0,0,0
endlayer

layer
0,0,0,0,0,0,0,0,0,0,0,0,0
0,0,0,0,0,0,0,0,0,0,0,0,0
0,0,0,0,0,0,0,0,0,0,0,0,0
0,0,0,0,0,0,0,0,0,0,0,0,0
0,0,0,0,0,0,0,0,0,0,0,0,0
0,0,0,0,0,0,0,0,0,0,0,0,0
0,0,0,0,0,0,1,0,0,0,0,0,0
0,0,0,0,0,0,0,0,0,0,0,0,0
0,0,0,0,0,0,0,0,0,0,0,0,0
0,0,0,0,0,0,0,0,0,0,0,0,0
0,0,0,0,0,0,0,0,0,0,0,0,0
0,0,0,0,0,0,0,0,0,0,0,0,0
0,0,0,0,0,0,0,0,0,0,0,0,0
endlayer

