weight=35
embed_into_distance=0
acceptable_target_blocks=1,2,3,12,13,250
dimensions=4,14,13
allowable_overhang=0
max_cut_in=0
cut_in_buffer=0
max_leveling=0
leveling_buffer=0
preserve_water=0
preserve_lava=0
preserve_plants=0


rule1=0,95,250
rule2=0,95,250,250,250,250,250,250,250,250,250,250,3304-2,3309-2,3310-2,3311-2,3312-2,4095-2


layer
0,0,0,0,0,1,1,1,1,1,0,0,0
0,0,0,0,1,1,1,1,1,1,1,0,0
0,0,0,0,1,1,1,1,1,1,1,0,0
0,0,0,0,1,2,1,1,1,1,1,1,0
0,0,0,1,2,1,2,1,1,1,1,1,0
0,0,1,1,1,1,1,1,1,1,1,1,0
0,0,1,1,1,2,2,2,1,1,1,1,1
0,1,1,1,1,2,1,2,1,1,1,1,0
1,1,1,1,2,1,1,1,1,1,1,0,0
1,1,1,1,1,1,2,1,1,1,0,0,0
0,1,1,1,1,1,1,1,1,0,0,0,0
0,0,1,1,1,1,1,1,1,0,0,0,0
0,0,1,1,1,1,1,1,0,0,0,0,0
0,0,1,1,1,1,1,0,0,0,0,0,0
endlayer

layer
0,0,0,0,0,0,0,0,0,0,0,0,0
0,0,0,0,0,0,0,0,0,0,0,0,0
0,0,0,0,0,0,1,1,1,1,0,0,0
0,0,0,0,1,1,1,1,1,1,0,0,0
0,0,0,0,1,1,1,1,1,1,0,0,0
0,0,0,1,1,1,1,1,1,1,1,0,0
0,0,0,1,1,1,1,1,1,1,1,0,0
0,0,0,1,1,1,1,1,1,1,0,0,0
0,0,0,0,1,1,1,1,1,1,0,0,0
0,0,0,1,1,1,1,1,1,0,0,0,0
0,0,0,1,1,1,1,0,0,0,0,0,0
0,0,0,0,1,1,0,0,0,0,0,0,0
0,0,0,0,0,0,0,0,0,0,0,0,0
0,0,0,0,0,0,0,0,0,0,0,0,0
endlayer

layer
0,0,0,0,0,0,0,0,0,0,0,0,0
0,0,0,0,0,0,0,0,0,0,0,0,0
0,0,0,0,0,0,0,0,0,0,0,0,0
0,0,0,0,0,0,0,0,0,0,0,0,0
0,0,0,0,0,0,1,1,1,0,0,0,0
0,0,0,0,1,1,1,1,1,0,0,0,0
0,0,0,1,1,1,1,1,1,1,0,0,0
0,0,0,0,1,1,1,1,1,0,0,0,0
0,0,0,0,1,1,1,0,0,0,0,0,0
0,0,0,0,1,0,0,0,0,0,0,0,0
0,0,0,0,0,0,0,0,0,0,0,0,0
0,0,0,0,0,0,0,0,0,0,0,0,0
0,0,0,0,0,0,0,0,0,0,0,0,0
0,0,0,0,0,0,0,0,0,0,0,0,0
endlayer

layer
0,0,0,0,0,0,0,0,0,0,0,0,0
0,0,0,0,0,0,0,0,0,0,0,0,0
0,0,0,0,0,0,0,0,0,0,0,0,0
0,0,0,0,0,0,0,0,0,0,0,0,0
0,0,0,0,0,0,0,0,0,0,0,0,0
0,0,0,0,0,0,0,0,0,0,0,0,0
0,0,0,0,1,1,1,0,0,0,0,0,0
0,0,0,0,1,0,0,0,0,0,0,0,0
0,0,0,0,0,0,0,0,0,0,0,0,0
0,0,0,0,0,0,0,0,0,0,0,0,0
0,0,0,0,0,0,0,0,0,0,0,0,0
0,0,0,0,0,0,0,0,0,0,0,0,0
0,0,0,0,0,0,0,0,0,0,0,0,0
0,0,0,0,0,0,0,0,0,0,0,0,0
endlayer

