# Converted from schematic
# THIS TEMPLATE USES DEFAULTS!  Please edit for corrections.
# If you need help, consult template_rules.txt

weight=1
embed_into_distance=41
acceptable_target_blocks=1,2,3,12,13,250
dimensions=56,21,30
allowable_overhang=0
max_cut_in=2
cut_in_buffer=1
max_leveling=2
leveling_buffer=1
preserve_water=0
preserve_lava=0
preserve_plants=0


rule1=0,100,250
rule2=0,100,2799-7
rule3=0,100,11
rule4=0,100,pyramidDesertyChest:10
rule5=0,100,HardMobSpawn,MediumMobSpawn
rule6=0,75,ChestGenHook:dungeonChest:10
rule7=0,100,1476-3
rule8=0,65,ChestGenHook:dungeonChest:10,HardMobSpawn,MediumMobSpawn,HardMobSpawn,MediumMobSpawn
rule9=0,100,3134-10
rule10=0,100,3123-1
rule11=0,100,2762-10
rule12=0,100,2764-11
rule13=0,100,2799-8
rule14=0,100,17
rule15=0,100,2802-8
rule16=0,100,2802-9
rule17=0,100,17-4
rule18=0,100,17-8


layer
1,1,1,1,1,1,1,1,1,1,1,1,1,1,1,1,1,1,1,1,1,1,1,1,1,1,1,1,1,1
1,1,1,1,1,1,1,1,1,1,1,1,1,1,1,1,1,1,1,1,1,1,1,1,1,1,1,1,1,1
1,1,1,1,1,1,1,1,1,1,1,1,1,1,1,1,1,1,1,1,1,1,1,1,1,1,1,1,1,1
1,1,1,1,1,1,1,1,1,1,1,1,1,1,2,2,2,2,2,2,2,2,2,2,2,2,2,2,2,1
1,1,1,1,1,1,1,1,1,1,1,1,1,1,2,2,2,2,2,2,2,2,2,2,2,2,2,2,2,1
1,1,1,1,1,1,1,1,1,1,1,1,1,1,2,2,2,2,2,2,2,2,2,2,2,2,2,2,2,1
1,1,1,1,1,1,1,1,1,1,1,1,1,1,2,2,2,2,2,2,3,3,3,2,2,2,2,2,2,1
1,1,1,1,1,1,1,1,1,1,1,1,1,1,2,2,2,2,2,3,3,3,3,3,2,2,2,2,2,1
1,1,1,1,1,1,1,1,1,1,1,1,1,1,2,2,2,2,3,3,3,3,3,3,3,2,2,2,2,1
1,1,1,1,1,1,1,1,1,1,1,1,1,1,2,2,2,3,3,3,3,2,3,3,3,3,2,2,2,1
1,1,1,1,1,1,1,1,1,1,1,1,1,1,2,2,2,3,3,3,2,2,2,3,3,3,2,2,2,1
1,1,1,1,1,1,1,1,1,1,1,1,1,1,2,2,2,3,3,3,3,2,3,3,3,3,2,2,2,1
1,1,1,1,1,1,1,1,1,1,1,1,1,1,2,2,2,2,3,3,3,3,3,3,3,2,2,2,2,1
1,1,1,1,1,1,1,1,1,1,1,1,1,1,2,2,2,2,2,3,3,3,3,3,2,2,2,2,2,1
1,1,1,1,1,1,1,1,1,1,1,1,1,1,2,2,2,2,2,2,3,3,3,2,2,2,2,2,2,1
1,1,1,1,1,1,1,1,1,1,1,1,1,1,2,2,2,2,2,2,2,2,2,2,2,2,2,2,2,1
1,1,1,1,1,1,1,1,1,1,1,1,1,1,2,2,2,2,2,2,2,2,2,2,2,2,2,2,2,1
1,1,1,1,1,1,1,1,1,1,1,1,1,1,2,2,2,2,2,2,2,2,2,2,2,2,2,2,2,1
1,1,1,1,1,1,1,1,1,1,1,1,1,1,1,1,1,1,1,1,1,1,1,1,1,1,1,1,1,1
1,1,1,1,1,1,1,1,1,1,1,1,1,1,1,1,1,1,1,1,1,1,1,1,1,1,1,1,1,1
1,1,1,1,1,1,1,1,1,1,1,1,1,1,1,1,1,1,1,1,1,1,1,1,1,1,1,1,1,1
endlayer

layer
1,1,1,1,1,1,1,1,1,1,1,1,1,1,1,1,1,1,1,1,1,1,1,1,1,1,1,1,1,1
1,1,1,1,1,1,1,1,1,1,1,1,1,1,1,1,1,1,1,1,1,1,1,1,1,1,1,1,1,1
1,1,1,1,1,1,1,1,1,1,1,1,1,1,1,1,1,1,1,1,1,1,1,1,1,1,1,1,1,1
1,1,1,1,1,1,1,1,1,1,1,1,1,1,2,2,2,2,2,2,2,2,2,2,2,2,2,2,2,1
1,1,1,1,1,1,1,1,1,1,1,1,1,1,2,2,2,2,2,2,2,2,2,2,2,2,2,2,2,1
1,1,1,1,1,1,1,1,1,1,1,1,1,1,2,2,2,2,2,2,2,2,2,2,2,2,2,2,2,1
1,1,1,1,1,1,1,1,1,1,1,1,1,1,2,2,2,2,2,2,0,0,0,2,2,2,2,2,2,1
1,1,1,1,1,1,1,1,1,1,1,1,1,1,2,2,2,2,2,0,0,0,0,0,2,2,2,2,2,1
1,1,1,1,1,1,1,1,1,1,1,1,1,1,2,2,2,2,0,0,0,0,0,0,0,2,2,2,2,1
1,1,1,1,1,1,1,1,1,1,1,1,1,1,2,2,2,0,0,0,0,2,0,0,0,0,2,2,2,1
1,1,1,1,1,1,1,1,1,1,1,1,1,1,2,2,2,0,0,0,2,2,2,0,0,0,2,2,2,1
1,1,1,1,1,1,1,1,1,1,1,1,1,1,2,2,2,0,0,0,0,2,0,0,0,0,2,2,2,1
1,1,1,1,1,1,1,1,1,1,1,1,1,1,2,2,2,2,0,0,0,0,0,0,0,2,2,2,2,1
1,1,1,1,1,1,1,1,1,1,1,1,1,1,2,2,2,2,2,0,0,0,0,0,2,2,2,2,2,1
1,1,1,1,1,1,1,1,1,1,1,1,1,1,2,2,2,2,2,2,0,0,0,2,2,2,2,2,2,1
1,1,1,1,1,1,1,1,1,1,1,1,1,1,2,2,2,2,2,2,2,2,2,2,2,2,2,2,2,1
1,1,1,1,1,1,1,1,1,1,1,1,1,1,2,2,2,2,2,2,2,2,2,2,2,2,2,2,2,1
1,1,1,1,1,1,1,1,1,1,1,1,1,1,2,2,2,2,2,2,2,2,2,2,2,2,2,2,2,1
1,1,1,1,1,1,1,1,1,1,1,1,1,1,1,1,1,1,1,1,1,1,1,1,1,1,1,1,1,1
1,1,1,1,1,1,1,1,1,1,1,1,1,1,1,1,1,1,1,1,1,1,1,1,1,1,1,1,1,1
1,1,1,1,1,1,1,1,1,1,1,1,1,1,1,1,1,1,1,1,1,1,1,1,1,1,1,1,1,1
endlayer

layer
1,1,1,1,1,1,1,1,1,1,1,1,1,1,1,1,1,1,1,1,1,1,1,1,1,1,1,1,1,1
1,1,1,1,1,1,1,1,1,1,1,1,1,1,1,1,1,1,1,1,1,1,1,1,1,1,1,1,1,1
1,1,1,1,1,1,1,1,1,1,1,1,1,1,1,1,1,1,1,1,1,1,1,1,1,1,1,1,1,1
1,1,1,1,1,1,1,1,1,1,1,1,1,1,2,2,2,2,2,2,2,2,2,2,2,2,2,2,2,1
1,1,1,1,1,1,1,1,1,1,1,1,1,1,2,2,2,2,2,2,2,2,2,2,2,2,2,2,2,1
1,1,1,1,1,1,1,1,1,1,1,1,1,1,2,2,2,2,2,2,2,2,2,2,2,2,2,2,2,1
1,1,1,1,1,1,1,1,1,1,1,1,1,1,2,2,2,2,2,2,0,0,0,2,2,2,2,2,2,1
1,1,1,1,1,1,1,1,1,1,1,1,1,1,2,2,2,2,2,0,0,0,0,0,2,2,2,2,2,1
1,1,1,1,1,1,1,1,1,1,1,1,1,1,2,2,2,2,0,0,0,0,0,0,0,2,2,2,2,1
1,1,1,1,1,1,1,1,1,1,1,1,1,1,2,2,2,0,0,0,0,2,0,0,0,0,2,2,2,1
1,1,1,1,1,1,1,1,1,1,1,1,1,1,2,2,2,0,0,0,2,2,2,0,0,0,2,2,2,1
1,1,1,1,1,1,1,1,1,1,1,1,1,1,2,2,2,0,0,0,0,2,0,0,0,0,2,2,2,1
1,1,1,1,1,1,1,1,1,1,1,1,1,1,2,2,2,2,0,0,0,0,0,0,0,2,2,2,2,1
1,1,1,1,1,1,1,1,1,1,1,1,1,1,2,2,2,2,2,0,0,0,0,0,2,2,2,2,2,1
1,1,1,1,1,1,1,1,1,1,1,1,1,1,2,2,2,2,2,2,0,0,0,2,2,2,2,2,2,1
1,1,1,1,1,1,1,1,1,1,1,1,1,1,2,2,2,2,2,2,2,2,2,2,2,2,2,2,2,1
1,1,1,1,1,1,1,1,1,1,1,1,1,1,2,2,2,2,2,2,2,2,2,2,2,2,2,2,2,1
1,1,1,1,1,1,1,1,1,1,1,1,1,1,2,2,2,2,2,2,2,2,2,2,2,2,2,2,2,1
1,1,1,1,1,1,1,1,1,1,1,1,1,1,1,1,1,1,1,1,1,1,1,1,1,1,1,1,1,1
1,1,1,1,1,1,1,1,1,1,1,1,1,1,1,1,1,1,1,1,1,1,1,1,1,1,1,1,1,1
1,1,1,1,1,1,1,1,1,1,1,1,1,1,1,1,1,1,1,1,1,1,1,1,1,1,1,1,1,1
endlayer

layer
1,1,1,1,1,1,1,1,1,1,1,1,1,1,1,1,1,1,1,1,1,1,1,1,1,1,1,1,1,1
1,1,1,1,1,1,1,1,1,1,1,1,1,1,1,1,1,1,1,1,1,1,1,1,1,1,1,1,1,1
1,1,1,1,1,1,1,1,1,1,1,1,1,1,1,1,1,1,1,1,1,1,1,1,1,1,1,1,1,1
1,1,1,1,1,1,1,1,1,1,1,1,1,1,2,2,2,2,2,2,2,2,2,2,2,2,2,2,2,1
1,1,1,1,1,1,1,1,1,1,1,1,1,1,2,2,2,2,2,2,2,2,2,2,2,2,2,2,2,1
1,1,1,1,1,1,1,1,1,1,1,1,1,1,2,2,2,2,2,2,2,2,2,2,2,2,2,2,2,1
1,1,1,1,1,1,1,1,1,1,1,1,1,1,2,2,2,2,2,2,0,0,0,2,2,2,2,2,2,1
1,1,1,1,1,1,1,1,1,1,1,1,1,1,2,2,2,2,2,0,0,0,0,0,2,2,2,2,2,1
1,1,1,1,1,1,1,1,1,1,1,1,1,1,2,2,2,2,0,0,0,0,0,0,0,2,2,2,2,1
1,1,1,1,1,1,1,1,1,1,1,1,1,1,2,2,2,0,0,0,0,2,0,0,0,0,2,2,2,1
1,1,1,1,1,1,1,1,1,1,1,1,1,1,2,2,2,0,0,0,2,2,2,0,0,0,2,2,2,1
1,1,1,1,1,1,1,1,1,1,1,1,1,1,2,2,2,0,0,0,0,2,0,0,0,0,2,2,2,1
1,1,1,1,1,1,1,1,1,1,1,1,1,1,2,2,2,2,0,0,0,0,0,0,0,2,2,2,2,1
1,1,1,1,1,1,1,1,1,1,1,1,1,1,2,2,2,2,2,0,0,0,0,0,2,2,2,2,2,1
1,1,1,1,1,1,1,1,1,1,1,1,1,1,2,2,2,2,2,2,0,0,0,2,2,2,2,2,2,1
1,1,1,1,1,1,1,1,1,1,1,1,1,1,2,2,2,2,2,2,2,2,2,2,2,2,2,2,2,1
1,1,1,1,1,1,1,1,1,1,1,1,1,1,2,2,2,2,2,2,2,2,2,2,2,2,2,2,2,1
1,1,1,1,1,1,1,1,1,1,1,1,1,1,2,2,2,2,2,2,2,2,2,2,2,2,2,2,2,1
1,1,1,1,1,1,1,1,1,1,1,1,1,1,1,1,1,1,1,1,1,1,1,1,1,1,1,1,1,1
1,1,1,1,1,1,1,1,1,1,1,1,1,1,1,1,1,1,1,1,1,1,1,1,1,1,1,1,1,1
1,1,1,1,1,1,1,1,1,1,1,1,1,1,1,1,1,1,1,1,1,1,1,1,1,1,1,1,1,1
endlayer

layer
1,1,1,1,1,1,1,1,1,1,1,1,1,1,1,1,1,1,1,1,1,1,1,1,1,1,1,1,1,1
1,1,1,1,1,1,1,1,1,1,1,1,1,1,1,1,1,1,1,1,1,1,1,1,1,1,1,1,1,1
1,1,1,1,1,1,1,1,1,1,1,1,1,1,1,1,1,1,1,1,1,1,1,1,1,1,1,1,1,1
1,1,1,1,1,1,1,1,1,1,1,1,1,1,2,2,2,2,2,2,2,2,2,2,2,2,2,2,2,1
1,1,1,1,1,1,1,1,1,1,1,1,1,1,2,2,2,2,2,2,2,2,2,2,2,2,2,2,2,1
1,1,1,1,1,1,1,1,1,1,1,1,1,1,2,2,2,2,2,2,2,2,2,2,2,2,2,2,2,1
1,1,1,1,1,1,1,1,1,1,1,1,1,1,2,2,2,2,2,2,0,0,0,2,2,2,2,2,2,1
1,1,1,1,1,1,1,1,1,1,1,1,1,1,2,2,2,2,2,0,0,0,0,0,2,2,2,2,2,1
1,1,1,1,1,1,1,1,1,1,1,1,1,1,2,2,2,2,0,0,0,0,0,0,0,2,2,2,2,1
1,1,1,1,1,1,1,1,1,1,1,1,1,1,2,2,2,0,0,0,0,2,0,0,0,0,2,2,2,1
1,1,1,1,1,1,1,1,1,1,1,1,1,1,2,2,2,0,0,0,2,2,2,0,0,0,2,2,2,1
1,1,1,1,1,1,1,1,1,1,1,1,1,1,2,2,2,0,0,0,0,2,0,0,0,0,2,2,2,1
1,1,1,1,1,1,1,1,1,1,1,1,1,1,2,2,2,2,0,0,0,0,0,0,0,2,2,2,2,1
1,1,1,1,1,1,1,1,1,1,1,1,1,1,2,2,2,2,2,0,0,0,0,0,2,2,2,2,2,1
1,1,1,1,1,1,1,1,1,1,1,1,1,1,2,2,2,2,2,2,0,0,0,2,2,2,2,2,2,1
1,1,1,1,1,1,1,1,1,1,1,1,1,1,2,2,2,2,2,2,2,2,2,2,2,2,2,2,2,1
1,1,1,1,1,1,1,1,1,1,1,1,1,1,2,2,2,2,2,2,2,2,2,2,2,2,2,2,2,1
1,1,1,1,1,1,1,1,1,1,1,1,1,1,2,2,2,2,2,2,2,2,2,2,2,2,2,2,2,1
1,1,1,1,1,1,1,1,1,1,1,1,1,1,1,1,1,1,1,1,1,1,1,1,1,1,1,1,1,1
1,1,1,1,1,1,1,1,1,1,1,1,1,1,1,1,1,1,1,1,1,1,1,1,1,1,1,1,1,1
1,1,1,1,1,1,1,1,1,1,1,1,1,1,1,1,1,1,1,1,1,1,1,1,1,1,1,1,1,1
endlayer

layer
1,1,1,1,1,1,1,1,1,1,1,1,1,1,1,1,1,1,1,1,1,1,1,1,1,1,1,1,1,1
1,1,1,1,1,1,1,1,1,1,1,1,1,1,1,1,1,1,1,1,1,1,1,1,1,1,1,1,1,1
1,1,1,1,1,1,1,1,1,1,1,1,1,1,1,1,1,1,1,1,1,1,1,1,1,1,1,1,1,1
1,1,1,1,1,1,1,1,1,1,1,1,1,1,2,2,2,2,2,2,2,2,2,2,2,2,2,2,2,1
1,1,1,1,1,1,1,1,1,1,1,1,1,1,2,2,2,2,2,2,2,2,2,2,2,2,2,2,2,1
1,1,1,1,1,1,1,1,1,1,1,1,1,1,2,2,2,2,2,2,2,2,2,2,2,2,2,2,2,1
1,1,1,1,1,1,1,1,1,1,1,1,1,1,2,2,2,2,2,2,0,0,0,2,2,2,2,2,2,1
1,1,1,1,1,1,1,1,1,1,1,1,1,1,2,2,2,2,2,0,0,0,0,0,2,2,2,2,2,1
1,1,1,1,1,1,1,1,1,1,1,1,1,1,2,2,2,2,0,0,0,0,0,0,0,2,2,2,2,1
1,1,1,1,1,1,1,1,1,1,1,1,1,1,2,2,2,0,0,0,0,2,0,0,0,0,2,2,2,1
1,1,1,1,1,1,1,1,1,1,1,1,1,1,2,2,2,0,0,0,2,2,2,0,0,0,2,2,2,1
1,1,1,1,1,1,1,1,1,1,1,1,1,1,2,2,2,0,0,0,0,2,0,0,0,0,2,2,2,1
1,1,1,1,1,1,1,1,1,1,1,1,1,1,2,2,2,2,0,0,0,0,0,0,0,2,2,2,2,1
1,1,1,1,1,1,1,1,1,1,1,1,1,1,2,2,2,2,2,0,0,0,0,0,2,2,2,2,2,1
1,1,1,1,1,1,1,1,1,1,1,1,1,1,2,2,2,2,2,2,0,0,0,2,2,2,2,2,2,1
1,1,1,1,1,1,1,1,1,1,1,1,1,1,2,2,2,2,2,2,2,2,2,2,2,2,2,2,2,1
1,1,1,1,1,1,1,1,1,1,1,1,1,1,2,2,2,2,2,2,2,2,2,2,2,2,2,2,2,1
1,1,1,1,1,1,1,1,1,1,1,1,1,1,2,2,2,2,2,2,2,2,2,2,2,2,2,2,2,1
1,1,1,1,1,1,1,1,1,1,1,1,1,1,1,1,1,1,1,1,1,1,1,1,1,1,1,1,1,1
1,1,1,1,1,1,1,1,1,1,1,1,1,1,1,1,1,1,1,1,1,1,1,1,1,1,1,1,1,1
1,1,1,1,1,1,1,1,1,1,1,1,1,1,1,1,1,1,1,1,1,1,1,1,1,1,1,1,1,1
endlayer

layer
1,1,1,1,1,1,1,1,1,1,1,1,1,1,1,1,1,1,1,1,1,1,1,1,1,1,1,1,1,1
1,1,1,1,1,1,1,1,1,1,1,1,1,1,1,1,1,1,1,1,1,1,1,1,1,1,1,1,1,1
1,1,1,1,1,1,1,1,1,1,1,1,1,1,1,1,1,1,1,1,1,1,1,1,1,1,1,1,1,1
1,1,1,1,1,1,1,1,1,1,1,1,1,1,2,2,2,2,2,2,2,2,2,2,2,2,2,2,2,1
1,1,1,1,1,1,1,1,1,1,1,1,1,1,2,2,2,2,2,2,2,2,2,2,2,2,2,2,2,1
1,1,1,1,1,1,1,1,1,1,1,1,1,1,2,2,2,2,2,2,2,2,2,2,2,2,2,2,2,1
1,1,1,1,1,1,1,1,1,1,1,1,1,1,2,2,2,2,2,2,0,0,0,2,2,2,2,2,2,1
1,1,1,1,1,1,1,1,1,1,1,1,1,1,2,2,2,2,2,0,0,0,0,0,2,2,2,2,2,1
1,1,1,1,1,1,1,1,1,1,1,1,1,1,2,2,2,2,0,0,0,0,0,0,0,2,2,2,2,1
1,1,1,1,1,1,1,1,1,1,1,1,1,1,2,2,2,0,0,0,0,2,0,0,0,0,2,2,2,1
1,1,1,1,1,1,1,1,1,1,1,1,1,1,2,2,2,0,0,0,2,2,2,0,0,0,2,2,2,1
1,1,1,1,1,1,1,1,1,1,1,1,1,1,2,2,2,0,0,0,0,2,0,0,0,0,2,2,2,1
1,1,1,1,1,1,1,1,1,1,1,1,1,1,2,2,2,2,0,0,0,0,0,0,0,2,2,2,2,1
1,1,1,1,1,1,1,1,1,1,1,1,1,1,2,2,2,2,2,0,0,0,0,0,2,2,2,2,2,1
1,1,1,1,1,1,1,1,1,1,1,1,1,1,2,2,2,2,2,2,0,0,0,2,2,2,2,2,2,1
1,1,1,1,1,1,1,1,1,1,1,1,1,1,2,2,2,2,2,2,2,2,2,2,2,2,2,2,2,1
1,1,1,1,1,1,1,1,1,1,1,1,1,1,2,2,2,2,2,2,2,2,2,2,2,2,2,2,2,1
1,1,1,1,1,1,1,1,1,1,1,1,1,1,2,2,2,2,2,2,2,2,2,2,2,2,2,2,2,1
1,1,1,1,1,1,1,1,1,1,1,1,1,1,1,1,1,1,1,1,1,1,1,1,1,1,1,1,1,1
1,1,1,1,1,1,1,1,1,1,1,1,1,1,1,1,1,1,1,1,1,1,1,1,1,1,1,1,1,1
1,1,1,1,1,1,1,1,1,1,1,1,1,1,1,1,1,1,1,1,1,1,1,1,1,1,1,1,1,1
endlayer

layer
1,1,1,1,1,1,1,1,1,1,1,1,1,1,1,1,1,1,1,1,1,1,1,1,1,1,1,1,1,1
1,1,1,1,1,1,1,1,1,1,1,1,1,1,1,1,1,1,1,1,1,1,1,1,1,1,1,1,1,1
1,1,1,1,1,1,1,1,1,1,1,1,1,1,1,1,1,1,1,1,1,1,1,1,1,1,1,1,1,1
1,1,1,1,1,1,1,1,1,1,1,1,1,1,2,2,2,2,2,2,2,2,2,2,2,2,2,2,2,1
1,1,1,1,1,1,1,1,1,1,1,1,1,1,2,2,2,2,2,2,2,2,2,2,2,2,2,2,2,1
1,1,1,1,1,1,1,1,1,1,1,1,1,1,2,2,2,2,2,2,2,2,2,2,2,2,2,2,2,1
1,1,1,1,1,1,1,1,1,1,1,1,1,1,2,2,2,2,2,2,0,0,0,2,2,2,2,2,2,1
1,1,1,1,1,1,1,1,1,1,1,1,1,1,2,2,2,2,2,0,0,0,0,0,2,2,2,2,2,1
1,1,1,1,1,1,1,1,1,1,1,1,1,1,2,2,2,2,0,0,0,0,0,0,0,2,2,2,2,1
1,1,1,1,1,1,1,1,1,1,1,1,1,1,2,2,2,0,0,0,0,2,0,0,0,0,2,2,2,1
1,1,1,1,1,1,1,1,1,1,1,1,1,1,2,2,2,0,0,0,2,2,2,0,0,0,2,2,2,1
1,1,1,1,1,1,1,1,1,1,1,1,1,1,2,2,2,0,0,0,0,2,0,0,0,0,2,2,2,1
1,1,1,1,1,1,1,1,1,1,1,1,1,1,2,2,2,2,0,0,0,0,0,0,0,2,2,2,2,1
1,1,1,1,1,1,1,1,1,1,1,1,1,1,2,2,2,2,2,0,0,0,0,0,2,2,2,2,2,1
1,1,1,1,1,1,1,1,1,1,1,1,1,1,2,2,2,2,2,2,0,0,0,2,2,2,2,2,2,1
1,1,1,1,1,1,1,1,1,1,1,1,1,1,2,2,2,2,2,2,2,2,2,2,2,2,2,2,2,1
1,1,1,1,1,1,1,1,1,1,1,1,1,1,2,2,2,2,2,2,2,2,2,2,2,2,2,2,2,1
1,1,1,1,1,1,1,1,1,1,1,1,1,1,2,2,2,2,2,2,2,2,2,2,2,2,2,2,2,1
1,1,1,1,1,1,1,1,1,1,1,1,1,1,1,1,1,1,1,1,1,1,1,1,1,1,1,1,1,1
1,1,1,1,1,1,1,1,1,1,1,1,1,1,1,1,1,1,1,1,1,1,1,1,1,1,1,1,1,1
1,1,1,1,1,1,1,1,1,1,1,1,1,1,1,1,1,1,1,1,1,1,1,1,1,1,1,1,1,1
endlayer

layer
1,1,1,1,1,1,1,1,1,1,1,1,1,1,1,1,1,1,1,1,1,1,1,1,1,1,1,1,1,1
1,1,1,1,1,1,1,1,1,1,1,1,1,1,1,1,1,1,1,1,1,1,1,1,1,1,1,1,1,1
1,1,1,1,1,1,1,1,1,1,1,1,1,1,1,1,1,1,1,1,1,1,1,1,1,1,1,1,1,1
1,1,1,1,1,1,1,1,1,1,1,1,1,1,2,2,2,2,2,2,2,2,2,2,2,2,2,2,2,1
1,1,1,1,1,1,1,1,1,1,1,1,1,1,2,2,2,2,2,2,2,2,2,2,2,2,2,2,2,1
1,1,1,1,1,1,1,1,1,1,1,1,1,1,2,2,2,2,2,2,2,2,2,2,2,2,2,2,2,1
1,1,1,1,1,1,1,1,1,1,1,1,1,1,2,2,2,2,2,2,0,0,0,2,2,2,2,2,2,1
1,1,1,1,1,1,1,1,1,1,1,1,1,1,2,2,2,2,2,0,0,0,0,0,2,2,2,2,2,1
1,1,1,1,1,1,1,1,1,1,1,1,1,1,2,2,2,2,0,0,0,0,0,0,0,2,2,2,2,1
1,1,1,1,1,1,1,1,1,1,1,1,1,1,2,2,2,0,0,0,0,2,0,0,0,0,2,2,2,1
1,1,1,1,1,1,1,1,1,1,1,1,1,1,2,2,2,0,0,0,2,2,2,0,0,0,2,2,2,1
1,1,1,1,1,1,1,1,1,1,1,1,1,1,2,2,2,0,0,0,0,2,0,0,0,0,2,2,2,1
1,1,1,1,1,1,1,1,1,1,1,1,1,1,2,2,2,2,0,0,0,0,0,0,0,2,2,2,2,1
1,1,1,1,1,1,1,1,1,1,1,1,1,1,2,2,2,2,2,0,0,0,0,0,2,2,2,2,2,1
1,1,1,1,1,1,1,1,1,1,1,1,1,1,2,2,2,2,2,2,0,0,0,2,2,2,2,2,2,1
1,1,1,1,1,1,1,1,1,1,1,1,1,1,2,2,2,2,2,2,2,2,2,2,2,2,2,2,2,1
1,1,1,1,1,1,1,1,1,1,1,1,1,1,2,2,2,2,2,2,2,2,2,2,2,2,2,2,2,1
1,1,1,1,1,1,1,1,1,1,1,1,1,1,2,2,2,2,2,2,2,2,2,2,2,2,2,2,2,1
1,1,1,1,1,1,1,1,1,1,1,1,1,1,1,1,1,1,1,1,1,1,1,1,1,1,1,1,1,1
1,1,1,1,1,1,1,1,1,1,1,1,1,1,1,1,1,1,1,1,1,1,1,1,1,1,1,1,1,1
1,1,1,1,1,1,1,1,1,1,1,1,1,1,1,1,1,1,1,1,1,1,1,1,1,1,1,1,1,1
endlayer

layer
1,1,1,1,1,1,1,1,1,1,1,1,1,1,1,1,1,1,1,1,1,1,1,1,1,1,1,1,1,1
1,1,1,1,1,1,1,1,1,1,1,1,1,1,1,1,1,1,1,1,1,1,1,1,1,1,1,1,1,1
1,1,1,1,1,1,1,1,1,1,1,1,1,1,1,1,1,1,1,1,1,1,1,1,1,1,1,1,1,1
1,1,1,1,1,1,1,1,1,1,1,1,1,1,2,2,2,2,2,2,2,2,2,2,2,2,2,2,2,1
1,1,1,1,1,1,1,1,1,1,1,1,1,1,2,2,2,2,2,2,0,0,0,2,2,2,2,2,2,1
1,1,1,1,1,1,1,1,1,1,1,1,1,1,2,2,2,2,2,0,0,0,0,0,2,2,2,2,2,1
1,1,1,1,1,1,1,1,1,1,1,1,1,1,2,2,2,0,0,0,0,0,0,0,0,2,2,2,2,1
1,1,1,1,1,1,1,1,1,1,1,1,1,1,2,2,2,0,0,0,0,0,0,0,0,0,2,2,2,1
1,1,1,1,1,1,1,1,1,1,1,1,1,1,2,2,0,0,0,0,0,0,0,0,0,0,0,2,2,1
1,1,1,1,1,1,1,1,1,1,1,1,1,1,2,0,0,0,0,0,0,0,0,0,0,0,0,0,2,1
1,1,1,1,1,1,1,1,1,1,1,1,1,1,2,0,0,0,0,0,0,2,0,0,0,0,0,0,2,1
1,1,1,1,1,1,1,1,1,1,1,1,1,1,2,0,0,0,0,0,0,0,0,0,0,0,0,0,2,1
1,1,1,1,1,1,1,1,1,1,1,1,1,1,2,2,0,0,0,0,0,0,0,0,0,0,0,2,2,1
1,1,1,1,1,1,1,1,1,1,1,1,1,1,2,2,2,0,0,0,0,0,0,0,0,0,2,2,2,1
1,1,1,1,1,1,1,1,1,1,1,1,1,1,2,2,2,2,0,0,0,0,0,0,0,2,2,2,2,1
1,1,1,1,1,1,1,1,1,1,1,1,1,1,2,2,2,2,2,0,0,0,0,0,2,2,2,2,2,1
1,1,1,1,1,1,1,1,1,1,1,1,1,1,2,2,2,2,2,2,0,0,0,2,2,2,2,2,2,1
1,1,1,1,1,1,1,1,1,1,1,1,1,1,2,2,2,2,2,2,2,2,2,2,2,2,2,2,2,1
1,1,1,1,1,1,1,1,1,1,1,1,1,1,1,1,1,1,1,1,1,1,1,1,1,1,1,1,1,1
1,1,1,1,1,1,1,1,1,1,1,1,1,1,1,1,1,1,1,1,1,1,1,1,1,1,1,1,1,1
1,1,1,1,1,1,1,1,1,1,1,1,1,1,1,1,1,1,1,1,1,1,1,1,1,1,1,1,1,1
endlayer

layer
1,1,1,1,1,1,1,1,1,1,1,1,1,1,1,1,1,1,1,1,1,1,1,1,1,1,1,1,1,1
1,1,1,1,1,1,1,1,1,1,1,1,1,1,1,1,1,1,1,1,1,1,1,1,1,1,1,1,1,1
1,1,1,1,1,1,1,1,1,1,1,1,1,1,1,1,1,1,1,1,1,1,1,1,1,1,1,1,1,1
1,1,1,1,1,1,1,1,1,1,1,1,1,1,2,2,2,2,2,2,2,2,2,2,2,2,2,2,2,1
1,1,1,1,1,1,1,1,1,1,1,1,1,1,2,2,2,2,0,2,0,0,0,2,2,2,2,2,2,1
1,1,1,1,1,1,1,1,1,1,1,1,1,1,2,2,2,2,2,0,0,0,0,0,2,0,2,2,2,1
1,1,1,1,1,1,1,1,1,1,1,1,1,1,2,2,2,0,0,0,0,0,0,0,0,2,0,2,2,1
1,1,1,1,1,1,1,1,1,1,1,1,1,1,2,0,2,0,0,0,0,0,0,0,0,0,2,0,2,1
1,1,1,1,1,1,1,1,1,1,1,1,1,1,2,2,0,0,0,0,0,0,0,0,0,0,0,2,2,1
1,1,1,1,1,1,1,1,1,1,1,1,1,1,2,0,0,0,0,0,0,0,0,0,0,0,0,0,2,1
1,1,1,1,1,1,1,1,1,1,1,1,1,1,2,0,0,0,0,0,0,4,0,0,0,0,0,0,2,1
1,1,1,1,1,1,1,1,1,1,1,1,1,1,2,0,0,0,0,0,0,0,0,0,0,0,0,0,2,1
1,1,1,1,1,1,1,1,1,1,1,1,1,1,2,2,0,0,0,0,0,0,0,0,0,0,0,2,2,1
1,1,1,1,1,1,1,1,1,1,1,1,1,1,2,2,2,0,0,0,0,0,0,0,0,0,2,2,2,1
1,1,1,1,1,1,1,1,1,1,1,1,1,1,2,2,0,2,0,0,0,0,0,0,0,2,0,2,2,1
1,1,1,1,1,1,1,1,1,1,1,1,1,1,2,2,2,0,2,0,0,0,0,0,2,0,2,2,2,1
1,1,1,1,1,1,1,1,1,1,1,1,1,1,2,2,2,2,0,2,0,0,0,2,0,2,2,2,2,1
1,1,1,1,1,1,1,1,1,1,1,1,1,1,2,2,2,2,2,2,2,2,2,2,2,2,2,2,2,1
1,1,1,1,1,1,1,1,1,1,1,1,1,1,1,1,1,1,1,1,1,1,1,1,1,1,1,1,1,1
1,1,1,1,1,1,1,1,1,1,1,1,1,1,1,1,1,1,1,1,1,1,1,1,1,1,1,1,1,1
1,1,1,1,1,1,1,1,1,1,1,1,1,1,1,1,1,1,1,1,1,1,1,1,1,1,1,1,1,1
endlayer

layer
1,1,1,1,1,1,1,1,1,1,1,1,1,1,1,1,1,1,1,1,1,1,1,1,1,1,1,1,1,1
1,1,1,1,1,1,1,1,1,1,1,1,1,1,1,1,1,1,1,1,1,1,1,1,1,1,1,1,1,1
1,1,1,1,1,1,1,1,1,1,1,1,1,1,1,1,1,1,1,1,1,1,1,1,1,1,1,1,1,1
1,1,1,1,1,1,1,1,1,1,1,1,1,1,2,2,2,2,2,2,2,2,2,2,2,2,2,2,2,1
1,1,1,1,1,1,1,1,1,1,1,1,1,1,2,2,2,2,2,2,0,0,0,2,2,2,2,2,2,1
1,1,1,1,1,1,1,1,1,1,1,1,1,1,2,2,2,2,2,0,0,0,0,0,2,2,2,2,2,1
1,1,1,1,1,1,1,1,1,1,1,1,1,1,2,2,2,0,0,0,0,0,0,0,0,2,2,2,2,1
1,1,1,1,1,1,1,1,1,1,1,1,1,1,2,2,2,0,0,0,0,0,0,0,0,0,2,2,2,1
1,1,1,1,1,1,1,1,1,1,1,1,1,1,2,2,0,0,0,0,0,0,0,0,0,0,0,2,2,1
1,1,1,1,1,1,1,1,1,1,1,1,1,1,2,0,0,0,0,0,0,0,0,0,0,0,0,0,2,1
1,1,1,1,1,1,1,1,1,1,1,1,1,1,2,0,0,0,0,0,0,0,0,0,0,0,0,0,2,1
1,1,1,1,1,1,1,1,1,1,1,1,1,1,2,0,0,0,0,0,0,0,0,0,0,0,0,0,2,1
1,1,1,1,1,1,1,1,1,1,1,1,1,1,2,2,0,0,0,0,0,0,0,0,0,0,0,2,2,1
1,1,1,1,1,1,1,1,1,1,1,1,1,1,2,2,2,0,0,0,0,0,0,0,0,0,2,2,2,1
1,1,1,1,1,1,1,1,1,1,1,1,1,1,2,2,2,2,0,0,0,0,0,0,0,2,2,2,2,1
1,1,1,1,1,1,1,1,1,1,1,1,1,1,2,2,2,2,2,0,0,0,0,0,2,2,2,2,2,1
1,1,1,1,1,1,1,1,1,1,1,1,1,1,2,2,2,2,2,2,0,0,0,2,2,2,2,2,2,1
1,1,1,1,1,1,1,1,1,1,1,1,1,1,2,2,2,2,2,2,2,2,2,2,2,2,2,2,2,1
1,1,1,1,1,1,1,1,1,1,1,1,1,1,1,1,1,1,1,1,1,1,1,1,1,1,1,1,1,1
1,1,1,1,1,1,1,1,1,1,1,1,1,1,1,1,1,1,1,1,1,1,1,1,1,1,1,1,1,1
1,1,1,1,1,1,1,1,1,1,1,1,1,1,1,1,1,1,1,1,1,1,1,1,1,1,1,1,1,1
endlayer

layer
1,1,1,1,1,1,1,1,1,1,1,1,1,1,1,1,1,1,1,1,1,1,1,1,1,1,1,1,1,1
1,1,1,1,1,1,1,1,1,1,1,1,1,1,1,1,1,1,1,1,1,1,1,1,1,1,1,1,1,1
1,1,1,1,1,1,1,1,1,1,1,1,1,1,1,1,1,1,1,1,1,1,1,1,1,1,1,1,1,1
1,1,1,1,1,1,1,1,1,1,1,1,1,1,2,2,2,2,2,2,2,2,2,2,2,2,2,2,2,1
1,1,1,1,1,1,1,1,1,1,1,1,1,1,2,2,2,2,2,2,2,2,2,2,2,2,2,2,2,1
1,1,1,1,1,1,1,1,1,1,1,1,1,1,2,2,2,2,2,2,2,2,2,2,2,2,2,2,2,1
1,1,1,1,1,1,1,1,1,1,1,1,1,1,2,2,2,0,2,2,2,2,2,2,2,2,2,2,2,1
1,1,1,1,1,1,1,1,1,1,1,1,1,1,2,2,2,2,2,2,2,2,2,2,2,2,2,2,2,1
1,1,1,1,1,1,1,1,1,1,1,1,1,1,2,2,2,2,2,2,2,2,2,2,2,2,2,2,2,1
1,1,1,1,1,1,1,1,1,1,1,1,1,1,2,2,2,0,2,2,2,2,2,2,2,2,2,0,2,1
1,1,1,1,1,1,1,1,1,1,1,1,1,1,2,2,2,2,2,2,2,2,2,2,2,2,2,2,2,1
1,1,1,1,1,1,1,1,1,1,1,1,1,1,2,2,2,2,2,2,2,2,2,5,2,2,2,2,2,1
1,1,1,1,1,1,1,1,1,1,1,1,1,1,2,2,2,2,2,2,2,6,2,2,2,2,2,2,2,1
1,1,1,1,1,1,1,1,1,1,1,1,1,1,2,2,2,2,2,2,2,2,2,2,2,2,2,2,2,1
1,1,1,1,1,1,1,1,1,1,1,1,1,1,2,2,2,2,2,2,2,2,2,2,2,2,2,2,2,1
1,1,1,1,1,1,1,1,1,1,1,1,1,1,2,2,2,2,2,2,2,2,2,2,2,2,2,2,2,1
1,1,1,1,1,1,1,1,1,1,1,1,1,1,2,2,2,2,2,2,2,2,2,2,2,2,2,2,2,1
1,1,1,1,1,1,1,1,1,1,1,1,1,1,2,2,2,2,2,2,2,2,2,2,2,2,2,2,2,1
1,1,1,1,1,1,1,1,1,1,1,1,1,1,1,1,1,1,1,1,1,1,1,1,1,1,1,1,1,1
1,1,1,1,1,1,1,1,1,1,1,1,1,1,1,1,1,1,1,1,1,1,1,1,1,1,1,1,1,1
1,1,1,1,1,1,1,1,1,1,1,1,1,1,1,1,1,1,1,1,1,1,1,1,1,1,1,1,1,1
endlayer

layer
1,1,1,1,1,1,1,1,1,1,1,1,1,1,1,1,1,1,1,1,1,1,1,1,1,1,1,1,1,1
1,1,1,1,1,1,1,1,1,1,1,1,1,1,1,1,1,1,1,1,1,1,1,1,1,1,1,1,1,1
1,1,1,1,1,1,1,1,1,1,1,1,1,1,1,1,1,1,1,1,1,1,1,1,1,1,1,1,1,1
1,1,1,1,1,1,1,1,1,1,1,1,1,1,2,2,2,2,2,2,2,2,2,2,2,2,2,2,2,1
1,1,1,1,1,1,1,1,1,1,1,1,1,1,2,0,0,0,2,0,0,0,0,0,0,0,0,0,2,1
1,1,1,1,1,1,1,1,1,1,1,1,1,1,2,0,2,0,2,0,2,0,2,2,2,0,2,0,2,1
1,1,1,1,1,1,1,1,1,1,1,1,1,1,2,0,2,0,2,0,2,0,0,0,2,0,2,0,2,1
1,1,1,1,1,1,1,1,1,1,1,1,1,1,2,0,2,2,2,0,2,0,2,0,2,0,2,0,2,1
1,1,1,1,1,1,1,1,1,1,1,1,1,1,2,0,2,2,2,0,2,0,2,0,2,0,2,2,2,1
1,1,1,1,1,1,1,1,1,1,1,1,1,1,2,0,2,0,2,0,2,0,2,0,2,0,2,0,2,1
1,1,1,1,1,1,1,1,1,1,1,1,1,1,2,0,2,0,0,0,2,0,2,0,2,0,2,0,2,1
1,1,1,1,1,1,1,1,1,1,1,1,1,1,2,0,2,2,0,0,0,0,2,2,2,0,2,0,2,1
1,1,1,1,1,1,1,1,1,1,1,1,1,1,2,0,2,2,2,2,2,2,2,0,0,0,0,0,2,1
1,1,1,1,1,1,1,1,1,1,1,1,1,1,2,0,2,2,2,0,0,0,0,0,2,2,2,2,2,1
1,1,1,1,1,1,1,1,1,1,1,1,1,1,2,0,2,2,2,0,2,0,2,0,2,2,2,2,2,1
1,1,1,1,1,1,1,1,1,1,1,1,1,1,2,0,2,2,2,0,2,2,2,2,2,2,2,0,2,1
1,1,1,1,1,1,1,1,1,1,1,1,1,1,2,0,0,0,0,0,0,0,0,0,0,0,0,0,2,1
1,1,1,1,1,1,1,1,1,1,1,1,1,1,2,2,2,2,2,2,2,2,2,2,2,2,2,2,2,1
1,1,1,1,1,1,1,1,1,1,1,1,1,1,1,1,1,1,1,1,1,1,1,1,1,1,1,1,1,1
1,1,1,1,1,1,1,1,1,1,1,1,1,1,1,1,1,1,1,1,1,1,1,1,1,1,1,1,1,1
1,1,1,1,1,1,1,1,1,1,1,1,1,1,1,1,1,1,1,1,1,1,1,1,1,1,1,1,1,1
endlayer

layer
1,1,1,1,1,1,1,1,1,1,1,1,1,1,1,1,1,1,1,1,1,1,1,1,1,1,1,1,1,1
1,1,1,1,1,1,1,1,1,1,1,1,1,1,1,1,1,1,1,1,1,1,1,1,1,1,1,1,1,1
1,1,1,1,1,1,1,1,1,1,1,1,1,1,1,1,1,1,1,1,1,1,1,1,1,1,1,1,1,1
1,1,1,1,1,1,1,1,1,1,1,1,1,1,2,2,2,2,2,2,2,2,2,2,2,2,2,2,2,1
1,1,1,1,1,1,1,1,1,1,1,1,1,1,2,0,0,0,2,0,0,0,0,0,0,0,0,0,2,1
1,1,1,1,1,1,1,1,1,1,1,1,1,1,2,0,2,0,2,0,2,0,2,2,2,0,2,0,2,1
1,1,1,1,1,1,1,1,1,1,1,1,1,1,2,0,2,0,2,0,2,0,0,0,2,0,2,0,2,1
1,1,1,1,1,1,1,1,1,1,1,1,1,1,2,0,2,2,2,0,2,0,2,0,2,0,2,0,2,1
1,1,1,1,1,1,1,1,1,1,1,1,1,1,2,0,2,2,2,0,2,0,2,0,2,0,2,2,2,1
1,1,1,1,1,1,1,1,1,1,1,1,1,1,2,0,2,0,2,0,2,0,2,0,2,0,2,0,2,1
1,1,1,1,1,1,1,1,1,1,1,1,1,1,2,0,2,0,0,0,2,0,2,0,2,0,2,0,2,1
1,1,1,1,1,1,1,1,1,1,1,1,1,1,2,0,2,0,0,0,0,0,2,2,2,0,2,0,2,1
1,1,1,1,1,1,1,1,1,1,1,1,1,1,2,0,2,2,2,2,2,2,2,0,0,0,0,0,2,1
1,1,1,1,1,1,1,1,1,1,1,1,1,1,2,0,2,2,2,0,0,0,0,0,2,2,2,2,2,1
1,1,1,1,1,1,1,1,1,1,1,1,1,1,2,0,2,2,2,0,2,0,2,0,2,2,2,2,2,1
1,1,1,1,1,1,1,1,1,1,1,1,1,1,2,0,2,2,2,0,2,2,2,2,2,2,2,0,2,1
1,1,1,1,1,1,1,1,1,1,1,1,1,1,2,0,0,0,0,0,0,0,0,0,0,0,0,0,2,1
1,1,1,1,1,1,1,1,1,1,1,1,1,1,2,2,2,2,2,2,2,2,2,2,2,2,2,2,2,1
1,1,1,1,1,1,1,1,1,1,1,1,1,1,1,1,1,1,1,1,1,1,1,1,1,1,1,1,1,1
1,1,1,1,1,1,1,1,1,1,1,1,1,1,1,1,1,1,1,1,1,1,1,1,1,1,1,1,1,1
1,1,1,1,1,1,1,1,1,1,1,1,1,1,1,1,1,1,1,1,1,1,1,1,1,1,1,1,1,1
endlayer

layer
1,1,1,1,1,1,1,1,1,1,1,1,1,1,1,1,1,1,1,1,1,1,1,1,1,1,1,1,1,1
1,1,1,1,1,1,1,1,1,1,1,1,1,1,1,1,1,1,1,1,1,1,1,1,1,1,1,1,1,1
1,1,1,1,1,1,1,1,1,1,1,1,1,1,1,1,1,1,1,1,1,1,1,1,1,1,1,1,1,1
1,1,1,1,1,1,1,1,1,1,1,1,1,1,2,2,2,2,2,2,2,2,2,2,2,2,2,2,2,1
1,1,1,1,1,1,1,1,1,1,1,1,1,1,2,0,0,0,2,0,0,0,0,0,0,0,0,0,2,1
1,1,1,1,1,1,1,1,1,1,1,1,1,1,2,0,2,0,2,0,2,2,2,2,2,0,2,0,2,1
1,1,1,1,1,1,1,1,1,1,1,1,1,1,2,0,2,0,2,0,2,0,0,0,2,0,2,0,2,1
1,1,1,1,1,1,1,1,1,1,1,1,1,1,2,0,2,2,2,0,2,0,2,0,2,0,2,0,2,1
1,1,1,1,1,1,1,1,1,1,1,1,1,1,2,0,2,2,2,0,2,0,2,0,2,0,2,2,2,1
1,1,1,1,1,1,1,1,1,1,1,1,1,1,2,0,2,2,2,0,2,0,2,0,2,0,2,0,2,1
1,1,1,1,1,1,1,1,1,1,1,1,1,1,2,0,2,2,0,0,2,0,2,0,2,0,2,0,2,1
1,1,1,1,1,1,1,1,1,1,1,1,1,1,2,0,2,2,0,0,0,0,2,2,2,0,2,0,2,1
1,1,1,1,1,1,1,1,1,1,1,1,1,1,2,0,2,2,2,2,2,2,2,0,0,0,0,0,2,1
1,1,1,1,1,1,1,1,1,1,1,1,1,1,2,0,2,2,2,0,0,0,2,0,2,2,2,2,2,1
1,1,1,1,1,1,1,1,1,1,1,1,1,1,2,0,2,2,2,0,2,0,2,0,2,2,2,2,2,1
1,1,1,1,1,1,1,1,1,1,1,1,1,1,2,0,2,2,2,0,2,2,2,2,2,2,2,0,2,1
1,1,1,1,1,1,1,1,1,1,1,1,1,1,2,0,0,0,0,0,0,0,0,0,0,0,0,0,2,1
1,1,1,1,1,1,1,1,1,1,1,1,1,1,2,2,2,2,2,2,2,2,2,2,2,2,2,2,2,1
1,1,1,1,1,1,1,1,1,1,1,1,1,1,1,1,1,1,1,1,1,1,1,1,1,1,1,1,1,1
1,1,1,1,1,1,1,1,1,1,1,1,1,1,1,1,1,1,1,1,1,1,1,1,1,1,1,1,1,1
1,1,1,1,1,1,1,1,1,1,1,1,1,1,1,1,1,1,1,1,1,1,1,1,1,1,1,1,1,1
endlayer

layer
1,1,1,1,1,1,1,1,1,1,1,1,1,1,1,1,1,1,1,1,1,1,1,1,1,1,1,1,1,1
1,1,1,1,1,1,1,1,1,1,1,1,1,1,1,1,1,1,1,1,1,1,1,1,1,1,1,1,1,1
1,1,1,1,1,1,1,1,1,1,1,1,1,1,1,1,1,1,1,1,1,1,1,1,1,1,1,1,1,1
1,1,1,1,1,1,1,1,1,1,1,1,1,1,2,2,2,2,2,2,2,2,2,2,2,2,2,2,2,1
1,1,1,1,1,1,1,1,1,1,1,1,1,1,2,2,2,2,2,2,2,2,2,2,2,2,2,2,2,1
1,1,1,1,1,1,1,1,1,1,1,1,1,1,2,2,2,2,2,2,2,2,2,2,2,2,2,2,2,1
1,1,1,1,1,1,1,1,1,1,1,1,1,1,2,2,2,2,2,2,2,2,2,2,2,0,2,2,2,1
1,1,1,1,1,1,1,1,1,1,1,1,1,1,2,2,2,2,2,2,2,2,2,2,2,2,2,2,2,1
1,1,1,1,1,1,1,1,1,1,1,1,1,1,2,2,2,2,2,2,2,2,2,2,2,2,2,2,2,1
1,1,1,1,1,1,1,1,1,1,1,1,1,1,2,2,2,2,2,2,2,2,2,2,2,2,2,2,2,1
1,1,1,1,1,1,1,1,1,1,1,1,1,1,2,2,2,2,2,2,2,2,2,2,2,2,2,2,2,1
1,1,1,1,1,1,1,1,1,1,1,1,1,1,2,2,2,2,2,2,2,2,2,2,2,2,2,2,2,1
1,1,1,1,1,1,1,1,1,1,1,1,1,1,2,2,2,2,2,2,2,2,2,2,2,2,2,2,2,1
1,1,1,1,1,1,1,1,1,1,1,1,1,1,2,2,2,2,2,2,2,2,2,2,2,2,2,2,2,1
1,1,1,1,1,1,1,1,1,1,1,1,1,1,2,2,2,2,2,2,2,2,2,2,2,2,2,2,2,1
1,1,1,1,1,1,1,1,1,1,1,1,1,1,2,2,2,2,2,2,2,2,2,2,2,2,2,2,2,1
1,1,1,1,1,1,1,1,1,1,1,1,1,1,2,0,2,2,2,2,2,2,2,2,2,2,2,0,2,1
1,1,1,1,1,1,1,1,1,1,1,1,1,1,2,2,2,2,2,2,2,2,2,2,2,2,2,2,2,1
1,1,1,1,1,1,1,1,1,1,1,1,1,1,1,1,1,1,1,1,1,1,1,1,1,1,1,1,1,1
1,1,1,1,1,1,1,1,1,1,1,1,1,1,1,1,1,1,1,1,1,1,1,1,1,1,1,1,1,1
1,1,1,1,1,1,1,1,1,1,1,1,1,1,1,1,1,1,1,1,1,1,1,1,1,1,1,1,1,1
endlayer

layer
1,1,1,1,1,1,1,1,1,1,1,1,1,1,1,1,1,1,1,1,1,1,1,1,1,1,1,1,1,1
1,1,1,1,1,1,1,1,1,1,1,1,1,1,1,1,1,1,1,1,1,1,1,1,1,1,1,1,1,1
1,1,1,1,1,1,1,1,1,1,1,1,1,1,1,1,1,1,1,1,1,1,1,1,1,1,1,1,1,1
1,1,1,1,1,1,1,1,1,1,1,1,1,1,2,2,2,2,2,2,2,2,2,2,2,2,2,2,2,1
1,1,1,1,1,1,1,1,1,1,1,1,1,1,2,0,0,0,0,0,0,0,0,0,2,0,0,0,2,1
1,1,1,1,1,1,1,1,1,1,1,1,1,1,2,0,2,2,2,2,2,0,2,2,0,0,2,0,2,1
1,1,1,1,1,1,1,1,1,1,1,1,1,1,2,0,2,0,0,0,0,0,2,2,0,0,2,0,2,1
1,1,1,1,1,1,1,1,1,1,1,1,1,1,2,0,2,0,0,0,0,0,2,2,2,2,2,0,2,1
1,1,1,1,1,1,1,1,1,1,1,1,1,1,2,0,0,0,0,0,0,0,0,0,0,0,0,0,2,1
1,1,1,1,1,1,1,1,1,1,1,1,1,1,2,0,2,0,0,0,0,0,2,0,2,2,2,2,2,1
1,1,1,1,1,1,1,1,1,1,1,1,1,1,2,0,2,2,2,2,2,2,2,0,0,0,0,0,2,1
1,1,1,1,1,1,1,1,1,1,1,1,1,1,2,0,2,0,0,0,0,0,2,0,2,2,2,0,2,1
1,1,1,1,1,1,1,1,1,1,1,1,1,1,2,0,2,0,2,2,2,0,2,0,0,0,0,0,2,1
1,1,1,1,1,1,1,1,1,1,1,1,1,1,2,0,0,0,2,0,0,0,2,0,2,0,2,0,2,1
1,1,1,1,1,1,1,1,1,1,1,1,1,1,2,2,2,0,2,0,2,2,2,0,2,0,2,0,2,1
1,1,1,1,1,1,1,1,1,1,1,1,1,1,2,0,0,0,2,0,0,0,0,0,2,0,2,0,2,1
1,1,1,1,1,1,1,1,1,1,1,1,1,1,2,0,0,0,2,0,0,0,0,0,2,0,2,0,2,1
1,1,1,1,1,1,1,1,1,1,1,1,1,1,2,2,2,2,2,2,2,2,2,2,2,2,2,2,2,1
1,1,1,1,1,1,1,1,1,1,1,1,1,1,1,1,1,1,1,1,1,1,1,1,1,1,1,1,1,1
1,1,1,1,1,1,1,1,1,1,1,1,1,1,1,1,1,1,1,1,1,1,1,1,1,1,1,1,1,1
1,1,1,1,1,1,1,1,1,1,1,1,1,1,1,1,1,1,1,1,1,1,1,1,1,1,1,1,1,1
endlayer

layer
1,1,1,1,1,1,1,1,1,1,1,1,1,1,1,1,1,1,1,1,1,1,1,1,1,1,1,1,1,1
1,1,1,1,1,1,1,1,1,1,1,1,1,1,1,1,1,1,1,1,1,1,1,1,1,1,1,1,1,1
1,1,1,1,1,1,1,1,1,1,1,1,1,1,1,1,1,1,1,1,1,1,1,1,1,1,1,1,1,1
1,1,1,1,1,1,1,1,1,1,1,1,1,1,2,2,2,2,2,2,2,2,2,2,2,2,2,2,2,1
1,1,1,1,1,1,1,1,1,1,1,1,1,1,2,0,0,0,0,0,0,0,0,0,2,0,0,0,2,1
1,1,1,1,1,1,1,1,1,1,1,1,1,1,2,0,2,2,2,2,2,0,2,2,0,0,2,0,2,1
1,1,1,1,1,1,1,1,1,1,1,1,1,1,2,0,2,0,0,0,0,0,2,2,0,0,2,0,2,1
1,1,1,1,1,1,1,1,1,1,1,1,1,1,2,0,2,0,0,0,0,0,2,2,2,2,2,0,2,1
1,1,1,1,1,1,1,1,1,1,1,1,1,1,2,0,0,0,0,0,0,0,0,0,0,0,0,0,2,1
1,1,1,1,1,1,1,1,1,1,1,1,1,1,2,0,2,0,0,0,0,0,2,0,2,2,2,2,2,1
1,1,1,1,1,1,1,1,1,1,1,1,1,1,2,0,2,2,2,2,2,2,2,0,0,0,0,0,2,1
1,1,1,1,1,1,1,1,1,1,1,1,1,1,2,0,2,0,0,0,0,0,2,0,2,2,2,0,2,1
1,1,1,1,1,1,1,1,1,1,1,1,1,1,2,0,2,0,2,2,2,0,2,0,0,0,0,0,2,1
1,1,1,1,1,1,1,1,1,1,1,1,1,1,2,0,0,0,2,0,0,0,2,0,2,0,2,0,2,1
1,1,1,1,1,1,1,1,1,1,1,1,1,1,2,2,2,0,2,0,2,2,2,0,2,0,2,0,2,1
1,1,1,1,1,1,1,1,1,1,1,1,1,1,2,0,0,0,2,0,0,0,0,0,2,0,2,0,2,1
1,1,1,1,1,1,1,1,1,1,1,1,1,1,2,0,0,0,2,0,0,0,0,0,2,0,2,0,2,1
1,1,1,1,1,1,1,1,1,1,1,1,1,1,2,2,2,2,2,2,2,2,2,2,2,2,2,2,2,1
1,1,1,1,1,1,1,1,1,1,1,1,1,1,1,1,1,1,1,1,1,1,1,1,1,1,1,1,1,1
1,1,1,1,1,1,1,1,1,1,1,1,1,1,1,1,1,1,1,1,1,1,1,1,1,1,1,1,1,1
1,1,1,1,1,1,1,1,1,1,1,1,1,1,1,1,1,1,1,1,1,1,1,1,1,1,1,1,1,1
endlayer

layer
1,1,1,1,1,1,1,1,1,1,1,1,1,1,1,1,1,1,1,1,1,1,1,1,1,1,1,1,1,1
1,1,1,1,1,1,1,1,1,1,1,1,1,1,1,1,1,1,1,1,1,1,1,1,1,1,1,1,1,1
1,1,1,1,1,1,1,1,1,1,1,1,1,1,1,1,1,1,1,1,1,1,1,1,1,1,1,1,1,1
1,1,1,1,1,1,1,1,1,1,1,1,1,1,2,2,2,2,2,2,2,2,2,2,2,2,2,2,2,1
1,1,1,1,1,1,1,1,1,1,1,1,1,1,2,0,0,0,0,0,0,0,0,0,2,0,0,0,2,1
1,1,1,1,1,1,1,1,1,1,1,1,1,1,2,0,2,2,2,2,2,2,2,2,0,0,2,0,2,1
1,1,1,1,1,1,1,1,1,1,1,1,1,1,2,0,2,0,0,0,0,0,2,2,0,0,2,0,2,1
1,1,1,1,1,1,1,1,1,1,1,1,1,1,2,0,2,0,0,0,0,0,2,2,2,2,2,0,2,1
1,1,1,1,1,1,1,1,1,1,1,1,1,1,2,0,0,0,0,0,0,0,0,0,0,0,0,0,2,1
1,1,1,1,1,1,1,1,1,1,1,1,1,1,2,0,2,0,0,0,0,0,2,0,2,2,2,2,2,1
1,1,1,1,1,1,1,1,1,1,1,1,1,1,2,0,2,2,2,2,2,2,2,0,0,0,0,0,2,1
1,1,1,1,1,1,1,1,1,1,1,1,1,1,2,0,2,0,0,0,0,0,2,2,2,2,2,0,2,1
1,1,1,1,1,1,1,1,1,1,1,1,1,1,2,0,2,0,2,2,2,0,2,0,0,0,0,0,2,1
1,1,1,1,1,1,1,1,1,1,1,1,1,1,2,0,0,0,2,0,0,0,2,0,2,0,2,0,2,1
1,1,1,1,1,1,1,1,1,1,1,1,1,1,2,2,2,0,2,0,2,2,2,0,2,0,2,0,2,1
1,1,1,1,1,1,1,1,1,1,1,1,1,1,2,0,0,0,2,0,0,0,0,0,2,0,2,0,2,1
1,1,1,1,1,1,1,1,1,1,1,1,1,1,2,0,0,0,2,0,0,0,0,0,2,0,2,0,2,1
1,1,1,1,1,1,1,1,1,1,1,1,1,1,2,2,2,2,2,2,2,2,2,2,2,2,2,2,2,1
1,1,1,1,1,1,1,1,1,1,1,1,1,1,1,1,1,1,1,1,1,1,1,1,1,1,1,1,1,1
1,1,1,1,1,1,1,1,1,1,1,1,1,1,1,1,1,1,1,1,1,1,1,1,1,1,1,1,1,1
1,1,1,1,1,1,1,1,1,1,1,1,1,1,1,1,1,1,1,1,1,1,1,1,1,1,1,1,1,1
endlayer

layer
1,1,1,1,1,1,1,1,1,1,1,1,1,1,1,1,1,1,1,1,1,1,1,1,1,1,1,1,1,1
1,1,1,1,1,1,1,1,1,1,1,1,1,1,1,1,1,1,1,1,1,1,1,1,1,1,1,1,1,1
1,1,1,1,1,1,1,1,1,1,1,1,1,1,1,1,1,1,1,1,1,1,1,1,1,1,1,1,1,1
1,1,1,1,1,1,1,1,1,1,1,1,1,1,2,2,2,2,2,2,2,2,2,2,2,2,2,2,2,1
1,1,1,1,1,1,1,1,1,1,1,1,1,1,2,2,2,2,2,2,2,2,2,2,2,2,2,2,6,1
1,1,1,1,1,1,1,1,1,1,1,1,1,1,2,2,2,2,2,2,2,0,2,2,2,2,2,2,2,1
1,1,1,1,1,1,1,1,1,1,1,1,1,1,2,2,2,0,2,2,2,2,2,2,2,2,2,2,2,1
1,1,1,1,1,1,1,1,1,1,1,1,1,1,2,2,2,2,2,2,2,2,2,2,2,2,2,0,2,1
1,1,1,1,1,1,1,1,1,1,1,1,1,1,2,2,2,2,2,2,2,2,2,2,2,2,2,2,2,1
1,1,1,1,1,1,1,1,1,1,1,1,1,1,2,2,2,2,2,2,2,2,2,2,2,2,2,2,2,1
1,1,1,1,1,1,1,1,1,1,1,1,1,1,2,2,2,2,2,2,2,2,2,2,2,2,2,2,2,1
1,1,1,1,1,1,1,1,1,1,1,1,1,1,2,2,2,2,2,2,2,2,6,5,2,2,2,2,2,1
1,1,1,1,1,1,1,1,1,1,1,1,1,1,2,2,2,2,2,2,2,2,2,2,2,2,2,2,2,1
1,1,1,1,1,1,1,1,1,1,1,1,1,1,2,2,2,2,2,2,2,2,5,2,2,2,2,2,2,1
1,1,1,1,1,1,1,1,1,1,1,1,1,1,2,2,2,2,2,2,2,2,0,2,2,2,2,2,2,1
1,1,1,1,1,1,1,1,1,1,1,1,1,1,2,2,2,2,2,2,2,0,2,2,2,2,2,2,2,1
1,1,1,1,1,1,1,1,1,1,1,1,1,1,2,2,2,2,2,2,2,2,2,2,2,2,2,2,2,1
1,1,1,1,1,1,1,1,1,1,1,1,1,1,2,2,2,2,2,2,2,2,2,2,2,2,2,2,2,1
1,1,1,1,1,1,1,1,1,1,1,1,1,1,1,1,1,1,1,1,1,1,1,1,1,1,1,1,1,1
1,1,1,1,1,1,1,1,1,1,1,1,1,1,1,1,1,1,1,1,1,1,1,1,1,1,1,1,1,1
1,1,1,1,1,1,1,1,1,1,1,1,1,1,1,1,1,1,1,1,1,1,1,1,1,1,1,1,1,1
endlayer

layer
1,1,1,1,1,1,1,1,1,1,1,1,1,1,1,1,1,1,1,1,1,1,1,1,1,1,1,1,1,1
1,1,1,1,1,1,1,1,1,1,1,1,1,1,1,1,1,1,1,1,1,1,1,1,1,1,1,1,1,1
1,1,1,1,1,1,1,1,1,1,1,1,1,1,1,1,1,1,1,1,1,1,1,1,1,1,1,1,1,1
1,1,1,1,1,1,1,1,1,1,1,1,1,1,2,2,2,2,2,2,2,2,2,2,2,2,2,2,2,1
1,1,1,1,1,1,1,1,1,1,1,1,1,1,2,0,0,0,2,0,0,0,0,0,0,0,0,0,2,1
1,1,1,1,1,1,1,1,1,1,1,1,1,1,2,0,2,0,2,0,2,2,2,2,2,0,2,0,2,1
1,1,1,1,1,1,1,1,1,1,1,1,1,1,2,0,2,0,2,0,2,0,0,0,2,0,2,0,2,1
1,1,1,1,1,1,1,1,1,1,1,1,1,1,2,0,2,2,2,0,2,0,2,0,2,0,2,0,2,1
1,1,1,1,1,1,1,1,1,1,1,1,1,1,2,0,0,0,0,0,2,0,2,0,2,0,2,2,2,1
1,1,1,1,1,1,1,1,1,1,1,1,1,1,2,0,2,2,2,0,2,0,2,0,2,0,2,0,2,1
1,1,1,1,1,1,1,1,1,1,1,1,1,1,2,0,2,0,0,0,2,0,2,0,2,0,2,0,2,1
1,1,1,1,1,1,1,1,1,1,1,1,1,1,2,0,2,0,0,0,0,0,2,2,2,0,2,0,2,1
1,1,1,1,1,1,1,1,1,1,1,1,1,1,2,0,2,0,2,2,2,2,2,0,0,0,0,0,2,1
1,1,1,1,1,1,1,1,1,1,1,1,1,1,2,0,2,0,2,0,0,0,2,0,2,2,2,2,2,1
1,1,1,1,1,1,1,1,1,1,1,1,1,1,2,0,2,0,2,0,2,0,2,0,0,0,0,0,2,1
1,1,1,1,1,1,1,1,1,1,1,1,1,1,2,0,2,0,2,0,2,2,2,2,2,2,2,0,2,1
1,1,1,1,1,1,1,1,1,1,1,1,1,1,2,0,0,0,2,0,0,0,0,0,0,0,0,0,2,1
1,1,1,1,1,1,1,1,1,1,1,1,1,1,2,2,2,2,2,2,2,2,2,2,2,2,2,2,2,1
1,1,1,1,1,1,1,1,1,1,1,1,1,1,1,1,1,1,1,1,1,1,1,1,1,1,1,1,1,1
1,1,1,1,1,1,1,1,1,1,1,1,1,1,1,1,1,1,1,1,1,1,1,1,1,1,1,1,1,1
1,1,1,1,1,1,1,1,1,1,1,1,1,1,1,1,1,1,1,1,1,1,1,1,1,1,1,1,1,1
endlayer

layer
1,1,1,1,1,1,1,1,1,1,1,1,1,1,1,1,1,1,1,1,1,1,1,1,1,1,1,1,1,1
1,1,1,1,1,1,1,1,1,1,1,1,1,1,1,1,1,1,1,1,1,1,1,1,1,1,1,1,1,1
1,1,1,1,1,1,1,1,1,1,1,1,1,1,1,1,1,1,1,1,1,1,1,1,1,1,1,1,1,1
1,1,1,1,1,1,1,1,1,1,1,1,1,1,2,2,2,2,2,2,2,2,2,2,2,2,2,2,2,1
1,1,1,1,1,1,1,1,1,1,1,1,1,1,2,0,0,0,2,0,0,0,0,0,0,0,0,0,2,1
1,1,1,1,1,1,1,1,1,1,1,1,1,1,2,0,2,0,2,0,2,1,2,2,2,0,2,0,2,1
1,1,1,1,1,1,1,1,1,1,1,1,1,1,2,0,2,0,2,0,2,0,0,0,2,0,2,0,2,1
1,1,1,1,1,1,1,1,1,1,1,1,1,1,2,0,2,2,2,0,2,0,2,0,2,0,2,0,2,1
1,1,1,1,1,1,1,1,1,1,1,1,1,1,2,0,0,0,0,0,2,0,2,0,2,0,2,2,2,1
1,1,1,1,1,1,1,1,1,1,1,1,1,1,2,0,2,2,2,0,2,0,2,0,2,0,2,0,2,1
1,1,1,1,1,1,1,1,1,1,1,1,1,1,2,0,2,0,0,0,2,0,2,0,2,0,2,0,2,1
1,1,1,1,1,1,1,1,1,1,1,1,1,1,2,0,2,0,0,0,0,0,2,2,2,0,2,0,2,1
1,1,1,1,1,1,1,1,1,1,1,1,1,1,2,0,2,0,2,2,2,2,2,0,0,0,0,0,2,1
1,1,1,1,1,1,1,1,1,1,1,1,1,1,2,0,2,0,2,0,0,0,2,0,2,2,2,2,2,1
1,1,1,1,1,1,1,1,1,1,1,1,1,1,2,0,2,0,2,0,2,0,1,0,0,0,0,0,2,1
1,1,1,1,1,1,1,1,1,1,1,1,1,1,2,0,2,0,2,0,2,2,2,2,2,2,2,0,2,1
1,1,1,1,1,1,1,1,1,1,1,1,1,1,2,0,0,0,2,0,0,0,0,0,0,0,0,0,2,1
1,1,1,1,1,1,1,1,1,1,1,1,1,1,2,2,2,2,2,2,2,2,2,2,2,2,2,2,2,1
1,1,1,1,1,1,1,1,1,1,1,1,1,1,1,1,1,1,1,1,1,1,1,1,1,1,1,1,1,1
1,1,1,1,1,1,1,1,1,1,1,1,1,1,1,1,1,1,1,1,1,1,1,1,1,1,1,1,1,1
1,1,1,1,1,1,1,1,1,1,1,1,1,1,1,1,1,1,1,1,1,1,1,1,1,1,1,1,1,1
endlayer

layer
1,1,1,1,1,1,1,1,1,1,1,1,1,1,1,1,1,1,1,1,1,1,1,1,1,1,1,1,1,1
1,1,1,1,1,1,1,1,1,1,1,1,1,1,1,1,1,1,1,1,1,1,1,1,1,1,1,1,1,1
1,1,1,1,1,1,1,1,1,1,1,1,1,1,1,1,1,1,1,1,1,1,1,1,1,1,1,1,1,1
1,1,1,1,1,1,1,1,1,1,1,1,1,1,2,2,2,2,2,2,2,2,2,2,2,2,2,2,2,1
1,1,1,1,1,1,1,1,1,1,1,1,1,1,2,0,0,0,2,0,0,0,0,0,0,0,0,0,2,1
1,1,1,1,1,1,1,1,1,1,1,1,1,1,2,0,2,0,2,0,2,2,2,2,2,0,2,0,2,1
1,1,1,1,1,1,1,1,1,1,1,1,1,1,2,0,2,0,2,0,2,0,0,0,2,0,2,0,2,1
1,1,1,1,1,1,1,1,1,1,1,1,1,1,2,0,2,2,2,0,2,0,2,0,2,0,2,0,2,1
1,1,1,1,1,1,1,1,1,1,1,1,1,1,2,0,0,0,0,0,2,0,2,0,2,0,2,2,2,1
1,1,1,1,1,1,1,1,1,1,1,1,1,1,2,0,2,2,2,0,2,0,2,0,2,0,2,0,2,1
1,1,1,1,1,1,1,1,1,1,1,1,1,1,2,0,2,0,0,0,2,0,2,0,2,0,2,0,2,1
1,1,1,1,1,1,1,1,1,1,1,1,1,1,2,0,2,0,0,0,0,0,2,2,2,0,2,0,2,1
1,1,1,1,1,1,1,1,1,1,1,1,1,1,2,0,2,0,2,2,2,2,2,0,0,0,0,0,2,1
1,1,1,1,1,1,1,1,1,1,1,1,1,1,2,0,2,0,2,0,0,0,2,0,2,2,2,2,2,1
1,1,1,1,1,1,1,1,1,1,1,1,1,1,2,0,2,0,2,0,2,0,2,0,0,0,0,0,2,1
1,1,1,1,1,1,1,1,1,1,1,1,1,1,2,0,2,0,2,0,2,2,2,2,2,2,2,0,2,1
1,1,1,1,1,1,1,1,1,1,1,1,1,1,2,0,0,0,2,0,0,0,0,0,0,0,0,0,2,1
1,1,1,1,1,1,1,1,1,1,1,1,1,1,2,2,2,2,2,2,2,2,2,2,2,2,2,2,2,1
1,1,1,1,1,1,1,1,1,1,1,1,1,1,1,1,1,1,1,1,1,1,1,1,1,1,1,1,1,1
1,1,1,1,1,1,1,1,1,1,1,1,1,1,1,1,1,1,1,1,1,1,1,1,1,1,1,1,1,1
1,1,1,1,1,1,1,1,1,1,1,1,1,1,1,1,1,1,1,1,1,1,1,1,1,1,1,1,1,1
endlayer

layer
1,1,1,1,1,1,1,1,1,1,1,1,1,1,1,1,1,1,1,1,1,1,1,1,1,1,1,1,1,1
1,1,1,1,1,1,1,1,1,1,1,1,1,1,1,1,1,1,1,1,1,1,1,1,1,1,1,1,1,1
1,1,1,1,1,1,1,1,1,1,1,1,1,1,1,1,1,1,1,1,1,1,1,1,1,1,1,1,1,1
1,1,1,1,1,1,1,1,1,1,1,1,1,1,2,2,2,2,2,2,2,2,2,2,2,2,2,2,2,1
1,1,1,1,1,1,1,1,1,1,1,1,1,1,2,2,2,2,2,2,2,2,2,2,2,2,2,2,2,1
1,1,1,1,1,1,1,1,1,1,1,1,1,1,2,2,2,2,6,2,2,0,2,2,2,2,2,2,5,1
1,1,1,1,1,1,1,1,1,1,1,1,1,1,2,2,2,2,2,2,2,2,2,2,2,0,2,2,2,1
1,1,1,1,1,1,1,1,1,1,1,1,1,1,2,2,2,2,2,2,2,2,2,2,0,2,2,2,2,1
1,1,1,1,1,1,1,1,1,1,1,1,1,1,2,2,2,2,2,2,2,2,2,2,2,2,2,2,2,1
1,1,1,1,1,1,1,1,1,1,1,1,1,1,2,2,2,2,2,2,2,2,2,2,2,2,2,2,2,1
1,1,1,1,1,1,1,1,1,1,1,1,1,1,2,2,2,2,2,2,2,2,2,2,2,2,2,2,2,1
1,1,1,1,1,1,1,1,1,1,1,1,1,1,2,2,2,2,2,2,2,2,2,0,5,2,2,2,2,1
1,1,1,1,1,1,1,1,1,1,1,1,1,1,2,2,2,2,0,2,2,2,2,2,2,2,2,2,2,1
1,1,1,1,1,1,1,1,1,1,1,1,1,1,2,2,2,2,2,2,2,2,2,2,2,2,2,2,2,1
1,1,1,1,1,1,1,1,1,1,1,1,1,1,2,2,2,2,2,2,2,2,2,2,2,2,2,2,2,1
1,1,1,1,1,1,1,1,1,1,1,1,1,1,2,2,2,2,2,2,2,2,2,2,2,2,2,2,2,1
1,1,1,1,1,1,1,1,1,1,1,1,1,1,2,0,2,2,2,2,2,2,2,2,2,2,2,0,2,1
1,1,1,1,1,1,1,1,1,1,1,1,1,1,2,2,2,2,2,2,2,2,2,2,2,2,2,2,2,1
1,1,1,1,1,1,1,1,1,1,1,1,1,1,1,1,1,1,1,1,1,1,1,1,1,1,1,1,1,1
1,1,1,1,1,1,1,1,1,1,1,1,1,1,1,1,1,1,1,1,1,1,1,1,1,1,1,1,1,1
1,1,1,1,1,1,1,1,1,1,1,1,1,1,1,1,1,1,1,1,1,1,1,1,1,1,1,1,1,1
endlayer

layer
1,1,1,1,1,1,1,1,1,1,1,1,1,1,1,1,1,1,1,1,1,1,1,1,1,1,1,1,1,1
1,1,1,1,1,1,1,1,1,1,1,1,1,1,1,1,1,1,1,1,1,1,1,1,1,1,1,1,1,1
1,1,1,1,1,1,1,1,1,1,1,1,1,1,1,1,1,1,1,1,1,1,1,1,1,1,1,1,1,1
1,1,1,1,1,1,1,1,1,1,1,1,1,1,2,2,2,2,2,2,2,2,2,2,2,2,2,2,2,1
1,1,1,1,1,1,1,1,1,1,1,1,1,1,2,0,0,0,0,0,0,0,0,0,2,0,0,0,2,1
1,1,1,1,1,1,1,1,1,1,1,1,1,1,2,0,2,2,2,2,2,2,2,0,0,0,2,0,2,1
1,1,1,1,1,1,1,1,1,1,1,1,1,1,2,0,2,0,0,0,0,6,2,0,0,0,2,0,2,1
1,1,1,1,1,1,1,1,1,1,1,1,1,1,2,0,2,0,0,0,0,0,2,2,2,2,2,0,2,1
1,1,1,1,1,1,1,1,1,1,1,1,1,1,2,0,0,0,0,0,0,0,0,0,0,0,0,0,2,1
1,1,1,1,1,1,1,1,1,1,1,1,1,1,2,0,2,0,0,0,0,0,2,0,2,2,2,2,2,1
1,1,1,1,1,1,1,1,1,1,1,1,1,1,2,0,2,2,2,2,2,2,2,0,0,0,0,0,2,1
1,1,1,1,1,1,1,1,1,1,1,1,1,1,2,0,2,0,0,0,0,0,2,2,2,2,2,0,2,1
1,1,1,1,1,1,1,1,1,1,1,1,1,1,2,0,2,0,2,2,2,0,2,0,0,0,0,0,2,1
1,1,1,1,1,1,1,1,1,1,1,1,1,1,2,0,0,0,2,0,0,0,2,0,2,0,2,0,2,1
1,1,1,1,1,1,1,1,1,1,1,1,1,1,2,2,2,0,2,0,2,2,2,0,2,0,2,0,2,1
1,1,1,1,1,1,1,1,1,1,1,1,1,1,2,0,0,0,2,0,0,0,0,0,2,0,2,0,2,1
1,1,1,1,1,1,1,1,1,1,1,1,1,1,2,0,0,0,2,0,0,0,0,0,2,0,2,0,2,1
1,1,1,1,1,1,1,1,1,1,1,1,1,1,2,2,2,2,2,2,2,2,2,2,2,2,2,2,2,1
1,1,1,1,1,1,1,1,1,1,1,1,1,1,1,1,1,1,1,1,1,1,1,1,1,1,1,1,1,1
1,1,1,1,1,1,1,1,1,1,1,1,1,1,1,1,1,1,1,1,1,1,1,1,1,1,1,1,1,1
1,1,1,1,1,1,1,1,1,1,1,1,1,1,1,1,1,1,1,1,1,1,1,1,1,1,1,1,1,1
endlayer

layer
1,1,1,1,1,1,1,1,1,1,1,1,1,1,1,1,1,1,1,1,1,1,1,1,1,1,1,1,1,1
1,1,1,1,1,1,1,1,1,1,1,1,1,1,1,1,1,1,1,1,1,1,1,1,1,1,1,1,1,1
1,1,1,1,1,1,1,1,1,1,1,1,1,1,1,1,1,1,1,1,1,1,1,1,1,1,1,1,1,1
1,1,1,1,1,1,1,1,1,1,1,1,1,1,2,2,2,2,2,2,2,2,2,2,2,2,2,2,2,1
1,1,1,1,1,1,1,1,1,1,1,1,1,1,2,0,0,0,0,0,0,0,0,0,2,0,0,0,2,1
1,1,1,1,1,1,1,1,1,1,1,1,1,1,2,0,2,2,2,2,2,1,2,0,0,0,2,0,2,1
1,1,1,1,1,1,1,1,1,1,1,1,1,1,2,0,2,0,0,0,0,0,2,0,0,0,2,0,2,1
1,1,1,1,1,1,1,1,1,1,1,1,1,1,2,0,2,0,0,0,0,0,2,2,2,2,2,0,2,1
1,1,1,1,1,1,1,1,1,1,1,1,1,1,2,0,0,0,0,0,0,0,0,0,0,0,0,0,2,1
1,1,1,1,1,1,1,1,1,1,1,1,1,1,2,0,2,0,0,0,0,0,2,0,2,2,2,2,2,1
1,1,1,1,1,1,1,1,1,1,1,1,1,1,2,0,2,2,2,2,2,2,2,0,0,0,0,0,2,1
1,1,1,1,1,1,1,1,1,1,1,1,1,1,2,0,2,0,0,0,0,0,2,1,2,2,2,0,2,1
1,1,1,1,1,1,1,1,1,1,1,1,1,1,2,0,2,0,2,2,2,0,2,0,0,0,0,0,2,1
1,1,1,1,1,1,1,1,1,1,1,1,1,1,2,0,0,0,2,0,0,0,2,0,2,0,2,0,2,1
1,1,1,1,1,1,1,1,1,1,1,1,1,1,2,2,2,0,2,0,2,2,2,0,2,0,2,0,2,1
1,1,1,1,1,1,1,1,1,1,1,1,1,1,2,0,0,0,2,0,0,0,0,0,2,0,2,0,2,1
1,1,1,1,1,1,1,1,1,1,1,1,1,1,2,0,0,0,2,0,0,0,0,0,2,0,2,0,2,1
1,1,1,1,1,1,1,1,1,1,1,1,1,1,2,2,2,2,2,2,2,2,2,2,2,2,2,2,2,1
1,1,1,1,1,1,1,1,1,1,1,1,1,1,1,1,1,1,1,1,1,1,1,1,1,1,1,1,1,1
1,1,1,1,1,1,1,1,1,1,1,1,1,1,1,1,1,1,1,1,1,1,1,1,1,1,1,1,1,1
1,1,1,1,1,1,1,1,1,1,1,1,1,1,1,1,1,1,1,1,1,1,1,1,1,1,1,1,1,1
endlayer

layer
1,1,1,1,1,1,1,1,1,1,1,1,1,1,1,1,1,1,1,1,1,1,1,1,1,1,1,1,1,1
1,1,1,1,1,1,1,1,1,1,1,1,1,1,1,1,1,1,1,1,1,1,1,1,1,1,1,1,1,1
1,1,1,1,1,1,1,1,1,1,1,1,1,1,1,1,1,1,1,1,1,1,1,1,1,1,1,1,1,1
1,1,1,1,1,1,1,1,1,1,1,1,1,1,2,2,2,2,2,2,2,2,2,2,2,2,2,2,2,1
1,1,1,1,1,1,1,1,1,1,1,1,1,1,2,0,0,0,0,0,0,0,0,0,2,0,0,0,2,1
1,1,1,1,1,1,1,1,1,1,1,1,1,1,2,0,2,2,2,2,2,2,2,0,0,0,2,0,2,1
1,1,1,1,1,1,1,1,1,1,1,1,1,1,2,0,2,0,0,0,0,0,2,0,0,0,2,0,2,1
1,1,1,1,1,1,1,1,1,1,1,1,1,1,2,0,2,0,0,0,0,0,2,2,2,2,2,0,2,1
1,1,1,1,1,1,1,1,1,1,1,1,1,1,2,0,0,0,0,0,0,0,0,0,0,0,0,0,2,1
1,1,1,1,1,1,1,1,1,1,1,1,1,1,2,0,2,0,0,0,0,0,2,0,2,2,2,2,2,1
1,1,1,1,1,1,1,1,1,1,1,1,1,1,2,0,2,2,2,2,2,2,2,0,0,0,0,0,2,1
1,1,1,1,1,1,1,1,1,1,1,1,1,1,2,0,2,0,0,0,0,0,2,2,2,2,2,0,2,1
1,1,1,1,1,1,1,1,1,1,1,1,1,1,2,0,2,0,2,2,2,0,2,0,0,0,0,0,2,1
1,1,1,1,1,1,1,1,1,1,1,1,1,1,2,0,0,0,2,0,0,0,2,0,2,0,2,0,2,1
1,1,1,1,1,1,1,1,1,1,1,1,1,1,2,2,2,0,2,0,2,2,2,0,2,0,2,0,2,1
1,1,1,1,1,1,1,1,1,1,1,1,1,1,2,0,0,0,2,0,0,0,0,0,2,0,2,0,2,1
1,1,1,1,1,1,1,1,1,1,1,1,1,1,2,0,0,0,2,0,0,0,0,0,2,0,2,0,2,1
1,1,1,1,1,1,1,1,1,1,1,1,1,1,2,2,2,2,2,2,2,2,2,2,2,2,2,2,2,1
1,1,1,1,1,1,1,1,1,1,1,1,1,1,1,1,1,1,1,1,1,1,1,1,1,1,1,1,1,1
1,1,1,1,1,1,1,1,1,1,1,1,1,1,1,1,1,1,1,1,1,1,1,1,1,1,1,1,1,1
1,1,1,1,1,1,1,1,1,1,1,1,1,1,1,1,1,1,1,1,1,1,1,1,1,1,1,1,1,1
endlayer

layer
1,1,1,1,1,1,1,1,1,1,1,1,1,1,1,1,1,1,1,1,1,1,1,1,1,1,1,1,1,1
1,1,1,1,1,1,1,1,1,1,1,1,1,1,1,1,1,1,1,1,1,1,1,1,1,1,1,1,1,1
1,1,1,1,1,1,1,1,1,1,1,1,1,1,1,1,1,1,1,1,1,1,1,1,1,1,1,1,1,1
1,1,1,1,1,1,1,1,1,1,1,1,1,1,2,2,2,2,2,2,2,2,2,2,2,2,2,2,2,1
1,1,1,1,1,1,1,1,1,1,1,1,1,1,2,2,2,2,2,2,2,2,2,2,2,2,2,2,2,1
1,1,1,1,1,1,1,1,1,1,1,1,1,1,2,2,2,2,2,2,2,2,2,2,2,2,2,2,2,1
1,1,1,1,1,1,1,1,1,1,1,1,1,1,2,2,2,0,2,2,2,2,2,2,2,2,2,2,2,1
1,1,1,1,1,1,1,1,1,1,1,1,1,1,2,2,2,2,2,2,2,2,2,0,2,2,2,0,2,1
1,1,1,1,1,1,1,1,1,1,1,1,1,1,2,2,2,2,2,2,2,2,2,2,2,2,2,2,2,1
1,1,1,1,1,1,1,1,1,1,1,1,1,1,2,2,2,2,2,2,6,2,2,2,2,2,2,2,2,1
1,1,1,1,1,1,1,1,1,1,1,1,1,1,2,2,2,2,2,2,2,2,2,2,2,2,2,2,2,1
1,1,1,1,1,1,1,1,1,1,1,1,1,1,2,2,2,2,2,2,2,2,2,2,2,2,2,2,2,1
1,1,1,1,1,1,1,1,1,1,1,1,1,1,2,2,2,2,2,2,2,2,2,2,2,2,2,2,2,1
1,1,1,1,1,1,1,1,1,1,1,1,1,1,2,2,2,2,2,2,2,2,2,2,2,2,2,2,2,1
1,1,1,1,1,1,1,1,1,1,1,1,1,1,2,2,2,2,0,2,2,2,2,2,2,2,2,2,2,1
1,1,1,1,1,1,1,1,1,1,1,1,1,1,2,2,2,2,2,2,2,0,2,2,2,2,2,2,2,1
1,1,1,1,1,1,1,1,1,1,1,1,1,1,2,2,2,2,2,2,2,2,2,2,2,2,2,2,2,1
1,1,1,1,1,1,1,1,1,1,1,1,1,1,2,5,2,2,2,2,2,2,2,2,2,2,2,2,2,1
1,1,1,1,1,1,1,1,1,1,1,1,1,1,1,1,1,1,1,1,1,1,1,1,1,1,1,1,1,1
1,1,1,1,1,1,1,1,1,1,1,1,1,1,1,1,1,1,1,1,1,1,1,1,1,1,1,1,1,1
1,1,1,1,1,1,1,1,1,1,1,1,1,1,1,1,1,1,1,1,1,1,1,1,1,1,1,1,1,1
endlayer

layer
1,1,1,1,1,1,1,1,1,1,1,1,1,1,1,1,1,1,1,1,1,1,1,1,1,1,1,1,1,1
1,1,1,1,1,1,1,1,1,1,1,1,1,1,1,1,1,1,1,1,1,1,1,1,1,1,1,1,1,1
1,1,1,1,1,1,1,1,1,1,1,1,1,1,1,1,1,1,1,1,1,1,1,1,1,1,1,1,1,1
1,1,1,1,1,1,1,1,1,1,1,1,1,1,2,2,2,2,2,2,2,2,2,2,2,2,2,2,2,1
1,1,1,1,1,1,1,1,1,1,1,1,1,1,2,0,0,0,2,0,0,0,0,0,0,0,0,0,2,1
1,1,1,1,1,1,1,1,1,1,1,1,1,1,2,0,2,0,2,0,2,2,2,2,2,0,2,0,2,1
1,1,1,1,1,1,1,1,1,1,1,1,1,1,2,0,2,0,2,0,2,0,0,0,2,0,2,0,2,1
1,1,1,1,1,1,1,1,1,1,1,1,1,1,2,0,2,2,2,0,2,0,2,0,2,0,2,0,2,1
1,1,1,1,1,1,1,1,1,1,1,1,1,1,2,0,0,0,0,0,2,0,2,0,2,0,2,2,2,1
1,1,1,1,1,1,1,1,1,1,1,1,1,1,2,0,2,2,2,0,2,0,2,0,2,0,2,0,2,1
1,1,1,1,1,1,1,1,1,1,1,1,1,1,2,0,2,0,0,0,2,0,2,0,2,0,2,0,2,1
1,1,1,1,1,1,1,1,1,1,1,1,1,1,2,0,2,0,0,0,0,0,2,2,2,0,2,0,2,1
1,1,1,1,1,1,1,1,1,1,1,1,1,1,2,0,2,0,2,2,2,2,2,0,0,0,0,0,2,1
1,1,1,1,1,1,1,1,1,1,1,1,1,1,2,0,2,0,2,0,0,0,2,0,2,2,2,2,2,1
1,1,1,1,1,1,1,1,1,1,1,1,1,1,2,0,2,0,2,0,2,0,2,0,0,0,0,0,2,1
1,1,1,1,1,1,1,1,1,1,1,1,1,1,2,0,2,0,2,0,2,2,2,2,2,2,2,0,2,1
1,1,1,1,1,1,1,1,1,1,1,1,1,1,2,0,0,0,2,0,0,0,0,0,0,0,0,0,2,1
1,1,1,1,1,1,1,1,1,1,1,1,1,1,2,2,2,2,2,2,2,2,2,2,2,2,2,2,2,1
1,1,1,1,1,1,1,1,1,1,1,1,1,1,1,1,1,1,1,1,1,1,1,1,1,1,1,1,1,1
1,1,1,1,1,1,1,1,1,1,1,1,1,1,1,1,1,1,1,1,1,1,1,1,1,1,1,1,1,1
1,1,1,1,1,1,1,1,1,1,1,1,1,1,1,1,1,1,1,1,1,1,1,1,1,1,1,1,1,1
endlayer

layer
1,1,1,1,1,1,1,1,1,1,1,1,1,1,1,1,1,1,1,1,1,1,1,1,1,1,1,1,1,1
1,1,1,1,1,1,1,1,1,1,1,1,1,1,1,1,1,1,1,1,1,1,1,1,1,1,1,1,1,1
1,1,1,1,1,1,1,1,1,1,1,1,1,1,1,1,1,1,1,1,1,1,1,1,1,1,1,1,1,1
1,1,1,1,1,1,1,1,1,1,1,1,1,1,2,2,2,2,2,2,2,2,2,2,2,2,2,2,2,1
1,1,1,1,1,1,1,1,1,1,1,1,1,1,2,0,0,0,2,0,0,0,0,0,0,0,0,0,2,1
1,1,1,1,1,1,1,1,1,1,1,1,1,1,2,0,2,0,2,0,2,1,2,2,2,0,2,0,2,1
1,1,1,1,1,1,1,1,1,1,1,1,1,1,2,0,2,0,2,0,2,0,0,0,2,0,2,0,2,1
1,1,1,1,1,1,1,1,1,1,1,1,1,1,2,0,2,2,2,0,2,0,2,0,2,0,2,0,2,1
1,1,1,1,1,1,1,1,1,1,1,1,1,1,2,0,0,0,0,0,2,0,2,0,2,0,2,2,2,1
1,1,1,1,1,1,1,1,1,1,1,1,1,1,2,0,2,2,2,0,2,0,2,0,2,0,2,0,2,1
1,1,1,1,1,1,1,1,1,1,1,1,1,1,2,0,2,0,0,0,2,0,2,0,2,0,2,0,2,1
1,1,1,1,1,1,1,1,1,1,1,1,1,1,2,0,2,0,0,0,0,0,2,2,2,0,2,0,2,1
1,1,1,1,1,1,1,1,1,1,1,1,1,1,2,0,2,0,2,2,2,2,2,0,0,0,0,0,2,1
1,1,1,1,1,1,1,1,1,1,1,1,1,1,2,0,2,0,2,0,0,0,2,0,2,2,2,2,2,1
1,1,1,1,1,1,1,1,1,1,1,1,1,1,2,0,2,0,2,0,2,0,1,0,0,0,0,0,2,1
1,1,1,1,1,1,1,1,1,1,1,1,1,1,2,0,2,0,2,0,2,2,2,2,2,2,2,0,2,1
1,1,1,1,1,1,1,1,1,1,1,1,1,1,2,0,0,0,2,0,0,0,0,0,0,0,0,0,2,1
1,1,1,1,1,1,1,1,1,1,1,1,1,1,2,2,2,2,2,2,2,2,2,2,2,2,2,2,2,1
1,1,1,1,1,1,1,1,1,1,1,1,1,1,1,1,1,1,1,1,1,1,1,1,1,1,1,1,1,1
1,1,1,1,1,1,1,1,1,1,1,1,1,1,1,1,1,1,1,1,1,1,1,1,1,1,1,1,1,1
1,1,1,1,1,1,1,1,1,1,1,1,1,1,1,1,1,1,1,1,1,1,1,1,1,1,1,1,1,1
endlayer

layer
1,1,1,1,1,1,1,1,1,1,1,1,1,1,1,1,1,1,1,1,1,1,1,1,1,1,1,1,1,1
1,1,1,1,1,1,1,1,1,1,1,1,1,1,1,1,1,1,1,1,1,1,1,1,1,1,1,1,1,1
1,1,1,1,1,1,1,1,1,1,1,1,1,1,1,1,1,1,1,1,1,1,1,1,1,1,1,1,1,1
1,1,1,1,1,1,1,1,1,1,1,1,1,1,2,2,2,2,2,2,2,2,2,2,2,2,2,2,2,1
1,1,1,1,1,1,1,1,1,1,1,1,1,1,2,0,0,0,2,0,0,0,0,0,0,0,0,0,2,1
1,1,1,1,1,1,1,1,1,1,1,1,1,1,2,0,2,0,2,0,2,2,2,2,2,0,2,0,2,1
1,1,1,1,1,1,1,1,1,1,1,1,1,1,2,0,2,0,2,0,2,0,0,0,2,0,2,0,2,1
1,1,1,1,1,1,1,1,1,1,1,1,1,1,2,0,2,2,2,0,2,0,2,0,2,0,2,0,2,1
1,1,1,1,1,1,1,1,1,1,1,1,1,1,2,0,0,0,0,0,2,0,2,0,2,0,2,2,2,1
1,1,1,1,1,1,1,1,1,1,1,1,1,1,2,0,2,2,2,0,2,0,2,0,2,0,2,0,2,1
1,1,1,1,1,1,1,1,1,1,1,1,1,1,2,0,2,0,0,0,2,0,2,0,2,0,2,0,2,1
1,1,1,1,1,1,1,1,1,1,1,1,1,1,2,0,2,0,0,0,0,0,2,2,2,0,2,0,2,1
1,1,1,1,1,1,1,1,1,1,1,1,1,1,2,0,2,0,2,2,2,2,2,0,0,0,0,0,2,1
1,1,1,1,1,1,1,1,1,1,1,1,1,1,2,0,2,0,2,0,0,0,2,0,2,2,2,2,2,1
1,1,1,1,1,1,1,1,1,1,1,1,1,1,2,0,2,0,2,0,2,0,2,0,0,0,0,0,2,1
1,1,1,1,1,1,1,1,1,1,1,1,1,1,2,0,2,0,2,0,2,2,2,2,2,2,2,0,2,1
1,1,1,1,1,1,1,1,1,1,1,1,1,1,2,0,0,0,2,0,0,0,0,0,0,0,0,0,2,1
1,1,1,1,1,1,1,1,1,1,1,1,1,1,2,2,2,2,2,2,2,2,2,2,2,2,2,2,2,1
1,1,1,1,1,1,1,1,1,1,1,1,1,1,1,1,1,1,1,1,1,1,1,1,1,1,1,1,1,1
1,1,1,1,1,1,1,1,1,1,1,1,1,1,1,1,1,1,1,1,1,1,1,1,1,1,1,1,1,1
1,1,1,1,1,1,1,1,1,1,1,1,1,1,1,1,1,1,1,1,1,1,1,1,1,1,1,1,1,1
endlayer

layer
1,1,1,1,1,1,1,1,1,1,1,1,1,1,1,1,1,1,1,1,1,1,1,1,1,1,1,1,1,1
1,1,1,1,1,1,1,1,1,1,1,1,1,1,1,1,1,1,1,1,1,1,1,1,1,1,1,1,1,1
1,1,1,1,1,1,1,1,1,1,1,1,1,1,1,1,1,1,1,1,1,1,1,1,1,1,1,1,1,1
1,1,1,1,1,1,1,1,1,1,1,1,1,1,2,2,5,2,2,2,2,2,2,2,2,2,2,2,2,1
1,1,1,1,1,1,1,1,1,1,1,1,1,1,2,2,2,2,2,2,2,2,2,2,2,2,2,2,2,1
1,1,1,1,1,1,1,1,1,1,1,1,1,1,2,2,2,2,2,2,2,0,2,2,2,2,2,2,2,1
1,1,1,1,1,1,1,1,1,1,1,1,1,1,2,2,2,2,2,2,2,2,2,2,2,0,2,2,2,1
1,1,1,1,1,1,1,1,1,1,1,1,1,1,2,2,2,2,2,2,2,2,2,2,0,2,2,2,2,1
1,1,1,1,1,1,1,1,1,1,1,1,1,1,2,2,2,2,2,2,2,2,2,2,2,2,2,2,2,1
1,1,1,1,1,1,1,1,1,1,1,1,1,1,2,2,2,2,2,2,2,2,2,2,0,2,2,2,2,1
1,1,1,1,1,1,1,1,1,1,1,1,1,1,2,2,2,2,2,2,2,2,2,2,2,2,2,2,2,1
1,1,1,1,1,1,1,1,1,1,1,1,1,1,2,2,2,2,2,2,2,2,2,0,2,2,2,2,2,1
1,1,1,1,1,1,1,1,1,1,1,1,1,1,2,2,2,2,0,2,5,2,2,2,2,2,2,2,2,1
1,1,1,1,1,1,1,1,1,1,1,1,1,1,2,2,2,2,2,2,2,2,2,2,2,2,2,2,2,1
1,1,1,1,1,1,1,1,1,1,1,1,1,1,2,2,6,2,2,2,2,2,2,2,2,2,2,2,2,1
1,1,1,1,1,1,1,1,1,1,1,1,1,1,2,2,2,2,2,2,2,2,2,2,2,2,2,2,2,1
1,1,1,1,1,1,1,1,1,1,1,1,1,1,2,0,2,2,2,2,2,2,2,2,2,2,2,0,2,1
1,1,1,1,1,1,1,1,1,1,1,1,1,1,2,2,2,2,2,2,2,2,2,2,2,2,2,2,2,1
1,1,1,1,1,1,1,1,1,1,1,1,1,1,1,1,1,1,1,1,1,1,1,1,1,1,1,1,1,1
1,1,1,1,1,1,1,1,1,1,1,1,1,1,1,1,1,1,1,1,1,1,1,1,1,1,1,1,1,1
1,1,1,1,1,1,1,1,1,1,1,1,1,1,1,1,1,1,1,1,1,1,1,1,1,1,1,1,1,1
endlayer

layer
1,1,1,1,1,1,1,1,1,1,1,1,1,1,1,1,1,1,1,1,1,1,1,1,1,1,1,1,1,1
1,1,1,1,1,1,1,1,1,1,1,1,1,1,1,1,1,1,1,1,1,1,1,1,1,1,1,1,1,1
1,1,1,1,1,1,1,1,1,1,1,1,1,1,1,1,1,1,1,1,1,1,1,1,1,1,1,1,1,1
1,1,1,1,1,1,1,1,1,1,1,1,1,1,2,2,2,2,2,2,2,2,2,2,2,2,2,2,2,1
1,1,1,1,1,1,1,1,1,1,1,1,1,1,2,0,0,0,0,0,0,0,0,0,2,0,0,0,2,1
1,1,1,1,1,1,1,1,1,1,1,1,1,1,2,0,2,2,2,2,2,2,2,0,0,0,2,0,2,1
1,1,1,1,1,1,1,1,1,1,1,1,1,1,2,0,2,0,0,0,0,0,2,0,0,0,2,0,2,1
1,1,1,1,1,1,1,1,1,1,1,1,1,1,2,0,2,0,0,0,0,0,2,2,2,2,2,0,2,1
1,1,1,1,1,1,1,1,1,1,1,1,1,1,2,0,0,0,0,0,0,0,0,0,0,0,0,0,2,1
1,1,1,1,1,1,1,1,1,1,1,1,1,1,2,0,2,0,0,0,0,0,2,0,2,2,2,2,2,1
1,1,1,1,1,1,1,1,1,1,1,1,1,1,2,0,2,2,2,2,2,2,2,0,0,0,0,0,2,1
1,1,1,1,1,1,1,1,1,1,1,1,1,1,2,0,2,0,0,0,0,0,2,2,2,2,2,0,2,1
1,1,1,1,1,1,1,1,1,1,1,1,1,1,2,0,2,0,2,2,2,0,2,0,0,0,0,0,2,1
1,1,1,1,1,1,1,1,1,1,1,1,1,1,2,0,0,0,2,0,0,0,2,0,2,0,2,0,2,1
1,1,1,1,1,1,1,1,1,1,1,1,1,1,2,2,2,0,2,0,2,2,2,0,2,0,2,0,2,1
1,1,1,1,1,1,1,1,1,1,1,1,1,1,2,0,0,0,2,0,0,0,0,0,2,0,2,0,2,1
1,1,1,1,1,1,1,1,1,1,1,1,1,1,2,0,0,0,2,0,0,0,0,0,2,0,2,0,2,1
1,1,1,1,1,1,1,1,1,1,1,1,1,1,2,2,2,2,2,2,2,2,2,2,2,2,2,2,2,1
1,1,1,1,1,1,1,1,1,1,1,1,1,1,1,1,1,1,1,1,1,1,1,1,1,1,1,1,1,1
1,1,1,1,1,1,1,1,1,1,1,1,1,1,1,1,1,1,1,1,1,1,1,1,1,1,1,1,1,1
1,1,1,1,1,1,1,1,1,1,1,1,1,1,1,1,1,1,1,1,1,1,1,1,1,1,1,1,1,1
endlayer

layer
1,1,1,1,1,1,1,1,1,1,1,1,1,1,1,1,1,1,1,1,1,1,1,1,1,1,1,1,1,1
1,1,1,1,1,1,1,1,1,1,1,1,1,1,1,1,1,1,1,1,1,1,1,1,1,1,1,1,1,1
1,1,1,1,1,1,1,1,1,1,1,1,1,1,1,1,1,1,1,1,1,1,1,1,1,1,1,1,1,1
1,1,1,1,1,1,1,1,1,1,1,1,1,1,2,2,2,2,2,2,2,2,2,2,2,2,2,2,2,1
1,1,1,1,1,1,1,1,1,1,1,1,1,1,2,0,0,0,0,0,0,0,0,0,2,0,0,0,2,1
1,1,1,1,1,1,1,1,1,1,1,1,1,1,2,0,2,2,2,2,2,1,2,0,0,0,2,0,2,1
1,1,1,1,1,1,1,1,1,1,1,1,1,1,2,0,2,0,0,0,0,0,2,0,0,0,2,0,2,1
1,1,1,1,1,1,1,1,1,1,1,1,1,1,2,0,2,0,0,0,0,0,2,2,1,2,2,0,2,1
1,1,1,1,1,1,1,1,1,1,1,1,1,1,2,0,0,0,0,0,0,0,0,0,0,0,0,0,2,1
1,1,1,1,1,1,1,1,1,1,1,1,1,1,2,0,2,0,0,0,0,0,2,0,2,2,2,2,2,1
1,1,1,1,1,1,1,1,1,1,1,1,1,1,2,0,2,2,2,2,2,2,2,0,0,0,0,0,2,1
1,1,1,1,1,1,1,1,1,1,1,1,1,1,2,0,2,0,0,0,0,0,2,1,2,2,2,0,2,1
1,1,1,1,1,1,1,1,1,1,1,1,1,1,2,0,2,0,2,2,2,0,2,0,0,0,0,0,2,1
1,1,1,1,1,1,1,1,1,1,1,1,1,1,2,0,0,0,2,0,0,0,2,0,2,0,2,0,2,1
1,1,1,1,1,1,1,1,1,1,1,1,1,1,2,2,2,0,2,0,2,2,2,0,2,0,2,0,2,1
1,1,1,1,1,1,1,1,1,1,1,1,1,1,2,0,0,0,2,0,0,0,0,0,2,0,2,0,2,1
1,1,1,1,1,1,1,1,1,1,1,1,1,1,2,0,0,0,2,0,0,0,0,0,2,0,2,0,2,1
1,1,1,1,1,1,1,1,1,1,1,1,1,1,2,2,2,2,2,2,2,2,2,2,2,2,2,2,2,1
1,1,1,1,1,1,1,1,1,1,1,1,1,1,1,1,1,1,1,1,1,1,1,1,1,1,1,1,1,1
1,1,1,1,1,1,1,1,1,1,1,1,1,1,1,1,1,1,1,1,1,1,1,1,1,1,1,1,1,1
1,1,1,1,1,1,1,1,1,1,1,1,1,1,1,1,1,1,1,1,1,1,1,1,1,1,1,1,1,1
endlayer

layer
1,1,1,1,1,1,1,1,1,1,1,1,1,1,1,1,1,1,1,1,1,1,1,1,1,1,1,1,1,1
1,1,1,1,1,1,1,1,1,1,1,1,1,1,1,1,1,1,1,1,1,1,1,1,1,1,1,1,1,1
1,1,1,1,1,1,1,1,1,1,1,1,1,1,1,1,1,1,1,1,1,1,1,1,1,1,1,1,1,1
1,1,1,1,1,1,1,1,1,1,1,1,1,1,2,2,2,2,2,2,2,2,2,2,2,2,2,2,2,1
1,1,1,1,1,1,1,1,1,1,1,1,1,1,2,0,0,0,0,0,0,0,0,0,2,0,0,0,2,1
1,1,1,1,1,1,1,1,1,1,1,1,1,1,2,0,2,2,2,2,2,2,2,0,0,0,2,0,2,1
1,1,1,1,1,1,1,1,1,1,1,1,1,1,2,0,2,0,0,0,0,0,2,0,0,0,2,0,2,1
1,1,1,1,1,1,1,1,1,1,1,1,1,1,2,0,2,0,0,0,0,0,2,2,2,2,2,0,2,1
1,1,1,1,1,1,1,1,1,1,1,1,1,1,2,0,0,0,0,0,0,0,0,0,0,0,0,0,2,1
1,1,1,1,1,1,1,1,1,1,1,1,1,1,2,0,2,0,0,0,0,0,2,0,2,2,2,2,2,1
1,1,1,1,1,1,1,1,1,1,1,1,1,1,2,0,2,2,2,2,2,2,2,0,0,0,0,0,2,1
1,1,1,1,1,1,1,1,1,1,1,1,1,1,2,0,2,0,0,0,0,0,2,2,2,2,2,0,2,1
1,1,1,1,1,1,1,1,1,1,1,1,1,1,2,0,2,0,2,2,2,0,2,0,0,0,0,0,2,1
1,1,1,1,1,1,1,1,1,1,1,1,1,1,2,0,0,0,2,0,0,0,2,0,2,0,2,0,2,1
1,1,1,1,1,1,1,1,1,1,1,1,1,1,2,2,2,0,2,0,2,2,2,0,2,0,2,0,2,1
1,1,1,1,1,1,1,1,1,1,1,1,1,1,2,0,0,0,2,0,0,0,0,0,2,0,2,0,2,1
1,1,1,1,1,1,1,1,1,1,1,1,1,1,2,0,0,0,2,0,0,0,0,0,2,0,2,0,2,1
1,1,1,1,1,1,1,1,1,1,1,1,1,1,2,2,2,2,2,2,2,2,2,2,2,2,2,2,2,1
1,1,1,1,1,1,1,1,1,1,1,1,1,1,1,1,1,1,1,1,1,1,1,1,1,1,1,1,1,1
1,1,1,1,1,1,1,1,1,1,1,1,1,1,1,1,1,1,1,1,1,1,1,1,1,1,1,1,1,1
1,1,1,1,1,1,1,1,1,1,1,1,1,1,1,1,1,1,1,1,1,1,1,1,1,1,1,1,1,1
endlayer

layer
1,1,1,1,1,1,1,1,1,1,1,1,1,1,1,1,1,1,1,1,1,1,1,1,1,1,1,1,1,1
1,1,1,1,1,1,1,1,1,1,1,1,1,1,1,1,1,1,1,1,1,1,1,1,1,1,1,1,1,1
1,1,1,1,1,1,1,1,1,1,1,1,1,1,1,1,1,1,1,1,1,1,1,1,1,1,1,1,1,1
1,1,1,1,1,1,1,1,1,1,1,1,1,1,2,2,2,2,2,2,2,2,2,2,2,2,2,2,2,1
1,1,1,1,1,1,1,1,1,1,1,1,1,1,2,2,2,2,2,2,2,2,2,2,2,2,2,2,2,1
1,1,1,1,1,1,1,1,1,1,1,1,1,1,2,2,2,2,2,2,2,0,2,2,2,2,2,2,2,1
1,1,1,1,1,1,1,1,1,1,1,1,1,1,2,2,2,0,2,2,2,2,2,2,2,2,2,2,2,1
1,1,1,1,1,1,1,1,1,1,1,1,1,1,2,2,2,2,2,2,2,2,2,2,2,0,2,0,2,1
1,1,1,1,1,1,1,1,1,1,1,1,1,1,2,2,2,2,2,2,2,2,2,2,2,2,2,2,2,1
1,1,1,1,1,1,1,1,1,1,1,1,1,1,2,2,2,2,2,2,2,2,2,2,2,2,2,2,2,1
1,1,1,1,1,1,1,1,1,1,1,1,1,1,2,2,2,2,2,2,2,2,2,2,2,2,2,2,2,1
1,1,1,1,1,1,1,1,1,1,1,1,1,1,2,2,2,2,2,2,2,2,2,2,2,2,2,2,2,1
1,1,1,1,1,1,1,1,1,1,1,1,1,1,2,2,6,2,2,2,2,2,2,2,0,2,2,2,2,1
1,1,1,1,1,1,1,1,1,1,1,1,1,1,2,2,2,2,2,2,2,2,2,2,2,2,2,2,2,1
1,1,1,1,1,1,1,1,1,1,1,1,1,1,2,2,2,2,2,2,2,2,2,2,2,2,2,2,2,1
1,1,1,1,1,1,1,1,1,1,1,1,1,1,2,2,2,2,0,2,2,0,2,2,2,2,2,2,2,1
1,1,1,1,1,1,1,1,1,1,1,1,1,1,2,2,2,2,2,2,2,2,2,2,2,2,2,2,2,1
1,1,1,1,1,1,1,1,1,1,1,1,1,1,2,2,2,2,2,2,2,2,2,2,2,2,2,2,2,1
1,1,1,1,1,1,1,1,1,1,1,1,1,1,1,1,1,1,1,1,1,1,1,1,1,1,1,1,1,1
1,1,1,1,1,1,1,1,1,1,1,1,1,1,1,1,1,1,1,1,1,1,1,1,1,1,1,1,1,1
1,1,1,1,1,1,1,1,1,1,1,1,1,1,1,1,1,1,1,1,1,1,1,1,1,1,1,1,1,1
endlayer

layer
1,1,1,1,1,1,1,1,1,1,1,1,1,1,1,1,1,1,1,1,1,1,1,1,1,1,1,1,1,1
1,1,1,1,1,1,1,1,1,1,1,1,1,1,1,1,1,1,1,1,1,1,1,1,1,1,1,1,1,1
1,1,1,1,1,1,1,1,1,1,1,1,1,1,1,1,1,1,1,1,1,1,1,1,1,1,1,1,1,1
1,1,1,1,1,1,1,1,1,1,1,1,1,1,2,2,2,2,2,2,2,2,2,2,2,2,2,2,2,1
1,1,1,1,1,1,1,1,1,1,1,1,1,1,2,0,0,0,0,0,0,2,0,2,0,0,0,2,2,1
1,1,1,1,1,1,1,1,1,1,1,1,1,1,2,0,2,2,2,2,0,2,0,2,0,2,0,2,2,1
1,1,1,1,1,1,1,1,1,1,1,1,1,1,2,0,2,0,0,2,0,2,0,2,0,2,0,5,2,1
1,1,1,1,1,1,1,1,1,1,1,1,1,1,2,0,0,0,0,2,0,2,0,0,0,2,0,0,2,1
1,1,1,1,1,1,1,1,1,1,1,1,1,1,2,2,2,2,2,2,0,2,0,2,0,2,2,2,2,1
1,1,1,1,1,1,1,1,1,1,1,1,1,1,2,0,0,0,0,0,0,2,0,2,0,2,2,2,2,1
1,1,1,1,1,1,1,1,1,1,1,1,1,1,2,0,0,2,0,2,0,2,0,2,0,2,2,2,2,1
1,1,1,1,1,1,1,1,1,1,1,1,1,1,2,0,0,2,0,2,0,2,0,2,0,0,2,0,2,1
1,1,1,1,1,1,1,1,1,1,1,1,1,1,2,0,5,2,0,2,2,2,0,2,2,2,0,0,2,1
1,1,1,1,1,1,1,1,1,1,1,1,1,1,2,2,2,2,0,2,0,0,0,0,0,0,2,0,2,1
1,1,1,1,1,1,1,1,1,1,1,1,1,1,2,0,0,0,0,0,0,2,2,0,2,0,2,0,2,1
1,1,1,1,1,1,1,1,1,1,1,1,1,1,2,0,2,2,2,2,2,0,2,0,2,0,2,0,2,1
1,1,1,1,1,1,1,1,1,1,1,1,1,1,2,0,0,0,0,0,0,0,2,0,2,0,0,0,2,1
1,1,1,1,1,1,1,1,1,1,1,1,1,1,2,2,2,2,2,2,2,2,2,2,2,2,2,2,2,1
1,1,1,1,1,1,1,1,1,1,1,1,1,1,1,1,1,1,1,1,1,1,1,1,1,1,1,1,1,1
1,1,1,1,1,1,1,1,1,1,1,1,1,1,1,1,1,1,1,1,1,1,1,1,1,1,1,1,1,1
1,1,1,1,1,1,1,1,1,1,1,1,1,1,1,1,1,1,1,1,1,1,1,1,1,1,1,1,1,1
endlayer

layer
1,1,1,1,1,1,1,1,1,1,1,1,1,1,1,1,1,1,1,1,1,1,1,1,1,1,1,1,1,1
1,1,1,1,1,1,1,1,1,1,1,1,1,1,1,1,1,1,1,1,1,1,1,1,1,1,1,1,1,1
1,1,1,1,1,1,1,1,1,1,1,1,1,1,1,1,1,1,1,1,1,1,1,1,1,1,1,1,1,1
1,1,1,1,1,1,1,1,1,1,1,1,1,1,2,2,2,2,2,2,2,2,2,2,2,2,2,2,2,1
1,1,1,1,1,1,1,1,1,1,1,1,1,1,2,0,0,0,0,0,0,2,0,2,0,0,0,2,2,1
1,1,1,1,1,1,1,1,1,1,1,1,1,1,2,0,2,2,2,2,0,1,0,2,0,2,0,2,2,1
1,1,1,1,1,1,1,1,1,1,1,1,1,1,2,0,2,0,0,2,0,2,0,2,0,2,0,0,2,1
1,1,1,1,1,1,1,1,1,1,1,1,1,1,2,0,0,0,0,2,0,2,0,0,0,2,0,0,2,1
1,1,1,1,1,1,1,1,1,1,1,1,1,1,2,2,2,2,2,2,0,2,0,2,0,2,2,2,2,1
1,1,1,1,1,1,1,1,1,1,1,1,1,1,2,0,0,0,0,0,0,2,0,2,0,2,2,2,2,1
1,1,1,1,1,1,1,1,1,1,1,1,1,1,2,0,0,2,0,2,0,2,0,2,0,2,2,2,2,1
1,1,1,1,1,1,1,1,1,1,1,1,1,1,2,0,0,2,0,2,0,2,0,2,0,0,0,0,2,1
1,1,1,1,1,1,1,1,1,1,1,1,1,1,2,0,0,2,0,2,2,2,0,2,1,2,0,0,2,1
1,1,1,1,1,1,1,1,1,1,1,1,1,1,2,2,2,2,0,2,0,0,0,0,0,0,2,0,2,1
1,1,1,1,1,1,1,1,1,1,1,1,1,1,2,0,0,0,0,0,0,2,2,0,2,0,2,0,2,1
1,1,1,1,1,1,1,1,1,1,1,1,1,1,2,0,2,2,1,2,2,0,2,0,2,0,2,0,2,1
1,1,1,1,1,1,1,1,1,1,1,1,1,1,2,0,0,0,0,0,0,0,2,0,2,0,0,0,2,1
1,1,1,1,1,1,1,1,1,1,1,1,1,1,2,2,2,2,2,2,2,2,2,2,2,2,2,2,2,1
1,1,1,1,1,1,1,1,1,1,1,1,1,1,1,1,1,1,1,1,1,1,1,1,1,1,1,1,1,1
1,1,1,1,1,1,1,1,1,1,1,1,1,1,1,1,1,1,1,1,1,1,1,1,1,1,1,1,1,1
1,1,1,1,1,1,1,1,1,1,1,1,1,1,1,1,1,1,1,1,1,1,1,1,1,1,1,1,1,1
endlayer

layer
1,1,1,1,1,1,1,1,1,1,1,1,1,1,1,1,1,1,1,1,1,1,1,1,1,1,1,1,1,1
1,1,1,1,1,1,1,1,1,1,1,1,1,1,1,1,1,1,1,1,1,1,1,1,1,1,1,1,1,1
1,1,1,1,1,1,1,1,1,1,1,1,1,1,1,1,1,1,1,1,1,1,1,1,1,1,1,1,1,1
1,1,1,1,1,1,1,1,1,1,1,1,1,1,2,2,2,2,2,2,2,2,2,2,2,2,2,2,2,1
1,1,1,1,1,1,1,1,1,1,1,1,1,1,2,0,0,0,0,0,0,2,0,2,0,0,0,2,2,1
1,1,1,1,1,1,1,1,1,1,1,1,1,1,2,0,2,2,2,2,0,2,0,2,0,2,0,2,2,1
1,1,1,1,1,1,1,1,1,1,1,1,1,1,2,0,2,0,0,2,0,2,0,2,0,2,0,0,2,1
1,1,1,1,1,1,1,1,1,1,1,1,1,1,2,0,0,0,0,2,0,2,0,0,0,2,2,2,2,1
1,1,1,1,1,1,1,1,1,1,1,1,1,1,2,2,2,2,2,2,0,2,0,2,0,2,2,2,2,1
1,1,1,1,1,1,1,1,1,1,1,1,1,1,2,0,0,0,0,0,0,2,0,2,0,2,2,2,2,1
1,1,1,1,1,1,1,1,1,1,1,1,1,1,2,0,0,2,0,2,0,2,0,2,0,2,0,2,2,1
1,1,1,1,1,1,1,1,1,1,1,1,1,1,2,0,0,2,0,2,0,2,0,2,0,0,0,0,2,1
1,1,1,1,1,1,1,1,1,1,1,1,1,1,2,0,0,2,0,2,2,2,0,2,2,2,0,0,2,1
1,1,1,1,1,1,1,1,1,1,1,1,1,1,2,2,2,2,0,2,0,0,0,0,0,0,2,0,2,1
1,1,1,1,1,1,1,1,1,1,1,1,1,1,2,0,0,0,0,0,0,2,2,0,2,0,2,0,2,1
1,1,1,1,1,1,1,1,1,1,1,1,1,1,2,0,2,2,2,2,2,0,2,0,2,0,2,0,2,1
1,1,1,1,1,1,1,1,1,1,1,1,1,1,2,0,0,0,0,0,0,0,2,0,2,0,0,0,2,1
1,1,1,1,1,1,1,1,1,1,1,1,1,1,2,2,2,2,2,2,2,2,2,2,2,2,2,2,2,1
1,1,1,1,1,1,1,1,1,1,1,1,1,1,1,1,1,1,1,1,1,1,1,1,1,1,1,1,1,1
1,1,1,1,1,1,1,1,1,1,1,1,1,1,1,1,1,1,1,1,1,1,1,1,1,1,1,1,1,1
1,1,1,1,1,1,1,1,1,1,1,1,1,1,1,1,1,1,1,1,1,1,1,1,1,1,1,1,1,1
endlayer

layer
1,1,1,1,1,1,1,1,1,1,1,1,1,1,1,1,1,1,1,1,1,1,1,1,1,1,1,1,1,1
1,1,1,1,1,7,7,7,7,7,7,7,7,7,7,7,7,7,7,7,7,7,7,7,7,7,7,7,7,1
1,1,1,1,1,7,7,7,7,7,7,7,7,7,7,7,7,7,7,7,7,7,7,7,7,7,7,7,7,1
1,1,1,1,1,7,7,7,7,7,7,7,7,7,2,2,2,2,2,2,2,2,2,2,2,2,2,2,2,1
1,1,1,1,1,7,7,7,7,7,7,7,7,7,2,2,2,2,2,2,2,2,2,2,2,2,2,2,2,1
1,1,1,1,1,7,7,7,7,7,7,7,7,7,2,2,2,2,2,2,2,2,2,2,2,2,2,2,2,1
1,1,1,1,1,7,7,7,7,7,7,7,7,7,2,2,2,2,2,2,2,2,2,2,2,2,2,2,2,1
1,1,1,1,1,7,7,7,7,7,7,7,7,7,2,2,2,2,2,2,2,2,2,2,2,2,2,2,2,1
1,1,1,1,1,7,7,7,7,7,7,7,7,7,2,2,2,2,2,2,2,2,2,2,2,2,2,2,2,1
1,1,1,1,1,7,7,7,7,7,7,7,7,7,2,2,2,2,2,2,2,2,2,2,2,2,0,2,2,1
1,1,1,1,1,7,7,7,7,7,7,7,7,7,2,2,2,2,2,2,2,2,2,2,2,2,0,2,2,1
1,1,1,1,1,7,7,7,7,7,7,7,7,7,2,2,2,2,2,2,2,2,2,2,2,2,2,2,2,1
1,1,1,1,1,7,7,7,7,7,7,7,7,7,2,2,2,2,2,2,2,2,2,2,2,2,2,2,2,1
1,1,1,1,1,7,7,7,7,7,7,7,7,7,2,2,2,2,2,2,2,2,2,2,2,2,2,2,2,1
1,1,1,1,1,7,7,7,7,7,7,7,7,7,2,2,2,2,2,2,2,2,2,2,2,2,2,2,2,1
1,1,1,1,1,7,7,7,7,7,7,7,7,7,2,2,2,2,2,2,2,2,2,2,2,2,2,2,2,1
1,1,1,1,1,7,7,7,7,7,7,7,7,7,2,2,2,2,2,2,2,2,2,2,2,2,2,2,2,1
1,1,1,1,1,7,7,7,7,7,7,7,7,7,2,2,2,2,2,2,2,2,2,2,2,2,2,2,2,1
1,1,1,1,1,7,7,7,7,7,7,7,7,7,7,7,7,7,7,7,7,7,7,7,7,7,7,7,7,1
1,1,1,1,1,7,7,7,7,7,7,7,7,7,7,7,7,7,7,7,7,7,7,7,7,7,7,7,7,1
1,1,1,1,1,1,1,1,1,1,1,1,1,1,1,1,1,1,1,1,1,1,1,1,1,1,1,1,1,1
endlayer

layer
0,0,0,0,2,2,2,2,2,2,2,2,2,2,2,2,9,9,2,2,2,2,2,2,2,2,2,2,2,2
0,0,0,0,2,7,7,7,7,7,7,7,7,7,7,7,9,9,7,7,7,7,7,7,7,7,7,7,7,2
0,0,0,0,2,7,7,7,7,7,7,7,7,7,7,7,9,9,7,7,7,7,7,7,7,7,7,7,7,2
0,0,0,0,2,7,8,7,8,7,8,7,8,7,8,7,9,9,7,8,7,8,7,8,7,8,7,8,7,2
0,0,0,0,2,7,7,7,7,7,7,7,7,7,7,7,9,9,7,7,7,7,7,7,7,7,7,7,7,2
0,0,0,0,2,7,9,9,9,9,9,9,9,9,9,9,9,9,9,9,9,9,9,9,9,9,9,9,7,2
0,0,0,0,2,7,9,9,9,9,9,9,9,9,9,9,9,9,9,9,9,9,9,9,9,9,9,9,7,2
0,0,0,0,2,7,7,7,7,7,7,7,7,7,7,7,9,9,7,7,7,7,7,7,7,7,7,7,7,2
0,0,0,0,2,7,7,7,7,7,8,7,8,7,8,7,9,9,7,8,7,8,7,8,7,7,7,7,7,2
0,0,0,0,2,7,7,7,7,7,7,7,7,7,7,7,9,9,7,7,7,7,7,7,7,7,0,7,7,2
0,0,0,0,2,7,7,7,7,7,7,7,7,7,7,7,9,9,7,7,7,7,7,7,7,7,0,7,7,2
0,0,0,0,2,7,7,8,7,7,7,7,7,7,7,7,9,9,7,7,7,7,7,7,7,7,7,7,7,2
0,0,0,0,2,7,7,7,7,7,8,7,8,7,8,7,9,9,7,8,7,8,7,8,7,7,7,7,7,2
0,0,0,0,2,7,7,7,7,7,7,7,7,7,7,7,9,9,7,7,7,7,7,7,7,7,7,7,7,2
0,0,0,0,2,7,9,9,9,9,9,9,9,9,9,9,9,9,9,9,9,9,9,9,9,9,9,9,7,2
0,0,0,0,2,7,9,9,9,9,9,9,9,9,9,9,9,9,9,9,9,9,9,9,9,9,9,9,7,2
0,0,0,0,2,7,7,7,7,7,7,7,7,7,7,7,9,9,7,7,7,7,7,7,7,7,7,7,7,2
0,0,0,0,2,7,8,7,8,7,8,7,8,7,8,7,9,9,7,8,7,8,7,8,7,8,7,8,7,2
0,0,0,0,2,7,7,7,7,7,7,7,7,7,7,7,9,9,7,7,7,7,7,7,7,7,7,7,7,2
0,0,0,0,2,7,7,7,7,7,7,7,7,7,7,7,9,9,7,7,7,7,7,7,7,7,7,7,7,2
0,0,0,0,2,2,2,2,2,2,2,2,2,2,2,2,9,9,2,2,2,2,2,2,2,2,2,2,2,2
endlayer

layer
0,0,0,0,2,2,2,2,2,2,2,2,2,2,2,2,0,0,2,2,2,2,2,2,2,2,2,2,2,2
0,0,0,0,2,10,10,10,10,10,10,10,10,10,10,10,0,0,10,10,10,10,10,10,10,10,10,10,10,2
0,0,0,0,2,10,11,0,11,0,11,0,11,0,11,0,0,0,0,11,0,11,0,11,0,11,0,11,10,2
0,0,0,0,2,10,12,0,12,0,12,0,12,0,12,0,0,0,0,12,0,12,0,12,0,12,0,12,10,2
0,0,0,0,2,10,0,0,0,0,0,0,0,0,0,0,0,0,0,0,0,0,0,0,0,0,0,0,10,2
0,0,0,0,2,10,0,0,0,0,0,0,0,0,0,0,0,0,0,0,0,0,0,0,0,0,0,0,10,2
0,0,0,0,2,14,0,0,0,0,0,0,0,0,0,0,0,0,0,0,0,0,0,0,0,0,0,0,10,2
0,0,0,0,2,10,0,0,0,0,0,0,0,0,0,0,0,0,0,0,0,0,0,0,0,0,0,0,10,2
0,0,0,0,2,10,0,0,0,0,12,0,12,0,12,0,0,0,0,12,0,12,0,12,0,13,0,13,10,2
0,0,0,0,2,10,0,0,0,0,11,0,11,0,11,0,0,0,0,11,0,11,0,11,0,13,11,13,10,2
0,0,0,0,2,10,13,13,13,0,0,0,0,0,0,0,0,0,0,0,0,0,0,0,0,13,13,13,10,2
0,0,0,0,2,10,13,11,13,0,11,0,11,0,11,0,0,0,0,11,0,11,0,11,0,0,0,0,10,2
0,0,0,0,2,10,13,0,13,0,12,0,12,0,12,0,0,0,0,12,0,12,0,12,0,0,0,0,10,2
0,0,0,0,2,10,0,0,0,0,0,0,0,0,0,0,0,0,0,0,0,0,0,0,0,0,0,14,10,2
0,0,0,0,2,10,0,0,0,0,0,0,0,0,0,0,0,0,0,0,0,0,0,0,0,0,0,0,10,2
0,0,0,0,2,10,0,0,0,0,0,0,0,0,0,0,0,0,0,0,0,0,0,0,0,0,0,0,10,2
0,0,0,0,2,10,0,0,0,0,0,0,0,0,0,0,0,0,0,0,0,0,0,0,0,0,0,0,10,2
0,0,0,0,2,10,12,0,12,0,12,0,12,0,12,0,0,0,0,12,0,12,0,12,0,12,0,12,10,2
0,0,0,0,2,10,11,0,11,0,11,0,11,0,11,0,0,0,0,11,0,11,0,11,0,11,0,11,10,2
0,0,0,0,2,10,10,10,10,10,10,10,10,10,10,10,0,0,10,10,10,10,10,10,10,10,10,10,10,2
0,0,0,0,2,2,2,2,2,2,2,2,2,2,2,2,0,0,2,2,2,2,2,2,2,2,2,2,2,2
endlayer

layer
0,0,0,0,15,15,15,15,15,15,15,15,15,15,15,2,0,0,2,15,15,15,15,15,15,15,15,15,15,15
0,0,0,0,15,10,0,0,0,0,0,0,0,0,0,10,0,0,10,0,0,0,0,0,0,0,0,0,10,15
0,0,0,0,15,0,0,0,0,0,0,0,0,0,0,0,0,0,0,0,0,0,0,0,0,0,0,0,0,15
0,0,0,0,15,0,0,0,0,0,0,0,0,0,0,0,0,0,0,0,0,0,0,0,0,0,0,0,0,15
0,0,0,0,15,0,0,0,0,0,0,0,0,0,0,0,0,0,0,0,0,0,0,0,0,0,0,0,0,15
0,0,0,0,15,0,0,0,0,0,0,0,0,0,0,0,0,0,0,0,0,0,0,0,0,0,0,0,0,15
0,0,0,0,15,14,0,0,0,0,0,0,0,0,0,0,0,0,0,0,0,0,0,0,0,0,0,0,0,15
0,0,0,0,15,0,0,0,0,0,0,0,0,0,0,0,0,0,0,0,0,0,0,0,0,0,0,0,0,15
0,0,0,0,15,0,0,0,0,0,0,0,0,0,0,0,0,0,0,0,0,0,0,0,0,13,0,13,0,15
0,0,0,0,15,0,0,0,0,0,0,0,0,0,0,0,0,0,0,0,0,0,0,0,0,13,11,13,0,15
0,0,0,0,15,0,13,13,13,0,0,0,0,0,0,0,0,0,0,0,0,0,0,0,0,13,13,13,0,15
0,0,0,0,15,0,13,11,13,0,0,0,0,0,0,0,0,0,0,0,0,0,0,0,0,0,0,0,0,15
0,0,0,0,15,0,13,0,13,0,0,0,0,0,0,0,0,0,0,0,0,0,0,0,0,0,0,0,0,15
0,0,0,0,15,0,0,0,0,0,0,0,0,0,0,0,0,0,0,0,0,0,0,0,0,0,0,14,0,15
0,0,0,0,15,0,0,0,0,0,0,0,0,0,0,0,0,0,0,0,0,0,0,0,0,0,0,0,0,15
0,0,0,0,15,0,0,0,0,0,0,0,0,0,0,0,0,0,0,0,0,0,0,0,0,0,0,0,0,15
0,0,0,0,15,0,0,0,0,0,0,0,0,0,0,0,0,0,0,0,0,0,0,0,0,0,0,0,0,15
0,0,0,0,15,0,0,0,0,0,0,0,0,0,0,0,0,0,0,0,0,0,0,0,0,0,0,0,0,15
0,0,0,0,15,0,0,0,0,0,0,0,0,0,0,0,0,0,0,0,0,0,0,0,0,0,0,0,0,15
0,0,0,0,15,10,0,0,0,0,0,0,0,0,0,10,0,0,10,0,0,0,0,0,0,0,0,0,10,15
0,0,0,0,15,15,15,15,15,15,15,15,15,15,15,2,0,0,2,15,15,15,15,15,15,15,15,15,15,15
endlayer

layer
0,0,0,0,16,16,16,16,16,16,16,16,16,16,16,2,15,15,2,16,16,16,16,16,16,16,16,16,16,16
0,0,0,0,16,0,0,0,0,0,0,0,0,0,0,0,0,0,0,0,0,0,0,0,0,0,0,0,0,16
0,0,0,0,16,0,0,0,0,0,0,0,0,0,0,0,0,0,0,0,0,0,0,0,0,0,0,0,0,16
0,0,0,0,16,0,0,0,0,0,0,0,0,0,0,0,0,0,0,0,0,0,0,0,0,0,0,0,0,16
0,0,0,0,16,0,0,0,0,0,0,0,0,0,0,0,0,0,0,0,0,0,0,0,0,0,0,0,0,16
0,0,0,0,16,0,0,0,0,0,0,0,0,0,0,0,0,0,0,0,0,0,0,0,0,0,0,0,0,16
0,0,0,0,16,14,0,0,0,0,0,0,0,0,0,0,0,0,0,0,0,0,0,0,0,0,0,0,0,16
0,0,0,0,16,0,0,0,0,0,0,0,0,0,0,0,0,0,0,0,0,0,0,0,0,0,0,0,0,16
0,0,0,0,16,0,0,0,0,0,0,0,0,0,0,0,0,0,0,0,0,0,0,0,0,0,13,0,0,16
0,0,0,0,16,0,0,0,0,0,0,0,0,0,0,0,0,0,0,0,0,0,0,0,0,13,0,13,0,16
0,0,0,0,16,0,0,13,0,0,0,0,0,0,0,0,0,0,0,0,0,0,0,0,0,0,13,0,0,16
0,0,0,0,16,0,13,0,13,0,0,0,0,0,0,0,0,0,0,0,0,0,0,0,0,0,0,0,0,16
0,0,0,0,16,0,0,13,0,0,0,0,0,0,0,0,0,0,0,0,0,0,0,0,0,0,0,0,0,16
0,0,0,0,16,0,0,0,0,0,0,0,0,0,0,0,0,0,0,0,0,0,0,0,0,0,0,14,0,16
0,0,0,0,16,0,0,0,0,0,0,0,0,0,0,0,0,0,0,0,0,0,0,0,0,0,0,0,0,16
0,0,0,0,16,0,0,0,0,0,0,0,0,0,0,0,0,0,0,0,0,0,0,0,0,0,0,0,0,16
0,0,0,0,16,0,0,0,0,0,0,0,0,0,0,0,0,0,0,0,0,0,0,0,0,0,0,0,0,16
0,0,0,0,16,0,0,0,0,0,0,0,0,0,0,0,0,0,0,0,0,0,0,0,0,0,0,0,0,16
0,0,0,0,16,0,0,0,0,0,0,0,0,0,0,0,0,0,0,0,0,0,0,0,0,0,0,0,0,16
0,0,0,0,16,0,0,0,0,0,0,0,0,0,0,0,0,0,0,0,0,0,0,0,0,0,0,0,0,16
0,0,0,0,16,16,16,16,16,16,16,16,16,16,16,2,15,15,2,16,16,16,16,16,16,16,16,16,16,16
endlayer

layer
0,0,0,0,0,0,0,0,0,0,0,0,0,0,0,0,2,2,0,0,0,0,0,0,0,0,0,0,0,0
0,0,0,0,0,0,0,0,0,0,0,0,0,0,0,0,0,0,0,0,0,0,0,0,0,0,0,0,0,0
0,0,0,0,0,0,0,0,0,0,0,0,0,0,0,0,0,0,0,0,0,0,0,0,0,0,0,0,0,0
0,0,0,0,0,0,0,0,0,0,0,0,0,0,0,0,0,0,0,0,0,0,0,0,0,0,0,0,0,0
0,0,0,0,0,0,0,0,0,0,0,0,0,0,0,0,0,0,0,0,0,0,0,0,0,0,0,0,0,0
0,0,0,0,0,0,0,0,0,0,0,0,0,0,0,0,0,0,0,0,0,0,0,0,0,0,0,0,0,0
0,0,0,0,0,14,0,0,0,0,0,0,0,0,0,0,0,0,0,0,0,0,0,0,0,0,0,0,0,0
0,0,0,0,0,0,0,0,0,0,0,0,0,0,0,0,0,0,0,0,0,0,0,0,0,0,0,0,0,0
0,0,0,0,0,0,0,0,0,0,0,0,0,0,0,0,0,0,0,0,0,0,0,0,0,0,0,0,0,0
0,0,0,0,0,0,0,0,0,0,0,0,0,0,0,0,0,0,0,0,0,0,0,0,0,0,13,0,0,0
0,0,0,0,0,0,0,0,0,0,0,0,0,0,0,0,0,0,0,0,0,0,0,0,0,0,0,0,0,0
0,0,0,0,0,0,0,13,0,0,0,0,0,0,0,0,0,0,0,0,0,0,0,0,0,0,0,0,0,0
0,0,0,0,0,0,0,0,0,0,0,0,0,0,0,0,0,0,0,0,0,0,0,0,0,0,0,0,0,0
0,0,0,0,0,0,0,0,0,0,0,0,0,0,0,0,0,0,0,0,0,0,0,0,0,0,0,14,0,0
0,0,0,0,0,0,0,0,0,0,0,0,0,0,0,0,0,0,0,0,0,0,0,0,0,0,0,0,0,0
0,0,0,0,0,0,0,0,0,0,0,0,0,0,0,0,0,0,0,0,0,0,0,0,0,0,0,0,0,0
0,0,0,0,0,0,0,0,0,0,0,0,0,0,0,0,0,0,0,0,0,0,0,0,0,0,0,0,0,0
0,0,0,0,0,0,0,0,0,0,0,0,0,0,0,0,0,0,0,0,0,0,0,0,0,0,0,0,0,0
0,0,0,0,0,0,0,0,0,0,0,0,0,0,0,0,0,0,0,0,0,0,0,0,0,0,0,0,0,0
0,0,0,0,0,0,0,0,0,0,0,0,0,0,0,0,0,0,0,0,0,0,0,0,0,0,0,0,0,0
0,0,0,0,0,0,0,0,0,0,0,0,0,0,0,0,2,2,0,0,0,0,0,0,0,0,0,0,0,0
endlayer

layer
0,0,0,0,0,0,0,0,0,0,0,0,0,0,0,0,0,0,0,0,0,0,0,0,0,0,0,0,0,0
0,0,0,0,0,0,0,0,0,0,0,0,0,0,0,0,0,0,0,0,0,0,0,0,0,0,0,0,0,0
0,0,0,0,0,0,0,0,0,0,0,0,0,0,0,0,0,0,0,0,0,0,0,0,0,0,0,0,0,0
0,0,0,0,0,0,0,0,0,0,0,0,0,0,0,0,0,0,0,0,0,0,0,0,0,0,0,0,0,0
0,0,0,0,0,0,0,0,0,0,0,0,0,0,0,0,0,0,0,0,0,0,0,0,0,0,0,0,0,0
0,0,0,0,0,0,0,0,0,0,0,0,0,0,0,0,0,0,0,0,0,0,0,0,0,0,0,0,0,0
0,0,0,0,0,14,17,17,0,10,0,0,0,0,0,0,0,0,0,0,0,0,0,0,0,0,0,0,0,0
0,0,0,0,0,0,17,17,10,10,10,0,0,0,0,0,0,0,0,0,0,0,0,0,0,0,0,0,0,0
0,0,0,0,0,0,0,10,0,10,0,0,0,0,0,0,0,0,0,0,0,0,0,0,0,0,0,0,0,0
0,0,0,0,0,0,0,0,0,0,0,0,0,0,0,0,0,0,0,0,0,0,0,0,0,0,0,0,0,0
0,0,0,0,0,0,0,0,0,0,0,0,0,0,0,0,0,0,0,0,0,0,0,0,0,0,0,0,0,0
0,0,0,0,0,0,0,0,0,0,0,0,0,0,0,0,0,0,0,0,0,0,0,0,0,10,10,10,10,0
0,0,0,0,0,0,0,0,0,0,0,0,0,0,0,0,0,0,0,0,0,0,0,0,0,10,10,10,10,10
0,0,0,0,0,0,0,0,0,0,0,0,0,0,0,0,0,0,0,0,0,0,0,0,0,10,10,14,10,10
0,0,0,0,0,0,0,0,0,0,0,0,0,0,0,0,0,0,0,0,0,0,0,0,0,10,10,10,10,10
0,0,0,0,0,0,0,0,0,0,0,0,0,0,0,0,0,0,0,0,0,0,0,0,0,10,10,10,10,0
0,0,0,0,0,0,0,0,0,0,0,0,0,0,0,0,0,0,0,0,0,0,0,0,0,0,0,0,0,0
0,0,0,0,0,0,0,0,0,0,0,0,0,0,0,0,0,0,0,0,0,0,0,0,0,0,0,0,0,0
0,0,0,0,0,0,0,0,0,0,0,0,0,0,0,0,0,0,0,0,0,0,0,0,0,0,0,0,0,0
0,0,0,0,0,0,0,0,0,0,0,0,0,0,0,0,0,0,0,0,0,0,0,0,0,0,0,0,0,0
0,0,0,0,0,0,0,0,0,0,0,0,0,0,0,0,0,0,0,0,0,0,0,0,0,0,0,0,0,0
endlayer

layer
0,0,0,0,0,0,0,0,0,0,0,0,0,0,0,0,0,0,0,0,0,0,0,0,0,0,0,0,0,0
0,0,0,0,0,0,0,0,0,0,0,0,0,0,0,0,0,0,0,0,0,0,0,0,0,0,0,0,0,0
0,0,0,0,0,0,0,0,0,0,0,0,0,0,0,0,0,0,0,0,0,0,0,0,0,0,0,0,0,0
0,0,0,0,0,0,0,0,0,0,0,0,0,0,0,0,0,0,0,0,0,0,0,0,0,0,0,0,0,0
0,0,0,0,0,0,0,0,0,0,0,0,0,0,0,0,0,0,0,0,0,0,0,0,0,0,0,0,0,0
0,0,0,0,0,0,10,10,10,10,10,0,0,0,0,0,0,0,0,0,0,0,0,0,0,0,0,0,0,0
0,0,0,0,0,14,10,10,17,17,10,10,0,0,0,0,0,0,0,0,0,0,0,0,0,0,0,0,0,0
0,0,0,0,0,10,10,10,10,10,10,10,0,0,0,0,0,0,0,0,0,0,0,0,0,0,0,0,0,0
0,0,0,0,0,10,10,10,17,10,10,10,0,0,0,0,0,0,0,0,0,0,0,0,0,0,0,0,0,0
0,0,0,0,0,0,10,10,10,10,10,0,0,0,0,0,0,0,0,0,0,0,0,0,0,0,0,0,0,0
0,0,0,0,0,0,0,0,0,0,0,0,0,0,0,0,0,0,0,0,0,0,0,0,0,0,0,0,0,0
0,0,0,0,0,0,0,0,0,0,0,0,0,0,0,0,0,0,0,0,0,0,0,0,0,0,10,10,10,10
0,0,0,0,0,0,0,0,0,0,0,0,0,0,0,0,0,0,0,0,0,0,0,0,0,10,10,10,10,10
0,0,0,0,0,0,0,0,0,0,0,0,0,0,0,0,0,0,0,0,0,0,0,0,0,10,10,14,10,10
0,0,0,0,0,0,0,0,0,0,0,0,0,0,0,0,0,0,0,0,0,0,0,0,0,10,10,10,10,10
0,0,0,0,0,0,0,0,0,0,0,0,0,0,0,0,0,0,0,0,0,0,0,0,0,0,10,10,10,0
0,0,0,0,0,0,0,0,0,0,0,0,0,0,0,0,0,0,0,0,0,0,0,0,0,0,0,0,0,0
0,0,0,0,0,0,0,0,0,0,0,0,0,0,0,0,0,0,0,0,0,0,0,0,0,0,0,0,0,0
0,0,0,0,0,0,0,0,0,0,0,0,0,0,0,0,0,0,0,0,0,0,0,0,0,0,0,0,0,0
0,0,0,0,0,0,0,0,0,0,0,0,0,0,0,0,0,0,0,0,0,0,0,0,0,0,0,0,0,0
0,0,0,0,0,0,0,0,0,0,0,0,0,0,0,0,0,0,0,0,0,0,0,0,0,0,0,0,0,0
endlayer

layer
0,0,0,0,0,0,0,0,0,0,0,0,0,0,0,0,0,0,0,0,0,0,0,0,0,0,0,0,0,0
0,0,0,0,0,0,0,0,0,0,0,0,0,0,0,0,0,0,0,0,0,0,0,0,0,0,0,0,0,0
0,0,0,0,0,0,0,0,0,0,0,0,0,0,0,0,0,0,0,0,0,0,0,0,0,0,0,0,0,0
0,0,0,0,0,0,10,0,0,0,0,0,0,0,0,0,0,0,0,0,0,0,0,0,0,0,0,0,0,0
0,0,0,17,0,10,18,10,10,10,10,0,0,0,0,0,0,0,0,0,0,0,0,0,0,0,0,0,0,0
0,0,0,0,17,10,17,10,10,10,10,10,0,0,0,0,0,0,0,0,0,0,0,0,0,0,0,0,0,0
0,0,0,0,0,14,10,10,10,10,10,10,0,0,0,0,0,0,0,0,0,0,0,0,0,0,0,0,0,0
0,0,0,0,0,10,17,10,10,10,10,10,0,0,0,0,0,0,0,0,0,0,0,0,0,0,0,0,0,0
0,0,0,0,0,10,10,17,10,10,10,10,0,0,0,0,0,0,0,0,0,0,0,0,0,0,0,0,0,0
0,0,0,0,0,0,10,10,10,10,10,0,0,0,0,0,0,0,0,0,0,0,0,0,0,0,0,0,0,0
0,0,0,0,0,0,0,10,10,10,0,0,0,0,0,0,0,0,0,0,0,0,0,0,0,0,0,0,0,0
0,0,0,0,0,0,0,0,0,0,0,0,0,0,0,0,0,0,0,0,0,0,0,0,0,0,0,0,0,0
0,0,0,0,0,0,0,0,0,0,0,0,0,0,0,0,0,0,0,0,0,0,0,0,0,0,10,10,0,0
0,0,0,0,0,0,0,0,0,0,0,0,0,0,0,0,0,0,0,0,0,0,0,0,0,0,10,14,10,0
0,0,0,0,0,0,0,0,0,0,0,0,0,0,0,0,0,0,0,0,0,0,0,0,0,0,10,10,0,0
0,0,0,0,0,0,0,0,0,0,0,0,0,0,0,0,0,0,0,0,0,0,0,0,0,0,0,0,0,0
0,0,0,0,0,0,0,0,0,0,0,0,0,0,0,0,0,0,0,0,0,0,0,0,0,0,0,0,0,0
0,0,0,0,0,0,0,0,0,0,0,0,0,0,0,0,0,0,0,0,0,0,0,0,0,0,0,0,0,0
0,0,0,0,0,0,0,0,0,0,0,0,0,0,0,0,0,0,0,0,0,0,0,0,0,0,0,0,0,0
0,0,0,0,0,0,0,0,0,0,0,0,0,0,0,0,0,0,0,0,0,0,0,0,0,0,0,0,0,0
0,0,0,0,0,0,0,0,0,0,0,0,0,0,0,0,0,0,0,0,0,0,0,0,0,0,0,0,0,0
endlayer

layer
0,0,0,0,0,0,0,0,0,0,0,0,0,0,0,0,0,0,0,0,0,0,0,0,0,0,0,0,0,0
0,0,0,0,0,0,0,0,0,0,0,0,0,0,0,0,0,0,0,0,0,0,0,0,0,0,0,0,0,0
0,0,10,0,0,10,10,10,0,0,0,0,0,0,0,0,0,0,0,0,0,0,0,0,0,0,0,0,0,0
0,10,17,10,10,10,10,10,10,0,0,0,0,0,0,0,0,0,0,0,0,0,0,0,0,0,0,0,0,0
0,0,10,0,10,10,10,10,10,10,10,0,0,0,0,0,0,0,0,0,0,0,0,0,0,0,0,0,0,0
0,0,0,0,10,10,10,10,10,10,10,10,0,0,0,0,0,0,0,0,0,0,0,0,0,0,0,0,0,0
0,0,0,0,10,14,17,17,10,10,10,10,0,0,0,0,0,0,0,0,0,0,0,0,0,0,0,0,0,0
0,0,0,0,0,18,10,10,10,10,10,10,0,0,0,0,0,0,0,0,0,0,0,0,0,0,0,0,0,0
0,0,0,0,18,0,10,10,10,10,10,0,0,0,0,0,0,0,0,0,0,0,0,0,0,0,0,0,0,0
0,0,0,0,0,0,10,10,17,10,10,0,0,0,0,0,0,0,0,0,0,0,0,0,0,0,0,0,0,0
0,0,0,0,0,0,0,10,10,10,0,0,0,0,0,0,0,0,0,0,0,0,0,0,0,0,0,0,0,0
0,0,0,0,0,0,0,0,0,0,0,0,0,0,0,0,0,0,0,0,0,0,0,0,0,0,0,0,0,0
0,0,0,0,0,0,0,0,0,0,0,0,0,0,0,0,0,0,0,0,0,0,0,0,0,0,0,10,0,0
0,0,0,0,0,0,0,0,0,0,0,0,0,0,0,0,0,0,0,0,0,0,0,0,0,0,10,10,10,0
0,0,0,0,0,0,0,0,0,0,0,0,0,0,0,0,0,0,0,0,0,0,0,0,0,0,0,10,0,0
0,0,0,0,0,0,0,0,0,0,0,0,0,0,0,0,0,0,0,0,0,0,0,0,0,0,0,0,0,0
0,0,0,0,0,0,0,0,0,0,0,0,0,0,0,0,0,0,0,0,0,0,0,0,0,0,0,0,0,0
0,0,0,0,0,0,0,0,0,0,0,0,0,0,0,0,0,0,0,0,0,0,0,0,0,0,0,0,0,0
0,0,0,0,0,0,0,0,0,0,0,0,0,0,0,0,0,0,0,0,0,0,0,0,0,0,0,0,0,0
0,0,0,0,0,0,0,0,0,0,0,0,0,0,0,0,0,0,0,0,0,0,0,0,0,0,0,0,0,0
0,0,0,0,0,0,0,0,0,0,0,0,0,0,0,0,0,0,0,0,0,0,0,0,0,0,0,0,0,0
endlayer

layer
0,0,0,0,0,0,0,0,0,0,0,0,0,0,0,0,0,0,0,0,0,0,0,0,0,0,0,0,0,0
0,10,10,10,0,0,0,0,0,0,0,0,0,0,0,0,0,0,0,0,0,0,0,0,0,0,0,0,0,0
10,10,10,10,10,10,10,10,0,0,0,0,0,0,0,0,0,0,0,0,0,0,0,0,0,0,0,0,0,0
10,10,10,10,10,10,10,10,10,0,0,0,0,0,0,0,0,0,0,0,0,0,0,0,0,0,0,0,0,0
10,10,10,10,10,10,10,10,10,0,0,0,0,0,0,0,0,0,0,0,0,0,0,0,0,0,0,0,0,0
0,10,10,10,10,10,10,10,10,10,0,0,0,0,0,0,0,0,0,0,0,0,0,0,0,0,0,0,0,0
0,0,0,0,10,14,10,10,17,17,10,0,0,0,0,0,0,0,0,0,0,0,0,0,0,0,0,0,0,0
0,0,0,0,17,10,10,10,10,10,0,0,0,0,0,0,0,0,0,0,0,0,0,0,0,0,0,0,0,0
0,0,0,0,10,0,10,10,10,10,10,0,0,0,0,0,0,0,0,0,0,0,0,0,0,0,0,0,0,0
0,0,0,10,18,10,10,10,10,10,10,0,0,0,0,0,0,0,0,0,0,0,0,0,0,0,0,0,0,0
0,0,0,0,10,0,10,10,10,10,10,0,0,0,0,0,0,0,0,0,0,0,0,0,0,0,0,0,0,0
0,0,0,0,0,0,0,10,10,10,0,0,0,0,0,0,0,0,0,0,0,0,0,0,0,0,0,0,0,0
0,0,0,0,0,0,0,0,0,0,0,0,0,0,0,0,0,0,0,0,0,0,0,0,0,0,0,0,0,0
0,0,0,0,0,0,0,0,0,0,0,0,0,0,0,0,0,0,0,0,0,0,0,0,0,0,0,0,0,0
0,0,0,0,0,0,0,0,0,0,0,0,0,0,0,0,0,0,0,0,0,0,0,0,0,0,0,0,0,0
0,0,0,0,0,0,0,0,0,0,0,0,0,0,0,0,0,0,0,0,0,0,0,0,0,0,0,0,0,0
0,0,0,0,0,0,0,0,0,0,0,0,0,0,0,0,0,0,0,0,0,0,0,0,0,0,0,0,0,0
0,0,0,0,0,0,0,0,0,0,0,0,0,0,0,0,0,0,0,0,0,0,0,0,0,0,0,0,0,0
0,0,0,0,0,0,0,0,0,0,0,0,0,0,0,0,0,0,0,0,0,0,0,0,0,0,0,0,0,0
0,0,0,0,0,0,0,0,0,0,0,0,0,0,0,0,0,0,0,0,0,0,0,0,0,0,0,0,0,0
0,0,0,0,0,0,0,0,0,0,0,0,0,0,0,0,0,0,0,0,0,0,0,0,0,0,0,0,0,0
endlayer

layer
0,0,0,0,0,0,0,0,0,0,0,0,0,0,0,0,0,0,0,0,0,0,0,0,0,0,0,0,0,0
0,10,10,10,0,0,0,0,0,0,0,0,0,0,0,0,0,0,0,0,0,0,0,0,0,0,0,0,0,0
10,10,10,10,10,0,0,0,0,0,0,0,0,0,0,0,0,0,0,0,0,0,0,0,0,0,0,0,0,0
10,10,10,10,10,0,10,0,0,0,0,0,0,0,0,0,0,0,0,0,0,0,0,0,0,0,0,0,0,0
10,10,10,10,10,10,10,10,10,10,10,0,0,0,0,0,0,0,0,0,0,0,0,0,0,0,0,0,0,0
0,10,10,17,10,10,10,10,10,10,10,10,0,0,0,0,0,0,0,0,0,0,0,0,0,0,0,0,0,0
0,0,0,10,17,14,10,10,10,10,10,10,0,0,0,0,0,0,0,0,0,0,0,0,0,0,0,0,0,0
0,0,0,10,10,10,0,10,10,10,10,10,0,0,0,0,0,0,0,0,0,0,0,0,0,0,0,0,0,0
0,0,10,17,10,10,10,10,10,10,10,0,0,0,0,0,0,0,0,0,0,0,0,0,0,0,0,0,0,0
0,0,10,10,10,10,10,10,10,10,10,0,0,0,0,0,0,0,0,0,0,0,0,0,0,0,0,0,0,0
0,0,10,10,10,10,10,10,10,10,10,0,0,0,0,0,0,0,0,0,0,0,0,0,0,0,0,0,0,0
0,0,0,10,10,10,0,10,10,10,0,0,0,0,0,0,0,0,0,0,0,0,0,0,0,0,0,0,0,0
0,0,0,0,0,0,0,0,0,0,0,0,0,0,0,0,0,0,0,0,0,0,0,0,0,0,0,0,0,0
0,0,0,0,0,0,0,0,0,0,0,0,0,0,0,0,0,0,0,0,0,0,0,0,0,0,0,0,0,0
0,0,0,0,0,0,0,0,0,0,0,0,0,0,0,0,0,0,0,0,0,0,0,0,0,0,0,0,0,0
0,0,0,0,0,0,0,0,0,0,0,0,0,0,0,0,0,0,0,0,0,0,0,0,0,0,0,0,0,0
0,0,0,0,0,0,0,0,0,0,0,0,0,0,0,0,0,0,0,0,0,0,0,0,0,0,0,0,0,0
0,0,0,0,0,0,0,0,0,0,0,0,0,0,0,0,0,0,0,0,0,0,0,0,0,0,0,0,0,0
0,0,0,0,0,0,0,0,0,0,0,0,0,0,0,0,0,0,0,0,0,0,0,0,0,0,0,0,0,0
0,0,0,0,0,0,0,0,0,0,0,0,0,0,0,0,0,0,0,0,0,0,0,0,0,0,0,0,0,0
0,0,0,0,0,0,0,0,0,0,0,0,0,0,0,0,0,0,0,0,0,0,0,0,0,0,0,0,0,0
endlayer

layer
0,0,0,0,0,0,0,0,0,0,0,0,0,0,0,0,0,0,0,0,0,0,0,0,0,0,0,0,0,0
0,0,0,0,0,0,0,0,0,0,0,0,0,0,0,0,0,0,0,0,0,0,0,0,0,0,0,0,0,0
0,0,10,0,0,0,0,0,0,0,0,0,0,0,0,0,0,0,0,0,0,0,0,0,0,0,0,0,0,0
0,10,10,10,10,0,0,0,0,0,0,0,0,0,0,0,0,0,0,0,0,0,0,0,0,0,0,0,0,0
0,10,10,10,10,10,0,0,10,10,10,0,0,0,0,0,0,0,0,0,0,0,0,0,0,0,0,0,0,0
0,10,10,10,10,10,0,10,10,10,10,10,0,0,0,0,0,0,0,0,0,0,0,0,0,0,0,0,0,0
0,10,10,10,10,14,10,10,10,10,10,10,0,0,0,0,0,0,0,0,0,0,0,0,0,0,0,0,0,0
0,10,10,10,10,10,0,10,10,10,10,10,0,0,0,0,0,0,0,0,0,0,0,0,0,0,0,0,0,0
0,10,10,10,10,10,10,0,10,10,10,0,0,0,0,0,0,0,0,0,0,0,0,0,0,0,0,0,0,0
0,10,10,10,10,10,10,10,10,10,0,0,0,0,0,0,0,0,0,0,0,0,0,0,0,0,0,0,0,0
0,0,10,10,10,10,10,0,10,0,0,0,0,0,0,0,0,0,0,0,0,0,0,0,0,0,0,0,0,0
0,0,0,10,10,10,0,0,0,0,0,0,0,0,0,0,0,0,0,0,0,0,0,0,0,0,0,0,0,0
0,0,0,0,0,0,0,0,0,0,0,0,0,0,0,0,0,0,0,0,0,0,0,0,0,0,0,0,0,0
0,0,0,0,0,0,0,0,0,0,0,0,0,0,0,0,0,0,0,0,0,0,0,0,0,0,0,0,0,0
0,0,0,0,0,0,0,0,0,0,0,0,0,0,0,0,0,0,0,0,0,0,0,0,0,0,0,0,0,0
0,0,0,0,0,0,0,0,0,0,0,0,0,0,0,0,0,0,0,0,0,0,0,0,0,0,0,0,0,0
0,0,0,0,0,0,0,0,0,0,0,0,0,0,0,0,0,0,0,0,0,0,0,0,0,0,0,0,0,0
0,0,0,0,0,0,0,0,0,0,0,0,0,0,0,0,0,0,0,0,0,0,0,0,0,0,0,0,0,0
0,0,0,0,0,0,0,0,0,0,0,0,0,0,0,0,0,0,0,0,0,0,0,0,0,0,0,0,0,0
0,0,0,0,0,0,0,0,0,0,0,0,0,0,0,0,0,0,0,0,0,0,0,0,0,0,0,0,0,0
0,0,0,0,0,0,0,0,0,0,0,0,0,0,0,0,0,0,0,0,0,0,0,0,0,0,0,0,0,0
endlayer

layer
0,0,0,0,0,0,0,0,0,0,0,0,0,0,0,0,0,0,0,0,0,0,0,0,0,0,0,0,0,0
0,0,0,0,0,0,0,0,0,0,0,0,0,0,0,0,0,0,0,0,0,0,0,0,0,0,0,0,0,0
0,0,0,0,0,0,0,0,0,0,0,0,0,0,0,0,0,0,0,0,0,0,0,0,0,0,0,0,0,0
0,0,10,10,10,0,0,0,0,0,0,0,0,0,0,0,0,0,0,0,0,0,0,0,0,0,0,0,0,0
0,10,10,10,10,10,10,0,0,0,0,0,0,0,0,0,0,0,0,0,0,0,0,0,0,0,0,0,0,0
0,10,10,10,10,10,10,10,0,10,0,0,0,0,0,0,0,0,0,0,0,0,0,0,0,0,0,0,0,0
0,10,10,10,10,10,10,10,10,10,10,0,0,0,0,0,0,0,0,0,0,0,0,0,0,0,0,0,0,0
0,10,10,10,10,10,10,10,0,10,0,0,0,0,0,0,0,0,0,0,0,0,0,0,0,0,0,0,0,0
0,10,10,10,10,10,10,0,0,0,0,0,0,0,0,0,0,0,0,0,0,0,0,0,0,0,0,0,0,0
0,10,10,10,10,10,0,0,0,0,0,0,0,0,0,0,0,0,0,0,0,0,0,0,0,0,0,0,0,0
0,0,10,10,10,0,0,0,0,0,0,0,0,0,0,0,0,0,0,0,0,0,0,0,0,0,0,0,0,0
0,0,0,0,0,0,0,0,0,0,0,0,0,0,0,0,0,0,0,0,0,0,0,0,0,0,0,0,0,0
0,0,0,0,0,0,0,0,0,0,0,0,0,0,0,0,0,0,0,0,0,0,0,0,0,0,0,0,0,0
0,0,0,0,0,0,0,0,0,0,0,0,0,0,0,0,0,0,0,0,0,0,0,0,0,0,0,0,0,0
0,0,0,0,0,0,0,0,0,0,0,0,0,0,0,0,0,0,0,0,0,0,0,0,0,0,0,0,0,0
0,0,0,0,0,0,0,0,0,0,0,0,0,0,0,0,0,0,0,0,0,0,0,0,0,0,0,0,0,0
0,0,0,0,0,0,0,0,0,0,0,0,0,0,0,0,0,0,0,0,0,0,0,0,0,0,0,0,0,0
0,0,0,0,0,0,0,0,0,0,0,0,0,0,0,0,0,0,0,0,0,0,0,0,0,0,0,0,0,0
0,0,0,0,0,0,0,0,0,0,0,0,0,0,0,0,0,0,0,0,0,0,0,0,0,0,0,0,0,0
0,0,0,0,0,0,0,0,0,0,0,0,0,0,0,0,0,0,0,0,0,0,0,0,0,0,0,0,0,0
0,0,0,0,0,0,0,0,0,0,0,0,0,0,0,0,0,0,0,0,0,0,0,0,0,0,0,0,0,0
endlayer

layer
0,0,0,0,0,0,0,0,0,0,0,0,0,0,0,0,0,0,0,0,0,0,0,0,0,0,0,0,0,0
0,0,0,0,0,0,0,0,0,0,0,0,0,0,0,0,0,0,0,0,0,0,0,0,0,0,0,0,0,0
0,0,0,0,0,0,0,0,0,0,0,0,0,0,0,0,0,0,0,0,0,0,0,0,0,0,0,0,0,0
0,0,0,0,0,0,0,0,0,0,0,0,0,0,0,0,0,0,0,0,0,0,0,0,0,0,0,0,0,0
0,0,0,10,10,10,10,0,0,0,0,0,0,0,0,0,0,0,0,0,0,0,0,0,0,0,0,0,0,0
0,0,10,10,10,10,10,10,0,0,0,0,0,0,0,0,0,0,0,0,0,0,0,0,0,0,0,0,0,0
0,0,0,10,10,10,10,10,0,0,0,0,0,0,0,0,0,0,0,0,0,0,0,0,0,0,0,0,0,0
0,0,0,10,10,10,10,10,0,0,0,0,0,0,0,0,0,0,0,0,0,0,0,0,0,0,0,0,0,0
0,0,10,10,10,10,10,0,0,0,0,0,0,0,0,0,0,0,0,0,0,0,0,0,0,0,0,0,0,0
0,0,0,10,0,0,0,0,0,0,0,0,0,0,0,0,0,0,0,0,0,0,0,0,0,0,0,0,0,0
0,0,0,0,0,0,0,0,0,0,0,0,0,0,0,0,0,0,0,0,0,0,0,0,0,0,0,0,0,0
0,0,0,0,0,0,0,0,0,0,0,0,0,0,0,0,0,0,0,0,0,0,0,0,0,0,0,0,0,0
0,0,0,0,0,0,0,0,0,0,0,0,0,0,0,0,0,0,0,0,0,0,0,0,0,0,0,0,0,0
0,0,0,0,0,0,0,0,0,0,0,0,0,0,0,0,0,0,0,0,0,0,0,0,0,0,0,0,0,0
0,0,0,0,0,0,0,0,0,0,0,0,0,0,0,0,0,0,0,0,0,0,0,0,0,0,0,0,0,0
0,0,0,0,0,0,0,0,0,0,0,0,0,0,0,0,0,0,0,0,0,0,0,0,0,0,0,0,0,0
0,0,0,0,0,0,0,0,0,0,0,0,0,0,0,0,0,0,0,0,0,0,0,0,0,0,0,0,0,0
0,0,0,0,0,0,0,0,0,0,0,0,0,0,0,0,0,0,0,0,0,0,0,0,0,0,0,0,0,0
0,0,0,0,0,0,0,0,0,0,0,0,0,0,0,0,0,0,0,0,0,0,0,0,0,0,0,0,0,0
0,0,0,0,0,0,0,0,0,0,0,0,0,0,0,0,0,0,0,0,0,0,0,0,0,0,0,0,0,0
0,0,0,0,0,0,0,0,0,0,0,0,0,0,0,0,0,0,0,0,0,0,0,0,0,0,0,0,0,0
endlayer

layer
0,0,0,0,0,0,0,0,0,0,0,0,0,0,0,0,0,0,0,0,0,0,0,0,0,0,0,0,0,0
0,0,0,0,0,0,0,0,0,0,0,0,0,0,0,0,0,0,0,0,0,0,0,0,0,0,0,0,0,0
0,0,0,0,0,0,0,0,0,0,0,0,0,0,0,0,0,0,0,0,0,0,0,0,0,0,0,0,0,0
0,0,0,0,0,0,0,0,0,0,0,0,0,0,0,0,0,0,0,0,0,0,0,0,0,0,0,0,0,0
0,0,0,0,0,0,0,0,0,0,0,0,0,0,0,0,0,0,0,0,0,0,0,0,0,0,0,0,0,0
0,0,0,0,0,10,0,0,0,0,0,0,0,0,0,0,0,0,0,0,0,0,0,0,0,0,0,0,0,0
0,0,0,0,10,10,10,0,0,0,0,0,0,0,0,0,0,0,0,0,0,0,0,0,0,0,0,0,0,0
0,0,0,0,0,10,0,0,0,0,0,0,0,0,0,0,0,0,0,0,0,0,0,0,0,0,0,0,0,0
0,0,0,0,0,0,0,0,0,0,0,0,0,0,0,0,0,0,0,0,0,0,0,0,0,0,0,0,0,0
0,0,0,0,0,0,0,0,0,0,0,0,0,0,0,0,0,0,0,0,0,0,0,0,0,0,0,0,0,0
0,0,0,0,0,0,0,0,0,0,0,0,0,0,0,0,0,0,0,0,0,0,0,0,0,0,0,0,0,0
0,0,0,0,0,0,0,0,0,0,0,0,0,0,0,0,0,0,0,0,0,0,0,0,0,0,0,0,0,0
0,0,0,0,0,0,0,0,0,0,0,0,0,0,0,0,0,0,0,0,0,0,0,0,0,0,0,0,0,0
0,0,0,0,0,0,0,0,0,0,0,0,0,0,0,0,0,0,0,0,0,0,0,0,0,0,0,0,0,0
0,0,0,0,0,0,0,0,0,0,0,0,0,0,0,0,0,0,0,0,0,0,0,0,0,0,0,0,0,0
0,0,0,0,0,0,0,0,0,0,0,0,0,0,0,0,0,0,0,0,0,0,0,0,0,0,0,0,0,0
0,0,0,0,0,0,0,0,0,0,0,0,0,0,0,0,0,0,0,0,0,0,0,0,0,0,0,0,0,0
0,0,0,0,0,0,0,0,0,0,0,0,0,0,0,0,0,0,0,0,0,0,0,0,0,0,0,0,0,0
0,0,0,0,0,0,0,0,0,0,0,0,0,0,0,0,0,0,0,0,0,0,0,0,0,0,0,0,0,0
0,0,0,0,0,0,0,0,0,0,0,0,0,0,0,0,0,0,0,0,0,0,0,0,0,0,0,0,0,0
0,0,0,0,0,0,0,0,0,0,0,0,0,0,0,0,0,0,0,0,0,0,0,0,0,0,0,0,0,0
endlayer

