biomesToSpawnIn=kelp forest,ocean,ocean oil field,oceanic abyss,coral reef,frozenocean,desert,dust planet
weight=750
embed_into_distance=0
acceptable_target_blocks=1,2,3,12,13,250
dimensions=4,14,13
allowable_overhang=0
max_cut_in=0
cut_in_buffer=0
max_leveling=0
leveling_buffer=0
preserve_water=0
preserve_lava=0
preserve_plants=0


rule1=0,75,250
rule2=0,10,159-14


layer
0,0,0,0,0,1,1,1,1,1,0,0,0
0,0,0,0,1,1,1,1,1,1,1,0,0
0,0,0,0,1,1,1,1,1,1,1,0,0
0,0,0,0,1,1,1,1,1,1,1,1,0
0,0,0,1,1,1,1,1,1,1,1,1,0
0,0,1,1,1,1,1,1,1,1,1,1,0
0,0,1,1,1,1,1,1,1,1,1,1,1
0,1,1,1,1,1,1,1,1,1,1,1,0
1,1,1,1,1,1,1,1,1,1,1,0,0
1,1,1,1,1,1,1,1,1,1,0,0,0
0,1,1,1,1,1,1,1,1,0,0,0,0
0,0,1,1,1,1,1,1,1,0,0,0,0
0,0,1,1,1,1,1,1,0,0,0,0,0
0,0,1,1,1,1,1,0,0,0,0,0,0
endlayer

layer
0,0,0,0,0,0,0,0,0,0,0,0,0
0,0,0,0,0,0,0,0,0,0,0,0,0
0,0,0,0,0,0,1,1,1,1,0,0,0
0,0,0,0,1,1,1,1,1,1,0,0,0
0,0,0,0,1,1,1,1,1,1,0,0,0
0,0,0,1,1,1,1,1,1,1,1,0,0
0,0,0,1,1,1,1,1,1,1,1,0,0
0,0,0,1,1,1,1,1,1,1,0,0,0
0,0,0,0,1,1,1,1,1,1,0,0,0
0,0,0,1,1,1,1,1,1,0,0,0,0
0,0,0,1,1,1,1,0,0,0,0,0,0
0,0,0,0,1,1,0,0,0,0,0,0,0
0,0,0,0,0,0,0,0,0,0,0,0,0
0,0,0,0,0,0,0,0,0,0,0,0,0
endlayer

layer
0,0,0,0,0,0,0,0,0,0,0,0,0
0,0,0,0,0,0,0,0,0,0,0,0,0
0,0,0,0,0,0,0,0,0,0,0,0,0
0,0,0,0,0,0,0,0,0,0,0,0,0
0,0,0,0,0,0,1,1,1,0,0,0,0
0,0,0,0,1,1,1,1,1,0,0,0,0
0,0,0,1,1,1,1,1,1,1,0,0,0
0,0,0,0,1,1,1,1,1,0,0,0,0
0,0,0,0,1,1,1,0,0,0,0,0,0
0,0,0,0,1,0,0,0,0,0,0,0,0
0,0,0,0,0,0,0,0,0,0,0,0,0
0,0,0,0,0,0,0,0,0,0,0,0,0
0,0,0,0,0,0,0,0,0,0,0,0,0
0,0,0,0,0,0,0,0,0,0,0,0,0
endlayer

layer
0,0,0,0,0,0,0,0,0,0,0,0,0
0,0,0,0,0,0,0,0,0,0,0,0,0
0,0,0,0,0,0,0,0,0,0,0,0,0
0,0,0,0,0,0,0,0,0,0,0,0,0
0,0,0,0,0,0,0,0,0,0,0,0,0
0,0,0,0,0,0,0,0,0,0,0,0,0
0,0,0,0,1,1,1,0,0,0,0,0,0
0,0,0,0,1,0,0,0,0,0,0,0,0
0,0,0,0,0,0,0,0,0,0,0,0,0
0,0,0,0,0,0,0,0,0,0,0,0,0
0,0,0,0,0,0,0,0,0,0,0,0,0
0,0,0,0,0,0,0,0,0,0,0,0,0
0,0,0,0,0,0,0,0,0,0,0,0,0
0,0,0,0,0,0,0,0,0,0,0,0,0
endlayer

