weight=1
embed_into_distance=1
max_leveling=4
max_cut_in=2
leveling_buffer=1
dimensions=22,18,18

rule1=0,100,2523-10
rule2=2,100,2843-4
rule3=0,100,2843-14,2843-14,2843-14,2843-14,2843
rule4=0,100,2835-2,2835-2,2835-2,2835-2,2835-2,2835-2,2835-2,2835-1,2835-1,2835-0
rule5=2,100,3225-3
rule6=0,100,622
rule7=0,100,64
rule8=0,100,623
rule9=0,100,64-8
rule10=0,100,2781-4,2781-4,2781-4,2781-4,2781-8
rule11=0,100,2523-10
rule12=0,100,300
rule13=0,100,159-14
rule14=0,100,159-15

layer
11,11,11,11,11,11,11,11,11,11,11,11,11,11,11,11,11,11
11,11,11,11,11,11,11,11,11,11,11,11,11,11,11,11,11,11
11,11,1,1,1,1,1,1,1,1,1,1,1,1,1,1,11,11
11,11,1,2,2,2,2,2,2,2,2,2,2,2,2,1,11,11
11,11,1,2,2,2,2,2,2,2,2,2,2,2,2,1,11,11
11,11,1,2,2,2,2,2,2,2,2,2,2,2,2,1,11,11
11,11,1,2,2,2,2,6,2,2,2,2,2,2,2,1,11,11
11,11,1,2,2,2,3,2,2,3,2,2,2,2,2,1,11,11
11,11,1,1,1,1,1,1,1,1,1,1,1,1,1,1,11,11
11,11,1,1,1,1,1,1,1,1,1,1,1,1,1,1,11,11
11,11,1,1,1,1,1,1,1,1,1,1,1,1,1,1,11,11
11,11,1,2,2,2,2,2,2,2,2,2,2,2,2,1,11,11
11,11,1,2,2,2,2,2,2,2,2,2,2,2,2,1,11,11
11,11,1,2,2,2,2,2,2,2,2,2,2,2,2,1,11,11
11,11,1,2,2,2,2,2,2,2,2,2,2,2,2,1,11,11
11,11,1,1,1,1,1,1,1,1,1,1,1,1,1,1,11,11
11,11,11,11,11,11,11,11,11,11,11,11,11,11,11,11,11,11
11,11,11,11,11,11,11,11,11,11,11,11,11,11,11,11,11,11
endlayer

layer
0,0,0,0,0,0,0,0,0,0,0,0,0,0,0,0,0,0
0,0,0,0,0,0,0,0,0,0,0,0,0,0,0,0,0,0
0,0,3,3,3,3,3,3,3,3,3,3,3,3,3,3,0,0
0,0,3,0,0,0,0,0,0,0,0,0,0,0,0,3,0,0
0,0,3,0,0,0,4,0,0,4,0,0,0,0,0,3,0,0
0,0,3,0,0,0,5,0,0,5,0,0,0,0,0,3,0,0
0,0,3,0,0,0,4,8,0,4,0,0,0,0,0,3,0,0
0,0,3,4,5,4,3,0,5,3,4,4,4,5,4,3,0,0
0,0,0,0,0,0,0,0,0,0,0,0,0,0,0,0,0,0
0,0,0,0,0,0,0,0,0,0,0,0,0,0,0,0,0,0
0,0,0,0,0,0,0,0,0,0,0,0,0,0,0,0,0,0
0,0,3,4,0,4,5,4,3,3,4,5,4,0,4,3,0,0
0,0,3,0,0,0,0,0,4,4,0,0,0,0,0,3,0,0
0,0,3,0,0,0,0,0,4,4,0,0,0,0,0,3,0,0
0,0,3,0,0,0,0,0,4,4,0,0,0,0,0,3,0,0
0,0,3,3,3,3,3,3,3,3,3,3,3,3,3,3,0,0
0,0,0,0,0,0,0,0,0,0,0,0,0,0,0,0,0,0
0,0,0,0,0,0,0,0,0,0,0,0,0,0,0,0,0,0
endlayer

layer
0,0,0,0,0,0,0,0,0,0,0,0,0,0,0,0,0,0
0,0,0,0,0,0,0,0,0,0,0,0,0,0,0,0,0,0
0,0,3,4,5,4,3,5,5,3,4,5,4,5,4,3,0,0
0,0,4,0,0,0,0,0,0,0,0,0,0,0,0,4,0,0
0,0,5,0,0,0,4,0,0,4,0,0,0,0,0,5,0,0
0,0,5,0,0,0,5,0,0,5,0,0,0,0,0,5,0,0
0,0,4,0,0,0,4,8,0,4,0,0,0,0,0,4,0,0
0,0,3,4,5,4,3,0,5,3,4,0,4,5,4,3,0,0
0,0,0,0,0,0,0,0,0,0,0,0,0,0,0,0,0,0
0,0,0,0,0,0,0,0,0,0,0,0,0,0,0,0,0,0
0,0,0,0,0,0,0,0,0,0,0,0,0,0,0,0,0,0
0,0,3,4,0,4,5,4,3,3,4,5,4,0,4,3,0,0
0,0,4,0,0,0,0,0,4,4,0,0,0,0,0,4,0,0
0,0,5,0,0,0,0,0,4,4,0,0,0,0,0,5,0,0
0,0,4,0,0,0,0,0,4,4,0,0,0,0,0,4,0,0
0,0,3,4,5,4,5,4,3,3,4,5,4,5,4,3,0,0
0,0,0,0,0,0,0,0,0,0,0,0,0,0,0,0,0,0
0,0,0,0,0,0,0,0,0,0,0,0,0,0,0,0,0,0
endlayer

layer
0,0,0,0,0,0,0,0,0,0,0,0,0,0,0,0,0,0
0,0,0,0,0,0,0,0,0,0,0,0,0,0,0,0,0,0
0,0,3,4,5,4,3,5,5,3,4,5,4,5,4,3,0,0
0,0,4,0,0,0,4,0,0,4,0,0,0,0,0,4,0,0
0,0,5,0,0,0,4,0,0,4,0,0,0,0,0,5,0,0
0,0,5,0,0,0,5,0,0,5,0,0,0,0,0,5,0,0
0,0,4,0,0,0,4,8,0,4,0,0,0,0,0,4,0,0
0,0,3,4,5,4,3,5,5,3,4,4,4,5,4,3,0,0
0,0,0,0,0,0,0,0,0,0,0,0,0,0,0,0,0,0
0,0,0,0,0,0,0,0,0,0,0,0,0,0,0,0,0,0
0,0,0,0,0,0,0,0,0,0,0,0,0,0,0,0,0,0
0,0,3,4,4,4,5,4,3,3,4,5,4,4,4,3,0,0
0,0,4,0,0,0,0,0,4,4,0,0,0,0,0,4,0,0
0,0,5,0,0,0,0,0,4,4,0,0,0,0,0,5,0,0
0,0,4,0,0,0,0,0,4,4,0,0,0,0,0,4,0,0
0,0,3,4,5,4,5,4,3,3,4,5,4,5,4,3,0,0
0,0,0,0,0,0,0,0,0,0,0,0,0,0,0,0,0,0
0,0,0,0,0,0,0,0,0,0,0,0,0,0,0,0,0,0
endlayer

layer
0,0,0,0,0,0,0,0,0,0,0,0,0,0,0,0,0,0
0,0,0,0,0,0,0,0,0,0,0,0,0,0,0,0,0,0
0,0,3,4,5,4,3,5,5,3,4,5,4,5,4,3,0,0
0,0,4,0,0,0,4,0,0,4,0,0,0,0,0,4,0,0
0,0,5,0,0,0,4,0,0,4,0,0,0,0,0,5,0,0
0,0,5,0,0,0,5,0,0,5,0,0,0,0,0,5,0,0
0,0,4,0,0,0,4,8,0,4,0,0,0,0,0,4,0,0
0,0,3,4,5,4,3,5,5,3,4,4,4,5,4,3,0,0
0,0,0,0,0,0,0,0,0,0,0,0,0,0,0,0,0,0
0,0,0,0,0,0,0,0,0,0,0,0,0,0,0,0,0,0
0,0,0,0,0,0,0,0,0,0,0,0,0,0,0,0,0,0
0,0,3,4,4,4,5,4,3,3,4,5,4,4,4,3,0,0
0,0,4,0,0,0,0,0,4,4,0,0,0,0,0,4,0,0
0,0,5,0,0,0,0,0,4,4,0,0,0,0,0,5,0,0
0,0,4,0,0,0,0,0,4,4,0,0,0,0,0,4,0,0
0,0,3,4,5,4,5,4,3,3,4,5,4,5,4,3,0,0
0,0,0,0,0,0,0,0,0,0,0,0,0,0,0,0,0,0
0,0,0,0,0,0,0,0,0,0,0,0,0,0,0,0,0,0
endlayer

layer
0,0,0,0,0,0,0,0,0,0,0,0,0,0,0,0,0,0
0,0,0,0,0,0,0,0,0,0,0,0,0,0,0,0,0,0
0,0,3,4,5,4,3,5,5,3,4,5,4,5,4,3,0,0
0,0,4,0,0,0,4,0,0,4,0,0,0,0,0,4,0,0
0,0,5,0,0,0,4,0,0,4,0,0,0,0,0,5,0,0
0,0,5,0,0,0,5,0,0,5,0,0,0,0,0,5,0,0
0,0,4,0,0,0,4,8,0,4,0,0,0,0,0,4,0,0
0,0,3,4,5,4,3,5,5,3,4,4,4,5,4,3,0,0
0,0,0,0,0,0,0,0,0,0,0,0,0,0,0,0,0,0
0,0,0,0,0,0,0,0,0,0,0,0,0,0,0,0,0,0
0,0,0,0,0,0,0,0,0,0,0,0,0,0,0,0,0,0
0,0,3,4,4,4,5,4,3,3,4,5,4,4,4,3,0,0
0,0,4,0,0,0,0,0,4,4,0,0,0,0,0,4,0,0
0,0,5,0,0,0,0,0,4,4,0,0,0,0,0,5,0,0
0,0,4,0,0,0,0,0,4,4,0,0,0,0,0,4,0,0
0,0,3,4,5,4,5,4,3,3,4,5,4,5,4,3,0,0
0,0,0,0,0,0,0,0,0,0,0,0,0,0,0,0,0,0
0,0,0,0,0,0,0,0,0,0,0,0,0,0,0,0,0,0
endlayer

layer
0,0,0,0,0,0,0,0,0,0,0,0,0,0,0,0,0,0
0,0,0,0,0,0,0,0,0,0,0,0,0,0,0,0,0,0
0,0,3,3,3,3,3,3,3,3,3,3,3,3,3,3,0,0
0,0,3,2,2,2,2,2,2,2,2,2,2,2,2,3,0,0
0,0,3,2,2,2,3,2,2,3,2,2,2,2,2,3,0,0
0,0,3,2,2,2,3,2,2,3,2,2,2,2,2,3,0,0
0,0,3,2,2,2,3,8,2,3,2,2,2,2,2,3,0,0
0,0,3,3,3,3,3,2,2,3,3,3,3,3,3,3,0,0
0,0,0,2,2,2,2,2,2,2,2,2,2,2,2,0,0,0
0,0,0,2,2,2,2,2,2,2,2,2,2,2,2,0,0,0
0,0,0,2,2,2,2,2,2,2,2,2,2,2,2,0,0,0
0,0,3,3,2,3,3,3,3,3,3,3,3,2,3,3,0,0
0,0,3,2,2,2,2,2,2,2,2,2,2,2,2,3,0,0
0,0,3,2,2,2,2,2,2,2,2,2,2,2,2,3,0,0
0,0,3,2,2,2,2,2,2,2,2,2,2,2,2,3,0,0
0,0,3,3,3,3,3,3,3,3,3,3,3,3,3,3,0,0
0,0,0,0,0,0,0,0,0,0,0,0,0,0,0,0,0,0
0,0,0,0,0,0,0,0,0,0,0,0,0,0,0,0,0,0
endlayer

layer
0,0,0,0,0,0,0,0,0,0,0,0,0,0,0,0,0,0
0,0,0,0,0,0,0,0,0,0,0,0,0,0,0,0,0,0
0,0,3,4,5,4,3,5,5,3,4,5,4,5,4,3,0,0
0,0,4,0,0,0,0,0,0,0,0,0,0,0,0,4,0,0
0,0,5,0,0,0,4,0,0,4,0,0,0,0,0,5,0,0
0,0,5,0,0,0,5,0,0,5,0,0,0,0,0,5,0,0
0,0,4,0,0,0,4,8,0,4,0,0,0,0,0,4,0,0
0,0,3,4,5,4,3,0,5,3,4,5,4,5,4,3,0,0
0,0,0,0,0,0,0,0,0,0,0,0,0,0,0,0,0,0
0,0,0,0,0,0,0,0,0,0,0,0,0,0,0,0,0,0
0,0,0,0,0,0,0,0,0,0,0,0,0,0,0,0,0,0
0,0,3,4,0,4,5,4,3,3,4,5,4,0,4,3,0,0
0,0,4,0,0,0,0,0,4,4,0,0,0,0,0,4,0,0
0,0,5,0,0,0,0,0,4,4,0,0,0,0,0,5,0,0
0,0,4,0,0,0,0,0,4,4,0,0,0,0,0,4,0,0
0,0,3,4,5,4,5,4,3,3,4,5,4,5,4,3,0,0
0,0,0,0,0,0,0,0,0,0,0,0,0,0,0,0,0,0
0,0,0,0,0,0,0,0,0,0,0,0,0,0,0,0,0,0
endlayer

layer
0,0,0,0,0,0,0,0,0,0,0,0,0,0,0,0,0,0
0,0,0,0,0,0,0,0,0,0,0,0,0,0,0,0,0,0
0,0,3,4,5,4,3,5,5,3,4,5,4,5,4,3,0,0
0,0,4,0,0,0,0,0,0,0,0,0,0,0,0,4,0,0
0,0,5,0,0,0,4,0,0,4,0,0,0,0,0,5,0,0
0,0,5,0,0,0,5,0,0,5,0,0,0,0,0,5,0,0
0,0,4,0,0,0,4,8,0,4,0,0,0,0,0,4,0,0
0,0,3,4,5,4,3,0,5,3,4,5,4,5,4,3,0,0
0,0,0,0,0,0,0,0,0,0,0,0,0,0,0,0,0,0
0,0,0,0,0,0,0,0,0,0,0,0,0,0,0,0,0,0
0,0,0,0,0,0,0,0,0,0,0,0,0,0,0,0,0,0
0,0,3,4,0,4,5,4,3,3,4,5,4,0,4,3,0,0
0,0,4,0,0,0,0,0,4,4,0,0,0,0,0,4,0,0
0,0,5,0,0,0,0,0,4,4,0,0,0,0,0,5,0,0
0,0,4,0,0,0,0,0,4,4,0,0,0,0,0,4,0,0
0,0,3,4,5,4,5,4,3,3,4,5,4,5,4,3,0,0
0,0,0,0,0,0,0,0,0,0,0,0,0,0,0,0,0,0
0,0,0,0,0,0,0,0,0,0,0,0,0,0,0,0,0,0
endlayer

layer
0,0,0,0,0,0,0,0,0,0,0,0,0,0,0,0,0,0
0,0,0,0,0,0,0,0,0,0,0,0,0,0,0,0,0,0
0,0,3,4,5,4,3,5,5,3,4,5,4,5,4,3,0,0
0,0,4,0,0,0,4,0,0,4,0,0,0,0,0,4,0,0
0,0,5,0,0,0,4,0,0,4,0,0,0,0,0,5,0,0
0,0,5,0,0,0,5,0,0,5,0,0,0,0,0,5,0,0
0,0,4,0,0,0,4,8,0,4,0,0,0,0,0,4,0,0
0,0,3,4,5,4,3,5,5,3,4,5,4,5,4,3,0,0
0,0,0,0,0,0,0,0,0,0,0,0,0,0,0,0,0,0
0,0,0,0,0,0,0,0,0,0,0,0,0,0,0,0,0,0
0,0,0,0,0,0,0,0,0,0,0,0,0,0,0,0,0,0
0,0,3,4,4,4,5,4,3,3,4,5,4,4,4,3,0,0
0,0,4,0,0,0,0,0,4,4,0,0,0,0,0,4,0,0
0,0,5,0,0,0,0,0,4,4,0,0,0,0,0,5,0,0
0,0,4,0,0,0,0,0,4,4,0,0,0,0,0,4,0,0
0,0,3,4,5,4,5,4,3,3,4,5,4,5,4,3,0,0
0,0,0,0,0,0,0,0,0,0,0,0,0,0,0,0,0,0
0,0,0,0,0,0,0,0,0,0,0,0,0,0,0,0,0,0
endlayer

layer
0,0,0,0,0,0,0,0,0,0,0,0,0,0,0,0,0,0
0,0,0,0,0,0,0,0,0,0,0,0,0,0,0,0,0,0
0,0,3,4,5,4,3,5,5,3,4,5,4,5,4,3,0,0
0,0,4,0,0,0,4,0,0,4,0,0,0,0,0,4,0,0
0,0,5,0,0,0,4,0,0,4,0,0,0,0,0,5,0,0
0,0,5,0,0,0,5,0,0,5,0,0,0,0,0,5,0,0
0,0,4,0,0,0,4,8,0,4,0,0,0,0,0,4,0,0
0,0,3,4,5,4,3,5,5,3,4,5,4,5,4,3,0,0
0,0,0,0,0,0,0,0,0,0,0,0,0,0,0,0,0,0
0,0,0,0,0,0,0,0,0,0,0,0,0,0,0,0,0,0
0,0,0,0,0,0,0,0,0,0,0,0,0,0,0,0,0,0
0,0,3,4,4,4,5,4,3,3,4,5,4,4,4,3,0,0
0,0,4,0,0,0,0,0,4,4,0,0,0,0,0,4,0,0
0,0,5,0,0,0,0,0,4,4,0,0,0,0,0,5,0,0
0,0,4,0,0,0,0,0,4,4,0,0,0,0,0,4,0,0
0,0,3,4,5,4,5,4,3,3,4,5,4,5,4,3,0,0
0,0,0,0,0,0,0,0,0,0,0,0,0,0,0,0,0,0
0,0,0,0,0,0,0,0,0,0,0,0,0,0,0,0,0,0
endlayer

layer
0,0,0,0,0,0,0,0,0,0,0,0,0,0,0,0,0,0
0,0,0,0,0,0,0,0,0,0,0,0,0,0,0,0,0,0
0,0,3,3,3,3,3,3,3,3,3,3,3,3,3,3,0,0
0,0,3,2,2,2,2,2,2,2,2,2,2,2,2,3,0,0
0,0,3,2,2,2,3,2,2,3,2,2,2,2,2,3,0,0
0,0,3,2,2,2,3,2,2,3,2,2,2,2,2,3,0,0
0,0,3,2,2,2,3,8,2,3,2,2,2,2,2,3,0,0
0,0,3,3,3,3,3,3,3,3,3,3,3,3,3,3,0,0
0,0,0,0,0,0,0,0,0,0,0,0,0,0,0,0,0,0
0,0,0,0,0,0,0,0,0,0,0,0,0,0,0,0,0,0
0,0,0,0,0,0,0,0,0,0,0,0,0,0,0,0,0,0
0,0,3,3,3,3,3,3,3,3,3,3,3,3,3,3,0,0
0,0,3,10,10,10,10,10,10,10,10,10,10,10,10,3,0,0
0,0,3,10,10,10,10,10,10,10,10,10,10,10,10,3,0,0
0,0,3,10,10,10,10,10,10,10,10,10,10,10,10,3,0,0
0,0,3,3,3,3,3,3,3,3,3,3,3,3,3,3,0,0
0,0,0,0,0,0,0,0,0,0,0,0,0,0,0,0,0,0
0,0,0,0,0,0,0,0,0,0,0,0,0,0,0,0,0,0
endlayer

layer
0,0,0,0,0,0,0,0,0,0,0,0,0,0,0,0,0,0
0,0,0,0,0,0,0,0,0,0,0,0,0,0,0,0,0,0
0,0,3,4,5,4,3,5,5,3,4,5,4,5,4,3,0,0
0,0,4,0,0,0,0,0,0,0,0,0,0,0,0,4,0,0
0,0,5,0,0,0,4,0,0,4,0,0,0,0,0,5,0,0
0,0,5,0,0,0,5,0,0,5,0,0,0,0,0,5,0,0
0,0,4,0,0,0,4,8,0,4,0,0,0,0,0,4,0,0
0,0,3,4,5,4,3,5,5,3,4,5,4,5,4,3,0,0
0,0,0,0,0,0,0,0,0,0,0,0,0,0,0,0,0,0
0,0,0,0,0,0,0,0,0,0,0,0,0,0,0,0,0,0
0,0,0,0,0,0,0,0,0,0,0,0,0,0,0,0,0,0
0,0,0,0,0,0,0,0,0,0,0,0,0,0,0,0,0,0
0,0,0,0,0,0,0,0,0,0,0,0,0,0,0,0,0,0
0,0,0,0,0,0,0,0,0,0,0,0,0,0,0,0,0,0
0,0,0,0,0,0,0,0,0,0,0,0,0,0,0,0,0,0
0,0,0,0,0,0,0,0,0,0,0,0,0,0,0,0,0,0
0,0,0,0,0,0,0,0,0,0,0,0,0,0,0,0,0,0
0,0,0,0,0,0,0,0,0,0,0,0,0,0,0,0,0,0
endlayer

layer
0,0,0,0,0,0,0,0,0,0,0,0,0,0,0,0,0,0
0,0,0,0,0,0,0,0,0,0,0,0,0,0,0,0,0,0
0,0,3,4,5,4,3,5,5,3,4,5,4,5,4,3,0,0
0,0,4,0,0,0,0,0,0,0,0,0,0,0,0,4,0,0
0,0,5,0,0,0,4,0,0,4,0,0,0,0,0,5,0,0
0,0,5,0,0,0,5,0,0,5,0,0,0,0,0,5,0,0
0,0,4,0,0,0,4,8,0,4,0,0,0,0,0,4,0,0
0,0,3,4,5,4,3,5,5,3,4,5,4,5,4,3,0,0
0,0,0,0,0,0,0,0,0,0,0,0,0,0,0,0,0,0
0,0,0,0,0,0,0,0,0,0,0,0,0,0,0,0,0,0
0,0,0,0,0,0,0,0,0,0,0,0,0,0,0,0,0,0
0,0,0,0,0,0,0,0,0,0,0,0,0,0,0,0,0,0
0,0,0,0,0,0,0,0,0,0,0,0,0,0,0,0,0,0
0,0,0,0,0,0,0,0,0,0,0,0,0,0,0,0,0,0
0,0,0,0,0,0,0,0,0,0,0,0,0,0,0,0,0,0
0,0,0,0,0,0,0,0,0,0,0,0,0,0,0,0,0,0
0,0,0,0,0,0,0,0,0,0,0,0,0,0,0,0,0,0
0,0,0,0,0,0,0,0,0,0,0,0,0,0,0,0,0,0
endlayer

layer
0,0,0,0,0,0,0,0,0,0,0,0,0,0,0,0,0,0
0,0,0,0,0,0,0,0,0,0,0,0,0,0,0,0,0,0
0,0,3,4,5,4,3,5,5,3,4,5,4,5,4,3,0,0
0,0,4,0,0,0,4,0,0,0,0,0,0,0,0,4,0,0
0,0,5,0,0,0,4,0,0,4,0,0,0,0,0,5,0,0
0,0,5,0,0,0,5,0,0,5,0,0,0,0,0,5,0,0
0,0,4,0,0,0,4,8,0,4,0,0,0,0,0,4,0,0
0,0,3,4,5,4,3,5,5,3,4,5,4,5,4,3,0,0
0,0,0,0,0,0,0,0,0,0,0,0,0,0,0,0,0,0
0,0,0,0,0,0,0,0,0,0,0,0,0,0,0,0,0,0
0,0,0,0,0,0,0,0,0,0,0,0,0,0,0,0,0,0
0,0,0,0,0,0,0,0,0,0,0,0,0,0,0,0,0,0
0,0,0,0,0,0,0,0,0,0,0,0,0,0,0,0,0,0
0,0,0,0,0,0,0,0,0,0,0,0,0,0,0,0,0,0
0,0,0,0,0,0,0,0,0,0,0,0,0,0,0,0,0,0
0,0,0,0,0,0,0,0,0,0,0,0,0,0,0,0,0,0
0,0,0,0,0,0,0,0,0,0,0,0,0,0,0,0,0,0
0,0,0,0,0,0,0,0,0,0,0,0,0,0,0,0,0,0
endlayer

layer
0,0,0,0,0,0,0,0,0,0,0,0,0,0,0,0,0,0
0,0,0,0,0,0,0,0,0,0,0,0,0,0,0,0,0,0
0,0,3,4,5,4,3,5,5,3,4,5,4,5,4,3,0,0
0,0,4,0,0,0,4,0,0,0,0,0,0,0,0,4,0,0
0,0,5,0,0,0,4,0,0,4,0,0,0,0,0,5,0,0
0,0,5,0,0,0,5,0,0,5,0,0,0,0,0,5,0,0
0,0,4,0,0,0,4,8,0,4,0,0,0,0,0,4,0,0
0,0,3,4,5,4,3,5,5,3,4,5,4,5,4,3,0,0
0,0,0,0,0,0,0,0,0,0,0,0,0,0,0,0,0,0
0,0,0,0,0,0,0,0,0,0,0,0,0,0,0,0,0,0
0,0,0,0,0,0,0,0,0,0,0,0,0,0,0,0,0,0
0,0,0,0,0,0,0,0,0,0,0,0,0,0,0,0,0,0
0,0,0,0,0,0,0,0,0,0,0,0,0,0,0,0,0,0
0,0,0,0,0,0,0,0,0,0,0,0,0,0,0,0,0,0
0,0,0,0,0,0,0,0,0,0,0,0,0,0,0,0,0,0
0,0,0,0,0,0,0,0,0,0,0,0,0,0,0,0,0,0
0,0,0,0,0,0,0,0,0,0,0,0,0,0,0,0,0,0
0,0,0,0,0,0,0,0,0,0,0,0,0,0,0,0,0,0
endlayer

layer
0,0,0,0,0,0,0,0,0,0,0,0,0,0,0,0,0,0
0,0,0,0,0,0,0,0,0,0,0,0,0,0,0,0,0,0
0,0,3,3,3,3,3,3,3,3,3,3,3,3,3,3,0,0
0,0,3,2,2,2,2,2,2,2,2,2,2,2,2,3,0,0
0,0,3,2,2,2,3,2,2,3,2,2,2,2,2,3,0,0
0,0,3,2,2,2,3,2,2,3,2,2,2,2,2,3,0,0
0,0,3,2,2,2,3,8,2,3,2,2,2,2,2,3,0,0
0,0,3,3,3,3,3,3,3,3,3,3,3,3,3,3,0,0
0,0,0,0,0,0,0,0,0,0,0,0,0,0,0,0,0,0
0,0,0,0,0,0,0,0,0,0,0,0,0,0,0,0,0,0
0,0,0,0,0,0,0,0,0,0,0,0,0,0,0,0,0,0
0,0,0,0,0,0,0,0,0,0,0,0,0,0,0,0,0,0
0,0,0,0,0,0,0,0,0,0,0,0,0,0,0,0,0,0
0,0,0,0,0,0,0,0,0,0,0,0,0,0,0,0,0,0
0,0,0,0,0,0,0,0,0,0,0,0,0,0,0,0,0,0
0,0,0,0,0,0,0,0,0,0,0,0,0,0,0,0,0,0
0,0,0,0,0,0,0,0,0,0,0,0,0,0,0,0,0,0
0,0,0,0,0,0,0,0,0,0,0,0,0,0,0,0,0,0
endlayer

layer
0,0,0,0,0,0,0,0,0,0,0,0,0,0,0,0,0,0
0,0,0,0,0,0,0,0,0,0,0,0,0,0,0,0,0,0
0,0,3,4,5,4,3,5,5,3,4,5,4,5,4,3,0,0
0,0,4,0,0,0,0,0,0,0,0,0,0,0,0,4,0,0
0,0,5,0,0,0,4,0,0,4,0,0,0,0,0,5,0,0
0,0,5,0,0,0,5,0,0,5,0,0,0,0,0,5,0,0
0,0,4,0,0,0,4,8,0,4,0,0,0,0,0,4,0,0
0,0,3,4,5,4,3,5,5,3,4,5,4,5,4,3,0,0
0,0,0,0,0,0,0,0,0,0,0,0,0,0,0,0,0,0
0,0,0,0,0,0,0,0,0,0,0,0,0,0,0,0,0,0
0,0,0,0,0,0,0,0,0,0,0,0,0,0,0,0,0,0
0,0,0,0,0,0,0,0,0,0,0,0,0,0,0,0,0,0
0,0,0,0,0,0,0,0,0,0,0,0,0,0,0,0,0,0
0,0,0,0,0,0,0,0,0,0,0,0,0,0,0,0,0,0
0,0,0,0,0,0,0,0,0,0,0,0,0,0,0,0,0,0
0,0,0,0,0,0,0,0,0,0,0,0,0,0,0,0,0,0
0,0,0,0,0,0,0,0,0,0,0,0,0,0,0,0,0,0
0,0,0,0,0,0,0,0,0,0,0,0,0,0,0,0,0,0
endlayer

layer
0,0,0,0,0,0,0,0,0,0,0,0,0,0,0,0,0,0
0,0,0,0,0,0,0,0,0,0,0,0,0,0,0,0,0,0
0,0,3,4,5,4,3,5,5,3,4,5,4,5,4,3,0,0
0,0,4,0,0,0,0,0,0,0,0,0,0,0,0,4,0,0
0,0,5,0,0,0,4,0,0,4,0,0,0,0,0,5,0,0
0,0,5,0,0,0,5,0,0,5,0,0,0,0,0,5,0,0
0,0,4,0,0,0,4,8,0,4,0,0,0,0,0,4,0,0
0,0,3,4,5,4,3,5,5,3,4,5,4,5,4,3,0,0
0,0,0,0,0,0,0,0,0,0,0,0,0,0,0,0,0,0
0,0,0,0,0,0,0,0,0,0,0,0,0,0,0,0,0,0
0,0,0,0,0,0,0,0,0,0,0,0,0,0,0,0,0,0
0,0,0,0,0,0,0,0,0,0,0,0,0,0,0,0,0,0
0,0,0,0,0,0,0,0,0,0,0,0,0,0,0,0,0,0
0,0,0,0,0,0,0,0,0,0,0,0,0,0,0,0,0,0
0,0,0,0,0,0,0,0,0,0,0,0,0,0,0,0,0,0
0,0,0,0,0,0,0,0,0,0,0,0,0,0,0,0,0,0
0,0,0,0,0,0,0,0,0,0,0,0,0,0,0,0,0,0
0,0,0,0,0,0,0,0,0,0,0,0,0,0,0,0,0,0
endlayer

layer
0,0,0,0,0,0,0,0,0,0,0,0,0,0,0,0,0,0
0,0,0,0,0,0,0,0,0,0,0,0,0,0,0,0,0,0
0,0,3,4,5,4,3,5,5,3,4,5,4,5,4,3,0,0
0,0,4,0,0,0,4,0,0,0,0,0,0,0,0,4,0,0
0,0,5,0,0,0,4,0,0,4,0,0,0,0,0,5,0,0
0,0,5,0,0,0,5,0,0,5,0,0,0,0,0,5,0,0
0,0,4,0,0,0,4,0,0,4,0,0,0,0,0,4,0,0
0,0,3,4,5,4,3,5,5,3,4,5,4,5,4,3,0,0
0,0,0,0,0,0,0,0,0,0,0,0,0,0,0,0,0,0
0,0,0,0,0,0,0,0,0,0,0,0,0,0,0,0,0,0
0,0,0,0,0,0,0,0,0,0,0,0,0,0,0,0,0,0
0,0,0,0,0,0,0,0,0,0,0,0,0,0,0,0,0,0
0,0,0,0,0,0,0,0,0,0,0,0,0,0,0,0,0,0
0,0,0,0,0,0,0,0,0,0,0,0,0,0,0,0,0,0
0,0,0,0,0,0,0,0,0,0,0,0,0,0,0,0,0,0
0,0,0,0,0,0,0,0,0,0,0,0,0,0,0,0,0,0
0,0,0,0,0,0,0,0,0,0,0,0,0,0,0,0,0,0
0,0,0,0,0,0,0,0,0,0,0,0,0,0,0,0,0,0
endlayer

layer
0,0,0,0,0,0,0,0,0,0,0,0,0,0,0,0,0,0
0,0,0,0,0,0,0,0,0,0,0,0,0,0,0,0,0,0
0,0,3,4,5,4,3,5,5,3,4,5,4,5,4,3,0,0
0,0,4,0,0,0,4,0,0,0,0,0,0,0,0,4,0,0
0,0,5,0,0,0,4,0,0,4,0,0,0,0,0,5,0,0
0,0,5,0,0,0,5,0,0,5,0,0,0,0,0,5,0,0
0,0,4,0,0,0,4,0,0,4,0,0,0,0,0,4,0,0
0,0,3,4,5,4,3,5,5,3,4,5,4,5,4,3,0,0
0,0,0,0,0,0,0,0,0,0,0,0,0,0,0,0,0,0
0,0,0,0,0,0,0,0,0,0,0,0,0,0,0,0,0,0
0,0,0,0,0,0,0,0,0,0,0,0,0,0,0,0,0,0
0,0,0,0,0,0,0,0,0,0,0,0,0,0,0,0,0,0
0,0,0,0,0,0,0,0,0,0,0,0,0,0,0,0,0,0
0,0,0,0,0,0,0,0,0,0,0,0,0,0,0,0,0,0
0,0,0,0,0,0,0,0,0,0,0,0,0,0,0,0,0,0
0,0,0,0,0,0,0,0,0,0,0,0,0,0,0,0,0,0
0,0,0,0,0,0,0,0,0,0,0,0,0,0,0,0,0,0
0,0,0,0,0,0,0,0,0,0,0,0,0,0,0,0,0,0
endlayer

layer
0,0,0,0,0,0,0,0,0,0,0,0,0,0,0,0,0,0
0,0,0,0,0,0,0,0,0,0,0,0,0,0,0,0,0,0
0,0,3,3,3,3,3,3,3,3,3,3,3,3,3,3,0,0
0,0,3,10,10,10,3,10,10,3,10,10,10,10,10,3,0,0
0,0,3,10,10,10,3,10,10,3,10,10,10,10,10,3,0,0
0,0,3,10,10,10,3,10,10,3,10,10,10,10,10,3,0,0
0,0,3,10,10,10,3,10,10,3,10,10,10,10,10,3,0,0
0,0,3,3,3,3,3,3,3,3,3,3,3,3,3,3,0,0
0,0,0,0,0,0,0,0,0,0,0,0,0,0,0,0,0,0
0,0,0,0,0,0,0,0,0,0,0,0,0,0,0,0,0,0
0,0,0,0,0,0,0,0,0,0,0,0,0,0,0,0,0,0
0,0,0,0,0,0,0,0,0,0,0,0,0,0,0,0,0,0
0,0,0,0,0,0,0,0,0,0,0,0,0,0,0,0,0,0
0,0,0,0,0,0,0,0,0,0,0,0,0,0,0,0,0,0
0,0,0,0,0,0,0,0,0,0,0,0,0,0,0,0,0,0
0,0,0,0,0,0,0,0,0,0,0,0,0,0,0,0,0,0
0,0,0,0,0,0,0,0,0,0,0,0,0,0,0,0,0,0
0,0,0,0,0,0,0,0,0,0,0,0,0,0,0,0,0,0
endlayer

